Workbook

Sheet 01
A1: Station: | B1: IGKV ,RAIPUR
A2: Date: | B2: =$A$9 -> 45323.042 | D2: Power Off | G2: Pw.Off | L2: Link Fail | N2: Link F | P2: Maintenance | R2: Maint.
A3: Report Type: | B3: Mean | D3: Calibration | G3: Calib. | L3: Data Fail | N3: Data F | P3: Invalid | R3: Invalid
A4: Time Base: | B4: 01 Hour | D4: Zero Referrence | G4: Z.Ref | L4: Warm Up | N4: Wm. Up
A7: Date & Time | B7: NO | C7: NO2 | D7: NOX | E7: SO2 | F7: O3 | G7: PM 10 | H7: PM 2.5 | I7: BENZ | J7: WS | K7: WD | L7: TEMP | M7: HUM | N7: SR | O7: RG | P7: CO | Q7: NH3
B8: ug/m3 | C8: ug/m3 | D8: ppb | E8: ug/m3 | F8: ug/m3 | G8: ug/m3 | H8: ug/m3 | I8: ug/m3 | J8: m/sec | K8: deg | L8: degreC | M8: % | N8: w/m2 | O8: mm | P8: mg/m3 | Q8: ug/m3
A9: 45323.042 | B9: 7.68 | C9: 20.33 | D9: 18.13 | E9: 6.04 | F9: 3.86 | G9: 94.82 | H9: 39.64 | I9: 9.45 | J9: 0.23 | K9: 212.69 | L9: 19.97 | M9: 83.03 | N9: 0 | O9: 0 | P9: 0.83 | Q9: 4.8
A10: 45323.083 | B10: 7.69 | C10: 20.57 | D10: 18.21 | E10: 6.58 | F10: 3.74 | G10: 83.46 | H10: 37.03 | I10: 9.06 | J10: 0.12 | K10: 186.63 | L10: 19.6 | M10: 81.17 | N10: 0 | O10: 0 | P10: 0.82 | Q10: 4.78
A11: 45323.125 | B11: 7.78 | C11: 19.49 | D11: 17.69 | E11: 5.26 | F11: 3.62 | G11: 76.01 | H11: 35.79 | I11: 8.72 | J11: 0.14 | K11: 226.45 | L11: 19.24 | M11: 81.72 | N11: 0 | O11: 0 | P11: 0.78 | Q11: 4.79
A12: 45323.167 | B12: 10.72 | C12: 20.43 | D12: 20.62 | E12: 5.33 | F12: 3.82 | G12: 71.74 | H12: 35.42 | I12: 8.36 | J12: 0.51 | K12: 344.33 | L12: 19.19 | M12: 81.46 | N12: 0 | O12: 0 | P12: 0.74 | Q12: 4.82
A13: 45323.208 | B13: 12.5 | C13: 22.28 | D13: 23.02 | E13: 5.25 | F13: 3.47 | G13: 69.94 | H13: 35.73 | I13: 8.04 | J13: 0.65 | K13: 48.5 | L13: 19.07 | M13: 82.14 | N13: 0 | O13: 0 | P13: 0.75 | Q13: 4.87
A14: 45323.25 | B14: 18.04 | C14: 25.02 | D14: 28.89 | E14: 5.46 | F14: 3.44 | G14: 78.71 | H14: 39.12 | I14: 8.41 | J14: 0.33 | K14: 187.22 | L14: 18.46 | M14: 87.18 | N14: 0 | O14: 0 | P14: 0.82 | Q14: 4.92
A15: 45323.292 | B15: 20.78 | C15: 26.01 | D15: 31.6 | E15: 5.55 | F15: 3.32 | G15: 93.29 | H15: 39.74 | I15: 8.81 | J15: 0.23 | K15: 192.27 | L15: 18.06 | M15: 90.8 | N15: 6.1 | O15: 0 | P15: 0.88 | Q15: 4.93
A16: 45323.333 | B16: 22.03 | C16: 26.5 | D16: 32.86 | E16: 5.98 | F16: 3.3 | G16: 93.46 | H16: 44.01 | I16: 9.14 | J16: 0.39 | K16: 183.59 | L16: 19.46 | M16: 90.98 | N16: 69.5 | O16: 0 | P16: 0.93 | Q16: 4.94
A17: 45323.375 | B17: 22.14 | C17: 27.04 | D17: 32.89 | E17: 6.11 | F17: 3.34 | G17: 98.58 | H17: 44.62 | I17: 9.7 | J17: 0.34 | K17: 152.27 | L17: 22.85 | M17: 78.75 | N17: 187.1 | O17: 0 | P17: 0.94 | Q17: 4.92
A18: 45323.417 | B18: 18.52 | C18: 27.76 | D18: 30.42 | E18: 6.18 | F18: 3.8 | G18: 96.82 | H18: 44.35 | I18: 9.73 | J18: 0.39 | K18: 359.76 | L18: 25.35 | M18: 64.17 | N18: 270.2 | O18: 0 | P18: 0.94 | Q18: 4.88
A19: 45323.458 | B19: 15.94 | C19: 21.35 | D19: 25.29 | E19: 7.28 | F19: 3.91 | G19: 93.59 | H19: 41.47 | I19: 9.75 | J19: 1.1 | K19: 319.89 | L19: 26.37 | M19: 52.52 | N19: 377.1 | O19: 0 | P19: 0.96 | Q19: 4.82
A20: 45323.5 | B20: 13.3 | C20: 21.41 | D20: 23.21 | E20: 7.53 | F20: 4.03 | G20: 93.13 | H20: 40.57 | I20: 10.91 | J20: 0.93 | K20: 299 | L20: 27.25 | M20: 49.47 | N20: 436.7 | O20: 0 | P20: 0.98 | Q20: 4.83
... A32: 45324 | B32: 19.07 | C32: 22.42 | D32: 28.16 | E32: 6.79 | F32: 3.48 | G32: 100.59 | H32: 34.43 | I32: 9.98 | J32: 0.19 | K32: 229.5 | L32: 20.01 | M32: 85.4 | N32: 0 | O32: 0 | P32: 1.02 | Q32: 4.92
A34: Min | B34: =MIN(B9:B32) -> 4.79 | C34: =MIN(C9:C32) -> 19.26 | D34: =MIN(D9:D32) -> 15.24 | E34: =MIN(E9:E32) -> 5.25 | F34: =MIN(F9:F32) -> 3.3 | G34: =MIN(G9:G32) -> 63.82 | H34: =MIN(H9:H32) -> 29.5 | I34: =MIN(I9:I32) -> 8.04 | ... Q34: =MIN(Q9:Q32) -> 4.76
A35: Max | B35: =MAX(B9:B32) -> 22.14 | C35: =MAX(C9:C32) -> 28.94 | D35: =MAX(D9:D32) -> 32.89 | E35: =MAX(E9:E32) -> 7.76 | F35: =MAX(F9:F32) -> 6.99 | G35: =MAX(G9:G32) -> 103.42 | H35: =MAX(H9:H32) -> 44.62 | I35: =MAX(I9:I32) -> 11.83 | ... Q35: =MAX(Q9:Q32) -> 4.94
A36: Avg | B36: =AVERAGE(B9:B32) -> 13.175833 | C36: =AVERAGE(C9:C32) -> 23.275 | D36: =AVERAGE(D9:D32) -> 23.98125 | E36: =AVERAGE(E9:E32) -> 6.6325 | F36: =AVERAGE(F9:F32) -> 4.1170833 | G36: =AVERAGE(G9:G32) -> 86.69625 | H36: =AVERAGE(H9:H32) -> 36.977917 | I36: =AVERAGE(I9:I32) -> 9.6995833 | ... Q36: =AVERAGE(Q9:Q32) -> 4.8416667
A37: Stdev | B37: =STDEV(B9:B32) -> 5.9714458 | C37: =STDEV(C9:C32) -> 3.0823086 | D37: =STDEV(D9:D32) -> 5.9154193 | E37: =STDEV(E9:E32) -> 0.83594388 | F37: =STDEV(F9:F32) -> 1.0302067 | G37: =STDEV(G9:G32) -> 12.391712 | H37: =STDEV(H9:H32) -> 4.5825861 | I37: =STDEV(I9:I32) -> 1.1056986 | ... Q37: =STDEV(Q9:Q32) -> 0.061337744
A38: Num | B38: =COUNT(B9:B32) -> 24 | C38: =COUNT(C9:C32) -> 24 | D38: =COUNT(D9:D32) -> 24 | E38: =COUNT(E9:E32) -> 24 | F38: =COUNT(F9:F32) -> 24 | G38: =COUNT(G9:G32) -> 24 | H38: =COUNT(H9:H32) -> 24 | I38: =COUNT(I9:I32) -> 24 | ... Q38: =COUNT(Q9:Q32) -> 24
A39: DCR | B39: =IF(B38>=22,">90%",IF(B38<=22,"<90%")) -> >90% | C39: =IF(C38>=22,">90%",IF(C38<=22,"<90%")) -> >90% | D39: =IF(D38>=22,">90%",IF(D38<=22,"<90%")) -> >90% | E39: =IF(E38>=22,">90%",IF(E38<=22,"<90%")) -> >90% | F39: =IF(F38>=22,">90%",IF(F38<=22,"<90%")) -> >90% | G39: =IF(G38>=22,">90%",IF(G38<=22,"<90%")) -> >90% | H39: =IF(H38>=22,">90%",IF(H38<=22,"<90%")) -> >90% | I39: =IF(I38>=22,">90%",IF(I38<=22,"<90%")) -> >90% | ... Q39: =IF(Q38>=22,">90%",IF(Q38<=22,"<90%")) -> >90%
A40: Status | B40: =IF(B38>=22,"OK",IF(B38<=22,"LESS")) -> OK | C40: =IF(C38>=22,"OK",IF(C38<=22,"LESS")) -> OK | D40: =IF(D38>=22,"OK",IF(D38<=22,"LESS")) -> OK | E40: =IF(E38>=22,"OK",IF(E38<=22,"LESS")) -> OK | F40: =IF(F38>=22,"OK",IF(F38<=22,"LESS")) -> OK | G40: =IF(G38>=22,"OK",IF(G38<=22,"LESS")) -> OK | H40: =IF(H38>=22,"OK",IF(H38<=22,"LESS")) -> OK | I40: =IF(I38>=22,"OK",IF(I38<=22,"LESS")) -> OK | ... Q40: =IF(Q38>=22,"OK",IF(Q38<=22,"LESS")) -> OK
A43: Done by | B43: AKASH
A45: Comment

Sheet 02
A1: Station: | B1: IGKV ,RAIPUR
A2: Date: | B2: =$A$9 -> 45324.042 | D2: Power Off | G2: Pw.Off | L2: Link Fail | N2: Link F | P2: Maintenance | R2: Maint.
A3: Report Type: | B3: Mean | D3: Calibration | G3: Calib. | L3: Data Fail | N3: Data F | P3: Invalid | R3: Invalid
A4: Time Base: | B4: 01 Hour | D4: Zero Referrence | G4: Z.Ref | L4: Warm Up | N4: Wm. Up
A7: Date & Time | B7: NO | C7: NO2 | D7: NOX | E7: SO2 | F7: O3 | G7: PM 10 | H7: PM 2.5 | I7: BENZ | J7: WS | K7: WD | L7: TEMP | M7: HUM | N7: SR | O7: RG | P7: CO | Q7: NH3
B8: ug/m3 | C8: ug/m3 | D8: ppb | E8: ug/m3 | F8: ug/m3 | G8: ug/m3 | H8: ug/m3 | I8: ug/m3 | J8: m/sec | K8: deg | L8: degreC | M8: % | N8: w/m2 | O8: mm | P8: mg/m3 | Q8: ug/m3
A9: 45324.042 | B9: 19.28 | C9: 22.62 | D9: 27.98 | E9: 7.2 | F9: 3.34 | G9: 96.05 | H9: 37.08 | I9: 10.32 | J9: 0.15 | K9: 189 | L9: 19.76 | M9: 85.41 | N9: 0 | O9: 0 | P9: 1.03 | Q9: 4.93
A10: 45324.083 | B10: 23.98 | C10: 25.63 | D10: 33.97 | E10: 7.37 | F10: 3.36 | G10: 87.17 | H10: 35.43 | I10: 10.35 | J10: 0.53 | K10: 142.65 | L10: 20.16 | M10: 81.51 | N10: 0 | O10: 0 | P10: 1.05 | Q10: 4.95
A11: 45324.125 | B11: 25.19 | C11: 27.36 | D11: 35.85 | E11: 7.73 | F11: 3.31 | G11: 98.1 | H11: 38.61 | I11: 10.35 | J11: 0.23 | K11: 249.61 | L11: 20.09 | M11: 85.52 | N11: 0 | O11: 0 | P11: 1.05 | Q11: 4.98
A12: 45324.167 | B12: 26.23 | C12: 27.85 | D12: 36.94 | E12: 8.29 | F12: 3.34 | G12: 100.27 | H12: 37.76 | I12: 0 | J12: 0.15 | K12: 310.32 | L12: 19.42 | M12: 86.83 | N12: 0 | O12: 0 | P12: 1.04 | Q12: 4.96
A13: 45324.208 | B13: 31.21 | C13: 28.95 | D13: 41.51 | E13: 8.22 | F13: 3.36 | G13: 105.8 | H13: 40.01 | I13: 0 | J13: 0.36 | K13: 77.42 | L13: 20.19 | M13: 82.05 | N13: 0 | O13: 0 | P13: 1.04 | Q13: 4.96
A14: 45324.25 | B14: 32.02 | C14: 29.27 | D14: 42.09 | E14: 8.64 | F14: 3.53 | G14: 113.46 | H14: 41.18 | I14: 0 | J14: 0.17 | K14: 211 | L14: 19.94 | M14: 86.9 | N14: 0 | O14: 0 | P14: 1.05 | Q14: 4.96
A15: 45324.292 | B15: 31.24 | C15: 23.42 | D15: 37.37 | E15: 8.01 | F15: 3.56 | G15: 109.57 | H15: 40.51 | I15: 0 | J15: 0.35 | K15: 262.94 | L15: 20.14 | M15: 85.84 | N15: 0 | O15: 0 | P15: 1.01 | Q15: 4.96
A16: 45324.333 | B16: 31.99 | C16: 23.96 | D16: 37.93 | E16: 8.36 | F16: 3.6 | G16: 105.78 | H16: 42.27 | I16: 0 | J16: 0.76 | K16: 342.39 | L16: 20.65 | M16: 80.39 | N16: 56.8 | O16: 0 | P16: 1.03 | Q16: 4.98
A17: 45324.375 | B17: 33.37 | C17: 23.75 | D17: 40.52 | E17: 9.01 | F17: 3.57 | G17: 118.54 | H17: 46.29 | I17: 0 | J17: 1.3 | K17: 52.2 | L17: 22.19 | M17: 79.67 | N17: 218.6 | O17: 0 | P17: 1.09 | Q17: 5.04
A18: 45324.417 | B18: 32.79 | C18: 23.24 | D18: 38.93 | E18: 8.55 | F18: 3.63 | G18: 127.73 | H18: 47.71 | I18: 0 | J18: 1.17 | K18: 63.5 | L18: 24.96 | M18: 67.47 | N18: 286 | O18: 0 | P18: 1.08 | Q18: 5.03
A19: 45324.458 | B19: 27.72 | C19: 28.03 | D19: 36.7 | E19: 7.49 | F19: 3.75 | G19: 123.74 | H19: 49.22 | I19: 0 | J19: 0.74 | K19: 84.78 | L19: 26.72 | M19: 58.42 | N19: 420.1 | O19: 0 | P19: 1.07 | Q19: 5.04
A20: 45324.5 | B20: 17.32 | C20: 28.9 | D20: 30.29 | E20: 7.35 | F20: 4.56 | G20: 117.77 | H20: 45.43 | I20: 0 | J20: 0.42 | K20: 346.55 | L20: 28.08 | M20: 50.96 | N20: 453.3 | O20: 0 | P20: 1.03 | Q20: 4.94
... A32: 45325 | B32: 13.71 | C32: 25.87 | D32: 25.86 | E32: 9.06 | F32: 3.35 | G32: 66.68 | H32: 32.17 | I32: 0 | J32: 0.19 | K32: 212.94 | L32: 20.99 | M32: 86.79 | N32: 0 | O32: 0 | P32: 0.95 | Q32: 4.82
A34: Min | B34: =MIN(B9:B32) -> 4.58 | C34: =MIN(C9:C32) -> 15.79 | D34: =MIN(D9:D32) -> 13.5 | E34: =MIN(E9:E32) -> 5.83 | F34: =MIN(F9:F32) -> 3.31 | G34: =MIN(G9:G32) -> 63.98 | H34: =MIN(H9:H32) -> 32.17 | I34: =MIN(I9:I32) -> 0 | ... Q34: =MIN(Q9:Q32) -> 4.71
A35: Max | B35: =MAX(B9:B32) -> 33.37 | C35: =MAX(C9:C32) -> 29.27 | D35: =MAX(D9:D32) -> 42.09 | E35: =MAX(E9:E32) -> 9.06 | F35: =MAX(F9:F32) -> 5.85 | G35: =MAX(G9:G32) -> 127.73 | H35: =MAX(H9:H32) -> 49.22 | I35: =MAX(I9:I32) -> 10.35 | ... Q35: =MAX(Q9:Q32) -> 5.04
A36: Avg | B36: =AVERAGE(B9:B32) -> 17.160417 | C36: =AVERAGE(C9:C32) -> 23.8375 | D36: =AVERAGE(D9:D32) -> 27.285 | E36: =AVERAGE(E9:E32) -> 7.855 | F36: =AVERAGE(F9:F32) -> 3.9133333 | G36: =AVERAGE(G9:G32) -> 95.270833 | H36: =AVERAGE(H9:H32) -> 39.27875 | I36: =AVERAGE(I9:I32) -> 1.2925 | ... Q36: =AVERAGE(Q9:Q32) -> 4.88625
A37: Stdev | B37: =STDEV(B9:B32) -> 11.526523 | C37: =STDEV(C9:C32) -> 4.4781821 | D37: =STDEV(D9:D32) -> 10.389288 | E37: =STDEV(E9:E32) -> 0.80573488 | F37: =STDEV(F9:F32) -> 0.73879848 | G37: =STDEV(G9:G32) -> 18.928074 | H37: =STDEV(H9:H32) -> 4.513993 | I37: =STDEV(I9:I32) -> 3.4931862 | ... Q37: =STDEV(Q9:Q32) -> 0.1014166
A38: Num | B38: =COUNT(B9:B32) -> 24 | C38: =COUNT(C9:C32) -> 24 | D38: =COUNT(D9:D32) -> 24 | E38: =COUNT(E9:E32) -> 24 | F38: =COUNT(F9:F32) -> 24 | G38: =COUNT(G9:G32) -> 24 | H38: =COUNT(H9:H32) -> 24 | I38: =COUNT(I9:I32) -> 24 | ... Q38: =COUNT(Q9:Q32) -> 24
A39: DCR | B39: =IF(B38>=22,">90%",IF(B38<=22,"<90%")) -> >90% | C39: =IF(C38>=22,">90%",IF(C38<=22,"<90%")) -> >90% | D39: =IF(D38>=22,">90%",IF(D38<=22,"<90%")) -> >90% | E39: =IF(E38>=22,">90%",IF(E38<=22,"<90%")) -> >90% | F39: =IF(F38>=22,">90%",IF(F38<=22,"<90%")) -> >90% | G39: =IF(G38>=22,">90%",IF(G38<=22,"<90%")) -> >90% | H39: =IF(H38>=22,">90%",IF(H38<=22,"<90%")) -> >90% | I39: =IF(I38>=22,">90%",IF(I38<=22,"<90%")) -> >90% | ... Q39: =IF(Q38>=22,">90%",IF(Q38<=22,"<90%")) -> >90%
A40: Status | B40: =IF(B38>=22,"OK",IF(B38<=22,"LESS")) -> OK | C40: =IF(C38>=22,"OK",IF(C38<=22,"LESS")) -> OK | D40: =IF(D38>=22,"OK",IF(D38<=22,"LESS")) -> OK | E40: =IF(E38>=22,"OK",IF(E38<=22,"LESS")) -> OK | F40: =IF(F38>=22,"OK",IF(F38<=22,"LESS")) -> OK | G40: =IF(G38>=22,"OK",IF(G38<=22,"LESS")) -> OK | H40: =IF(H38>=22,"OK",IF(H38<=22,"LESS")) -> OK | I40: =IF(I38>=22,"OK",IF(I38<=22,"LESS")) -> OK | ... Q40: =IF(Q38>=22,"OK",IF(Q38<=22,"LESS")) -> OK
A43: Done by | B43: AKASH
A45: Comment

Sheet 03
A1: Station: | B1: IGKV ,RAIPUR
A2: Date: | B2: =$A$9 -> 45325.042 | D2: Power Off | G2: Pw.Off | L2: Link Fail | N2: Link F | P2: Maintenance | R2: Maint.
A3: Report Type: | B3: Mean | D3: Calibration | G3: Calib. | L3: Data Fail | N3: Data F | P3: Invalid | R3: Invalid
A4: Time Base: | B4: 01 Hour | D4: Zero Referrence | G4: Z.Ref | L4: Warm Up | N4: Wm. Up
A7: Date & Time | B7: NO | C7: NO2 | D7: NOX | E7: SO2 | F7: O3 | G7: PM 10 | H7: PM 2.5 | I7: BENZ | J7: WS | K7: WD | L7: TEMP | M7: HUM | N7: SR | O7: RG | P7: CO | Q7: NH3
B8: ug/m3 | C8: ug/m3 | D8: ppb | E8: ug/m3 | F8: ug/m3 | G8: ug/m3 | H8: ug/m3 | I8: ug/m3 | J8: m/sec | K8: deg | L8: degreC | M8: % | N8: w/m2 | O8: mm | P8: mg/m3 | Q8: ug/m3
A9: 45325.042 | B9: 19.14 | C9: 28.37 | D9: 31.52 | E9: 9.21 | F9: 3.27 | G9: 70.65 | H9: 33.46 | I9: 0 | J9: 0.21 | K9: 226.36 | L9: 20.34 | M9: 87.56 | N9: 0 | O9: 0 | P9: 1.04 | Q9: 4.84
A10: 45325.083 | B10: 23.22 | C10: 27.51 | D10: 33.1 | E10: 9.04 | F10: 3.57 | G10: 85.11 | H10: 35.99 | I10: 0 | J10: 0.79 | K10: 64.44 | L10: 20.99 | M10: 72.69 | N10: 0 | O10: 0 | P10: 1.06 | Q10: 4.87
A11: 45325.125 | B11: 22.5 | C11: 24.87 | D11: 31.95 | E11: 6.76 | F11: 3.33 | G11: 83.24 | H11: 35.43 | I11: 0 | J11: 0.65 | K11: 62.91 | L11: 20.22 | M11: 63.2 | N11: 0 | O11: 0 | P11: 1.02 | Q11: 4.89
A12: 45325.167 | B12: 21.59 | C12: 24.62 | D12: 31.53 | E12: 6.44 | F12: 3.52 | G12: 75.43 | H12: 31.56 | I12: 0 | J12: 0.41 | K12: 172.05 | L12: 19.28 | M12: 78.39 | N12: 0 | O12: 0 | P12: 0.97 | Q12: 4.91
A13: 45325.208 | B13: 20.26 | C13: 23.44 | D13: 29.85 | E13: 6.36 | F13: 3.41 | G13: 63.77 | H13: 29.68 | I13: 0 | J13: 0.4 | K13: 173.95 | L13: 17.14 | M13: 81.12 | N13: 0 | O13: 0 | P13: 0.86 | Q13: 4.94
A14: 45325.25 | B14: 27.73 | C14: 25.15 | D14: 36.73 | E14: 6.59 | F14: 3.32 | G14: 59.36 | H14: 27.5 | I14: 0 | J14: 0.44 | K14: 186.86 | L14: 17.48 | M14: 85.01 | N14: 0 | O14: 0 | P14: 0.81 | Q14: 5.03
A15: 45325.292 | B15: 29.43 | C15: 25.94 | D15: 38.5 | E15: 6.88 | F15: 3.33 | G15: 62.32 | H15: 26.94 | I15: 0 | J15: 0.57 | K15: 184.49 | L15: 16.7 | M15: 87.71 | N15: 5 | O15: 0 | P15: 0.76 | Q15: 5.05
A16: 45325.333 | B16: 34.53 | C16: 29.35 | D16: 44.37 | E16: 6.53 | F16: 3.36 | G16: 66.73 | H16: 27.33 | I16: 0 | J16: 0.69 | K16: 56.46 | L16: 18.47 | M16: 75.94 | N16: 53.9 | O16: 0 | P16: 0.82 | Q16: 5.06
A17: 45325.375 | B17: 34.99 | C17: 30.16 | D17: 45 | E17: 6.98 | F17: 3.39 | G17: 88.86 | H17: 32.17 | I17: 0 | J17: 1.08 | K17: 67.24 | L17: 21.76 | M17: 67.27 | N17: 286.4 | O17: 0 | P17: 0.84 | Q17: 5.08
A18: 45325.417 | B18: 30.81 | C18: 30.95 | D18: 41.98 | E18: 7.08 | F18: 3.58 | G18: 87.29 | H18: 30.79 | I18: 0 | J18: 0.85 | K18: 81.18 | L18: 24.92 | M18: 45.52 | N18: 361.4 | O18: 0 | P18: 0.83 | Q18: 5.04
A19: 45325.458 | B19: 23.53 | C19: 30.86 | D19: 36.34 | E19: 8.57 | F19: 3.86 | G19: 86.69 | H19: 31.45 | I19: 0 | J19: 0.97 | K19: 79.43 | L19: 26.76 | M19: 32.67 | N19: 563.7 | O19: 0 | P19: 0.78 | Q19: 4.95
A20: 45325.5 | B20: 17.14 | C20: 27.63 | D20: 29.53 | E20: 7.81 | F20: 4.32 | G20: 80.95 | H20: 28.2 | I20: 0 | J20: 1.05 | K20: 85.9 | L20: 27.84 | M20: 27.13 | N20: 612.7 | O20: 0 | P20: 0.74 | Q20: 4.89
... A32: 45326 | B32: 25.11 | C32: 24.77 | D32: 34.12 | E32: 7.18 | F32: 3.49 | G32: 112.68 | H32: 37.28 | I32: 0 | J32: 0.25 | K32: 226.81 | L32: 17.55 | M32: 79.83 | N32: 0 | O32: 0 | P32: 0.96 | Q32: 4.96
A34: Min | B34: =MIN(B9:B32) -> 6.55 | C34: =MIN(C9:C32) -> 20.21 | D34: =MIN(D9:D32) -> 17.85 | E34: =MIN(E9:E32) -> 6.36 | F34: =MIN(F9:F32) -> 3.24 | G34: =MIN(G9:G32) -> 57.28 | H34: =MIN(H9:H32) -> 21.12 | I34: =MIN(I9:I32) -> 0 | ... Q34: =MIN(Q9:Q32) -> 4.83
A35: Max | B35: =MAX(B9:B32) -> 34.99 | C35: =MAX(C9:C32) -> 30.95 | D35: =MAX(D9:D32) -> 45 | E35: =MAX(E9:E32) -> 9.21 | F35: =MAX(F9:F32) -> 6.15 | G35: =MAX(G9:G32) -> 112.68 | H35: =MAX(H9:H32) -> 37.28 | I35: =MAX(I9:I32) -> 0 | ... Q35: =MAX(Q9:Q32) -> 5.08
A36: Avg | B36: =AVERAGE(B9:B32) -> 19.6775 | C36: =AVERAGE(C9:C32) -> 25.900417 | D36: =AVERAGE(D9:D32) -> 30.532917 | E36: =AVERAGE(E9:E32) -> 7.4079167 | F36: =AVERAGE(F9:F32) -> 3.94125 | G36: =AVERAGE(G9:G32) -> 77.512083 | H36: =AVERAGE(H9:H32) -> 29.682917 | I36: =AVERAGE(I9:I32) -> 0 | ... Q36: =AVERAGE(Q9:Q32) -> 4.9320833
A37: Stdev | B37: =STDEV(B9:B32) -> 8.2595243 | C37: =STDEV(C9:C32) -> 3.0307518 | D37: =STDEV(D9:D32) -> 7.7210821 | E37: =STDEV(E9:E32) -> 0.89437848 | F37: =STDEV(F9:F32) -> 0.86803783 | G37: =STDEV(G9:G32) -> 16.339211 | H37: =STDEV(H9:H32) -> 4.7538456 | I37: =STDEV(I9:I32) -> 0 | ... Q37: =STDEV(Q9:Q32) -> 0.074248652
A38: Num | B38: =COUNT(B9:B32) -> 24 | C38: =COUNT(C9:C32) -> 24 | D38: =COUNT(D9:D32) -> 24 | E38: =COUNT(E9:E32) -> 24 | F38: =COUNT(F9:F32) -> 24 | G38: =COUNT(G9:G32) -> 24 | H38: =COUNT(H9:H32) -> 24 | I38: =COUNT(I9:I32) -> 24 | ... Q38: =COUNT(Q9:Q32) -> 24
A39: DCR | B39: =IF(B38>=22,">90%",IF(B38<=22,"<90%")) -> >90% | C39: =IF(C38>=22,">90%",IF(C38<=22,"<90%")) -> >90% | D39: =IF(D38>=22,">90%",IF(D38<=22,"<90%")) -> >90% | E39: =IF(E38>=22,">90%",IF(E38<=22,"<90%")) -> >90% | F39: =IF(F38>=22,">90%",IF(F38<=22,"<90%")) -> >90% | G39: =IF(G38>=22,">90%",IF(G38<=22,"<90%")) -> >90% | H39: =IF(H38>=22,">90%",IF(H38<=22,"<90%")) -> >90% | I39: =IF(I38>=22,">90%",IF(I38<=22,"<90%")) -> >90% | ... Q39: =IF(Q38>=22,">90%",IF(Q38<=22,"<90%")) -> >90%
A40: Status | B40: =IF(B38>=22,"OK",IF(B38<=22,"LESS")) -> OK | C40: =IF(C38>=22,"OK",IF(C38<=22,"LESS")) -> OK | D40: =IF(D38>=22,"OK",IF(D38<=22,"LESS")) -> OK | E40: =IF(E38>=22,"OK",IF(E38<=22,"LESS")) -> OK | F40: =IF(F38>=22,"OK",IF(F38<=22,"LESS")) -> OK | G40: =IF(G38>=22,"OK",IF(G38<=22,"LESS")) -> OK | H40: =IF(H38>=22,"OK",IF(H38<=22,"LESS")) -> OK | I40: =IF(I38>=22,"OK",IF(I38<=22,"LESS")) -> OK | ... Q40: =IF(Q38>=22,"OK",IF(Q38<=22,"LESS")) -> OK
A43: Done by | B43: AKASH
A45: Comment

Sheet 04
A1: Station: | B1: IGKV ,RAIPUR
A2: Date: | B2: =$A$9 -> 45326.042 | D2: Power Off | G2: Pw.Off | L2: Link Fail | N2: Link F | P2: Maintenance | R2: Maint.
A3: Report Type: | B3: Mean | D3: Calibration | G3: Calib. | L3: Data Fail | N3: Data F | P3: Invalid | R3: Invalid
A4: Time Base: | B4: 01 Hour | D4: Zero Referrence | G4: Z.Ref | L4: Warm Up | N4: Wm. Up
A7: Date & Time | B7: NO | C7: NO2 | D7: NOX | E7: SO2 | F7: O3 | G7: PM 10 | H7: PM 2.5 | I7: BENZ | J7: WS | K7: WD | L7: TEMP | M7: HUM | N7: SR | O7: RG | P7: CO | Q7: NH3
B8: ug/m3 | C8: ug/m3 | D8: ppb | E8: ug/m3 | F8: ug/m3 | G8: ug/m3 | H8: ug/m3 | I8: ug/m3 | J8: m/sec | K8: deg | L8: degreC | M8: % | N8: w/m2 | O8: mm | P8: mg/m3 | Q8: ug/m3
A9: 45326.042 | B9: 27.07 | C9: 25.08 | D9: 36.16 | E9: 7.31 | F9: 3.34 | G9: 112.88 | H9: 36.84 | I9: 0 | J9: 0.17 | K9: 193.48 | L9: 17.14 | M9: 81.55 | N9: 0 | O9: 0 | P9: 0.97 | Q9: 4.97
A10: 45326.083 | B10: 36.87 | C10: 27.44 | D10: 45.26 | E10: 7.47 | F10: 3.32 | G10: 109.56 | H10: 35.85 | I10: 0 | J10: 0.22 | K10: 191.84 | L10: 16.92 | M10: 84.13 | N10: 0 | O10: 0 | P10: 0.99 | Q10: 5.1
A11: 45326.125 | B11: 40.4 | C11: 27.63 | D11: 48.19 | E11: 7.92 | F11: 3.42 | G11: 104.07 | H11: 36.1 | I11: 0 | J11: 0.18 | K11: 197.37 | L11: 16.08 | M11: 82.44 | N11: 0 | O11: 0 | P11: 1 | Q11: 5.11
A12: 45326.167 | B12: 56.21 | C12: 29 | D12: 61.52 | E12: 8.43 | F12: 3.42 | G12: 101.79 | H12: 35.63 | I12: 0 | J12: 0.2 | K12: 207.91 | L12: 16.21 | M12: 88.18 | N12: 0 | O12: 0 | P12: 1.03 | Q12: 5.22
A13: 45326.208 | B13: 57.04 | C13: 28.66 | D13: 62.06 | E13: 8.17 | F13: 3.33 | G13: 101.5 | H13: 38.63 | I13: 0 | J13: 0.22 | K13: 255.29 | L13: 15.39 | M13: 87.35 | N13: 0 | O13: 0 | P13: 1.05 | Q13: 5.26
A14: 45326.25 | B14: 55.5 | C14: 28.54 | D14: 60.76 | E14: 8.31 | F14: 3.26 | G14: 98.73 | H14: 37.03 | I14: 0 | J14: 0.18 | K14: 255.72 | L14: 14.96 | M14: 87.65 | N14: 0 | O14: 0 | P14: 1.04 | Q14: 5.21
A15: 45326.292 | B15: 51.21 | C15: 27.2 | D15: 56.63 | E15: 8.44 | F15: 3.43 | G15: 94.07 | H15: 34.85 | I15: 0 | J15: 0.2 | K15: 216.2 | L15: 14.96 | M15: 91.49 | N15: 5.4 | O15: 0 | P15: 1.04 | Q15: 5.2
A16: 45326.333 | B16: 49.19 | C16: 25.85 | D16: 54.3 | E16: 8.04 | F16: 3.52 | G16: 91.49 | H16: 34.25 | I16: 0 | J16: 0.7 | K16: 268.77 | L16: 17.43 | M16: 91.4 | N16: 46.6 | O16: 0 | P16: 1.03 | Q16: 5.16
A17: 45326.375 | B17: 51.05 | C17: 28.8 | D17: 57.34 | E17: 8.61 | F17: 3.44 | G17: 105.91 | H17: 41.33 | I17: 0 | J17: 0.63 | K17: 87.76 | L17: 22.45 | M17: 68.67 | N17: 295.5 | O17: 0 | P17: 1.11 | Q17: 5.15
A18: 45326.417 | B18: 47.14 | C18: 26.24 | D18: 52.86 | E18: 8.45 | F18: 3.56 | G18: 110.4 | H18: 42.12 | I18: 0 | J18: 0.41 | K18: 291.03 | L18: 25.68 | M18: 43.46 | N18: 375.8 | O18: 0 | P18: 1.11 | Q18: 5.15
A19: 45326.458 | B19: 38.43 | C19: 26.81 | D19: 46.18 | E19: 7.76 | F19: 3.69 | G19: 102.07 | H19: 40.67 | I19: 0 | J19: 0.67 | K19: 184.83 | L19: 27.67 | M19: 36.38 | N19: 565.8 | O19: 0 | P19: 1.07 | Q19: 5.08
A20: 45326.5 | B20: 28.17 | C20: 27.06 | D20: 36.81 | E20: 7.63 | F20: 4.87 | G20: 87.5 | H20: 36.9 | I20: 0 | J20: 0.46 | K20: 131.14 | L20: 29.28 | M20: 28.74 | N20: 623.9 | O20: 0 | P20: 0.97 | Q20: 5.01
... A32: 45327 | B32: 7.08 | C32: 21.22 | D32: 18.12 | E32: 10.33 | F32: 3.5 | G32: 51.27 | H32: 20.8 | I32: 0 | J32: 0.17 | K32: 222.91 | L32: 19.04 | M32: 73.89 | N32: 0 | O32: 0 | P32: 0.74 | Q32: 4.8
A34: Min | B34: =MIN(B9:B32) -> 3.86 | C34: =MIN(C9:C32) -> 15.15 | D34: =MIN(D9:D32) -> 12.97 | E34: =MIN(E9:E32) -> 6.49 | F34: =MIN(F9:F32) -> 3.26 | G34: =MIN(G9:G32) -> 26.66 | H34: =MIN(H9:H32) -> 13.72 | I34: =MIN(I9:I32) -> 0 | ... Q34: =MIN(Q9:Q32) -> 4.73
A35: Max | B35: =MAX(B9:B32) -> 57.04 | C35: =MAX(C9:C32) -> 29 | D35: =MAX(D9:D32) -> 62.06 | E35: =MAX(E9:E32) -> 10.33 | F35: =MAX(F9:F32) -> 8.52 | G35: =MAX(G9:G32) -> 112.88 | H35: =MAX(H9:H32) -> 42.12 | I35: =MAX(I9:I32) -> 0 | ... Q35: =MAX(Q9:Q32) -> 5.26
A36: Avg | B36: =AVERAGE(B9:B32) -> 25.5975 | C36: =AVERAGE(C9:C32) -> 23.696667 | D36: =AVERAGE(D9:D32) -> 34.178333 | E36: =AVERAGE(E9:E32) -> 8.2070833 | F36: =AVERAGE(F9:F32) -> 4.37375 | G36: =AVERAGE(G9:G32) -> 71.978333 | H36: =AVERAGE(H9:H32) -> 28.180417 | I36: =AVERAGE(I9:I32) -> 0 | ... Q36: =AVERAGE(Q9:Q32) -> 4.96
A37: Stdev | B37: =STDEV(B9:B32) -> 21.064925 | C37: =STDEV(C9:C32) -> 4.5780978 | D37: =STDEV(D9:D32) -> 18.959107 | E37: =STDEV(E9:E32) -> 1.1107204 | F37: =STDEV(F9:F32) -> 1.6527522 | G37: =STDEV(G9:G32) -> 32.016929 | H37: =STDEV(H9:H32) -> 10.160657 | I37: =STDEV(I9:I32) -> 0 | ... Q37: =STDEV(Q9:Q32) -> 0.1911976
A38: Num | B38: =COUNT(B9:B32) -> 24 | C38: =COUNT(C9:C32) -> 24 | D38: =COUNT(D9:D32) -> 24 | E38: =COUNT(E9:E32) -> 24 | F38: =COUNT(F9:F32) -> 24 | G38: =COUNT(G9:G32) -> 24 | H38: =COUNT(H9:H32) -> 24 | I38: =COUNT(I9:I32) -> 24 | ... Q38: =COUNT(Q9:Q32) -> 24
A39: DCR | B39: =IF(B38>=22,">90%",IF(B38<=22,"<90%")) -> >90% | C39: =IF(C38>=22,">90%",IF(C38<=22,"<90%")) -> >90% | D39: =IF(D38>=22,">90%",IF(D38<=22,"<90%")) -> >90% | E39: =IF(E38>=22,">90%",IF(E38<=22,"<90%")) -> >90% | F39: =IF(F38>=22,">90%",IF(F38<=22,"<90%")) -> >90% | G39: =IF(G38>=22,">90%",IF(G38<=22,"<90%")) -> >90% | H39: =IF(H38>=22,">90%",IF(H38<=22,"<90%")) -> >90% | I39: =IF(I38>=22,">90%",IF(I38<=22,"<90%")) -> >90% | ... Q39: =IF(Q38>=22,">90%",IF(Q38<=22,"<90%")) -> >90%
A40: Status | B40: =IF(B38>=22,"OK",IF(B38<=22,"LESS")) -> OK | C40: =IF(C38>=22,"OK",IF(C38<=22,"LESS")) -> OK | D40: =IF(D38>=22,"OK",IF(D38<=22,"LESS")) -> OK | E40: =IF(E38>=22,"OK",IF(E38<=22,"LESS")) -> OK | F40: =IF(F38>=22,"OK",IF(F38<=22,"LESS")) -> OK | G40: =IF(G38>=22,"OK",IF(G38<=22,"LESS")) -> OK | H40: =IF(H38>=22,"OK",IF(H38<=22,"LESS")) -> OK | I40: =IF(I38>=22,"OK",IF(I38<=22,"LESS")) -> OK | ... Q40: =IF(Q38>=22,"OK",IF(Q38<=22,"LESS")) -> OK
A43: Done by | B43: AKASH
A45: Comment

Sheet 05
A1: Station: | B1: IGKV ,RAIPUR
A2: Date: | B2: =$A$9 -> 45327.042 | D2: Power Off | G2: Pw.Off | L2: Link Fail | N2: Link F | P2: Maintenance | R2: Maint.
A3: Report Type: | B3: Mean | D3: Calibration | G3: Calib. | L3: Data Fail | N3: Data F | P3: Invalid | R3: Invalid
A4: Time Base: | B4: 01 Hour | D4: Zero Referrence | G4: Z.Ref | L4: Warm Up | N4: Wm. Up
A7: Date & Time | B7: NO | C7: NO2 | D7: NOX | E7: SO2 | F7: O3 | G7: PM 10 | H7: PM 2.5 | I7: BENZ | J7: WS | K7: WD | L7: TEMP | M7: HUM | N7: SR | O7: RG | P7: CO | Q7: NH3
B8: ug/m3 | C8: ug/m3 | D8: ppb | E8: ug/m3 | F8: ug/m3 | G8: ug/m3 | H8: ug/m3 | I8: ug/m3 | J8: m/sec | K8: deg | L8: degreC | M8: % | N8: w/m2 | O8: mm | P8: mg/m3 | Q8: ug/m3
A9: 45327.042 | B9: 7.41 | C9: 21.55 | D9: 18.55 | E9: 10.35 | F9: 3.39 | G9: 50.51 | H9: 22.16 | I9: 0 | J9: 0.17 | K9: 198.94 | L9: 18.57 | M9: 76.66 | N9: 0 | O9: 0 | P9: 0.76 | Q9: 4.79
A10: 45327.083 | B10: 7.43 | C10: 21.64 | D10: 18.58 | E10: 10.69 | F10: 3.46 | G10: 48.24 | H10: 22.4 | I10: 0 | J10: 0.09 | K10: 216.46 | L10: 18.42 | M10: 71.04 | N10: 0 | O10: 0 | P10: 0.77 | Q10: 4.79
A11: 45327.125 | B11: 7.04 | C11: 21.45 | D11: 18.11 | E11: 6.2 | F11: 3.75 | G11: 48.33 | H11: 22.06 | I11: 0 | J11: 0.19 | K11: 234.4 | L11: 18.18 | M11: 76.66 | N11: 0 | O11: 0 | P11: 0.75 | Q11: 4.77
A12: 45327.167 | B12: 8.44 | C12: 19.16 | D12: 18.13 | E12: 5.8 | F12: 3.52 | G12: 44.74 | H12: 18.44 | I12: 0 | J12: 0.16 | K12: 164.64 | L12: 17.59 | M12: 79.46 | N12: 0 | O12: 0 | P12: 0.72 | Q12: 4.76
A13: 45327.208 | B13: 14.29 | C13: 21.54 | D13: 24.06 | E13: 6.1 | F13: 3.37 | G13: 45.51 | H13: 21.4 | I13: 0 | J13: 0.18 | K13: 195.35 | L13: 17.47 | M13: 82.91 | N13: 0 | O13: 0 | P13: 0.72 | Q13: 4.82
A14: 45327.25 | B14: 16.12 | C14: 21.51 | D14: 25.29 | E14: 6.14 | F14: 3.4 | G14: 54.57 | H14: 22.24 | I14: 0 | J14: 0.43 | K14: 188.69 | L14: 16.68 | M14: 87.48 | N14: 0 | O14: 0 | P14: 0.72 | Q14: 4.86
A15: 45327.292 | B15: 16.22 | C15: 21.36 | D15: 25.48 | E15: 5.92 | F15: 3.43 | G15: 52.2 | H15: 20.78 | I15: 0 | J15: 0.22 | K15: 253.13 | L15: 16.14 | M15: 88.23 | N15: 5.9 | O15: 0 | P15: 0.71 | Q15: 4.86
A16: 45327.333 | B16: 15.66 | C16: 21.61 | D16: 24.65 | E16: 6.47 | F16: 3.5 | G16: 57.6 | H16: 23.95 | I16: 0 | J16: 0.19 | K16: 290.83 | L16: 19.08 | M16: 86.38 | N16: 49.8 | O16: 0 | P16: 0.71 | Q16: 4.86
A17: 45327.375 | B17: 13.61 | C17: 22.25 | D17: 23.7 | E17: 6.41 | F17: 3.5 | G17: 58.39 | H17: 25.36 | I17: 0 | J17: 0.47 | K17: 290.22 | L17: 23.29 | M17: 68.23 | N17: 292.9 | O17: 0 | P17: 0.73 | Q17: 4.83
A18: 45327.417 | B18: 10 | C18: 22.44 | D18: 21.1 | E18: 6.84 | F18: 4.02 | G18: 52.65 | H18: 22.27 | I18: 0 | J18: 0.72 | K18: 284.08 | L18: 26.27 | M18: 50.98 | N18: 368.1 | O18: 0 | P18: 0.69 | Q18: 4.81
A19: 45327.458 | B19: 6.79 | C19: 23.02 | D19: 18.39 | E19: 7.38 | F19: 4.39 | G19: 46.92 | H19: 20.83 | I19: 0 | J19: 1.08 | K19: 304.67 | L19: 28.23 | M19: 48.92 | N19: 528 | O19: 0 | P19: 0.66 | Q19: 4.77
A20: 45327.5 | B20: 5.18 | C20: 22.96 | D20: 17.5 | E20: 8.03 | F20: 6.25 | G20: 49.89 | H20: 22.51 | I20: 0 | J20: 1.18 | K20: 290.46 | L20: 29.83 | M20: 45.69 | N20: 583.7 | O20: 0 | P20: 0.68 | Q20: 4.76
... A32: 45328 | B32: 7.92 | C32: 16.86 | D32: 16.51 | E32: 6.14 | F32: 3.71 | G32: 78.05 | H32: 31.31 | I32: 0 | J32: 0.16 | K32: 174.85 | L32: 21.75 | M32: 80.63 | N32: 0 | O32: 0 | P32: 0.87 | Q32: 4.71
A34: Min | B34: =MIN(B9:B32) -> 3.79 | C34: =MIN(C9:C32) -> 13.06 | D34: =MIN(D9:D32) -> 11.24 | E34: =MIN(E9:E32) -> 5.8 | F34: =MIN(F9:F32) -> 3.37 | G34: =MIN(G9:G32) -> 44.74 | H34: =MIN(H9:H32) -> 17.8 | I34: =MIN(I9:I32) -> 0 | ... Q34: =MIN(Q9:Q32) -> 4.7
A35: Max | B35: =MAX(B9:B32) -> 16.22 | C35: =MAX(C9:C32) -> 23.02 | D35: =MAX(D9:D32) -> 25.48 | E35: =MAX(E9:E32) -> 10.76 | F35: =MAX(F9:F32) -> 13.45 | G35: =MAX(G9:G32) -> 78.05 | H35: =MAX(H9:H32) -> 31.31 | I35: =MAX(I9:I32) -> 0 | ... Q35: =MAX(Q9:Q32) -> 4.86
A36: Avg | B36: =AVERAGE(B9:B32) -> 7.89375 | C36: =AVERAGE(C9:C32) -> 19.8875 | D36: =AVERAGE(D9:D32) -> 17.97625 | E36: =AVERAGE(E9:E32) -> 7.34125 | F36: =AVERAGE(F9:F32) -> 5.1029167 | G36: =AVERAGE(G9:G32) -> 55.8725 | H36: =AVERAGE(H9:H32) -> 23.194167 | I36: =AVERAGE(I9:I32) -> 0 | ... Q36: =AVERAGE(Q9:Q32) -> 4.7691667
A37: Stdev | B37: =STDEV(B9:B32) -> 4.1703089 | C37: =STDEV(C9:C32) -> 2.8249652 | D37: =STDEV(D9:D32) -> 4.2127878 | E37: =STDEV(E9:E32) -> 1.508853 | F37: =STDEV(F9:F32) -> 2.5048396 | G37: =STDEV(G9:G32) -> 10.711339 | H37: =STDEV(H9:H32) -> 3.4852433 | I37: =STDEV(I9:I32) -> 0 | ... Q37: =STDEV(Q9:Q32) -> 0.050812243
A38: Num | B38: =COUNT(B9:B32) -> 24 | C38: =COUNT(C9:C32) -> 24 | D38: =COUNT(D9:D32) -> 24 | E38: =COUNT(E9:E32) -> 24 | F38: =COUNT(F9:F32) -> 24 | G38: =COUNT(G9:G32) -> 24 | H38: =COUNT(H9:H32) -> 24 | I38: =COUNT(I9:I32) -> 24 | ... Q38: =COUNT(Q9:Q32) -> 24
A39: DCR | B39: =IF(B38>=22,">90%",IF(B38<=22,"<90%")) -> >90% | C39: =IF(C38>=22,">90%",IF(C38<=22,"<90%")) -> >90% | D39: =IF(D38>=22,">90%",IF(D38<=22,"<90%")) -> >90% | E39: =IF(E38>=22,">90%",IF(E38<=22,"<90%")) -> >90% | F39: =IF(F38>=22,">90%",IF(F38<=22,"<90%")) -> >90% | G39: =IF(G38>=22,">90%",IF(G38<=22,"<90%")) -> >90% | H39: =IF(H38>=22,">90%",IF(H38<=22,"<90%")) -> >90% | I39: =IF(I38>=22,">90%",IF(I38<=22,"<90%")) -> >90% | ... Q39: =IF(Q38>=22,">90%",IF(Q38<=22,"<90%")) -> >90%
A40: Status | B40: =IF(B38>=22,"OK",IF(B38<=22,"LESS")) -> OK | C40: =IF(C38>=22,"OK",IF(C38<=22,"LESS")) -> OK | D40: =IF(D38>=22,"OK",IF(D38<=22,"LESS")) -> OK | E40: =IF(E38>=22,"OK",IF(E38<=22,"LESS")) -> OK | F40: =IF(F38>=22,"OK",IF(F38<=22,"LESS")) -> OK | G40: =IF(G38>=22,"OK",IF(G38<=22,"LESS")) -> OK | H40: =IF(H38>=22,"OK",IF(H38<=22,"LESS")) -> OK | I40: =IF(I38>=22,"OK",IF(I38<=22,"LESS")) -> OK | ... Q40: =IF(Q38>=22,"OK",IF(Q38<=22,"LESS")) -> OK
A43: Done by | B43: AKASH
A45: Comment

Sheet 06
A1: Station: | B1: IGKV ,RAIPUR
A2: Date: | B2: =$A$9 -> 45328.042 | D2: Power Off | G2: Pw.Off | L2: Link Fail | N2: Link F | P2: Maintenance | R2: Maint.
A3: Report Type: | B3: Mean | D3: Calibration | G3: Calib. | L3: Data Fail | N3: Data F | P3: Invalid | R3: Invalid
A4: Time Base: | B4: 01 Hour | D4: Zero Referrence | G4: Z.Ref | L4: Warm Up | N4: Wm. Up
A7: Date & Time | B7: NO | C7: NO2 | D7: NOX | E7: SO2 | F7: O3 | G7: PM 10 | H7: PM 2.5 | I7: BENZ | J7: WS | K7: WD | L7: TEMP | M7: HUM | N7: SR | O7: RG | P7: CO | Q7: NH3
B8: ug/m3 | C8: ug/m3 | D8: ppb | E8: ug/m3 | F8: ug/m3 | G8: ug/m3 | H8: ug/m3 | I8: ug/m3 | J8: m/sec | K8: deg | L8: degreC | M8: % | N8: w/m2 | O8: mm | P8: mg/m3 | Q8: ug/m3
A9: 45328.042 | B9: 9.51 | C9: 18.51 | D9: 18.01 | E9: 6.51 | F9: 3.5 | G9: 74.89 | H9: 31.34 | I9: 0 | J9: 0.13 | K9: 179.39 | L9: 21.51 | M9: 83.01 | N9: 0 | O9: 0 | P9: 0.86 | Q9: 4.75
A10: 45328.083 | B10: 9.97 | C10: 17.17 | D10: 18.14 | E10: 6.24 | F10: 3.65 | G10: 67.51 | H10: 29.88 | I10: 0 | J10: 0.11 | K10: 200.41 | L10: 21.29 | M10: 81.85 | N10: 0 | O10: 0 | P10: 0.84 | Q10: 4.76
A11: 45328.125 | B11: 10.13 | C11: 16.94 | D11: 18.33 | E11: 7.7 | F11: 3.43 | G11: 54.9 | H11: 28.43 | I11: 0 | J11: 0.14 | K11: 168.65 | L11: 21.16 | M11: 83.99 | N11: 0 | O11: 0 | P11: 0.81 | Q11: 4.76
A12: 45328.167 | B12: 9.97 | C12: 18.01 | D12: 18.42 | E12: 8.09 | F12: 3.42 | G12: 45.96 | H12: 25.27 | I12: 0 | J12: 0.15 | K12: 181.8 | L12: 20.78 | M12: 84.64 | N12: 0 | O12: 0 | P12: 0.78 | Q12: 4.77
A13: 45328.208 | B13: 11.07 | C13: 20.58 | D13: 20.98 | E13: 8.47 | F13: 3.33 | G13: 42.53 | H13: 24.2 | I13: 0 | J13: 0.22 | K13: 163.49 | L13: 20.66 | M13: 83.6 | N13: 0 | O13: 0 | P13: 0.76 | Q13: 4.75
A14: 45328.25 | B14: 16.42 | C14: 23.81 | D14: 26.96 | E14: 8.48 | F14: 3.23 | G14: 45.41 | H14: 23.27 | I14: 0 | J14: 0.35 | K14: 175.51 | L14: 20.65 | M14: 85.27 | N14: 0 | O14: 0 | P14: 0.74 | Q14: 4.8
A15: 45328.292 | B15: 17.35 | C15: 24.14 | D15: 27.83 | E15: 9 | F15: 3.23 | G15: 49.31 | H15: 25.98 | I15: 0 | J15: 0.25 | K15: 208.01 | L15: 20.02 | M15: 91.3 | N15: 5.5 | O15: 0 | P15: 0.73 | Q15: 4.82
A16: 45328.333 | B16: 17.26 | C16: 24.11 | D16: 27.76 | E16: 8.89 | F16: 3.43 | G16: 55.08 | H16: 26.28 | I16: 0 | J16: 0.39 | K16: 178.69 | L16: 21.29 | M16: 90.1 | N16: 59.3 | O16: 0 | P16: 0.73 | Q16: 4.82
A17: 45328.375 | B17: 17.27 | C17: 23.13 | D17: 27.03 | E17: 8.64 | F17: 3.78 | G17: 59.07 | H17: 28.43 | I17: 0 | J17: 0.82 | K17: 286.05 | L17: 25.36 | M17: 80.39 | N17: 219.3 | O17: 0 | P17: 0.77 | Q17: 4.78
A18: 45328.417 | B18: 16.56 | C18: 18.67 | D18: 24.34 | E18: 8.37 | F18: 3.8 | G18: 68.55 | H18: 28.08 | I18: 0 | J18: 1.01 | K18: 281.43 | L18: 27.02 | M18: 63.96 | N18: 293.9 | O18: 0 | P18: 0.78 | Q18: 4.79
A19: 45328.458 | B19: 13.57 | C19: 16.78 | D19: 21 | E19: 7.65 | F19: 4.64 | G19: 61.38 | H19: 27.82 | I19: 0 | J19: 1.07 | K19: 275.19 | L19: 29.17 | M19: 60.22 | N19: 482.2 | O19: 0 | P19: 0.75 | Q19: 4.77
A20: 45328.5 | B20: 9.81 | C20: 15.64 | D20: 17.39 | E20: 8.09 | F20: 6.02 | G20: 54.3 | H20: 26.31 | I20: 0 | J20: 1.34 | K20: 279.14 | L20: 30.44 | M20: 55.52 | N20: 529.4 | O20: 0 | P20: 0.69 | Q20: 4.74
... A32: 45329 | B32: 21.14 | C32: 22.9 | D32: 29.54 | E32: 6.58 | F32: 3.52 | G32: 105.74 | H32: 36.54 | I32: 0 | J32: 1.05 | K32: 56.7 | L32: 23.25 | M32: 67.55 | N32: 0 | O32: 0 | P32: 0.89 | Q32: 4.94
A34: Min | B34: =MIN(B9:B32) -> 5.11 | C34: =MIN(C9:C32) -> 14.88 | D34: =MIN(D9:D32) -> 13.82 | E34: =MIN(E9:E32) -> 5.97 | F34: =MIN(F9:F32) -> 3.23 | G34: =MIN(G9:G32) -> 42.53 | H34: =MIN(H9:H32) -> 20.78 | I34: =MIN(I9:I32) -> 0 | ... Q34: =MIN(Q9:Q32) -> 4.68
A35: Max | B35: =MAX(B9:B32) -> 21.2 | C35: =MAX(C9:C32) -> 24.14 | D35: =MAX(D9:D32) -> 29.54 | E35: =MAX(E9:E32) -> 10.86 | F35: =MAX(F9:F32) -> 12.06 | G35: =MAX(G9:G32) -> 111.73 | H35: =MAX(H9:H32) -> 37.22 | I35: =MAX(I9:I32) -> 0 | ... Q35: =MAX(Q9:Q32) -> 4.94
A36: Avg | B36: =AVERAGE(B9:B32) -> 11.987917 | C36: =AVERAGE(C9:C32) -> 19.100833 | D36: =AVERAGE(D9:D32) -> 20.805417 | E36: =AVERAGE(E9:E32) -> 8.10125 | F36: =AVERAGE(F9:F32) -> 5.3441667 | G36: =AVERAGE(G9:G32) -> 63.7075 | H36: =AVERAGE(H9:H32) -> 27.4325 | I36: =AVERAGE(I9:I32) -> 0 | ... Q36: =AVERAGE(Q9:Q32) -> 4.7795833
A37: Stdev | B37: =STDEV(B9:B32) -> 5.289245 | C37: =STDEV(C9:C32) -> 2.9115242 | D37: =STDEV(D9:D32) -> 5.2946815 | E37: =STDEV(E9:E32) -> 1.4235086 | F37: =STDEV(F9:F32) -> 2.8848403 | G37: =STDEV(G9:G32) -> 19.494117 | H37: =STDEV(H9:H32) -> 4.435217 | I37: =STDEV(I9:I32) -> 0 | ... Q37: =STDEV(Q9:Q32) -> 0.06570548
A38: Num | B38: =COUNT(B9:B32) -> 24 | C38: =COUNT(C9:C32) -> 24 | D38: =COUNT(D9:D32) -> 24 | E38: =COUNT(E9:E32) -> 24 | F38: =COUNT(F9:F32) -> 24 | G38: =COUNT(G9:G32) -> 24 | H38: =COUNT(H9:H32) -> 24 | I38: =COUNT(I9:I32) -> 24 | ... Q38: =COUNT(Q9:Q32) -> 24
A39: DCR | B39: =IF(B38>=22,">90%",IF(B38<=22,"<90%")) -> >90% | C39: =IF(C38>=22,">90%",IF(C38<=22,"<90%")) -> >90% | D39: =IF(D38>=22,">90%",IF(D38<=22,"<90%")) -> >90% | E39: =IF(E38>=22,">90%",IF(E38<=22,"<90%")) -> >90% | F39: =IF(F38>=22,">90%",IF(F38<=22,"<90%")) -> >90% | G39: =IF(G38>=22,">90%",IF(G38<=22,"<90%")) -> >90% | H39: =IF(H38>=22,">90%",IF(H38<=22,"<90%")) -> >90% | I39: =IF(I38>=22,">90%",IF(I38<=22,"<90%")) -> >90% | ... Q39: =IF(Q38>=22,">90%",IF(Q38<=22,"<90%")) -> >90%
A40: Status | B40: =IF(B38>=22,"OK",IF(B38<=22,"LESS")) -> OK | C40: =IF(C38>=22,"OK",IF(C38<=22,"LESS")) -> OK | D40: =IF(D38>=22,"OK",IF(D38<=22,"LESS")) -> OK | E40: =IF(E38>=22,"OK",IF(E38<=22,"LESS")) -> OK | F40: =IF(F38>=22,"OK",IF(F38<=22,"LESS")) -> OK | G40: =IF(G38>=22,"OK",IF(G38<=22,"LESS")) -> OK | H40: =IF(H38>=22,"OK",IF(H38<=22,"LESS")) -> OK | I40: =IF(I38>=22,"OK",IF(I38<=22,"LESS")) -> OK | ... Q40: =IF(Q38>=22,"OK",IF(Q38<=22,"LESS")) -> OK
A43: Done by | B43: AKASH
A45: Comment

Sheet 07
A1: Station: | B1: IGKV ,RAIPUR
A2: Date: | B2: =$A$9 -> 45329.042 | D2: Power Off | G2: Pw.Off | L2: Link Fail | N2: Link F | P2: Maintenance | R2: Maint.
A3: Report Type: | B3: Mean | D3: Calibration | G3: Calib. | L3: Data Fail | N3: Data F | P3: Invalid | R3: Invalid
A4: Time Base: | B4: 01 Hour | D4: Zero Referrence | G4: Z.Ref | L4: Warm Up | N4: Wm. Up
A7: Date & Time | B7: NO | C7: NO2 | D7: NOX | E7: SO2 | F7: O3 | G7: PM 10 | H7: PM 2.5 | I7: BENZ | J7: WS | K7: WD | L7: TEMP | M7: HUM | N7: SR | O7: RG | P7: CO | Q7: NH3
B8: ug/m3 | C8: ug/m3 | D8: ppb | E8: ug/m3 | F8: ug/m3 | G8: ug/m3 | H8: ug/m3 | I8: ug/m3 | J8: m/sec | K8: deg | L8: degreC | M8: % | N8: w/m2 | O8: mm | P8: mg/m3 | Q8: ug/m3
A9: 45329.042 | B9: 17.2 | C9: 24.15 | D9: 27.47 | E9: 6.92 | F9: 3.53 | G9: 91.55 | H9: 33.06 | I9: 0 | J9: 1.26 | K9: 56.95 | L9: 22.22 | M9: 71.71 | N9: 0 | O9: 0 | P9: 0.83 | Q9: 4.91
A10: 45329.083 | B10: 15.1 | C10: 24.29 | D10: 26.15 | E10: 6.32 | F10: 3.39 | G10: 74.86 | H10: 30.84 | I10: 0 | J10: 1.29 | K10: 59.74 | L10: 21.38 | M10: 74.58 | N10: 0 | O10: 0 | P10: 0.76 | Q10: 4.89
A11: 45329.125 | B11: 12.7 | C11: 24.34 | D11: 24.25 | E11: 6.55 | F11: 3.45 | G11: 62.47 | H11: 30.75 | I11: 0 | J11: 0.43 | K11: 161.95 | L11: 20.79 | M11: 77.23 | N11: 0 | O11: 0 | P11: 0.71 | Q11: 4.82
A12: 45329.167 | B12: 12.26 | C12: 24.62 | D12: 24.04 | E12: 6.8 | F12: 3.4 | G12: 60.75 | H12: 28.9 | I12: 0 | J12: 1.04 | K12: 70.43 | L12: 20.38 | M12: 79.2 | N12: 0 | O12: 0 | P12: 0.67 | Q12: 4.79
A13: 45329.208 | B13: 13.6 | C13: 22.96 | D13: 23.39 | E13: 6.52 | F13: 3.63 | G13: 63.92 | H13: 29.24 | I13: 0 | J13: 1.29 | K13: 63.67 | L13: 20.26 | M13: 78.66 | N13: 0 | O13: 0 | P13: 0.65 | Q13: 4.77
A14: 45329.25 | B14: 14.75 | C14: 20.06 | D14: 23.32 | E14: 6.27 | F14: 3.51 | G14: 62.2 | H14: 29.56 | I14: 0 | J14: 1.23 | K14: 62.12 | L14: 19.71 | M14: 81.77 | N14: 0 | O14: 0 | P14: 0.61 | Q14: 4.79
A15: 45329.292 | B15: 16.25 | C15: 19.12 | D15: 24.37 | E15: 6.17 | F15: 3.62 | G15: 60.4 | H15: 29.29 | I15: 0 | J15: 1.13 | K15: 64.96 | L15: 19.38 | M15: 81.64 | N15: 3.7 | O15: 0 | P15: 0.58 | Q15: 4.85
A16: 45329.333 | B16: 18.68 | C16: 19.28 | D16: 25.72 | E16: 6.09 | F16: 3.39 | G16: 66.6 | H16: 28.29 | I16: 0 | J16: 1.18 | K16: 83.78 | L16: 20.25 | M16: 81.72 | N16: 67.7 | O16: 0 | P16: 0.59 | Q16: 4.9
A17: 45329.375 | B17: 19.38 | C17: 20.77 | D17: 27.73 | E17: 6.35 | F17: 3.35 | G17: 66.95 | H17: 28.26 | I17: 0 | J17: 1.05 | K17: 82.19 | L17: 22.08 | M17: 76.23 | N17: 218.3 | O17: 0 | P17: 0.6 | Q17: 4.92
A18: 45329.417 | B18: 19.49 | C18: 23.04 | D18: 28.93 | E18: 7.22 | F18: 3.45 | G18: 64.59 | H18: 29.11 | I18: 0 | J18: 0.94 | K18: 74 | L18: 24.25 | M18: 67.98 | N18: 303.1 | O18: 0 | P18: 0.6 | Q18: 4.91
A19: 45329.458 | B19: 19.12 | C19: 24.39 | D19: 28.98 | E19: 8.72 | F19: 3.59 | G19: 71.21 | H19: 30.06 | I19: 0 | J19: 0.68 | K19: 61.81 | L19: 25.83 | M19: 59.88 | N19: 402.7 | O19: 0 | P19: 0.62 | Q19: 4.91
A20: 45329.5 | B20: 17.56 | C20: 25.41 | D20: 28.35 | E20: 8.75 | F20: 4.25 | G20: 72.44 | H20: 30.97 | I20: 0 | J20: 1.02 | K20: 358.21 | L20: 27.28 | M20: 52.22 | N20: 526.3 | O20: 0 | P20: 0.61 | Q20: 4.85
... A32: 45330 | B32: 12.84 | C32: 26.7 | D32: 25.6 | E32: 10.36 | F32: 3.7 | G32: 100.58 | H32: 39.54 | I32: 0 | J32: 1.75 | K32: 52.71 | L32: 22.61 | M32: 55.31 | N32: 0 | O32: 0 | P32: 1.07 | Q32: 4.81
A34: Min | B34: =MIN(B9:B32) -> 4.36 | C34: =MIN(C9:C32) -> 13.44 | D34: =MIN(D9:D32) -> 11.81 | E34: =MIN(E9:E32) -> 6.09 | F34: =MIN(F9:F32) -> 3.35 | G34: =MIN(G9:G32) -> 60.4 | H34: =MIN(H9:H32) -> 28.26 | I34: =MIN(I9:I32) -> 0 | ... Q34: =MIN(Q9:Q32) -> 4.73
A35: Max | B35: =MAX(B9:B32) -> 19.49 | C35: =MAX(C9:C32) -> 26.94 | D35: =MAX(D9:D32) -> 28.98 | E35: =MAX(E9:E32) -> 10.36 | F35: =MAX(F9:F32) -> 9.19 | G35: =MAX(G9:G32) -> 100.58 | H35: =MAX(H9:H32) -> 39.59 | I35: =MAX(I9:I32) -> 0 | ... Q35: =MAX(Q9:Q32) -> 4.92
A36: Avg | B36: =AVERAGE(B9:B32) -> 11.99125 | C36: =AVERAGE(C9:C32) -> 21.472917 | D36: =AVERAGE(D9:D32) -> 22.045417 | E36: =AVERAGE(E9:E32) -> 8.0795833 | F36: =AVERAGE(F9:F32) -> 4.5166667 | G36: =AVERAGE(G9:G32) -> 71.849583 | H36: =AVERAGE(H9:H32) -> 31.254167 | I36: =AVERAGE(I9:I32) -> 0 | ... Q36: =AVERAGE(Q9:Q32) -> 4.8204167
A37: Stdev | B37: =STDEV(B9:B32) -> 5.4756618 | C37: =STDEV(C9:C32) -> 3.993677 | D37: =STDEV(D9:D32) -> 5.8128276 | E37: =STDEV(E9:E32) -> 1.5584175 | F37: =STDEV(F9:F32) -> 1.6634136 | G37: =STDEV(G9:G32) -> 10.492677 | H37: =STDEV(H9:H32) -> 3.2497758 | I37: =STDEV(I9:I32) -> 0 | ... Q37: =STDEV(Q9:Q32) -> 0.057971445
A38: Num | B38: =COUNT(B9:B32) -> 24 | C38: =COUNT(C9:C32) -> 24 | D38: =COUNT(D9:D32) -> 24 | E38: =COUNT(E9:E32) -> 24 | F38: =COUNT(F9:F32) -> 24 | G38: =COUNT(G9:G32) -> 24 | H38: =COUNT(H9:H32) -> 24 | I38: =COUNT(I9:I32) -> 24 | ... Q38: =COUNT(Q9:Q32) -> 24
A39: DCR | B39: =IF(B38>=22,">90%",IF(B38<=22,"<90%")) -> >90% | C39: =IF(C38>=22,">90%",IF(C38<=22,"<90%")) -> >90% | D39: =IF(D38>=22,">90%",IF(D38<=22,"<90%")) -> >90% | E39: =IF(E38>=22,">90%",IF(E38<=22,"<90%")) -> >90% | F39: =IF(F38>=22,">90%",IF(F38<=22,"<90%")) -> >90% | G39: =IF(G38>=22,">90%",IF(G38<=22,"<90%")) -> >90% | H39: =IF(H38>=22,">90%",IF(H38<=22,"<90%")) -> >90% | I39: =IF(I38>=22,">90%",IF(I38<=22,"<90%")) -> >90% | ... Q39: =IF(Q38>=22,">90%",IF(Q38<=22,"<90%")) -> >90%
A40: Status | B40: =IF(B38>=22,"OK",IF(B38<=22,"LESS")) -> OK | C40: =IF(C38>=22,"OK",IF(C38<=22,"LESS")) -> OK | D40: =IF(D38>=22,"OK",IF(D38<=22,"LESS")) -> OK | E40: =IF(E38>=22,"OK",IF(E38<=22,"LESS")) -> OK | F40: =IF(F38>=22,"OK",IF(F38<=22,"LESS")) -> OK | G40: =IF(G38>=22,"OK",IF(G38<=22,"LESS")) -> OK | H40: =IF(H38>=22,"OK",IF(H38<=22,"LESS")) -> OK | I40: =IF(I38>=22,"OK",IF(I38<=22,"LESS")) -> OK | ... Q40: =IF(Q38>=22,"OK",IF(Q38<=22,"LESS")) -> OK
A43: Done by | B43: AKASH
A45: Comment

Sheet 08
A1: Station: | B1: IGKV ,RAIPUR
A2: Date: | B2: =$A$9 -> 45330.042 | D2: Power Off | G2: Pw.Off | L2: Link Fail | N2: Link F | P2: Maintenance | R2: Maint.
A3: Report Type: | B3: Mean | D3: Calibration | G3: Calib. | L3: Data Fail | N3: Data F | P3: Invalid | R3: Invalid
A4: Time Base: | B4: 01 Hour | D4: Zero Referrence | G4: Z.Ref | L4: Warm Up | N4: Wm. Up
A7: Date & Time | B7: NO | C7: NO2 | D7: NOX | E7: SO2 | F7: O3 | G7: PM 10 | H7: PM 2.5 | I7: BENZ | J7: WS | K7: WD | L7: TEMP | M7: HUM | N7: SR | O7: RG | P7: CO | Q7: NH3
B8: ug/m3 | C8: ug/m3 | D8: ppb | E8: ug/m3 | F8: ug/m3 | G8: ug/m3 | H8: ug/m3 | I8: ug/m3 | J8: m/sec | K8: deg | L8: degreC | M8: % | N8: w/m2 | O8: mm | P8: mg/m3 | Q8: ug/m3
A9: 45330.042 | B9: 11.7 | C9: 20.67 | D9: 21.48 | E9: 9.29 | F9: 3.82 | G9: 90.4 | H9: 32.04 | I9: 0 | J9: 1.41 | K9: 55.38 | L9: 21.44 | M9: 47.78 | N9: 0 | O9: 0 | P9: 0.95 | Q9: 4.76
A10: 45330.083 | B10: 11.61 | C10: 21.27 | D10: 21.6 | E10: 9.15 | F10: 3.5 | G10: 71.4 | H10: 25.87 | I10: 0 | J10: 0.97 | K10: 49.22 | L10: 20.6 | M10: 48.08 | N10: 0 | O10: 0 | P10: 0.87 | Q10: 4.79
A11: 45330.125 | B11: 11.99 | C11: 20.13 | D11: 21.49 | E11: 6.36 | F11: 3.46 | G11: 57.93 | H11: 23.68 | I11: 0 | J11: 0.57 | K11: 41.91 | L11: 19.79 | M11: 48.96 | N11: 0 | O11: 0 | P11: 0.77 | Q11: 4.84
A12: 45330.167 | B12: 12.04 | C12: 20.85 | D12: 21.9 | E12: 6.06 | F12: 3.48 | G12: 47.62 | H12: 17.12 | I12: 0 | J12: 1.16 | K12: 62.66 | L12: 19.28 | M12: 49.38 | N12: 0 | O12: 0 | P12: 0.73 | Q12: 4.85
A13: 45330.208 | B13: 11.97 | C13: 19.97 | D13: 20.76 | E13: 5.71 | F13: 3.66 | G13: 42.7 | H13: 17.35 | I13: 0 | J13: 1.44 | K13: 58.52 | L13: 19 | M13: 46.99 | N13: 0 | O13: 0 | P13: 0.65 | Q13: 4.86
A14: 45330.25 | B14: 10.01 | C14: 20.9 | D14: 20 | E14: 5.73 | F14: 3.93 | G14: 39.66 | H14: 16.57 | I14: 0 | J14: 1.34 | K14: 56.27 | L14: 18.75 | M14: 48.78 | N14: 0 | O14: 0 | P14: 0.59 | Q14: 4.84
A15: 45330.292 | B15: 8.87 | C15: 21.53 | D15: 19.53 | E15: 5.21 | F15: 3.9 | G15: 36.49 | H15: 14.36 | I15: 0 | J15: 1.7 | K15: 50.48 | L15: 18.19 | M15: 49.21 | N15: 7.2 | O15: 0 | P15: 0.56 | Q15: 4.83
A16: 45330.333 | B16: 8.92 | C16: 22.54 | D16: 20.28 | E16: 5.51 | F16: 3.98 | G16: 42.89 | H16: 12.98 | I16: 0 | J16: 1.48 | K16: 43.76 | L16: 18.69 | M16: 49.84 | N16: 61.6 | O16: 0 | P16: 0.55 | Q16: 4.82
A17: 45330.375 | B17: 8.38 | C17: 22.62 | D17: 19.89 | E17: 5.54 | F17: 4.27 | G17: 46.38 | H17: 16.58 | I17: 0 | J17: 1.75 | K17: 49.16 | L17: 21.09 | M17: 40.15 | N17: 286.3 | O17: 0 | P17: 0.55 | Q17: 4.83
A18: 45330.417 | B18: 7.48 | C18: 22.69 | D18: 19.2 | E18: 5.3 | F18: 4.55 | G18: 44.95 | H18: 15.25 | I18: 0 | J18: 2.29 | K18: 57.92 | L18: 22.81 | M18: 26.39 | N18: 368.9 | O18: 0 | P18: 0.54 | Q18: 4.8
A19: 45330.458 | B19: 6.65 | C19: 20.01 | D19: 17.13 | E19: 7.09 | F19: 5.08 | G19: 44.64 | H19: 14.06 | I19: 0 | J19: 1.9 | K19: 46.05 | L19: 23.87 | M19: 21 | N19: 552.3 | O19: 0 | P19: 0.53 | Q19: 4.77
A20: 45330.5 | B20: 6.7 | C20: 19.04 | D20: 16.55 | E20: 7.53 | F20: 4.86 | G20: 43.77 | H20: 14.45 | I20: 0 | J20: 1.66 | K20: 54.39 | L20: 25.2 | M20: 24.33 | N20: 619.9 | O20: 0 | P20: 0.51 | Q20: 4.79
... A22: 45330.583 | B22: 5.78 | C22: 18.29 | D22: 15.54 | E22: 10.62 | F22: 10.07 | G22: 52.76 | H22: 15.06 | I22: 8.49 | J22: 1.64 | K22: 53.05 | L22: 26.48 | M22: 24.48 | N22: 561.8 | O22: 0 | P22: 0.49 | Q22: 4.81
A23: 45330.625 | B23: Calib. | C23: Calib. | D23: Calib. | E23: Calib. | F23: 10.1 | G23: Calib. | H23: Calib. | I23: 8.49 | J23: 1.21 | K23: 346.48 | L23: 26.64 | M23: 25.53 | N23: 489.4 | O23: 0 | P23: 0.44 | Q23: 4.8
A24: 45330.667 | B24: 6.73 | C24: 22.92 | D24: 18.36 | E24: 16.25 | F24: 10.26 | G24: 27.9 | H24: 1.13 | I24: 71 | J24: 0.98 | K24: 344.64 | L24: 26.01 | M24: 27.25 | N24: 93.3 | O24: 0 | P24: 0.43 | Q24: 4.82
A25: 45330.708 | B25: 8.83 | C25: 34.02 | D25: 26.21 | E25: 14.5 | F25: 14.56 | G25: 41.35 | H25: 3.24 | I25: 41.98 | J25: 1.11 | K25: 52.04 | L25: 25.69 | M25: 28.99 | N25: 66.1 | O25: 0 | P25: 0.45 | Q25: 4.82
A26: 45330.75 | B26: 8.81 | C26: 33.36 | D26: 25.27 | E26: 9.03 | F26: 6.52 | G26: 61.07 | H26: 11.23 | I26: 26.46 | J26: 0.64 | K26: 73.15 | L26: 25.24 | M26: 34.19 | N26: 19.7 | O26: 0 | P26: 0.53 | Q26: 4.84
A27: 45330.792 | B27: 10.01 | C27: 31.61 | D27: 25.45 | E27: 5.61 | F27: 3.86 | G27: 73.29 | H27: 18.69 | I27: 20.45 | J27: 0.32 | K27: 183.27 | L27: 22.9 | M27: 54.29 | N27: 0 | O27: 0 | P27: 0.59 | Q27: 4.83
A28: 45330.833 | B28: 10.7 | C28: 28.38 | D28: 24.25 | E28: 4.88 | F28: 3.74 | G28: 80.32 | H28: 24.46 | I28: 17.83 | J28: 0.22 | K28: 177.7 | L28: 20.9 | M28: 60.45 | N28: 0 | O28: 0 | P28: 0.64 | Q28: 4.82
A29: 45330.875 | B29: 12.86 | C29: 24.37 | D29: 24.4 | E29: 4.6 | F29: 3.7 | G29: 88.27 | H29: 25.81 | I29: 16.48 | J29: 0.26 | K29: 198.77 | L29: 19.65 | M29: 67.26 | N29: 0 | O29: 0 | P29: 0.7 | Q29: 4.78
A30: 45330.917 | B30: 13.41 | C30: 24.75 | D30: 24.74 | E30: 4.65 | F30: 3.53 | G30: 91.13 | H30: 27.54 | I30: 15.45 | J30: 0.22 | K30: 235.58 | L30: 18.11 | M30: 72.49 | N30: 0 | O30: 0 | P30: 0.73 | Q30: 4.82
A31: 45330.958 | B31: 14.35 | C31: 22.72 | D31: 24.73 | E31: 5.35 | F31: 3.31 | G31: 92.28 | H31: 28.31 | I31: 14.35 | J31: 0.23 | K31: 182.67 | L31: 17.59 | M31: 70.98 | N31: 0 | O31: 0 | P31: 0.79 | Q31: 4.81
A32: 45331 | B32: 27.76 | C32: 24.44 | D32: 36.38 | E32: 5.65 | F32: 3.61 | G32: 113.16 | H32: 38.27 | I32: 13.53 | J32: 0.6 | K32: 103.91 | L32: 18.52 | M32: 63.71 | N32: 0 | O32: 0 | P32: 0.88 | Q32: 4.89
A34: Min | B34: =MIN(B9:B32) -> 5.78 | C34: =MIN(C9:C32) -> 18.29 | D34: =MIN(D9:D32) -> 15.54 | E34: =MIN(E9:E32) -> 4.6 | F34: =MIN(F9:F32) -> 3.31 | G34: =MIN(G9:G32) -> 27.9 | H34: =MIN(H9:H32) -> 1.13 | I34: =MIN(I9:I32) -> 0 | ... Q34: =MIN(Q9:Q32) -> 4.76
A35: Max | B35: =MAX(B9:B32) -> 27.76 | C35: =MAX(C9:C32) -> 34.02 | D35: =MAX(D9:D32) -> 36.38 | E35: =MAX(E9:E32) -> 16.25 | F35: =MAX(F9:F32) -> 14.56 | G35: =MAX(G9:G32) -> 113.16 | H35: =MAX(H9:H32) -> 38.27 | I35: =MAX(I9:I32) -> 71 | ... Q35: =MAX(Q9:Q32) -> 4.89
A36: Avg | B36: =AVERAGE(B9:B32) -> 10.527391 | C36: =AVERAGE(C9:C32) -> 23.288696 | D36: =AVERAGE(D9:D32) -> 21.802174 | E36: =AVERAGE(E9:E32) -> 7.293913 | F36: =AVERAGE(F9:F32) -> 5.3008333 | G36: =AVERAGE(G9:G32) -> 60.196957 | H36: =AVERAGE(H9:H32) -> 18.759565 | I36: =AVERAGE(I9:I32) -> 10.604583 | ... Q36: =AVERAGE(Q9:Q32) -> 4.8175
A37: Stdev | B37: =STDEV(B9:B32) -> 4.483846 | C37: =STDEV(C9:C32) -> 4.4773768 | D37: =STDEV(D9:D32) -> 4.4739295 | E37: =STDEV(E9:E32) -> 3.0583429 | F37: =STDEV(F9:F32) -> 2.9261815 | G37: =STDEV(G9:G32) -> 22.735803 | H37: =STDEV(H9:H32) -> 8.5973037 | I37: =STDEV(I9:I32) -> 16.919281 | ... Q37: =STDEV(Q9:Q32) -> 0.029229229
A38: Num | B38: 24 | C38: 24 | D38: 24 | E38: 24 | F38: 24 | G38: 24 | H38: 24 | I38: 24 | J38: =COUNT(J9:J32) -> 24 | K38: =COUNT(K9:K32) -> 24 | L38: =COUNT(L9:L32) -> 24 | M38: =COUNT(M9:M32) -> 24 | N38: =COUNT(N9:N32) -> 24 | O38: =COUNT(O9:O32) -> 24 | P38: =COUNT(P9:P32) -> 24 | Q38: =COUNT(Q9:Q32) -> 24
A39: DCR | B39: =IF(B38>=22,">90%",IF(B38<=22,"<90%")) -> >90% | C39: =IF(C38>=22,">90%",IF(C38<=22,"<90%")) -> >90% | D39: =IF(D38>=22,">90%",IF(D38<=22,"<90%")) -> >90% | E39: =IF(E38>=22,">90%",IF(E38<=22,"<90%")) -> >90% | F39: =IF(F38>=22,">90%",IF(F38<=22,"<90%")) -> >90% | G39: =IF(G38>=22,">90%",IF(G38<=22,"<90%")) -> >90% | H39: =IF(H38>=22,">90%",IF(H38<=22,"<90%")) -> >90% | I39: =IF(I38>=22,">90%",IF(I38<=22,"<90%")) -> >90% | ... Q39: =IF(Q38>=22,">90%",IF(Q38<=22,"<90%")) -> >90%
A40: Status | B40: =IF(B38>=22,"OK",IF(B38<=22,"LESS")) -> OK | C40: =IF(C38>=22,"OK",IF(C38<=22,"LESS")) -> OK | D40: =IF(D38>=22,"OK",IF(D38<=22,"LESS")) -> OK | E40: =IF(E38>=22,"OK",IF(E38<=22,"LESS")) -> OK | F40: =IF(F38>=22,"OK",IF(F38<=22,"LESS")) -> OK | G40: =IF(G38>=22,"OK",IF(G38<=22,"LESS")) -> OK | H40: =IF(H38>=22,"OK",IF(H38<=22,"LESS")) -> OK | I40: =IF(I38>=22,"OK",IF(I38<=22,"LESS")) -> OK | ... Q40: =IF(Q38>=22,"OK",IF(Q38<=22,"LESS")) -> OK
A43: Done by | B43: AKASH
A45: Comment

Sheet 09
A1: Station: | B1: IGKV ,RAIPUR
A2: Date: | B2: =$A$9 -> 45331.042 | D2: Power Off | G2: Pw.Off | L2: Link Fail | N2: Link F | P2: Maintenance | R2: Maint.
A3: Report Type: | B3: Mean | D3: Calibration | G3: Calib. | L3: Data Fail | N3: Data F | P3: Invalid | R3: Invalid
A4: Time Base: | B4: 01 Hour | D4: Zero Referrence | G4: Z.Ref | L4: Warm Up | N4: Wm. Up
A7: Date & Time | B7: NO | C7: NO2 | D7: NOX | E7: SO2 | F7: O3 | G7: PM 10 | H7: PM 2.5 | I7: BENZ | J7: WS | K7: WD | L7: TEMP | M7: HUM | N7: SR | O7: RG | P7: CO | Q7: NH3
B8: ug/m3 | C8: ug/m3 | D8: ppb | E8: ug/m3 | F8: ug/m3 | G8: ug/m3 | H8: ug/m3 | I8: ug/m3 | J8: m/sec | K8: deg | L8: degreC | M8: % | N8: w/m2 | O8: mm | P8: mg/m3 | Q8: ug/m3
A9: 45331.042 | B9: 30.16 | C9: 27.64 | D9: 39.98 | E9: 6.68 | F9: 3.4 | G9: 126.74 | H9: 39.94 | I9: 13.44 | J9: 0.66 | K9: 54.65 | L9: 18.32 | M9: 61.05 | N9: 0 | O9: 0 | P9: 0.93 | Q9: 4.99
A10: 45331.083 | B10: 30.06 | C10: 28.11 | D10: 40.03 | E10: 6.48 | F10: 3.49 | G10: 126.74 | H10: 39.94 | I10: 13.16 | J10: 0.78 | K10: 57.83 | L10: 17.88 | M10: 61.37 | N10: 0 | O10: 0 | P10: 0.9 | Q10: 4.98
A11: 45331.125 | B11: 27.45 | C11: 28.14 | D11: 38.06 | E11: 9.86 | F11: 3.57 | G11: 107.04 | H11: 36.84 | I11: 11.99 | J11: 0.63 | K11: 50.65 | L11: 17.17 | M11: 59.73 | N11: 0 | O11: 0 | P11: 0.85 | Q11: 4.97
A12: 45331.167 | B12: 24.41 | C12: 28.05 | D12: 35.58 | E12: 8.52 | F12: 3.56 | G12: 88.55 | H12: 34.13 | I12: 10.77 | J12: 0.56 | K12: 66.26 | L12: 16.5 | M12: 63.39 | N12: 0 | O12: 0 | P12: 0.79 | Q12: 4.93
A13: 45331.208 | B13: 22.86 | C13: 27.18 | D13: 33.88 | E13: 8.51 | F13: 3.5 | G13: 69.69 | H13: 31 | I13: 9.91 | J13: 0.64 | K13: 65.27 | L13: 15.52 | M13: 64.42 | N13: 0 | O13: 0 | P13: 0.74 | Q13: 4.91
A14: 45331.25 | B14: 22.74 | C14: 26.86 | D14: 33.52 | E14: 8.59 | F14: 3.56 | G14: 65.5 | H14: 28.69 | I14: 9.35 | J14: 0.54 | K14: 125.52 | L14: 15.07 | M14: 66.35 | N14: 0 | O14: 0 | P14: 0.71 | Q14: 4.9
A15: 45331.292 | B15: 23.12 | C15: 26.77 | D15: 33.88 | E15: 8.57 | F15: 3.33 | G15: 65.5 | H15: 27.4 | I15: 8.88 | J15: 0.77 | K15: 63.92 | L15: 14.55 | M15: 62.46 | N15: 7.4 | O15: 0 | P15: 0.68 | Q15: 4.89
A16: 45331.333 | B16: 23.42 | C16: 27.33 | D16: 34.31 | E16: 8.77 | F16: 3.52 | G16: 72.22 | H16: 26.2 | I16: 8.58 | J16: 1 | K16: 75.25 | L16: 16.25 | M16: 57.32 | N16: 47.8 | O16: 0 | P16: 0.67 | Q16: 4.92
A17: 45331.375 | B17: 20.87 | C17: 27.21 | D17: 31.49 | E17: 8.6 | F17: 3.61 | G17: 72.22 | H17: 26.2 | I17: 8.5 | J17: 0.96 | K17: 89.51 | L17: 19.64 | M17: 44.64 | N17: 340.1 | O17: 0 | P17: 0.66 | Q17: 4.88
A18: 45331.417 | B18: 18.76 | C18: 26.97 | D18: 30.1 | E18: 8.2 | F18: 3.74 | G18: 71.16 | H18: 24.35 | I18: 8.11 | J18: 2.01 | K18: 73.37 | L18: 21.9 | M18: 31.53 | N18: 419.9 | O18: 0 | P18: 0.62 | Q18: 4.88
A19: 45331.458 | B19: 15.37 | C19: 25.91 | D19: 27.12 | E19: 9.5 | F19: 4.57 | G19: 74.32 | H19: 22.83 | I19: 7.51 | J19: 2.38 | K19: 64.13 | L19: 23.48 | M19: 24.93 | N19: 590.2 | O19: 0 | P19: 0.6 | Q19: 4.87
A20: 45331.5 | B20: 10.76 | C20: 25.82 | D20: 23.47 | E20: 9.98 | F20: 4.81 | G20: 76.03 | H20: 23.31 | I20: 6.83 | J20: 2.13 | K20: 64.28 | L20: 25.8 | M20: 22.55 | N20: 641.5 | O20: 0 | P20: 0.57 | Q20: 4.81
... A32: 45332 | B32: 23.52 | C32: 32.43 | D32: 37.16 | E32: 8.7 | F32: 3.4 | G32: 104.9 | H32: 34.58 | I32: 0 | J32: 0.31 | K32: 258.4 | L32: 17.58 | M32: 65.52 | N32: 0 | O32: 0 | P32: 0.8 | Q32: 4.94
A34: Min | B34: =MIN(B9:B32) -> 6.33 | C34: =MIN(C9:C32) -> 19.22 | D34: =MIN(D9:D32) -> 16.46 | E34: =MIN(E9:E32) -> 6.48 | F34: =MIN(F9:F32) -> 3.33 | G34: =MIN(G9:G32) -> 44.9 | H34: =MIN(H9:H32) -> 17.65 | I34: =MIN(I9:I32) -> 0 | ... Q34: =MIN(Q9:Q32) -> 4.73
A35: Max | B35: =MAX(B9:B32) -> 30.16 | C35: =MAX(C9:C32) -> 32.43 | D35: =MAX(D9:D32) -> 40.03 | E35: =MAX(E9:E32) -> 10.81 | F35: =MAX(F9:F32) -> 6.6 | G35: =MAX(G9:G32) -> 126.74 | H35: =MAX(H9:H32) -> 39.94 | I35: =MAX(I9:I32) -> 13.44 | ... Q35: =MAX(Q9:Q32) -> 4.99
A36: Avg | B36: =AVERAGE(B9:B32) -> 17.104167 | C36: =AVERAGE(C9:C32) -> 25.851667 | D36: =AVERAGE(D9:D32) -> 28.47875 | E36: =AVERAGE(E9:E32) -> 8.6475 | F36: =AVERAGE(F9:F32) -> 4.1708333 | G36: =AVERAGE(G9:G32) -> 81.582083 | H36: =AVERAGE(H9:H32) -> 27.767083 | I36: =AVERAGE(I9:I32) -> 4.87625 | ... Q36: =AVERAGE(Q9:Q32) -> 4.85875
A37: Stdev | B37: =STDEV(B9:B32) -> 7.7663169 | C37: =STDEV(C9:C32) -> 3.353028 | D37: =STDEV(D9:D32) -> 7.6546572 | E37: =STDEV(E9:E32) -> 1.0576933 | F37: =STDEV(F9:F32) -> 1.0898261 | G37: =STDEV(G9:G32) -> 22.893254 | H37: =STDEV(H9:H32) -> 6.6250634 | I37: =STDEV(I9:I32) -> 5.200657 | ... Q37: =STDEV(Q9:Q32) -> 0.07963572
A38: Num | B38: =COUNT(B9:B32) -> 24 | C38: =COUNT(C9:C32) -> 24 | D38: =COUNT(D9:D32) -> 24 | E38: =COUNT(E9:E32) -> 24 | F38: =COUNT(F9:F32) -> 24 | G38: =COUNT(G9:G32) -> 24 | H38: =COUNT(H9:H32) -> 24 | I38: =COUNT(I9:I32) -> 24 | ... Q38: =COUNT(Q9:Q32) -> 24
A39: DCR | B39: =IF(B38>=22,">90%",IF(B38<=22,"<90%")) -> >90% | C39: =IF(C38>=22,">90%",IF(C38<=22,"<90%")) -> >90% | D39: =IF(D38>=22,">90%",IF(D38<=22,"<90%")) -> >90% | E39: =IF(E38>=22,">90%",IF(E38<=22,"<90%")) -> >90% | F39: =IF(F38>=22,">90%",IF(F38<=22,"<90%")) -> >90% | G39: =IF(G38>=22,">90%",IF(G38<=22,"<90%")) -> >90% | H39: =IF(H38>=22,">90%",IF(H38<=22,"<90%")) -> >90% | I39: =IF(I38>=22,">90%",IF(I38<=22,"<90%")) -> >90% | ... Q39: =IF(Q38>=22,">90%",IF(Q38<=22,"<90%")) -> >90%
A40: Status | B40: =IF(B38>=22,"OK",IF(B38<=22,"LESS")) -> OK | C40: =IF(C38>=22,"OK",IF(C38<=22,"LESS")) -> OK | D40: =IF(D38>=22,"OK",IF(D38<=22,"LESS")) -> OK | E40: =IF(E38>=22,"OK",IF(E38<=22,"LESS")) -> OK | F40: =IF(F38>=22,"OK",IF(F38<=22,"LESS")) -> OK | G40: =IF(G38>=22,"OK",IF(G38<=22,"LESS")) -> OK | H40: =IF(H38>=22,"OK",IF(H38<=22,"LESS")) -> OK | I40: =IF(I38>=22,"OK",IF(I38<=22,"LESS")) -> OK | ... Q40: =IF(Q38>=22,"OK",IF(Q38<=22,"LESS")) -> OK
A43: Done by | B43: AKASH
A45: Comment

Sheet 10
A1: Station: | B1: IGKV ,RAIPUR
A2: Date: | B2: =$A$9 -> 45332.042 | D2: Power Off | G2: Pw.Off | L2: Link Fail | N2: Link F | P2: Maintenance | R2: Maint.
A3: Report Type: | B3: Mean | D3: Calibration | G3: Calib. | L3: Data Fail | N3: Data F | P3: Invalid | R3: Invalid
A4: Time Base: | B4: 01 Hour | D4: Zero Referrence | G4: Z.Ref | L4: Warm Up | N4: Wm. Up
A7: Date & Time | B7: NO | C7: NO2 | D7: NOX | E7: SO2 | F7: O3 | G7: PM 10 | H7: PM 2.5 | I7: BENZ | J7: WS | K7: WD | L7: TEMP | M7: HUM | N7: SR | O7: RG | P7: CO | Q7: NH3
B8: ug/m3 | C8: ug/m3 | D8: ppb | E8: ug/m3 | F8: ug/m3 | G8: ug/m3 | H8: ug/m3 | I8: ug/m3 | J8: m/sec | K8: deg | L8: degreC | M8: % | N8: w/m2 | O8: mm | P8: mg/m3 | Q8: ug/m3
A9: 45332.042 | B9: 31.92 | C9: 33.9 | D9: 44.66 | E9: 8.61 | F9: 3.52 | G9: 95.22 | H9: 34.58 | I9: 0 | J9: 0.17 | K9: 222.56 | L9: 16.71 | M9: 68.7 | N9: 0 | O9: 0 | P9: 0.83 | Q9: 4.99
A10: 45332.083 | B10: 36.65 | C10: 34.2 | D10: 47.59 | E10: 7.74 | F10: 3.59 | G10: 93.53 | H10: 35.1 | I10: 0 | J10: 0.59 | K10: 165.16 | L10: 17.06 | M10: 68.92 | N10: 0 | O10: 0 | P10: 0.84 | Q10: 5.04
A11: 45332.125 | B11: 34.09 | C11: 31.02 | D11: 44.79 | E11: 7.05 | F11: 3.32 | G11: 93.53 | H11: 35.85 | I11: 0 | J11: 0.23 | K11: 179.95 | L11: 16.7 | M11: 65.87 | N11: 0 | O11: 0 | P11: 0.83 | Q11: 5.02
A12: 45332.167 | B12: 30.33 | C12: 31.05 | D12: 41.9 | E12: 6.94 | F12: 3.35 | G12: 91.6 | H12: 36.38 | I12: 0 | J12: 0.34 | K12: 104.19 | L12: 16.33 | M12: 65.28 | N12: 0 | O12: 0 | P12: 0.84 | Q12: 5
A13: 45332.208 | B13: 28.04 | C13: 29.48 | D13: 38.89 | E13: 7.14 | F13: 3.56 | G13: 92.73 | H13: 36.38 | I13: 0 | J13: 0.29 | K13: 155.87 | L13: 16.07 | M13: 76.83 | N13: 0 | O13: 0 | P13: 0.83 | Q13: 4.96
A14: 45332.25 | B14: 25.82 | C14: 28.68 | D14: 37.04 | E14: 7.47 | F14: 3.4 | G14: 94.97 | H14: 37.22 | I14: 0 | J14: 0.69 | K14: 66.57 | L14: 15.56 | M14: 70.73 | N14: 0 | O14: 0 | P14: 0.83 | Q14: 4.96
A15: 45332.292 | B15: 26.51 | C15: 29.37 | D15: 37.95 | E15: 7.92 | F15: 3.42 | G15: 95.73 | H15: 39.03 | I15: 0 | J15: 1.06 | K15: 59.64 | L15: 15.53 | M15: 63.42 | N15: 7.5 | O15: 0 | P15: 0.85 | Q15: 4.96
A16: 45332.333 | B16: 27.17 | C16: 30.6 | D16: 38.86 | E16: 8.41 | F16: 3.64 | G16: 101.47 | H16: 39.03 | I16: 0 | J16: 1.18 | K16: 62.99 | L16: 17.4 | M16: 59.91 | N16: 57.6 | O16: 0 | P16: 0.86 | Q16: 4.97
A17: 45332.375 | B17: 24.5 | C17: 30.56 | D17: 36.97 | E17: 9.11 | F17: 3.74 | G17: 104.82 | H17: 38.27 | I17: 0 | J17: 1.3 | K17: 70.42 | L17: 21 | M17: 49.01 | N17: 290.5 | O17: 0 | P17: 0.87 | Q17: 4.95
A18: 45332.417 | B18: 17.91 | C18: 30.5 | D18: 31.49 | E18: 12.01 | F18: 3.94 | G18: 104.82 | H18: 37.85 | I18: 0 | J18: 1.08 | K18: 76.55 | L18: 24.21 | M18: 36.41 | N18: 356.4 | O18: 0 | P18: 0.85 | Q18: 4.91
A19: 45332.458 | B19: 11.75 | C19: 29.82 | D19: 26.35 | E19: 11.68 | F19: 4.6 | G19: 91.09 | H19: 35.19 | I19: 0 | J19: 0.96 | K19: 78.73 | L19: 26.11 | M19: 31.91 | N19: 460.7 | O19: 0 | P19: 0.82 | Q19: 4.85
A20: 45332.5 | B20: 6.63 | C20: 26.76 | D20: 20.65 | E20: 20.45 | F20: 19.49 | G20: 85.69 | H20: 34.57 | I20: 0 | J20: 0.77 | K20: 81.76 | L20: 27.8 | M20: 29.11 | N20: 566.4 | O20: 0 | P20: 0.78 | Q20: 4.79
... A32: 45333 | B32: 9.74 | C32: 26.31 | D32: 22.91 | E32: 8.52 | F32: 3.77 | G32: 113.53 | H32: 43.91 | I32: 7.06 | J32: 0.22 | K32: 168.95 | L32: 21.46 | M32: 53.76 | N32: 0 | O32: 0 | P32: 0.88 | Q32: 4.8
A34: Min | B34: =MIN(B9:B32) -> 2.2 | C34: =MIN(C9:C32) -> 18.19 | D34: =MIN(D9:D32) -> 12.78 | E34: =MIN(E9:E32) -> 6.94 | F34: =MIN(F9:F32) -> 3.32 | G34: =MIN(G9:G32) -> 57.02 | H34: =MIN(H9:H32) -> 24.32 | I34: =MIN(I9:I32) -> 0 | ... Q34: =MIN(Q9:Q32) -> 4.73
A35: Max | B35: =MAX(B9:B32) -> 36.65 | C35: =MAX(C9:C32) -> 37.82 | D35: =MAX(D9:D32) -> 47.59 | E35: =MAX(E9:E32) -> 28.94 | F35: =MAX(F9:F32) -> 23.38 | G35: =MAX(G9:G32) -> 116.45 | H35: =MAX(H9:H32) -> 43.91 | I35: =MAX(I9:I32) -> 7.08 | ... Q35: =MAX(Q9:Q32) -> 5.04
A36: Avg | B36: =AVERAGE(B9:B32) -> 15.868333 | C36: =AVERAGE(C9:C32) -> 29.015 | D36: =AVERAGE(D9:D32) -> 29.056667 | E36: =AVERAGE(E9:E32) -> 10.709167 | F36: =AVERAGE(F9:F32) -> 7.0083333 | G36: =AVERAGE(G9:G32) -> 93.352917 | H36: =AVERAGE(H9:H32) -> 35.748333 | I36: =AVERAGE(I9:I32) -> 2.6454167 | ... Q36: =AVERAGE(Q9:Q32) -> 4.8654167
A37: Stdev | B37: =STDEV(B9:B32) -> 11.481044 | C37: =STDEV(C9:C32) -> 4.3674776 | D37: =STDEV(D9:D32) -> 10.479994 | E37: =STDEV(E9:E32) -> 4.905125 | F37: =STDEV(F9:F32) -> 6.2968168 | G37: =STDEV(G9:G32) -> 16.762905 | H37: =STDEV(H9:H32) -> 4.7680829 | I37: =STDEV(I9:I32) -> 2.8678154 | ... Q37: =STDEV(Q9:Q32) -> 0.1014666
A38: Num | B38: =COUNT(B9:B32) -> 24 | C38: =COUNT(C9:C32) -> 24 | D38: =COUNT(D9:D32) -> 24 | E38: =COUNT(E9:E32) -> 24 | F38: =COUNT(F9:F32) -> 24 | G38: =COUNT(G9:G32) -> 24 | H38: =COUNT(H9:H32) -> 24 | I38: =COUNT(I9:I32) -> 24 | ... Q38: =COUNT(Q9:Q32) -> 24
