Workbook

Sheet 01
A1: Station: | B1: IGKV RAIPUR
A2: Date: | B2: =$A$9 -> 45323.01 | C2: Power Off | G2: Pw.Off | J2: Link Fail | L2: Link F | N2: Maintenance | P2: Maint.
A3: Report Type: | B3: Mean | C3: Calibration | G3: Calib. | J3: Data Fail | L3: Data F | N3: Invalid | P3: Invalid
A4: Time Base: | B4: 15 Min | C4: Zero Referrence | G4: Z.Ref | J4: Warm Up | L4: Wm. Up
A7: Date & Time | B7: NO | C7: NO2 | D7: NOX | E7: SO2 | F7: O3 | G7: PM 10 | H7: PM 2.5 | I7: BENZ | J7: WS | K7: WD | L7: TEMP | M7: HUM | N7: SR | O7: RG | P7: CO | Q7: NH3
B8: ug/m3 | C8: ug/m3 | D8: ppb | E8: ug/m3 | F8: ug/m3 | G8: ug/m3 | H8: ug/m3 | I8: ug/m3 | J8: m/sec | K8: deg | L8: degreC | M8: % | N8: w/m2 | O8: mm | P8: mg/m3 | Q8: ug/m3
A9: 45323.01 | B9: 7.56 | C9: 18.9 | D9: 17.29 | E9: 5.83 | F9: 3.86 | G9: 94.82 | H9: 39.64 | I9: 9.45 | J9: 0.11 | K9: 185.22 | L9: 19.89 | M9: 77.15 | N9: 0 | O9: 0 | P9: 0.83 | Q9: 4.76
A10: 45323.021 | B10: 7.58 | C10: 18.59 | D10: 17.14 | E10: 5.87 | F10: 3.75 | G10: 90.43 | H10: 39.6 | I10: 9.32 | J10: 0.09 | K10: 212.69 | L10: 19.97 | M10: 79.29 | N10: 0 | O10: 0 | P10: 0.82 | Q10: 4.78
A11: 45323.031 | B11: 7.68 | C11: 19.44 | D11: 17.67 | E11: 6.04 | F11: 3.56 | G11: 90.43 | H11: 39.6 | I11: 9.22 | J11: 0.18 | K11: 174.17 | L11: 19.96 | M11: 80.6 | N11: 0 | O11: 0 | P11: 0.82 | Q11: 4.8
A12: 45323.042 | B12: 7.68 | C12: 20.33 | D12: 18.13 | E12: 5.63 | F12: 3.48 | G12: 90.43 | H12: 39.6 | I12: 9.13 | J12: 0.23 | K12: 199.57 | L12: 19.45 | M12: 83.03 | N12: 0 | O12: 0 | P12: 0.81 | Q12: 4.79
A13: 45323.052 | B13: 7.63 | C13: 20.57 | D13: 18.21 | E13: 6.58 | F13: 3.5 | G13: 83.46 | H13: 37.03 | I13: 9.06 | J13: 0.07 | K13: 186.63 | L13: 19.33 | M13: 81.17 | N13: 0 | O13: 0 | P13: 0.82 | Q13: 4.78
A14: 45323.062 | B14: 7.66 | C14: 19.45 | D14: 17.66 | E14: 6.15 | F14: 3.74 | G14: 78.12 | H14: 36.2 | I14: 9.02 | J14: 0.09 | K14: 181.34 | L14: 19.5 | M14: 78.73 | N14: 0 | O14: 0 | P14: 0.8 | Q14: 4.78
A15: 45323.073 | B15: 7.66 | C15: 17.58 | D15: 16.67 | E15: 5.98 | F15: 3.68 | G15: 78.12 | H15: 36.2 | I15: 8.93 | J15: 0.11 | K15: 82.21 | L15: 19.6 | M15: 77.01 | N15: 0 | O15: 0 | P15: 0.78 | Q15: 4.77
A16: 45323.083 | B16: 7.69 | C16: 17.14 | D16: 16.48 | E16: 5.77 | F16: 3.56 | G16: 78.12 | H16: 36.2 | I16: 8.82 | J16: 0.12 | K16: 183.55 | L16: 19.45 | M16: 78.5 | N16: 0 | O16: 0 | P16: 0.77 | Q16: 4.78
A17: 45323.094 | B17: 7.76 | C17: 18.22 | D17: 17.1 | E17: 4 | F17: 3.5 | G17: 76.01 | H17: 35.79 | I17: 8.72 | J17: 0.06 | K17: 226.45 | L17: 19.17 | M17: 81.72 | N17: 0 | O17: 0 | P17: 0.78 | Q17: 4.77
A18: 45323.104 | B18: 7.71 | C18: 18.96 | D18: 17.44 | E18: 4.92 | F18: 3.53 | G18: 74.39 | H18: 35.54 | I18: 8.6 | J18: 0.09 | K18: 166.39 | L18: 19.2 | M18: 80.16 | N18: 0 | O18: 0 | P18: 0.76 | Q18: 4.78
A19: 45323.115 | B19: 7.67 | C19: 19.49 | D19: 17.69 | E19: 4.84 | F19: 3.36 | G19: 74.39 | H19: 35.54 | I19: 8.54 | J19: 0.14 | K19: 139.49 | L19: 19.2 | M19: 79.73 | N19: 0 | O19: 0 | P19: 0.77 | Q19: 4.78
A20: 45323.125 | B20: 7.78 | C20: 18.63 | D20: 17.32 | E20: 5.26 | F20: 3.62 | G20: 74.39 | H20: 35.54 | I20: 8.47 | J20: 0.1 | K20: 147.12 | L20: 19.24 | M20: 79.66 | N20: 0 | O20: 0 | P20: 0.76 | Q20: 4.79
... A104: 45324 | B104: 19.07 | C104: 20.56 | D104: 27.39 | E104: 6.68 | F104: 3.48 | G104: 98.42 | H104: 34.4 | I104: 9.98 | J104: 0.13 | K104: 191.46 | L104: 19.88 | M104: 84.75 | N104: 0 | O104: 0 | P104: 1.01 | Q104: 4.89
A106: Min | B106: =MIN(B9:B104) -> 4.69 | C106: =MIN(C9:C104) -> 17.14 | D106: =MIN(D9:D104) -> 15.17 | E106: =MIN(E9:E104) -> 4 | F106: =MIN(F9:F104) -> 3.15 | G106: =MIN(G9:G104) -> 61.35 | H106: =MIN(H9:H104) -> 29.28 | I106: =MIN(I9:I104) -> 7.98 | ... Q106: =MIN(Q9:Q104) -> 4.74
A107: Max | B107: =MAX(B9:B104) -> 22.14 | C107: =MAX(C9:C104) -> 28.94 | D107: =MAX(D9:D104) -> 32.89 | E107: =MAX(E9:E104) -> 7.76 | F107: =MAX(F9:F104) -> 6.99 | G107: =MAX(G9:G104) -> 103.42 | H107: =MAX(H9:H104) -> 44.62 | I107: =MAX(I9:I104) -> 11.83 | ... Q107: =MAX(Q9:Q104) -> 4.94
A108: Avg | B108: =AVERAGE(B9:B104) -> 12.418646 | C108: =AVERAGE(C9:C104) -> 22.316563 | D108: =AVERAGE(D9:D104) -> 22.969792 | E108: =AVERAGE(E9:E104) -> 6.3083333 | F108: =AVERAGE(F9:F104) -> 3.8880208 | G108: =AVERAGE(G9:G104) -> 85.368125 | H108: =AVERAGE(H9:H104) -> 36.753958 | I108: =AVERAGE(I9:I104) -> 9.5289583 | ... Q108: =AVERAGE(Q9:Q104) -> 4.8257292
A109: Stdev | B109: =STDEV(B9:B104) -> 5.7610031 | C109: =STDEV(C9:C104) -> 3.0021388 | D109: =STDEV(D9:D104) -> 5.7115829 | E109: =STDEV(E9:E104) -> 0.82789736 | F109: =STDEV(F9:F104) -> 0.89434789 | G109: =STDEV(G9:G104) -> 12.598476 | H109: =STDEV(H9:H104) -> 4.5424351 | I109: =STDEV(I9:I104) -> 1.0727245 | ... Q109: =STDEV(Q9:Q104) -> 0.058682819
A110: Num | B110: =COUNT(B9:B104) -> 96 | C110: =COUNT(C9:C104) -> 96 | D110: =COUNT(D9:D104) -> 96 | E110: =COUNT(E9:E104) -> 96 | F110: =COUNT(F9:F104) -> 96 | G110: =COUNT(G9:G104) -> 96 | H110: =COUNT(H9:H104) -> 96 | I110: =COUNT(I9:I104) -> 96 | ... Q110: =COUNT(Q9:Q104) -> 96
A111: DCR | B111: =IF(B110>=87,">90%",IF(B110<=87,"<90%")) -> >90% | C111: =IF(C110>=87,">90%",IF(C110<=87,"<90%")) -> >90% | D111: =IF(D110>=87,">90%",IF(D110<=87,"<90%")) -> >90% | E111: =IF(E110>=87,">90%",IF(E110<=87,"<90%")) -> >90% | F111: =IF(F110>=87,">90%",IF(F110<=87,"<90%")) -> >90% | G111: =IF(G110>=87,">90%",IF(G110<=87,"<90%")) -> >90% | H111: =IF(H110>=87,">90%",IF(H110<=87,"<90%")) -> >90% | I111: =IF(I110>=87,">90%",IF(I110<=87,"<90%")) -> >90% | ... Q111: =IF(Q110>=87,">90%",IF(Q110<=87,"<90%")) -> >90%
A112: Status | B112: =IF(B110>=87,"OK",IF(B110<=87,"LESS")) -> OK | C112: =IF(C110>=87,"OK",IF(C110<=87,"LESS")) -> OK | D112: =IF(D110>=87,"OK",IF(D110<=87,"LESS")) -> OK | E112: =IF(E110>=87,"OK",IF(E110<=87,"LESS")) -> OK | F112: =IF(F110>=87,"OK",IF(F110<=87,"LESS")) -> OK | G112: =IF(G110>=87,"OK",IF(G110<=87,"LESS")) -> OK | H112: =IF(H110>=87,"OK",IF(H110<=87,"LESS")) -> OK | I112: =IF(I110>=87,"OK",IF(I110<=87,"LESS")) -> OK | ... Q112: =IF(Q110>=87,"OK",IF(Q110<=87,"LESS")) -> OK
A115: Done by | B115: AKASH
A117: Comment

Sheet 02
A1: Station: | B1: IGKV RAIPUR
A2: Date: | B2: =$A$9 -> 45324.01 | C2: Power Off | G2: Pw.Off | J2: Link Fail | L2: Link F | N2: Maintenance | P2: Maint.
A3: Report Type: | B3: Mean | C3: Calibration | G3: Calib. | J3: Data Fail | L3: Data F | N3: Invalid | P3: Invalid
A4: Time Base: | B4: 15 Min | C4: Zero Referrence | G4: Z.Ref | J4: Warm Up | L4: Wm. Up
A7: Date & Time | B7: NO | C7: NO2 | D7: NOX | E7: SO2 | F7: O3 | G7: PM 10 | H7: PM 2.5 | I7: BENZ | J7: WS | K7: WD | L7: TEMP | M7: HUM | N7: SR | O7: RG | P7: CO | Q7: NH3
B8: ug/m3 | C8: ug/m3 | D8: ppb | E8: ug/m3 | F8: ug/m3 | G8: ug/m3 | H8: ug/m3 | I8: ug/m3 | J8: m/sec | K8: deg | L8: degreC | M8: % | N8: w/m2 | O8: mm | P8: mg/m3 | Q8: ug/m3
A9: 45324.01 | B9: 19.28 | C9: 20.49 | D9: 27.52 | E9: 6.82 | F9: 3.34 | G9: 96.05 | H9: 36.44 | I9: 10.04 | J9: 0.13 | K9: 189 | L9: 19.75 | M9: 84.83 | N9: 0 | O9: 0 | P9: 1.02 | Q9: 4.92
A10: 45324.021 | B10: 19.11 | C10: 21.39 | D10: 27.85 | E10: 6.99 | F10: 3.24 | G10: 94.25 | H10: 37.08 | I10: 10.15 | J10: 0.11 | K10: 181.65 | L10: 19.74 | M10: 85.41 | N10: 0 | O10: 0 | P10: 1.03 | Q10: 4.93
A11: 45324.031 | B11: 18.73 | C11: 22.23 | D11: 27.98 | E11: 7.2 | F11: 3.23 | G11: 94.25 | H11: 37.08 | I11: 10.27 | J11: 0.15 | K11: 159.24 | L11: 19.76 | M11: 85.22 | N11: 0 | O11: 0 | P11: 1.02 | Q11: 4.93
A12: 45324.042 | B12: 18.35 | C12: 22.62 | D12: 27.88 | E12: 6.78 | F12: 3.31 | G12: 94.25 | H12: 37.08 | I12: 10.32 | J12: 0.14 | K12: 157.81 | L12: 19.72 | M12: 84.34 | N12: 0 | O12: 0 | P12: 1.02 | Q12: 4.93
A13: 45324.052 | B13: 18.23 | C13: 23.02 | D13: 28 | E13: 7.22 | F13: 3.36 | G13: 87.17 | H13: 35.43 | I13: 10.34 | J13: 0.19 | K13: 101.74 | L13: 19.99 | M13: 80.58 | N13: 0 | O13: 0 | P13: 1.03 | Q13: 4.92
A14: 45324.062 | B14: 19.84 | C14: 23.79 | D14: 29.69 | E14: 7.37 | F14: 3.26 | G14: 81.76 | H14: 34.9 | I14: 10.35 | J14: 0.16 | K14: 142.65 | L14: 20.07 | M14: 81.51 | N14: 0 | O14: 0 | P14: 1.04 | Q14: 4.9
A15: 45324.073 | B15: 22.34 | C15: 24.75 | D15: 32.2 | E15: 7.05 | F15: 3.22 | G15: 81.76 | H15: 34.9 | I15: 10.31 | J15: 0.48 | K15: 38.72 | L15: 20.07 | M15: 79.39 | N15: 0 | O15: 0 | P15: 1.04 | Q15: 4.92
A16: 45324.083 | B16: 23.98 | C16: 25.63 | D16: 33.97 | E16: 7.23 | F16: 3.26 | G16: 81.76 | H16: 34.9 | I16: 10.25 | J16: 0.53 | K16: 64.24 | L16: 20.16 | M16: 78.1 | N16: 0 | O16: 0 | P16: 1.05 | Q16: 4.95
A17: 45324.094 | B17: 24.55 | C17: 26.47 | D17: 34.87 | E17: 6.85 | F17: 3.23 | G17: 91.02 | H17: 37.23 | I17: 10.28 | J17: 0.17 | K17: 105.34 | L17: 20.04 | M17: 79.43 | N17: 0 | O17: 0 | P17: 1.05 | Q17: 4.94
A18: 45324.104 | B18: 24.93 | C18: 26.83 | D18: 35.36 | E18: 7.41 | F18: 3.22 | G18: 98.1 | H18: 38.61 | I18: 10.32 | J18: 0.23 | K18: 99.92 | L18: 20.09 | M18: 78.95 | N18: 0 | O18: 0 | P18: 1.05 | Q18: 4.95
A19: 45324.115 | B19: 25.19 | C19: 27.36 | D19: 35.85 | E19: 7.72 | F19: 3.27 | G19: 98.1 | H19: 38.61 | I19: 10.35 | J19: 0.23 | K19: 189.87 | L19: 19.88 | M19: 81.54 | N19: 0 | O19: 0 | P19: 1.04 | Q19: 4.97
A20: 45324.125 | B20: 25.09 | C20: 27.35 | D20: 35.76 | E20: 7.73 | F20: 3.31 | G20: 98.1 | H20: 38.61 | I20: 5.02 | J20: 0.19 | K20: 249.61 | L20: 19.24 | M20: 85.52 | N20: 0 | O20: 0 | P20: 1.05 | Q20: 4.98
... A104: 45325 | B104: 13.71 | C104: 25.87 | D104: 25.86 | E104: 9.06 | F104: 3.35 | G104: 65.85 | H104: 31.53 | I104: 0 | J104: 0.19 | K104: 212.94 | L104: 19.99 | M104: 86.79 | N104: 0 | O104: 0 | P104: 0.95 | Q104: 4.82
A106: Min | B106: =MIN(B9:B104) -> 4.51 | C106: =MIN(C9:C104) -> 14.65 | D106: =MIN(D9:D104) -> 12.88 | E106: =MIN(E9:E104) -> 5.41 | F106: =MIN(F9:F104) -> 3.14 | G106: =MIN(G9:G104) -> 61.31 | H106: =MIN(H9:H104) -> 31.53 | I106: =MIN(I9:I104) -> 0 | ... Q106: =MIN(Q9:Q104) -> 4.69
A107: Max | B107: =MAX(B9:B104) -> 33.37 | C107: =MAX(C9:C104) -> 29.27 | D107: =MAX(D9:D104) -> 42.09 | E107: =MAX(E9:E104) -> 9.06 | F107: =MAX(F9:F104) -> 5.85 | G107: =MAX(G9:G104) -> 127.73 | H107: =MAX(H9:H104) -> 49.22 | I107: =MAX(I9:I104) -> 10.35 | ... Q107: =MAX(Q9:Q104) -> 5.04
A108: Avg | B108: =AVERAGE(B9:B104) -> 16.192292 | C108: =AVERAGE(C9:C104) -> 22.841562 | D108: =AVERAGE(D9:D104) -> 26.269583 | E108: =AVERAGE(E9:E104) -> 7.5232292 | F108: =AVERAGE(F9:F104) -> 3.7445833 | G108: =AVERAGE(G9:G104) -> 93.713229 | H108: =AVERAGE(H9:H104) -> 38.995208 | I108: =AVERAGE(I9:I104) -> 1.2291667 | ... Q108: =AVERAGE(Q9:Q104) -> 4.8696875
A109: Stdev | B109: =STDEV(B9:B104) -> 11.039556 | C109: =STDEV(C9:C104) -> 4.4822089 | D109: =STDEV(D9:D104) -> 10.053129 | E109: =STDEV(E9:E104) -> 0.84713075 | F109: =STDEV(F9:F104) -> 0.67821269 | G109: =STDEV(G9:G104) -> 18.651818 | H109: =STDEV(H9:H104) -> 4.4648656 | I109: =STDEV(I9:I104) -> 3.3097275 | ... Q109: =STDEV(Q9:Q104) -> 0.10196442
A110: Num | B110: =COUNT(B9:B104) -> 96 | C110: =COUNT(C9:C104) -> 96 | D110: =COUNT(D9:D104) -> 96 | E110: =COUNT(E9:E104) -> 96 | F110: =COUNT(F9:F104) -> 96 | G110: =COUNT(G9:G104) -> 96 | H110: =COUNT(H9:H104) -> 96 | I110: =COUNT(I9:I104) -> 96 | ... Q110: =COUNT(Q9:Q104) -> 96
A111: DCR | B111: =IF(B110>=87,">90%",IF(B110<=87,"<90%")) -> >90% | C111: =IF(C110>=87,">90%",IF(C110<=87,"<90%")) -> >90% | D111: =IF(D110>=87,">90%",IF(D110<=87,"<90%")) -> >90% | E111: =IF(E110>=87,">90%",IF(E110<=87,"<90%")) -> >90% | F111: =IF(F110>=87,">90%",IF(F110<=87,"<90%")) -> >90% | G111: =IF(G110>=87,">90%",IF(G110<=87,"<90%")) -> >90% | H111: =IF(H110>=87,">90%",IF(H110<=87,"<90%")) -> >90% | I111: =IF(I110>=87,">90%",IF(I110<=87,"<90%")) -> >90% | ... Q111: =IF(Q110>=87,">90%",IF(Q110<=87,"<90%")) -> >90%
A112: Status | B112: =IF(B110>=87,"OK",IF(B110<=87,"LESS")) -> OK | C112: =IF(C110>=87,"OK",IF(C110<=87,"LESS")) -> OK | D112: =IF(D110>=87,"OK",IF(D110<=87,"LESS")) -> OK | E112: =IF(E110>=87,"OK",IF(E110<=87,"LESS")) -> OK | F112: =IF(F110>=87,"OK",IF(F110<=87,"LESS")) -> OK | G112: =IF(G110>=87,"OK",IF(G110<=87,"LESS")) -> OK | H112: =IF(H110>=87,"OK",IF(H110<=87,"LESS")) -> OK | I112: =IF(I110>=87,"OK",IF(I110<=87,"LESS")) -> OK | ... Q112: =IF(Q110>=87,"OK",IF(Q110<=87,"LESS")) -> OK
A115: Done by | B115: AKASH
A117: Comment

Sheet 03
A1: Station: | B1: IGKV RAIPUR
A2: Date: | B2: =$A$9 -> 45325.01 | C2: Power Off | G2: Pw.Off | J2: Link Fail | L2: Link F | N2: Maintenance | P2: Maint.
A3: Report Type: | B3: Mean | C3: Calibration | G3: Calib. | J3: Data Fail | L3: Data F | N3: Invalid | P3: Invalid
A4: Time Base: | B4: 15 Min | C4: Zero Referrence | G4: Z.Ref | J4: Warm Up | L4: Wm. Up
A7: Date & Time | B7: NO | C7: NO2 | D7: NOX | E7: SO2 | F7: O3 | G7: PM 10 | H7: PM 2.5 | I7: BENZ | J7: WS | K7: WD | L7: TEMP | M7: HUM | N7: SR | O7: RG | P7: CO | Q7: NH3
B8: ug/m3 | C8: ug/m3 | D8: ppb | E8: ug/m3 | F8: ug/m3 | G8: ug/m3 | H8: ug/m3 | I8: ug/m3 | J8: m/sec | K8: deg | L8: degreC | M8: % | N8: w/m2 | O8: mm | P8: mg/m3 | Q8: ug/m3
A9: 45325.01 | B9: 14.38 | C9: 26.81 | D9: 26.89 | E9: 8.8 | F9: 3.27 | G9: 68.57 | H9: 33 | I9: 0 | J9: 0.13 | K9: 226.36 | L9: 19.76 | M9: 87.56 | N9: 0 | O9: 0 | P9: 0.98 | Q9: 4.83
A10: 45325.021 | B10: 14.54 | C10: 26.73 | D10: 26.97 | E10: 9.21 | F10: 3.26 | G10: 70.65 | H10: 33.46 | I10: 0 | J10: 0.1 | K10: 185.01 | L10: 19.89 | M10: 85.95 | N10: 0 | O10: 0 | P10: 0.98 | Q10: 4.83
A11: 45325.031 | B11: 15.81 | C11: 27.02 | D11: 28.15 | E11: 8.77 | F11: 3.21 | G11: 70.65 | H11: 33.46 | I11: 0 | J11: 0.11 | K11: 34.82 | L11: 20.04 | M11: 83.09 | N11: 0 | O11: 0 | P11: 1 | Q11: 4.84
A12: 45325.042 | B12: 19.14 | C12: 28.37 | D12: 31.52 | E12: 9.07 | F12: 3.15 | G12: 70.65 | H12: 33.46 | I12: 0 | J12: 0.21 | K12: 55.28 | L12: 20.34 | M12: 77.07 | N12: 0 | O12: 0 | P12: 1.04 | Q12: 4.83
A13: 45325.052 | B13: 21.66 | C13: 27.51 | D13: 33.1 | E13: 9.04 | F13: 3.43 | G13: 78.84 | H13: 35.37 | I13: 0 | J13: 0.35 | K13: 64.44 | L13: 20.5 | M13: 72.69 | N13: 0 | O13: 0 | P13: 1.06 | Q13: 4.86
A14: 45325.062 | B14: 22.92 | C14: 25.12 | D14: 32.85 | E14: 8.96 | F14: 3.57 | G14: 85.11 | H14: 35.99 | I14: 0 | J14: 0.61 | K14: 57.9 | L14: 20.35 | M14: 69.9 | N14: 0 | O14: 0 | P14: 1.06 | Q14: 4.86
A15: 45325.073 | B15: 23.22 | C15: 23.23 | D15: 32.11 | E15: 8.79 | F15: 3.55 | G15: 85.11 | H15: 35.99 | I15: 0 | J15: 0.79 | K15: 37.56 | L15: 20.99 | M15: 59.4 | N15: 0 | O15: 0 | P15: 1.04 | Q15: 4.87
A16: 45325.083 | B16: 22.88 | C16: 22.41 | D16: 31.41 | E16: 8.58 | F16: 3.47 | G16: 85.11 | H16: 35.99 | I16: 0 | J16: 0.67 | K16: 39.91 | L16: 20.58 | M16: 62.81 | N16: 0 | O16: 0 | P16: 1.02 | Q16: 4.87
A17: 45325.094 | B17: 22.5 | C17: 23.3 | D17: 31.57 | E17: 5.89 | F17: 3.33 | G17: 83.24 | H17: 35.43 | I17: 0 | J17: 0.65 | K17: 47.65 | L17: 20.22 | M17: 62.23 | N17: 0 | O17: 0 | P17: 1.02 | Q17: 4.87
A18: 45325.104 | B18: 22.22 | C18: 24.45 | D18: 31.95 | E18: 6.67 | F18: 3.31 | G18: 81.82 | H18: 35.11 | I18: 0 | J18: 0.63 | K18: 44.51 | L18: 19.96 | M18: 61.17 | N18: 0 | O18: 0 | P18: 1.01 | Q18: 4.87
A19: 45325.115 | B19: 21.85 | C19: 24.7 | D19: 31.78 | E19: 6.76 | F19: 3.32 | G19: 81.82 | H19: 35.11 | I19: 0 | J19: 0.45 | K19: 51.76 | L19: 19.72 | M19: 60.45 | N19: 0 | O19: 0 | P19: 0.99 | Q19: 4.89
A20: 45325.125 | B20: 21.53 | C20: 24.87 | D20: 31.61 | E20: 6.59 | F20: 3.24 | G20: 81.82 | H20: 35.11 | I20: 0 | J20: 0.27 | K20: 62.91 | L20: 19.25 | M20: 63.2 | N20: 0 | O20: 0 | P20: 0.99 | Q20: 4.88
... A104: 45326 | B104: 25.09 | C104: 23.51 | D104: 33.76 | E104: 6.92 | F104: 3.25 | G104: 112.68 | H104: 37.28 | I104: 0 | J104: 0.12 | K104: 174.6 | L104: 16.7 | M104: 78.88 | N104: 0 | O104: 0 | P104: 0.94 | Q104: 4.96
A106: Min | B106: =MIN(B9:B104) -> 5.97 | C106: =MIN(C9:C104) -> 19.44 | D106: =MIN(D9:D104) -> 17.37 | E106: =MIN(E9:E104) -> 5.82 | F106: =MIN(F9:F104) -> 3.08 | G106: =MIN(G9:G104) -> 56.55 | H106: =MIN(H9:H104) -> 20.63 | I106: =MIN(I9:I104) -> 0 | ... Q106: =MIN(Q9:Q104) -> 4.81
A107: Max | B107: =MAX(B9:B104) -> 34.99 | C107: =MAX(C9:C104) -> 30.95 | D107: =MAX(D9:D104) -> 45 | E107: =MAX(E9:E104) -> 9.21 | F107: =MAX(F9:F104) -> 6.15 | G107: =MAX(G9:G104) -> 112.68 | H107: =MAX(H9:H104) -> 37.28 | I107: =MAX(I9:I104) -> 0 | ... Q107: =MAX(Q9:Q104) -> 5.08
A108: Avg | B108: =AVERAGE(B9:B104) -> 18.459271 | C108: =AVERAGE(C9:C104) -> 24.984375 | D108: =AVERAGE(D9:D104) -> 29.207812 | E108: =AVERAGE(E9:E104) -> 7.0232292 | F108: =AVERAGE(F9:F104) -> 3.735 | G108: =AVERAGE(G9:G104) -> 76.079167 | H108: =AVERAGE(H9:H104) -> 29.357813 | I108: =AVERAGE(I9:I104) -> 0 | ... Q108: =AVERAGE(Q9:Q104) -> 4.9161458
A109: Stdev | B109: =STDEV(B9:B104) -> 7.9367606 | C109: =STDEV(C9:C104) -> 3.1671803 | D109: =STDEV(D9:D104) -> 7.4317232 | E109: =STDEV(E9:E104) -> 0.81815903 | F109: =STDEV(F9:F104) -> 0.71987426 | G109: =STDEV(G9:G104) -> 16.128677 | H109: =STDEV(H9:H104) -> 4.7196517 | I109: =STDEV(I9:I104) -> 0 | ... Q109: =STDEV(Q9:Q104) -> 0.073145418
A110: Num | B110: =COUNT(B9:B104) -> 96 | C110: =COUNT(C9:C104) -> 96 | D110: =COUNT(D9:D104) -> 96 | E110: =COUNT(E9:E104) -> 96 | F110: =COUNT(F9:F104) -> 96 | G110: =COUNT(G9:G104) -> 96 | H110: =COUNT(H9:H104) -> 96 | I110: =COUNT(I9:I104) -> 96 | ... Q110: =COUNT(Q9:Q104) -> 96
A111: DCR | B111: =IF(B110>=87,">90%",IF(B110<=87,"<90%")) -> >90% | C111: =IF(C110>=87,">90%",IF(C110<=87,"<90%")) -> >90% | D111: =IF(D110>=87,">90%",IF(D110<=87,"<90%")) -> >90% | E111: =IF(E110>=87,">90%",IF(E110<=87,"<90%")) -> >90% | F111: =IF(F110>=87,">90%",IF(F110<=87,"<90%")) -> >90% | G111: =IF(G110>=87,">90%",IF(G110<=87,"<90%")) -> >90% | H111: =IF(H110>=87,">90%",IF(H110<=87,"<90%")) -> >90% | I111: =IF(I110>=87,">90%",IF(I110<=87,"<90%")) -> >90% | ... Q111: =IF(Q110>=87,">90%",IF(Q110<=87,"<90%")) -> >90%
A112: Status | B112: =IF(B110>=87,"OK",IF(B110<=87,"LESS")) -> OK | C112: =IF(C110>=87,"OK",IF(C110<=87,"LESS")) -> OK | D112: =IF(D110>=87,"OK",IF(D110<=87,"LESS")) -> OK | E112: =IF(E110>=87,"OK",IF(E110<=87,"LESS")) -> OK | F112: =IF(F110>=87,"OK",IF(F110<=87,"LESS")) -> OK | G112: =IF(G110>=87,"OK",IF(G110<=87,"LESS")) -> OK | H112: =IF(H110>=87,"OK",IF(H110<=87,"LESS")) -> OK | I112: =IF(I110>=87,"OK",IF(I110<=87,"LESS")) -> OK | ... Q112: =IF(Q110>=87,"OK",IF(Q110<=87,"LESS")) -> OK
A115: Done by | B115: AKASH
A117: Comment

Sheet 04
A1: Station: | B1: IGKV RAIPUR
A2: Date: | B2: =$A$9 -> 45326.01 | C2: Power Off | G2: Pw.Off | J2: Link Fail | L2: Link F | N2: Maintenance | P2: Maint.
A3: Report Type: | B3: Mean | C3: Calibration | G3: Calib. | J3: Data Fail | L3: Data F | N3: Invalid | P3: Invalid
A4: Time Base: | B4: 15 Min | C4: Zero Referrence | G4: Z.Ref | J4: Warm Up | L4: Wm. Up
A7: Date & Time | B7: NO | C7: NO2 | D7: NOX | E7: SO2 | F7: O3 | G7: PM 10 | H7: PM 2.5 | I7: BENZ | J7: WS | K7: WD | L7: TEMP | M7: HUM | N7: SR | O7: RG | P7: CO | Q7: NH3
B8: ug/m3 | C8: ug/m3 | D8: ppb | E8: ug/m3 | F8: ug/m3 | G8: ug/m3 | H8: ug/m3 | I8: ug/m3 | J8: m/sec | K8: deg | L8: degreC | M8: % | N8: w/m2 | O8: mm | P8: mg/m3 | Q8: ug/m3
A9: 45326.01 | B9: 24.31 | C9: 23.53 | D9: 33.14 | E9: 6.78 | F9: 3.34 | G9: 112.79 | H9: 36.84 | I9: 0 | J9: 0.17 | K9: 178.23 | L9: 17.04 | M9: 77.34 | N9: 0 | O9: 0 | P9: 0.95 | Q9: 4.95
A10: 45326.021 | B10: 24.13 | C10: 24.45 | D10: 33.47 | E10: 7.11 | F10: 3.16 | G10: 112.88 | H10: 36.7 | I10: 0 | J10: 0.13 | K10: 174.33 | L10: 16.85 | M10: 81.55 | N10: 0 | O10: 0 | P10: 0.96 | Q10: 4.94
A11: 45326.031 | B11: 24.25 | C11: 23.71 | D11: 33.19 | E11: 7.31 | F11: 3.27 | G11: 112.88 | H11: 36.7 | I11: 0 | J11: 0.09 | K11: 51.25 | L11: 16.98 | M11: 74.45 | N11: 0 | O11: 0 | P11: 0.96 | Q11: 4.95
A12: 45326.042 | B12: 27.07 | C12: 25.08 | D12: 36.16 | E12: 7.19 | F12: 3.27 | G12: 112.88 | H12: 36.7 | I12: 0 | J12: 0.08 | K12: 193.48 | L12: 17.14 | M12: 72.31 | N12: 0 | O12: 0 | P12: 0.97 | Q12: 4.97
A13: 45326.052 | B13: 31.34 | C13: 24.55 | D13: 39.31 | E13: 6.81 | F13: 3.32 | G13: 109.56 | H13: 35.85 | I13: 0 | J13: 0.22 | K13: 191.84 | L13: 16.92 | M13: 77.92 | N13: 0 | O13: 0 | P13: 0.97 | Q13: 4.99
A14: 45326.062 | B14: 33.99 | C14: 26.83 | D14: 42.63 | E14: 7.42 | F14: 3.19 | G14: 107.03 | H14: 35.58 | I14: 0 | J14: 0.15 | K14: 185.58 | L14: 16.38 | M14: 81.44 | N14: 0 | O14: 0 | P14: 0.99 | Q14: 5.01
A15: 45326.073 | B15: 35.66 | C15: 27.12 | D15: 44.11 | E15: 7.47 | F15: 3.25 | G15: 107.03 | H15: 35.58 | I15: 0 | J15: 0.18 | K15: 180.11 | L15: 16.35 | M15: 83.2 | N15: 0 | O15: 0 | P15: 0.98 | Q15: 5.07
A16: 45326.083 | B16: 36.87 | C16: 27.44 | D16: 45.26 | E16: 7.32 | F16: 3.22 | G16: 107.03 | H16: 35.58 | I16: 0 | J16: 0.16 | K16: 187.43 | L16: 16.16 | M16: 84.13 | N16: 0 | O16: 0 | P16: 0.99 | Q16: 5.1
A17: 45326.094 | B17: 37.41 | C17: 27.25 | D17: 45.59 | E17: 6.29 | F17: 3.35 | G17: 104.07 | H17: 35.91 | I17: 0 | J17: 0.18 | K17: 156.24 | L17: 16.02 | M17: 82.44 | N17: 0 | O17: 0 | P17: 0.99 | Q17: 5.09
A18: 45326.104 | B18: 37.29 | C18: 27.37 | D18: 45.55 | E18: 7.74 | F18: 3.42 | G18: 101.82 | H18: 36.1 | I18: 0 | J18: 0.18 | K18: 171.44 | L18: 16.08 | M18: 81.17 | N18: 0 | O18: 0 | P18: 1 | Q18: 5.06
A19: 45326.115 | B19: 37.12 | C19: 27.39 | D19: 45.43 | E19: 7.83 | F19: 3.26 | G19: 101.82 | H19: 36.1 | I19: 0 | J19: 0.03 | K19: 126.69 | L19: 15.96 | M19: 82.03 | N19: 0 | O19: 0 | P19: 0.99 | Q19: 5.07
A20: 45326.125 | B20: 40.4 | C20: 27.63 | D20: 48.19 | E20: 7.92 | F20: 3.31 | G20: 101.82 | H20: 36.1 | I20: 0 | J20: 0.12 | K20: 197.37 | L20: 16.03 | M20: 81.45 | N20: 0 | O20: 0 | P20: 1 | Q20: 5.11
... A104: 45327 | B104: 7.08 | C104: 21.22 | D104: 18.12 | E104: 10 | F104: 3.48 | G104: 51.27 | H104: 20.8 | I104: 0 | J104: 0.15 | K104: 202.57 | L104: 18.95 | M104: 72.82 | N104: 0 | O104: 0 | P104: 0.74 | Q104: 4.8
A106: Min | B106: =MIN(B9:B104) -> 3.72 | C106: =MIN(C9:C104) -> 13.79 | D106: =MIN(D9:D104) -> 12.29 | E106: =MIN(E9:E104) -> 6.14 | F106: =MIN(F9:F104) -> 3.09 | G106: =MIN(G9:G104) -> 25.52 | H106: =MIN(H9:H104) -> 13.27 | I106: =MIN(I9:I104) -> 0 | ... Q106: =MIN(Q9:Q104) -> 4.71
A107: Max | B107: =MAX(B9:B104) -> 57.04 | C107: =MAX(C9:C104) -> 29 | D107: =MAX(D9:D104) -> 62.06 | E107: =MAX(E9:E104) -> 10.33 | F107: =MAX(F9:F104) -> 8.52 | G107: =MAX(G9:G104) -> 112.88 | H107: =MAX(H9:H104) -> 42.12 | I107: =MAX(I9:I104) -> 0 | ... Q107: =MAX(Q9:Q104) -> 5.26
A108: Avg | B108: =AVERAGE(B9:B104) -> 24.18125 | C108: =AVERAGE(C9:C104) -> 22.964375 | D108: =AVERAGE(D9:D104) -> 32.740833 | E108: =AVERAGE(E9:E104) -> 7.9361458 | F108: =AVERAGE(F9:F104) -> 4.0761458 | G108: =AVERAGE(G9:G104) -> 70.3125 | H108: =AVERAGE(H9:H104) -> 27.816875 | I108: =AVERAGE(I9:I104) -> 0 | ... Q108: =AVERAGE(Q9:Q104) -> 4.9394792
A109: Stdev | B109: =STDEV(B9:B104) -> 20.118923 | C109: =STDEV(C9:C104) -> 4.6281591 | D109: =STDEV(D9:D104) -> 18.149797 | E109: =STDEV(E9:E104) -> 1.1126359 | F109: =STDEV(F9:F104) -> 1.3459697 | G109: =STDEV(G9:G104) -> 31.531405 | H109: =STDEV(H9:H104) -> 10.017352 | I109: =STDEV(I9:I104) -> 0 | ... Q109: =STDEV(Q9:Q104) -> 0.18373533
A110: Num | B110: =COUNT(B9:B104) -> 96 | C110: =COUNT(C9:C104) -> 96 | D110: =COUNT(D9:D104) -> 96 | E110: =COUNT(E9:E104) -> 96 | F110: =COUNT(F9:F104) -> 96 | G110: =COUNT(G9:G104) -> 96 | H110: =COUNT(H9:H104) -> 96 | I110: =COUNT(I9:I104) -> 96 | ... Q110: =COUNT(Q9:Q104) -> 96
A111: DCR | B111: =IF(B110>=87,">90%",IF(B110<=87,"<90%")) -> >90% | C111: =IF(C110>=87,">90%",IF(C110<=87,"<90%")) -> >90% | D111: =IF(D110>=87,">90%",IF(D110<=87,"<90%")) -> >90% | E111: =IF(E110>=87,">90%",IF(E110<=87,"<90%")) -> >90% | F111: =IF(F110>=87,">90%",IF(F110<=87,"<90%")) -> >90% | G111: =IF(G110>=87,">90%",IF(G110<=87,"<90%")) -> >90% | H111: =IF(H110>=87,">90%",IF(H110<=87,"<90%")) -> >90% | I111: =IF(I110>=87,">90%",IF(I110<=87,"<90%")) -> >90% | ... Q111: =IF(Q110>=87,">90%",IF(Q110<=87,"<90%")) -> >90%
A112: Status | B112: =IF(B110>=87,"OK",IF(B110<=87,"LESS")) -> OK | C112: =IF(C110>=87,"OK",IF(C110<=87,"LESS")) -> OK | D112: =IF(D110>=87,"OK",IF(D110<=87,"LESS")) -> OK | E112: =IF(E110>=87,"OK",IF(E110<=87,"LESS")) -> OK | F112: =IF(F110>=87,"OK",IF(F110<=87,"LESS")) -> OK | G112: =IF(G110>=87,"OK",IF(G110<=87,"LESS")) -> OK | H112: =IF(H110>=87,"OK",IF(H110<=87,"LESS")) -> OK | I112: =IF(I110>=87,"OK",IF(I110<=87,"LESS")) -> OK | ... Q112: =IF(Q110>=87,"OK",IF(Q110<=87,"LESS")) -> OK
A115: Done by | B115: AKASH
A117: Comment

Sheet 05
A1: Station: | B1: IGKV RAIPUR
A2: Date: | B2: =$A$9 -> 45327.01 | C2: Power Off | G2: Pw.Off | J2: Link Fail | L2: Link F | N2: Maintenance | P2: Maint.
A3: Report Type: | B3: Mean | C3: Calibration | G3: Calib. | J3: Data Fail | L3: Data F | N3: Invalid | P3: Invalid
A4: Time Base: | B4: 15 Min | C4: Zero Referrence | G4: Z.Ref | J4: Warm Up | L4: Wm. Up
A7: Date & Time | B7: NO | C7: NO2 | D7: NOX | E7: SO2 | F7: O3 | G7: PM 10 | H7: PM 2.5 | I7: BENZ | J7: WS | K7: WD | L7: TEMP | M7: HUM | N7: SR | O7: RG | P7: CO | Q7: NH3
B8: ug/m3 | C8: ug/m3 | D8: ppb | E8: ug/m3 | F8: ug/m3 | G8: ug/m3 | H8: ug/m3 | I8: ug/m3 | J8: m/sec | K8: deg | L8: degreC | M8: % | N8: w/m2 | O8: mm | P8: mg/m3 | Q8: ug/m3
A9: 45327.01 | B9: 6.95 | C9: 21.34 | D9: 18.07 | E9: 10.03 | F9: 3.39 | G9: 50.51 | H9: 21.83 | I9: 0 | J9: 0.17 | K9: 198.94 | L9: 18.57 | M9: 75.6 | N9: 0 | O9: 0 | P9: 0.75 | Q9: 4.78
A10: 45327.021 | B10: 7.24 | C10: 21.37 | D10: 18.32 | E10: 10.3 | F10: 3.34 | G10: 49.93 | H10: 22.16 | I10: 0 | J10: 0.12 | K10: 196.44 | L10: 18.34 | M10: 74.49 | N10: 0 | O10: 0 | P10: 0.76 | Q10: 4.79
A11: 45327.031 | B11: 7.34 | C11: 21.41 | D11: 18.42 | E11: 10.14 | F11: 3.38 | G11: 49.93 | H11: 22.16 | I11: 0 | J11: 0.09 | K11: 189.91 | L11: 18.15 | M11: 76.66 | N11: 0 | O11: 0 | P11: 0.76 | Q11: 4.78
A12: 45327.042 | B12: 7.41 | C12: 21.55 | D12: 18.55 | E12: 10.35 | F12: 3.38 | G12: 49.93 | H12: 22.16 | I12: 0 | J12: 0.09 | K12: 166.06 | L12: 18.17 | M12: 72.49 | N12: 0 | O12: 0 | P12: 0.76 | Q12: 4.77
A13: 45327.052 | B13: 7.38 | C13: 21.64 | D13: 18.58 | E13: 10.26 | F13: 3.43 | G13: 48.24 | H13: 22.34 | I13: 0 | J13: 0.07 | K13: 198.36 | L13: 18.27 | M13: 70.59 | N13: 0 | O13: 0 | P13: 0.77 | Q13: 4.78
A14: 45327.062 | B14: 7.43 | C14: 21.51 | D14: 18.55 | E14: 10.19 | F14: 3.38 | G14: 46.94 | H14: 22.4 | I14: 0 | J14: 0.09 | K14: 214.15 | L14: 18.42 | M14: 69.06 | N14: 0 | O14: 0 | P14: 0.76 | Q14: 4.77
A15: 45327.073 | B15: 7.25 | C15: 21.59 | D15: 18.44 | E15: 10.08 | F15: 3.4 | G15: 46.94 | H15: 22.4 | I15: 0 | J15: 0.08 | K15: 173.36 | L15: 18.41 | M15: 70.29 | N15: 0 | O15: 0 | P15: 0.76 | Q15: 4.77
A16: 45327.083 | B16: 7.13 | C16: 21.5 | D16: 18.3 | E16: 10.69 | F16: 3.46 | G16: 46.94 | H16: 22.4 | I16: 0 | J16: 0.08 | K16: 216.46 | L16: 18.19 | M16: 71.04 | N16: 0 | O16: 0 | P16: 0.75 | Q16: 4.79
A17: 45327.094 | B17: 6.92 | C17: 21.45 | D17: 18.11 | E17: 5.59 | F17: 3.52 | G17: 47.73 | H17: 22.06 | I17: 0 | J17: 0.09 | K17: 234.4 | L17: 18.18 | M17: 70.2 | N17: 0 | O17: 0 | P17: 0.75 | Q17: 4.77
A18: 45327.104 | B18: 6.89 | C18: 20.86 | D18: 17.78 | E18: 6.2 | F18: 3.42 | G18: 48.33 | H18: 21.86 | I18: 0 | J18: 0.14 | K18: 157.69 | L18: 18.18 | M18: 73.38 | N18: 0 | O18: 0 | P18: 0.74 | Q18: 4.75
A19: 45327.115 | B19: 7 | C19: 19.63 | D19: 17.22 | E19: 5.55 | F19: 3.59 | G19: 48.33 | H19: 21.86 | I19: 0 | J19: 0.15 | K19: 173.27 | L19: 17.94 | M19: 75.82 | N19: 0 | O19: 0 | P19: 0.75 | Q19: 4.74
A20: 45327.125 | B20: 7.04 | C20: 18.07 | D20: 16.44 | E20: 5.45 | F20: 3.75 | G20: 48.33 | H20: 21.86 | I20: 0 | J20: 0.19 | K20: 161.63 | L20: 17.93 | M20: 76.66 | N20: 0 | O20: 0 | P20: 0.73 | Q20: 4.75
... A104: 45328 | B104: 7.92 | C104: 16.86 | D104: 16.51 | E104: 6.08 | F104: 3.22 | G104: 78.05 | H104: 31.31 | I104: 0 | J104: 0.16 | K104: 173.69 | L104: 21.64 | M104: 80.63 | N104: 0 | O104: 0 | P104: 0.87 | Q104: 4.71
A106: Min | B106: =MIN(B9:B104) -> 3.63 | C106: =MIN(C9:C104) -> 11.49 | D106: =MIN(D9:D104) -> 10.37 | E106: =MIN(E9:E104) -> 5.38 | F106: =MIN(F9:F104) -> 3.17 | G106: =MIN(G9:G104) -> 42 | H106: =MIN(H9:H104) -> 16.53 | I106: =MIN(I9:I104) -> 0 | ... Q106: =MIN(Q9:Q104) -> 4.66
A107: Max | B107: =MAX(B9:B104) -> 16.22 | C107: =MAX(C9:C104) -> 23.02 | D107: =MAX(D9:D104) -> 25.48 | E107: =MAX(E9:E104) -> 10.76 | F107: =MAX(F9:F104) -> 13.45 | G107: =MAX(G9:G104) -> 78.05 | H107: =MAX(H9:H104) -> 31.31 | I107: =MAX(I9:I104) -> 0 | ... Q107: =MAX(Q9:Q104) -> 4.86
A108: Avg | B108: =AVERAGE(B9:B104) -> 7.4853125 | C108: =AVERAGE(C9:C104) -> 19.239063 | D108: =AVERAGE(D9:D104) -> 17.405833 | E108: =AVERAGE(E9:E104) -> 6.9905208 | F108: =AVERAGE(F9:F104) -> 4.7844792 | G108: =AVERAGE(G9:G104) -> 55.092083 | H108: =AVERAGE(H9:H104) -> 22.973125 | I108: =AVERAGE(I9:I104) -> 0 | ... Q108: =AVERAGE(Q9:Q104) -> 4.7576042
A109: Stdev | B109: =STDEV(B9:B104) -> 3.8883729 | C109: =STDEV(C9:C104) -> 3.0578162 | D109: =STDEV(D9:D104) -> 4.1420152 | E109: =STDEV(E9:E104) -> 1.4570232 | F109: =STDEV(F9:F104) -> 2.2207239 | G109: =STDEV(G9:G104) -> 10.748065 | H109: =STDEV(H9:H104) -> 3.5615397 | I109: =STDEV(I9:I104) -> 0 | ... Q109: =STDEV(Q9:Q104) -> 0.050110295
A110: Num | B110: =COUNT(B9:B104) -> 96 | C110: =COUNT(C9:C104) -> 96 | D110: =COUNT(D9:D104) -> 96 | E110: =COUNT(E9:E104) -> 96 | F110: =COUNT(F9:F104) -> 96 | G110: =COUNT(G9:G104) -> 96 | H110: =COUNT(H9:H104) -> 96 | I110: =COUNT(I9:I104) -> 96 | ... Q110: =COUNT(Q9:Q104) -> 96
A111: DCR | B111: =IF(B110>=87,">90%",IF(B110<=87,"<90%")) -> >90% | C111: =IF(C110>=87,">90%",IF(C110<=87,"<90%")) -> >90% | D111: =IF(D110>=87,">90%",IF(D110<=87,"<90%")) -> >90% | E111: =IF(E110>=87,">90%",IF(E110<=87,"<90%")) -> >90% | F111: =IF(F110>=87,">90%",IF(F110<=87,"<90%")) -> >90% | G111: =IF(G110>=87,">90%",IF(G110<=87,"<90%")) -> >90% | H111: =IF(H110>=87,">90%",IF(H110<=87,"<90%")) -> >90% | I111: =IF(I110>=87,">90%",IF(I110<=87,"<90%")) -> >90% | ... Q111: =IF(Q110>=87,">90%",IF(Q110<=87,"<90%")) -> >90%
A112: Status | B112: =IF(B110>=87,"OK",IF(B110<=87,"LESS")) -> OK | C112: =IF(C110>=87,"OK",IF(C110<=87,"LESS")) -> OK | D112: =IF(D110>=87,"OK",IF(D110<=87,"LESS")) -> OK | E112: =IF(E110>=87,"OK",IF(E110<=87,"LESS")) -> OK | F112: =IF(F110>=87,"OK",IF(F110<=87,"LESS")) -> OK | G112: =IF(G110>=87,"OK",IF(G110<=87,"LESS")) -> OK | H112: =IF(H110>=87,"OK",IF(H110<=87,"LESS")) -> OK | I112: =IF(I110>=87,"OK",IF(I110<=87,"LESS")) -> OK | ... Q112: =IF(Q110>=87,"OK",IF(Q110<=87,"LESS")) -> OK
A115: Done by | B115: AKASH
A117: Comment

Sheet 06
A1: Station: | B1: IGKV RAIPUR
A2: Date: | B2: =$A$9 -> 45328.01 | C2: Power Off | G2: Pw.Off | J2: Link Fail | L2: Link F | N2: Maintenance | P2: Maint.
A3: Report Type: | B3: Mean | C3: Calibration | G3: Calib. | J3: Data Fail | L3: Data F | N3: Invalid | P3: Invalid
A4: Time Base: | B4: 15 Min | C4: Zero Referrence | G4: Z.Ref | J4: Warm Up | L4: Wm. Up
A7: Date & Time | B7: NO | C7: NO2 | D7: NOX | E7: SO2 | F7: O3 | G7: PM 10 | H7: PM 2.5 | I7: BENZ | J7: WS | K7: WD | L7: TEMP | M7: HUM | N7: SR | O7: RG | P7: CO | Q7: NH3
B8: ug/m3 | C8: ug/m3 | D8: ppb | E8: ug/m3 | F8: ug/m3 | G8: ug/m3 | H8: ug/m3 | I8: ug/m3 | J8: m/sec | K8: deg | L8: degreC | M8: % | N8: w/m2 | O8: mm | P8: mg/m3 | Q8: ug/m3
A9: 45328.01 | B9: 8.72 | C9: 18.51 | D9: 18.01 | E9: 6.51 | F9: 3.18 | G9: 74.89 | H9: 31.33 | I9: 0 | J9: 0.13 | K9: 179.39 | L9: 21.51 | M9: 83.01 | N9: 0 | O9: 0 | P9: 0.86 | Q9: 4.73
A10: 45328.021 | B10: 9.22 | C10: 16.21 | D10: 17.22 | E10: 6.38 | F10: 3.5 | G10: 72.47 | H10: 31.34 | I10: 0 | J10: 0.09 | K10: 144.77 | L10: 21.35 | M10: 81.84 | N10: 0 | O10: 0 | P10: 0.85 | Q10: 4.73
A11: 45328.031 | B11: 9.4 | C11: 15 | D11: 16.72 | E11: 5.72 | F11: 3.43 | G11: 72.47 | H11: 31.34 | I11: 0 | J11: 0.11 | K11: 145.9 | L11: 21.38 | M11: 80.41 | N11: 0 | O11: 0 | P11: 0.84 | Q11: 4.75
A12: 45328.042 | B12: 9.51 | C12: 15.45 | D12: 17.05 | E12: 6.19 | F12: 3.39 | G12: 72.47 | H12: 31.34 | I12: 0 | J12: 0.08 | K12: 152.57 | L12: 21.23 | M12: 82.45 | N12: 0 | O12: 0 | P12: 0.84 | Q12: 4.73
A13: 45328.052 | B13: 9.58 | C13: 16.81 | D13: 17.82 | E13: 5.7 | F13: 3.23 | G13: 67.51 | H13: 29.88 | I13: 0 | J13: 0.08 | K13: 200.41 | L13: 21.11 | M13: 81.85 | N13: 0 | O13: 0 | P13: 0.84 | Q13: 4.75
A14: 45328.062 | B14: 9.75 | C14: 17.17 | D14: 18.14 | E14: 6.24 | F14: 3.25 | G14: 63.71 | H14: 29.41 | I14: 0 | J14: 0.11 | K14: 157.14 | L14: 21.26 | M14: 81.41 | N14: 0 | O14: 0 | P14: 0.84 | Q14: 4.75
A15: 45328.073 | B15: 9.9 | C15: 15.91 | D15: 17.6 | E15: 5.61 | F15: 3.55 | G15: 63.71 | H15: 29.41 | I15: 0 | J15: 0.05 | K15: 148.28 | L15: 21.29 | M15: 80.44 | N15: 0 | O15: 0 | P15: 0.83 | Q15: 4.76
A16: 45328.083 | B16: 9.97 | C16: 14.38 | D16: 16.86 | E16: 5.88 | F16: 3.65 | G16: 63.71 | H16: 29.41 | I16: 0 | J16: 0.06 | K16: 159.76 | L16: 21.23 | M16: 80.03 | N16: 0 | O16: 0 | P16: 0.82 | Q16: 4.76
A17: 45328.094 | B17: 9.96 | C17: 14.48 | D17: 16.91 | E17: 5.89 | F17: 3.43 | G17: 54.9 | H17: 28.43 | I17: 0 | J17: 0.12 | K17: 168.65 | L17: 21.16 | M17: 81.47 | N17: 0 | O17: 0 | P17: 0.81 | Q17: 4.75
A18: 45328.104 | B18: 10.04 | C18: 15.52 | D18: 17.51 | E18: 7.32 | F18: 3.32 | G18: 48.16 | H18: 27.82 | I18: 0 | J18: 0.14 | K18: 162.21 | L18: 20.93 | M18: 83.54 | N18: 0 | O18: 0 | P18: 0.81 | Q18: 4.76
A19: 45328.115 | B19: 10.08 | C19: 16.52 | D19: 18.07 | E19: 7.43 | F19: 3.2 | G19: 48.16 | H19: 27.82 | I19: 0 | J19: 0.14 | K19: 155.58 | L19: 20.78 | M19: 83.93 | N19: 0 | O19: 0 | P19: 0.81 | Q19: 4.73
A20: 45328.125 | B20: 10.13 | C20: 16.94 | D20: 18.33 | E20: 7.7 | F20: 3.26 | G20: 48.16 | H20: 27.82 | I20: 0 | J20: 0.14 | K20: 158.7 | L20: 20.76 | M20: 83.99 | N20: 0 | O20: 0 | P20: 0.8 | Q20: 4.75
... A104: 45329 | B104: 19.26 | C104: 22.9 | D104: 28.76 | E104: 6.26 | F104: 3.52 | G104: 101.15 | H104: 36.32 | I104: 0 | J104: 0.96 | K104: 54.01 | L104: 22.42 | M104: 67.55 | N104: 0 | O104: 0 | P104: 0.84 | Q104: 4.91
A106: Min | B106: =MIN(B9:B104) -> 4.75 | C106: =MIN(C9:C104) -> 14.38 | D106: =MIN(D9:D104) -> 13.53 | E106: =MIN(E9:E104) -> 5.61 | F106: =MIN(F9:F104) -> 3.13 | G106: =MIN(G9:G104) -> 41.2 | H106: =MIN(H9:H104) -> 19.18 | I106: =MIN(I9:I104) -> 0 | ... Q106: =MIN(Q9:Q104) -> 4.65
A107: Max | B107: =MAX(B9:B104) -> 21.2 | C107: =MAX(C9:C104) -> 24.14 | D107: =MAX(D9:D104) -> 29.54 | E107: =MAX(E9:E104) -> 10.86 | F107: =MAX(F9:F104) -> 12.06 | G107: =MAX(G9:G104) -> 111.73 | H107: =MAX(H9:H104) -> 37.22 | I107: =MAX(I9:I104) -> 0 | ... Q107: =MAX(Q9:Q104) -> 4.94
A108: Avg | B108: =AVERAGE(B9:B104) -> 11.308646 | C108: =AVERAGE(C9:C104) -> 18.202396 | D108: =AVERAGE(D9:D104) -> 19.930521 | E108: =AVERAGE(E9:E104) -> 7.7535417 | F108: =AVERAGE(F9:F104) -> 4.9288542 | G108: =AVERAGE(G9:G104) -> 62.23375 | H108: =AVERAGE(H9:H104) -> 27.188333 | I108: =AVERAGE(I9:I104) -> 0 | ... Q108: =AVERAGE(Q9:Q104) -> 4.7635417
A109: Stdev | B109: =STDEV(B9:B104) -> 5.0813483 | C109: =STDEV(C9:C104) -> 2.8298297 | D109: =STDEV(D9:D104) -> 5.1976937 | E109: =STDEV(E9:E104) -> 1.4264295 | F109: =STDEV(F9:F104) -> 2.4879613 | G109: =STDEV(G9:G104) -> 18.915315 | H109: =STDEV(H9:H104) -> 4.4227987 | I109: =STDEV(I9:I104) -> 0 | ... Q109: =STDEV(Q9:Q104) -> 0.062153954
A110: Num | B110: =COUNT(B9:B104) -> 96 | C110: =COUNT(C9:C104) -> 96 | D110: =COUNT(D9:D104) -> 96 | E110: =COUNT(E9:E104) -> 96 | F110: =COUNT(F9:F104) -> 96 | G110: =COUNT(G9:G104) -> 96 | H110: =COUNT(H9:H104) -> 96 | I110: =COUNT(I9:I104) -> 96 | ... Q110: =COUNT(Q9:Q104) -> 96
A111: DCR | B111: =IF(B110>=87,">90%",IF(B110<=87,"<90%")) -> >90% | C111: =IF(C110>=87,">90%",IF(C110<=87,"<90%")) -> >90% | D111: =IF(D110>=87,">90%",IF(D110<=87,"<90%")) -> >90% | E111: =IF(E110>=87,">90%",IF(E110<=87,"<90%")) -> >90% | F111: =IF(F110>=87,">90%",IF(F110<=87,"<90%")) -> >90% | G111: =IF(G110>=87,">90%",IF(G110<=87,"<90%")) -> >90% | H111: =IF(H110>=87,">90%",IF(H110<=87,"<90%")) -> >90% | I111: =IF(I110>=87,">90%",IF(I110<=87,"<90%")) -> >90% | ... Q111: =IF(Q110>=87,">90%",IF(Q110<=87,"<90%")) -> >90%
A112: Status | B112: =IF(B110>=87,"OK",IF(B110<=87,"LESS")) -> OK | C112: =IF(C110>=87,"OK",IF(C110<=87,"LESS")) -> OK | D112: =IF(D110>=87,"OK",IF(D110<=87,"LESS")) -> OK | E112: =IF(E110>=87,"OK",IF(E110<=87,"LESS")) -> OK | F112: =IF(F110>=87,"OK",IF(F110<=87,"LESS")) -> OK | G112: =IF(G110>=87,"OK",IF(G110<=87,"LESS")) -> OK | H112: =IF(H110>=87,"OK",IF(H110<=87,"LESS")) -> OK | I112: =IF(I110>=87,"OK",IF(I110<=87,"LESS")) -> OK | ... Q112: =IF(Q110>=87,"OK",IF(Q110<=87,"LESS")) -> OK
A115: Done by | B115: AKASH
A117: Comment

Sheet 07
A1: Station: | B1: IGKV RAIPUR
A2: Date: | B2: =$A$9 -> 45329.01 | C2: Power Off | G2: Pw.Off | J2: Link Fail | L2: Link F | N2: Maintenance | P2: Maint.
A3: Report Type: | B3: Mean | C3: Calibration | G3: Calib. | J3: Data Fail | L3: Data F | N3: Invalid | P3: Invalid
A4: Time Base: | B4: 15 Min | C4: Zero Referrence | G4: Z.Ref | J4: Warm Up | L4: Wm. Up
A7: Date & Time | B7: NO | C7: NO2 | D7: NOX | E7: SO2 | F7: O3 | G7: PM 10 | H7: PM 2.5 | I7: BENZ | J7: WS | K7: WD | L7: TEMP | M7: HUM | N7: SR | O7: RG | P7: CO | Q7: NH3
B8: ug/m3 | C8: ug/m3 | D8: ppb | E8: ug/m3 | F8: ug/m3 | G8: ug/m3 | H8: ug/m3 | I8: ug/m3 | J8: m/sec | K8: deg | L8: degreC | M8: % | N8: w/m2 | O8: mm | P8: mg/m3 | Q8: ug/m3
A9: 45329.01 | B9: 17.2 | C9: 23.58 | D9: 27.47 | E9: 6.92 | F9: 3.53 | G9: 91.55 | H9: 33.06 | I9: 0 | J9: 1.14 | K9: 47.75 | L9: 22.22 | M9: 68.57 | N9: 0 | O9: 0 | P9: 0.83 | Q9: 4.91
A10: 45329.021 | B10: 16.89 | C10: 23.69 | D10: 27.27 | E10: 6.2 | F10: 3.45 | G10: 84.2 | H10: 32.04 | I10: 0 | J10: 1.26 | K10: 49.01 | L10: 21.99 | M10: 69.61 | N10: 0 | O10: 0 | P10: 0.81 | Q10: 4.9
A11: 45329.031 | B11: 16.38 | C11: 23.79 | D11: 26.92 | E11: 6.38 | F11: 3.44 | G11: 84.2 | H11: 32.04 | I11: 0 | J11: 1.2 | K11: 55.12 | L11: 21.76 | M11: 70.72 | N11: 0 | O11: 0 | P11: 0.79 | Q11: 4.89
A12: 45329.042 | B12: 15.85 | C12: 24.15 | D12: 26.68 | E12: 6.29 | F12: 3.32 | G12: 84.2 | H12: 32.04 | I12: 0 | J12: 1.16 | K12: 56.95 | L12: 21.53 | M12: 71.71 | N12: 0 | O12: 0 | P12: 0.76 | Q12: 4.88
A13: 45329.052 | B13: 15.1 | C13: 24.29 | D13: 26.15 | E13: 6.32 | F13: 3.35 | G13: 74.86 | H13: 30.84 | I13: 0 | J13: 0.97 | K13: 50.49 | L13: 21.38 | M13: 72.38 | N13: 0 | O13: 0 | P13: 0.76 | Q13: 4.89
A14: 45329.062 | B14: 14.37 | C14: 24.2 | D14: 25.52 | E14: 6.25 | F14: 3.34 | G14: 67.72 | H14: 30.45 | I14: 0 | J14: 1.29 | K14: 56.23 | L14: 21.23 | M14: 73.07 | N14: 0 | O14: 0 | P14: 0.74 | Q14: 4.87
A15: 45329.073 | B15: 13.68 | C15: 24.16 | D15: 24.95 | E15: 6.32 | F15: 3.39 | G15: 67.72 | H15: 30.45 | I15: 0 | J15: 1.04 | K15: 54.75 | L15: 21.07 | M15: 73.75 | N15: 0 | O15: 0 | P15: 0.74 | Q15: 4.86
A16: 45329.083 | B16: 13.07 | C16: 24.17 | D16: 24.46 | E16: 6.1 | F16: 3.35 | G16: 67.72 | H16: 30.45 | I16: 0 | J16: 0.92 | K16: 59.74 | L16: 20.89 | M16: 74.58 | N16: 0 | O16: 0 | P16: 0.73 | Q16: 4.83
A17: 45329.094 | B17: 12.7 | C17: 24.34 | D17: 24.25 | E17: 5.64 | F17: 3.45 | G17: 62.47 | H17: 30.64 | I17: 0 | J17: 0.3 | K17: 73.29 | L17: 20.78 | M17: 75.28 | N17: 0 | O17: 0 | P17: 0.71 | Q17: 4.82
A18: 45329.104 | B18: 12.41 | C18: 24.2 | D18: 23.94 | E18: 6.37 | F18: 3.33 | G18: 58.45 | H18: 30.75 | I18: 0 | J18: 0.13 | K18: 161.95 | L18: 20.68 | M18: 77.23 | N18: 0 | O18: 0 | P18: 0.7 | Q18: 4.81
A19: 45329.115 | B19: 11.96 | C19: 24.04 | D19: 23.5 | E19: 6.55 | F19: 3.31 | G19: 58.45 | H19: 30.75 | I19: 0 | J19: 0.37 | K19: 81.07 | L19: 20.79 | M19: 75.77 | N19: 0 | O19: 0 | P19: 0.7 | Q19: 4.8
A20: 45329.125 | B20: 11.76 | C20: 23.89 | D20: 23.26 | E20: 6.29 | F20: 3.2 | G20: 58.45 | H20: 30.75 | I20: 0 | J20: 0.43 | K20: 74.64 | L20: 20.66 | M20: 76.44 | N20: 0 | O20: 0 | P20: 0.67 | Q20: 4.79
... A104: 45330 | B104: 11.71 | C104: 24.77 | D104: 23.69 | E104: 9.66 | F104: 3.7 | G104: 100.58 | H104: 39.52 | I104: 0 | J104: 1.47 | K104: 51.84 | L104: 21.68 | M104: 49.81 | N104: 0 | O104: 0 | P104: 0.98 | Q104: 4.76
A106: Min | B106: =MIN(B9:B104) -> 4.21 | C106: =MIN(C9:C104) -> 13.07 | D106: =MIN(D9:D104) -> 11.73 | E106: =MIN(E9:E104) -> 5.2 | F106: =MIN(F9:F104) -> 3.05 | G106: =MIN(G9:G104) -> 58.45 | H106: =MIN(H9:H104) -> 27.59 | I106: =MIN(I9:I104) -> 0 | ... Q106: =MIN(Q9:Q104) -> 4.71
A107: Max | B107: =MAX(B9:B104) -> 19.49 | C107: =MAX(C9:C104) -> 26.94 | D107: =MAX(D9:D104) -> 28.98 | E107: =MAX(E9:E104) -> 10.36 | F107: =MAX(F9:F104) -> 9.19 | G107: =MAX(G9:G104) -> 100.58 | H107: =MAX(H9:H104) -> 39.59 | I107: =MAX(I9:I104) -> 0 | ... Q107: =MAX(Q9:Q104) -> 4.92
A108: Avg | B108: =AVERAGE(B9:B104) -> 11.400938 | C108: =AVERAGE(C9:C104) -> 20.679271 | D108: =AVERAGE(D9:D104) -> 21.298646 | E108: =AVERAGE(E9:E104) -> 7.6357292 | F108: =AVERAGE(F9:F104) -> 4.02875 | G108: =AVERAGE(G9:G104) -> 70.684062 | H108: =AVERAGE(H9:H104) -> 31.082083 | I108: =AVERAGE(I9:I104) -> 0 | ... Q108: =AVERAGE(Q9:Q104) -> 4.8046875
A109: Stdev | B109: =STDEV(B9:B104) -> 5.2877447 | C109: =STDEV(C9:C104) -> 4.0436441 | D109: =STDEV(D9:D104) -> 5.673989 | E109: =STDEV(E9:E104) -> 1.5355409 | F109: =STDEV(F9:F104) -> 1.1205292 | G109: =STDEV(G9:G104) -> 10.117465 | H109: =STDEV(H9:H104) -> 3.2111683 | I109: =STDEV(I9:I104) -> 0 | ... Q109: =STDEV(Q9:Q104) -> 0.058055384
A110: Num | B110: =COUNT(B9:B104) -> 96 | C110: =COUNT(C9:C104) -> 96 | D110: =COUNT(D9:D104) -> 96 | E110: =COUNT(E9:E104) -> 96 | F110: =COUNT(F9:F104) -> 96 | G110: =COUNT(G9:G104) -> 96 | H110: =COUNT(H9:H104) -> 96 | I110: =COUNT(I9:I104) -> 96 | ... Q110: =COUNT(Q9:Q104) -> 96
A111: DCR | B111: =IF(B110>=87,">90%",IF(B110<=87,"<90%")) -> >90% | C111: =IF(C110>=87,">90%",IF(C110<=87,"<90%")) -> >90% | D111: =IF(D110>=87,">90%",IF(D110<=87,"<90%")) -> >90% | E111: =IF(E110>=87,">90%",IF(E110<=87,"<90%")) -> >90% | F111: =IF(F110>=87,">90%",IF(F110<=87,"<90%")) -> >90% | G111: =IF(G110>=87,">90%",IF(G110<=87,"<90%")) -> >90% | H111: =IF(H110>=87,">90%",IF(H110<=87,"<90%")) -> >90% | I111: =IF(I110>=87,">90%",IF(I110<=87,"<90%")) -> >90% | ... Q111: =IF(Q110>=87,">90%",IF(Q110<=87,"<90%")) -> >90%
A112: Status | B112: =IF(B110>=87,"OK",IF(B110<=87,"LESS")) -> OK | C112: =IF(C110>=87,"OK",IF(C110<=87,"LESS")) -> OK | D112: =IF(D110>=87,"OK",IF(D110<=87,"LESS")) -> OK | E112: =IF(E110>=87,"OK",IF(E110<=87,"LESS")) -> OK | F112: =IF(F110>=87,"OK",IF(F110<=87,"LESS")) -> OK | G112: =IF(G110>=87,"OK",IF(G110<=87,"LESS")) -> OK | H112: =IF(H110>=87,"OK",IF(H110<=87,"LESS")) -> OK | I112: =IF(I110>=87,"OK",IF(I110<=87,"LESS")) -> OK | ... Q112: =IF(Q110>=87,"OK",IF(Q110<=87,"LESS")) -> OK
A115: Done by | B115: AKASH
A117: Comment

Sheet 08
A1: Station: | B1: IGKV RAIPUR
A2: Date: | B2: =$A$9 -> 45330.01 | C2: Power Off | G2: Pw.Off | J2: Link Fail | L2: Link F | N2: Maintenance | P2: Maint.
A3: Report Type: | B3: Mean | C3: Calibration | G3: Calib. | J3: Data Fail | L3: Data F | N3: Invalid | P3: Invalid
A4: Time Base: | B4: 15 Min | C4: Zero Referrence | G4: Z.Ref | J4: Warm Up | L4: Wm. Up
A7: Date & Time | B7: NO | C7: NO2 | D7: NOX | E7: SO2 | F7: O3 | G7: PM 10 | H7: PM 2.5 | I7: BENZ | J7: WS | K7: WD | L7: TEMP | M7: HUM | N7: SR | O7: RG | P7: CO | Q7: NH3
B8: ug/m3 | C8: ug/m3 | D8: ppb | E8: ug/m3 | F8: ug/m3 | G8: ug/m3 | H8: ug/m3 | I8: ug/m3 | J8: m/sec | K8: deg | L8: degreC | M8: % | N8: w/m2 | O8: mm | P8: mg/m3 | Q8: ug/m3
A9: 45330.01 | B9: 11.63 | C9: 20.67 | D9: 21.48 | E9: 9.29 | F9: 3.82 | G9: 90.4 | H9: 32.04 | I9: 0 | J9: 0.96 | K9: 50.38 | L9: 21.44 | M9: 47.78 | N9: 0 | O9: 0 | P9: 0.95 | Q9: 4.76
A10: 45330.021 | B10: 11.7 | C10: 19.71 | D10: 21.03 | E10: 8.74 | F10: 3.65 | G10: 82.61 | H10: 29.69 | I10: 0 | J10: 1.1 | K10: 50.81 | L10: 21.22 | M10: 47 | N10: 0 | O10: 0 | P10: 0.91 | Q10: 4.74
A11: 45330.031 | B11: 11.68 | C11: 19.15 | D11: 20.72 | E11: 8.67 | F11: 3.61 | G11: 82.61 | H11: 29.69 | I11: 0 | J11: 1.41 | K11: 55.38 | L11: 21.04 | M11: 46.06 | N11: 0 | O11: 0 | P11: 0.89 | Q11: 4.76
A12: 45330.042 | B12: 11.61 | C12: 19.65 | D12: 20.93 | E12: 8.43 | F12: 3.4 | G12: 82.61 | H12: 29.69 | I12: 0 | J12: 1.15 | K12: 48.84 | L12: 20.83 | M12: 45.54 | N12: 0 | O12: 0 | P12: 0.87 | Q12: 4.75
A13: 45330.052 | B13: 11.33 | C13: 20.76 | D13: 21.28 | E13: 8.55 | F13: 3.3 | G13: 71.4 | H13: 25.87 | I13: 0 | J13: 0.97 | K13: 47.47 | L13: 20.6 | M13: 45.94 | N13: 0 | O13: 0 | P13: 0.87 | Q13: 4.78
A14: 45330.062 | B14: 11.2 | C14: 21.14 | D14: 21.38 | E14: 9.15 | F14: 3.29 | G14: 62.83 | H14: 24.64 | I14: 0 | J14: 0.43 | K14: 47.22 | L14: 20.32 | M14: 47.01 | N14: 0 | O14: 0 | P14: 0.84 | Q14: 4.78
A15: 45330.073 | B15: 11.4 | C15: 21.27 | D15: 21.6 | E15: 8.98 | F15: 3.31 | G15: 62.83 | H15: 24.64 | I15: 0 | J15: 0.56 | K15: 42.9 | L15: 20.1 | M15: 47.84 | N15: 0 | O15: 0 | P15: 0.82 | Q15: 4.77
A16: 45330.083 | B16: 11.61 | C16: 19.76 | D16: 20.98 | E16: 8.01 | F16: 3.5 | G16: 62.83 | H16: 24.64 | I16: 0 | J16: 0.65 | K16: 49.22 | L16: 19.93 | M16: 48.08 | N16: 0 | O16: 0 | P16: 0.8 | Q16: 4.79
A17: 45330.094 | B17: 11.77 | C17: 18.47 | D17: 20.44 | E17: 5.51 | F17: 3.46 | G17: 57.93 | H17: 23.68 | I17: 0 | J17: 0.57 | K17: 37.04 | L17: 19.79 | M17: 48.18 | N17: 0 | O17: 0 | P17: 0.77 | Q17: 4.81
A18: 45330.104 | B18: 11.88 | C18: 18.62 | D18: 20.61 | E18: 6.03 | F18: 3.37 | G18: 54.18 | H18: 23.09 | I18: 0 | J18: 0.53 | K18: 41.91 | L18: 19.67 | M18: 48.35 | N18: 0 | O18: 0 | P18: 0.75 | Q18: 4.81
A19: 45330.115 | B19: 11.92 | C19: 19.64 | D19: 21.17 | E19: 6.06 | F19: 3.28 | G19: 54.18 | H19: 23.09 | I19: 0 | J19: 0.53 | K19: 38.65 | L19: 19.52 | M19: 48.76 | N19: 0 | O19: 0 | P19: 0.75 | Q19: 4.82
A20: 45330.125 | B20: 11.99 | C20: 20.13 | D20: 21.49 | E20: 6.36 | F20: 3.2 | G20: 54.18 | H20: 23.09 | I20: 0 | J20: 0.55 | K20: 35.8 | L20: 19.4 | M20: 48.96 | N20: 0 | O20: 0 | P20: 0.73 | Q20: 4.84
... A61: 45330.552 | B61: 5.78 | C61: 18.29 | D61: 15.54 | E61: 10.62 | F61: 10.07 | G61: 52.76 | H61: 15.06 | I61: 0 | J61: 1.42 | K61: 52.94 | L61: 26.13 | M61: 24.48 | N61: 561.8 | O61: 0 | P61: 0.49 | Q61: 4.81
A62: 45330.562 | B62: Calib. | C62: Calib. | D62: Calib. | E62: Calib. | F62: Calib. | G62: Calib. | H62: Calib. | I62: 0 | J62: 1.6 | K62: 52.42 | L62: 26.27 | M62: 24.09 | N62: 533.6 | O62: 0 | P62: Calib. | Q62: 4.81
A63: 45330.573 | B63: Calib. | C63: Calib. | D63: Calib. | E63: Calib. | F63: Calib. | G63: Calib. | H63: Calib. | I63: 3.77 | J63: 1.06 | K63: 27.22 | L63: 26.33 | M63: 24 | N63: 532.1 | O63: 0 | P63: Calib. | Q63: 4.8
A64: 45330.583 | B64: Calib. | C64: Calib. | D64: Calib. | E64: Calib. | F64: Calib. | G64: Calib. | H64: Calib. | I64: 8.49 | J64: 1.64 | K64: 53.05 | L64: 26.48 | M64: 24 | N64: 522.7 | O64: 0 | P64: Calib. | Q64: 4.8
A65: 45330.594 | B65: Calib. | C65: Calib. | D65: Calib. | E65: Calib. | F65: Calib. | G65: Calib. | H65: Calib. | I65: 13.51 | J65: 1.21 | K65: 34.9 | L65: 26.51 | M65: 24.35 | N65: 489.4 | O65: 0 | P65: Calib. | Q65: 4.8
A66: 45330.604 | B66: Calib. | C66: Calib. | D66: Calib. | E66: Calib. | F66: 6.37 | G66: Calib. | H66: Calib. | I66: 21.07 | J66: 1.14 | K66: 31.34 | L66: 26.64 | M66: 24.67 | N66: 463.7 | O66: 0 | P66: Calib. | Q66: 4.78
A67: 45330.615 | B67: Calib. | C67: Calib. | D67: Calib. | E67: Calib. | F67: 7.93 | G67: Calib. | H67: Calib. | I67: 30.63 | J67: 1.04 | K67: 337.36 | L67: 26.62 | M67: 24.85 | N67: 404.5 | O67: 0 | P67: 0.41 | Q67: 4.79
A68: 45330.625 | B68: Calib. | C68: Calib. | D68: Calib. | E68: Calib. | F68: 10.1 | G68: Calib. | H68: Calib. | I68: 41.67 | J68: 0.98 | K68: 346.48 | L68: 26.1 | M68: 25.53 | N68: 146.9 | O68: 0 | P68: 0.44 | Q68: 4.8
A69: 45330.635 | B69: 6.11 | C69: 22.34 | D69: 17.92 | E69: Calib. | F69: 10.26 | G69: Calib. | H69: Calib. | I69: 47.85 | J69: 0.98 | K69: 344.64 | L69: 26.01 | M69: 25.98 | N69: 93.3 | O69: 0 | P69: 0.43 | Q69: 4.8
A70: 45330.646 | B70: 6.6 | C70: 22.42 | D70: 18.36 | E70: Calib. | F70: 10.2 | G70: Calib. | H70: Calib. | I70: 53.09 | J70: 0.82 | K70: 4.2 | L70: 25.84 | M70: 26.4 | N70: 93.2 | O70: 0 | P70: 0.42 | Q70: 4.82
A71: 45330.656 | B71: 6.73 | C71: 22.19 | D71: 18.35 | E71: 16.25 | F71: 9.07 | G71: 27.9 | H71: 1.13 | I71: 62.52 | J71: 0.58 | K71: 17.26 | L71: 25.77 | M71: 26.78 | N71: 76.5 | O71: 0 | P71: 0.43 | Q71: 4.8
A72: 45330.667 | B72: 5.77 | C72: 22.92 | D72: 17.95 | E72: 11.85 | F72: 8.85 | G72: 27.9 | H72: 0 | I72: 71 | J72: 0.63 | K72: 16.87 | L72: 25.87 | M72: 27.25 | N72: 70.4 | O72: 0 | P72: 0.42 | Q72: 4.79
A73: 45330.677 | B73: 6.69 | C73: 26.61 | D73: 20.62 | E73: 14.5 | F73: 14.56 | G73: 27.9 | H73: 1.13 | I73: 41.98 | J73: 1.11 | K73: 52.04 | L73: 25.65 | M73: 27.75 | N73: 66.1 | O73: 0 | P73: 0.43 | Q73: 4.8
A74: 45330.688 | B74: 6.09 | C74: 27.34 | D74: 20.53 | E74: 12.09 | F74: 12.8 | G74: 27.9 | H74: 1.13 | I74: 0 | J74: 0.54 | K74: 25.7 | L74: 25.69 | M74: 27.91 | N74: 58.4 | O74: 0 | P74: 0.43 | Q74: 4.82
A75: 45330.698 | B75: 7.03 | C75: 27.15 | D75: 21.17 | E75: 11.03 | F75: 9.7 | G75: 34.78 | H75: 2.57 | I75: 0 | J75: 0.92 | K75: 39.89 | L75: 25.54 | M75: 28.42 | N75: 53.5 | O75: 0 | P75: 0.43 | Q75: 4.79
A76: 45330.708 | B76: 8.83 | C76: 34.02 | D76: 26.21 | E76: 12 | F76: 8.97 | G76: 41.35 | H76: 3.24 | I76: 0 | J76: 0.62 | K76: 39.83 | L76: 25.45 | M76: 28.99 | N76: 39.7 | O76: 0 | P76: 0.45 | Q76: 4.8
A77: 45330.719 | B77: 8.09 | C77: 33.36 | D77: 25.27 | E77: 9.03 | F77: 6.52 | G77: 41.35 | H77: 3.24 | I77: 12.59 | J77: 0.63 | K77: 51.45 | L77: 25.24 | M77: 29.69 | N77: 19.7 | O77: 0 | P77: 0.46 | Q77: 4.83
A78: 45330.729 | B78: 7.86 | C78: 32.41 | D78: 24.59 | E78: 8.69 | F78: 5.56 | G78: 41.35 | H78: 3.24 | I78: 26.46 | J78: 0.58 | K78: 56.48 | L78: 25.04 | M78: 30.91 | N78: 6.6 | O78: 0 | P78: 0.49 | Q78: 4.83
A79: 45330.74 | B79: 8.1 | C79: 32.48 | D79: 24.81 | E79: 8.29 | F79: 4.5 | G79: 51.43 | H79: 8.69 | I79: 22.98 | J79: 0.64 | K79: 61.13 | L79: 24.6 | M79: 32.18 | N79: 0.1 | O79: 0 | P79: 0.52 | Q79: 4.84
A80: 45330.75 | B80: 8.81 | C80: 32.1 | D80: 25.19 | E80: 7.44 | F80: 3.88 | G80: 61.07 | H80: 11.23 | I80: 21.09 | J80: 0.41 | K80: 73.15 | L80: 24.13 | M80: 34.19 | N80: 0 | O80: 0 | P80: 0.53 | Q80: 4.82
A81: 45330.76 | B81: 9.46 | C81: 31.61 | D81: 25.45 | E81: 5.22 | F81: 3.8 | G81: 61.07 | H81: 11.23 | I81: 20.45 | J81: 0.26 | K81: 167.1 | L81: 22.9 | M81: 41.75 | N81: 0 | O81: 0 | P81: 0.55 | Q81: 4.82
A82: 45330.771 | B82: 9.64 | C82: 30.81 | D82: 25.18 | E82: 5.61 | F82: 3.86 | G82: 61.07 | H82: 11.23 | I82: 20.04 | J82: 0.27 | K82: 183.27 | L82: 22.19 | M82: 45.61 | N82: 0 | O82: 0 | P82: 0.55 | Q82: 4.79
...

Sheet 09
A1: Station: | B1: IGKV RAIPUR
A2: Date: | B2: =$A$9 -> 45331.01 | C2: Power Off | G2: Pw.Off | J2: Link Fail | L2: Link F | N2: Maintenance | P2: Maint.
A3: Report Type: | B3: Mean | C3: Calibration | G3: Calib. | J3: Data Fail | L3: Data F | N3: Invalid | P3: Invalid
A4: Time Base: | B4: 15 Min | C4: Zero Referrence | G4: Z.Ref | J4: Warm Up | L4: Wm. Up
A7: Date & Time | B7: NO | C7: NO2 | D7: NOX | E7: SO2 | F7: O3 | G7: PM 10 | H7: PM 2.5 | I7: BENZ | J7: WS | K7: WD | L7: TEMP | M7: HUM | N7: SR | O7: RG | P7: CO | Q7: NH3
B8: ug/m3 | C8: ug/m3 | D8: ppb | E8: ug/m3 | F8: ug/m3 | G8: ug/m3 | H8: ug/m3 | I8: ug/m3 | J8: m/sec | K8: deg | L8: degreC | M8: % | N8: w/m2 | O8: mm | P8: mg/m3 | Q8: ug/m3
A9: 45331.01 | B9: 28.24 | C9: 26.54 | D9: 37.87 | E9: 5.99 | F9: 3.18 | G9: 113.16 | H9: 38.27 | I9: 13.44 | J9: 0.44 | K9: 45.79 | L9: 18.32 | M9: 59.71 | N9: 0 | O9: 0 | P9: 0.9 | Q9: 4.92
A10: 45331.021 | B10: 29.55 | C10: 26.88 | D10: 39.09 | E10: 6.68 | F10: 3.4 | G10: 113.16 | H10: 38.27 | I10: 13.41 | J10: 0.66 | K10: 54.65 | L10: 18.22 | M10: 60.48 | N10: 0 | O10: 0 | P10: 0.91 | Q10: 4.96
A11: 45331.031 | B11: 30.14 | C11: 27.51 | D11: 39.89 | E11: 5.95 | F11: 3.35 | G11: 120.1 | H11: 39.41 | I11: 13.44 | J11: 0.55 | K11: 36.74 | L11: 18.23 | M11: 60.27 | N11: 0 | O11: 0 | P11: 0.93 | Q11: 4.99
A12: 45331.042 | B12: 30.16 | C12: 27.64 | D12: 39.98 | E12: 5.96 | F12: 3.4 | G12: 126.74 | H12: 39.94 | I12: 13.35 | J12: 0.52 | K12: 36.11 | L12: 18.04 | M12: 61.05 | N12: 0 | O12: 0 | P12: 0.92 | Q12: 4.97
A13: 45331.052 | B13: 30.06 | C13: 27.9 | D13: 40.03 | E13: 6.16 | F13: 3.49 | G13: 126.74 | H13: 39.94 | I13: 13.16 | J13: 0.45 | K13: 39.82 | L13: 17.88 | M13: 61.37 | N13: 0 | O13: 0 | P13: 0.9 | Q13: 4.96
A14: 45331.062 | B14: 29.77 | C14: 27.94 | D14: 39.82 | E14: 6.31 | F14: 3.34 | G14: 126.74 | H14: 39.94 | I14: 12.94 | J14: 0.61 | K14: 57.83 | L14: 17.75 | M14: 59.81 | N14: 0 | O14: 0 | P14: 0.9 | Q14: 4.98
A15: 45331.073 | B15: 28.97 | C15: 28.1 | D15: 39.26 | E15: 6.48 | F15: 3.48 | G15: 116.67 | H15: 37.82 | I15: 12.65 | J15: 0.78 | K15: 52.54 | L15: 17.64 | M15: 59.09 | N15: 0 | O15: 0 | P15: 0.89 | Q15: 4.97
A16: 45331.083 | B16: 28.21 | C16: 28.11 | D16: 38.66 | E16: 6.25 | F16: 3.42 | G16: 107.04 | H16: 36.84 | I16: 12.3 | J16: 0.62 | K16: 42.98 | L16: 17.43 | M16: 59.59 | N16: 0 | O16: 0 | P16: 0.88 | Q16: 4.96
A17: 45331.094 | B17: 27.45 | C17: 28.13 | D17: 38.06 | E17: 7.7 | F17: 3.41 | G17: 107.04 | H17: 36.84 | I17: 11.99 | J17: 0.52 | K17: 32.34 | L17: 17.17 | M17: 59.53 | N17: 0 | O17: 0 | P17: 0.85 | Q17: 4.97
A18: 45331.104 | B18: 26.51 | C18: 28.1 | D18: 37.29 | E18: 8.85 | F18: 3.57 | G18: 107.04 | H18: 36.84 | I18: 11.65 | J18: 0.62 | K18: 29.3 | L18: 17.06 | M18: 58.84 | N18: 0 | O18: 0 | P18: 0.83 | Q18: 4.95
A19: 45331.115 | B19: 25.9 | C19: 28.13 | D19: 36.82 | E19: 9.86 | F19: 3.45 | G19: 97.59 | H19: 35.48 | I19: 11.31 | J19: 0.63 | K19: 50.65 | L19: 16.91 | M19: 58.73 | N19: 0 | O19: 0 | P19: 0.82 | Q19: 4.94
A20: 45331.125 | B20: 25.32 | C20: 28.14 | D20: 36.36 | E20: 9.26 | F20: 3.41 | G20: 88.55 | H20: 34.13 | I20: 11.05 | J20: 0.61 | K20: 49.93 | L20: 16.72 | M20: 59.73 | N20: 0 | O20: 0 | P20: 0.8 | Q20: 4.92
... A104: 45332 | B104: 23.52 | C104: 32.43 | D104: 37.16 | E104: 8.7 | F104: 3.26 | G104: 95.22 | H104: 34.58 | I104: 0 | J104: 0.13 | K104: 191.77 | L104: 16.82 | M104: 65.52 | N104: 0 | O104: 0 | P104: 0.8 | Q104: 4.94
A106: Min | B106: =MIN(B9:B104) -> 6.08 | C106: =MIN(C9:C104) -> 18.78 | D106: =MIN(D9:D104) -> 16.17 | E106: =MIN(E9:E104) -> 5.95 | F106: =MIN(F9:F104) -> 3.18 | G106: =MIN(G9:G104) -> 42.86 | H106: =MIN(H9:H104) -> 17.65 | I106: =MIN(I9:I104) -> 0 | ... Q106: =MIN(Q9:Q104) -> 4.72
A107: Max | B107: =MAX(B9:B104) -> 30.16 | C107: =MAX(C9:C104) -> 32.43 | D107: =MAX(D9:D104) -> 40.03 | E107: =MAX(E9:E104) -> 10.81 | F107: =MAX(F9:F104) -> 6.6 | G107: =MAX(G9:G104) -> 126.74 | H107: =MAX(H9:H104) -> 39.94 | I107: =MAX(I9:I104) -> 13.44 | ... Q107: =MAX(Q9:Q104) -> 4.99
A108: Avg | B108: =AVERAGE(B9:B104) -> 16.30875 | C108: =AVERAGE(C9:C104) -> 25.259687 | D108: =AVERAGE(D9:D104) -> 27.627083 | E108: =AVERAGE(E9:E104) -> 8.1694792 | F108: =AVERAGE(F9:F104) -> 3.9583333 | G108: =AVERAGE(G9:G104) -> 77.108125 | H108: =AVERAGE(H9:H104) -> 26.790104 | I108: =AVERAGE(I9:I104) -> 4.6246875 | ... Q108: =AVERAGE(Q9:Q104) -> 4.8442708
A109: Stdev | B109: =STDEV(B9:B104) -> 7.5272331 | C109: =STDEV(C9:C104) -> 3.3372956 | D109: =STDEV(D9:D104) -> 7.4395117 | E109: =STDEV(E9:E104) -> 1.1354687 | F109: =STDEV(F9:F104) -> 0.87698127 | G109: =STDEV(G9:G104) -> 21.782126 | H109: =STDEV(H9:H104) -> 6.469865 | I109: =STDEV(I9:I104) -> 5.044748 | ... Q109: =STDEV(Q9:Q104) -> 0.075487814
A110: Num | B110: =COUNT(B9:B104) -> 96 | C110: =COUNT(C9:C104) -> 96 | D110: =COUNT(D9:D104) -> 96 | E110: =COUNT(E9:E104) -> 96 | F110: =COUNT(F9:F104) -> 96 | G110: =COUNT(G9:G104) -> 96 | H110: =COUNT(H9:H104) -> 96 | I110: =COUNT(I9:I104) -> 96 | ... Q110: =COUNT(Q9:Q104) -> 96
A111: DCR | B111: =IF(B110>=87,">90%",IF(B110<=87,"<90%")) -> >90% | C111: =IF(C110>=87,">90%",IF(C110<=87,"<90%")) -> >90% | D111: =IF(D110>=87,">90%",IF(D110<=87,"<90%")) -> >90% | E111: =IF(E110>=87,">90%",IF(E110<=87,"<90%")) -> >90% | F111: =IF(F110>=87,">90%",IF(F110<=87,"<90%")) -> >90% | G111: =IF(G110>=87,">90%",IF(G110<=87,"<90%")) -> >90% | H111: =IF(H110>=87,">90%",IF(H110<=87,"<90%")) -> >90% | I111: =IF(I110>=87,">90%",IF(I110<=87,"<90%")) -> >90% | ... Q111: =IF(Q110>=87,">90%",IF(Q110<=87,"<90%")) -> >90%
A112: Status | B112: =IF(B110>=87,"OK",IF(B110<=87,"LESS")) -> OK | C112: =IF(C110>=87,"OK",IF(C110<=87,"LESS")) -> OK | D112: =IF(D110>=87,"OK",IF(D110<=87,"LESS")) -> OK | E112: =IF(E110>=87,"OK",IF(E110<=87,"LESS")) -> OK | F112: =IF(F110>=87,"OK",IF(F110<=87,"LESS")) -> OK | G112: =IF(G110>=87,"OK",IF(G110<=87,"LESS")) -> OK | H112: =IF(H110>=87,"OK",IF(H110<=87,"LESS")) -> OK | I112: =IF(I110>=87,"OK",IF(I110<=87,"LESS")) -> OK | ... Q112: =IF(Q110>=87,"OK",IF(Q110<=87,"LESS")) -> OK
A115: Done by | B115: AKASH
A117: Comment

Sheet 10
A1: Station: | B1: IGKV RAIPUR
A2: Date: | B2: =$A$9 -> 45332.01 | C2: Power Off | G2: Pw.Off | J2: Link Fail | L2: Link F | N2: Maintenance | P2: Maint.
A3: Report Type: | B3: Mean | C3: Calibration | G3: Calib. | J3: Data Fail | L3: Data F | N3: Invalid | P3: Invalid
A4: Time Base: | B4: 15 Min | C4: Zero Referrence | G4: Z.Ref | J4: Warm Up | L4: Wm. Up
A7: Date & Time | B7: NO | C7: NO2 | D7: NOX | E7: SO2 | F7: O3 | G7: PM 10 | H7: PM 2.5 | I7: BENZ | J7: WS | K7: WD | L7: TEMP | M7: HUM | N7: SR | O7: RG | P7: CO | Q7: NH3
B8: ug/m3 | C8: ug/m3 | D8: ppb | E8: ug/m3 | F8: ug/m3 | G8: ug/m3 | H8: ug/m3 | I8: ug/m3 | J8: m/sec | K8: deg | L8: degreC | M8: % | N8: w/m2 | O8: mm | P8: mg/m3 | Q8: ug/m3
A9: 45332.01 | B9: 24.3 | C9: 32.45 | D9: 37.79 | E9: 8.31 | F9: 3.34 | G9: 95.22 | H9: 34.58 | I9: 0 | J9: 0.13 | K9: 202.24 | L9: 16.71 | M9: 65.07 | N9: 0 | O9: 0 | P9: 0.82 | Q9: 4.94
A10: 45332.021 | B10: 26.77 | C10: 32.98 | D10: 40.05 | E10: 7.47 | F10: 3.42 | G10: 95.22 | H10: 34.58 | I10: 0 | J10: 0.11 | K10: 215.74 | L10: 16.57 | M10: 68.7 | N10: 0 | O10: 0 | P10: 0.82 | Q10: 4.96
A11: 45332.031 | B11: 28.84 | C11: 33.32 | D11: 41.89 | E11: 7.99 | F11: 3.52 | G11: 93.52 | H11: 34.4 | I11: 0 | J11: 0.14 | K11: 222.56 | L11: 16.38 | M11: 66.63 | N11: 0 | O11: 0 | P11: 0.82 | Q11: 4.98
A12: 45332.042 | B12: 31.92 | C12: 33.9 | D12: 44.66 | E12: 8.61 | F12: 3.39 | G12: 91.89 | H12: 34.32 | I12: 0 | J12: 0.17 | K12: 170.81 | L12: 16.39 | M12: 67.15 | N12: 0 | O12: 0 | P12: 0.83 | Q12: 4.99
A13: 45332.052 | B13: 34.64 | C13: 34.2 | D13: 47 | E13: 7.64 | F13: 3.41 | G13: 91.89 | H13: 34.32 | I13: 0 | J13: 0.21 | K13: 165.16 | L13: 16.21 | M13: 68.92 | N13: 0 | O13: 0 | P13: 0.84 | Q13: 5.01
A14: 45332.062 | B14: 36.3 | C14: 32.78 | D14: 47.59 | E14: 7.54 | F14: 3.5 | G14: 91.89 | H14: 34.32 | I14: 0 | J14: 0.36 | K14: 50.04 | L14: 16.51 | M14: 60.36 | N14: 0 | O14: 0 | P14: 0.84 | Q14: 5
A15: 45332.073 | B15: 36.65 | C15: 30.64 | D15: 46.75 | E15: 7.74 | F15: 3.59 | G15: 92.73 | H15: 34.85 | I15: 0 | J15: 0.59 | K15: 53.03 | L15: 17.06 | M15: 54.86 | N15: 0 | O15: 0 | P15: 0.82 | Q15: 5.02
A16: 45332.083 | B16: 35.61 | C16: 31.59 | D16: 46.41 | E16: 7.33 | F16: 3.32 | G16: 93.53 | H16: 35.1 | I16: 0 | J16: 0.48 | K16: 37.35 | L16: 17.04 | M16: 55.34 | N16: 0 | O16: 0 | P16: 0.81 | Q16: 5.04
A17: 45332.094 | B17: 34.09 | C17: 30.83 | D17: 44.79 | E17: 5.78 | F17: 3.32 | G17: 93.53 | H17: 35.1 | I17: 0 | J17: 0.16 | K17: 179.95 | L17: 16.7 | M17: 59.67 | N17: 0 | O17: 0 | P17: 0.82 | Q17: 5.02
A18: 45332.104 | B18: 32.49 | C18: 30.49 | D18: 43.33 | E18: 7.05 | F18: 3.32 | G18: 93.53 | H18: 35.1 | I18: 0 | J18: 0.23 | K18: 34.4 | L18: 16.22 | M18: 62.59 | N18: 0 | O18: 0 | P18: 0.81 | Q18: 5.01
A19: 45332.115 | B19: 31.75 | C19: 30.97 | D19: 42.99 | E19: 6.96 | F19: 3.27 | G19: 92.55 | H19: 35.47 | I19: 0 | J19: 0.13 | K19: 98.2 | L19: 16.42 | M19: 61.28 | N19: 0 | O19: 0 | P19: 0.83 | Q19: 5.01
A20: 45332.125 | B20: 31.23 | C20: 31.02 | D20: 42.6 | E20: 6.71 | F20: 3.25 | G20: 91.6 | H20: 35.85 | I20: 0 | J20: 0.17 | K20: 93.34 | L20: 15.97 | M20: 65.87 | N20: 0 | O20: 0 | P20: 0.82 | Q20: 5
... A104: 45333 | B104: 9.15 | C104: 23.82 | D104: 21.13 | E104: 7.96 | F104: 3.73 | G104: 103.98 | H104: 43.91 | I104: 6.99 | J104: 0.22 | K104: 163.62 | L104: 20.87 | M104: 52.85 | N104: 0 | O104: 0 | P104: 0.85 | Q104: 4.78
A106: Min | B106: =MIN(B9:B104) -> 1.61 | C106: =MIN(C9:C104) -> 16.42 | D106: =MIN(D9:D104) -> 12.09 | E106: =MIN(E9:E104) -> 5.23 | F106: =MIN(F9:F104) -> 3.12 | G106: =MIN(G9:G104) -> 53.17 | H106: =MIN(H9:H104) -> 23.87 | I106: =MIN(I9:I104) -> 0 | ... Q106: =MIN(Q9:Q104) -> 4.71
