Workbook

Sheet 01
A1: Station: | B1: BHATAGAON RAIPUR
A2: Date: | B2: =$A$9 -> 45809.01 | D2: Power Off | G2: Pw.Off | L2: Link Fail | N2: Link F | P2: Maintenance | R2: Maint.
A3: Report Type: | B3: Mean | D3: Calibration | G3: Calib. | L3: Data Fail | N3: Data F | P3: Invalid | R3: Invalid
A4: Time Base: | B4: 15 Min | D4: Zero Referrence | G4: Z.Ref | L4: Warm Up | N4: Wm. Up
A7: Date & Time | B7: NO_BHATAGAON | C7: NO2__BHATAGAON | D7: NOX_BHATAGAON | E7: SO2__BHATAGAON | F7: O3__BHATAGAON | G7: PM10__BHATAGAON | H7: PM2_5__BHATAGAON | I7: BENZ__BHATAGAON | J7: WS__BHATAGAON | K7: WD__BHATAGAON | L7: TEMP__BHATAGAON | M7: HUM__BHATAGAON | N7: SR__BHATAGAON | O7: RG__BHATAGAON | P7: CO__BHATAGAON | Q7: NH3__BHATAGAON
B8: ug/m3 | C8: ug/m3 | D8: ppb | E8: ug/m3 | F8: ug/m3 | G8: ug/m3 | H8: ug/m3 | I8: ug/m3 | J8: m/sec | K8: deg | L8: degreC | M8: % | N8: w/m2 | O8: mm | P8: mg/m3 | Q8: ug/m3
A9: 45809.01 | B9: 11.32 | C9: 19.37 | D9: 19.7 | E9: 4.72 | F9: 4.83 | G9: 55.16 | H9: 9.02 | I9: 4.04 | J9: 0.11 | K9: 113.75 | L9: 25.27 | M9: 100.82 | N9: 26.3 | O9: 0 | P9: 0.61 | Q9: 9.41
A10: 45809.021 | B10: 11.23 | C10: 21.31 | D10: 23.55 | E10: 4.94 | F10: 5.58 | G10: 52.72 | H10: 7.82 | I10: 4.02 | J10: 0.3 | K10: 0.95 | L10: 25.23 | M10: 100.83 | N10: 26.3 | O10: 0 | P10: 0.56 | Q10: 9.4
A11: 45809.031 | B11: 12.33 | C11: 20.83 | D11: 20.95 | E11: 4.82 | F11: 5.58 | G11: 52.72 | H11: 7.82 | I11: 3.96 | J11: 0.18 | K11: 359.43 | L11: 25.15 | M11: 100.84 | N11: 26.3 | O11: 0 | P11: 0.62 | Q11: 9.4
A12: 45809.042 | B12: 11.07 | C12: 20.1 | D12: 21.49 | E12: 4.8 | F12: 6.88 | G12: 52.72 | H12: 7.82 | I12: 3.97 | J12: 0.17 | K12: 344.1 | L12: 25.09 | M12: 100.89 | N12: 26.2 | O12: 0 | P12: 0.58 | Q12: 9.41
A13: 45809.052 | B13: 11.45 | C13: 19.73 | D13: 20.19 | E13: 4.77 | F13: 5.49 | G13: 52.29 | H13: 18.36 | I13: 3.84 | J13: 0.07 | K13: 333.48 | L13: 25.03 | M13: 100.9 | N13: 26.3 | O13: 0 | P13: 0.59 | Q13: 9.4
A14: 45809.062 | B14: 9.81 | C14: 18.26 | D14: 19.89 | E14: 4.82 | F14: 6.01 | G14: 52.1 | H14: 22.87 | I14: 4 | J14: 0.02 | K14: 151.84 | L14: 24.92 | M14: 100.91 | N14: 26.2 | O14: 0 | P14: 0.57 | Q14: 9.41
A15: 45809.073 | B15: 19.46 | C15: 32.39 | D15: 32.14 | E15: 4.75 | F15: 5.56 | G15: 52.1 | H15: 22.87 | I15: 3.99 | J15: 0.04 | K15: 268.04 | L15: 24.9 | M15: 100.93 | N15: 26.3 | O15: 0 | P15: 0.62 | Q15: 9.41
A16: 45809.083 | B16: 10.49 | C16: 25.85 | D16: 33.38 | E16: 4.4 | F16: 4.32 | G16: 52.1 | H16: 22.87 | I16: 3.99 | J16: 0.06 | K16: 82.48 | L16: 24.86 | M16: 100.93 | N16: 26.2 | O16: 0 | P16: 0.6 | Q16: 9.43
A17: 45809.094 | B17: 30.05 | C17: 42.95 | D17: 36.09 | E17: 4.58 | F17: 4.24 | G17: 49.02 | H17: 17.84 | I17: 4.06 | J17: 0.09 | K17: 216.4 | L17: 24.81 | M17: 100.98 | N17: 26.1 | O17: 0 | P17: 0.59 | Q17: 9.45
A18: 45809.104 | B18: 18.35 | C18: 32.49 | D18: 34.01 | E18: 4.77 | F18: 4.14 | G18: 47.63 | H18: 15.68 | I18: 4.08 | J18: 0.07 | K18: 263.22 | L18: 24.69 | M18: 101.02 | N18: 26.2 | O18: 0 | P18: 0.62 | Q18: 9.48
A19: 45809.115 | B19: 36.39 | C19: 48.39 | D19: 36.77 | E19: 4.81 | F19: 3.59 | G19: 47.63 | H19: 15.68 | I19: 3.98 | J19: 0.07 | K19: 319.24 | L19: 24.64 | M19: 101.04 | N19: 26.2 | O19: 0 | P19: 0.63 | Q19: 9.52
A20: 45809.125 | B20: 27.91 | C20: 39.47 | D20: 32.7 | E20: 5.21 | F20: 3.86 | G20: 47.63 | H20: 15.68 | I20: 3.98 | J20: 0.26 | K20: 163.75 | L20: 24.65 | M20: 101.03 | N20: 26 | O20: 0 | P20: 0.63 | Q20: 9.56
... A104: 45810 | B104: 6.4 | C104: 19.79 | D104: 28.05 | E104: 4.65 | F104: 11.89 | G104: 58.65 | H104: 81.05 | I104: 3.82 | J104: 0.05 | K104: 233.72 | L104: 26.48 | M104: 61.86 | N104: 26.5 | O104: 0 | P104: 0.28 | Q104: 9.37
A106: Min | B106: =MIN(B9:B104) -> 4.16 | C106: =MIN(C9:C104) -> 16.23 | D106: =MIN(D9:D104) -> 18.43 | E106: =MIN(E9:E104) -> 3.67 | F106: =MIN(F9:F104) -> 3.43 | G106: =MIN(G9:G104) -> 42.12 | H106: =MIN(H9:H104) -> 0 | I106: =MIN(I9:I104) -> 3.82 | ... Q106: =MIN(Q9:Q104) -> 9.13
A107: Max | B107: =MAX(B9:B104) -> 36.39 | C107: =MAX(C9:C104) -> 48.39 | D107: =MAX(D9:D104) -> 41.66 | E107: =MAX(E9:E104) -> 5.33 | F107: =MAX(F9:F104) -> 13.03 | G107: =MAX(G9:G104) -> 65.13 | H107: =MAX(H9:H104) -> 311.8 | I107: =MAX(I9:I104) -> 4.24 | ... Q107: =MAX(Q9:Q104) -> 9.63
A108: Avg | B108: =AVERAGE(B9:B104) -> 10.478437 | C108: =AVERAGE(C9:C104) -> 22.752813 | D108: =AVERAGE(D9:D104) -> 27.465521 | E108: =AVERAGE(E9:E104) -> 4.5585417 | F108: =AVERAGE(F9:F104) -> 6.5555208 | G108: =AVERAGE(G9:G104) -> 55.482083 | H108: =AVERAGE(H9:H104) -> 33.968854 | I108: =AVERAGE(I9:I104) -> 4.0120833 | ... Q108: =AVERAGE(Q9:Q104) -> 9.3453125
A109: Stdev | B109: =STDEV(B9:B104) -> 6.208637 | C109: =STDEV(C9:C104) -> 5.3814083 | D109: =STDEV(D9:D104) -> 5.200472 | E109: =STDEV(E9:E104) -> 0.37513781 | F109: =STDEV(F9:F104) -> 2.3336824 | G109: =STDEV(G9:G104) -> 7.5905487 | H109: =STDEV(H9:H104) -> 63.36741 | I109: =STDEV(I9:I104) -> 0.077227165 | ... Q109: =STDEV(Q9:Q104) -> 0.17055916
A110: Num | B110: =COUNT(B9:B104) -> 96 | C110: =COUNT(C9:C104) -> 96 | D110: =COUNT(D9:D104) -> 96 | E110: =COUNT(E9:E104) -> 96 | F110: =COUNT(F9:F104) -> 96 | G110: =COUNT(G9:G104) -> 96 | H110: =COUNT(H9:H104) -> 96 | I110: =COUNT(I9:I104)+1 -> 97 | J110: =COUNT(J9:J104) -> 96 | K110: =COUNT(K9:K104) -> 96 | L110: =COUNT(L9:L104) -> 96 | M110: =COUNT(M9:M104) -> 96 | N110: =COUNT(N9:N104) -> 96 | O110: =COUNT(O9:O104) -> 96 | P110: =COUNT(P9:P104) -> 96 | Q110: =COUNT(Q9:Q104) -> 96
A111: DCR | B111: =IF(B110>=87,">90%",IF(B110<=87,"<90%")) -> >90% | C111: =IF(C110>=87,">90%",IF(C110<=87,"<90%")) -> >90% | D111: =IF(D110>=87,">90%",IF(D110<=87,"<90%")) -> >90% | E111: =IF(E110>=87,">90%",IF(E110<=87,"<90%")) -> >90% | F111: =IF(F110>=87,">90%",IF(F110<=87,"<90%")) -> >90% | G111: =IF(G110>=87,">90%",IF(G110<=87,"<90%")) -> >90% | H111: =IF(H110>=87,">90%",IF(H110<=87,"<90%")) -> >90% | I111: =IF(I110>=87,">90%",IF(I110<=87,"<90%")) -> >90% | ... Q111: =IF(Q110>=87,">90%",IF(Q110<=87,"<90%")) -> >90%
A112: Status | B112: =IF(B110>=87,"OK",IF(B110<=87,"LESS")) -> OK | C112: =IF(C110>=87,"OK",IF(C110<=87,"LESS")) -> OK | D112: =IF(D110>=87,"OK",IF(D110<=87,"LESS")) -> OK | E112: =IF(E110>=87,"OK",IF(E110<=87,"LESS")) -> OK | F112: =IF(F110>=87,"OK",IF(F110<=87,"LESS")) -> OK | G112: =IF(G110>=87,"OK",IF(G110<=87,"LESS")) -> OK | H112: =IF(H110>=87,"OK",IF(H110<=87,"LESS")) -> OK | I112: =IF(I110>=87,"OK",IF(I110<=87,"LESS")) -> OK | ... Q112: =IF(Q110>=87,"OK",IF(Q110<=87,"LESS")) -> OK
A115: Done by | B115: RK
A117: Comment

Sheet 02
A1: Station: | B1: BHATAGAON RAIPUR
A2: Date: | B2: =$A$9 -> 45810.01 | D2: Power Off | G2: Pw.Off | L2: Link Fail | N2: Link F | P2: Maintenance | R2: Maint.
A3: Report Type: | B3: Mean | D3: Calibration | G3: Calib. | L3: Data Fail | N3: Data F | P3: Invalid | R3: Invalid
A4: Time Base: | B4: 15 Min | D4: Zero Referrence | G4: Z.Ref | L4: Warm Up | N4: Wm. Up
A7: Date & Time | B7: NO_BHATAGAON | C7: NO2__BHATAGAON | D7: NOX_BHATAGAON | E7: SO2__BHATAGAON | F7: O3__BHATAGAON | G7: PM10__BHATAGAON | H7: PM2_5__BHATAGAON | I7: BENZ__BHATAGAON | J7: WS__BHATAGAON | K7: WD__BHATAGAON | L7: TEMP__BHATAGAON | M7: HUM__BHATAGAON | N7: SR__BHATAGAON | O7: RG__BHATAGAON | P7: CO__BHATAGAON | Q7: NH3__BHATAGAON
B8: ug/m3 | C8: ug/m3 | D8: ppb | E8: ug/m3 | F8: ug/m3 | G8: ug/m3 | H8: ug/m3 | I8: ug/m3 | J8: m/sec | K8: deg | L8: degreC | M8: % | N8: w/m2 | O8: mm | P8: mg/m3 | Q8: ug/m3
A9: 45810.01 | B9: 8.22 | C9: 24.82 | D9: 34.9 | E9: 4 | F9: 9.08 | G9: 54.69 | H9: 89.89 | I9: 3.91 | J9: 0.04 | K9: 278.29 | L9: 26.43 | M9: 61.99 | N9: 26.3 | O9: 0 | P9: 0.28 | Q9: 9.38
A10: 45810.021 | B10: 7.66 | C10: 20.6 | D10: 27.66 | E10: 4.42 | F10: 10.86 | G10: 52.99 | H10: 93.68 | I10: 3.98 | J10: 0.14 | K10: 147.23 | L10: 26.41 | M10: 60.97 | N10: 26.2 | O10: 0 | P10: 0.28 | Q10: 9.4
A11: 45810.031 | B11: 7.11 | C11: 18.62 | D11: 24.73 | E11: 4.67 | F11: 11.58 | G11: 52.99 | H11: 93.68 | I11: 3.94 | J11: 0.13 | K11: 169.09 | L11: 26.04 | M11: 62.75 | N11: 26.6 | O11: 0 | P11: 0.26 | Q11: 9.42
A12: 45810.042 | B12: 7.36 | C12: 18.71 | D12: 24.52 | E12: 4.45 | F12: 11.08 | G12: 52.99 | H12: 93.68 | I12: 4.05 | J12: 0.03 | K12: 176.05 | L12: 25.76 | M12: 63.51 | N12: 26.5 | O12: 0 | P12: 0.26 | Q12: 9.41
A13: 45810.052 | B13: 7.01 | C13: 17.55 | D13: 22.83 | E13: 4.58 | F13: 12.2 | G13: 50.76 | H13: 39.98 | I13: 4.1 | J13: 0.08 | K13: 226.81 | L13: 25.41 | M13: 63.86 | N13: 26.5 | O13: 0 | P13: 0.2 | Q13: 9.43
A14: 45810.062 | B14: 7.9 | C14: 17.59 | D14: 21.54 | E14: 4.69 | F14: 11.24 | G14: 49.75 | H14: 16.96 | I14: 3.99 | J14: 0.07 | K14: 290.77 | L14: 25.26 | M14: 64 | N14: 26.3 | O14: 0 | P14: 0.26 | Q14: 9.43
A15: 45810.073 | B15: 10.74 | C15: 19.37 | D15: 20.59 | E15: 4.52 | F15: 4.95 | G15: 49.75 | H15: 16.96 | I15: 4.01 | J15: 0.07 | K15: 294.77 | L15: 25.52 | M15: 60.58 | N15: 26.1 | O15: 0 | P15: 0.33 | Q15: 9.42
A16: 45810.083 | B16: 11.51 | C16: 20.25 | D16: 21.09 | E16: 4.62 | F16: 5.92 | G16: 49.75 | H16: 16.96 | I16: 3.93 | J16: 0.05 | K16: 311.93 | L16: 25.56 | M16: 60.72 | N16: 26.4 | O16: 0 | P16: 0.31 | Q16: 9.4
A17: 45810.094 | B17: 12.18 | C17: 20.99 | D17: 21.5 | E17: 4.55 | F17: 4.84 | G17: 48.77 | H17: 13.75 | I17: 4.14 | J17: 0.12 | K17: 282.59 | L17: 25.2 | M17: 62.17 | N17: 26.2 | O17: 0 | P17: 0.33 | Q17: 9.39
A18: 45810.104 | B18: 12.05 | C18: 20.82 | D18: 21.35 | E18: 4.23 | F18: 4.83 | G18: 48.32 | H18: 12.3 | I18: 4.03 | J18: 0.08 | K18: 303.06 | L18: 25.22 | M18: 60.33 | N18: 26.3 | O18: 0 | P18: 0.31 | Q18: 9.38
A19: 45810.115 | B19: 11.74 | C19: 20.71 | D19: 21.63 | E19: 4.66 | F19: 4.98 | G19: 48.32 | H19: 12.3 | I19: 4.05 | J19: 0.08 | K19: 291.04 | L19: 25.03 | M19: 61.87 | N19: 26.4 | O19: 0 | P19: 0.3 | Q19: 9.38
A20: 45810.125 | B20: 11.63 | C20: 20.74 | D20: 21.85 | E20: 4.22 | F20: 4.75 | G20: 48.32 | H20: 12.3 | I20: 4.04 | J20: 0.07 | K20: 290.71 | L20: 24.94 | M20: 62.22 | N20: 26.4 | O20: 0 | P20: 0.31 | Q20: 9.37
... A104: 45811 | B104: 8.33 | C104: 18.32 | D104: 22.28 | E104: 4.24 | F104: 6.52 | G104: 32.83 | H104: 50.8 | I104: 3.86 | J104: 0.18 | K104: 175.96 | L104: 27.04 | M104: 67.03 | N104: 26.6 | O104: 0 | P104: 0.32 | Q104: 9.36
A106: Min | B106: =MIN(B9:B104) -> 4.06 | C106: =MIN(C9:C104) -> 17.11 | D106: =MIN(D9:D104) -> 20.59 | E106: =MIN(E9:E104) -> 3.96 | F106: =MIN(F9:F104) -> 3.25 | G106: =MIN(G9:G104) -> 0 | H106: =MIN(H9:H104) -> -63.1 | I106: =MIN(I9:I104) -> 3.8 | ... Q106: =MIN(Q9:Q104) -> 9.14
A107: Max | B107: =MAX(B9:B104) -> 16.55 | C107: =MAX(C9:C104) -> 45.97 | D107: =MAX(D9:D104) -> 74.3 | E107: =MAX(E9:E104) -> 6.04 | F107: =MAX(F9:F104) -> 22.6 | G107: =MAX(G9:G104) -> 54.69 | H107: =MAX(H9:H104) -> 545.31 | I107: =MAX(I9:I104) -> 4.29 | ... Q107: =MAX(Q9:Q104) -> 9.52
A108: Avg | B108: =AVERAGE(B9:B104) -> 8.1029167 | C108: =AVERAGE(C9:C104) -> 21.839687 | D108: =AVERAGE(D9:D104) -> 29.365417 | E108: =AVERAGE(E9:E104) -> 4.9811458 | F108: =AVERAGE(F9:F104) -> 7.7716667 | G108: =AVERAGE(G9:G104) -> 36.715729 | H108: =AVERAGE(H9:H104) -> 45.188021 | I108: =AVERAGE(I9:I104) -> 4.02 | ... Q108: =AVERAGE(Q9:Q104) -> 9.3202083
A109: Stdev | B109: =STDEV(B9:B104) -> 3.5176334 | C109: =STDEV(C9:C104) -> 4.1238925 | D109: =STDEV(D9:D104) -> 8.0320472 | E109: =STDEV(E9:E104) -> 0.50729182 | F109: =STDEV(F9:F104) -> 3.764795 | G109: =STDEV(G9:G104) -> 10.863792 | H109: =STDEV(H9:H104) -> 106.68133 | I109: =STDEV(I9:I104) -> 0.091156315 | ... Q109: =STDEV(Q9:Q104) -> 0.10867604
A110: Num | B110: =COUNT(B9:B104) -> 96 | C110: =COUNT(C9:C104) -> 96 | D110: =COUNT(D9:D104) -> 96 | E110: =COUNT(E9:E104) -> 96 | F110: =COUNT(F9:F104) -> 96 | G110: =COUNT(G9:G104) -> 96 | H110: =COUNT(H9:H104) -> 96 | I110: =COUNT(I9:I104)+22 -> 118 | J110: =COUNT(J9:J104) -> 96 | K110: =COUNT(K9:K104) -> 96 | L110: =COUNT(L9:L104) -> 96 | M110: =COUNT(M9:M104) -> 96 | N110: =COUNT(N9:N104) -> 96 | O110: =COUNT(O9:O104) -> 96 | P110: =COUNT(P9:P104) -> 96 | Q110: =COUNT(Q9:Q104) -> 96
A111: DCR | B111: =IF(B110>=87,">90%",IF(B110<=87,"<90%")) -> >90% | C111: =IF(C110>=87,">90%",IF(C110<=87,"<90%")) -> >90% | D111: =IF(D110>=87,">90%",IF(D110<=87,"<90%")) -> >90% | E111: =IF(E110>=87,">90%",IF(E110<=87,"<90%")) -> >90% | F111: =IF(F110>=87,">90%",IF(F110<=87,"<90%")) -> >90% | G111: =IF(G110>=87,">90%",IF(G110<=87,"<90%")) -> >90% | H111: =IF(H110>=87,">90%",IF(H110<=87,"<90%")) -> >90% | I111: =IF(I110>=87,">90%",IF(I110<=87,"<90%")) -> >90% | ... Q111: =IF(Q110>=87,">90%",IF(Q110<=87,"<90%")) -> >90%
A112: Status | B112: =IF(B110>=87,"OK",IF(B110<=87,"LESS")) -> OK | C112: =IF(C110>=87,"OK",IF(C110<=87,"LESS")) -> OK | D112: =IF(D110>=87,"OK",IF(D110<=87,"LESS")) -> OK | E112: =IF(E110>=87,"OK",IF(E110<=87,"LESS")) -> OK | F112: =IF(F110>=87,"OK",IF(F110<=87,"LESS")) -> OK | G112: =IF(G110>=87,"OK",IF(G110<=87,"LESS")) -> OK | H112: =IF(H110>=87,"OK",IF(H110<=87,"LESS")) -> OK | I112: =IF(I110>=87,"OK",IF(I110<=87,"LESS")) -> OK | ... Q112: =IF(Q110>=87,"OK",IF(Q110<=87,"LESS")) -> OK
A115: Done by | B115: RK
A117: Comment

Sheet 03
A1: Station: | B1: BHATAGAON RAIPUR
A2: Date: | B2: =$A$9 -> 45811.01 | D2: Power Off | G2: Pw.Off | L2: Link Fail | N2: Link F | P2: Maintenance | R2: Maint.
A3: Report Type: | B3: Mean | D3: Calibration | G3: Calib. | L3: Data Fail | N3: Data F | P3: Invalid | R3: Invalid
A4: Time Base: | B4: 15 Min | D4: Zero Referrence | G4: Z.Ref | L4: Warm Up | N4: Wm. Up
A7: Date & Time | B7: NO_BHATAGAON | C7: NO2__BHATAGAON | D7: NOX_BHATAGAON | E7: SO2__BHATAGAON | F7: O3__BHATAGAON | G7: PM10__BHATAGAON | H7: PM2_5__BHATAGAON | I7: BENZ__BHATAGAON | J7: WS__BHATAGAON | K7: WD__BHATAGAON | L7: TEMP__BHATAGAON | M7: HUM__BHATAGAON | N7: SR__BHATAGAON | O7: RG__BHATAGAON | P7: CO__BHATAGAON | Q7: NH3__BHATAGAON
B8: ug/m3 | C8: ug/m3 | D8: ppb | E8: ug/m3 | F8: ug/m3 | G8: ug/m3 | H8: ug/m3 | I8: ug/m3 | J8: m/sec | K8: deg | L8: degreC | M8: % | N8: w/m2 | O8: mm | P8: mg/m3 | Q8: ug/m3
A9: 45811.01 | B9: 7.82 | C9: 17.19 | D9: 20.89 | E9: 4.49 | F9: 6.47 | G9: 32.26 | H9: 29.47 | I9: 3.93 | J9: 0.07 | K9: 158.12 | L9: 26.85 | M9: 68.48 | N9: 26.5 | O9: 0 | P9: 0.3 | Q9: 9.35
A10: 45811.021 | B10: 9.03 | C10: 17.74 | D10: 20.1 | E10: 4.08 | F10: 5.44 | G10: 32.26 | H10: 29.47 | I10: 3.89 | J10: 0.15 | K10: 178.1 | L10: 26.65 | M10: 69.34 | N10: 26.6 | O10: 0 | P10: 0.32 | Q10: 9.34
A11: 45811.031 | B11: 7.94 | C11: 16.37 | D11: 19.15 | E11: 4.38 | F11: 7.38 | G11: 32.26 | H11: 29.47 | I11: 4.02 | J11: 0.07 | K11: 209.77 | L11: 26.49 | M11: 70.23 | N11: 26.7 | O11: 0 | P11: 0.27 | Q11: 9.34
A12: 45811.042 | B12: 8.28 | C12: 16.54 | D12: 18.95 | E12: 4.06 | F12: 6.52 | G12: 30.41 | H12: 11.13 | I12: 4.25 | J12: 0.03 | K12: 239.11 | L12: 26.25 | M12: 71.88 | N12: 26.8 | O12: 0 | P12: 0.3 | Q12: 9.32
A13: 45811.052 | B13: 7.75 | C13: 16.51 | D13: 19.71 | E13: 3.98 | F13: 6.16 | G13: 29.28 | H13: 0 | I13: 3.97 | J13: 0.09 | K13: 160.8 | L13: 26.08 | M13: 73.36 | N13: 26.5 | O13: 0 | P13: 0.25 | Q13: 9.33
A14: 45811.062 | B14: 7.97 | C14: 17.69 | D14: 21.61 | E14: 4 | F14: 5.97 | G14: 29.28 | H14: 0 | I14: 3.99 | J14: 0.2 | K14: 140.38 | L14: 26.04 | M14: 74.05 | N14: 26.3 | O14: 0 | P14: 0.29 | Q14: 9.33
A15: 45811.073 | B15: 8.62 | C15: 18.33 | D15: 21.85 | E15: 4.03 | F15: 5.24 | G15: 29.28 | H15: 0 | I15: 4 | J15: 0.11 | K15: 156.12 | L15: 25.97 | M15: 73.94 | N15: 26.4 | O15: 0 | P15: 0.28 | Q15: 9.33
A16: 45811.083 | B16: 7.87 | C16: 17.4 | D16: 21.22 | E16: 3.84 | F16: 6.7 | G16: 29.15 | H16: 146.2 | I16: 3.99 | J16: 0.07 | K16: 168.49 | L16: 25.97 | M16: 73.87 | N16: 26.4 | O16: 0 | P16: 0.27 | Q16: 9.33
A17: 45811.094 | B17: 8.28 | C17: 17.58 | D17: 20.94 | E17: 3.8 | F17: 5.95 | G17: 29.06 | H17: 234.97 | I17: 3.87 | J17: 0.18 | K17: 146.45 | L17: 25.9 | M17: 75.04 | N17: 26.3 | O17: 0 | P17: 0.26 | Q17: 9.34
A18: 45811.104 | B18: 6.34 | C18: 16.12 | D18: 21.12 | E18: 3.82 | F18: 8.79 | G18: 29.06 | H18: 234.97 | I18: 3.93 | J18: 0.04 | K18: 217.41 | L18: 25.84 | M18: 75.34 | N18: 26.5 | O18: 0 | P18: 0.23 | Q18: 9.37
A19: 45811.115 | B19: 6.18 | C19: 16.21 | D19: 21.55 | E19: 4.05 | F19: 8.22 | G19: 29.06 | H19: 234.97 | I19: 4.06 | J19: 0.05 | K19: 239.21 | L19: 25.74 | M19: 76.35 | N19: 26.5 | O19: 0 | P19: 0.23 | Q19: 9.38
A20: 45811.125 | B20: 6 | C20: 14.78 | D20: 19.09 | E20: 4.21 | F20: 8.94 | G20: 26.65 | H20: 121.24 | I20: 3.87 | J20: 0.08 | K20: 240.08 | L20: 25.57 | M20: 77.24 | N20: 26.5 | O20: 0 | P20: 0.21 | Q20: 9.4
... A104: 45812 | B104: 11.89 | C104: 24.6 | D104: 28.83 | E104: 4.71 | F104: 7.99 | G104: 52.87 | H104: 68.41 | I104: 3.98 | J104: 0.33 | K104: 302.17 | L104: 27.67 | M104: 59.16 | N104: 26.2 | O104: 0 | P104: 0.41 | Q104: 9.42
A106: Min | B106: =MIN(B9:B104) -> 4.43 | C106: =MIN(C9:C104) -> 14.59 | D106: =MIN(D9:D104) -> 18.01 | E106: =MIN(E9:E104) -> 3.74 | F106: =MIN(F9:F104) -> 3.91 | G106: =MIN(G9:G104) -> 20.74 | H106: =MIN(H9:H104) -> 0 | I106: =MIN(I9:I104) -> 3.7 | ... Q106: =MIN(Q9:Q104) -> 9.18
A107: Max | B107: =MAX(B9:B104) -> 16.21 | C107: =MAX(C9:C104) -> 37.09 | D107: =MAX(D9:D104) -> 53.95 | E107: =MAX(E9:E104) -> 5.78 | F107: =MAX(F9:F104) -> 14.85 | G107: =MAX(G9:G104) -> 55.55 | H107: =MAX(H9:H104) -> 341.83 | I107: =MAX(I9:I104) -> 4.25 | ... Q107: =MAX(Q9:Q104) -> 9.56
A108: Avg | B108: =AVERAGE(B9:B104) -> 8.3211458 | C108: =AVERAGE(C9:C104) -> 22.232292 | D108: =AVERAGE(D9:D104) -> 29.781042 | E108: =AVERAGE(E9:E104) -> 4.7264583 | F108: =AVERAGE(F9:F104) -> 7.2596875 | G108: =AVERAGE(G9:G104) -> 38.973438 | H108: =AVERAGE(H9:H104) -> 100.20635 | I108: =AVERAGE(I9:I104) -> 3.9816667 | ... Q108: =AVERAGE(Q9:Q104) -> 9.3236458
A109: Stdev | B109: =STDEV(B9:B104) -> 3.0451262 | C109: =STDEV(C9:C104) -> 4.411445 | D109: =STDEV(D9:D104) -> 7.3861669 | E109: =STDEV(E9:E104) -> 0.53750296 | F109: =STDEV(F9:F104) -> 2.49889 | G109: =STDEV(G9:G104) -> 10.020671 | H109: =STDEV(H9:H104) -> 102.4826 | I109: =STDEV(I9:I104) -> 0.090293867 | ... Q109: =STDEV(Q9:Q104) -> 0.10235254
A110: Num | B110: =COUNT(B9:B104)+44 -> 140 | C110: =COUNT(C9:C104)+44 -> 140 | D110: =COUNT(D9:D104)+44 -> 140 | E110: =COUNT(E9:E104)+44 -> 140 | F110: =COUNT(F9:F104)+44 -> 140 | G110: =COUNT(G9:G104)+44 -> 140 | H110: =COUNT(H9:H104)+44 -> 140 | I110: =COUNT(I9:I104)+44 -> 140 | ... P110: =COUNT(P9:P104)+44 -> 140 | Q110: =COUNT(Q9:Q104)+45 -> 141
A111: DCR | B111: =IF(B110>=87,">90%",IF(B110<=87,"<90%")) -> >90% | C111: =IF(C110>=87,">90%",IF(C110<=87,"<90%")) -> >90% | D111: =IF(D110>=87,">90%",IF(D110<=87,"<90%")) -> >90% | E111: =IF(E110>=87,">90%",IF(E110<=87,"<90%")) -> >90% | F111: =IF(F110>=87,">90%",IF(F110<=87,"<90%")) -> >90% | G111: =IF(G110>=87,">90%",IF(G110<=87,"<90%")) -> >90% | H111: =IF(H110>=87,">90%",IF(H110<=87,"<90%")) -> >90% | I111: =IF(I110>=87,">90%",IF(I110<=87,"<90%")) -> >90% | ... Q111: =IF(Q110>=87,">90%",IF(Q110<=87,"<90%")) -> >90%
A112: Status | B112: =IF(B110>=87,"OK",IF(B110<=87,"LESS")) -> OK | C112: =IF(C110>=87,"OK",IF(C110<=87,"LESS")) -> OK | D112: =IF(D110>=87,"OK",IF(D110<=87,"LESS")) -> OK | E112: =IF(E110>=87,"OK",IF(E110<=87,"LESS")) -> OK | F112: =IF(F110>=87,"OK",IF(F110<=87,"LESS")) -> OK | G112: =IF(G110>=87,"OK",IF(G110<=87,"LESS")) -> OK | H112: =IF(H110>=87,"OK",IF(H110<=87,"LESS")) -> OK | I112: =IF(I110>=87,"OK",IF(I110<=87,"LESS")) -> OK | ... Q112: =IF(Q110>=87,"OK",IF(Q110<=87,"LESS")) -> OK
A115: Done by | B115: RK
A117: Comment

Sheet 04
A1: Station: | B1: BHATAGAON RAIPUR
A2: Date: | B2: =$A$9 -> 45812.01 | D2: Power Off | G2: Pw.Off | L2: Link Fail | N2: Link F | P2: Maintenance | R2: Maint.
A3: Report Type: | B3: Mean | D3: Calibration | G3: Calib. | L3: Data Fail | N3: Data F | P3: Invalid | R3: Invalid
A4: Time Base: | B4: 15 Min | D4: Zero Referrence | G4: Z.Ref | L4: Warm Up | N4: Wm. Up
A7: Date & Time | B7: NO_BHATAGAON | C7: NO2__BHATAGAON | D7: NOX_BHATAGAON | E7: SO2__BHATAGAON | F7: O3__BHATAGAON | G7: PM10__BHATAGAON | H7: PM2_5__BHATAGAON | I7: BENZ__BHATAGAON | J7: WS__BHATAGAON | K7: WD__BHATAGAON | L7: TEMP__BHATAGAON | M7: HUM__BHATAGAON | N7: SR__BHATAGAON | O7: RG__BHATAGAON | P7: CO__BHATAGAON | Q7: NH3__BHATAGAON
B8: ug/m3 | C8: ug/m3 | D8: ppb | E8: ug/m3 | F8: ug/m3 | G8: ug/m3 | H8: ug/m3 | I8: ug/m3 | J8: m/sec | K8: deg | L8: degreC | M8: % | N8: w/m2 | O8: mm | P8: mg/m3 | Q8: ug/m3
A9: 45812.01 | B9: 11.51 | C9: 23.92 | D9: 28.12 | E9: 4.55 | F9: 6.86 | G9: 53.79 | H9: 40.15 | I9: 4.05 | J9: 0.17 | K9: 303.52 | L9: 27.7 | M9: 58.92 | N9: 26.4 | O9: 0 | P9: 0.44 | Q9: 9.42
A10: 45812.021 | B10: 10.79 | C10: 32.22 | D10: 45.11 | E10: 5.14 | F10: 7.98 | G10: 53.79 | H10: 40.15 | I10: 3.87 | J10: 0.12 | K10: 296.07 | L10: 27.68 | M10: 59.07 | N10: 26.5 | O10: 0 | P10: 0.53 | Q10: 9.45
A11: 45812.031 | B11: 9.91 | C11: 27.89 | D11: 38.17 | E11: 5.33 | F11: 7.98 | G11: 53.79 | H11: 40.15 | I11: 3.84 | J11: 0.16 | K11: 301.83 | L11: 27.71 | M11: 58.42 | N11: 26.3 | O11: 0 | P11: 0.6 | Q11: 9.46
A12: 45812.042 | B12: 8.79 | C12: 25.56 | D12: 35.44 | E12: 5.93 | F12: 8.49 | G12: 52.91 | H12: 8.5 | I12: 4.07 | J12: 0.08 | K12: 298.84 | L12: 27.75 | M12: 58.03 | N12: 26.5 | O12: 0 | P12: 0.76 | Q12: 9.48
A13: 45812.052 | B13: 7.4 | C13: 23.72 | D13: 34.04 | E13: 5.95 | F13: 11.02 | G13: 52.38 | H13: -10.72 | I13: 4.08 | J13: 0.12 | K13: 305.76 | L13: 27.49 | M13: 59.86 | N13: 26.7 | O13: 0 | P13: 0.69 | Q13: 9.48
A14: 45812.062 | B14: 6.81 | C14: 22.44 | D14: 32.5 | E14: 6.06 | F14: 11.06 | G14: 52.38 | H14: -10.72 | I14: 4.12 | J14: 0.08 | K14: 290.6 | L14: 27.22 | M14: 61.34 | N14: 26.6 | O14: 0 | P14: 0.68 | Q14: 9.48
A15: 45812.073 | B15: 6.92 | C15: 21.54 | D15: 30.6 | E15: 5.94 | F15: 9.6 | G15: 52.38 | H15: -10.72 | I15: 4.09 | J15: 0.44 | K15: 154.91 | L15: 27.28 | M15: 61.74 | N15: 26.2 | O15: 0 | P15: 0.66 | Q15: 9.49
A16: 45812.083 | B16: 8.1 | C16: 19.62 | D16: 25.11 | E16: 5.68 | F16: 10.83 | G16: 53.83 | H16: -16.94 | I16: 4.16 | J16: 0.36 | K16: 144.69 | L16: 26.83 | M16: 66.07 | N16: 26.8 | O16: 0 | P16: 0.54 | Q16: 9.49
A17: 45812.094 | B17: 9.21 | C17: 18.91 | D17: 22.05 | E17: 5.18 | F17: 6.61 | G17: 54.71 | H17: -20.72 | I17: 3.88 | J17: 0.18 | K17: 198.88 | L17: 26.47 | M17: 67.61 | N17: 26.7 | O17: 0 | P17: 0.48 | Q17: 9.49
A18: 45812.104 | B18: 9.56 | C18: 19.05 | D18: 21.8 | E18: 5.3 | F18: 8.04 | G18: 54.71 | H18: -20.72 | I18: 3.95 | J18: 0.05 | K18: 291.84 | L18: 26.22 | M18: 68.61 | N18: 26.8 | O18: 0 | P18: 0.4 | Q18: 9.46
A19: 45812.115 | B19: 10.29 | C19: 19.54 | D19: 21.61 | E19: 5.2 | F19: 6 | G19: 54.71 | H19: -20.72 | I19: 4.03 | J19: 0.19 | K19: 297.92 | L19: 26.09 | M19: 69.25 | N19: 26.4 | O19: 0 | P19: 0.45 | Q19: 9.43
A20: 45812.125 | B20: 10.09 | C20: 19.9 | D20: 22.6 | E20: 4.98 | F20: 6.4 | G20: 52.84 | H20: 24.43 | I20: 3.76 | J20: 0.14 | K20: 303.24 | L20: 25.97 | M20: 69.32 | N20: 26.5 | O20: 0 | P20: 0.45 | Q20: 9.41
... A104: 45813 | B104: 9.59 | C104: 22.02 | D104: 27.43 | E104: 5.21 | F104: 7.41 | G104: 51.51 | H104: 20.16 | I104: 4.03 | J104: 1.29 | K104: 339.38 | L104: 28.17 | M104: 58.13 | N104: 42.4 | O104: 0 | P104: 0.54 | Q104: 9.5
A106: Min | B106: =MIN(B9:B104) -> 3.75 | C106: =MIN(C9:C104) -> 18.91 | D106: =MIN(D9:D104) -> 21.61 | E106: =MIN(E9:E104) -> 4.55 | F106: =MIN(F9:F104) -> 3.63 | G106: =MIN(G9:G104) -> 40.33 | H106: =MIN(H9:H104) -> -20.72 | I106: =MIN(I9:I104) -> 3.76 | ... Q106: =MIN(Q9:Q104) -> 9.22
A107: Max | B107: =MAX(B9:B104) -> 20.34 | C107: =MAX(C9:C104) -> 37.94 | D107: =MAX(D9:D104) -> 52.7 | E107: =MAX(E9:E104) -> 8.31 | F107: =MAX(F9:F104) -> 18.88 | G107: =MAX(G9:G104) -> 56.21 | H107: =MAX(H9:H104) -> 51.84 | I107: =MAX(I9:I104) -> 4.26 | ... Q107: =MAX(Q9:Q104) -> 9.54
A108: Avg | B108: =AVERAGE(B9:B104) -> 8.7333333 | C108: =AVERAGE(C9:C104) -> 24.860729 | D108: =AVERAGE(D9:D104) -> 34.178542 | E108: =AVERAGE(E9:E104) -> 5.7188542 | F108: =AVERAGE(F9:F104) -> 8.4032292 | G108: =AVERAGE(G9:G104) -> 49.377083 | H108: =AVERAGE(H9:H104) -> 17.611354 | I108: =AVERAGE(I9:I104) -> 4.0113542 | ... Q108: =AVERAGE(Q9:Q104) -> 9.3934375
A109: Stdev | B109: =STDEV(B9:B104) -> 3.7482747 | C109: =STDEV(C9:C104) -> 4.2774668 | D109: =STDEV(D9:D104) -> 6.7533486 | E109: =STDEV(E9:E104) -> 0.61610811 | F109: =STDEV(F9:F104) -> 3.1535619 | G109: =STDEV(G9:G104) -> 4.6071192 | H109: =STDEV(H9:H104) -> 13.720796 | I109: =STDEV(I9:I104) -> 0.10149016 | ... Q109: =STDEV(Q9:Q104) -> 0.098961216
A110: Num | B110: =COUNT(B9:B104) -> 96 | C110: =COUNT(C9:C104) -> 96 | D110: =COUNT(D9:D104) -> 96 | E110: =COUNT(E9:E104) -> 96 | F110: =COUNT(F9:F104) -> 96 | G110: =COUNT(G9:G104) -> 96 | H110: =COUNT(H9:H104) -> 96 | I110: =COUNT(I9:I104) -> 96 | ... Q110: =COUNT(Q9:Q104) -> 96
A111: DCR | B111: =IF(B110>=87,">90%",IF(B110<=87,"<90%")) -> >90% | C111: =IF(C110>=87,">90%",IF(C110<=87,"<90%")) -> >90% | D111: =IF(D110>=87,">90%",IF(D110<=87,"<90%")) -> >90% | E111: =IF(E110>=87,">90%",IF(E110<=87,"<90%")) -> >90% | F111: =IF(F110>=87,">90%",IF(F110<=87,"<90%")) -> >90% | G111: =IF(G110>=87,">90%",IF(G110<=87,"<90%")) -> >90% | H111: =IF(H110>=87,">90%",IF(H110<=87,"<90%")) -> >90% | I111: =IF(I110>=87,">90%",IF(I110<=87,"<90%")) -> >90% | ... Q111: =IF(Q110>=87,">90%",IF(Q110<=87,"<90%")) -> >90%
A112: Status | B112: =IF(B110>=87,"OK",IF(B110<=87,"LESS")) -> OK | C112: =IF(C110>=87,"OK",IF(C110<=87,"LESS")) -> OK | D112: =IF(D110>=87,"OK",IF(D110<=87,"LESS")) -> OK | E112: =IF(E110>=87,"OK",IF(E110<=87,"LESS")) -> OK | F112: =IF(F110>=87,"OK",IF(F110<=87,"LESS")) -> OK | G112: =IF(G110>=87,"OK",IF(G110<=87,"LESS")) -> OK | H112: =IF(H110>=87,"OK",IF(H110<=87,"LESS")) -> OK | I112: =IF(I110>=87,"OK",IF(I110<=87,"LESS")) -> OK | ... Q112: =IF(Q110>=87,"OK",IF(Q110<=87,"LESS")) -> OK
A115: Done by | B115: RK
A117: Comment

Sheet 05
A1: Station: | B1: BHATAGAON RAIPUR
A2: Date: | B2: =$A$9 -> 45813.01 | D2: Power Off | G2: Pw.Off | L2: Link Fail | N2: Link F | P2: Maintenance | R2: Maint.
A3: Report Type: | B3: Mean | D3: Calibration | G3: Calib. | L3: Data Fail | N3: Data F | P3: Invalid | R3: Invalid
A4: Time Base: | B4: 15 Min | D4: Zero Referrence | G4: Z.Ref | L4: Warm Up | N4: Wm. Up
A7: Date & Time | B7: NO_BHATAGAON | C7: NO2__BHATAGAON | D7: NOX_BHATAGAON | E7: SO2__BHATAGAON | F7: O3__BHATAGAON | G7: PM10__BHATAGAON | H7: PM2_5__BHATAGAON | I7: BENZ__BHATAGAON | J7: WS__BHATAGAON | K7: WD__BHATAGAON | L7: TEMP__BHATAGAON | M7: HUM__BHATAGAON | N7: SR__BHATAGAON | O7: RG__BHATAGAON | P7: CO__BHATAGAON | Q7: NH3__BHATAGAON
B8: ug/m3 | C8: ug/m3 | D8: ppb | E8: ug/m3 | F8: ug/m3 | G8: ug/m3 | H8: ug/m3 | I8: ug/m3 | J8: m/sec | K8: deg | L8: degreC | M8: % | N8: w/m2 | O8: mm | P8: mg/m3 | Q8: ug/m3
A9: 45813.01 | B9: 10.77 | C9: 22.56 | D9: 26.64 | E9: 5.59 | F9: 6.25 | G9: 51.19 | H9: 17.02 | I9: 4.01 | J9: 1.26 | K9: 340.12 | L9: 28.11 | M9: 58.42 | N9: 42.7 | O9: 0 | P9: 0.56 | Q9: 9.5
A10: 45813.021 | B10: 11.07 | C10: 23.05 | D10: 27.14 | E10: 4.92 | F10: 5.15 | G10: 51.19 | H10: 17.02 | I10: 4.01 | J10: 0.93 | K10: 348.11 | L10: 27.86 | M10: 59.62 | N10: 42.8 | O10: 0 | P10: 0.58 | Q10: 9.49
A11: 45813.031 | B11: 11.55 | C11: 25.23 | D11: 30.56 | E11: 5.53 | F11: 8.51 | G11: 51.19 | H11: 17.02 | I11: 4.03 | J11: 0.61 | K11: 347.3 | L11: 27.78 | M11: 59.3 | N11: 42.8 | O11: 0 | P11: 0.51 | Q11: 9.5
A12: 45813.042 | B12: 9.79 | C12: 22.23 | D12: 27.52 | E12: 5.62 | F12: 6.78 | G12: 51.58 | H12: 17.49 | I12: 3.94 | J12: 0.18 | K12: 318.22 | L12: 27.5 | M12: 60.22 | N12: 42.9 | O12: 0 | P12: 0.53 | Q12: 9.5
A13: 45813.052 | B13: 8.46 | C13: 21.99 | D13: 29.11 | E13: 6.18 | F13: 7.88 | G13: 51.81 | H13: 17.78 | I13: 4.16 | J13: 0.04 | K13: 290.49 | L13: 27.16 | M13: 61.5 | N13: 42.9 | O13: 0 | P13: 0.43 | Q13: 9.49
A14: 45813.062 | B14: 9.8 | C14: 23.86 | D14: 30.63 | E14: 6.92 | F14: 6.34 | G14: 51.81 | H14: 17.78 | I14: 4.09 | J14: 0.17 | K14: 334.22 | L14: 26.89 | M14: 65.98 | N14: 42.8 | O14: 0 | P14: 0.49 | Q14: 9.47
A15: 45813.073 | B15: 10.73 | C15: 23.28 | D15: 28.09 | E15: 5.86 | F15: 4.99 | G15: 51.81 | H15: 17.78 | I15: 3.91 | J15: 0.12 | K15: 301.67 | L15: 26.81 | M15: 66.68 | N15: 42.5 | O15: 0 | P15: 0.49 | Q15: 9.46
A16: 45813.083 | B16: 10.7 | C16: 22.4 | D16: 26.46 | E16: 5.38 | F16: 4.54 | G16: 52.27 | H16: 14.43 | I16: 3.98 | J16: 0.15 | K16: 279.76 | L16: 27.22 | M16: 63.3 | N16: 42.4 | O16: 0 | P16: 0.48 | Q16: 9.46
A17: 45813.094 | B17: 11 | C17: 21.65 | D17: 24.56 | E17: 4.61 | F17: 4.39 | G17: 52.55 | H17: 12.4 | I17: 4.09 | J17: 0.11 | K17: 294.42 | L17: 26.92 | M17: 65.38 | N17: 42.9 | O17: 0 | P17: 0.5 | Q17: 9.43
A18: 45813.104 | B18: 10.15 | C18: 21.39 | D18: 25.36 | E18: 4.77 | F18: 4.44 | G18: 52.55 | H18: 12.4 | I18: 4.03 | J18: 0.11 | K18: 299.7 | L18: 26.83 | M18: 64.71 | N18: 42.6 | O18: 0 | P18: 0.45 | Q18: 9.42
A19: 45813.115 | B19: 9.56 | C19: 20.29 | D19: 24.15 | E19: 4.88 | F19: 5.48 | G19: 52.55 | H19: 12.4 | I19: 3.91 | J19: 0.09 | K19: 269.94 | L19: 26.8 | M19: 63.54 | N19: 42.5 | O19: 0 | P19: 0.43 | Q19: 9.4
A20: 45813.125 | B20: 7.11 | C20: 17.82 | D20: 23.18 | E20: 5.27 | F20: 10.87 | G20: 49.44 | H20: 13.13 | I20: 3.75 | J20: 0.1 | K20: 275.94 | L20: 26.67 | M20: 64.37 | N20: 42.7 | O20: 0 | P20: 0.28 | Q20: 9.39
... A104: 45814 | B104: 15.83 | C104: 34.59 | D104: 41.9 | E104: 5.41 | F104: 10.39 | G104: 75.07 | H104: 17.12 | I104: 4.04 | J104: 0.01 | K104: 323.43 | L104: 29.26 | M104: 53.61 | N104: 70.5 | O104: 0 | P104: 0.62 | Q104: 9.63
A106: Min | B106: =MIN(B9:B104) -> 4.38 | C106: =MIN(C9:C104) -> 14.42 | D106: =MIN(D9:D104) -> 18.55 | E106: =MIN(E9:E104) -> 4.35 | F106: =MIN(F9:F104) -> 3.39 | G106: =MIN(G9:G104) -> 32.99 | H106: =MIN(H9:H104) -> 0 | I106: =MIN(I9:I104) -> 3.75 | ... Q106: =MIN(Q9:Q104) -> 9.17
A107: Max | B107: =MAX(B9:B104) -> 82.68 | C107: =MAX(C9:C104) -> 127.96 | D107: =MAX(D9:D104) -> 118.01 | E107: =MAX(E9:E104) -> 13.59 | F107: =MAX(F9:F104) -> 27.67 | G107: =MAX(G9:G104) -> 75.07 | H107: =MAX(H9:H104) -> 943.87 | I107: =MAX(I9:I104) -> 4.22 | ... Q107: =MAX(Q9:Q104) -> 9.63
A108: Avg | B108: =AVERAGE(B9:B104) -> 12.381771 | C108: =AVERAGE(C9:C104) -> 30.23625 | D108: =AVERAGE(D9:D104) -> 38.867396 | E108: =AVERAGE(E9:E104) -> 6.1858333 | F108: =AVERAGE(F9:F104) -> 9.8565625 | G108: =AVERAGE(G9:G104) -> 44.724167 | H108: =AVERAGE(H9:H104) -> 56.59625 | I108: =AVERAGE(I9:I104) -> 4.0036458 | ... Q108: =AVERAGE(Q9:Q104) -> 9.3548958
A109: Stdev | B109: =STDEV(B9:B104) -> 12.897564 | C109: =STDEV(C9:C104) -> 19.746954 | D109: =STDEV(D9:D104) -> 20.33123 | E109: =STDEV(E9:E104) -> 1.4113589 | F109: =STDEV(F9:F104) -> 5.5780309 | G109: =STDEV(G9:G104) -> 9.7318469 | H109: =STDEV(H9:H104) -> 174.6752 | I109: =STDEV(I9:I104) -> 0.092156843 | ... Q109: =STDEV(Q9:Q104) -> 0.10810321
A110: Num | B110: =COUNT(B9:B104) -> 96 | C110: =COUNT(C9:C104) -> 96 | D110: =COUNT(D9:D104) -> 96 | E110: =COUNT(E9:E104) -> 96 | F110: =COUNT(F9:F104) -> 96 | G110: =COUNT(G9:G104) -> 96 | H110: =COUNT(H9:H104) -> 96 | I110: =COUNT(I9:I104) -> 96 | ... Q110: =COUNT(Q9:Q104) -> 96
A111: DCR | B111: =IF(B110>=87,">90%",IF(B110<=87,"<90%")) -> >90% | C111: =IF(C110>=87,">90%",IF(C110<=87,"<90%")) -> >90% | D111: =IF(D110>=87,">90%",IF(D110<=87,"<90%")) -> >90% | E111: =IF(E110>=87,">90%",IF(E110<=87,"<90%")) -> >90% | F111: =IF(F110>=87,">90%",IF(F110<=87,"<90%")) -> >90% | G111: =IF(G110>=87,">90%",IF(G110<=87,"<90%")) -> >90% | H111: =IF(H110>=87,">90%",IF(H110<=87,"<90%")) -> >90% | I111: =IF(I110>=87,">90%",IF(I110<=87,"<90%")) -> >90% | ... Q111: =IF(Q110>=87,">90%",IF(Q110<=87,"<90%")) -> >90%
A112: Status | B112: =IF(B110>=87,"OK",IF(B110<=87,"LESS")) -> OK | C112: =IF(C110>=87,"OK",IF(C110<=87,"LESS")) -> OK | D112: =IF(D110>=87,"OK",IF(D110<=87,"LESS")) -> OK | E112: =IF(E110>=87,"OK",IF(E110<=87,"LESS")) -> OK | F112: =IF(F110>=87,"OK",IF(F110<=87,"LESS")) -> OK | G112: =IF(G110>=87,"OK",IF(G110<=87,"LESS")) -> OK | H112: =IF(H110>=87,"OK",IF(H110<=87,"LESS")) -> OK | I112: =IF(I110>=87,"OK",IF(I110<=87,"LESS")) -> OK | ... Q112: =IF(Q110>=87,"OK",IF(Q110<=87,"LESS")) -> OK
A115: Done by | B115: RK
A117: Comment

Sheet 06
A1: Station: | B1: BHATAGAON RAIPUR
A2: Date: | B2: =$A$9 -> 45814.01 | D2: Power Off | G2: Pw.Off | L2: Link Fail | N2: Link F | P2: Maintenance | R2: Maint.
A3: Report Type: | B3: Mean | D3: Calibration | G3: Calib. | L3: Data Fail | N3: Data F | P3: Invalid | R3: Invalid
A4: Time Base: | B4: 15 Min | D4: Zero Referrence | G4: Z.Ref | L4: Warm Up | N4: Wm. Up
A7: Date & Time | B7: NO_BHATAGAON | C7: NO2__BHATAGAON | D7: NOX_BHATAGAON | E7: SO2__BHATAGAON | F7: O3__BHATAGAON | G7: PM10__BHATAGAON | H7: PM2_5__BHATAGAON | I7: BENZ__BHATAGAON | J7: WS__BHATAGAON | K7: WD__BHATAGAON | L7: TEMP__BHATAGAON | M7: HUM__BHATAGAON | N7: SR__BHATAGAON | O7: RG__BHATAGAON | P7: CO__BHATAGAON | Q7: NH3__BHATAGAON
B8: ug/m3 | C8: ug/m3 | D8: ppb | E8: ug/m3 | F8: ug/m3 | G8: ug/m3 | H8: ug/m3 | I8: ug/m3 | J8: m/sec | K8: deg | L8: degreC | M8: % | N8: w/m2 | O8: mm | P8: mg/m3 | Q8: ug/m3
A9: 45814.01 | B9: 14.2 | C9: 30.73 | D9: 37.03 | E9: 6.13 | F9: 11.55 | G9: 77.31 | H9: 16.85 | I9: 3.9 | J9: 0.01 | K9: 239.98 | L9: 29.06 | M9: 54.94 | N9: 71.6 | O9: 0 | P9: 0.63 | Q9: 9.61
A10: 45814.021 | B10: 15.14 | C10: 30.14 | D10: 34.45 | E10: 6.25 | F10: 11.64 | G10: 77.31 | H10: 16.85 | I10: 4.09 | J10: 0.06 | K10: 302.39 | L10: 28.82 | M10: 58.84 | N10: 78.4 | O10: 0 | P10: 0.68 | Q10: 9.62
A11: 45814.031 | B11: 17.19 | C11: 31.78 | D11: 34.44 | E11: 5.99 | F11: 10.59 | G11: 77.31 | H11: 16.85 | I11: 4.13 | J11: 0.08 | K11: 301.85 | L11: 28.53 | M11: 61.03 | N11: 79.4 | O11: 0 | P11: 0.7 | Q11: 9.6
A12: 45814.042 | B12: 9.2 | C12: 23.52 | D12: 30.89 | E12: 6.06 | F12: 17.06 | G12: 72.14 | H12: 19.74 | I12: 3.86 | J12: 0.05 | K12: 287.72 | L12: 28.34 | M12: 61.64 | N12: 74.4 | O12: 0 | P12: 0.57 | Q12: 9.61
A13: 45814.052 | B13: 9.5 | C13: 24.26 | D13: 31.86 | E13: 5.98 | F13: 15.7 | G13: 68.99 | H13: 21.5 | I13: 4.04 | J13: 0.1 | K13: 337.78 | L13: 28.19 | M13: 63.12 | N13: 80.3 | O13: 0 | P13: 0.44 | Q13: 9.64
A14: 45814.062 | B14: 9.97 | C14: 23.37 | D14: 29.44 | E14: 5.87 | F14: 15.63 | G14: 68.99 | H14: 21.5 | I14: 3.97 | J14: 0.03 | K14: 290.68 | L14: 27.89 | M14: 64.9 | N14: 76.2 | O14: 0 | P14: 0.47 | Q14: 9.63
A15: 45814.073 | B15: 10.59 | C15: 24.48 | D15: 30.62 | E15: 5.73 | F15: 13.97 | G15: 68.99 | H15: 21.5 | I15: 4.02 | J15: 0.08 | K15: 59.68 | L15: 27.83 | M15: 66.1 | N15: 75.2 | O15: 0 | P15: 0.49 | Q15: 9.61
A16: 45814.083 | B16: 9.35 | C16: 25.02 | D16: 33.55 | E16: 6.07 | F16: 13.52 | G16: 64.92 | H16: 8.12 | I16: 4.06 | J16: 0.09 | K16: 126.94 | L16: 27.62 | M16: 67.14 | N16: 74.8 | O16: 0 | P16: 0.47 | Q16: 9.63
A17: 45814.094 | B17: 11.32 | C17: 34.22 | D17: 48.12 | E17: 5.91 | F17: 10.54 | G17: 62.44 | H17: 0 | I17: 4.07 | J17: 0.05 | K17: 313.84 | L17: 27.62 | M17: 65.7 | N17: 74.9 | O17: 0 | P17: 0.44 | Q17: 9.62
A18: 45814.104 | B18: 11.35 | C18: 30.49 | D18: 40.95 | E18: 5.74 | F18: 8.49 | G18: 62.44 | H18: 0 | I18: 4.06 | J18: 0.13 | K18: 330.25 | L18: 27.3 | M18: 72.81 | N18: 75.2 | O18: 0 | P18: 0.5 | Q18: 9.63
A19: 45814.115 | B19: 11.66 | C19: 33.16 | D19: 45.58 | E19: 5.33 | F19: 6.66 | G19: 62.44 | H19: 0 | I19: 4.04 | J19: 0.13 | K19: 292.51 | L19: 27.15 | M19: 70.45 | N19: 74.7 | O19: 0 | P19: 0.5 | Q19: 9.64
A20: 45814.125 | B20: 14.15 | C20: 32.57 | D20: 40.61 | E20: 5.75 | F20: 6.13 | G20: 62.34 | H20: 62.68 | I20: 3.89 | J20: 0.08 | K20: 318.22 | L20: 26.89 | M20: 75.51 | N20: 74.9 | O20: 0 | P20: 0.56 | Q20: 9.61
... A104: 45815 | B104: 6.18 | C104: 20.53 | D104: 29.8 | E104: 5.7 | F104: 16.19 | G104: 46.09 | H104: 202.65 | I104: 4.05 | J104: 0.53 | K104: 155.16 | L104: 28.52 | M104: 52.32 | N104: 80.8 | O104: 0 | P104: 0.26 | Q104: 9.39
A106: Min | B106: =MIN(B9:B104) -> 3.4 | C106: =MIN(C9:C104) -> 18.17 | D106: =MIN(D9:D104) -> 28.18 | E106: =MIN(E9:E104) -> 4.96 | F106: =MIN(F9:F104) -> 4.5 | G106: =MIN(G9:G104) -> 0 | H106: =MIN(H9:H104) -> -12.42 | I106: =MIN(I9:I104) -> 3.75 | ... Q106: =MIN(Q9:Q104) -> 9.2
A107: Max | B107: =MAX(B9:B104) -> 33.34 | C107: =MAX(C9:C104) -> 84.55 | D107: =MAX(D9:D104) -> 123.58 | E107: =MAX(E9:E104) -> 15.5 | F107: =MAX(F9:F104) -> 36.44 | G107: =MAX(G9:G104) -> 91.7 | H107: =MAX(H9:H104) -> 562.22 | I107: =MAX(I9:I104) -> 4.26 | ... Q107: =MAX(Q9:Q104) -> 9.64
A108: Avg | B108: =AVERAGE(B9:B104) -> 10.103646 | C108: =AVERAGE(C9:C104) -> 30.102083 | D108: =AVERAGE(D9:D104) -> 42.109271 | E108: =AVERAGE(E9:E104) -> 7.1822917 | F108: =AVERAGE(F9:F104) -> 14.038333 | G108: =AVERAGE(G9:G104) -> 65.960625 | H108: =AVERAGE(H9:H104) -> 51.752917 | I108: =AVERAGE(I9:I104) -> 3.9975 | ... Q108: =AVERAGE(Q9:Q104) -> 9.4304167
A109: Stdev | B109: =STDEV(B9:B104) -> 6.7165306 | C109: =STDEV(C9:C104) -> 10.062633 | D109: =STDEV(D9:D104) -> 13.229014 | E109: =STDEV(E9:E104) -> 2.2236681 | F109: =STDEV(F9:F104) -> 6.8095553 | G109: =STDEV(G9:G104) -> 17.66 | H109: =STDEV(H9:H104) -> 106.2184 | I109: =STDEV(I9:I104) -> 0.096605546 | ... Q109: =STDEV(Q9:Q104) -> 0.14874858
A110: Num | B110: =COUNT(B9:B104)+1 -> 97 | C110: =COUNT(C9:C104)+1 -> 97 | D110: =COUNT(D9:D104)+1 -> 97 | E110: =COUNT(E9:E104) -> 96 | F110: =COUNT(F9:F104) -> 96 | G110: =COUNT(G9:G104) -> 96 | H110: =COUNT(H9:H104)+4 -> 100 | I110: =COUNT(I9:I104)+1 -> 97 | J110: =COUNT(J9:J104) -> 96 | K110: =COUNT(K9:K104) -> 96 | L110: =COUNT(L9:L104) -> 96 | M110: =COUNT(M9:M104) -> 96 | N110: =COUNT(N9:N104) -> 96 | O110: =COUNT(O9:O104) -> 96 | P110: =COUNT(P9:P104) -> 96 | Q110: =COUNT(Q9:Q104) -> 96
A111: DCR | B111: =IF(B110>=87,">90%",IF(B110<=87,"<90%")) -> >90% | C111: =IF(C110>=87,">90%",IF(C110<=87,"<90%")) -> >90% | D111: =IF(D110>=87,">90%",IF(D110<=87,"<90%")) -> >90% | E111: =IF(E110>=87,">90%",IF(E110<=87,"<90%")) -> >90% | F111: =IF(F110>=87,">90%",IF(F110<=87,"<90%")) -> >90% | G111: =IF(G110>=87,">90%",IF(G110<=87,"<90%")) -> >90% | H111: =IF(H110>=87,">90%",IF(H110<=87,"<90%")) -> >90% | I111: =IF(I110>=87,">90%",IF(I110<=87,"<90%")) -> >90% | ... Q111: =IF(Q110>=87,">90%",IF(Q110<=87,"<90%")) -> >90%
A112: Status | B112: =IF(B110>=87,"OK",IF(B110<=87,"LESS")) -> OK | C112: =IF(C110>=87,"OK",IF(C110<=87,"LESS")) -> OK | D112: =IF(D110>=87,"OK",IF(D110<=87,"LESS")) -> OK | E112: =IF(E110>=87,"OK",IF(E110<=87,"LESS")) -> OK | F112: =IF(F110>=87,"OK",IF(F110<=87,"LESS")) -> OK | G112: =IF(G110>=87,"OK",IF(G110<=87,"LESS")) -> OK | H112: =IF(H110>=87,"OK",IF(H110<=87,"LESS")) -> OK | I112: =IF(I110>=87,"OK",IF(I110<=87,"LESS")) -> OK | ... Q112: =IF(Q110>=87,"OK",IF(Q110<=87,"LESS")) -> OK
A115: Done by | B115: RK
A117: Comment

Sheet 07
A1: Station: | B1: BHATAGAON RAIPUR
A2: Date: | B2: =$A$9 -> 45815.01 | D2: Power Off | G2: Pw.Off | L2: Link Fail | N2: Link F | P2: Maintenance | R2: Maint.
A3: Report Type: | B3: Mean | D3: Calibration | G3: Calib. | L3: Data Fail | N3: Data F | P3: Invalid | R3: Invalid
A4: Time Base: | B4: 15 Min | D4: Zero Referrence | G4: Z.Ref | L4: Warm Up | N4: Wm. Up
A7: Date & Time | B7: NO_BHATAGAON | C7: NO2__BHATAGAON | D7: NOX_BHATAGAON | E7: SO2__BHATAGAON | F7: O3__BHATAGAON | G7: PM10__BHATAGAON | H7: PM2_5__BHATAGAON | I7: BENZ__BHATAGAON | J7: WS__BHATAGAON | K7: WD__BHATAGAON | L7: TEMP__BHATAGAON | M7: HUM__BHATAGAON | N7: SR__BHATAGAON | O7: RG__BHATAGAON | P7: CO__BHATAGAON | Q7: NH3__BHATAGAON
B8: ug/m3 | C8: ug/m3 | D8: ppb | E8: ug/m3 | F8: ug/m3 | G8: ug/m3 | H8: ug/m3 | I8: ug/m3 | J8: m/sec | K8: deg | L8: degreC | M8: % | N8: w/m2 | O8: mm | P8: mg/m3 | Q8: ug/m3
A9: 45815.01 | B9: 5.6 | C9: 19.76 | D9: 29.23 | E9: 6.43 | F9: 15.83 | G9: 41.37 | H9: 424.16 | I9: 4.07 | J9: 0.47 | K9: 144.47 | L9: 28.44 | M9: 53.57 | N9: 80.9 | O9: 0 | P9: 0.27 | Q9: 9.4
A10: 45815.021 | B10: 6.11 | C10: 18.42 | D10: 25.88 | E10: 6.64 | F10: 13.12 | G10: 41.37 | H10: 424.16 | I10: 4.2 | J10: 0.52 | K10: 152.43 | L10: 28.3 | M10: 55.21 | N10: 81.2 | O10: 0 | P10: 0.27 | Q10: 9.4
A11: 45815.031 | B11: 5.67 | C11: 17.88 | D11: 25.52 | E11: 6.62 | F11: 14.42 | G11: 41.37 | H11: 424.16 | I11: 4.12 | J11: 0.38 | K11: 152.43 | L11: 28.18 | M11: 55.35 | N11: 81.4 | O11: 0 | P11: 0.26 | Q11: 9.4
A12: 45815.042 | B12: 6.04 | C12: 18.15 | D12: 25.46 | E12: 6.08 | F12: 11.08 | G12: 41.68 | H12: 221.5 | I12: 3.89 | J12: 0.2 | K12: 141.53 | L12: 27.99 | M12: 56.53 | N12: 81.6 | O12: 0 | P12: 0.29 | Q12: 9.38
A13: 45815.052 | B13: 6.15 | C13: 18.19 | D13: 25.38 | E13: 6.53 | F13: 9.12 | G13: 42 | H13: 0 | I13: 4.07 | J13: 0.09 | K13: 229.68 | L13: 27.8 | M13: 56.76 | N13: 81.7 | O13: 0 | P13: 0.32 | Q13: 9.34
A14: 45815.062 | B14: 6.5 | C14: 18.27 | D14: 24.99 | E14: 6.17 | F14: 7.8 | G14: 42 | H14: 0 | I14: 3.93 | J14: 0.04 | K14: 274.78 | L14: 27.59 | M14: 56.57 | N14: 82 | O14: 0 | P14: 0.35 | Q14: 9.31
A15: 45815.073 | B15: 6.45 | C15: 18.12 | D15: 24.78 | E15: 6.06 | F15: 8.14 | G15: 42 | H15: 0 | I15: 3.83 | J15: 0.11 | K15: 181.35 | L15: 27.31 | M15: 59.18 | N15: 82.1 | O15: 0 | P15: 0.35 | Q15: 9.3
A16: 45815.083 | B16: 6.16 | C16: 17.52 | D16: 24.07 | E16: 6.09 | F16: 10.58 | G16: 40.66 | H16: 0 | I16: 4.05 | J16: 0.19 | K16: 179.85 | L16: 27.08 | M16: 62.82 | N16: 82.5 | O16: 0 | P16: 0.34 | Q16: 9.3
A17: 45815.094 | B17: 6.17 | C17: 18.01 | D17: 25.01 | E17: 5.68 | F17: 9.42 | G17: 39.13 | H17: 0 | I17: 4.06 | J17: 0.18 | K17: 169.49 | L17: 26.98 | M17: 64.64 | N17: 82.4 | O17: 0 | P17: 0.34 | Q17: 9.3
A18: 45815.104 | B18: 6.46 | C18: 18.11 | D18: 24.74 | E18: 6.1 | F18: 7.28 | G18: 39.13 | H18: 0 | I18: 3.9 | J18: 0.31 | K18: 159.75 | L18: 26.87 | M18: 65.7 | N18: 83.2 | O18: 0 | P18: 0.35 | Q18: 9.3
A19: 45815.115 | B19: 6.54 | C19: 17.85 | D19: 24.13 | E19: 5.61 | F19: 7.3 | G19: 39.13 | H19: 0 | I19: 3.87 | J19: 0.24 | K19: 164.43 | L19: 26.67 | M19: 66.68 | N19: 83.8 | O19: 0 | P19: 0.36 | Q19: 9.29
A20: 45815.125 | B20: 6.4 | C20: 17.49 | D20: 23.66 | E20: 5.98 | F20: 7.99 | G20: 38.16 | H20: 915.08 | I20: 4.15 | J20: 0.12 | K20: 225.35 | L20: 26.56 | M20: 66.86 | N20: 84.3 | O20: 0 | P20: 0.35 | Q20: 9.28
... A104: 45816 | B104: 14.49 | C104: 28.36 | D104: 32.04 | E104: 3.88 | F104: 5.94 | G104: 69.11 | H104: 15.59 | I104: 4.06 | J104: 0.98 | K104: 152.32 | L104: 30.35 | M104: 40.24 | N104: 96.6 | O104: 0 | P104: 0.79 | Q104: 9.58
A106: Min | B106: =MIN(B9:B104) -> 4.14 | C106: =MIN(C9:C104) -> 16.68 | D106: =MIN(D9:D104) -> 23.66 | E106: =MIN(E9:E104) -> 3.88 | F106: =MIN(F9:F104) -> 4.63 | G106: =MIN(G9:G104) -> 37.06 | H106: =MIN(H9:H104) -> 0 | I106: =MIN(I9:I104) -> 3.8 | ... Q106: =MIN(Q9:Q104) -> 9.22
A107: Max | B107: =MAX(B9:B104) -> 27.38 | C107: =MAX(C9:C104) -> 56.85 | D107: =MAX(D9:D104) -> 67.79 | E107: =MAX(E9:E104) -> 15.01 | F107: =MAX(F9:F104) -> 26.65 | G107: =MAX(G9:G104) -> 70.86 | H107: =MAX(H9:H104) -> 1960.88 | I107: =MAX(I9:I104) -> 4.21 | ... Q107: =MAX(Q9:Q104) -> 9.59
A108: Avg | B108: =AVERAGE(B9:B104) -> 8.9882292 | C108: =AVERAGE(C9:C104) -> 26.751042 | D108: =AVERAGE(D9:D104) -> 37.409167 | E108: =AVERAGE(E9:E104) -> 7.0615625 | F108: =AVERAGE(F9:F104) -> 11.410312 | G108: =AVERAGE(G9:G104) -> 51.655104 | H108: =AVERAGE(H9:H104) -> 176.51594 | I108: =AVERAGE(I9:I104) -> 4.00875 | ... Q108: =AVERAGE(Q9:Q104) -> 9.3691667
A109: Stdev | B109: =STDEV(B9:B104) -> 5.3335046 | C109: =STDEV(C9:C104) -> 10.042848 | D109: =STDEV(D9:D104) -> 12.637962 | E109: =STDEV(E9:E104) -> 1.9926393 | F109: =STDEV(F9:F104) -> 4.8695309 | G109: =STDEV(G9:G104) -> 10.197698 | H109: =STDEV(H9:H104) -> 408.43306 | I109: =STDEV(I9:I104) -> 0.092704965 | ... Q109: =STDEV(Q9:Q104) -> 0.10619413
A110: Num | B110: =COUNT(B9:B104) -> 96 | C110: =COUNT(C9:C104) -> 96 | D110: =COUNT(D9:D104) -> 96 | E110: =COUNT(E9:E104) -> 96 | F110: =COUNT(F9:F104)+1 -> 97 | G110: =COUNT(G9:G104) -> 96 | H110: =COUNT(H9:H104) -> 96 | I110: =COUNT(I9:I104)+7+25 -> 128 | J110: =COUNT(J9:J104) -> 96 | K110: =COUNT(K9:K104) -> 96 | L110: =COUNT(L9:L104) -> 96 | M110: =COUNT(M9:M104) -> 96 | N110: =COUNT(N9:N104) -> 96 | O110: =COUNT(O9:O104) -> 96 | P110: =COUNT(P9:P104) -> 96 | Q110: =COUNT(Q9:Q104) -> 96
A111: DCR | B111: =IF(B110>=87,">90%",IF(B110<=87,"<90%")) -> >90% | C111: =IF(C110>=87,">90%",IF(C110<=87,"<90%")) -> >90% | D111: =IF(D110>=87,">90%",IF(D110<=87,"<90%")) -> >90% | E111: =IF(E110>=87,">90%",IF(E110<=87,"<90%")) -> >90% | F111: =IF(F110>=87,">90%",IF(F110<=87,"<90%")) -> >90% | G111: =IF(G110>=87,">90%",IF(G110<=87,"<90%")) -> >90% | H111: =IF(H110>=87,">90%",IF(H110<=87,"<90%")) -> >90% | I111: =IF(I110>=87,">90%",IF(I110<=87,"<90%")) -> >90% | ... Q111: =IF(Q110>=87,">90%",IF(Q110<=87,"<90%")) -> >90%
A112: Status | B112: =IF(B110>=87,"OK",IF(B110<=87,"LESS")) -> OK | C112: =IF(C110>=87,"OK",IF(C110<=87,"LESS")) -> OK | D112: =IF(D110>=87,"OK",IF(D110<=87,"LESS")) -> OK | E112: =IF(E110>=87,"OK",IF(E110<=87,"LESS")) -> OK | F112: =IF(F110>=87,"OK",IF(F110<=87,"LESS")) -> OK | G112: =IF(G110>=87,"OK",IF(G110<=87,"LESS")) -> OK | H112: =IF(H110>=87,"OK",IF(H110<=87,"LESS")) -> OK | I112: =IF(I110>=87,"OK",IF(I110<=87,"LESS")) -> OK | ... Q112: =IF(Q110>=87,"OK",IF(Q110<=87,"LESS")) -> OK
A115: Done by | B115: RK
A117: Comment

Sheet 08
A1: Station: | B1: BHATAGAON RAIPUR
A2: Date: | B2: =$A$9 -> 45816.01 | D2: Power Off | G2: Pw.Off | L2: Link Fail | N2: Link F | P2: Maintenance | R2: Maint.
A3: Report Type: | B3: Mean | D3: Calibration | G3: Calib. | L3: Data Fail | N3: Data F | P3: Invalid | R3: Invalid
A4: Time Base: | B4: 15 Min | D4: Zero Referrence | G4: Z.Ref | L4: Warm Up | N4: Wm. Up
A7: Date & Time | B7: NO_BHATAGAON | C7: NO2__BHATAGAON | D7: NOX_BHATAGAON | E7: SO2__BHATAGAON | F7: O3__BHATAGAON | G7: PM10__BHATAGAON | H7: PM2_5__BHATAGAON | I7: BENZ__BHATAGAON | J7: WS__BHATAGAON | K7: WD__BHATAGAON | L7: TEMP__BHATAGAON | M7: HUM__BHATAGAON | N7: SR__BHATAGAON | O7: RG__BHATAGAON | P7: CO__BHATAGAON | Q7: NH3__BHATAGAON
B8: ug/m3 | C8: ug/m3 | D8: ppb | E8: ug/m3 | F8: ug/m3 | G8: ug/m3 | H8: ug/m3 | I8: ug/m3 | J8: m/sec | K8: deg | L8: degreC | M8: % | N8: w/m2 | O8: mm | P8: mg/m3 | Q8: ug/m3
A9: 45816.01 | B9: 10.25 | C9: 24.14 | D9: 30.47 | E9: 4.49 | F9: 10.34 | G9: 67.2 | H9: 14.32 | I9: 3.85 | J9: 0.6 | K9: 139.47 | L9: 30.16 | M9: 42.51 | N9: 96.8 | O9: 0 | P9: 0.59 | Q9: 9.57
A10: 45816.021 | B10: 11.11 | C10: 24.34 | D10: 29.53 | E10: 4.38 | F10: 8.92 | G10: 67.2 | H10: 14.32 | I10: 3.94 | J10: 0.68 | K10: 132.7 | L10: 29.84 | M10: 44.6 | N10: 96.9 | O10: 0 | P10: 0.64 | Q10: 9.56
A11: 45816.031 | B11: 9.42 | C11: 23.13 | D11: 29.8 | E11: 4.89 | F11: 13.62 | G11: 67.2 | H11: 14.32 | I11: 3.94 | J11: 0.13 | K11: 177.91 | L11: 29.52 | M11: 47.38 | N11: 97.9 | O11: 0 | P11: 0.48 | Q11: 9.55
A12: 45816.042 | B12: 8.02 | C12: 21.38 | D12: 28.61 | E12: 4.88 | F12: 12.64 | G12: 63.31 | H12: 19.75 | I12: 3.89 | J12: 0.09 | K12: 224.64 | L12: 29.25 | M12: 49.48 | N12: 99.7 | O12: 0 | P12: 0.48 | Q12: 9.58
A13: 45816.052 | B13: 8.11 | C13: 22.39 | D13: 30.4 | E13: 4.7 | F13: 13.24 | G13: 59.05 | H13: 25.69 | I13: 4.07 | J13: 0.03 | K13: 247.55 | L13: 28.96 | M13: 51.94 | N13: 99.4 | O13: 0 | P13: 0.43 | Q13: 9.56
A14: 45816.062 | B14: 7.3 | C14: 20.77 | D14: 28.55 | E14: 5 | F14: 13.41 | G14: 59.05 | H14: 25.69 | I14: 4.03 | J14: 0.06 | K14: 188.31 | L14: 28.69 | M14: 53.92 | N14: 99 | O14: 0 | P14: 0.44 | Q14: 9.55
A15: 45816.073 | B15: 5.97 | C15: 18.64 | D15: 26.51 | E15: 5.07 | F15: 17.02 | G15: 59.05 | H15: 25.69 | I15: 3.69 | J15: 0.11 | K15: 134.35 | L15: 28.48 | M15: 55.39 | N15: 99 | O15: 0 | P15: 0.39 | Q15: 9.54
A16: 45816.083 | B16: 5.77 | C16: 18.91 | D16: 27.34 | E16: 5.1 | F16: 17.53 | G16: 56.08 | H16: 19.89 | I16: 4.1 | J16: 0.04 | K16: 195.23 | L16: 28.38 | M16: 56.42 | N16: 98.7 | O16: 0 | P16: 0.38 | Q16: 9.52
A17: 45816.094 | B17: 5.8 | C17: 18.29 | D17: 26.09 | E17: 5.27 | F17: 16.83 | G17: 52.68 | H17: 13.26 | I17: 4.11 | J17: 0.04 | K17: 284.4 | L17: 28.33 | M17: 56.89 | N17: 98.5 | O17: 0 | P17: 0.38 | Q17: 9.51
A18: 45816.104 | B18: 6.41 | C18: 18.73 | D18: 26.01 | E18: 5.37 | F18: 16.11 | G18: 52.68 | H18: 13.26 | I18: 4.04 | J18: 0.06 | K18: 296.9 | L18: 28.41 | M18: 56.9 | N18: 98.3 | O18: 0 | P18: 0.42 | Q18: 9.49
A19: 45816.115 | B19: 6.01 | C19: 17.79 | D19: 24.83 | E19: 5 | F19: 17.59 | G19: 52.68 | H19: 13.26 | I19: 3.92 | J19: 0.08 | K19: 287.91 | L19: 28.34 | M19: 57.48 | N19: 99 | O19: 0 | P19: 0.39 | Q19: 9.49
A20: 45816.125 | B20: 5.57 | C20: 16.55 | D20: 23.14 | E20: 5.44 | F20: 17.26 | G20: 51.1 | H20: 14.91 | I20: 3.92 | J20: 0.08 | K20: 281.11 | L20: 28.21 | M20: 57.88 | N20: 98.5 | O20: 0 | P20: 0.39 | Q20: 9.48
... A104: 45817 | B104: 4.69 | C104: 19.88 | D104: 30.84 | E104: 5.17 | F104: 16.91 | G104: 45.24 | H104: 10.94 | I104: 4.08 | J104: 0.75 | K104: 143.61 | L104: 28.82 | M104: 57.49 | N104: 120.1 | O104: 0 | P104: 0.34 | Q104: 9.33
A106: Min | B106: =MIN(B9:B104) -> 4.12 | C106: =MIN(C9:C104) -> 16.05 | D106: =MIN(D9:D104) -> 22.69 | E106: =MIN(E9:E104) -> 3.97 | F106: =MIN(F9:F104) -> 5.3 | G106: =MIN(G9:G104) -> 45.24 | H106: =MIN(H9:H104) -> -29.72 | I106: =MIN(I9:I104) -> 3.69 | ... Q106: =MIN(Q9:Q104) -> 9.23
A107: Max | B107: =MAX(B9:B104) -> 14.33 | C107: =MAX(C9:C104) -> 42.78 | D107: =MAX(D9:D104) -> 63.15 | E107: =MAX(E9:E104) -> 11.4 | F107: =MAX(F9:F104) -> 22.68 | G107: =MAX(G9:G104) -> 67.2 | H107: =MAX(H9:H104) -> 78.84 | I107: =MAX(I9:I104) -> 4.27 | ... Q107: =MAX(Q9:Q104) -> 9.58
A108: Avg | B108: =AVERAGE(B9:B104) -> 6.8186458 | C108: =AVERAGE(C9:C104) -> 23.739688 | D108: =AVERAGE(D9:D104) -> 34.972187 | E108: =AVERAGE(E9:E104) -> 5.6360417 | F108: =AVERAGE(F9:F104) -> 12.996354 | G108: =AVERAGE(G9:G104) -> 53.331042 | H108: =AVERAGE(H9:H104) -> 16.526146 | I108: =AVERAGE(I9:I104) -> 3.9917708 | ... Q108: =AVERAGE(Q9:Q104) -> 9.3778125
A109: Stdev | B109: =STDEV(B9:B104) -> 2.0729494 | C109: =STDEV(C9:C104) -> 4.4205488 | D109: =STDEV(D9:D104) -> 6.7785052 | E109: =STDEV(E9:E104) -> 1.1274998 | F109: =STDEV(F9:F104) -> 4.6039965 | G109: =STDEV(G9:G104) -> 5.649107 | H109: =STDEV(H9:H104) -> 18.523048 | I109: =STDEV(I9:I104) -> 0.10359836 | ... Q109: =STDEV(Q9:Q104) -> 0.094012352
A110: Num | B110: =COUNT(B9:B104) -> 96 | C110: =COUNT(C9:C104) -> 96 | D110: =COUNT(D9:D104) -> 96 | E110: =COUNT(E9:E104) -> 96 | F110: =COUNT(F9:F104) -> 96 | G110: =COUNT(G9:G104) -> 96 | H110: =COUNT(H9:H104) -> 96 | I110: =COUNT(I9:I104) -> 96 | ... Q110: =COUNT(Q9:Q104) -> 96
A111: DCR | B111: =IF(B110>=87,">90%",IF(B110<=87,"<90%")) -> >90% | C111: =IF(C110>=87,">90%",IF(C110<=87,"<90%")) -> >90% | D111: =IF(D110>=87,">90%",IF(D110<=87,"<90%")) -> >90% | E111: =IF(E110>=87,">90%",IF(E110<=87,"<90%")) -> >90% | F111: =IF(F110>=87,">90%",IF(F110<=87,"<90%")) -> >90% | G111: =IF(G110>=87,">90%",IF(G110<=87,"<90%")) -> >90% | H111: =IF(H110>=87,">90%",IF(H110<=87,"<90%")) -> >90% | I111: =IF(I110>=87,">90%",IF(I110<=87,"<90%")) -> >90% | ... Q111: =IF(Q110>=87,">90%",IF(Q110<=87,"<90%")) -> >90%
A112: Status | B112: =IF(B110>=87,"OK",IF(B110<=87,"LESS")) -> OK | C112: =IF(C110>=87,"OK",IF(C110<=87,"LESS")) -> OK | D112: =IF(D110>=87,"OK",IF(D110<=87,"LESS")) -> OK | E112: =IF(E110>=87,"OK",IF(E110<=87,"LESS")) -> OK | F112: =IF(F110>=87,"OK",IF(F110<=87,"LESS")) -> OK | G112: =IF(G110>=87,"OK",IF(G110<=87,"LESS")) -> OK | H112: =IF(H110>=87,"OK",IF(H110<=87,"LESS")) -> OK | I112: =IF(I110>=87,"OK",IF(I110<=87,"LESS")) -> OK | ... Q112: =IF(Q110>=87,"OK",IF(Q110<=87,"LESS")) -> OK
A115: Done by | B115: RK
A117: Comment

Sheet 09
A1: Station: | B1: BHATAGAON RAIPUR
A2: Date: | B2: =$A$9 -> 45817.01 | D2: Power Off | G2: Pw.Off | L2: Link Fail | N2: Link F | P2: Maintenance | R2: Maint.
A3: Report Type: | B3: Mean | D3: Calibration | G3: Calib. | L3: Data Fail | N3: Data F | P3: Invalid | R3: Invalid
A4: Time Base: | B4: 15 Min | D4: Zero Referrence | G4: Z.Ref | L4: Warm Up | N4: Wm. Up
A7: Date & Time | B7: NO_BHATAGAON | C7: NO2__BHATAGAON | D7: NOX_BHATAGAON | E7: SO2__BHATAGAON | F7: O3__BHATAGAON | G7: PM10__BHATAGAON | H7: PM2_5__BHATAGAON | I7: BENZ__BHATAGAON | J7: WS__BHATAGAON | K7: WD__BHATAGAON | L7: TEMP__BHATAGAON | M7: HUM__BHATAGAON | N7: SR__BHATAGAON | O7: RG__BHATAGAON | P7: CO__BHATAGAON | Q7: NH3__BHATAGAON
B8: ug/m3 | C8: ug/m3 | D8: ppb | E8: ug/m3 | F8: ug/m3 | G8: ug/m3 | H8: ug/m3 | I8: ug/m3 | J8: m/sec | K8: deg | L8: degreC | M8: % | N8: w/m2 | O8: mm | P8: mg/m3 | Q8: ug/m3
A9: 45817.01 | B9: 4.42 | C9: 16.68 | D9: 25.14 | E9: 5.04 | F9: 21.5 | G9: 42.14 | H9: 6.53 | I9: 3.97 | J9: 0.24 | K9: 134.6 | L9: 28.52 | M9: 59.02 | N9: 129.2 | O9: 0 | P9: 0.25 | Q9: 9.32
A10: 45817.021 | B10: 4.36 | C10: 16.58 | D10: 25.04 | E10: 5.4 | F10: 19.15 | G10: 42.14 | H10: 6.53 | I10: 3.99 | J10: 0.06 | K10: 337.21 | L10: 28.59 | M10: 58.75 | N10: 127.2 | O10: 0 | P10: 0.27 | Q10: 9.33
A11: 45817.031 | B11: 4.38 | C11: 17.83 | D11: 27.4 | E11: 5.7 | F11: 18.44 | G11: 42.14 | H11: 6.53 | I11: 3.95 | J11: 0.22 | K11: 135.35 | L11: 28.62 | M11: 57.66 | N11: 120.4 | O11: 0 | P11: 0.25 | Q11: 9.34
A12: 45817.042 | B12: 4.27 | C12: 15.86 | D12: 23.8 | E12: 5.7 | F12: 21.39 | G12: 40.01 | H12: -4.18 | I12: 4.03 | J12: 0.09 | K12: 219.98 | L12: 28.66 | M12: 56.51 | N12: 115.3 | O12: 0 | P12: 0.24 | Q12: 9.34
A13: 45817.052 | B13: 4.76 | C13: 15.71 | D13: 22.75 | E13: 5.58 | F13: 18.27 | G13: 37.69 | H13: -15.89 | I13: 3.99 | J13: 0.52 | K13: 148.91 | L13: 28.66 | M13: 56.24 | N13: 114.4 | O13: 0 | P13: 0.28 | Q13: 9.34
A14: 45817.062 | B14: 4.84 | C14: 15.05 | D14: 21.38 | E14: 5.49 | F14: 14.84 | G14: 37.69 | H14: -15.89 | I14: 4.06 | J14: 0.12 | K14: 201.23 | L14: 28.43 | M14: 56.44 | N14: 96.8 | O14: 0 | P14: 0.3 | Q14: 9.34
A15: 45817.073 | B15: 5.37 | C15: 18.02 | D15: 26.24 | E15: 5.22 | F15: 11.55 | G15: 37.69 | H15: -15.89 | I15: 4.04 | J15: 0.28 | K15: 155.04 | L15: 28.25 | M15: 57.62 | N15: 125 | O15: 0 | P15: 0.34 | Q15: 9.33
A16: 45817.083 | B16: 4.8 | C16: 16.4 | D16: 24.02 | E16: 5.09 | F16: 15.3 | G16: 35.71 | H16: -6.9 | I16: 3.99 | J16: 0.22 | K16: 147.4 | L16: 28.16 | M16: 58.64 | N16: 99.7 | O16: 0 | P16: 0.3 | Q16: 9.32
A17: 45817.094 | B17: 5.16 | C17: 17.93 | D17: 26.4 | E17: 5.08 | F17: 12.83 | G17: 33.45 | H17: 3.37 | I17: 4.19 | J17: 0.59 | K17: 144.21 | L17: 28.1 | M17: 59.08 | N17: 81 | O17: 0 | P17: 0.34 | Q17: 9.3
A18: 45817.104 | B18: 4.87 | C18: 16.84 | D18: 24.75 | E18: 5.59 | F18: 13.21 | G18: 33.45 | H18: 3.37 | I18: 4.1 | J18: 0.25 | K18: 143.29 | L18: 27.94 | M18: 60.07 | N18: 62.2 | O18: 0 | P18: 0.3 | Q18: 9.3
A19: 45817.115 | B19: 5.02 | C19: 17.67 | D19: 26.12 | E19: 5.4 | F19: 11.25 | G19: 33.45 | H19: 3.37 | I19: 4.07 | J19: 0.39 | K19: 152.61 | L19: 27.83 | M19: 60.82 | N19: 62.4 | O19: 0 | P19: 0.32 | Q19: 9.29
A20: 45817.125 | B20: 4.88 | C20: 16.42 | D20: 23.93 | E20: 4.91 | F20: 10.28 | G20: 32.04 | H20: 5.01 | I20: 4.01 | J20: 0.02 | K20: 187.42 | L20: 27.67 | M20: 61.35 | N20: 63.4 | O20: 0 | P20: 0.31 | Q20: 9.28
... A104: 45818 | B104: 5.79 | C104: 19.73 | D104: 28.88 | E104: 6.13 | F104: 11.6 | G104: 39.73 | H104: 12.46 | I104: 3.89 | J104: 0.11 | K104: 179.39 | L104: 27.8 | M104: 63.52 | N104: 52.5 | O104: 0 | P104: 0.36 | Q104: 9.35
A106: Min | B106: =MIN(B9:B104) -> 3.9 | C106: =MIN(C9:C104) -> 15.05 | D106: =MIN(D9:D104) -> 21.38 | E106: =MIN(E9:E104) -> 4.91 | F106: =MIN(F9:F104) -> 4.11 | G106: =MIN(G9:G104) -> 24.53 | H106: =MIN(H9:H104) -> -15.89 | I106: =MIN(I9:I104) -> 3.81 | ... Q106: =MIN(Q9:Q104) -> 9.21
A107: Max | B107: =MAX(B9:B104) -> 8.01 | C107: =MAX(C9:C104) -> 33.25 | D107: =MAX(D9:D104) -> 51.34 | E107: =MAX(E9:E104) -> 7.96 | F107: =MAX(F9:F104) -> 23.95 | G107: =MAX(G9:G104) -> 54.81 | H107: =MAX(H9:H104) -> 21.15 | I107: =MAX(I9:I104) -> 4.25 | ... Q107: =MAX(Q9:Q104) -> 9.37
A108: Avg | B108: =AVERAGE(B9:B104) -> 5.1446875 | C108: =AVERAGE(C9:C104) -> 21.179479 | D108: =AVERAGE(D9:D104) -> 32.641563 | E108: =AVERAGE(E9:E104) -> 6.0609375 | F108: =AVERAGE(F9:F104) -> 12.657188 | G108: =AVERAGE(G9:G104) -> 38.96875 | H108: =AVERAGE(H9:H104) -> 11.678646 | I108: =AVERAGE(I9:I104) -> 3.9977083 | ... Q108: =AVERAGE(Q9:Q104) -> 9.3014583
A109: Stdev | B109: =STDEV(B9:B104) -> 1.0211768 | C109: =STDEV(C9:C104) -> 3.2598445 | D109: =STDEV(D9:D104) -> 5.8174301 | E109: =STDEV(E9:E104) -> 0.82285137 | F109: =STDEV(F9:F104) -> 4.9258084 | G109: =STDEV(G9:G104) -> 8.0714919 | H109: =STDEV(H9:H104) -> 6.9937391 | I109: =STDEV(I9:I104) -> 0.089000049 | ... Q109: =STDEV(Q9:Q104) -> 0.043721106
A110: Num | B110: =COUNT(B9:B104) -> 96 | C110: =COUNT(C9:C104) -> 96 | D110: =COUNT(D9:D104) -> 96 | E110: =COUNT(E9:E104) -> 96 | F110: =COUNT(F9:F104) -> 96 | G110: =COUNT(G9:G104) -> 96 | H110: =COUNT(H9:H104) -> 96 | I110: =COUNT(I9:I104) -> 96 | ... Q110: =COUNT(Q9:Q104) -> 96
A111: DCR | B111: =IF(B110>=87,">90%",IF(B110<=87,"<90%")) -> >90% | C111: =IF(C110>=87,">90%",IF(C110<=87,"<90%")) -> >90% | D111: =IF(D110>=87,">90%",IF(D110<=87,"<90%")) -> >90% | E111: =IF(E110>=87,">90%",IF(E110<=87,"<90%")) -> >90% | F111: =IF(F110>=87,">90%",IF(F110<=87,"<90%")) -> >90% | G111: =IF(G110>=87,">90%",IF(G110<=87,"<90%")) -> >90% | H111: =IF(H110>=87,">90%",IF(H110<=87,"<90%")) -> >90% | I111: =IF(I110>=87,">90%",IF(I110<=87,"<90%")) -> >90% | ... Q111: =IF(Q110>=87,">90%",IF(Q110<=87,"<90%")) -> >90%
A112: Status | B112: =IF(B110>=87,"OK",IF(B110<=87,"LESS")) -> OK | C112: =IF(C110>=87,"OK",IF(C110<=87,"LESS")) -> OK | D112: =IF(D110>=87,"OK",IF(D110<=87,"LESS")) -> OK | E112: =IF(E110>=87,"OK",IF(E110<=87,"LESS")) -> OK | F112: =IF(F110>=87,"OK",IF(F110<=87,"LESS")) -> OK | G112: =IF(G110>=87,"OK",IF(G110<=87,"LESS")) -> OK | H112: =IF(H110>=87,"OK",IF(H110<=87,"LESS")) -> OK | I112: =IF(I110>=87,"OK",IF(I110<=87,"LESS")) -> OK | ... Q112: =IF(Q110>=87,"OK",IF(Q110<=87,"LESS")) -> OK
A115: Done by | B115: RK
A117: Comment

Sheet 10
A1: Station: | B1: BHATAGAON RAIPUR
A2: Date: | B2: =$A$9 -> 45818.01 | D2: Power Off | G2: Pw.Off | L2: Link Fail | N2: Link F | P2: Maintenance | R2: Maint.
A3: Report Type: | B3: Mean | D3: Calibration | G3: Calib. | L3: Data Fail | N3: Data F | P3: Invalid | R3: Invalid
A4: Time Base: | B4: 15 Min | D4: Zero Referrence | G4: Z.Ref | L4: Warm Up | N4: Wm. Up
A7: Date & Time | B7: NO_BHATAGAON | C7: NO2__BHATAGAON | D7: NOX_BHATAGAON | E7: SO2__BHATAGAON | F7: O3__BHATAGAON | G7: PM10__BHATAGAON | H7: PM2_5__BHATAGAON | I7: BENZ__BHATAGAON | J7: WS__BHATAGAON | K7: WD__BHATAGAON | L7: TEMP__BHATAGAON | M7: HUM__BHATAGAON | N7: SR__BHATAGAON | O7: RG__BHATAGAON | P7: CO__BHATAGAON | Q7: NH3__BHATAGAON
B8: ug/m3 | C8: ug/m3 | D8: ppb | E8: ug/m3 | F8: ug/m3 | G8: ug/m3 | H8: ug/m3 | I8: ug/m3 | J8: m/sec | K8: deg | L8: degreC | M8: % | N8: w/m2 | O8: mm | P8: mg/m3 | Q8: ug/m3
A9: 45818.01 | B9: 5.76 | C9: 19.35 | D9: 28.2 | E9: 5.89 | F9: 11.42 | G9: 39.37 | H9: 13.23 | I9: 3.96 | J9: 0.24 | K9: 148.42 | L9: 27.67 | M9: 65.42 | N9: 52.4 | O9: 0 | P9: 0.35 | Q9: 9.34
A10: 45818.021 | B10: 5.72 | C10: 18.39 | D10: 26.43 | E10: 5.89 | F10: 8.78 | G10: 39.37 | H10: 13.23 | I10: 3.94 | J10: 0.13 | K10: 197.16 | L10: 27.6 | M10: 66.88 | N10: 52.4 | O10: 0 | P10: 0.37 | Q10: 9.33
A11: 45818.031 | B11: 5.55 | C11: 17.77 | D11: 25.5 | E11: 6.01 | F11: 11.7 | G11: 39.37 | H11: 13.23 | I11: 4.09 | J11: 0.13 | K11: 196.04 | L11: 27.53 | M11: 67.99 | N11: 52.4 | O11: 0 | P11: 0.32 | Q11: 9.32
A12: 45818.042 | B12: 5.6 | C12: 17.08 | D12: 24.11 | E12: 5.72 | F12: 10.02 | G12: 37.57 | H12: 11.84 | I12: 3.91 | J12: 0.11 | K12: 170.61 | L12: 27.45 | M12: 69.6 | N12: 52.4 | O12: 0 | P12: 0.34 | Q12: 9.3
A13: 45818.052 | B13: 5.45 | C13: 17.41 | D13: 24.96 | E13: 5.83 | F13: 12.66 | G13: 35.61 | H13: 10.31 | I13: 3.86 | J13: 0.1 | K13: 203.39 | L13: 27.37 | M13: 70.65 | N13: 52.3 | O13: 0 | P13: 0.35 | Q13: 9.3
A14: 45818.062 | B14: 5.59 | C14: 17.03 | D14: 24.01 | E14: 5.87 | F14: 7.98 | G14: 35.61 | H14: 10.31 | I14: 3.99 | J14: 0.13 | K14: 200.1 | L14: 27.26 | M14: 71.81 | N14: 52.3 | O14: 0 | P14: 0.4 | Q14: 9.29
A15: 45818.073 | B15: 5.42 | C15: 17.49 | D15: 25.15 | E15: 6.05 | F15: 10.03 | G15: 35.61 | H15: 10.31 | I15: 4.17 | J15: 0.07 | K15: 185.87 | L15: 27.17 | M15: 73.27 | N15: 52.4 | O15: 0 | P15: 0.36 | Q15: 9.3
A16: 45818.083 | B16: 5.15 | C16: 16 | D16: 22.72 | E16: 5.87 | F16: 9.23 | G16: 33.42 | H16: 8.71 | I16: 3.9 | J16: 0.05 | K16: 248.18 | L16: 27.06 | M16: 74.24 | N16: 52.4 | O16: 0 | P16: 0.35 | Q16: 9.29
