Workbook

Sheet 01
A1: Station: | B1: IGKV RAIPUR
A2: Date: | B2: =$A$9 -> 01/02/2025 00:15 | C2: Power Off | G2: Pw.Off | J2: Link Fail | L2: Link F | N2: Maintenance | P2: Maint.
A3: Report Type: | B3: Mean | C3: Calibration | G3: Calib. | J3: Data Fail | L3: Data F | N3: Invalid | P3: Invalid
A4: Time Base: | B4: 15 Min | C4: Zero Referrence | G4: Z.Ref | J4: Warm Up | L4: Wm. Up
A7: Date & Time | B7: NO | C7: NO2 | D7: NOX | E7: SO2 | F7: O3 | G7: PM 10 | H7: PM 2.5 | I7: BENZ | J7: WS | K7: WD | L7: TEMP | M7: HUM | N7: SR | O7: RG | P7: CO | Q7: NH3
B8: ug/m3 | C8: ug/m3 | D8: ppb | E8: ug/m3 | F8: ug/m3 | G8: ug/m3 | H8: ug/m3 | I8: ug/m3 | J8: m/sec | K8: deg | L8: degreC | M8: % | N8: w/m2 | O8: mm | P8: mg/m3 | Q8: ug/m3
A9: 01/02/2025 00:15 | B9: 11 | C9: 26.45 | D9: 23.99 | E9: 10.13 | F9: Invalid | G9: 85.7 | H9: 26.02 | I9: 11.32 | J9: 0.14 | K9: 156.62 | L9: 21.92 | M9: 83.39 | N9: 1.3 | O9: 0 | P9: 0.96 | Q9: 12.97
A10: 01/02/2025 00:30 | B10: 11.25 | C10: 24.95 | D10: 23.41 | E10: 9.87 | F10: Invalid | G10: 85.7 | H10: 26.02 | I10: 11.4 | J10: 0.17 | K10: 189.37 | L10: 21.7 | M10: 87.51 | N10: 1.4 | O10: 0 | P10: 0.96 | Q10: 12.95
A11: 01/02/2025 00:45 | B11: 11.59 | C11: 23.63 | D11: 22.99 | E11: 9.71 | F11: Invalid | G11: 85.7 | H11: 26 | I11: 11.48 | J11: 0.15 | K11: 177.76 | L11: 21.21 | M11: 88.34 | N11: 1.6 | O11: 0 | P11: 0.97 | Q11: 12.95
A12: 01/02/2025 01:00 | B12: 11.86 | C12: 24.49 | D12: 23.66 | E12: 9.78 | F12: Invalid | G12: 85.84 | H12: 25.41 | I12: 11.54 | J12: 0.16 | K12: 218.05 | L12: 21.07 | M12: 88.69 | N12: 1.4 | O12: 0 | P12: 0.97 | Q12: 12.96
A13: 01/02/2025 01:15 | B13: 12.11 | C13: 24.53 | D13: 23.88 | E13: 9.86 | F13: Invalid | G13: 85.84 | H13: 25.41 | I13: 11.53 | J13: 0.09 | K13: 162.09 | L13: 20.97 | M13: 87.27 | N13: 1.3 | O13: 0 | P13: 0.97 | Q13: 12.96
A14: 01/02/2025 01:30 | B14: 12.39 | C14: 23.4 | D14: 23.52 | E14: 9.82 | F14: Invalid | G14: 85.84 | H14: 25.41 | I14: 11.59 | J14: 0.13 | K14: 192.97 | L14: 20.87 | M14: 87.37 | N14: 1.3 | O14: 0 | P14: 0.98 | Q14: 12.96
A15: 01/02/2025 01:45 | B15: 12.64 | C15: 23.58 | D15: 23.81 | E15: 9.67 | F15: Invalid | G15: 85.66 | H15: 25.53 | I15: 11.58 | J15: 0.13 | K15: 186.51 | L15: 20.72 | M15: 87.44 | N15: 1.4 | O15: 0 | P15: 0.98 | Q15: 12.95
A16: 01/02/2025 02:00 | B16: 12.83 | C16: 24.53 | D16: 24.46 | E16: 9.75 | F16: Invalid | G16: 80.47 | H16: 29.32 | I16: 11.55 | J16: 0.12 | K16: 144.3 | L16: 20.55 | M16: 87.86 | N16: 1.3 | O16: 0 | P16: 0.97 | Q16: 12.95
A17: 01/02/2025 02:15 | B17: 13.13 | C17: 23.89 | D17: 24.36 | E17: 8.91 | F17: Invalid | G17: 80.47 | H17: 29.32 | I17: 11.57 | J17: 0.2 | K17: 151.99 | L17: 20.46 | M17: 88.63 | N17: 1.4 | O17: 0 | P17: 0.99 | Q17: 12.95
A18: 01/02/2025 02:30 | B18: 13.34 | C18: 24.26 | D18: 24.72 | E18: 10.16 | F18: Invalid | G18: 80.47 | H18: 29.32 | I18: 11.54 | J18: 0.13 | K18: 171.8 | L18: 20.32 | M18: 88.46 | N18: 1.4 | O18: 0 | P18: 0.99 | Q18: 12.96
A19: 01/02/2025 02:45 | B19: 13.5 | C19: 24.49 | D19: 24.97 | E19: 10.24 | F19: Invalid | G19: 80.18 | H19: 29.19 | I19: 11.56 | J19: 0.15 | K19: 229.58 | L19: 20.08 | M19: 89.54 | N19: 1.4 | O19: 0 | P19: 1 | Q19: 12.96
A20: 01/02/2025 03:00 | B20: 13.64 | C20: 24.54 | D20: 25.11 | E20: 10.33 | F20: Invalid | G20: 71.72 | H20: 24.83 | I20: 11.64 | J20: 0.11 | K20: 199.99 | L20: 19.97 | M20: 90.19 | N20: 1.3 | O20: 0 | P20: 0.99 | Q20: 12.97
... A104: 01/02/2025 24:00 | B104: 14.89 | C104: 23.76 | D104: 25.7 | E104: 8.26 | F104: Invalid | G104: 95.67 | H104: 27.18 | I104: 11.67 | J104: 0.17 | K104: 200.86 | L104: 21.46 | M104: 79.14 | N104: 1.2 | O104: 0 | P104: 0.99 | Q104: 12.97
A106: Min | B106: =MIN(B9:B104) -> 4.06 | C106: =MIN(C9:C104) -> 16.51 | D106: =MIN(D9:D104) -> 13.96 | E106: =MIN(E9:E104) -> 6.83 | F106: =MIN(F9:F104) -> 0 | G106: =MIN(G9:G104) -> 37.15 | H106: =MIN(H9:H104) -> 16.62 | I106: =MIN(I9:I104) -> 5.68 | ... Q106: =MIN(Q9:Q104) -> 12.91
A107: Max | B107: =MAX(B9:B104) -> 16.44 | C107: =MAX(C9:C104) -> 27.11 | D107: =MAX(D9:D104) -> 27.57 | E107: =MAX(E9:E104) -> 11.06 | F107: =MAX(F9:F104) -> 0 | G107: =MAX(G9:G104) -> 145.38 | H107: =MAX(H9:H104) -> 29.32 | I107: =MAX(I9:I104) -> 12.58 | ... Q107: =MAX(Q9:Q104) -> 12.98
A108: Avg | B108: =AVERAGE(B9:B104) -> 10.149271 | C108: =AVERAGE(C9:C104) -> 21.721458 | D108: =AVERAGE(D9:D104) -> 20.838646 | E108: =AVERAGE(E9:E104) -> 9.5063542 | F108: =AVERAGE(F9:F104) -> #DIV/0! | G108: =AVERAGE(G9:G104) -> 71.219896 | H108: =AVERAGE(H9:H104) -> 22.801875 | I108: =AVERAGE(I9:I104) -> 10.100417 | ... Q108: =AVERAGE(Q9:Q104) -> 12.945417
A109: Stdev | B109: =STDEV(B9:B104) -> 4.0223639 | C109: =STDEV(C9:C104) -> 2.8424011 | D109: =STDEV(D9:D104) -> 4.4120616 | E109: =STDEV(E9:E104) -> 0.74675596 | F109: =STDEV(F9:F104) -> #DIV/0! | G109: =STDEV(G9:G104) -> 32.322386 | H109: =STDEV(H9:H104) -> 3.2465727 | I109: =STDEV(I9:I104) -> 2.1759832 | ... Q109: =STDEV(Q9:Q104) -> 0.019730642
A110: Num | B110: =COUNT(B9:B104) -> 96 | C110: =COUNT(C9:C104) -> 96 | D110: =COUNT(D9:D104) -> 96 | E110: =COUNT(E9:E104) -> 96 | F110: =COUNT(F9:F104) -> 0 | G110: =COUNT(G9:G104) -> 96 | H110: =COUNT(H9:H104) -> 96 | I110: =COUNT(I9:I104) -> 96 | ... Q110: =COUNT(Q9:Q104) -> 96
A111: DCR | B111: =IF(B110>=87,">90%",IF(B110<=87,"<90%")) -> >90% | C111: =IF(C110>=87,">90%",IF(C110<=87,"<90%")) -> >90% | D111: =IF(D110>=87,">90%",IF(D110<=87,"<90%")) -> >90% | E111: =IF(E110>=87,">90%",IF(E110<=87,"<90%")) -> >90% | F111: =IF(F110>=87,">90%",IF(F110<=87,"<90%")) -> <90% | G111: =IF(G110>=87,">90%",IF(G110<=87,"<90%")) -> >90% | H111: =IF(H110>=87,">90%",IF(H110<=87,"<90%")) -> >90% | I111: =IF(I110>=87,">90%",IF(I110<=87,"<90%")) -> >90% | ... Q111: =IF(Q110>=87,">90%",IF(Q110<=87,"<90%")) -> >90%
A112: Status | B112: =IF(B110>=87,"OK",IF(B110<=87,"LESS")) -> OK | C112: =IF(C110>=87,"OK",IF(C110<=87,"LESS")) -> OK | D112: =IF(D110>=87,"OK",IF(D110<=87,"LESS")) -> OK | E112: =IF(E110>=87,"OK",IF(E110<=87,"LESS")) -> OK | F112: =IF(F110>=87,"OK",IF(F110<=87,"LESS")) -> LESS | G112: =IF(G110>=87,"OK",IF(G110<=87,"LESS")) -> OK | H112: =IF(H110>=87,"OK",IF(H110<=87,"LESS")) -> OK | I112: =IF(I110>=87,"OK",IF(I110<=87,"LESS")) -> OK | ... Q112: =IF(Q110>=87,"OK",IF(Q110<=87,"LESS")) -> OK
A115: Done by | B115: AKASH
A117: Comment

Sheet 02
A1: Station: | B1: IGKV RAIPUR
A2: Date: | B2: =$A$9 -> 02/02/2025 00:15 | C2: Power Off | G2: Pw.Off | J2: Link Fail | L2: Link F | N2: Maintenance | P2: Maint.
A3: Report Type: | B3: Mean | C3: Calibration | G3: Calib. | J3: Data Fail | L3: Data F | N3: Invalid | P3: Invalid
A4: Time Base: | B4: 15 Min | C4: Zero Referrence | G4: Z.Ref | J4: Warm Up | L4: Wm. Up
A7: Date & Time | B7: NO | C7: NO2 | D7: NOX | E7: SO2 | F7: O3 | G7: PM 10 | H7: PM 2.5 | I7: BENZ | J7: WS | K7: WD | L7: TEMP | M7: HUM | N7: SR | O7: RG | P7: CO | Q7: NH3
B8: ug/m3 | C8: ug/m3 | D8: ppb | E8: ug/m3 | F8: ug/m3 | G8: ug/m3 | H8: ug/m3 | I8: ug/m3 | J8: m/sec | K8: deg | L8: degreC | M8: % | N8: w/m2 | O8: mm | P8: mg/m3 | Q8: ug/m3
A9: 02/02/2025 00:15 | B9: 14.48 | C9: 22.42 | D9: 24.68 | E9: 8.18 | F9: Invalid | G9: 95.67 | H9: 27.18 | I9: 11.86 | J9: 0.17 | K9: 207.42 | L9: 21.27 | M9: 79.39 | N9: 1.4 | O9: 0 | P9: 0.99 | Q9: 12.97
A10: 02/02/2025 00:30 | B10: 14.21 | C10: 23.38 | D10: 24.96 | E10: 8.09 | F10: Invalid | G10: 95.67 | H10: 27.18 | I10: 12.05 | J10: 0.14 | K10: 202.35 | L10: 20.95 | M10: 80.44 | N10: 1.4 | O10: 0 | P10: 1.01 | Q10: 12.96
A11: 02/02/2025 00:45 | B11: 13.98 | C11: 23.51 | D11: 24.84 | E11: 7.94 | F11: Invalid | G11: 96.08 | H11: 27.08 | I11: 12.19 | J11: 0.14 | K11: 215.2 | L11: 20.91 | M11: 82.35 | N11: 1.2 | O11: 0 | P11: 1.01 | Q11: 12.96
A12: 02/02/2025 01:00 | B12: 13.78 | C12: 23.39 | D12: 24.62 | E12: 7.94 | F12: Invalid | G12: 104.91 | H12: 24.13 | I12: 12.35 | J12: 0.15 | K12: 226.82 | L12: 20.78 | M12: 82.84 | N12: 1.3 | O12: 0 | P12: 1.02 | Q12: 12.96
A13: 02/02/2025 01:15 | B13: 13.63 | C13: 23.37 | D13: 24.49 | E13: 8.11 | F13: Invalid | G13: 104.91 | H13: 24.13 | I13: 12.52 | J13: 0.16 | K13: 203.88 | L13: 20.8 | M13: 83.61 | N13: 1.2 | O13: 0 | P13: 1.02 | Q13: 12.96
A14: 02/02/2025 01:30 | B14: 13.53 | C14: 23.33 | D14: 24.39 | E14: 7.66 | F14: Invalid | G14: 104.91 | H14: 24.13 | I14: 12.68 | J14: 0.17 | K14: 202.11 | L14: 20.67 | M14: 84.51 | N14: 1.3 | O14: 0 | P14: 1.03 | Q14: 12.97
A15: 02/02/2025 01:45 | B15: 13.42 | C15: 23.19 | D15: 24.23 | E15: 7.6 | F15: Invalid | G15: 104.27 | H15: 24.15 | I15: 12.77 | J15: 0.16 | K15: 211.01 | L15: 20.57 | M15: 84.05 | N15: 1.3 | O15: 0 | P15: 1.03 | Q15: 12.98
A16: 02/02/2025 02:00 | B16: 13.29 | C16: 23.15 | D16: 24.1 | E16: 7.65 | F16: Invalid | G16: 90.49 | H16: 24.78 | I16: 12.85 | J16: 0.13 | K16: 199.41 | L16: 20.49 | M16: 83.71 | N16: 1.3 | O16: 0 | P16: 1.02 | Q16: 12.96
A17: 02/02/2025 02:15 | B17: 13.2 | C17: 23 | D17: 23.95 | E17: 9.07 | F17: Invalid | G17: 90.49 | H17: 24.78 | I17: 12.94 | J17: 0.12 | K17: 157.46 | L17: 20.3 | M17: 83.76 | N17: 1.4 | O17: 0 | P17: 1.03 | Q17: 12.95
A18: 02/02/2025 02:30 | B18: 13.15 | C18: 22.77 | D18: 23.79 | E18: 11.22 | F18: Invalid | G18: 90.49 | H18: 24.78 | I18: 12.99 | J18: 0.11 | K18: 140.57 | L18: 20.19 | M18: 83.94 | N18: 1.3 | O18: 0 | P18: 1.03 | Q18: 12.96
A19: 02/02/2025 02:45 | B19: 13.02 | C19: 22.49 | D19: 23.54 | E19: 10.74 | F19: Invalid | G19: 90.24 | H19: 24.62 | I19: 13.02 | J19: 0.18 | K19: 157.08 | L19: 20.22 | M19: 84.27 | N19: 1.1 | O19: 0 | P19: 1.03 | Q19: 12.96
A20: 02/02/2025 03:00 | B20: 12.83 | C20: 22.55 | D20: 23.42 | E20: 11.03 | F20: Invalid | G20: 83.25 | H20: 21.37 | I20: 13.08 | J20: 0.18 | K20: 162.49 | L20: 20.24 | M20: 83.85 | N20: 1.3 | O20: 0 | P20: 1.02 | Q20: 12.93
... A104: 02/02/2025 24:00 | B104: 11 | C104: 23.6 | D104: 22.5 | E104: 8.84 | F104: Invalid | G104: 80.69 | H104: 24.4 | I104: 12.98 | J104: 0.19 | K104: 134.34 | L104: 21.92 | M104: 73.22 | N104: 1.4 | O104: 0 | P104: 1.1 | Q104: 12.94
A106: Min | B106: =MIN(B9:B104) -> 3.94 | C106: =MIN(C9:C104) -> 19.48 | D106: =MIN(D9:D104) -> 15.09 | E106: =MIN(E9:E104) -> 7.06 | F106: =MIN(F9:F104) -> 0 | G106: =MIN(G9:G104) -> 37.54 | H106: =MIN(H9:H104) -> 15.65 | I106: =MIN(I9:I104) -> 8.58 | ... Q106: =MIN(Q9:Q104) -> 12.9
A107: Max | B107: =MAX(B9:B104) -> 14.55 | C107: =MAX(C9:C104) -> 25.26 | D107: =MAX(D9:D104) -> 24.96 | E107: =MAX(E9:E104) -> 19.06 | F107: =MAX(F9:F104) -> 0 | G107: =MAX(G9:G104) -> 104.91 | H107: =MAX(H9:H104) -> 27.18 | I107: =MAX(I9:I104) -> 15.83 | ... Q107: =MAX(Q9:Q104) -> 12.98
A108: Avg | B108: =AVERAGE(B9:B104) -> 8.8175 | C108: =AVERAGE(C9:C104) -> 22.713646 | D108: =AVERAGE(D9:D104) -> 20.288958 | E108: =AVERAGE(E9:E104) -> 10.544792 | F108: =AVERAGE(F9:F104) -> #DIV/0! | G108: =AVERAGE(G9:G104) -> 65.308958 | H108: =AVERAGE(H9:H104) -> 21.862188 | I108: =AVERAGE(I9:I104) -> 11.943854 | ... Q108: =AVERAGE(Q9:Q104) -> 12.9425
A109: Stdev | B109: =STDEV(B9:B104) -> 3.9827903 | C109: =STDEV(C9:C104) -> 1.1651791 | D109: =STDEV(D9:D104) -> 3.2295007 | E109: =STDEV(E9:E104) -> 2.5085122 | F109: =STDEV(F9:F104) -> #DIV/0! | G109: =STDEV(G9:G104) -> 16.596399 | H109: =STDEV(H9:H104) -> 2.615075 | I109: =STDEV(I9:I104) -> 1.9079939 | ... Q109: =STDEV(Q9:Q104) -> 0.016795989
A110: Num | B110: =COUNT(B9:B104) -> 96 | C110: =COUNT(C9:C104) -> 96 | D110: =COUNT(D9:D104) -> 96 | E110: =COUNT(E9:E104) -> 96 | F110: =COUNT(F9:F104) -> 0 | G110: =COUNT(G9:G104) -> 96 | H110: =COUNT(H9:H104) -> 96 | I110: =COUNT(I9:I104) -> 96 | ... Q110: =COUNT(Q9:Q104) -> 96
A111: DCR | B111: =IF(B110>=87,">90%",IF(B110<=87,"<90%")) -> >90% | C111: =IF(C110>=87,">90%",IF(C110<=87,"<90%")) -> >90% | D111: =IF(D110>=87,">90%",IF(D110<=87,"<90%")) -> >90% | E111: =IF(E110>=87,">90%",IF(E110<=87,"<90%")) -> >90% | F111: =IF(F110>=87,">90%",IF(F110<=87,"<90%")) -> <90% | G111: =IF(G110>=87,">90%",IF(G110<=87,"<90%")) -> >90% | H111: =IF(H110>=87,">90%",IF(H110<=87,"<90%")) -> >90% | I111: =IF(I110>=87,">90%",IF(I110<=87,"<90%")) -> >90% | ... Q111: =IF(Q110>=87,">90%",IF(Q110<=87,"<90%")) -> >90%
A112: Status | B112: =IF(B110>=87,"OK",IF(B110<=87,"LESS")) -> OK | C112: =IF(C110>=87,"OK",IF(C110<=87,"LESS")) -> OK | D112: =IF(D110>=87,"OK",IF(D110<=87,"LESS")) -> OK | E112: =IF(E110>=87,"OK",IF(E110<=87,"LESS")) -> OK | F112: =IF(F110>=87,"OK",IF(F110<=87,"LESS")) -> LESS | G112: =IF(G110>=87,"OK",IF(G110<=87,"LESS")) -> OK | H112: =IF(H110>=87,"OK",IF(H110<=87,"LESS")) -> OK | I112: =IF(I110>=87,"OK",IF(I110<=87,"LESS")) -> OK | ... Q112: =IF(Q110>=87,"OK",IF(Q110<=87,"LESS")) -> OK
A115: Done by | B115: AKASH
A117: Comment

Sheet 03
A1: Station: | B1: IGKV RAIPUR
A2: Date: | B2: =$A$9 -> 03/02/2025 00:15 | C2: Power Off | G2: Pw.Off | J2: Link Fail | L2: Link F | N2: Maintenance | P2: Maint.
A3: Report Type: | B3: Mean | C3: Calibration | G3: Calib. | J3: Data Fail | L3: Data F | N3: Invalid | P3: Invalid
A4: Time Base: | B4: 15 Min | C4: Zero Referrence | G4: Z.Ref | J4: Warm Up | L4: Wm. Up
A7: Date & Time | B7: NO | C7: NO2 | D7: NOX | E7: SO2 | F7: O3 | G7: PM 10 | H7: PM 2.5 | I7: BENZ | J7: WS | K7: WD | L7: TEMP | M7: HUM | N7: SR | O7: RG | P7: CO | Q7: NH3
B8: ug/m3 | C8: ug/m3 | D8: ppb | E8: ug/m3 | F8: ug/m3 | G8: ug/m3 | H8: ug/m3 | I8: ug/m3 | J8: m/sec | K8: deg | L8: degreC | M8: % | N8: w/m2 | O8: mm | P8: mg/m3 | Q8: ug/m3
A9: 03/02/2025 00:15 | B9: 12.25 | C9: 21.03 | D9: 22.16 | E9: 9.2 | F9: Invalid | G9: 69.07 | H9: 17.42 | I9: 8.91 | J9: 0.17 | K9: 176.87 | L9: 20.83 | M9: 62.17 | N9: 1 | O9: 0 | P9: 0.77 | Q9: 14.58
A10: 03/02/2025 00:30 | B10: 12.36 | C10: 21.32 | D10: 22.4 | E10: 9.35 | F10: Invalid | G10: 72.23 | H10: 21.6 | I10: 9.13 | J10: 0.14 | K10: 205.45 | L10: 20.56 | M10: 65.19 | N10: 1.1 | O10: 0 | P10: 0.78 | Q10: 14.58
A11: 03/02/2025 00:45 | B11: 12.52 | C11: 21.42 | D11: 22.58 | E11: 9.64 | F11: Invalid | G11: 73.37 | H11: 21.67 | I11: 9.33 | J11: 0.26 | K11: 86.52 | L11: 20.57 | M11: 62.74 | N11: 0.9 | O11: 0 | P11: 0.77 | Q11: 14.58
A12: 03/02/2025 01:00 | B12: 12.84 | C12: 21.69 | D12: 22.98 | E12: 9.39 | F12: Invalid | G12: 73.37 | H12: 21.67 | I12: 9.5 | J12: 0.64 | K12: 41.06 | L12: 21.99 | M12: 51.4 | N12: 0 | O12: 0 | P12: 0.73 | Q12: 14.58
A13: 03/02/2025 01:15 | B13: 13.8 | C13: 22.41 | D13: 24.13 | E13: 9.5 | F13: Invalid | G13: 73.37 | H13: 21.67 | I13: 9.58 | J13: 0.2 | K13: 67.75 | L13: 22.41 | M13: 51.31 | N13: 0.9 | O13: 0 | P13: 0.74 | Q13: 14.58
A14: 03/02/2025 01:30 | B14: 14.84 | C14: 22.99 | D14: 25.27 | E14: 9.8 | F14: Invalid | G14: 77.78 | H14: 19.34 | I14: 9.77 | J14: 0.19 | K14: 142.35 | L14: 22.07 | M14: 54.42 | N14: 1.4 | O14: 0 | P14: 0.78 | Q14: 14.58
A15: 03/02/2025 01:45 | B15: 15.8 | C15: 23.55 | D15: 26.32 | E15: 10.2 | F15: Invalid | G15: 79.38 | H15: 19.3 | I15: 10.27 | J15: 0.23 | K15: 181.05 | L15: 21.53 | M15: 58 | N15: 1.6 | O15: 0 | P15: 0.81 | Q15: 14.58
A16: 03/02/2025 02:00 | B16: 16.73 | C16: 23.87 | D16: 27.24 | E16: 10.04 | F16: Invalid | G16: 79.38 | H16: 19.3 | I16: 10.91 | J16: 0.19 | K16: 194.6 | L16: 20.63 | M16: 64.44 | N16: 1.8 | O16: 0 | P16: 0.84 | Q16: 14.58
A17: 03/02/2025 02:15 | B17: 17.47 | C17: 24.02 | D17: 27.91 | E17: 8.29 | F17: Invalid | G17: 79.38 | H17: 19.3 | I17: 11.59 | J17: 0.22 | K17: 184.03 | L17: 20.18 | M17: 67.36 | N17: 1.6 | O17: 0 | P17: 0.88 | Q17: 14.58
A18: 03/02/2025 02:30 | B18: 17.97 | C18: 24.05 | D18: 28.33 | E18: 9.72 | F18: Invalid | G18: 96.26 | H18: 26.23 | I18: 12.27 | J18: 0.21 | K18: 167.84 | L18: 20.02 | M18: 66.39 | N18: 1.3 | O18: 0 | P18: 0.9 | Q18: 14.58
A19: 03/02/2025 02:45 | B19: 18.46 | C19: 23.85 | D19: 28.61 | E19: 10.16 | F19: Invalid | G19: 102.4 | H19: 26.34 | I19: 12.84 | J19: 0.14 | K19: 195.08 | L19: 19.75 | M19: 69.19 | N19: 1.3 | O19: 0 | P19: 0.92 | Q19: 14.58
A20: 03/02/2025 03:00 | B20: 18.76 | C20: 23.83 | D20: 28.85 | E20: 9.65 | F20: Invalid | G20: 102.4 | H20: 26.34 | I20: 13.29 | J20: 0.18 | K20: 183.01 | L20: 19.66 | M20: 67.65 | N20: 1.1 | O20: 0 | P20: 0.93 | Q20: 14.58
... A104: 03/02/2025 24:00 | B104: 7.08 | C104: 24.57 | D104: 19.87 | E104: 10.59 | F104: Invalid | G104: 107.8 | H104: 31.99 | I104: 11.92 | J104: 0.15 | K104: 200.21 | L104: 21.82 | M104: 64.27 | N104: 1.1 | O104: 0 | P104: 0.85 | Q104: 12.93
A106: Min | B106: =MIN(B9:B104) -> 3.77 | C106: =MIN(C9:C104) -> 21.03 | D106: =MIN(D9:D104) -> 16.66 | E106: =MIN(E9:E104) -> 8.29 | F106: =MIN(F9:F104) -> 0 | G106: =MIN(G9:G104) -> 66.95 | H106: =MIN(H9:H104) -> 17.42 | I106: =MIN(I9:I104) -> 8.91 | ... Q106: =MIN(Q9:Q104) -> 12.89
A107: Max | B107: =MAX(B9:B104) -> 43.65 | C107: =MAX(C9:C104) -> 32.41 | D107: =MAX(D9:D104) -> 50.39 | E107: =MAX(E9:E104) -> 44.16 | F107: =MAX(F9:F104) -> 0 | G107: =MAX(G9:G104) -> 137.72 | H107: =MAX(H9:H104) -> 40.85 | I107: =MAX(I9:I104) -> 17.16 | ... Q107: =MAX(Q9:Q104) -> 14.58
A108: Avg | B108: =AVERAGE(B9:B104) -> 15.995938 | C108: =AVERAGE(C9:C104) -> 25.836354 | D108: =AVERAGE(D9:D104) -> 27.677083 | E108: =AVERAGE(E9:E104) -> 13.822188 | F108: =AVERAGE(F9:F104) -> #DIV/0! | G108: =AVERAGE(G9:G104) -> 99.183021 | H108: =AVERAGE(H9:H104) -> 32.228542 | I108: =AVERAGE(I9:I104) -> 12.597188 | ... Q108: =AVERAGE(Q9:Q104) -> 13.783438
A109: Stdev | B109: =STDEV(B9:B104) -> 13.210722 | C109: =STDEV(C9:C104) -> 2.2374817 | D109: =STDEV(D9:D104) -> 10.709715 | E109: =STDEV(E9:E104) -> 7.6088153 | F109: =STDEV(F9:F104) -> #DIV/0! | G109: =STDEV(G9:G104) -> 19.934434 | H109: =STDEV(H9:H104) -> 6.9894752 | I109: =STDEV(I9:I104) -> 2.4639086 | ... Q109: =STDEV(Q9:Q104) -> 0.83488143
A110: Num | B110: =COUNT(B9:B104) -> 96 | C110: =COUNT(C9:C104) -> 96 | D110: =COUNT(D9:D104) -> 96 | E110: =COUNT(E9:E104) -> 96 | F110: =COUNT(F9:F104) -> 0 | G110: =COUNT(G9:G104) -> 96 | H110: =COUNT(H9:H104) -> 96 | I110: =COUNT(I9:I104) -> 96 | ... Q110: =COUNT(Q9:Q104) -> 96
A111: DCR | B111: =IF(B110>=87,">90%",IF(B110<=87,"<90%")) -> >90% | C111: =IF(C110>=87,">90%",IF(C110<=87,"<90%")) -> >90% | D111: =IF(D110>=87,">90%",IF(D110<=87,"<90%")) -> >90% | E111: =IF(E110>=87,">90%",IF(E110<=87,"<90%")) -> >90% | F111: =IF(F110>=87,">90%",IF(F110<=87,"<90%")) -> <90% | G111: =IF(G110>=87,">90%",IF(G110<=87,"<90%")) -> >90% | H111: =IF(H110>=87,">90%",IF(H110<=87,"<90%")) -> >90% | I111: =IF(I110>=87,">90%",IF(I110<=87,"<90%")) -> >90% | ... Q111: =IF(Q110>=87,">90%",IF(Q110<=87,"<90%")) -> >90%
A112: Status | B112: =IF(B110>=87,"OK",IF(B110<=87,"LESS")) -> OK | C112: =IF(C110>=87,"OK",IF(C110<=87,"LESS")) -> OK | D112: =IF(D110>=87,"OK",IF(D110<=87,"LESS")) -> OK | E112: =IF(E110>=87,"OK",IF(E110<=87,"LESS")) -> OK | F112: =IF(F110>=87,"OK",IF(F110<=87,"LESS")) -> LESS | G112: =IF(G110>=87,"OK",IF(G110<=87,"LESS")) -> OK | H112: =IF(H110>=87,"OK",IF(H110<=87,"LESS")) -> OK | I112: =IF(I110>=87,"OK",IF(I110<=87,"LESS")) -> OK | ... Q112: =IF(Q110>=87,"OK",IF(Q110<=87,"LESS")) -> OK
A115: Done by | B115: AKASH
A117: Comment

Sheet 04
A1: Station: | B1: IGKV RAIPUR
A2: Date: | B2: =$A$9 -> 04/02/2025 00:15 | C2: Power Off | G2: Pw.Off | J2: Link Fail | L2: Link F | N2: Maintenance | P2: Maint.
A3: Report Type: | B3: Mean | C3: Calibration | G3: Calib. | J3: Data Fail | L3: Data F | N3: Invalid | P3: Invalid
A4: Time Base: | B4: 15 Min | C4: Zero Referrence | G4: Z.Ref | J4: Warm Up | L4: Wm. Up
A7: Date & Time | B7: NO | C7: NO2 | D7: NOX | E7: SO2 | F7: O3 | G7: PM 10 | H7: PM 2.5 | I7: BENZ | J7: WS | K7: WD | L7: TEMP | M7: HUM | N7: SR | O7: RG | P7: CO | Q7: NH3
B8: ug/m3 | C8: ug/m3 | D8: ppb | E8: ug/m3 | F8: ug/m3 | G8: ug/m3 | H8: ug/m3 | I8: ug/m3 | J8: m/sec | K8: deg | L8: degreC | M8: % | N8: w/m2 | O8: mm | P8: mg/m3 | Q8: ug/m3
A9: 04/02/2025 00:15 | B9: 10.16 | C9: 25.67 | D9: 22.91 | E9: 11.28 | F9: Invalid | G9: 89.53 | H9: 26.38 | I9: 11.52 | J9: 0.09 | K9: 94.97 | L9: 23.86 | M9: 54.71 | N9: 1.2 | O9: 0 | P9: 0.9 | Q9: 12.96
A10: 04/02/2025 00:30 | B10: 10.42 | C10: 26.32 | D10: 23.46 | E10: 11.03 | F10: Invalid | G10: 102.25 | H10: 35.3 | I10: 11.72 | J10: 0.08 | K10: 133.61 | L10: 22.84 | M10: 60.18 | N10: 1.8 | O10: 0 | P10: 0.91 | Q10: 12.98
A11: 04/02/2025 00:45 | B11: 11.09 | C11: 27.03 | D11: 24.36 | E11: 10.84 | F11: Invalid | G11: 106.88 | H11: 35.44 | I11: 11.85 | J11: 0.33 | K11: 83.5 | L11: 23.2 | M11: 56.69 | N11: 0.8 | O11: 0 | P11: 0.92 | Q11: 12.97
A12: 04/02/2025 01:00 | B12: 12.16 | C12: 27.86 | D12: 25.66 | E12: 11.05 | F12: Invalid | G12: 106.88 | H12: 35.44 | I12: 11.96 | J12: 0.28 | K12: 184.61 | L12: 22.45 | M12: 63.58 | N12: 1.9 | O12: 0 | P12: 0.93 | Q12: 12.99
A13: 04/02/2025 01:15 | B13: 12.48 | C13: 28.21 | D13: 26.1 | E13: 11.18 | F13: Invalid | G13: 106.88 | H13: 35.44 | I13: 12.17 | J13: 0.21 | K13: 163.54 | L13: 21.67 | M13: 66.46 | N13: 1.5 | O13: 0 | P13: 0.94 | Q13: 12.99
A14: 04/02/2025 01:30 | B14: 12.38 | C14: 28.19 | D14: 26.01 | E14: 11.18 | F14: Invalid | G14: 113.17 | H14: 35.28 | I14: 12.37 | J14: 0.15 | K14: 226.79 | L14: 21.29 | M14: 68.55 | N14: 1.4 | O14: 0 | P14: 0.95 | Q14: 12.99
A15: 04/02/2025 01:45 | B15: 12.67 | C15: 28.13 | D15: 26.21 | E15: 10.84 | F15: Invalid | G15: 115.46 | H15: 35.28 | I15: 12.47 | J15: 0.07 | K15: 142.25 | L15: 21.34 | M15: 66.62 | N15: 1.1 | O15: 0 | P15: 0.96 | Q15: 12.99
A16: 04/02/2025 02:00 | B16: 13.21 | C16: 28.24 | D16: 26.7 | E16: 10.75 | F16: Invalid | G16: 115.46 | H16: 35.28 | I16: 12.56 | J16: 0.26 | K16: 198.74 | L16: 21.43 | M16: 67.83 | N16: 1.1 | O16: 0 | P16: 0.97 | Q16: 13
A17: 04/02/2025 02:15 | B17: 13.44 | C17: 28.33 | D17: 26.93 | E17: 9.1 | F17: Invalid | G17: 115.46 | H17: 35.28 | I17: 12.65 | J17: 0.08 | K17: 218.1 | L17: 21.06 | M17: 68.53 | N17: 1.3 | O17: 0 | P17: 0.98 | Q17: 13
A18: 04/02/2025 02:30 | B18: 13.89 | C18: 28.62 | D18: 27.44 | E18: 10.65 | F18: Invalid | G18: 108.31 | H18: 35.42 | I18: 12.74 | J18: 0.21 | K18: 103.22 | L18: 21.52 | M18: 66.16 | N18: 0.8 | O18: 0 | P18: 0.99 | Q18: 13
A19: 04/02/2025 02:45 | B19: 14.82 | C19: 28.84 | D19: 28.3 | E19: 11.03 | F19: Invalid | G19: 105.72 | H19: 35.42 | I19: 12.81 | J19: 0.01 | K19: 349.69 | L19: 21.15 | M19: 70.05 | N19: 1.4 | O19: 0 | P19: 1 | Q19: 13
A20: 04/02/2025 03:00 | B20: 15.34 | C20: 29.46 | D20: 29.05 | E20: 11.34 | F20: Invalid | G20: 105.72 | H20: 35.42 | I20: 12.88 | J20: 0.49 | K20: 63.8 | L20: 21.83 | M20: 65.39 | N20: 0.4 | O20: 0 | P20: 1.04 | Q20: 12.99
... A104: 04/02/2025 24:00 | B104: 24.66 | C104: 26.62 | D104: 35.04 | E104: 9.29 | F104: Invalid | G104: 107.32 | H104: 29.45 | I104: 12.39 | J104: 0.19 | K104: 203.37 | L104: 20.58 | M104: 66.76 | N104: 0.9 | O104: 0 | P104: 0.93 | Q104: 13
A106: Min | B106: =MIN(B9:B104) -> 4.03 | C106: =MIN(C9:C104) -> 22.27 | D106: =MIN(D9:D104) -> 16.8 | E106: =MIN(E9:E104) -> 8.03 | F106: =MIN(F9:F104) -> 0 | G106: =MIN(G9:G104) -> 45.71 | H106: =MIN(H9:H104) -> 22.1 | I106: =MIN(I9:I104) -> 6.78 | ... Q106: =MIN(Q9:Q104) -> 12.9
A107: Max | B107: =MAX(B9:B104) -> 24.66 | C107: =MAX(C9:C104) -> 29.46 | D107: =MAX(D9:D104) -> 35.12 | E107: =MAX(E9:E104) -> 24.56 | F107: =MAX(F9:F104) -> 0 | G107: =MAX(G9:G104) -> 115.46 | H107: =MAX(H9:H104) -> 50.92 | I107: =MAX(I9:I104) -> 12.93 | ... Q107: =MAX(Q9:Q104) -> 13
A108: Avg | B108: =AVERAGE(B9:B104) -> 10.409479 | C108: =AVERAGE(C9:C104) -> 26.135208 | D108: =AVERAGE(D9:D104) -> 23.35375 | E108: =AVERAGE(E9:E104) -> 11.507917 | F108: =AVERAGE(F9:F104) -> #DIV/0! | G108: =AVERAGE(G9:G104) -> 82.487604 | H108: =AVERAGE(H9:H104) -> 33.683958 | I108: =AVERAGE(I9:I104) -> 10.210833 | ... Q108: =AVERAGE(Q9:Q104) -> 12.954896
A109: Stdev | B109: =STDEV(B9:B104) -> 5.484585 | C109: =STDEV(C9:C104) -> 1.9081029 | D109: =STDEV(D9:D104) -> 5.016769 | E109: =STDEV(E9:E104) -> 2.9420161 | F109: =STDEV(F9:F104) -> #DIV/0! | G109: =STDEV(G9:G104) -> 19.232299 | H109: =STDEV(H9:H104) -> 6.3572969 | I109: =STDEV(I9:I104) -> 2.0148332 | ... Q109: =STDEV(Q9:Q104) -> 0.031986668
A110: Num | B110: =COUNT(B9:B104) -> 96 | C110: =COUNT(C9:C104) -> 96 | D110: =COUNT(D9:D104) -> 96 | E110: =COUNT(E9:E104) -> 96 | F110: =COUNT(F9:F104) -> 0 | G110: =COUNT(G9:G104) -> 96 | H110: =COUNT(H9:H104) -> 96 | I110: =COUNT(I9:I104) -> 96 | ... Q110: =COUNT(Q9:Q104) -> 96
A111: DCR | B111: =IF(B110>=87,">90%",IF(B110<=87,"<90%")) -> >90% | C111: =IF(C110>=87,">90%",IF(C110<=87,"<90%")) -> >90% | D111: =IF(D110>=87,">90%",IF(D110<=87,"<90%")) -> >90% | E111: =IF(E110>=87,">90%",IF(E110<=87,"<90%")) -> >90% | F111: =IF(F110>=87,">90%",IF(F110<=87,"<90%")) -> <90% | G111: =IF(G110>=87,">90%",IF(G110<=87,"<90%")) -> >90% | H111: =IF(H110>=87,">90%",IF(H110<=87,"<90%")) -> >90% | I111: =IF(I110>=87,">90%",IF(I110<=87,"<90%")) -> >90% | ... Q111: =IF(Q110>=87,">90%",IF(Q110<=87,"<90%")) -> >90%
A112: Status | B112: =IF(B110>=87,"OK",IF(B110<=87,"LESS")) -> OK | C112: =IF(C110>=87,"OK",IF(C110<=87,"LESS")) -> OK | D112: =IF(D110>=87,"OK",IF(D110<=87,"LESS")) -> OK | E112: =IF(E110>=87,"OK",IF(E110<=87,"LESS")) -> OK | F112: =IF(F110>=87,"OK",IF(F110<=87,"LESS")) -> LESS | G112: =IF(G110>=87,"OK",IF(G110<=87,"LESS")) -> OK | H112: =IF(H110>=87,"OK",IF(H110<=87,"LESS")) -> OK | I112: =IF(I110>=87,"OK",IF(I110<=87,"LESS")) -> OK | ... Q112: =IF(Q110>=87,"OK",IF(Q110<=87,"LESS")) -> OK
A115: Done by | B115: AKASH
A117: Comment

Sheet 05
A1: Station: | B1: IGKV RAIPUR
A2: Date: | B2: =$A$9 -> 05/02/2025 00:15 | C2: Power Off | G2: Pw.Off | J2: Link Fail | L2: Link F | N2: Maintenance | P2: Maint.
A3: Report Type: | B3: Mean | C3: Calibration | G3: Calib. | J3: Data Fail | L3: Data F | N3: Invalid | P3: Invalid
A4: Time Base: | B4: 15 Min | C4: Zero Referrence | G4: Z.Ref | J4: Warm Up | L4: Wm. Up
A7: Date & Time | B7: NO | C7: NO2 | D7: NOX | E7: SO2 | F7: O3 | G7: PM 10 | H7: PM 2.5 | I7: BENZ | J7: WS | K7: WD | L7: TEMP | M7: HUM | N7: SR | O7: RG | P7: CO | Q7: NH3
B8: ug/m3 | C8: ug/m3 | D8: ppb | E8: ug/m3 | F8: ug/m3 | G8: ug/m3 | H8: ug/m3 | I8: ug/m3 | J8: m/sec | K8: deg | L8: degreC | M8: % | N8: w/m2 | O8: mm | P8: mg/m3 | Q8: ug/m3
A9: 05/02/2025 00:15 | B9: Pw.Off | C9: Pw.Off | D9: Pw.Off | E9: Pw.Off | F9: Pw.Off | G9: Pw.Off | H9: Pw.Off | I9: Pw.Off | J9: Pw.Off | K9: Pw.Off | L9: Pw.Off | M9: Pw.Off | N9: Pw.Off | O9: Pw.Off | P9: Pw.Off | Q9: Pw.Off
A10: 05/02/2025 00:30 | B10: Pw.Off | C10: Pw.Off | D10: Pw.Off | E10: Pw.Off | F10: Pw.Off | G10: Pw.Off | H10: Pw.Off | I10: Pw.Off | J10: Pw.Off | K10: Pw.Off | L10: Pw.Off | M10: Pw.Off | N10: Pw.Off | O10: Pw.Off | P10: Pw.Off | Q10: Pw.Off
A11: 05/02/2025 00:45 | B11: Pw.Off | C11: Pw.Off | D11: Pw.Off | E11: Pw.Off | F11: Pw.Off | G11: Pw.Off | H11: Pw.Off | I11: Pw.Off | J11: Pw.Off | K11: Pw.Off | L11: Pw.Off | M11: Pw.Off | N11: Pw.Off | O11: Pw.Off | P11: Pw.Off | Q11: Pw.Off
A12: 05/02/2025 01:00 | B12: 5.33 | C12: 23.88 | D12: 18.1 | E12: 11.07 | F12: Invalid | G12: 72.43 | H12: 27.44 | I12: 14.68 | J12: 0.82 | K12: 289.82 | L12: 29.57 | M12: 45.13 | N12: 257.9 | O12: 0 | P12: 1.05 | Q12: 12.95
A13: 05/02/2025 01:15 | B13: 4.78 | C13: 24.32 | D13: 17.89 | E13: 11.49 | F13: Invalid | G13: 72.33 | H13: 27.49 | I13: 14.75 | J13: 0.62 | K13: 270.66 | L13: 30.08 | M13: 44.41 | N13: 276.4 | O13: 0 | P13: 1.06 | Q13: 12.95
A14: 05/02/2025 01:30 | B14: 4.45 | C14: 24.5 | D14: 17.72 | E14: 12 | F14: Invalid | G14: 69.43 | H14: 29.22 | I14: 14.75 | J14: 0.89 | K14: 292.63 | L14: 30.54 | M14: 43.32 | N14: 280.8 | O14: 0 | P14: 1.06 | Q14: 12.95
A15: 05/02/2025 01:45 | B15: 4.24 | C15: 24.68 | D15: 17.64 | E15: 11.5 | F15: Invalid | G15: 69.43 | H15: 29.22 | I15: 14.86 | J15: 0.61 | K15: 275.24 | L15: 30.96 | M15: 43.17 | N15: 285.9 | O15: 0 | P15: 1.05 | Q15: 12.95
A16: 05/02/2025 02:00 | B16: 4 | C16: 24.57 | D16: 17.39 | E16: 11.29 | F16: Invalid | G16: 69.43 | H16: 29.22 | I16: 14.79 | J16: 0.71 | K16: 270.15 | L16: 31.41 | M16: 41.39 | N16: 276.7 | O16: 0 | P16: 1.04 | Q16: 12.95
A17: 05/02/2025 02:15 | B17: 3.82 | C17: 24.18 | D17: 17.05 | E17: 12.1 | F17: Invalid | G17: 69.57 | H17: 29.23 | I17: 14.6 | J17: 0.78 | K17: 254.62 | L17: 32.13 | M17: 39.31 | N17: 278.9 | O17: 0 | P17: 1 | Q17: 12.95
A18: 05/02/2025 02:30 | B18: 3.75 | C18: 23.74 | D18: 16.76 | E18: 12.44 | F18: Invalid | G18: 72.54 | H18: 29.45 | I18: 14.34 | J18: 0.98 | K18: 285.68 | L18: 32.45 | M18: 37.74 | N18: 306 | O18: 0 | P18: 0.99 | Q18: 12.95
A19: 05/02/2025 02:45 | B19: 3.73 | C19: 23.54 | D19: 16.64 | E19: 12.14 | F19: Invalid | G19: 72.54 | H19: 29.45 | I19: 13.95 | J19: 1.2 | K19: 297.59 | L19: 32.24 | M19: 37.03 | N19: 307.9 | O19: 0 | P19: 0.97 | Q19: 12.94
A20: 05/02/2025 03:00 | B20: 3.75 | C20: 23.44 | D20: 16.6 | E20: 12.94 | F20: Invalid | G20: 72.54 | H20: 29.45 | I20: 13.65 | J20: 0.74 | K20: 308.29 | L20: 32.36 | M20: 37.46 | N20: 299.6 | O20: 0 | P20: 0.96 | Q20: 12.94
A21: 05/02/2025 03:15 | B21: 3.72 | C21: 23.43 | D21: 16.58 | E21: 13.65 | F21: Invalid | G21: 72.51 | H21: 29.51 | I21: 13.31 | J21: 0.83 | K21: 290.34 | L21: 32.59 | M21: 37.52 | N21: 310 | O21: 0 | P21: 0.95 | Q21: 12.95
A22: 05/02/2025 03:30 | B22: 3.7 | C22: 23.29 | D22: 16.49 | E22: 13.64 | F22: Invalid | G22: 71.9 | H22: 31.53 | I22: 13.25 | J22: 0.83 | K22: 279.53 | L22: 32.94 | M22: 36.07 | N22: 313.5 | O22: 0 | P22: 0.95 | Q22: 12.96
A23: 05/02/2025 03:45 | B23: 3.69 | C23: 23.13 | D23: 16.39 | E23: 12.68 | F23: Invalid | G23: 71.9 | H23: 31.53 | I23: 13.2 | J23: 1.02 | K23: 287.97 | L23: 32.85 | M23: 35.55 | N23: 299.5 | O23: 0 | P23: 0.93 | Q23: 12.94
... A66: 05/02/2025 14:30 | B66: 5.85 | C66: 21.36 | D66: 17.2 | E66: 11.02 | F66: Invalid | G66: 74.73 | H66: 39.96 | I66: 13.8 | J66: 0.13 | K66: 162.77 | L66: 22.98 | M66: 66.66 | N66: 1.4 | O66: 0 | P66: 0.99 | Q66: 12.94
A67: 05/02/2025 14:45 | B67: Pw.Off | C67: Pw.Off | D67: Pw.Off | E67: Pw.Off | F67: Invalid | G67: Pw.Off | H67: Pw.Off | I67: Pw.Off | J67: Pw.Off | K67: Pw.Off | L67: Pw.Off | M67: Pw.Off | N67: Pw.Off | O67: Pw.Off | P67: Pw.Off | Q67: Pw.Off
A68: 05/02/2025 15:00 | B68: 3.88 | C68: 17.39 | D68: 13.55 | E68: 9.83 | F68: Invalid | G68: 41.07 | H68: 27.49 | I68: 7.47 | J68: 0.8 | K68: 305.32 | L68: 33.37 | M68: 26.25 | N68: 87.6 | O68: 0 | P68: 0.49 | Q68: 12.93
A69: 05/02/2025 15:15 | B69: 4.13 | C69: 16.7 | D69: 13.39 | E69: 10.1 | F69: Invalid | G69: 41.07 | H69: 27.49 | I69: 7.44 | J69: 0.61 | K69: 276.41 | L69: 33.57 | M69: 27.07 | N69: 74.2 | O69: 0 | P69: 0.56 | Q69: 12.93
A70: 05/02/2025 15:30 | B70: 3.77 | C70: 16.33 | D70: 12.9 | E70: 9.81 | F70: Invalid | G70: 41.07 | H70: 27.49 | I70: 7.16 | J70: 0.62 | K70: 286.69 | L70: 33.45 | M70: 25.97 | N70: 78.4 | O70: 0 | P70: 0.56 | Q70: 12.92
A71: 05/02/2025 15:45 | B71: 3.57 | C71: 16.17 | D71: 12.66 | E71: 8.9 | F71: Invalid | G71: 40.82 | H71: 27.45 | I71: 6.95 | J71: 0.65 | K71: 269.09 | L71: 33.45 | M71: 26.64 | N71: 87.6 | O71: 0 | P71: 0.46 | Q71: 12.93
A72: 05/02/2025 16:00 | B72: 3.72 | C72: 17.17 | D72: 13.31 | E72: 10.47 | F72: Invalid | G72: 33.6 | H72: 25.97 | I72: 6.8 | J72: 0.78 | K72: 272.24 | L72: 33.13 | M72: 26.2 | N72: 55.2 | O72: 0 | P72: 0.42 | Q72: 12.94
A73: 05/02/2025 16:15 | B73: 3.77 | C73: 17.87 | D73: 13.71 | E73: 10.56 | F73: Invalid | G73: 33.6 | H73: 25.97 | I73: 6.65 | J73: 0.48 | K73: 259.25 | L73: 32.89 | M73: 27.63 | N73: 43.8 | O73: 0 | P73: 0.44 | Q73: 12.95
A74: 05/02/2025 16:30 | B74: 3.78 | C74: 18.28 | D74: 13.93 | E74: 12.28 | F74: Invalid | G74: 33.6 | H74: 25.97 | I74: 6.61 | J74: 0.48 | K74: 288.3 | L74: 32.72 | M74: 27.37 | N74: 40.6 | O74: 0 | P74: 0.44 | Q74: 12.95
A75: 05/02/2025 16:45 | B75: 3.85 | C75: 18.94 | D75: 14.34 | E75: 12.17 | F75: Invalid | G75: 33.49 | H75: 25.85 | I75: 6.61 | J75: 0.42 | K75: 271.43 | L75: 32.67 | M75: 27.99 | N75: 38.6 | O75: 0 | P75: 0.45 | Q75: 12.95
A76: 05/02/2025 17:00 | B76: 3.92 | C76: 19.34 | D76: 14.6 | E76: 11.77 | F76: Invalid | G76: 30.26 | H76: 21.93 | I76: 6.65 | J76: 0.48 | K76: 260.49 | L76: 32.03 | M76: 29.63 | N76: 26 | O76: 0 | P76: 0.43 | Q76: 12.94
A77: 05/02/2025 17:15 | B77: 3.9 | C77: 19.39 | D77: 14.61 | E77: 11.01 | F77: Invalid | G77: 30.26 | H77: 21.93 | I77: 6.69 | J77: 0.37 | K77: 255.71 | L77: 31.5 | M77: 30.33 | N77: 18.8 | O77: 0 | P77: 0.43 | Q77: 12.94
A78: 05/02/2025 17:30 | B78: 3.93 | C78: 19.21 | D78: 14.53 | E78: 10.48 | F78: Invalid | G78: 30.26 | H78: 21.93 | I78: 6.66 | J78: 0.4 | K78: 252.76 | L78: 31.09 | M78: 30.34 | N78: 12.3 | O78: 0 | P78: 0.43 | Q78: 12.93
A79: 05/02/2025 17:45 | B79: 3.95 | C79: 19.21 | D79: 14.56 | E79: 10.5 | F79: Invalid | G79: 30.54 | H79: 21.91 | I79: 6.6 | J79: 0.24 | K79: 177.8 | L79: 30.36 | M79: 34.53 | N79: 7.1 | O79: 0 | P79: 0.44 | Q79: 12.94
... A104: 05/02/2025 24:00 | B104: 12.52 | C104: 21.87 | D104: 22.82 | E104: 10.52 | F104: Invalid | G104: 58.52 | H104: 18.69 | I104: 10.94 | J104: 0.23 | K104: 184.44 | L104: 22.82 | M104: 66.7 | N104: 1.5 | O104: 0 | P104: 0.8 | Q104: 12.95
A106: Min | B106: =MIN(B9:B104) -> 3.57 | C106: =MIN(C9:C104) -> 16.17 | D106: =MIN(D9:D104) -> 12.66 | E106: =MIN(E9:E104) -> 8.79 | F106: =MIN(F9:F104) -> 0 | G106: =MIN(G9:G104) -> 30.26 | H106: =MIN(H9:H104) -> 18.69 | I106: =MIN(I9:I104) -> 6.53 | ... Q106: =MIN(Q9:Q104) -> 12.9
A107: Max | B107: =MAX(B9:B104) -> 12.52 | C107: =MAX(C9:C104) -> 24.68 | D107: =MAX(D9:D104) -> 22.82 | E107: =MAX(E9:E104) -> 19.4 | F107: =MAX(F9:F104) -> 0 | G107: =MAX(G9:G104) -> 185.6 | H107: =MAX(H9:H104) -> 57.58 | I107: =MAX(I9:I104) -> 14.86 | ... Q107: =MAX(Q9:Q104) -> 12.96
A108: Avg | B108: =AVERAGE(B9:B104) -> 5.2833696 | C108: =AVERAGE(C9:C104) -> 21.316957 | D108: =AVERAGE(D9:D104) -> 16.72587 | E108: =AVERAGE(E9:E104) -> 11.96337 | F108: =AVERAGE(F9:F104) -> #DIV/0! | G108: =AVERAGE(G9:G104) -> 71.56087 | H108: =AVERAGE(H9:H104) -> 29.692717 | I108: =AVERAGE(I9:I104) -> 10.144891 | ... Q108: =AVERAGE(Q9:Q104) -> 12.93663
A109: Stdev | B109: =STDEV(B9:B104) -> 1.9309181 | C109: =STDEV(C9:C104) -> 1.7791681 | D109: =STDEV(D9:D104) -> 1.9151359 | E109: =STDEV(E9:E104) -> 2.3538695 | F109: =STDEV(F9:F104) -> #DIV/0! | G109: =STDEV(G9:G104) -> 30.11372 | H109: =STDEV(H9:H104) -> 9.7113062 | I109: =STDEV(I9:I104) -> 2.6450283 | ... Q109: =STDEV(Q9:Q104) -> 0.010615888
...

Sheet 06
A1: Station: | B1: IGKV RAIPUR
A2: Date: | B2: =$A$9 -> 06/02/2025 00:15 | C2: Power Off | G2: Pw.Off | J2: Link Fail | L2: Link F | N2: Maintenance | P2: Maint.
A3: Report Type: | B3: Mean | C3: Calibration | G3: Calib. | J3: Data Fail | L3: Data F | N3: Invalid | P3: Invalid
A4: Time Base: | B4: 15 Min | C4: Zero Referrence | G4: Z.Ref | J4: Warm Up | L4: Wm. Up
A7: Date & Time | B7: NO | C7: NO2 | D7: NOX | E7: SO2 | F7: O3 | G7: PM 10 | H7: PM 2.5 | I7: BENZ | J7: WS | K7: WD | L7: TEMP | M7: HUM | N7: SR | O7: RG | P7: CO | Q7: NH3
B8: ug/m3 | C8: ug/m3 | D8: ppb | E8: ug/m3 | F8: ug/m3 | G8: ug/m3 | H8: ug/m3 | I8: ug/m3 | J8: m/sec | K8: deg | L8: degreC | M8: % | N8: w/m2 | O8: mm | P8: mg/m3 | Q8: ug/m3
A9: 06/02/2025 00:15 | B9: 13.52 | C9: 23.12 | D9: 24.27 | E9: 10.41 | F9: Invalid | G9: 58.52 | H9: 18.69 | I9: 11.08 | J9: 0.08 | K9: 166.75 | L9: 22.21 | M9: 67.66 | N9: 1.5 | O9: 0 | P9: 0.81 | Q9: 12.96
A10: 06/02/2025 00:30 | B10: 14.37 | C10: 22.49 | D10: 24.62 | E10: 10.88 | F10: Invalid | G10: 58.52 | H10: 18.69 | I10: 11.22 | J10: 0.15 | K10: 58.68 | L10: 22.87 | M10: 60.85 | N10: 0.6 | O10: 0 | P10: 0.83 | Q10: 12.96
A11: 06/02/2025 00:45 | B11: 16.08 | C11: 22.88 | D11: 26.2 | E11: 10.27 | F11: Invalid | G11: 59.39 | H11: 18.72 | I11: 11.33 | J11: 0.32 | K11: 49.85 | L11: 23.69 | M11: 56.23 | N11: 0.5 | O11: 0 | P11: 0.84 | Q11: 12.95
A12: 06/02/2025 01:00 | B12: 17.41 | C12: 23.21 | D12: 27.44 | E12: 11.14 | F12: Invalid | G12: 78.16 | H12: 19.57 | I12: 11.44 | J12: 0.38 | K12: 31.99 | L12: 23.81 | M12: 56.28 | N12: 0.8 | O12: 0 | P12: 0.85 | Q12: 12.98
A13: 06/02/2025 01:15 | B13: 18.26 | C13: 23.15 | D13: 28.09 | E13: 10.74 | F13: Invalid | G13: 78.16 | H13: 19.57 | I13: 11.53 | J13: 0.58 | K13: 23.39 | L13: 23.74 | M13: 57.67 | N13: 0.9 | O13: 0 | P13: 0.85 | Q13: 12.98
A14: 06/02/2025 01:30 | B14: 18.59 | C14: 23.11 | D14: 28.34 | E14: 10.36 | F14: Invalid | G14: 78.16 | H14: 19.57 | I14: 11.6 | J14: 0.58 | K14: 40.78 | L14: 23.87 | M14: 57.88 | N14: 0.9 | O14: 0 | P14: 0.82 | Q14: 12.98
A15: 06/02/2025 01:45 | B15: 17.97 | C15: 23.33 | D15: 27.95 | E15: 10.29 | F15: Invalid | G15: 78.32 | H15: 19.59 | I15: 11.62 | J15: 0.32 | K15: 46.92 | L15: 23.84 | M15: 58.45 | N15: 1.3 | O15: 0 | P15: 0.77 | Q15: 12.99
A16: 06/02/2025 02:00 | B16: 17.31 | C16: 23.67 | D16: 27.6 | E16: 10.55 | F16: Invalid | G16: 82.82 | H16: 20.45 | I16: 11.53 | J16: 0.44 | K16: 51.7 | L16: 23.53 | M16: 59.72 | N16: 1.4 | O16: 0 | P16: 0.76 | Q16: 12.98
A17: 06/02/2025 02:15 | B17: 16.89 | C17: 24.01 | D17: 27.44 | E17: 8.95 | F17: Invalid | G17: 82.82 | H17: 20.45 | I17: 11.33 | J17: 0.3 | K17: 328.48 | L17: 23.13 | M17: 61.96 | N17: 1.5 | O17: 0 | P17: 0.75 | Q17: 12.99
A18: 06/02/2025 02:30 | B18: 16.35 | C18: 24.26 | D18: 27.14 | E18: 10.45 | F18: Invalid | G18: 82.82 | H18: 20.45 | I18: 11.17 | J18: 0.54 | K18: 37.77 | L18: 23.13 | M18: 61.29 | N18: 1.1 | O18: 0 | P18: 0.72 | Q18: 12.98
A19: 06/02/2025 02:45 | B19: 15.73 | C19: 24.54 | D19: 26.79 | E19: 9.8 | F19: Invalid | G19: 82.18 | H19: 20.46 | I19: 11.05 | J19: 0.64 | K19: 39.78 | L19: 23.15 | M19: 61.34 | N19: 1.2 | O19: 0 | P19: 0.72 | Q19: 12.98
A20: 06/02/2025 03:00 | B20: 15.13 | C20: 24.83 | D20: 26.46 | E20: 9.68 | F20: Invalid | G20: 68.44 | H20: 20.55 | I20: 10.87 | J20: 0.65 | K20: 49 | L20: 22.85 | M20: 62.61 | N20: 1.5 | O20: 0 | P20: 0.71 | Q20: 12.98
... A104: 06/02/2025 24:00 | B104: 9.01 | C104: 26.03 | D104: 22.18 | E104: 9.99 | F104: Invalid | G104: 65.29 | H104: 20.06 | I104: 8.17 | J104: 0.83 | K104: 51.53 | L104: 21.43 | M104: 32.83 | N104: 1.3 | O104: 0 | P104: 0.67 | Q104: 12.95
A106: Min | B106: =MIN(B9:B104) -> 3.94 | C106: =MIN(C9:C104) -> 22.49 | D106: =MIN(D9:D104) -> 16.79 | E106: =MIN(E9:E104) -> 8.44 | F106: =MIN(F9:F104) -> 0 | G106: =MIN(G9:G104) -> 53.31 | H106: =MIN(H9:H104) -> 17.46 | I106: =MIN(I9:I104) -> 7.1 | ... Q106: =MIN(Q9:Q104) -> 12.92
A107: Max | B107: =MAX(B9:B104) -> 18.59 | C107: =MAX(C9:C104) -> 26.72 | D107: =MAX(D9:D104) -> 28.34 | E107: =MAX(E9:E104) -> 13.2 | F107: =MAX(F9:F104) -> 0 | G107: =MAX(G9:G104) -> 82.82 | H107: =MAX(H9:H104) -> 31.82 | I107: =MAX(I9:I104) -> 11.62 | ... Q107: =MAX(Q9:Q104) -> 12.99
A108: Avg | B108: =AVERAGE(B9:B104) -> 8.449375 | C108: =AVERAGE(C9:C104) -> 24.457708 | D108: =AVERAGE(D9:D104) -> 20.905937 | E108: =AVERAGE(E9:E104) -> 10.112812 | F108: =AVERAGE(F9:F104) -> #DIV/0! | G108: =AVERAGE(G9:G104) -> 67.101042 | H108: =AVERAGE(H9:H104) -> 24.01375 | I108: =AVERAGE(I9:I104) -> 8.7520833 | ... Q108: =AVERAGE(Q9:Q104) -> 12.95125
A109: Stdev | B109: =STDEV(B9:B104) -> 3.7147824 | C109: =STDEV(C9:C104) -> 0.96407739 | D109: =STDEV(D9:D104) -> 2.9283948 | E109: =STDEV(E9:E104) -> 0.93850464 | F109: =STDEV(F9:F104) -> #DIV/0! | G109: =STDEV(G9:G104) -> 8.8606694 | H109: =STDEV(H9:H104) -> 5.1486792 | I109: =STDEV(I9:I104) -> 1.2335169 | ... Q109: =STDEV(Q9:Q104) -> 0.01674892
A110: Num | B110: =COUNT(B9:B104) -> 96 | C110: =COUNT(C9:C104) -> 96 | D110: =COUNT(D9:D104) -> 96 | E110: =COUNT(E9:E104) -> 96 | F110: =COUNT(F9:F104) -> 0 | G110: =COUNT(G9:G104) -> 96 | H110: =COUNT(H9:H104) -> 96 | I110: =COUNT(I9:I104) -> 96 | ... Q110: =COUNT(Q9:Q104) -> 96
A111: DCR | B111: =IF(B110>=87,">90%",IF(B110<=87,"<90%")) -> >90% | C111: =IF(C110>=87,">90%",IF(C110<=87,"<90%")) -> >90% | D111: =IF(D110>=87,">90%",IF(D110<=87,"<90%")) -> >90% | E111: =IF(E110>=87,">90%",IF(E110<=87,"<90%")) -> >90% | F111: =IF(F110>=87,">90%",IF(F110<=87,"<90%")) -> <90% | G111: =IF(G110>=87,">90%",IF(G110<=87,"<90%")) -> >90% | H111: =IF(H110>=87,">90%",IF(H110<=87,"<90%")) -> >90% | I111: =IF(I110>=87,">90%",IF(I110<=87,"<90%")) -> >90% | ... Q111: =IF(Q110>=87,">90%",IF(Q110<=87,"<90%")) -> >90%
A112: Status | B112: =IF(B110>=87,"OK",IF(B110<=87,"LESS")) -> OK | C112: =IF(C110>=87,"OK",IF(C110<=87,"LESS")) -> OK | D112: =IF(D110>=87,"OK",IF(D110<=87,"LESS")) -> OK | E112: =IF(E110>=87,"OK",IF(E110<=87,"LESS")) -> OK | F112: =IF(F110>=87,"OK",IF(F110<=87,"LESS")) -> LESS | G112: =IF(G110>=87,"OK",IF(G110<=87,"LESS")) -> OK | H112: =IF(H110>=87,"OK",IF(H110<=87,"LESS")) -> OK | I112: =IF(I110>=87,"OK",IF(I110<=87,"LESS")) -> OK | ... Q112: =IF(Q110>=87,"OK",IF(Q110<=87,"LESS")) -> OK
A115: Done by | B115: AKASH
A117: Comment

Sheet 07
A1: Station: | B1: IGKV RAIPUR
A2: Date: | B2: =$A$9 -> 07/02/2025 00:15 | C2: Power Off | G2: Pw.Off | J2: Link Fail | L2: Link F | N2: Maintenance | P2: Maint.
A3: Report Type: | B3: Mean | C3: Calibration | G3: Calib. | J3: Data Fail | L3: Data F | N3: Invalid | P3: Invalid
A4: Time Base: | B4: 15 Min | C4: Zero Referrence | G4: Z.Ref | J4: Warm Up | L4: Wm. Up
A7: Date & Time | B7: NO | C7: NO2 | D7: NOX | E7: SO2 | F7: O3 | G7: PM 10 | H7: PM 2.5 | I7: BENZ | J7: WS | K7: WD | L7: TEMP | M7: HUM | N7: SR | O7: RG | P7: CO | Q7: NH3
B8: ug/m3 | C8: ug/m3 | D8: ppb | E8: ug/m3 | F8: ug/m3 | G8: ug/m3 | H8: ug/m3 | I8: ug/m3 | J8: m/sec | K8: deg | L8: degreC | M8: % | N8: w/m2 | O8: mm | P8: mg/m3 | Q8: ug/m3
A9: 07/02/2025 00:15 | B9: 8.84 | C9: 26.29 | D9: 22.18 | E9: 9.93 | F9: Invalid | G9: 65.29 | H9: 20.06 | I9: 7.89 | J9: 0.9 | K9: 49.91 | L9: 21.25 | M9: 32.91 | N9: 1.3 | O9: 0 | P9: 0.66 | Q9: 12.95
A10: 07/02/2025 00:30 | B10: 9.05 | C10: 26.05 | D10: 22.22 | E10: 9.52 | F10: Invalid | G10: 65.29 | H10: 20.06 | I10: 7.75 | J10: 0.71 | K10: 58.86 | L10: 21.06 | M10: 33.26 | N10: 1.3 | O10: 0 | P10: 0.65 | Q10: 12.97
A11: 07/02/2025 00:45 | B11: 9.08 | C11: 25.77 | D11: 22.09 | E11: 9.94 | F11: Invalid | G11: 65.24 | H11: 20.08 | I11: 7.67 | J11: 0.61 | K11: 56.74 | L11: 20.87 | M11: 33.93 | N11: 1.2 | O11: 0 | P11: 0.64 | Q11: 12.96
A12: 07/02/2025 01:00 | B12: 9.66 | C12: 25.72 | D12: 22.54 | E12: 9.71 | F12: Invalid | G12: 64.08 | H12: 20.74 | I12: 7.6 | J12: 0.6 | K12: 53.91 | L12: 20.71 | M12: 34.39 | N12: 1.3 | O12: 0 | P12: 0.64 | Q12: 12.95
A13: 07/02/2025 01:15 | B13: 10.39 | C13: 25.78 | D13: 23.15 | E13: 9.5 | F13: Invalid | G13: 64.08 | H13: 20.74 | I13: 7.5 | J13: 0.3 | K13: 50.5 | L13: 20.55 | M13: 35.36 | N13: 1.1 | O13: 0 | P13: 0.63 | Q13: 12.96
A14: 07/02/2025 01:30 | B14: 11.36 | C14: 25.93 | D14: 24.01 | E14: 9.33 | F14: Invalid | G14: 64.08 | H14: 20.74 | I14: 7.47 | J14: 0.42 | K14: 62.85 | L14: 20.46 | M14: 34.5 | N14: 1 | O14: 0 | P14: 0.62 | Q14: 12.98
A15: 07/02/2025 01:45 | B15: 11.79 | C15: 25.81 | D15: 24.29 | E15: 9.22 | F15: Invalid | G15: 63.95 | H15: 20.73 | I15: 7.42 | J15: 0.48 | K15: 58.81 | L15: 20.33 | M15: 34.29 | N15: 1.1 | O15: 0 | P15: 0.61 | Q15: 12.98
A16: 07/02/2025 02:00 | B16: 11.92 | C16: 25.69 | D16: 24.34 | E16: 8.78 | F16: Invalid | G16: 60.23 | H16: 20.47 | I16: 7.36 | J16: 0.46 | K16: 44.12 | L16: 20.22 | M16: 34.15 | N16: 1 | O16: 0 | P16: 0.61 | Q16: 12.98
A17: 07/02/2025 02:15 | B17: 12 | C17: 25.75 | D17: 24.43 | E17: 7.82 | F17: Invalid | G17: 60.23 | H17: 20.47 | I17: 7.3 | J17: 0.56 | K17: 49.37 | L17: 20.18 | M17: 33.45 | N17: 1.1 | O17: 0 | P17: 0.62 | Q17: 12.97
A18: 07/02/2025 02:30 | B18: 11.99 | C18: 25.63 | D18: 24.36 | E18: 9.64 | F18: Invalid | G18: 60.23 | H18: 20.47 | I18: 7.36 | J18: 0.25 | K18: 73.27 | L18: 20.01 | M18: 35 | N18: 1.3 | O18: 0 | P18: 0.66 | Q18: 12.97
A19: 07/02/2025 02:45 | B19: 11.88 | C19: 25.25 | D19: 24.07 | E19: 9.3 | F19: Invalid | G19: 60.24 | H19: 20.5 | I19: 7.39 | J19: 0.19 | K19: 162 | L19: 19.27 | M19: 46.22 | N19: 1.8 | O19: 0 | P19: 0.67 | Q19: 12.96
A20: 07/02/2025 03:00 | B20: 11.7 | C20: 24.59 | D20: 23.58 | E20: 8.95 | F20: Invalid | G20: 60.38 | H20: 21.48 | I20: 7.35 | J20: 0.17 | K20: 167.6 | L20: 18.68 | M20: 48.38 | N20: 1.4 | O20: 0 | P20: 0.67 | Q20: 12.95
... A104: 07/02/2025 24:00 | B104: 30.41 | C104: 28.13 | D104: 40.44 | E104: 9.66 | F104: Invalid | G104: 112.24 | H104: 29.57 | I104: 18.17 | J104: 0.11 | K104: 186.2 | L104: 19.55 | M104: 57.42 | N104: 1.2 | O104: 0 | P104: 1.12 | Q104: 13.05
A106: Min | B106: =MIN(B9:B104) -> 7.48 | C106: =MIN(C9:C104) -> 22.6 | D106: =MIN(D9:D104) -> 21.68 | E106: =MIN(E9:E104) -> 6.68 | F106: =MIN(F9:F104) -> 0 | G106: =MIN(G9:G104) -> 48.96 | H106: =MIN(H9:H104) -> 13.08 | I106: =MIN(I9:I104) -> 6.29 | ... Q106: =MIN(Q9:Q104) -> 12.94
A107: Max | B107: =MAX(B9:B104) -> 30.41 | C107: =MAX(C9:C104) -> 31.13 | D107: =MAX(D9:D104) -> 40.44 | E107: =MAX(E9:E104) -> 37.35 | F107: =MAX(F9:F104) -> 0 | G107: =MAX(G9:G104) -> 169.27 | H107: =MAX(H9:H104) -> 40.15 | I107: =MAX(I9:I104) -> 19.03 | ... Q107: =MAX(Q9:Q104) -> 13.06
A108: Avg | B108: =AVERAGE(B9:B104) -> 13.500312 | C108: =AVERAGE(C9:C104) -> 26.485 | D108: =AVERAGE(D9:D104) -> 26.014688 | E108: =AVERAGE(E9:E104) -> 9.9695833 | F108: =AVERAGE(F9:F104) -> #DIV/0! | G108: =AVERAGE(G9:G104) -> 75.479271 | H108: =AVERAGE(H9:H104) -> 24.749271 | I108: =AVERAGE(I9:I104) -> 8.8651042 | ... Q108: =AVERAGE(Q9:Q104) -> 12.981042
A109: Stdev | B109: =STDEV(B9:B104) -> 4.9268321 | C109: =STDEV(C9:C104) -> 2.5345785 | D109: =STDEV(D9:D104) -> 4.7003547 | E109: =STDEV(E9:E104) -> 4.4439553 | F109: =STDEV(F9:F104) -> #DIV/0! | G109: =STDEV(G9:G104) -> 32.073982 | H109: =STDEV(H9:H104) -> 7.3737561 | I109: =STDEV(I9:I104) -> 4.1460726 | ... Q109: =STDEV(Q9:Q104) -> 0.028744946
A110: Num | B110: =COUNT(B9:B104) -> 96 | C110: =COUNT(C9:C104) -> 96 | D110: =COUNT(D9:D104) -> 96 | E110: =COUNT(E9:E104) -> 96 | F110: =COUNT(F9:F104) -> 0 | G110: =COUNT(G9:G104) -> 96 | H110: =COUNT(H9:H104) -> 96 | I110: =COUNT(I9:I104) -> 96 | ... Q110: =COUNT(Q9:Q104) -> 96
A111: DCR | B111: =IF(B110>=87,">90%",IF(B110<=87,"<90%")) -> >90% | C111: =IF(C110>=87,">90%",IF(C110<=87,"<90%")) -> >90% | D111: =IF(D110>=87,">90%",IF(D110<=87,"<90%")) -> >90% | E111: =IF(E110>=87,">90%",IF(E110<=87,"<90%")) -> >90% | F111: =IF(F110>=87,">90%",IF(F110<=87,"<90%")) -> <90% | G111: =IF(G110>=87,">90%",IF(G110<=87,"<90%")) -> >90% | H111: =IF(H110>=87,">90%",IF(H110<=87,"<90%")) -> >90% | I111: =IF(I110>=87,">90%",IF(I110<=87,"<90%")) -> >90% | ... Q111: =IF(Q110>=87,">90%",IF(Q110<=87,"<90%")) -> >90%
A112: Status | B112: =IF(B110>=87,"OK",IF(B110<=87,"LESS")) -> OK | C112: =IF(C110>=87,"OK",IF(C110<=87,"LESS")) -> OK | D112: =IF(D110>=87,"OK",IF(D110<=87,"LESS")) -> OK | E112: =IF(E110>=87,"OK",IF(E110<=87,"LESS")) -> OK | F112: =IF(F110>=87,"OK",IF(F110<=87,"LESS")) -> LESS | G112: =IF(G110>=87,"OK",IF(G110<=87,"LESS")) -> OK | H112: =IF(H110>=87,"OK",IF(H110<=87,"LESS")) -> OK | I112: =IF(I110>=87,"OK",IF(I110<=87,"LESS")) -> OK | ... Q112: =IF(Q110>=87,"OK",IF(Q110<=87,"LESS")) -> OK
A115: Done by | B115: AKASH
A117: Comment

Sheet 08
A1: Station: | B1: IGKV RAIPUR
A2: Date: | B2: =$A$9 -> 08/02/2025 00:15 | C2: Power Off | G2: Pw.Off | J2: Link Fail | L2: Link F | N2: Maintenance | P2: Maint.
A3: Report Type: | B3: Mean | C3: Calibration | G3: Calib. | J3: Data Fail | L3: Data F | N3: Invalid | P3: Invalid
A4: Time Base: | B4: 15 Min | C4: Zero Referrence | G4: Z.Ref | J4: Warm Up | L4: Wm. Up
A7: Date & Time | B7: NO | C7: NO2 | D7: NOX | E7: SO2 | F7: O3 | G7: PM 10 | H7: PM 2.5 | I7: BENZ | J7: WS | K7: WD | L7: TEMP | M7: HUM | N7: SR | O7: RG | P7: CO | Q7: NH3
B8: ug/m3 | C8: ug/m3 | D8: ppb | E8: ug/m3 | F8: ug/m3 | G8: ug/m3 | H8: ug/m3 | I8: ug/m3 | J8: m/sec | K8: deg | L8: degreC | M8: % | N8: w/m2 | O8: mm | P8: mg/m3 | Q8: ug/m3
A9: 08/02/2025 00:15 | B9: 32.28 | C9: 28 | D9: 41.86 | E9: 10.01 | F9: Invalid | G9: 112.24 | H9: 29.57 | I9: 17.99 | J9: 0.16 | K9: 169.44 | L9: 19.67 | M9: 56.17 | N9: 1.2 | O9: 0 | P9: 1.12 | Q9: 13.05
A10: 08/02/2025 00:30 | B10: 32.63 | C10: 28.02 | D10: 42.16 | E10: 9.91 | F10: Invalid | G10: 112.24 | H10: 29.57 | I10: 17.85 | J10: 0.25 | K10: 163.66 | L10: 19.37 | M10: 65.01 | N10: 1.3 | O10: 0 | P10: 1.12 | Q10: 13.06
A11: 08/02/2025 00:45 | B11: 32.89 | C11: 27.74 | D11: 42.22 | E11: 10.03 | F11: Invalid | G11: 111.55 | H11: 29.5 | I11: 17.63 | J11: 0.22 | K11: 181.46 | L11: 18.83 | M11: 67.84 | N11: 1.6 | O11: 0 | P11: 1.12 | Q11: 13.05
A12: 08/02/2025 01:00 | B12: 32.91 | C12: 27.31 | D12: 42.01 | E12: 10.02 | F12: Invalid | G12: 96.59 | H12: 27.39 | I12: 17.43 | J12: 0.17 | K12: 165.93 | L12: 18.71 | M12: 64.69 | N12: 1.3 | O12: 0 | P12: 1.12 | Q12: 13.07
A13: 08/02/2025 01:15 | B13: 32.71 | C13: 27.21 | D13: 41.79 | E13: 9.76 | F13: Invalid | G13: 96.59 | H13: 27.39 | I13: 17.25 | J13: 0.22 | K13: 176.24 | L13: 18.71 | M13: 67.22 | N13: 1.3 | O13: 0 | P13: 1.11 | Q13: 13.06
A14: 08/02/2025 01:30 | B14: 32.49 | C14: 26.92 | D14: 41.47 | E14: 9.84 | F14: Invalid | G14: 96.59 | H14: 27.39 | I14: 17.12 | J14: 0.2 | K14: 210.1 | L14: 18.21 | M14: 66.81 | N14: 1.5 | O14: 0 | P14: 1.12 | Q14: 13.06
A15: 08/02/2025 01:45 | B15: 32.12 | C15: 26.63 | D15: 41.03 | E15: 9.92 | F15: Invalid | G15: 96.49 | H15: 27.26 | I15: 16.94 | J15: 0.16 | K15: 172.6 | L15: 18.05 | M15: 70.82 | N15: 1.4 | O15: 0 | P15: 1.12 | Q15: 13.06
A16: 08/02/2025 02:00 | B16: 31.7 | C16: 26.12 | D16: 40.42 | E16: 9.66 | F16: Invalid | G16: 94.34 | H16: 23.12 | I16: 16.68 | J16: 0.18 | K16: 214.45 | L16: 17.71 | M16: 71.73 | N16: 1.4 | O16: 0 | P16: 1.11 | Q16: 13.06
A17: 08/02/2025 02:15 | B17: 31.28 | C17: 25.86 | D17: 39.95 | E17: 8.15 | F17: Invalid | G17: 94.34 | H17: 23.12 | I17: 16.51 | J17: 0.11 | K17: 194.98 | L17: 17.64 | M17: 71.67 | N17: 1.2 | O17: 0 | P17: 1.11 | Q17: 13.05
A18: 08/02/2025 02:30 | B18: 30.81 | C18: 25.56 | D18: 39.41 | E18: 9.99 | F18: Invalid | G18: 94.34 | H18: 23.12 | I18: 16.35 | J18: 0.14 | K18: 217.53 | L18: 17.71 | M18: 69.79 | N18: 1.2 | O18: 0 | P18: 1.1 | Q18: 13.04
A19: 08/02/2025 02:45 | B19: 30.03 | C19: 25.43 | D19: 38.72 | E19: 10 | F19: Invalid | G19: 93.45 | H19: 23.11 | I19: 16.19 | J19: 0.11 | K19: 135.57 | L19: 17.82 | M19: 66.63 | N19: 1.1 | O19: 0 | P19: 1.05 | Q19: 13.03
A20: 08/02/2025 03:00 | B20: 29.55 | C20: 25.22 | D20: 38.23 | E20: 9.97 | F20: Invalid | G20: 74.24 | H20: 22.84 | I20: 16.09 | J20: 0.36 | K20: 66.39 | L20: 18.27 | M20: 61.52 | N20: 0.7 | O20: 0 | P20: 0.98 | Q20: 13.04
... A104: 08/02/2025 24:00 | B104: 25 | C104: 27.45 | D104: 35.74 | E104: 11.48 | F104: Invalid | G104: 140.65 | H104: 26.82 | I104: 12.66 | J104: 0.15 | K104: 117.12 | L104: 19.85 | M104: 41.47 | N104: 0.8 | O104: 0 | P104: 0.91 | Q104: 13.04
A106: Min | B106: =MIN(B9:B104) -> 3.86 | C106: =MIN(C9:C104) -> 24.71 | D106: =MIN(D9:D104) -> 18.21 | E106: =MIN(E9:E104) -> 8.15 | F106: =MIN(F9:F104) -> 0 | G106: =MIN(G9:G104) -> 56.68 | H106: =MIN(H9:H104) -> 18.99 | I106: =MIN(I9:I104) -> 8.12 | ... Q106: =MIN(Q9:Q104) -> 12.94
A107: Max | B107: =MAX(B9:B104) -> 32.91 | C107: =MAX(C9:C104) -> 28.19 | D107: =MAX(D9:D104) -> 42.22 | E107: =MAX(E9:E104) -> 17.99 | F107: =MAX(F9:F104) -> 0 | G107: =MAX(G9:G104) -> 140.65 | H107: =MAX(H9:H104) -> 30.23 | I107: =MAX(I9:I104) -> 17.99 | ... Q107: =MAX(Q9:Q104) -> 13.07
A108: Avg | B108: =AVERAGE(B9:B104) -> 18.558021 | C108: =AVERAGE(C9:C104) -> 26.295937 | D108: =AVERAGE(D9:D104) -> 29.972083 | E108: =AVERAGE(E9:E104) -> 11.264896 | F108: =AVERAGE(F9:F104) -> #DIV/0! | G108: =AVERAGE(G9:G104) -> 83.021354 | H108: =AVERAGE(H9:H104) -> 25.414062 | I108: =AVERAGE(I9:I104) -> 12.825729 | ... Q108: =AVERAGE(Q9:Q104) -> 13.002813
A109: Stdev | B109: =STDEV(B9:B104) -> 9.4548567 | C109: =STDEV(C9:C104) -> 0.93631144 | D109: =STDEV(D9:D104) -> 7.5398496 | E109: =STDEV(E9:E104) -> 1.8366927 | F109: =STDEV(F9:F104) -> #DIV/0! | G109: =STDEV(G9:G104) -> 18.171469 | H109: =STDEV(H9:H104) -> 3.2295173 | I109: =STDEV(I9:I104) -> 2.7333834 | ... Q109: =STDEV(Q9:Q104) -> 0.036983727
A110: Num | B110: =COUNT(B9:B104) -> 96 | C110: =COUNT(C9:C104) -> 96 | D110: =COUNT(D9:D104) -> 96 | E110: =COUNT(E9:E104) -> 96 | F110: =COUNT(F9:F104) -> 0 | G110: =COUNT(G9:G104) -> 96 | H110: =COUNT(H9:H104) -> 96 | I110: =COUNT(I9:I104) -> 96 | ... Q110: =COUNT(Q9:Q104) -> 96
A111: DCR | B111: =IF(B110>=87,">90%",IF(B110<=87,"<90%")) -> >90% | C111: =IF(C110>=87,">90%",IF(C110<=87,"<90%")) -> >90% | D111: =IF(D110>=87,">90%",IF(D110<=87,"<90%")) -> >90% | E111: =IF(E110>=87,">90%",IF(E110<=87,"<90%")) -> >90% | F111: =IF(F110>=87,">90%",IF(F110<=87,"<90%")) -> <90% | G111: =IF(G110>=87,">90%",IF(G110<=87,"<90%")) -> >90% | H111: =IF(H110>=87,">90%",IF(H110<=87,"<90%")) -> >90% | I111: =IF(I110>=87,">90%",IF(I110<=87,"<90%")) -> >90% | ... Q111: =IF(Q110>=87,">90%",IF(Q110<=87,"<90%")) -> >90%
A112: Status | B112: =IF(B110>=87,"OK",IF(B110<=87,"LESS")) -> OK | C112: =IF(C110>=87,"OK",IF(C110<=87,"LESS")) -> OK | D112: =IF(D110>=87,"OK",IF(D110<=87,"LESS")) -> OK | E112: =IF(E110>=87,"OK",IF(E110<=87,"LESS")) -> OK | F112: =IF(F110>=87,"OK",IF(F110<=87,"LESS")) -> LESS | G112: =IF(G110>=87,"OK",IF(G110<=87,"LESS")) -> OK | H112: =IF(H110>=87,"OK",IF(H110<=87,"LESS")) -> OK | I112: =IF(I110>=87,"OK",IF(I110<=87,"LESS")) -> OK | ... Q112: =IF(Q110>=87,"OK",IF(Q110<=87,"LESS")) -> OK
A115: Done by | B115: AKASH
A117: Comment

Sheet 09
A1: Station: | B1: IGKV RAIPUR
A2: Date: | B2: =$A$9 -> 09/02/2025 00:15 | C2: Power Off | G2: Pw.Off | J2: Link Fail | L2: Link F | N2: Maintenance | P2: Maint.
A3: Report Type: | B3: Mean | C3: Calibration | G3: Calib. | J3: Data Fail | L3: Data F | N3: Invalid | P3: Invalid
A4: Time Base: | B4: 15 Min | C4: Zero Referrence | G4: Z.Ref | J4: Warm Up | L4: Wm. Up
A7: Date & Time | B7: NO | C7: NO2 | D7: NOX | E7: SO2 | F7: O3 | G7: PM 10 | H7: PM 2.5 | I7: BENZ | J7: WS | K7: WD | L7: TEMP | M7: HUM | N7: SR | O7: RG | P7: CO | Q7: NH3
B8: ug/m3 | C8: ug/m3 | D8: ppb | E8: ug/m3 | F8: ug/m3 | G8: ug/m3 | H8: ug/m3 | I8: ug/m3 | J8: m/sec | K8: deg | L8: degreC | M8: % | N8: w/m2 | O8: mm | P8: mg/m3 | Q8: ug/m3
A9: 09/02/2025 00:15 | B9: 25.44 | C9: 27.84 | D9: 36.3 | E9: 11.54 | F9: Invalid | G9: 140.65 | H9: 26.82 | I9: 12.44 | J9: 0.18 | K9: 103.06 | L9: 19.26 | M9: 44.58 | N9: 1 | O9: 0 | P9: 0.89 | Q9: 13.04
A10: 09/02/2025 00:30 | B10: 25.56 | C10: 28.29 | D10: 36.63 | E10: 11.51 | F10: Invalid | G10: 140.65 | H10: 26.82 | I10: 12.24 | J10: 0.26 | K10: 71.53 | L10: 19.56 | M10: 40.57 | N10: 0.6 | O10: 0 | P10: 0.87 | Q10: 13.03
A11: 09/02/2025 00:45 | B11: 26.17 | C11: 28.33 | D11: 37.14 | E11: 11.5 | F11: Invalid | G11: 140.73 | H11: 26.91 | I11: 12.06 | J11: 0.17 | K11: 105.17 | L11: 19.41 | M11: 41.94 | N11: 0.9 | O11: 0 | P11: 0.86 | Q11: 13.05
A12: 09/02/2025 01:00 | B12: 26.58 | C12: 28.42 | D12: 37.51 | E12: 11.31 | F12: Invalid | G12: 142.42 | H12: 29.96 | I12: 11.84 | J12: 0.34 | K12: 74.94 | L12: 19.37 | M12: 40.04 | N12: 0.6 | O12: 0 | P12: 0.85 | Q12: 13.04
A13: 09/02/2025 01:15 | B13: 26.73 | C13: 28.48 | D13: 37.67 | E13: 11.59 | F13: Invalid | G13: 142.42 | H13: 29.96 | I13: 11.63 | J13: 0.38 | K13: 76.5 | L13: 19.32 | M13: 40.5 | N13: 0.7 | O13: 0 | P13: 0.83 | Q13: 13.04
A14: 09/02/2025 01:30 | B14: 26.63 | C14: 28.58 | D14: 37.64 | E14: 11.8 | F14: Invalid | G14: 142.42 | H14: 29.96 | I14: 11.45 | J14: 0.23 | K14: 80.21 | L14: 18.94 | M14: 42.25 | N14: 0.9 | O14: 0 | P14: 0.81 | Q14: 13.04
A15: 09/02/2025 01:45 | B15: 26.4 | C15: 28.59 | D15: 37.46 | E15: 11.71 | F15: Invalid | G15: 142.8 | H15: 29.88 | I15: 11.24 | J15: 0.42 | K15: 59.71 | L15: 18.8 | M15: 41.5 | N15: 0.5 | O15: 0 | P15: 0.8 | Q15: 13.04
A16: 09/02/2025 02:00 | B16: 26.18 | C16: 28.44 | D16: 37.21 | E16: 11.19 | F16: Invalid | G16: 151.03 | H16: 27.41 | I16: 11.02 | J16: 0.38 | K16: 58.75 | L16: 18.82 | M16: 40.03 | N16: 0.6 | O16: 0 | P16: 0.8 | Q16: 13.05
A17: 09/02/2025 02:15 | B17: 25.68 | C17: 28.44 | D17: 36.8 | E17: 9.54 | F17: Invalid | G17: 151.03 | H17: 27.41 | I17: 10.84 | J17: 0.13 | K17: 67.92 | L17: 18.59 | M17: 41.72 | N17: 0.9 | O17: 0 | P17: 0.77 | Q17: 13.03
A18: 09/02/2025 02:30 | B18: 25.22 | C18: 28.47 | D18: 36.45 | E18: 10.69 | F18: Invalid | G18: 151.03 | H18: 27.41 | I18: 10.73 | J18: 0.19 | K18: 171.7 | L18: 17.48 | M18: 58.34 | N18: 1.6 | O18: 0 | P18: 0.76 | Q18: 13.03
A19: 09/02/2025 02:45 | B19: 24.74 | C19: 28.14 | D19: 35.89 | E19: 10.87 | F19: Invalid | G19: 150.91 | H19: 27.39 | I19: 10.58 | J19: 0.15 | K19: 178.37 | L19: 16.83 | M19: 55.67 | N19: 1 | O19: 0 | P19: 0.74 | Q19: 13.04
A20: 09/02/2025 03:00 | B20: 24.63 | C20: 27.99 | D20: 35.72 | E20: 10.39 | F20: Invalid | G20: 147.39 | H20: 26.51 | I20: 10.41 | J20: 0.12 | K20: 149.4 | L20: 16.6 | M20: 59.62 | N20: 1 | O20: 0 | P20: 0.74 | Q20: 13.02
... A104: 09/02/2025 24:00 | B104: 20.43 | C104: 24.19 | D104: 30.37 | E104: 11.4 | F104: Invalid | G104: 67.56 | H104: 20.76 | I104: 9.18 | J104: 0.11 | K104: 189.33 | L104: 17.16 | M104: 65.41 | N104: 0.9 | O104: 0 | P104: 0.78 | Q104: 13.01
A106: Min | B106: =MIN(B9:B104) -> 3.85 | C106: =MIN(C9:C104) -> 17.32 | D106: =MIN(D9:D104) -> 13.73 | E106: =MIN(E9:E104) -> 7.41 | F106: =MIN(F9:F104) -> 0 | G106: =MIN(G9:G104) -> 36.92 | H106: =MIN(H9:H104) -> 17.16 | I106: =MIN(I9:I104) -> 6.46 | ... Q106: =MIN(Q9:Q104) -> 12.91
A107: Max | B107: =MAX(B9:B104) -> 29.01 | C107: =MAX(C9:C104) -> 28.79 | D107: =MAX(D9:D104) -> 39.62 | E107: =MAX(E9:E104) -> 28.88 | F107: =MAX(F9:F104) -> 0 | G107: =MAX(G9:G104) -> 151.03 | H107: =MAX(H9:H104) -> 33.18 | I107: =MAX(I9:I104) -> 12.44 | ... Q107: =MAX(Q9:Q104) -> 13.05
A108: Avg | B108: =AVERAGE(B9:B104) -> 13.161458 | C108: =AVERAGE(C9:C104) -> 23.282708 | D108: =AVERAGE(D9:D104) -> 24.069792 | E108: =AVERAGE(E9:E104) -> 11.552708 | F108: =AVERAGE(F9:F104) -> #DIV/0! | G108: =AVERAGE(G9:G104) -> 79.991563 | H108: =AVERAGE(H9:H104) -> 24.139062 | I108: =AVERAGE(I9:I104) -> 8.7827083 | ... Q108: =AVERAGE(Q9:Q104) -> 12.978125
A109: Stdev | B109: =STDEV(B9:B104) -> 9.2522181 | C109: =STDEV(C9:C104) -> 3.8337028 | D109: =STDEV(D9:D104) -> 9.0491144 | E109: =STDEV(E9:E104) -> 3.6949221 | F109: =STDEV(F9:F104) -> #DIV/0! | G109: =STDEV(G9:G104) -> 36.281611 | H109: =STDEV(H9:H104) -> 4.5843976 | I109: =STDEV(I9:I104) -> 1.5588724 | ... Q109: =STDEV(Q9:Q104) -> 0.043777247
A110: Num | B110: =COUNT(B9:B104) -> 96 | C110: =COUNT(C9:C104) -> 96 | D110: =COUNT(D9:D104) -> 96 | E110: =COUNT(E9:E104) -> 96 | F110: =COUNT(F9:F104) -> 0 | G110: =COUNT(G9:G104) -> 96 | H110: =COUNT(H9:H104) -> 96 | I110: =COUNT(I9:I104) -> 96 | ... Q110: =COUNT(Q9:Q104) -> 96
A111: DCR | B111: =IF(B110>=87,">90%",IF(B110<=87,"<90%")) -> >90% | C111: =IF(C110>=87,">90%",IF(C110<=87,"<90%")) -> >90% | D111: =IF(D110>=87,">90%",IF(D110<=87,"<90%")) -> >90% | E111: =IF(E110>=87,">90%",IF(E110<=87,"<90%")) -> >90% | F111: =IF(F110>=87,">90%",IF(F110<=87,"<90%")) -> <90% | G111: =IF(G110>=87,">90%",IF(G110<=87,"<90%")) -> >90% | H111: =IF(H110>=87,">90%",IF(H110<=87,"<90%")) -> >90% | I111: =IF(I110>=87,">90%",IF(I110<=87,"<90%")) -> >90% | ... Q111: =IF(Q110>=87,">90%",IF(Q110<=87,"<90%")) -> >90%
A112: Status | B112: =IF(B110>=87,"OK",IF(B110<=87,"LESS")) -> OK | C112: =IF(C110>=87,"OK",IF(C110<=87,"LESS")) -> OK | D112: =IF(D110>=87,"OK",IF(D110<=87,"LESS")) -> OK | E112: =IF(E110>=87,"OK",IF(E110<=87,"LESS")) -> OK | F112: =IF(F110>=87,"OK",IF(F110<=87,"LESS")) -> LESS | G112: =IF(G110>=87,"OK",IF(G110<=87,"LESS")) -> OK | H112: =IF(H110>=87,"OK",IF(H110<=87,"LESS")) -> OK | I112: =IF(I110>=87,"OK",IF(I110<=87,"LESS")) -> OK | ... Q112: =IF(Q110>=87,"OK",IF(Q110<=87,"LESS")) -> OK
A115: Done by | B115: AKASH
A117: Comment

Sheet 10
A1: Station: | B1: IGKV RAIPUR
A2: Date: | B2: =$A$9 -> 10/02/2025 00:15 | C2: Power Off | G2: Pw.Off | J2: Link Fail | L2: Link F | N2: Maintenance | P2: Maint.
A3: Report Type: | B3: Mean | C3: Calibration | G3: Calib. | J3: Data Fail | L3: Data F | N3: Invalid | P3: Invalid
A4: Time Base: | B4: 15 Min | C4: Zero Referrence | G4: Z.Ref | J4: Warm Up | L4: Wm. Up
A7: Date & Time | B7: NO | C7: NO2 | D7: NOX | E7: SO2 | F7: O3 | G7: PM 10 | H7: PM 2.5 | I7: BENZ | J7: WS | K7: WD | L7: TEMP | M7: HUM | N7: SR | O7: RG | P7: CO | Q7: NH3
B8: ug/m3 | C8: ug/m3 | D8: ppb | E8: ug/m3 | F8: ug/m3 | G8: ug/m3 | H8: ug/m3 | I8: ug/m3 | J8: m/sec | K8: deg | L8: degreC | M8: % | N8: w/m2 | O8: mm | P8: mg/m3 | Q8: ug/m3
A9: 10/02/2025 00:15 | B9: 20.56 | C9: 24.36 | D9: 30.56 | E9: 11.43 | F9: Invalid | G9: 67.56 | H9: 20.76 | I9: 9.32 | J9: 0.27 | K9: 165.18 | L9: 17.16 | M9: 63.8 | N9: 0.9 | O9: 0 | P9: 0.77 | Q9: 13
