Workbook

Sheet 01
A1: Station: | B1: IGKV ,RAIPUR
A2: Date: | B2: =$A$9 -> 01/02/2025 01:00 | D2: Power Off | G2: Pw.Off | L2: Link Fail | N2: Link F | P2: Maintenance | R2: Maint.
A3: Report Type: | B3: Mean | D3: Calibration | G3: Calib. | L3: Data Fail | N3: Data F | P3: Invalid | R3: Invalid
A4: Time Base: | B4: 01 Hour | D4: Zero Referrence | G4: Z.Ref | L4: Warm Up | N4: Wm. Up
A7: Date & Time | B7: NO | C7: NO2 | D7: NOX | E7: SO2 | F7: O3 | G7: PM 10 | H7: PM 2.5 | I7: BENZ | J7: WS | K7: WD | L7: TEMP | M7: HUM | N7: SR | O7: RG | P7: CO | Q7: NH3
B8: ug/m3 | C8: ug/m3 | D8: ppb | E8: ug/m3 | F8: ug/m3 | G8: ug/m3 | H8: ug/m3 | I8: ug/m3 | J8: m/sec | K8: deg | L8: degreC | M8: % | N8: w/m2 | O8: mm | P8: mg/m3 | Q8: ug/m3
A9: 01/02/2025 01:00 | B9: 11.86 | C9: 26.45 | D9: 23.99 | E9: 10.13 | F9: 4.07 | G9: 85.84 | H9: 26.02 | I9: 11.54 | J9: 0.17 | K9: 218.05 | L9: 21.92 | M9: 88.69 | N9: 1.6 | O9: 0 | P9: 0.97 | Q9: 12.97
A10: 01/02/2025 02:00 | B10: 12.83 | C10: 24.53 | D10: 24.46 | E10: 9.86 | F10: 4.11 | G10: 85.84 | H10: 29.32 | I10: 11.59 | J10: 0.13 | K10: 192.97 | L10: 20.97 | M10: 87.86 | N10: 1.4 | O10: 0 | P10: 0.98 | Q10: 12.96
A11: 01/02/2025 03:00 | B11: 13.64 | C11: 24.54 | D11: 25.11 | E11: 10.33 | F11: 4.02 | G11: 80.47 | H11: 29.32 | I11: 11.64 | J11: 0.2 | K11: 229.58 | L11: 20.46 | M11: 90.19 | N11: 1.4 | O11: 0 | P11: 1 | Q11: 12.97
A12: 01/02/2025 04:00 | B12: 13.8 | C12: 22.84 | D12: 24.35 | E12: 10.21 | F12: 3.89 | G12: 71.72 | H12: 24.9 | I12: 12.02 | J12: 0.13 | K12: 201.19 | L12: 19.96 | M12: 91.15 | N12: 1.3 | O12: 0 | P12: 0.99 | Q12: 12.97
A13: 01/02/2025 05:00 | B13: 12.72 | C13: 21.19 | D13: 22.62 | E13: 9.26 | F13: 3.86 | G13: 64.63 | H13: 24.9 | I13: 11.97 | J13: 0.15 | K13: 205.22 | L13: 20.07 | M13: 89.53 | N13: 1.3 | O13: 0 | P13: 0.97 | Q13: 12.96
A14: 01/02/2025 06:00 | B14: 12.28 | C14: 20.97 | D14: 22.15 | E14: 9.08 | F14: 3.84 | G14: 63.1 | H14: 23.87 | I14: 11.91 | J14: 0.14 | K14: 237.15 | L14: 19.71 | M14: 93.4 | N14: 1.4 | O14: 0 | P14: 0.95 | Q14: 12.95
A15: 01/02/2025 07:00 | B15: 12.05 | C15: 20.44 | D15: 21.7 | E15: 8.92 | F15: 3.93 | G15: 63.1 | H15: 23.03 | I15: 11.81 | J15: 0.27 | K15: 193.93 | L15: 19.79 | M15: 94.98 | N15: 7.6 | O15: 0 | P15: 0.92 | Q15: 12.96
A16: 01/02/2025 08:00 | B16: 12.07 | C16: 20.25 | D16: 21.54 | E16: 9.07 | F16: 3.8 | G16: 57.75 | H16: 23.27 | I16: 12.22 | J16: 0.25 | K16: 171.87 | L16: 21.49 | M16: 94.23 | N16: 44 | O16: 0 | P16: 0.94 | Q16: 12.95
A17: 01/02/2025 09:00 | B17: 12.14 | C17: 23.27 | D17: 23.24 | E17: 9.56 | F17: 4.23 | G17: 59.33 | H17: 24.08 | I17: 12.58 | J17: 0.32 | K17: 266.52 | L17: 24.9 | M17: 82.13 | N17: 166.3 | O17: 0 | P17: 0.95 | Q17: 12.96
A18: 01/02/2025 10:00 | B18: 12.02 | C18: 23.13 | D18: 22.91 | E18: 9.81 | F18: 4.49 | G18: 59.33 | H18: 25.84 | I18: 12.51 | J18: 0.38 | K18: 264.85 | L18: 27.96 | M18: 66.96 | N18: 269 | O18: 0 | P18: 0.92 | Q18: 12.96
A19: 01/02/2025 11:00 | B19: 10.42 | C19: 22.96 | D19: 21.71 | E19: 10.93 | F19: 6.81 | G19: 56.68 | H19: 25.84 | I19: 12.04 | J19: 0.32 | K19: 255.93 | L19: 30.86 | M19: 54.2 | N19: 329.3 | O19: 0 | P19: 0.87 | Q19: 12.96
A20: 01/02/2025 12:00 | B20: 8.15 | C20: 20.2 | D20: 18.44 | E20: 11 | F20: 7.62 | G20: 46.69 | H20: 21.07 | I20: 11.31 | J20: 0.49 | K20: 283.13 | L20: 32.25 | M20: 40.34 | N20: 351.7 | O20: 0 | P20: 0.8 | Q20: 12.95
... A32: 01/02/2025 24:00 | B32: 16.04 | C32: 23.86 | D32: 26.57 | E32: 8.78 | F32: 3.81 | G32: 110.63 | H32: 27.18 | I32: 11.67 | J32: 0.25 | K32: 212.81 | L32: 21.6 | M32: 79.14 | N32: 1.3 | O32: 0 | P32: 0.99 | Q32: 12.98
A34: Min | B34: =MIN(B9:B32) -> 4.1 | C34: =MIN(C9:C32) -> 17.82 | D34: =MIN(D9:D32) -> 14.12 | E34: =MIN(E9:E32) -> 8.78 | F34: =MIN(F9:F32) -> 3.8 | G34: =MIN(G9:G32) -> 39.63 | H34: =MIN(H9:H32) -> 18.16 | I34: =MIN(I9:I32) -> 5.79 | ... Q34: =MIN(Q9:Q32) -> 12.92
A35: Max | B35: =MAX(B9:B32) -> 16.44 | C35: =MAX(C9:C32) -> 27.11 | D35: =MAX(D9:D32) -> 27.57 | E35: =MAX(E9:E32) -> 11.06 | F35: =MAX(F9:F32) -> 14.66 | G35: =MAX(G9:G32) -> 145.38 | H35: =MAX(H9:H32) -> 29.32 | I35: =MAX(I9:I32) -> 12.58 | ... Q35: =MAX(Q9:Q32) -> 12.98
A36: Avg | B36: =AVERAGE(B9:B32) -> 10.565417 | C36: =AVERAGE(C9:C32) -> 22.431667 | D36: =AVERAGE(D9:D32) -> 21.445 | E36: =AVERAGE(E9:E32) -> 9.8258333 | F36: =AVERAGE(F9:F32) -> 6.35125 | G36: =AVERAGE(G9:G32) -> 75.88 | H36: =AVERAGE(H9:H32) -> 23.797083 | I36: =AVERAGE(I9:I32) -> 10.302083 | ... Q36: =AVERAGE(Q9:Q32) -> 12.954583
A37: Stdev | B37: =STDEV(B9:B32) -> 4.0785856 | C37: =STDEV(C9:C32) -> 2.8611607 | D37: =STDEV(D9:D32) -> 4.4374248 | E37: =STDEV(E9:E32) -> 0.70448203 | F37: =STDEV(F9:F32) -> 3.5740457 | G37: =STDEV(G9:G32) -> 35.178776 | H37: =STDEV(H9:H32) -> 3.2370954 | I37: =STDEV(I9:I32) -> 2.1463882 | ... Q37: =STDEV(Q9:Q32) -> 0.017932038
A38: Num | B38: =COUNT(B9:B32) -> 24 | C38: =COUNT(C9:C32) -> 24 | D38: =COUNT(D9:D32) -> 24 | E38: =COUNT(E9:E32) -> 24 | F38: =COUNT(F9:F32) -> 24 | G38: =COUNT(G9:G32) -> 24 | H38: =COUNT(H9:H32) -> 24 | I38: =COUNT(I9:I32) -> 24 | ... Q38: =COUNT(Q9:Q32) -> 24
A39: DCR | B39: =IF(B38>=22,">90%",IF(B38<=22,"<90%")) -> >90% | C39: =IF(C38>=22,">90%",IF(C38<=22,"<90%")) -> >90% | D39: =IF(D38>=22,">90%",IF(D38<=22,"<90%")) -> >90% | E39: =IF(E38>=22,">90%",IF(E38<=22,"<90%")) -> >90% | F39: =IF(F38>=22,">90%",IF(F38<=22,"<90%")) -> >90% | G39: =IF(G38>=22,">90%",IF(G38<=22,"<90%")) -> >90% | H39: =IF(H38>=22,">90%",IF(H38<=22,"<90%")) -> >90% | I39: =IF(I38>=22,">90%",IF(I38<=22,"<90%")) -> >90% | ... Q39: =IF(Q38>=22,">90%",IF(Q38<=22,"<90%")) -> >90%
A40: Status | B40: =IF(B38>=22,"OK",IF(B38<=22,"LESS")) -> OK | C40: =IF(C38>=22,"OK",IF(C38<=22,"LESS")) -> OK | D40: =IF(D38>=22,"OK",IF(D38<=22,"LESS")) -> OK | E40: =IF(E38>=22,"OK",IF(E38<=22,"LESS")) -> OK | F40: =IF(F38>=22,"OK",IF(F38<=22,"LESS")) -> OK | G40: =IF(G38>=22,"OK",IF(G38<=22,"LESS")) -> OK | H40: =IF(H38>=22,"OK",IF(H38<=22,"LESS")) -> OK | I40: =IF(I38>=22,"OK",IF(I38<=22,"LESS")) -> OK | ... Q40: =IF(Q38>=22,"OK",IF(Q38<=22,"LESS")) -> OK
A43: Done by | B43: AKASH
A45: Comment

Sheet 02
A1: Station: | B1: IGKV ,RAIPUR
A2: Date: | B2: =$A$9 -> 02/02/2025 01:00 | D2: Power Off | G2: Pw.Off | L2: Link Fail | N2: Link F | P2: Maintenance | R2: Maint.
A3: Report Type: | B3: Mean | D3: Calibration | G3: Calib. | L3: Data Fail | N3: Data F | P3: Invalid | R3: Invalid
A4: Time Base: | B4: 01 Hour | D4: Zero Referrence | G4: Z.Ref | L4: Warm Up | N4: Wm. Up
A7: Date & Time | B7: NO | C7: NO2 | D7: NOX | E7: SO2 | F7: O3 | G7: PM 10 | H7: PM 2.5 | I7: BENZ | J7: WS | K7: WD | L7: TEMP | M7: HUM | N7: SR | O7: RG | P7: CO | Q7: NH3
B8: ug/m3 | C8: ug/m3 | D8: ppb | E8: ug/m3 | F8: ug/m3 | G8: ug/m3 | H8: ug/m3 | I8: ug/m3 | J8: m/sec | K8: deg | L8: degreC | M8: % | N8: w/m2 | O8: mm | P8: mg/m3 | Q8: ug/m3
A9: 02/02/2025 01:00 | B9: 14.48 | C9: 23.51 | D9: 24.96 | E9: 8.18 | F9: 3.8 | G9: 104.91 | H9: 27.18 | I9: 12.35 | J9: 0.17 | K9: 226.82 | L9: 21.27 | M9: 82.84 | N9: 1.4 | O9: 0 | P9: 1.02 | Q9: 12.97
A10: 02/02/2025 02:00 | B10: 13.63 | C10: 23.37 | D10: 24.49 | E10: 8.11 | F10: 3.88 | G10: 104.91 | H10: 24.78 | I10: 12.85 | J10: 0.17 | K10: 211.01 | L10: 20.8 | M10: 84.51 | N10: 1.3 | O10: 0 | P10: 1.03 | Q10: 12.98
A11: 02/02/2025 03:00 | B11: 13.2 | C11: 23 | D11: 23.95 | E11: 11.22 | F11: 4.01 | G11: 90.49 | H11: 24.78 | I11: 13.08 | J11: 0.18 | K11: 162.49 | L11: 20.3 | M11: 84.27 | N11: 1.4 | O11: 0 | P11: 1.03 | Q11: 12.96
A12: 02/02/2025 04:00 | B12: 12.67 | C12: 22.29 | D12: 23.13 | E12: 11.39 | F12: 3.84 | G12: 83.25 | H12: 24.32 | I12: 13.18 | J12: 0.19 | K12: 226.52 | L12: 20.09 | M12: 87.39 | N12: 1.4 | O12: 0 | P12: 1.03 | Q12: 12.96
A13: 02/02/2025 05:00 | B13: 12.69 | C13: 22.75 | D13: 23.41 | E13: 11.72 | F13: 3.95 | G13: 61.21 | H13: 24.32 | I13: 13.12 | J13: 0.13 | K13: 202.95 | L13: 19.65 | M13: 88.86 | N13: 1.3 | O13: 0 | P13: 1.02 | Q13: 12.96
A14: 02/02/2025 06:00 | B14: 13.4 | C14: 23.32 | D14: 24.28 | E14: 11.55 | F14: 3.86 | G14: 58.79 | H14: 23.34 | I14: 13.15 | J14: 0.22 | K14: 175.59 | L14: 19.71 | M14: 86.47 | N14: 1.3 | O14: 0 | P14: 1.01 | Q14: 12.97
A15: 02/02/2025 07:00 | B15: 14.28 | C15: 22.87 | D15: 24.6 | E15: 10.95 | F15: 3.87 | G15: 58.79 | H15: 21.65 | I15: 12.85 | J15: 0.2 | K15: 177.69 | L15: 19.37 | M15: 89.51 | N15: 7.7 | O15: 0 | P15: 1 | Q15: 12.96
A16: 02/02/2025 08:00 | B16: 14.55 | C16: 22.47 | D16: 24.64 | E16: 11.03 | F16: 3.95 | G16: 54.22 | H16: 21.65 | I16: 12.44 | J16: 0.44 | K16: 166.66 | L16: 21.05 | M16: 89.17 | N16: 38.9 | O16: 0 | P16: 0.97 | Q16: 12.97
A17: 02/02/2025 09:00 | B17: 14.53 | C17: 22.65 | D17: 24.74 | E17: 10.93 | F17: 4.14 | G17: 62.8 | H17: 23.43 | I17: 12.17 | J17: 0.39 | K17: 261.53 | L17: 25.13 | M17: 73.18 | N17: 175.9 | O17: 0 | P17: 0.97 | Q17: 12.97
A18: 02/02/2025 10:00 | B18: 12.26 | C18: 24.14 | D18: 22.71 | E18: 10.71 | F18: 5.24 | G18: 81.29 | H18: 25.02 | I18: 13.59 | J18: 0.57 | K18: 275.12 | L18: 28.23 | M18: 58.57 | N18: 289.5 | O18: 0 | P18: 1.03 | Q18: 12.96
A19: 02/02/2025 11:00 | B19: 7.08 | C19: 25.26 | D19: 19.72 | E19: 10.93 | F19: 7.16 | G19: 81.29 | H19: 25.02 | I19: 15.83 | J19: 1 | K19: 293.15 | L19: 29.84 | M19: 45.54 | N19: 336.8 | O19: 0 | P19: 1.03 | Q19: 12.96
A20: 02/02/2025 12:00 | B20: 4.92 | C20: 25.26 | D20: 18.5 | E20: 9.86 | F20: 9.37 | G20: 69.05 | H20: 23.71 | I20: 15.5 | J20: 1.06 | K20: 300.69 | L20: 31.62 | M20: 42.22 | N20: 362.7 | O20: 0 | P20: 1.03 | Q20: 12.95
... A32: 02/02/2025 24:00 | B32: 11 | C32: 23.6 | D32: 22.5 | E32: 8.84 | F32: 3.99 | G32: 80.69 | H32: 24.4 | I32: 12.98 | J32: 0.26 | K32: 179.1 | L32: 22.61 | M32: 75.16 | N32: 1.6 | O32: 0 | P32: 1.1 | Q32: 12.94
A34: Min | B34: =MIN(B9:B32) -> 4.07 | C34: =MIN(C9:C32) -> 20.96 | D34: =MIN(D9:D32) -> 15.85 | E34: =MIN(E9:E32) -> 8.11 | F34: =MIN(F9:F32) -> 3.8 | G34: =MIN(G9:G32) -> 39.37 | H34: =MIN(H9:H32) -> 18.22 | I34: =MIN(I9:I32) -> 9.08 | ... Q34: =MIN(Q9:Q32) -> 12.92
A35: Max | B35: =MAX(B9:B32) -> 14.55 | C35: =MAX(C9:C32) -> 25.26 | D35: =MAX(D9:D32) -> 24.96 | E35: =MAX(E9:E32) -> 19.06 | F35: =MAX(F9:F32) -> 32.61 | G35: =MAX(G9:G32) -> 104.91 | H35: =MAX(H9:H32) -> 27.18 | I35: =MAX(I9:I32) -> 15.83 | ... Q35: =MAX(Q9:Q32) -> 12.98
A36: Avg | B36: =AVERAGE(B9:B32) -> 9.1875 | C36: =AVERAGE(C9:C32) -> 23.130833 | D36: =AVERAGE(D9:D32) -> 20.684167 | E36: =AVERAGE(E9:E32) -> 11.194583 | F36: =AVERAGE(F9:F32) -> 8.66875 | G36: =AVERAGE(G9:G32) -> 69.003333 | H36: =AVERAGE(H9:H32) -> 22.73 | I36: =AVERAGE(I9:I32) -> 12.201667 | ... Q36: =AVERAGE(Q9:Q32) -> 12.951667
A37: Stdev | B37: =STDEV(B9:B32) -> 4.1063411 | C37: =STDEV(C9:C32) -> 1.0746442 | D37: =STDEV(D9:D32) -> 3.2635549 | E37: =STDEV(E9:E32) -> 2.8197471 | F37: =STDEV(F9:F32) -> 8.4906395 | G37: =STDEV(G9:G32) -> 16.931055 | H37: =STDEV(H9:H32) -> 2.4331497 | I37: =STDEV(I9:I32) -> 1.9365493 | ... Q37: =STDEV(Q9:Q32) -> 0.015510632
A38: Num | B38: =COUNT(B9:B32) -> 24 | C38: =COUNT(C9:C32) -> 24 | D38: =COUNT(D9:D32) -> 24 | E38: =COUNT(E9:E32) -> 24 | F38: =COUNT(F9:F32) -> 24 | G38: =COUNT(G9:G32) -> 24 | H38: =COUNT(H9:H32) -> 24 | I38: =COUNT(I9:I32) -> 24 | ... Q38: =COUNT(Q9:Q32) -> 24
A39: DCR | B39: =IF(B38>=22,">90%",IF(B38<=22,"<90%")) -> >90% | C39: =IF(C38>=22,">90%",IF(C38<=22,"<90%")) -> >90% | D39: =IF(D38>=22,">90%",IF(D38<=22,"<90%")) -> >90% | E39: =IF(E38>=22,">90%",IF(E38<=22,"<90%")) -> >90% | F39: =IF(F38>=22,">90%",IF(F38<=22,"<90%")) -> >90% | G39: =IF(G38>=22,">90%",IF(G38<=22,"<90%")) -> >90% | H39: =IF(H38>=22,">90%",IF(H38<=22,"<90%")) -> >90% | I39: =IF(I38>=22,">90%",IF(I38<=22,"<90%")) -> >90% | ... Q39: =IF(Q38>=22,">90%",IF(Q38<=22,"<90%")) -> >90%
A40: Status | B40: =IF(B38>=22,"OK",IF(B38<=22,"LESS")) -> OK | C40: =IF(C38>=22,"OK",IF(C38<=22,"LESS")) -> OK | D40: =IF(D38>=22,"OK",IF(D38<=22,"LESS")) -> OK | E40: =IF(E38>=22,"OK",IF(E38<=22,"LESS")) -> OK | F40: =IF(F38>=22,"OK",IF(F38<=22,"LESS")) -> OK | G40: =IF(G38>=22,"OK",IF(G38<=22,"LESS")) -> OK | H40: =IF(H38>=22,"OK",IF(H38<=22,"LESS")) -> OK | I40: =IF(I38>=22,"OK",IF(I38<=22,"LESS")) -> OK | ... Q40: =IF(Q38>=22,"OK",IF(Q38<=22,"LESS")) -> OK
A43: Done by | B43: AKASH
A45: Comment

Sheet 03
A1: Station: | B1: IGKV ,RAIPUR
A2: Date: | B2: =$A$9 -> 03/02/2025 01:00 | D2: Power Off | G2: Pw.Off | L2: Link Fail | N2: Link F | P2: Maintenance | R2: Maint.
A3: Report Type: | B3: Mean | D3: Calibration | G3: Calib. | L3: Data Fail | N3: Data F | P3: Invalid | R3: Invalid
A4: Time Base: | B4: 01 Hour | D4: Zero Referrence | G4: Z.Ref | L4: Warm Up | N4: Wm. Up
A7: Date & Time | B7: NO | C7: NO2 | D7: NOX | E7: SO2 | F7: O3 | G7: PM 10 | H7: PM 2.5 | I7: BENZ | J7: WS | K7: WD | L7: TEMP | M7: HUM | N7: SR | O7: RG | P7: CO | Q7: NH3
B8: ug/m3 | C8: ug/m3 | D8: ppb | E8: ug/m3 | F8: ug/m3 | G8: ug/m3 | H8: ug/m3 | I8: ug/m3 | J8: m/sec | K8: deg | L8: degreC | M8: % | N8: w/m2 | O8: mm | P8: mg/m3 | Q8: ug/m3
A9: 03/02/2025 01:00 | B9: Pw.Off | C9: Pw.Off | D9: Pw.Off | E9: Pw.Off | F9: Pw.Off | G9: Pw.Off | H9: Pw.Off | I9: Pw.Off | J9: Pw.Off | K9: Pw.Off | L9: Pw.Off | M9: Pw.Off | N9: Pw.Off | O9: Pw.Off | P9: Pw.Off | Q9: Pw.Off
A10: 03/02/2025 02:00 | B10: Pw.Off | C10: Pw.Off | D10: Pw.Off | E10: Pw.Off | F10: Pw.Off | G10: Pw.Off | H10: Pw.Off | I10: Pw.Off | J10: Pw.Off | K10: Pw.Off | L10: Pw.Off | M10: Pw.Off | N10: Pw.Off | O10: Pw.Off | P10: Pw.Off | Q10: Pw.Off
A11: 03/02/2025 03:00 | B11: Pw.Off | C11: Pw.Off | D11: Pw.Off | E11: Pw.Off | F11: Pw.Off | G11: Pw.Off | H11: Pw.Off | I11: Pw.Off | J11: Pw.Off | K11: Pw.Off | L11: Pw.Off | M11: Pw.Off | N11: Pw.Off | O11: Pw.Off | P11: Pw.Off | Q11: Pw.Off
A12: 03/02/2025 04:00 | B12: Pw.Off | C12: Pw.Off | D12: Pw.Off | E12: Pw.Off | F12: Pw.Off | G12: Pw.Off | H12: Pw.Off | I12: Pw.Off | J12: Pw.Off | K12: Pw.Off | L12: Pw.Off | M12: Pw.Off | N12: Pw.Off | O12: Pw.Off | P12: Pw.Off | Q12: Pw.Off
A13: 03/02/2025 05:00 | B13: Pw.Off | C13: Pw.Off | D13: Pw.Off | E13: Pw.Off | F13: Pw.Off | G13: Pw.Off | H13: Pw.Off | I13: Pw.Off | J13: Pw.Off | K13: Pw.Off | L13: Pw.Off | M13: Pw.Off | N13: Pw.Off | O13: Pw.Off | P13: Pw.Off | Q13: Pw.Off
A14: 03/02/2025 06:00 | B14: Pw.Off | C14: Pw.Off | D14: Pw.Off | E14: Pw.Off | F14: Pw.Off | G14: Pw.Off | H14: Pw.Off | I14: Pw.Off | J14: Pw.Off | K14: Pw.Off | L14: Pw.Off | M14: Pw.Off | N14: Pw.Off | O14: Pw.Off | P14: Pw.Off | Q14: Pw.Off
A15: 03/02/2025 07:00 | B15: Pw.Off | C15: Pw.Off | D15: Pw.Off | E15: Pw.Off | F15: Pw.Off | G15: Pw.Off | H15: Pw.Off | I15: Pw.Off | J15: Pw.Off | K15: Pw.Off | L15: Pw.Off | M15: Pw.Off | N15: Pw.Off | O15: Pw.Off | P15: Pw.Off | Q15: Pw.Off
A16: 03/02/2025 08:00 | B16: Pw.Off | C16: Pw.Off | D16: Pw.Off | E16: Pw.Off | F16: Pw.Off | G16: Pw.Off | H16: Pw.Off | I16: Pw.Off | J16: Pw.Off | K16: Pw.Off | L16: Pw.Off | M16: Pw.Off | N16: Pw.Off | O16: Pw.Off | P16: Pw.Off | Q16: Pw.Off
A17: 03/02/2025 09:00 | B17: Pw.Off | C17: Pw.Off | D17: Pw.Off | E17: Pw.Off | F17: Pw.Off | G17: Pw.Off | H17: Pw.Off | I17: Pw.Off | J17: Pw.Off | K17: Pw.Off | L17: Pw.Off | M17: Pw.Off | N17: Pw.Off | O17: Pw.Off | P17: Pw.Off | Q17: Pw.Off
A18: 03/02/2025 10:00 | B18: Pw.Off | C18: Pw.Off | D18: Pw.Off | E18: Pw.Off | F18: Pw.Off | G18: Pw.Off | H18: Pw.Off | I18: Pw.Off | J18: Pw.Off | K18: Pw.Off | L18: Pw.Off | M18: Pw.Off | N18: Pw.Off | O18: Pw.Off | P18: Pw.Off | Q18: Pw.Off
A19: 03/02/2025 11:00 | B19: 43.01 | C19: 52.26 | D19: 63.26 | E19: 9.69 | F19: 5.25 | G19: 75.83 | H19: 29.11 | I19: 9.35 | J19: 1.42 | K19: 58.14 | L19: 26.02 | M19: 26.65 | N19: 510.5 | O19: 0 | P19: 1.07 | Q19: 7.96
A20: 03/02/2025 12:00 | B20: 33.09 | C20: 50.82 | D20: 54.62 | E20: 9.12 | F20: 5.89 | G20: 72.56 | H20: 27.25 | I20: 8.09 | J20: 1.45 | K20: 54.57 | L20: 27.08 | M20: 16.06 | N20: 557.3 | O20: 0 | P20: 0.96 | Q20: 7.39
A21: 03/02/2025 13:00 | B21: 24.93 | C21: 50.22 | D21: 47.78 | E21: 8.29 | F21: 6.74 | G21: 61.62 | H21: 22.16 | I21: 6.93 | J21: 1.08 | K21: 353.56 | L21: 28.48 | M21: 13.22 | N21: 561.4 | O21: 0 | P21: 0.85 | Q21: 6.82
A22: 03/02/2025 14:00 | B22: 16.33 | C22: 50.06 | D22: 40.8 | E22: 8.22 | F22: 6.26 | G22: 47.74 | H22: 14.52 | I22: 6.09 | J22: 1.32 | K22: 324.27 | L22: 29.68 | M22: 11.06 | N22: 554.7 | O22: 0 | P22: 0.76 | Q22: 6.29
A23: 03/02/2025 15:00 | B23: 9.6 | C23: 47.43 | D23: 34.03 | E23: 7.94 | F23: 6.8 | G23: 38.39 | H23: 13.59 | I23: 5.19 | J23: 0.79 | K23: 341.12 | L23: 30.37 | M23: 9.71 | N23: 511.5 | O23: 0 | P23: 0.6 | Q23: 5.66
A24: 03/02/2025 16:00 | B24: 7.27 | C24: 44.45 | D24: 30.6 | E24: 8.11 | F24: 8.18 | G24: 36.93 | H24: 13.59 | I24: 4.6 | J24: 0.84 | K24: 345.41 | L24: 28.93 | M24: 11.13 | N24: 116.3 | O24: 0 | P24: 0.56 | Q24: 5.33
A25: 03/02/2025 17:00 | B25: 7.16 | C25: 44.96 | D25: 30.78 | E25: 8.54 | F25: 7.63 | G25: 36.93 | H25: 12.01 | I25: 4 | J25: 1.07 | K25: 45.45 | L25: 28.17 | M25: 13.42 | N25: 91.8 | O25: 0 | P25: 0.54 | Q25: 5.23
A26: 03/02/2025 18:00 | B26: 15.89 | C26: 50.36 | D26: 40.6 | E26: 7.58 | F26: 6 | G26: 52.3 | H26: 13.53 | I26: 3.73 | J26: 0.72 | K26: 58.89 | L26: 26.86 | M26: 15.46 | N26: 26.9 | O26: 0 | P26: 0.59 | Q26: 5.76
A27: 03/02/2025 19:00 | B27: 22.61 | C27: 51.38 | D27: 46.46 | E27: 8.11 | F27: 4.99 | G27: 74.37 | H27: 18.88 | I27: 3.94 | J27: 0.25 | K27: 163.73 | L27: 24 | M27: 39.33 | N27: 26.9 | O27: 0 | P27: 0.64 | Q27: 6.34
A28: 03/02/2025 20:00 | B28: 26.09 | C28: 51.64 | D28: 49.44 | E28: 8.3 | F28: 4.77 | G28: 78.51 | H28: 20.91 | I28: 4.57 | J28: 0.24 | K28: 177.85 | L28: 19.03 | M28: 51.26 | N28: 26.9 | O28: 0 | P28: 0.71 | Q28: 6.63
A29: 03/02/2025 21:00 | B29: 25.89 | C29: 50.92 | D29: 48.92 | E29: 7.91 | F29: 4.57 | G29: 78.51 | H29: 20.91 | I29: 4.92 | J29: 0.23 | K29: 191.91 | L29: 16.8 | M29: 58.26 | N29: 26.9 | O29: 0 | P29: 0.76 | Q29: 6.62
A30: 03/02/2025 22:00 | B30: 24.06 | C30: 49.45 | D30: 46.68 | E30: 7.81 | F30: 4.67 | G30: 65.48 | H30: 17.59 | I30: 5.27 | J30: 0.27 | K30: 171.47 | L30: 15.67 | M30: 59.36 | N30: 26.9 | O30: 0 | P30: 0.81 | Q30: 6.53
... A32: 03/02/2025 24:00 | B32: 46.44 | C32: 49.36 | D32: 63.94 | E32: 8.09 | F32: 4.66 | G32: 76.7 | H32: 29.56 | I32: 7.31 | J32: 0.2 | K32: 206.99 | L32: 14.82 | M32: 69.19 | N32: 26.9 | O32: 0 | P32: 1.03 | Q32: 7.99
A34: Min | B34: =MIN(B9:B32) -> 7.16 | C34: =MIN(C9:C32) -> 44.45 | D34: =MIN(D9:D32) -> 30.6 | E34: =MIN(E9:E32) -> 7.58 | F34: =MIN(F9:F32) -> 4.57 | G34: =MIN(G9:G32) -> 36.93 | H34: =MIN(H9:H32) -> 12.01 | I34: =MIN(I9:I32) -> 3.73 | ... Q34: =MIN(Q9:Q32) -> 5.23
A35: Max | B35: =MAX(B9:B32) -> 46.44 | C35: =MAX(C9:C32) -> 52.26 | D35: =MAX(D9:D32) -> 63.94 | E35: =MAX(E9:E32) -> 9.69 | F35: =MAX(F9:F32) -> 8.18 | G35: =MAX(G9:G32) -> 78.51 | H35: =MAX(H9:H32) -> 29.56 | I35: =MAX(I9:I32) -> 9.35 | ... Q35: =MAX(Q9:Q32) -> 7.99
A36: Avg | B36: =AVERAGE(B9:B32) -> 24.278571 | C36: =AVERAGE(C9:C32) -> 49.51 | D36: =AVERAGE(D9:D32) -> 46.82 | E36: =AVERAGE(E9:E32) -> 8.275 | F36: =AVERAGE(F9:F32) -> 5.79 | G36: =AVERAGE(G9:G32) -> 61.935 | H36: =AVERAGE(H9:H32) -> 20.085714 | I36: =AVERAGE(I9:I32) -> 5.7221429 | ... Q36: =AVERAGE(Q9:Q32) -> 6.565
A37: Stdev | B37: =STDEV(B9:B32) -> 12.513736 | C37: =STDEV(C9:C32) -> 2.3466933 | D37: =STDEV(D9:D32) -> 10.781032 | E37: =STDEV(E9:E32) -> 0.54363096 | F37: =STDEV(F9:F32) -> 1.1957167 | G37: =STDEV(G9:G32) -> 16.234183 | H37: =STDEV(H9:H32) -> 6.2986283 | I37: =STDEV(I9:I32) -> 1.6840892 | ... Q37: =STDEV(Q9:Q32) -> 0.88854029
A38: Num | B38: =COUNT(B9:B32)+10 -> 24 | C38: =COUNT(C9:C32)+10 -> 24 | D38: =COUNT(D9:D32)+10 -> 24 | E38: =COUNT(E9:E32)+10 -> 24 | F38: =COUNT(F9:F32)+10 -> 24 | G38: =COUNT(G9:G32)+10 -> 24 | H38: =COUNT(H9:H32)+10 -> 24 | I38: =COUNT(I9:I32)+10 -> 24 | ... Q38: =COUNT(Q9:Q32)+10 -> 24
A39: DCR | B39: =IF(B38>=22,">90%",IF(B38<=22,"<90%")) -> >90% | C39: =IF(C38>=22,">90%",IF(C38<=22,"<90%")) -> >90% | D39: =IF(D38>=22,">90%",IF(D38<=22,"<90%")) -> >90% | E39: =IF(E38>=22,">90%",IF(E38<=22,"<90%")) -> >90% | F39: =IF(F38>=22,">90%",IF(F38<=22,"<90%")) -> >90% | G39: =IF(G38>=22,">90%",IF(G38<=22,"<90%")) -> >90% | H39: =IF(H38>=22,">90%",IF(H38<=22,"<90%")) -> >90% | I39: =IF(I38>=22,">90%",IF(I38<=22,"<90%")) -> >90% | ... Q39: =IF(Q38>=22,">90%",IF(Q38<=22,"<90%")) -> >90%
A40: Status | B40: =IF(B38>=22,"OK",IF(B38<=22,"LESS")) -> OK | C40: =IF(C38>=22,"OK",IF(C38<=22,"LESS")) -> OK | D40: =IF(D38>=22,"OK",IF(D38<=22,"LESS")) -> OK | E40: =IF(E38>=22,"OK",IF(E38<=22,"LESS")) -> OK | F40: =IF(F38>=22,"OK",IF(F38<=22,"LESS")) -> OK | G40: =IF(G38>=22,"OK",IF(G38<=22,"LESS")) -> OK | H40: =IF(H38>=22,"OK",IF(H38<=22,"LESS")) -> OK | I40: =IF(I38>=22,"OK",IF(I38<=22,"LESS")) -> OK | ... Q40: =IF(Q38>=22,"OK",IF(Q38<=22,"LESS")) -> OK
A43: Done by | B43: AKASH
A45: Comment

Sheet 04
A1: Station: | B1: IGKV ,RAIPUR
A2: Date: | B2: =$A$9 -> 45692.042 | D2: Power Off | G2: Pw.Off | L2: Link Fail | N2: Link F | P2: Maintenance | R2: Maint.
A3: Report Type: | B3: Mean | D3: Calibration | G3: Calib. | L3: Data Fail | N3: Data F | P3: Invalid | R3: Invalid
A4: Time Base: | B4: 01 Hour | D4: Zero Referrence | G4: Z.Ref | L4: Warm Up | N4: Wm. Up
A7: Date & Time | B7: NO | C7: NO2 | D7: NOX | E7: SO2 | F7: O3 | G7: PM 10 | H7: PM 2.5 | I7: BENZ | J7: WS | K7: WD | L7: TEMP | M7: HUM | N7: SR | O7: RG | P7: CO | Q7: NH3
B8: ug/m3 | C8: ug/m3 | D8: ppb | E8: ug/m3 | F8: ug/m3 | G8: ug/m3 | H8: ug/m3 | I8: ug/m3 | J8: m/sec | K8: deg | L8: degreC | M8: % | N8: w/m2 | O8: mm | P8: mg/m3 | Q8: ug/m3
A9: 45692.042 | B9: 49.63 | C9: 47.24 | D9: 65.32 | E9: 8.13 | F9: 4.6 | G9: 76.7 | H9: 29.56 | I9: 7.96 | J9: 0.21 | K9: 182.95 | L9: 14.36 | M9: 70.74 | N9: 0 | O9: 0 | P9: 1.1 | Q9: 7.99
A10: 45692.083 | B10: 84.71 | C10: 47.48 | D10: 94.28 | E10: 8.98 | F10: 4.64 | G10: 93.18 | H10: 35.78 | I10: 9.4 | J10: 0.21 | K10: 176.24 | L10: 14.72 | M10: 68.36 | N10: 0 | O10: 0 | P10: 1.32 | Q10: 10.1
A11: 45692.125 | B11: 102.91 | C11: 48.23 | D11: 109.04 | E11: 8.49 | F11: 4.65 | G11: 110.17 | H11: 43.06 | I11: 11.62 | J11: 0.22 | K11: 203.24 | L11: 14.03 | M11: 77.13 | N11: 0 | O11: 0 | P11: 1.44 | Q11: 11.35
A12: 45692.167 | B12: 99.85 | C12: 46.09 | D12: 105.7 | E12: 8.41 | F12: 4.66 | G12: 120.96 | H12: 43.06 | I12: 12.38 | J12: 0.19 | K12: 192.51 | L12: 12.75 | M12: 77.32 | N12: 0 | O12: 0 | P12: 1.47 | Q12: 11.26
A13: 45692.208 | B13: 114.09 | C13: 48.33 | D13: 118.29 | E13: 8.81 | F13: 4.61 | G13: 139.62 | H13: 44.93 | I13: 13.32 | J13: 0.44 | K13: 188.01 | L13: 13.68 | M13: 81.13 | N13: 0 | O13: 0 | P13: 1.57 | Q13: 12
A14: 45692.25 | B14: 112.02 | C14: 47.54 | D14: 116.22 | E14: 8.87 | F14: 4.73 | G14: 139.62 | H14: 44.93 | I14: 13.81 | J14: 0.21 | K14: 204.18 | L14: 11.39 | M14: 83.14 | N14: 0 | O14: 0 | P14: 1.55 | Q14: 11.88
A15: 45692.292 | B15: 100.36 | C15: 46.18 | D15: 106.16 | E15: 8.67 | F15: 4.69 | G15: 125.25 | H15: 42.72 | I15: 13.6 | J15: 0.16 | K15: 205.15 | L15: 10.83 | M15: 84.93 | N15: 1.1 | O15: 0 | P15: 1.52 | Q15: 11.2
A16: 45692.333 | B16: 88.99 | C16: 47.4 | D16: 96.76 | E16: 8.51 | F16: 4.63 | G16: 109.99 | H16: 43.61 | I16: 13.4 | J16: 0.14 | K16: 164.97 | L16: 14.29 | M16: 84.13 | N16: 25.8 | O16: 0 | P16: 1.53 | Q16: 10.48
A17: 45692.375 | B17: 78.79 | C17: 53.65 | D17: 90.44 | E17: 9.5 | F17: 4.72 | G17: 109.99 | H17: 43.61 | I17: 13.62 | J17: 0.28 | K17: 232.42 | L17: 21.83 | M17: 51.29 | N17: 301.5 | O17: 0 | P17: 1.52 | Q17: 9.95
A18: 45692.417 | B18: 57.52 | C18: 55.36 | D18: 76.06 | E18: 11.16 | F18: 4.9 | G18: 88.39 | H18: 40.58 | I18: 13.23 | J18: 0.93 | K18: 78.14 | L18: 24.24 | M18: 32.99 | N18: 387.8 | O18: 0 | P18: 1.4 | Q18: 9
A19: 45692.458 | B19: 41.29 | C19: 56.1 | D19: 63.57 | E19: 10.1 | F19: 5.11 | G19: 83.34 | H19: 36.01 | I19: 11.63 | J19: 1.24 | K19: 57.84 | L19: 26.3 | M19: 26.46 | N19: 478.8 | O19: 0 | P19: 1.2 | Q19: 7.99
A20: 45692.5 | B20: 33.06 | C20: 56.41 | D20: 57.44 | E20: 14.16 | F20: 5.37 | G20: 72.51 | H20: 33.18 | I20: 9.94 | J20: 1.02 | K20: 113.08 | L20: 28.48 | M20: 22.03 | N20: 530.6 | O20: 0 | P20: 1.04 | Q20: 7.5
... A32: 45693 | B32: 25.12 | C32: 46.23 | D32: 45.83 | E32: 7.89 | F32: 4.63 | G32: 85.5 | H32: 26.1 | I32: 7 | J32: 0.19 | K32: 200.25 | L32: 15.3 | M32: 69.51 | N32: 0 | O32: 0 | P32: 0.85 | Q32: 6.55
A34: Min | B34: =MIN(B9:B32) -> 8.41 | C34: =MIN(C9:C32) -> 46.09 | D34: =MIN(D9:D32) -> 33.8 | E34: =MIN(E9:E32) -> 7.89 | F34: =MIN(F9:F32) -> 4.39 | G34: =MIN(G9:G32) -> 43.22 | H34: =MIN(H9:H32) -> 19.21 | I34: =MIN(I9:I32) -> 4.9 | ... Q34: =MIN(Q9:Q32) -> 5.61
A35: Max | B35: =MAX(B9:B32) -> 114.09 | C35: =MAX(C9:C32) -> 56.41 | D35: =MAX(D9:D32) -> 118.29 | E35: =MAX(E9:E32) -> 14.16 | F35: =MAX(F9:F32) -> 9.61 | G35: =MAX(G9:G32) -> 139.62 | H35: =MAX(H9:H32) -> 44.93 | I35: =MAX(I9:I32) -> 13.81 | ... Q35: =MAX(Q9:Q32) -> 12
A36: Avg | B36: =AVERAGE(B9:B32) -> 49.20125 | C36: =AVERAGE(C9:C32) -> 50.537917 | D36: =AVERAGE(D9:D32) -> 67.075833 | E36: =AVERAGE(E9:E32) -> 9.4058333 | F36: =AVERAGE(F9:F32) -> 5.4804167 | G36: =AVERAGE(G9:G32) -> 85.671667 | H36: =AVERAGE(H9:H32) -> 31.465833 | I36: =AVERAGE(I9:I32) -> 9.1295833 | ... Q36: =AVERAGE(Q9:Q32) -> 8.1633333
A37: Stdev | B37: =STDEV(B9:B32) -> 37.509648 | C37: =STDEV(C9:C32) -> 3.5414133 | D37: =STDEV(D9:D32) -> 29.261046 | E37: =STDEV(E9:E32) -> 1.5722786 | F37: =STDEV(F9:F32) -> 1.5547305 | G37: =STDEV(G9:G32) -> 28.446654 | H37: =STDEV(H9:H32) -> 9.6598721 | I37: =STDEV(I9:I32) -> 3.2837736 | ... Q37: =STDEV(Q9:Q32) -> 2.2483127
A38: Num | B38: =COUNT(B9:B32) -> 24 | C38: =COUNT(C9:C32) -> 24 | D38: =COUNT(D9:D32) -> 24 | E38: =COUNT(E9:E32) -> 24 | F38: =COUNT(F9:F32) -> 24 | G38: =COUNT(G9:G32) -> 24 | H38: =COUNT(H9:H32) -> 24 | I38: =COUNT(I9:I32) -> 24 | ... Q38: =COUNT(Q9:Q32) -> 24
A39: DCR | B39: =IF(B38>=22,">90%",IF(B38<=22,"<90%")) -> >90% | C39: =IF(C38>=22,">90%",IF(C38<=22,"<90%")) -> >90% | D39: =IF(D38>=22,">90%",IF(D38<=22,"<90%")) -> >90% | E39: =IF(E38>=22,">90%",IF(E38<=22,"<90%")) -> >90% | F39: =IF(F38>=22,">90%",IF(F38<=22,"<90%")) -> >90% | G39: =IF(G38>=22,">90%",IF(G38<=22,"<90%")) -> >90% | H39: =IF(H38>=22,">90%",IF(H38<=22,"<90%")) -> >90% | I39: =IF(I38>=22,">90%",IF(I38<=22,"<90%")) -> >90% | ... Q39: =IF(Q38>=22,">90%",IF(Q38<=22,"<90%")) -> >90%
A40: Status | B40: =IF(B38>=22,"OK",IF(B38<=22,"LESS")) -> OK | C40: =IF(C38>=22,"OK",IF(C38<=22,"LESS")) -> OK | D40: =IF(D38>=22,"OK",IF(D38<=22,"LESS")) -> OK | E40: =IF(E38>=22,"OK",IF(E38<=22,"LESS")) -> OK | F40: =IF(F38>=22,"OK",IF(F38<=22,"LESS")) -> OK | G40: =IF(G38>=22,"OK",IF(G38<=22,"LESS")) -> OK | H40: =IF(H38>=22,"OK",IF(H38<=22,"LESS")) -> OK | I40: =IF(I38>=22,"OK",IF(I38<=22,"LESS")) -> OK | ... Q40: =IF(Q38>=22,"OK",IF(Q38<=22,"LESS")) -> OK
A43: Done by | B43: AKASH
A45: Comment

Sheet 05
A1: Station: | B1: IGKV ,RAIPUR
A2: Date: | B2: =$A$9 -> 05/02/2025 01:00 | D2: Power Off | G2: Pw.Off | L2: Link Fail | N2: Link F | P2: Maintenance | R2: Maint.
A3: Report Type: | B3: Mean | D3: Calibration | G3: Calib. | L3: Data Fail | N3: Data F | P3: Invalid | R3: Invalid
A4: Time Base: | B4: 01 Hour | D4: Zero Referrence | G4: Z.Ref | L4: Warm Up | N4: Wm. Up
A7: Date & Time | B7: NO | C7: NO2 | D7: NOX | E7: SO2 | F7: O3 | G7: PM 10 | H7: PM 2.5 | I7: BENZ | J7: WS | K7: WD | L7: TEMP | M7: HUM | N7: SR | O7: RG | P7: CO | Q7: NH3
B8: ug/m3 | C8: ug/m3 | D8: ppb | E8: ug/m3 | F8: ug/m3 | G8: ug/m3 | H8: ug/m3 | I8: ug/m3 | J8: m/sec | K8: deg | L8: degreC | M8: % | N8: w/m2 | O8: mm | P8: mg/m3 | Q8: ug/m3
A9: 05/02/2025 01:00 | B9: 31.43 | C9: 47.25 | D9: 51.44 | E9: 8.07 | F9: 4.65 | G9: 85.35 | H9: 26.25 | I9: 7.42 | J9: 0.2 | K9: 211.03 | L9: 14.84 | M9: 68.95 | N9: 0 | O9: 0 | P9: 0.94 | Q9: 6.83
A10: 05/02/2025 02:00 | B10: 55.72 | C10: 50.16 | D10: 72.44 | E10: 8.38 | F10: 4.71 | G10: 104.83 | H10: 33.28 | I10: 8.73 | J10: 0.22 | K10: 151.79 | L10: 14.83 | M10: 70.08 | N10: 0 | O10: 0 | P10: 1.18 | Q10: 8.31
A11: 05/02/2025 03:00 | B11: 87.24 | C11: 52.21 | D11: 98.61 | E11: 8.24 | F11: 4.53 | G11: 121.03 | H11: 41.08 | I11: 10.73 | J11: 0.27 | K11: 204.95 | L11: 14.41 | M11: 75.23 | N11: 0 | O11: 0 | P11: 1.39 | Q11: 10.38
A12: 05/02/2025 04:00 | B12: 91.3 | C12: 51.48 | D12: 101.47 | E12: 8.5 | F12: 4.6 | G12: 121.03 | H12: 41.96 | I12: 11.75 | J12: 0.18 | K12: 201.7 | L12: 13.09 | M12: 79.97 | N12: 0 | O12: 0 | P12: 1.44 | Q12: 10.68
A13: 05/02/2025 05:00 | B13: 89.97 | C13: 50.68 | D13: 100.17 | E13: 8.41 | F13: 4.45 | G13: 119.15 | H13: 41.96 | I13: 12.23 | J13: 0.17 | K13: 188.89 | L13: 12.38 | M13: 80.19 | N13: 0 | O13: 0 | P13: 1.45 | Q13: 10.63
A14: 05/02/2025 06:00 | B14: 81.92 | C14: 48.19 | D14: 92.42 | E14: 8.42 | F14: 4.59 | G14: 118.9 | H14: 37.56 | I14: 12.28 | J14: 0.19 | K14: 190.48 | L14: 11.93 | M14: 82.4 | N14: 0 | O14: 0 | P14: 1.44 | Q14: 10.11
A15: 05/02/2025 07:00 | B15: 72.87 | C15: 45.35 | D15: 83.68 | E15: 8.29 | F15: 4.54 | G15: 118.9 | H15: 38.8 | I15: 12.23 | J15: 0.24 | K15: 179.31 | L15: 11.37 | M15: 84.64 | N15: 1.3 | O15: 0 | P15: 1.42 | Q15: 9.49
A16: 05/02/2025 08:00 | B16: 65.05 | C16: 44.35 | D16: 76.44 | E16: 8.17 | F16: 4.52 | G16: 118.59 | H16: 40.1 | I16: 12.48 | J16: 0.19 | K16: 171.3 | L16: 14.29 | M16: 84.14 | N16: 27 | O16: 0 | P16: 1.4 | Q16: 8.96
A17: 05/02/2025 09:00 | B17: Pw.Off | C17: Pw.Off | D17: Pw.Off | E17: Pw.Off | F17: Pw.Off | G17: Pw.Off | H17: Pw.Off | I17: Pw.Off | J17: Pw.Off | K17: Pw.Off | L17: Pw.Off | M17: Pw.Off | N17: Pw.Off | O17: Pw.Off | P17: Pw.Off | Q17: Pw.Off
A18: 05/02/2025 10:00 | B18: Pw.Off | C18: Pw.Off | D18: Pw.Off | E18: Pw.Off | F18: Pw.Off | G18: Pw.Off | H18: Pw.Off | I18: Pw.Off | J18: Pw.Off | K18: Pw.Off | L18: Pw.Off | M18: Pw.Off | N18: Pw.Off | O18: Pw.Off | P18: Pw.Off | Q18: Pw.Off
A19: 05/02/2025 11:00 | B19: Pw.Off | C19: Pw.Off | D19: Pw.Off | E19: Pw.Off | F19: Pw.Off | G19: Pw.Off | H19: Pw.Off | I19: Pw.Off | J19: Pw.Off | K19: Pw.Off | L19: Pw.Off | M19: Pw.Off | N19: Pw.Off | O19: Pw.Off | P19: Pw.Off | Q19: Pw.Off
A20: 05/02/2025 12:00 | B20: Pw.Off | C20: Pw.Off | D20: Pw.Off | E20: Pw.Off | F20: Pw.Off | G20: Pw.Off | H20: Pw.Off | I20: Pw.Off | J20: Pw.Off | K20: Pw.Off | L20: Pw.Off | M20: Pw.Off | N20: Pw.Off | O20: Pw.Off | P20: Pw.Off | Q20: Pw.Off
A21: 05/02/2025 13:00 | B21: Pw.Off | C21: Pw.Off | D21: Pw.Off | E21: Pw.Off | F21: Pw.Off | G21: Pw.Off | H21: Pw.Off | I21: Pw.Off | J21: Pw.Off | K21: Pw.Off | L21: Pw.Off | M21: Pw.Off | N21: Pw.Off | O21: Pw.Off | P21: Pw.Off | Q21: Pw.Off
A22: 05/02/2025 14:00 | B22: Pw.Off | C22: Pw.Off | D22: Pw.Off | E22: Pw.Off | F22: Pw.Off | G22: Pw.Off | H22: Pw.Off | I22: Pw.Off | J22: Pw.Off | K22: Pw.Off | L22: Pw.Off | M22: Pw.Off | N22: Pw.Off | O22: Pw.Off | P22: Pw.Off | Q22: Pw.Off
A23: 05/02/2025 15:00 | B23: 3.88 | C23: 17.39 | D23: 13.55 | E23: 9.83 | F23: 1.3 | G23: 41.07 | H23: 27.49 | I23: 7.47 | J23: 0.8 | K23: 305.32 | L23: 33.37 | M23: 26.25 | N23: 87.6 | O23: 0 | P23: 0.49 | Q23: 12.93
A24: 05/02/2025 16:00 | B24: 4.13 | C24: 17.17 | D24: 13.39 | E24: 10.47 | F24: 2.6 | G24: 41.07 | H24: 27.49 | I24: 7.44 | J24: 0.78 | K24: 286.69 | L24: 33.57 | M24: 27.07 | N24: 87.6 | O24: 0 | P24: 0.56 | Q24: 12.94
A25: 05/02/2025 17:00 | B25: 3.92 | C25: 19.34 | D25: 14.6 | E25: 12.28 | F25: 3.5 | G25: 33.6 | H25: 25.97 | I25: 6.65 | J25: 0.48 | K25: 288.3 | L25: 32.89 | M25: 29.63 | N25: 43.8 | O25: 0 | P25: 0.45 | Q25: 12.95
A26: 05/02/2025 18:00 | B26: 4 | C26: 19.39 | D26: 14.61 | E26: 11.01 | F26: 2.6 | G26: 36.53 | H26: 21.93 | I26: 6.69 | J26: 0.4 | K26: 255.71 | L26: 31.5 | M26: 39.05 | N26: 18.8 | O26: 0 | P26: 0.44 | Q26: 12.94
A27: 05/02/2025 19:00 | B27: 4.53 | C27: 19.49 | D27: 15.17 | E27: 10.1 | F27: 5.9 | G27: 63.55 | H27: 21.34 | I27: 6.64 | J27: 0.3 | K27: 168.25 | L27: 28.15 | M27: 54.82 | N27: 2 | O27: 0 | P27: 0.47 | Q27: 12.94
A28: 05/02/2025 20:00 | B28: 5.24 | C28: 20.15 | D28: 16.08 | E28: 10.37 | F28: 6.5 | G28: 65.86 | H28: 19.97 | I28: 7.11 | J28: 0.25 | K28: 195.11 | L28: 26 | M28: 60.01 | N28: 1.5 | O28: 0 | P28: 0.53 | Q28: 12.94
A29: 05/02/2025 21:00 | B29: 6.59 | C29: 22.91 | D29: 18.61 | E29: 10.39 | F29: 3.54 | G29: 65.86 | H29: 19.98 | I29: 8.15 | J29: 0.19 | K29: 189.93 | L29: 24.69 | M29: 63.25 | N29: 1.1 | O29: 0 | P29: 0.66 | Q29: 12.95
A30: 05/02/2025 22:00 | B30: 8.53 | C30: 22.58 | D30: 19.77 | E30: 10.32 | F30: 2.6 | G30: 86.22 | H30: 19.98 | I30: 9.44 | J30: 0.23 | K30: 189.1 | L30: 23.87 | M30: 69.23 | N30: 1.5 | O30: 0 | P30: 0.73 | Q30: 12.93
A31: 05/02/2025 23:00 | B31: 10.05 | C31: 21.62 | D31: 20.6 | E31: 10.52 | F31: 2.6 | G31: 86.22 | H31: 19.2 | I31: 10.46 | J31: 0.16 | K31: 194.78 | L31: 22.8 | M31: 70.33 | N31: 1.1 | O31: 0 | P31: 0.77 | Q31: 12.95
A32: 05/02/2025 24:00 | B32: 12.52 | C32: 21.87 | D32: 22.82 | E32: 10.68 | F32: 2.6 | G32: 75.21 | H32: 19.2 | I32: 10.94 | J32: 0.23 | K32: 328.95 | L32: 23 | M32: 66.7 | N32: 1.5 | O32: 0 | P32: 0.8 | Q32: 12.95
A34: Min | B34: =MIN(B9:B32) -> 3.88 | C34: =MIN(C9:C32) -> 17.17 | D34: =MIN(D9:D32) -> 13.39 | E34: =MIN(E9:E32) -> 8.07 | F34: =MIN(F9:F32) -> 1.3 | G34: =MIN(G9:G32) -> 33.6 | H34: =MIN(H9:H32) -> 19.2 | I34: =MIN(I9:I32) -> 6.64 | ... Q34: =MIN(Q9:Q32) -> 6.83
A35: Max | B35: =MAX(B9:B32) -> 91.3 | C35: =MAX(C9:C32) -> 52.21 | D35: =MAX(D9:D32) -> 101.47 | E35: =MAX(E9:E32) -> 12.28 | F35: =MAX(F9:F32) -> 6.5 | G35: =MAX(G9:G32) -> 121.03 | H35: =MAX(H9:H32) -> 41.96 | I35: =MAX(I9:I32) -> 12.48 | ... Q35: =MAX(Q9:Q32) -> 12.95
A36: Avg | B36: =AVERAGE(B9:B32) -> 35.493889 | C36: =AVERAGE(C9:C32) -> 32.865556 | D36: =AVERAGE(D9:D32) -> 46.992778 | E36: =AVERAGE(E9:E32) -> 9.5805556 | F36: =AVERAGE(F9:F32) -> 3.9072222 | G36: =AVERAGE(G9:G32) -> 83.498333 | H36: =AVERAGE(H9:H32) -> 29.085556 | I36: =AVERAGE(I9:I32) -> 9.38 | ... Q36: =AVERAGE(Q9:Q32) -> 11.378333
A37: Stdev | B37: =STDEV(B9:B32) -> 36.132766 | C37: =STDEV(C9:C32) -> 14.772586 | D37: =STDEV(D9:D32) -> 36.41698 | E37: =STDEV(E9:E32) -> 1.27025 | F37: =STDEV(F9:F32) -> 1.3270215 | G37: =STDEV(G9:G32) -> 32.253232 | H37: =STDEV(H9:H32) -> 8.940541 | I37: =STDEV(I9:I32) -> 2.2471708 | ... Q37: =STDEV(Q9:Q32) -> 1.9944076
A38: Num | B38: =COUNT(B9:B32)+6 -> 24 | C38: =COUNT(C9:C32)+6 -> 24 | D38: =COUNT(D9:D32)+6 -> 24 | E38: =COUNT(E9:E32)+6 -> 24 | F38: =COUNT(F9:F32)+6 -> 24 | G38: =COUNT(G9:G32)+6 -> 24 | H38: =COUNT(H9:H32)+6 -> 24 | I38: =COUNT(I9:I32)+6 -> 24 | ... Q38: =COUNT(Q9:Q32)+6 -> 24
A39: DCR | B39: =IF(B38>=22,">90%",IF(B38<=22,"<90%")) -> >90% | C39: =IF(C38>=22,">90%",IF(C38<=22,"<90%")) -> >90% | D39: =IF(D38>=22,">90%",IF(D38<=22,"<90%")) -> >90% | E39: =IF(E38>=22,">90%",IF(E38<=22,"<90%")) -> >90% | F39: =IF(F38>=22,">90%",IF(F38<=22,"<90%")) -> >90% | G39: =IF(G38>=22,">90%",IF(G38<=22,"<90%")) -> >90% | H39: =IF(H38>=22,">90%",IF(H38<=22,"<90%")) -> >90% | I39: =IF(I38>=22,">90%",IF(I38<=22,"<90%")) -> >90% | ... Q39: =IF(Q38>=22,">90%",IF(Q38<=22,"<90%")) -> >90%
A40: Status | B40: =IF(B38>=22,"OK",IF(B38<=22,"LESS")) -> OK | C40: =IF(C38>=22,"OK",IF(C38<=22,"LESS")) -> OK | D40: =IF(D38>=22,"OK",IF(D38<=22,"LESS")) -> OK | E40: =IF(E38>=22,"OK",IF(E38<=22,"LESS")) -> OK | F40: =IF(F38>=22,"OK",IF(F38<=22,"LESS")) -> OK | G40: =IF(G38>=22,"OK",IF(G38<=22,"LESS")) -> OK | H40: =IF(H38>=22,"OK",IF(H38<=22,"LESS")) -> OK | I40: =IF(I38>=22,"OK",IF(I38<=22,"LESS")) -> OK | ... Q40: =IF(Q38>=22,"OK",IF(Q38<=22,"LESS")) -> OK
A43: Done by | B43: AKASH
A45: Comment

Sheet 06
A1: Station: | B1: IGKV ,RAIPUR
A2: Date: | B2: =$A$9 -> 06/02/2025 01:00 | D2: Power Off | G2: Pw.Off | L2: Link Fail | N2: Link F | P2: Maintenance | R2: Maint.
A3: Report Type: | B3: Mean | D3: Calibration | G3: Calib. | L3: Data Fail | N3: Data F | P3: Invalid | R3: Invalid
A4: Time Base: | B4: 01 Hour | D4: Zero Referrence | G4: Z.Ref | L4: Warm Up | N4: Wm. Up
A7: Date & Time | B7: NO | C7: NO2 | D7: NOX | E7: SO2 | F7: O3 | G7: PM 10 | H7: PM 2.5 | I7: BENZ | J7: WS | K7: WD | L7: TEMP | M7: HUM | N7: SR | O7: RG | P7: CO | Q7: NH3
B8: ug/m3 | C8: ug/m3 | D8: ppb | E8: ug/m3 | F8: ug/m3 | G8: ug/m3 | H8: ug/m3 | I8: ug/m3 | J8: m/sec | K8: deg | L8: degreC | M8: % | N8: w/m2 | O8: mm | P8: mg/m3 | Q8: ug/m3
A9: 06/02/2025 01:00 | B9: 17.41 | C9: 23.21 | D9: 27.44 | E9: 11.14 | F9: 3.92 | G9: 78.16 | H9: 19.57 | I9: 11.44 | J9: 0.38 | K9: 166.75 | L9: 23.81 | M9: 67.66 | N9: 1.5 | O9: 0 | P9: 0.85 | Q9: 12.98
A10: 06/02/2025 02:00 | B10: 18.59 | C10: 23.67 | D10: 28.34 | E10: 10.74 | F10: 3.86 | G10: 82.82 | H10: 20.45 | I10: 11.62 | J10: 0.58 | K10: 51.7 | L10: 23.87 | M10: 59.72 | N10: 1.4 | O10: 0 | P10: 0.85 | Q10: 12.99
A11: 06/02/2025 03:00 | B11: 16.89 | C11: 24.83 | D11: 27.44 | E11: 10.45 | F11: 3.79 | G11: 82.82 | H11: 20.55 | I11: 11.33 | J11: 0.65 | K11: 328.48 | L11: 23.15 | M11: 62.61 | N11: 1.5 | O11: 0 | P11: 0.75 | Q11: 12.99
A12: 06/02/2025 04:00 | B12: 14.33 | C12: 25.18 | D12: 25.87 | E12: 9.94 | F12: 3.93 | G12: 68.44 | H12: 20.55 | I12: 10.68 | J12: 0.77 | K12: 45.45 | L12: 22.69 | M12: 65.38 | N12: 1.5 | O12: 0 | P12: 0.7 | Q12: 12.99
A13: 06/02/2025 05:00 | B13: 10.85 | C13: 25.28 | D13: 23.14 | E13: 9.99 | F13: 3.92 | G13: 60.24 | H13: 18.59 | I13: 10.09 | J13: 0.92 | K13: 53.26 | L13: 22.09 | M13: 67.11 | N13: 1.7 | O13: 0 | P13: 0.65 | Q13: 12.97
A14: 06/02/2025 06:00 | B14: 8.44 | C14: 25.13 | D14: 21.25 | E14: 9.71 | F14: 3.84 | G14: 56.76 | H14: 17.71 | I14: 9.39 | J14: 1.21 | K14: 47.57 | L14: 21.42 | M14: 67.2 | N14: 1.4 | O14: 0 | P14: 0.62 | Q14: 12.97
A15: 06/02/2025 07:00 | B15: 6.98 | C15: 24.86 | D15: 19.86 | E15: 9.92 | F15: 3.68 | G15: 61.3 | H15: 17.6 | I15: 8.95 | J15: 1.32 | K15: 54.38 | L15: 21.14 | M15: 66.53 | N15: 8.7 | O15: 0 | P15: 0.67 | Q15: 12.95
A16: 06/02/2025 08:00 | B16: 7.63 | C16: 24.41 | D16: 19.96 | E16: 9.21 | F16: 4.39 | G16: 61.3 | H16: 19.38 | I16: 8.89 | J16: 1.2 | K16: 55.22 | L16: 21.49 | M16: 66.92 | N16: 41.5 | O16: 0 | P16: 0.67 | Q16: 12.95
A17: 06/02/2025 09:00 | B17: 7.68 | C17: 23.64 | D17: 19.83 | E17: 8.71 | F17: 12.01 | G17: 59.89 | H17: 19.63 | I17: 8.81 | J17: 1.48 | K17: 56.86 | L17: 23.33 | M17: 64.34 | N17: 169.9 | O17: 0 | P17: 0.68 | Q17: 12.95
A18: 06/02/2025 10:00 | B18: 7.82 | C18: 23.86 | D18: 20.09 | E18: 9.79 | F18: 17.13 | G18: 59.89 | H18: 21.11 | I18: 8.75 | J18: 1.77 | K18: 52.24 | L18: 24.88 | M18: 56.93 | N18: 256.4 | O18: 0 | P18: 0.67 | Q18: 12.95
A19: 06/02/2025 11:00 | B19: 8.08 | C19: 25.43 | D19: 21.11 | E19: 12.63 | F19: 24.83 | G19: 60.98 | H19: 21.11 | I19: 8.7 | J19: 1.62 | K19: 55.63 | L19: 26.24 | M19: 49.81 | N19: 307.7 | O19: 0 | P19: 0.67 | Q19: 12.95
A20: 06/02/2025 12:00 | B20: 8.13 | C20: 26.33 | D20: 21.03 | E20: 11.32 | F20: 44.3 | G20: 68.02 | H20: 25.37 | I20: 8.57 | J20: 1.41 | K20: 52.94 | L20: 28.51 | M20: 45.19 | N20: 320.1 | O20: 0 | P20: 0.64 | Q20: 12.96
... A32: 06/02/2025 24:00 | B32: 9.09 | C32: 26.34 | D32: 22.35 | E32: 10.61 | F32: 7.92 | G32: 65.74 | H32: 22.64 | I32: 8.34 | J32: 0.93 | K32: 55.4 | L32: 22.13 | M32: 33 | N32: 1.3 | O32: 0 | P32: 0.68 | Q32: 12.96
A34: Min | B34: =MIN(B9:B32) -> 4.09 | C34: =MIN(C9:C32) -> 23.21 | D34: =MIN(D9:D32) -> 17.06 | E34: =MIN(E9:E32) -> 8.71 | F34: =MIN(F9:F32) -> 3.68 | G34: =MIN(G9:G32) -> 56.76 | H34: =MIN(H9:H32) -> 17.6 | I34: =MIN(I9:I32) -> 7.19 | ... Q34: =MIN(Q9:Q32) -> 12.93
A35: Max | B35: =MAX(B9:B32) -> 18.59 | C35: =MAX(C9:C32) -> 26.72 | D35: =MAX(D9:D32) -> 28.34 | E35: =MAX(E9:E32) -> 13.2 | F35: =MAX(F9:F32) -> 55.67 | G35: =MAX(G9:G32) -> 82.82 | H35: =MAX(H9:H32) -> 31.82 | I35: =MAX(I9:I32) -> 11.62 | ... Q35: =MAX(Q9:Q32) -> 12.99
A36: Avg | B36: =AVERAGE(B9:B32) -> 8.9220833 | C36: =AVERAGE(C9:C32) -> 24.770833 | D36: =AVERAGE(D9:D32) -> 21.317917 | E36: =AVERAGE(E9:E32) -> 10.578333 | F36: =AVERAGE(F9:F32) -> 22.694167 | G36: =AVERAGE(G9:G32) -> 70.17125 | H36: =AVERAGE(H9:H32) -> 24.76625 | I36: =AVERAGE(I9:I32) -> 8.8545833 | ... Q36: =AVERAGE(Q9:Q32) -> 12.957917
A37: Stdev | B37: =STDEV(B9:B32) -> 4.0438552 | C37: =STDEV(C9:C32) -> 0.99212077 | D37: =STDEV(D9:D32) -> 3.1458793 | E37: =STDEV(E9:E32) -> 1.0249185 | F37: =STDEV(F9:F32) -> 19.729078 | G37: =STDEV(G9:G32) -> 8.6116121 | H37: =STDEV(H9:H32) -> 5.3122548 | I37: =STDEV(I9:I32) -> 1.2844183 | ... Q37: =STDEV(Q9:Q32) -> 0.016412924
A38: Num | B38: =COUNT(B9:B32) -> 24 | C38: =COUNT(C9:C32) -> 24 | D38: =COUNT(D9:D32) -> 24 | E38: =COUNT(E9:E32) -> 24 | F38: =COUNT(F9:F32) -> 24 | G38: =COUNT(G9:G32) -> 24 | H38: =COUNT(H9:H32) -> 24 | I38: =COUNT(I9:I32) -> 24 | ... Q38: =COUNT(Q9:Q32) -> 24
A39: DCR | B39: =IF(B38>=22,">90%",IF(B38<=22,"<90%")) -> >90% | C39: =IF(C38>=22,">90%",IF(C38<=22,"<90%")) -> >90% | D39: =IF(D38>=22,">90%",IF(D38<=22,"<90%")) -> >90% | E39: =IF(E38>=22,">90%",IF(E38<=22,"<90%")) -> >90% | F39: =IF(F38>=22,">90%",IF(F38<=22,"<90%")) -> >90% | G39: =IF(G38>=22,">90%",IF(G38<=22,"<90%")) -> >90% | H39: =IF(H38>=22,">90%",IF(H38<=22,"<90%")) -> >90% | I39: =IF(I38>=22,">90%",IF(I38<=22,"<90%")) -> >90% | ... Q39: =IF(Q38>=22,">90%",IF(Q38<=22,"<90%")) -> >90%
A40: Status | B40: =IF(B38>=22,"OK",IF(B38<=22,"LESS")) -> OK | C40: =IF(C38>=22,"OK",IF(C38<=22,"LESS")) -> OK | D40: =IF(D38>=22,"OK",IF(D38<=22,"LESS")) -> OK | E40: =IF(E38>=22,"OK",IF(E38<=22,"LESS")) -> OK | F40: =IF(F38>=22,"OK",IF(F38<=22,"LESS")) -> OK | G40: =IF(G38>=22,"OK",IF(G38<=22,"LESS")) -> OK | H40: =IF(H38>=22,"OK",IF(H38<=22,"LESS")) -> OK | I40: =IF(I38>=22,"OK",IF(I38<=22,"LESS")) -> OK | ... Q40: =IF(Q38>=22,"OK",IF(Q38<=22,"LESS")) -> OK
A43: Done by | B43: AKASH
A45: Comment

Sheet 07
A1: Station: | B1: IGKV ,RAIPUR
A2: Date: | B2: =$A$9 -> 07/02/2025 01:00 | D2: Power Off | G2: Pw.Off | L2: Link Fail | N2: Link F | P2: Maintenance | R2: Maint.
A3: Report Type: | B3: Mean | D3: Calibration | G3: Calib. | L3: Data Fail | N3: Data F | P3: Invalid | R3: Invalid
A4: Time Base: | B4: 01 Hour | D4: Zero Referrence | G4: Z.Ref | L4: Warm Up | N4: Wm. Up
A7: Date & Time | B7: NO | C7: NO2 | D7: NOX | E7: SO2 | F7: O3 | G7: PM 10 | H7: PM 2.5 | I7: BENZ | J7: WS | K7: WD | L7: TEMP | M7: HUM | N7: SR | O7: RG | P7: CO | Q7: NH3
B8: ug/m3 | C8: ug/m3 | D8: ppb | E8: ug/m3 | F8: ug/m3 | G8: ug/m3 | H8: ug/m3 | I8: ug/m3 | J8: m/sec | K8: deg | L8: degreC | M8: % | N8: w/m2 | O8: mm | P8: mg/m3 | Q8: ug/m3
A9: 07/02/2025 01:00 | B9: 9.66 | C9: 26.29 | D9: 22.54 | E9: 9.94 | F9: 4.6 | G9: 65.29 | H9: 20.74 | I9: 7.89 | J9: 0.9 | K9: 58.86 | L9: 21.25 | M9: 34.39 | N9: 1.3 | O9: 0 | P9: 0.66 | Q9: 12.97
A10: 07/02/2025 02:00 | B10: 11.92 | C10: 25.93 | D10: 24.34 | E10: 9.5 | F10: 4.64 | G10: 64.08 | H10: 20.74 | I10: 7.5 | J10: 0.48 | K10: 62.85 | L10: 20.55 | M10: 35.36 | N10: 1.1 | O10: 0 | P10: 0.63 | Q10: 12.98
A11: 07/02/2025 03:00 | B11: 12 | C11: 25.75 | D11: 24.43 | E11: 9.64 | F11: 4.65 | G11: 60.38 | H11: 21.48 | I11: 7.39 | J11: 0.56 | K11: 167.6 | L11: 20.18 | M11: 48.38 | N11: 1.8 | O11: 0 | P11: 0.67 | Q11: 12.97
A12: 07/02/2025 04:00 | B12: 11.46 | C12: 24.06 | D12: 23.11 | E12: 9.12 | F12: 4.66 | G12: 60.38 | H12: 21.48 | I12: 7.28 | J12: 0.17 | K12: 193.44 | L12: 18.36 | M12: 53.67 | N12: 1.3 | O12: 0 | P12: 0.66 | Q12: 12.97
A13: 07/02/2025 05:00 | B13: 10.79 | C13: 22.77 | D13: 21.9 | E13: 8.56 | F13: 4.61 | G13: 55.07 | H13: 18.48 | I13: 6.98 | J13: 0.14 | K13: 178.52 | L13: 17.82 | M13: 55.21 | N13: 1.3 | O13: 0 | P13: 0.64 | Q13: 12.96
A14: 07/02/2025 06:00 | B14: 10.91 | C14: 23.08 | D14: 22.16 | E14: 8.68 | F14: 4.73 | G14: 52.48 | H14: 14.92 | I14: 6.73 | J14: 0.17 | K14: 223.36 | L14: 17.85 | M14: 54.38 | N14: 1.4 | O14: 0 | P14: 0.62 | Q14: 12.95
A15: 07/02/2025 07:00 | B15: 15.5 | C15: 24.38 | D15: 26.52 | E15: 8.07 | F15: 4.69 | G15: 54.89 | H15: 14 | I15: 6.51 | J15: 0.35 | K15: 188.75 | L15: 17.12 | M15: 57.6 | N15: 8.5 | O15: 0 | P15: 0.61 | Q15: 12.97
A16: 07/02/2025 08:00 | B16: 16.5 | C16: 25.05 | D16: 27.61 | E16: 8.64 | F16: 4.63 | G16: 55.86 | H16: 14.56 | I16: 6.78 | J16: 0.58 | K16: 64.16 | L16: 19.33 | M16: 39.79 | N16: 41.9 | O16: 0 | P16: 0.55 | Q16: 13
A17: 07/02/2025 09:00 | B17: 16.05 | C17: 25.64 | D17: 27.44 | E17: 8.3 | F17: 4.72 | G17: 68.54 | H17: 16.63 | I17: 7.17 | J17: 0.72 | K17: 106.83 | L17: 22.71 | M17: 35.59 | N17: 193.9 | O17: 0 | P17: 0.56 | Q17: 13
A18: 07/02/2025 10:00 | B18: 12.83 | C18: 27.1 | D18: 25.24 | E18: 7.84 | F18: 4.9 | G18: 68.54 | H18: 23.02 | I18: 7.26 | J18: 1.16 | K18: 66.17 | L18: 24.16 | M18: 24.87 | N18: 281.8 | O18: 0 | P18: 0.56 | Q18: 12.99
A19: 07/02/2025 11:00 | B19: 11.96 | C19: 28.1 | D19: 25.42 | E19: 8.42 | F19: 5.11 | G19: 61.15 | H19: 24.02 | I19: 7.21 | J19: 1.08 | K19: 66.34 | L19: 26.16 | M19: 23.47 | N19: 330.1 | O19: 0 | P19: 0.55 | Q19: 12.98
A20: 07/02/2025 12:00 | B20: 12.56 | C20: 28.87 | D20: 26.5 | E20: 8.94 | F20: 5.37 | G20: 61.27 | H20: 26.41 | I20: 7.12 | J20: 1.21 | K20: 61.78 | L20: 28.1 | M20: 17.44 | N20: 343.9 | O20: 0 | P20: 0.54 | Q20: 13
... A32: 07/02/2025 24:00 | B32: 30.41 | C32: 28.41 | D32: 40.44 | E32: 10.46 | F32: 4.63 | G32: 113.32 | H32: 29.57 | I32: 18.55 | J32: 0.22 | K32: 224.06 | L32: 19.92 | M32: 62.46 | N32: 1.3 | O32: 0 | P32: 1.12 | Q32: 13.06
A34: Min | B34: =MIN(B9:B32) -> 8.39 | C34: =MIN(C9:C32) -> 22.77 | D34: =MIN(D9:D32) -> 21.9 | E34: =MIN(E9:E32) -> 7.84 | F34: =MIN(F9:F32) -> 4.39 | G34: =MIN(G9:G32) -> 52.48 | H34: =MIN(H9:H32) -> 14 | I34: =MIN(I9:I32) -> 6.37 | ... Q34: =MIN(Q9:Q32) -> 12.95
A35: Max | B35: =MAX(B9:B32) -> 30.41 | C35: =MAX(C9:C32) -> 31.13 | D35: =MAX(D9:D32) -> 40.44 | E35: =MAX(E9:E32) -> 37.35 | F35: =MAX(F9:F32) -> 9.61 | G35: =MAX(G9:G32) -> 169.27 | H35: =MAX(H9:H32) -> 40.15 | I35: =MAX(I9:I32) -> 19.03 | ... Q35: =MAX(Q9:Q32) -> 13.06
A36: Avg | B36: =AVERAGE(B9:B32) -> 14.182083 | C36: =AVERAGE(C9:C32) -> 26.890833 | D36: =AVERAGE(D9:D32) -> 26.610833 | E36: =AVERAGE(E9:E32) -> 11.139167 | F36: =AVERAGE(F9:F32) -> 5.4804167 | G36: =AVERAGE(G9:G32) -> 80.76375 | H36: =AVERAGE(H9:H32) -> 25.991667 | I36: =AVERAGE(I9:I32) -> 9.13875 | ... Q36: =AVERAGE(Q9:Q32) -> 12.99
A37: Stdev | B37: =STDEV(B9:B32) -> 5.3607973 | C37: =STDEV(C9:C32) -> 2.6006152 | D37: =STDEV(D9:D32) -> 5.0229741 | E37: =STDEV(E9:E32) -> 6.6068324 | F37: =STDEV(F9:F32) -> 1.5547305 | G37: =STDEV(G9:G32) -> 37.099716 | H37: =STDEV(H9:H32) -> 7.7149638 | I37: =STDEV(I9:I32) -> 4.3989854 | ... Q37: =STDEV(Q9:Q32) -> 0.029042697
A38: Num | B38: =COUNT(B9:B32) -> 24 | C38: =COUNT(C9:C32) -> 24 | D38: =COUNT(D9:D32) -> 24 | E38: =COUNT(E9:E32) -> 24 | F38: =COUNT(F9:F32) -> 24 | G38: =COUNT(G9:G32) -> 24 | H38: =COUNT(H9:H32) -> 24 | I38: =COUNT(I9:I32) -> 24 | ... Q38: =COUNT(Q9:Q32) -> 24
A39: DCR | B39: =IF(B38>=22,">90%",IF(B38<=22,"<90%")) -> >90% | C39: =IF(C38>=22,">90%",IF(C38<=22,"<90%")) -> >90% | D39: =IF(D38>=22,">90%",IF(D38<=22,"<90%")) -> >90% | E39: =IF(E38>=22,">90%",IF(E38<=22,"<90%")) -> >90% | F39: =IF(F38>=22,">90%",IF(F38<=22,"<90%")) -> >90% | G39: =IF(G38>=22,">90%",IF(G38<=22,"<90%")) -> >90% | H39: =IF(H38>=22,">90%",IF(H38<=22,"<90%")) -> >90% | I39: =IF(I38>=22,">90%",IF(I38<=22,"<90%")) -> >90% | ... Q39: =IF(Q38>=22,">90%",IF(Q38<=22,"<90%")) -> >90%
A40: Status | B40: =IF(B38>=22,"OK",IF(B38<=22,"LESS")) -> OK | C40: =IF(C38>=22,"OK",IF(C38<=22,"LESS")) -> OK | D40: =IF(D38>=22,"OK",IF(D38<=22,"LESS")) -> OK | E40: =IF(E38>=22,"OK",IF(E38<=22,"LESS")) -> OK | F40: =IF(F38>=22,"OK",IF(F38<=22,"LESS")) -> OK | G40: =IF(G38>=22,"OK",IF(G38<=22,"LESS")) -> OK | H40: =IF(H38>=22,"OK",IF(H38<=22,"LESS")) -> OK | I40: =IF(I38>=22,"OK",IF(I38<=22,"LESS")) -> OK | ... Q40: =IF(Q38>=22,"OK",IF(Q38<=22,"LESS")) -> OK
A43: Done by | B43: AKASH
A45: Comment

Sheet 08
A1: Station: | B1: IGKV ,RAIPUR
A2: Date: | B2: =$A$9 -> 08/02/2025 01:00 | D2: Power Off | G2: Pw.Off | L2: Link Fail | N2: Link F | P2: Maintenance | R2: Maint.
A3: Report Type: | B3: Mean | D3: Calibration | G3: Calib. | L3: Data Fail | N3: Data F | P3: Invalid | R3: Invalid
A4: Time Base: | B4: 01 Hour | D4: Zero Referrence | G4: Z.Ref | L4: Warm Up | N4: Wm. Up
A7: Date & Time | B7: NO | C7: NO2 | D7: NOX | E7: SO2 | F7: O3 | G7: PM 10 | H7: PM 2.5 | I7: BENZ | J7: WS | K7: WD | L7: TEMP | M7: HUM | N7: SR | O7: RG | P7: CO | Q7: NH3
B8: ug/m3 | C8: ug/m3 | D8: ppb | E8: ug/m3 | F8: ug/m3 | G8: ug/m3 | H8: ug/m3 | I8: ug/m3 | J8: m/sec | K8: deg | L8: degreC | M8: % | N8: w/m2 | O8: mm | P8: mg/m3 | Q8: ug/m3
A9: 08/02/2025 01:00 | B9: 32.91 | C9: 28.02 | D9: 42.22 | E9: 10.03 | F9: 4 | G9: 112.24 | H9: 29.57 | I9: 17.99 | J9: 0.25 | K9: 181.46 | L9: 19.67 | M9: 67.84 | N9: 1.6 | O9: 0 | P9: 1.12 | Q9: 13.07
A10: 08/02/2025 02:00 | B10: 32.71 | C10: 27.21 | D10: 41.79 | E10: 9.92 | F10: 4.22 | G10: 96.59 | H10: 27.39 | I10: 17.25 | J10: 0.22 | K10: 214.45 | L10: 18.71 | M10: 71.73 | N10: 1.5 | O10: 0 | P10: 1.12 | Q10: 13.06
A11: 08/02/2025 03:00 | B11: 31.28 | C11: 25.86 | D11: 39.95 | E11: 10 | F11: 4.37 | G11: 94.34 | H11: 23.12 | I11: 16.51 | J11: 0.36 | K11: 217.53 | L11: 18.27 | M11: 71.67 | N11: 1.2 | O11: 0 | P11: 1.11 | Q11: 13.05
A12: 08/02/2025 04:00 | B12: 30.19 | C12: 25.79 | D12: 38.81 | E12: 10.68 | F12: 6.67 | G12: 81.95 | H12: 22.84 | I12: 15.92 | J12: 0.66 | K12: 50.89 | L12: 19.28 | M12: 57.54 | N12: 1.2 | O12: 0 | P12: 0.97 | Q12: 13.06
A13: 08/02/2025 05:00 | B13: 28.53 | C13: 25.7 | D13: 37.66 | E13: 10.34 | F13: 3.97 | G13: 81.95 | H13: 22.21 | I13: 15.29 | J13: 0.49 | K13: 69.85 | L13: 18.83 | M13: 60.87 | N13: 1.4 | O13: 0 | P13: 0.9 | Q13: 13.04
A14: 08/02/2025 06:00 | B14: 27.28 | C14: 26.08 | D14: 36.55 | E14: 10.29 | F14: 4.09 | G14: 90.16 | H14: 21.72 | I14: 14.38 | J14: 0.68 | K14: 102.83 | L14: 18.69 | M14: 54.14 | N14: 1.5 | O14: 0 | P14: 0.86 | Q14: 13.05
A15: 08/02/2025 07:00 | B15: 25.75 | C15: 26.11 | D15: 35.64 | E15: 10.22 | F15: 4.25 | G15: 90.16 | H15: 19.81 | I15: 14.13 | J15: 0.39 | K15: 170.74 | L15: 18.04 | M15: 62.73 | N15: 8.9 | O15: 0 | P15: 0.81 | Q15: 13.04
A16: 08/02/2025 08:00 | B16: 25.33 | C16: 26.74 | D16: 35.59 | E16: 10.33 | F16: 7.74 | G16: 90.79 | H16: 22.06 | I16: 14.2 | J16: 0.56 | K16: 83.18 | L16: 19.2 | M16: 54.83 | N16: 41.4 | O16: 0 | P16: 0.82 | Q16: 13.02
A17: 08/02/2025 09:00 | B17: 24.83 | C17: 27.39 | D17: 35.47 | E17: 10.14 | F17: 12.62 | G17: 92.98 | H17: 25.04 | I17: 15.86 | J17: 0.74 | K17: 64.77 | L17: 22.41 | M17: 42.47 | N17: 202.7 | O17: 0 | P17: 0.85 | Q17: 13.04
A18: 08/02/2025 10:00 | B18: 21.92 | C18: 27.13 | D18: 33.09 | E18: 10.27 | F18: 15.36 | G18: 92.98 | H18: 25.04 | I18: 15.76 | J18: 1.13 | K18: 67.76 | L18: 24.86 | M18: 31.02 | N18: 290.5 | O18: 0 | P18: 0.83 | Q18: 13.03
A19: 08/02/2025 11:00 | B19: 21.49 | C19: 26.64 | D19: 32.33 | E19: 12.04 | F19: 27.25 | G19: 72.48 | H19: 24.9 | I19: 14.49 | J19: 1.21 | K19: 58.57 | L19: 26.94 | M19: 25.52 | N19: 342.3 | O19: 0 | P19: 0.79 | Q19: 13.01
A20: 08/02/2025 12:00 | B20: 18.69 | C20: 26.09 | D20: 29.97 | E20: 12.03 | F20: 38.63 | G20: 75.97 | H20: 26.14 | I20: 13.38 | J20: 0.81 | K20: 341.83 | L20: 28.69 | M20: 22.05 | N20: 353.8 | O20: 0 | P20: 0.75 | Q20: 13.02
... A32: 08/02/2025 24:00 | B32: 25 | C32: 27.45 | D32: 35.74 | E32: 11.85 | F32: 3.75 | G32: 140.65 | H32: 26.82 | I32: 12.91 | J32: 0.29 | K32: 117.12 | L32: 20.13 | M32: 47 | N32: 0.9 | O32: 0 | P32: 0.94 | Q32: 13.04
A34: Min | B34: =MIN(B9:B32) -> 4.03 | C34: =MIN(C9:C32) -> 24.78 | D34: =MIN(D9:D32) -> 18.93 | E34: =MIN(E9:E32) -> 9.92 | F34: =MIN(F9:F32) -> 3.58 | G34: =MIN(G9:G32) -> 60.9 | H34: =MIN(H9:H32) -> 19.81 | I34: =MIN(I9:I32) -> 8.45 | ... Q34: =MIN(Q9:Q32) -> 12.96
A35: Max | B35: =MAX(B9:B32) -> 32.91 | C35: =MAX(C9:C32) -> 28.19 | D35: =MAX(D9:D32) -> 42.22 | E35: =MAX(E9:E32) -> 17.99 | F35: =MAX(F9:F32) -> 46.53 | G35: =MAX(G9:G32) -> 140.65 | H35: =MAX(H9:H32) -> 30.23 | I35: =MAX(I9:I32) -> 17.99 | ... Q35: =MAX(Q9:Q32) -> 13.07
A36: Avg | B36: =AVERAGE(B9:B32) -> 19.378333 | C36: =AVERAGE(C9:C32) -> 26.614167 | D36: =AVERAGE(D9:D32) -> 30.6525 | E36: =AVERAGE(E9:E32) -> 11.76375 | F36: =AVERAGE(F9:F32) -> 18.939583 | G36: =AVERAGE(G9:G32) -> 88.63125 | H36: =AVERAGE(H9:H32) -> 26.160833 | I36: =AVERAGE(I9:I32) -> 13.16375 | ... Q36: =AVERAGE(Q9:Q32) -> 13.0125
A37: Stdev | B37: =STDEV(B9:B32) -> 9.4654101 | C37: =STDEV(C9:C32) -> 0.99310631 | D37: =STDEV(D9:D32) -> 7.5721792 | E37: =STDEV(E9:E32) -> 2.1485664 | F37: =STDEV(F9:F32) -> 16.207201 | G37: =STDEV(G9:G32) -> 18.98959 | H37: =STDEV(H9:H32) -> 3.04796 | I37: =STDEV(I9:I32) -> 2.7759069 | ... Q37: =STDEV(Q9:Q32) -> 0.036623822
A38: Num | B38: =COUNT(B9:B32) -> 24 | C38: =COUNT(C9:C32) -> 24 | D38: =COUNT(D9:D32) -> 24 | E38: =COUNT(E9:E32) -> 24 | F38: =COUNT(F9:F32) -> 24 | G38: =COUNT(G9:G32) -> 24 | H38: =COUNT(H9:H32) -> 24 | I38: =COUNT(I9:I32) -> 24 | ... Q38: =COUNT(Q9:Q32) -> 24
A39: DCR | B39: =IF(B38>=22,">90%",IF(B38<=22,"<90%")) -> >90% | C39: =IF(C38>=22,">90%",IF(C38<=22,"<90%")) -> >90% | D39: =IF(D38>=22,">90%",IF(D38<=22,"<90%")) -> >90% | E39: =IF(E38>=22,">90%",IF(E38<=22,"<90%")) -> >90% | F39: =IF(F38>=22,">90%",IF(F38<=22,"<90%")) -> >90% | G39: =IF(G38>=22,">90%",IF(G38<=22,"<90%")) -> >90% | H39: =IF(H38>=22,">90%",IF(H38<=22,"<90%")) -> >90% | I39: =IF(I38>=22,">90%",IF(I38<=22,"<90%")) -> >90% | ... Q39: =IF(Q38>=22,">90%",IF(Q38<=22,"<90%")) -> >90%
A40: Status | B40: =IF(B38>=22,"OK",IF(B38<=22,"LESS")) -> OK | C40: =IF(C38>=22,"OK",IF(C38<=22,"LESS")) -> OK | D40: =IF(D38>=22,"OK",IF(D38<=22,"LESS")) -> OK | E40: =IF(E38>=22,"OK",IF(E38<=22,"LESS")) -> OK | F40: =IF(F38>=22,"OK",IF(F38<=22,"LESS")) -> OK | G40: =IF(G38>=22,"OK",IF(G38<=22,"LESS")) -> OK | H40: =IF(H38>=22,"OK",IF(H38<=22,"LESS")) -> OK | I40: =IF(I38>=22,"OK",IF(I38<=22,"LESS")) -> OK | ... Q40: =IF(Q38>=22,"OK",IF(Q38<=22,"LESS")) -> OK
A43: Done by | B43: AKASH
A45: Comment

Sheet 09
A1: Station: | B1: IGKV ,RAIPUR
A2: Date: | B2: =$A$9 -> 09/02/2025 01:00 | D2: Power Off | G2: Pw.Off | L2: Link Fail | N2: Link F | P2: Maintenance | R2: Maint.
A3: Report Type: | B3: Mean | D3: Calibration | G3: Calib. | L3: Data Fail | N3: Data F | P3: Invalid | R3: Invalid
A4: Time Base: | B4: 01 Hour | D4: Zero Referrence | G4: Z.Ref | L4: Warm Up | N4: Wm. Up
A7: Date & Time | B7: NO | C7: NO2 | D7: NOX | E7: SO2 | F7: O3 | G7: PM 10 | H7: PM 2.5 | I7: BENZ | J7: WS | K7: WD | L7: TEMP | M7: HUM | N7: SR | O7: RG | P7: CO | Q7: NH3
B8: ug/m3 | C8: ug/m3 | D8: ppb | E8: ug/m3 | F8: ug/m3 | G8: ug/m3 | H8: ug/m3 | I8: ug/m3 | J8: m/sec | K8: deg | L8: degreC | M8: % | N8: w/m2 | O8: mm | P8: mg/m3 | Q8: ug/m3
A9: 09/02/2025 01:00 | B9: 26.58 | C9: 28.42 | D9: 37.51 | E9: 11.54 | F9: 4.37 | G9: 142.42 | H9: 29.96 | I9: 12.44 | J9: 0.34 | K9: 105.17 | L9: 19.56 | M9: 44.58 | N9: 1 | O9: 0 | P9: 0.89 | Q9: 13.05
A10: 09/02/2025 02:00 | B10: 26.73 | C10: 28.59 | D10: 37.67 | E10: 11.8 | F10: 4.92 | G10: 151.03 | H10: 29.96 | I10: 11.63 | J10: 0.42 | K10: 80.21 | L10: 19.32 | M10: 42.25 | N10: 0.9 | O10: 0 | P10: 0.83 | Q10: 13.05
A11: 09/02/2025 03:00 | B11: 25.68 | C11: 28.47 | D11: 36.8 | E11: 10.87 | F11: 3.97 | G11: 151.03 | H11: 27.41 | I11: 10.84 | J11: 0.19 | K11: 178.37 | L11: 18.59 | M11: 59.62 | N11: 1.6 | O11: 0 | P11: 0.77 | Q11: 13.04
A12: 09/02/2025 04:00 | B12: 28.84 | C12: 28.79 | D12: 39.53 | E12: 11.06 | F12: 3.69 | G12: 147.39 | H12: 26.51 | I12: 10.26 | J12: 0.23 | K12: 165.41 | L12: 16.86 | M12: 59.88 | N12: 1.1 | O12: 0 | P12: 0.79 | Q12: 13.04
A13: 09/02/2025 05:00 | B13: 29.01 | C13: 28.71 | D13: 39.62 | E13: 10.7 | F13: 3.63 | G13: 136.66 | H13: 23.62 | I13: 9.84 | J13: 0.2 | K13: 207.78 | L13: 15.31 | M13: 73.69 | N13: 1.3 | O13: 0 | P13: 0.78 | Q13: 13.05
A14: 09/02/2025 06:00 | B14: 25.81 | C14: 26.27 | D14: 35.77 | E14: 9.85 | F14: 3.67 | G14: 113.75 | H14: 20.09 | I14: 9.38 | J14: 0.18 | K14: 216.06 | L14: 13.87 | M14: 77.17 | N14: 1 | O14: 0 | P14: 0.75 | Q14: 13.03
A15: 09/02/2025 07:00 | B15: 21.99 | C15: 24.59 | D15: 31.83 | E15: 9.31 | F15: 3.73 | G15: 101.29 | H15: 17.76 | I15: 9.04 | J15: 0.19 | K15: 180.47 | L15: 13.38 | M15: 77.65 | N15: 7.4 | O15: 0 | P15: 0.73 | Q15: 13.03
A16: 09/02/2025 08:00 | B16: 19.23 | C16: 23.1 | D16: 28.84 | E16: 9.5 | F16: 8.22 | G16: 81.01 | H16: 17.17 | I16: 8.85 | J16: 0.11 | K16: 172.93 | L16: 16.34 | M16: 78.38 | N16: 31 | O16: 0 | P16: 0.78 | Q16: 13
A17: 09/02/2025 09:00 | B17: 17.71 | C17: 25.69 | D17: 28 | E17: 9.71 | F17: 17.33 | G17: 78.91 | H17: 20.02 | I17: 9.41 | J17: 0.85 | K17: 143.74 | L17: 22.22 | M17: 50.72 | N17: 264.1 | O17: 0 | P17: 0.76 | Q17: 13.02
A18: 09/02/2025 10:00 | B18: 14.26 | C18: 27.02 | D18: 26.54 | E18: 10.44 | F18: 36.35 | G18: 77.04 | H18: 26.97 | I18: 10.16 | J18: 0.57 | K18: 97.96 | L18: 26.06 | M18: 27.53 | N18: 363.6 | O18: 0 | P18: 0.73 | Q18: 13
A19: 09/02/2025 11:00 | B19: 8.42 | C19: 26.99 | D19: 22.21 | E19: 10.43 | F19: 42.51 | G19: 73.48 | H19: 33.18 | I19: 10.2 | J19: 0.75 | K19: 74.98 | L19: 28.26 | M19: 21.98 | N19: 397.5 | O19: 0 | P19: 0.69 | Q19: 12.98
A20: 09/02/2025 12:00 | B20: 4.67 | C20: 26.53 | D20: 18.95 | E20: 10.54 | F20: 56.17 | G20: 63.76 | H20: 33.18 | I20: 9.93 | J20: 1.01 | K20: 81.39 | L20: 29.77 | M20: 17.82 | N20: 401.1 | O20: 0 | P20: 0.68 | Q20: 12.98
... A32: 09/02/2025 24:00 | B32: 20.43 | C32: 24.43 | D32: 30.37 | E32: 11.88 | F32: 11.84 | G32: 67.56 | H32: 21.89 | I32: 9.18 | J32: 0.24 | K32: 195.2 | L32: 18.07 | M32: 65.41 | N32: 1.3 | O32: 0 | P32: 0.78 | Q32: 13.01
A34: Min | B34: =MIN(B9:B32) -> 3.94 | C34: =MIN(C9:C32) -> 17.98 | D34: =MIN(D9:D32) -> 14.21 | E34: =MIN(E9:E32) -> 9.31 | F34: =MIN(F9:F32) -> 3.63 | G34: =MIN(G9:G32) -> 39.47 | H34: =MIN(H9:H32) -> 17.17 | I34: =MIN(I9:I32) -> 6.59 | ... Q34: =MIN(Q9:Q32) -> 12.92
A35: Max | B35: =MAX(B9:B32) -> 29.01 | C35: =MAX(C9:C32) -> 28.79 | D35: =MAX(D9:D32) -> 39.62 | E35: =MAX(E9:E32) -> 28.88 | F35: =MAX(F9:F32) -> 79.87 | G35: =MAX(G9:G32) -> 151.03 | H35: =MAX(H9:H32) -> 33.18 | I35: =MAX(I9:I32) -> 12.44 | ... Q35: =MAX(Q9:Q32) -> 13.05
A36: Avg | B36: =AVERAGE(B9:B32) -> 13.967083 | C36: =AVERAGE(C9:C32) -> 23.74375 | D36: =AVERAGE(D9:D32) -> 24.87 | E36: =AVERAGE(E9:E32) -> 12.494167 | F36: =AVERAGE(F9:F32) -> 31.611667 | G36: =AVERAGE(G9:G32) -> 82.554167 | H36: =AVERAGE(H9:H32) -> 25.177083 | I36: =AVERAGE(I9:I32) -> 8.97 | ... Q36: =AVERAGE(Q9:Q32) -> 12.987917
A37: Stdev | B37: =STDEV(B9:B32) -> 9.6965863 | C37: =STDEV(C9:C32) -> 3.8738957 | D37: =STDEV(D9:D32) -> 9.4252492 | E37: =STDEV(E9:E32) -> 4.9756231 | F37: =STDEV(F9:F32) -> 26.941382 | G37: =STDEV(G9:G32) -> 37.092771 | H37: =STDEV(H9:H32) -> 4.7207732 | I37: =STDEV(I9:I32) -> 1.5991384 | ... Q37: =STDEV(Q9:Q32) -> 0.04413213
A38: Num | B38: =COUNT(B9:B32) -> 24 | C38: =COUNT(C9:C32) -> 24 | D38: =COUNT(D9:D32) -> 24 | E38: =COUNT(E9:E32) -> 24 | F38: =COUNT(F9:F32) -> 24 | G38: =COUNT(G9:G32) -> 24 | H38: =COUNT(H9:H32) -> 24 | I38: =COUNT(I9:I32) -> 24 | ... Q38: =COUNT(Q9:Q32) -> 24
A39: DCR | B39: =IF(B38>=22,">90%",IF(B38<=22,"<90%")) -> >90% | C39: =IF(C38>=22,">90%",IF(C38<=22,"<90%")) -> >90% | D39: =IF(D38>=22,">90%",IF(D38<=22,"<90%")) -> >90% | E39: =IF(E38>=22,">90%",IF(E38<=22,"<90%")) -> >90% | F39: =IF(F38>=22,">90%",IF(F38<=22,"<90%")) -> >90% | G39: =IF(G38>=22,">90%",IF(G38<=22,"<90%")) -> >90% | H39: =IF(H38>=22,">90%",IF(H38<=22,"<90%")) -> >90% | I39: =IF(I38>=22,">90%",IF(I38<=22,"<90%")) -> >90% | ... Q39: =IF(Q38>=22,">90%",IF(Q38<=22,"<90%")) -> >90%
A40: Status | B40: =IF(B38>=22,"OK",IF(B38<=22,"LESS")) -> OK | C40: =IF(C38>=22,"OK",IF(C38<=22,"LESS")) -> OK | D40: =IF(D38>=22,"OK",IF(D38<=22,"LESS")) -> OK | E40: =IF(E38>=22,"OK",IF(E38<=22,"LESS")) -> OK | F40: =IF(F38>=22,"OK",IF(F38<=22,"LESS")) -> OK | G40: =IF(G38>=22,"OK",IF(G38<=22,"LESS")) -> OK | H40: =IF(H38>=22,"OK",IF(H38<=22,"LESS")) -> OK | I40: =IF(I38>=22,"OK",IF(I38<=22,"LESS")) -> OK | ... Q40: =IF(Q38>=22,"OK",IF(Q38<=22,"LESS")) -> OK
A43: Done by | B43: AKASH
A45: Comment

Sheet 10
A1: Station: | B1: IGKV ,RAIPUR
A2: Date: | B2: =$A$9 -> 10/02/2025 01:00 | D2: Power Off | G2: Pw.Off | L2: Link Fail | N2: Link F | P2: Maintenance | R2: Maint.
A3: Report Type: | B3: Mean | D3: Calibration | G3: Calib. | L3: Data Fail | N3: Data F | P3: Invalid | R3: Invalid
A4: Time Base: | B4: 01 Hour | D4: Zero Referrence | G4: Z.Ref | L4: Warm Up | N4: Wm. Up
A7: Date & Time | B7: NO | C7: NO2 | D7: NOX | E7: SO2 | F7: O3 | G7: PM 10 | H7: PM 2.5 | I7: BENZ | J7: WS | K7: WD | L7: TEMP | M7: HUM | N7: SR | O7: RG | P7: CO | Q7: NH3
