Workbook

Sheet 01
A1: Station: | B1: BHATAGAON RAIPUR
A2: Date: | B2: =$A$9 -> 01/07/2024 00:15 | D2: Power Off | G2: Pw.Off | L2: Link Fail | N2: Link F | P2: Maintenance | R2: Maint.
A3: Report Type: | B3: Mean | D3: Calibration | G3: Calib. | L3: Data Fail | N3: Data F | P3: Invalid | R3: Invalid
A4: Time Base: | B4: 15 Min | D4: Zero Referrence | G4: Z.Ref | L4: Warm Up | N4: Wm. Up
A7: Date & Time | B7: NO_BHATAGAON | C7: NO2__BHATAGAON | D7: NOX_BHATAGAON | E7: SO2__BHATAGAON | F7: O3__BHATAGAON | G7: PM10__BHATAGAON | H7: PM2_5__BHATAGAON | I7: BENZ__BHATAGAON | J7: WS__BHATAGAON | K7: WD__BHATAGAON | L7: TEMP__BHATAGAON | M7: HUM__BHATAGAON | N7: SR__BHATAGAON | O7: RG__BHATAGAON | P7: CO__BHATAGAON | Q7: NH3__BHATAGAON
B8: ug/m3 | C8: ug/m3 | D8: ppb | E8: ug/m3 | F8: ug/m3 | G8: ug/m3 | H8: ug/m3 | I8: ug/m3 | J8: m/sec | K8: deg | L8: degreC | M8: % | N8: w/m2 | O8: mm | P8: mg/m3 | Q8: ug/m3
A9: 01/07/2024 00:15 | B9: 8.32 | C9: 3.2 | D9: 12.12 | E9: 2.93 | F9: 3.09 | G9: 18.96 | H9: 6.68 | I9: 4.94 | J9: 1.19 | K9: 149.93 | L9: 22.86 | M9: 98.38 | N9: 17.3 | O9: 0 | P9: 0.34 | Q9: 9.29
A10: 01/07/2024 00:30 | B10: 8.37 | C10: 3.26 | D10: 12.19 | E10: 2.91 | F10: 4.2 | G10: 18.96 | H10: 6.68 | I10: 4.81 | J10: 1.51 | K10: 147.47 | L10: 22.88 | M10: 98.39 | N10: 17.2 | O10: 0 | P10: 0.35 | Q10: 9.32
A11: 01/07/2024 00:45 | B11: 8.34 | C11: 3.25 | D11: 12.16 | E11: 3.36 | F11: 2.89 | G11: 20.77 | H11: 6.66 | I11: 4.68 | J11: 1.64 | K11: 143.01 | L11: 22.95 | M11: 98.39 | N11: 17.1 | O11: 0 | P11: 0.33 | Q11: 9.32
A12: 01/07/2024 01:00 | B12: 8.31 | C12: 3.19 | D12: 12.1 | E12: 3.61 | F12: 3 | G12: 21.93 | H12: 6.65 | I12: 4.66 | J12: 1.56 | K12: 143.98 | L12: 23.06 | M12: 98.36 | N12: 17.5 | O12: 0 | P12: 0.31 | Q12: 9.31
A13: 01/07/2024 01:15 | B13: 8.3 | C13: 3.15 | D13: 12.08 | E13: 3.48 | F13: 4.13 | G13: 21.93 | H13: 6.65 | I13: 4.69 | J13: 1.06 | K13: 141.07 | L13: 23.13 | M13: 98.35 | N13: 17.7 | O13: 0 | P13: 0.37 | Q13: 9.3
A14: 01/07/2024 01:30 | B14: 8.35 | C14: 3.2 | D14: 12.14 | E14: 3.51 | F14: 2.45 | G14: 21.93 | H14: 6.65 | I14: 4.67 | J14: 0.72 | K14: 169.96 | L14: 23.16 | M14: 98.35 | N14: 17.8 | O14: 0 | P14: 0.36 | Q14: 9.27
A15: 01/07/2024 01:45 | B15: 8.34 | C15: 3.23 | D15: 12.15 | E15: 3.38 | F15: 3.16 | G15: 19.94 | H15: 5.64 | I15: 4.6 | J15: 0.34 | K15: 168.79 | L15: 23.14 | M15: 98.35 | N15: 17.8 | O15: 0 | P15: 0.35 | Q15: 9.29
A16: 01/07/2024 02:00 | B16: 8.33 | C16: 3.2 | D16: 12.13 | E16: 2.93 | F16: 3.5 | G16: 18.68 | H16: 5 | I16: 4.49 | J16: 0.51 | K16: 154.47 | L16: 23.21 | M16: 98.35 | N16: 17.9 | O16: 0 | P16: 0.34 | Q16: 9.31
A17: 01/07/2024 02:15 | B17: 8.32 | C17: 3.21 | D17: 12.13 | E17: 2.88 | F17: 3.66 | G17: 18.68 | H17: 5 | I17: 4.45 | J17: 0.37 | K17: 194.8 | L17: 23.33 | M17: 98.35 | N17: 18 | O17: 0 | P17: 0.34 | Q17: 9.3
A18: 01/07/2024 02:30 | B18: 8.34 | C18: 3.25 | D18: 12.15 | E18: 3.22 | F18: 3.63 | G18: 18.68 | H18: 5 | I18: 4.43 | J18: 0.29 | K18: 189.52 | L18: 23.41 | M18: 98.34 | N18: 18.1 | O18: 0 | P18: 0.34 | Q18: 9.3
A19: 01/07/2024 02:45 | B19: 8.37 | C19: 3.31 | D19: 12.21 | E19: 3.07 | F19: 3.44 | G19: 18.5 | H19: 5.41 | I19: 4.35 | J19: 0.17 | K19: 27.47 | L19: 23.45 | M19: 98.33 | N19: 17.8 | O19: 0 | P19: 0.33 | Q19: 9.31
A20: 01/07/2024 03:00 | B20: 8.39 | C20: 3.33 | D20: 12.24 | E20: 3.15 | F20: 3.68 | G20: 18.39 | H20: 5.68 | I20: 4.25 | J20: 0.39 | K20: 351.46 | L20: 23.53 | M20: 98.32 | N20: 17.7 | O20: 0 | P20: 0.32 | Q20: 9.35
... A104: 01/07/2024 24:00 | B104: 8.17 | C104: 3.19 | D104: 12 | E104: 3.2 | F104: 3.55 | G104: 30.39 | H104: 7.68 | I104: 3.95 | J104: 0.14 | K104: 300.54 | L104: 23.75 | M104: 98.33 | N104: 18.1 | O104: 0 | P104: 0.4 | Q104: 9.39
A106: Min | B106: =MIN(B9:B104) -> 8.12 | C106: =MIN(C9:C104) -> 3.08 | D106: =MIN(D9:D104) -> 11.92 | E106: =MIN(E9:E104) -> 2.78 | F106: =MIN(F9:F104) -> 2.39 | G106: =MIN(G9:G104) -> 14.64 | H106: =MIN(H9:H104) -> 3.46 | I106: =MIN(I9:I104) -> 1.04 | ... Q106: =MIN(Q9:Q104) -> 9.18
A107: Max | B107: =MAX(B9:B104) -> 8.41 | C107: =MAX(C9:C104) -> 3.56 | D107: =MAX(D9:D104) -> 12.37 | E107: =MAX(E9:E104) -> 4.97 | F107: =MAX(F9:F104) -> 8.31 | G107: =MAX(G9:G104) -> 54.4 | H107: =MAX(H9:H104) -> 14.09 | I107: =MAX(I9:I104) -> 4.94 | ... Q107: =MAX(Q9:Q104) -> 9.4
A108: Avg | B108: =AVERAGE(B9:B104) -> 8.2598958 | C108: =AVERAGE(C9:C104) -> 3.2446875 | D108: =AVERAGE(D9:D104) -> 12.093229 | E108: =AVERAGE(E9:E104) -> 3.9110417 | F108: =AVERAGE(F9:F104) -> 4.1796875 | G108: =AVERAGE(G9:G104) -> 27.276563 | H108: =AVERAGE(H9:H104) -> 8.4948958 | I108: =AVERAGE(I9:I104) -> 2.4802083 | ... Q108: =AVERAGE(Q9:Q104) -> 9.2879167
A109: Stdev | B109: =STDEV(B9:B104) -> 0.06864853 | C109: =STDEV(C9:C104) -> 0.084154659 | D109: =STDEV(D9:D104) -> 0.084747238 | E109: =STDEV(E9:E104) -> 0.61356161 | F109: =STDEV(F9:F104) -> 1.2181724 | G109: =STDEV(G9:G104) -> 10.601917 | H109: =STDEV(H9:H104) -> 3.3230411 | I109: =STDEV(I9:I104) -> 1.2439902 | ... Q109: =STDEV(Q9:Q104) -> 0.061505955
A110: Num | B110: =COUNT(B9:B104) -> 96 | C110: =COUNT(C9:C104) -> 96 | D110: =COUNT(D9:D104) -> 96 | E110: =COUNT(E9:E104) -> 96 | F110: =COUNT(F9:F104) -> 96 | G110: =COUNT(G9:G104) -> 96 | H110: =COUNT(H9:H104) -> 96 | I110: =COUNT(I9:I104) -> 96 | ... Q110: =COUNT(Q9:Q104) -> 96
A111: DCR | B111: =IF(B110>=87,">90%",IF(B110<=87,"<90%")) -> >90% | C111: =IF(C110>=87,">90%",IF(C110<=87,"<90%")) -> >90% | D111: =IF(D110>=87,">90%",IF(D110<=87,"<90%")) -> >90% | E111: =IF(E110>=87,">90%",IF(E110<=87,"<90%")) -> >90% | F111: =IF(F110>=87,">90%",IF(F110<=87,"<90%")) -> >90% | G111: =IF(G110>=87,">90%",IF(G110<=87,"<90%")) -> >90% | H111: =IF(H110>=87,">90%",IF(H110<=87,"<90%")) -> >90% | I111: =IF(I110>=87,">90%",IF(I110<=87,"<90%")) -> >90% | ... Q111: =IF(Q110>=87,">90%",IF(Q110<=87,"<90%")) -> >90%
A112: Status | B112: =IF(B110>=87,"OK",IF(B110<=87,"LESS")) -> OK | C112: =IF(C110>=87,"OK",IF(C110<=87,"LESS")) -> OK | D112: =IF(D110>=87,"OK",IF(D110<=87,"LESS")) -> OK | E112: =IF(E110>=87,"OK",IF(E110<=87,"LESS")) -> OK | F112: =IF(F110>=87,"OK",IF(F110<=87,"LESS")) -> OK | G112: =IF(G110>=87,"OK",IF(G110<=87,"LESS")) -> OK | H112: =IF(H110>=87,"OK",IF(H110<=87,"LESS")) -> OK | I112: =IF(I110>=87,"OK",IF(I110<=87,"LESS")) -> OK | ... Q112: =IF(Q110>=87,"OK",IF(Q110<=87,"LESS")) -> OK
A115: Done by | B115: RK
A117: Comment

Sheet 02
A1: Station: | B1: BHATAGAON RAIPUR
A2: Date: | B2: =$A$9 -> 02/07/2024 00:15 | D2: Power Off | G2: Pw.Off | L2: Link Fail | N2: Link F | P2: Maintenance | R2: Maint.
A3: Report Type: | B3: Mean | D3: Calibration | G3: Calib. | L3: Data Fail | N3: Data F | P3: Invalid | R3: Invalid
A4: Time Base: | B4: 15 Min | D4: Zero Referrence | G4: Z.Ref | L4: Warm Up | N4: Wm. Up
A7: Date & Time | B7: NO_BHATAGAON | C7: NO2__BHATAGAON | D7: NOX_BHATAGAON | E7: SO2__BHATAGAON | F7: O3__BHATAGAON | G7: PM10__BHATAGAON | H7: PM2_5__BHATAGAON | I7: BENZ__BHATAGAON | J7: WS__BHATAGAON | K7: WD__BHATAGAON | L7: TEMP__BHATAGAON | M7: HUM__BHATAGAON | N7: SR__BHATAGAON | O7: RG__BHATAGAON | P7: CO__BHATAGAON | Q7: NH3__BHATAGAON
B8: ug/m3 | C8: ug/m3 | D8: ppb | E8: ug/m3 | F8: ug/m3 | G8: ug/m3 | H8: ug/m3 | I8: ug/m3 | J8: m/sec | K8: deg | L8: degreC | M8: % | N8: w/m2 | O8: mm | P8: mg/m3 | Q8: ug/m3
A9: 02/07/2024 00:15 | B9: 8.21 | C9: 3.19 | D9: 12.02 | E9: 3.84 | F9: 3.1 | G9: 30.39 | H9: 7.68 | I9: 3.77 | J9: 0.05 | K9: 241.29 | L9: 23.74 | M9: 98.33 | N9: 18 | O9: 0 | P9: 0.38 | Q9: 9.37
A10: 02/07/2024 00:30 | B10: 8.19 | C10: 3.21 | D10: 12.02 | E10: 3.55 | F10: 3.53 | G10: 30.39 | H10: 7.68 | I10: 3.64 | J10: 0.16 | K10: 40.96 | L10: 23.75 | M10: 98.33 | N10: 18 | O10: 0 | P10: 0.37 | Q10: 9.34
A11: 02/07/2024 00:45 | B11: 8.22 | C11: 3.19 | D11: 12.04 | E11: 3.56 | F11: 3.18 | G11: 27.49 | H11: 6.51 | I11: 3.58 | J11: 0.2 | K11: 22.13 | L11: 23.88 | M11: 98.3 | N11: 17.9 | O11: 0 | P11: 0.36 | Q11: 9.33
A12: 02/07/2024 01:00 | B12: 8.33 | C12: 3.3 | D12: 12.18 | E12: 3.62 | F12: 3.49 | G12: 25.74 | H12: 5.8 | I12: 3.53 | J12: 0.15 | K12: 237.77 | L12: 23.91 | M12: 98.27 | N12: 17.7 | O12: 0 | P12: 0.35 | Q12: 9.35
A13: 02/07/2024 01:15 | B13: 8.28 | C13: 3.2 | D13: 12.09 | E13: 3.55 | F13: 3.39 | G13: 25.74 | H13: 5.8 | I13: 3.56 | J13: 0.08 | K13: 343.58 | L13: 23.89 | M13: 98.28 | N13: 17.6 | O13: 0 | P13: 0.33 | Q13: 9.33
A14: 02/07/2024 01:30 | B14: 8.26 | C14: 3.14 | D14: 12.04 | E14: 3.83 | F14: 3.32 | G14: 25.74 | H14: 5.8 | I14: 3.67 | J14: 0.19 | K14: 348.22 | L14: 24.02 | M14: 97.28 | N14: 17.5 | O14: 0 | P14: 0.34 | Q14: 9.35
A15: 02/07/2024 01:45 | B15: 8.24 | C15: 3.16 | D15: 12.03 | E15: 3.77 | F15: 3.52 | G15: 23.43 | H15: 4.73 | I15: 3.78 | J15: 0.22 | K15: 348.94 | L15: 24.07 | M15: 95.86 | N15: 17.8 | O15: 0 | P15: 0.32 | Q15: 9.38
A16: 02/07/2024 02:00 | B16: 8.23 | C16: 3.24 | D16: 12.07 | E16: 3.48 | F16: 3.95 | G16: 21.97 | H16: 4.06 | I16: 3.78 | J16: 0.22 | K16: 341.42 | L16: 23.83 | M16: 96.04 | N16: 18.1 | O16: 0 | P16: 0.31 | Q16: 9.36
A17: 02/07/2024 02:15 | B17: 8.19 | C17: 3.12 | D17: 11.97 | E17: 3.93 | F17: 4.03 | G17: 21.97 | H17: 4.06 | I17: 3.59 | J17: 0.55 | K17: 5.65 | L17: 23.6 | M17: 94.34 | N17: 17.8 | O17: 0 | P17: 0.3 | Q17: 9.31
A18: 02/07/2024 02:30 | B18: 8.16 | C18: 3.1 | D18: 11.94 | E18: 3.74 | F18: 4.77 | G18: 21.97 | H18: 4.06 | I18: 3.33 | J18: 0.57 | K18: 4.14 | L18: 23.33 | M18: 91.66 | N18: 17.7 | O18: 0 | P18: 0.28 | Q18: 9.34
A19: 02/07/2024 02:45 | B19: 8.13 | C19: 3.11 | D19: 11.92 | E19: 3.99 | F19: 5.61 | G19: 22.7 | H19: 3.83 | I19: 3.11 | J19: 0.37 | K19: 343.78 | L19: 23.14 | M19: 88.5 | N19: 17.8 | O19: 0 | P19: 0.28 | Q19: 9.3
A20: 02/07/2024 03:00 | B20: 8.16 | C20: 3.16 | D20: 11.97 | E20: 4.1 | F20: 2.87 | G20: 23.17 | H20: 3.68 | I20: 2.85 | J20: 0.5 | K20: 0.63 | L20: 22.88 | M20: 87.79 | N20: 17.7 | O20: 0 | P20: 0.26 | Q20: 9.21
... A104: 02/07/2024 24:00 | B104: 8.27 | C104: 3.27 | D104: 12.12 | E104: 4.7 | F104: 4.37 | G104: 23.79 | H104: 8.61 | I104: 3.37 | J104: 0.65 | K104: 10.05 | L104: 23.42 | M104: 96.68 | N104: 18.1 | O104: 0 | P104: 0.38 | Q104: 9.32
A106: Min | B106: =MIN(B9:B104) -> 8.11 | C106: =MIN(C9:C104) -> 3.02 | D106: =MIN(D9:D104) -> 11.87 | E106: =MIN(E9:E104) -> 3.08 | F106: =MIN(F9:F104) -> 2.55 | G106: =MIN(G9:G104) -> 14.58 | H106: =MIN(H9:H104) -> 1.11 | I106: =MIN(I9:I104) -> 0.96 | ... Q106: =MIN(Q9:Q104) -> 9.17
A107: Max | B107: =MAX(B9:B104) -> 8.39 | C107: =MAX(C9:C104) -> 3.71 | D107: =MAX(D9:D104) -> 12.43 | E107: =MAX(E9:E104) -> 5.06 | F107: =MAX(F9:F104) -> 6.28 | G107: =MAX(G9:G104) -> 46.52 | H107: =MAX(H9:H104) -> 14.84 | I107: =MAX(I9:I104) -> 4.86 | ... Q107: =MAX(Q9:Q104) -> 9.47
A108: Avg | B108: =AVERAGE(B9:B104) -> 8.2084375 | C108: =AVERAGE(C9:C104) -> 3.19375 | D108: =AVERAGE(D9:D104) -> 12.025417 | E108: =AVERAGE(E9:E104) -> 4.1141667 | F108: =AVERAGE(F9:F104) -> 3.9802083 | G108: =AVERAGE(G9:G104) -> 29.526562 | H108: =AVERAGE(H9:H104) -> 7.5639583 | I108: =AVERAGE(I9:I104) -> 2.3561458 | ... Q108: =AVERAGE(Q9:Q104) -> 9.2786458
A109: Stdev | B109: =STDEV(B9:B104) -> 0.051612486 | C109: =STDEV(C9:C104) -> 0.10525408 | D109: =STDEV(D9:D104) -> 0.09181121 | E109: =STDEV(E9:E104) -> 0.37026212 | F109: =STDEV(F9:F104) -> 0.84012152 | G109: =STDEV(G9:G104) -> 9.456236 | H109: =STDEV(H9:H104) -> 3.8591648 | I109: =STDEV(I9:I104) -> 1.1849747 | ... Q109: =STDEV(Q9:Q104) -> 0.083560502
A110: Num | B110: =COUNT(B9:B104) -> 96 | C110: =COUNT(C9:C104) -> 96 | D110: =COUNT(D9:D104) -> 96 | E110: =COUNT(E9:E104) -> 96 | F110: =COUNT(F9:F104) -> 96 | G110: =COUNT(G9:G104) -> 96 | H110: =COUNT(H9:H104) -> 96 | I110: =COUNT(I9:I104) -> 96 | ... Q110: =COUNT(Q9:Q104) -> 96
A111: DCR | B111: =IF(B110>=87,">90%",IF(B110<=87,"<90%")) -> >90% | C111: =IF(C110>=87,">90%",IF(C110<=87,"<90%")) -> >90% | D111: =IF(D110>=87,">90%",IF(D110<=87,"<90%")) -> >90% | E111: =IF(E110>=87,">90%",IF(E110<=87,"<90%")) -> >90% | F111: =IF(F110>=87,">90%",IF(F110<=87,"<90%")) -> >90% | G111: =IF(G110>=87,">90%",IF(G110<=87,"<90%")) -> >90% | H111: =IF(H110>=87,">90%",IF(H110<=87,"<90%")) -> >90% | I111: =IF(I110>=87,">90%",IF(I110<=87,"<90%")) -> >90% | ... Q111: =IF(Q110>=87,">90%",IF(Q110<=87,"<90%")) -> >90%
A112: Status | B112: =IF(B110>=87,"OK",IF(B110<=87,"LESS")) -> OK | C112: =IF(C110>=87,"OK",IF(C110<=87,"LESS")) -> OK | D112: =IF(D110>=87,"OK",IF(D110<=87,"LESS")) -> OK | E112: =IF(E110>=87,"OK",IF(E110<=87,"LESS")) -> OK | F112: =IF(F110>=87,"OK",IF(F110<=87,"LESS")) -> OK | G112: =IF(G110>=87,"OK",IF(G110<=87,"LESS")) -> OK | H112: =IF(H110>=87,"OK",IF(H110<=87,"LESS")) -> OK | I112: =IF(I110>=87,"OK",IF(I110<=87,"LESS")) -> OK | ... Q112: =IF(Q110>=87,"OK",IF(Q110<=87,"LESS")) -> OK
A115: Done by | B115: RK
A117: Comment

Sheet 03
A1: Station: | B1: BHATAGAON RAIPUR
A2: Date: | B2: =$A$9 -> 03/07/2024 00:15 | D2: Power Off | G2: Pw.Off | L2: Link Fail | N2: Link F | P2: Maintenance | R2: Maint.
A3: Report Type: | B3: Mean | D3: Calibration | G3: Calib. | L3: Data Fail | N3: Data F | P3: Invalid | R3: Invalid
A4: Time Base: | B4: 15 Min | D4: Zero Referrence | G4: Z.Ref | L4: Warm Up | N4: Wm. Up
A7: Date & Time | B7: NO_BHATAGAON | C7: NO2__BHATAGAON | D7: NOX_BHATAGAON | E7: SO2__BHATAGAON | F7: O3__BHATAGAON | G7: PM10__BHATAGAON | H7: PM2_5__BHATAGAON | I7: BENZ__BHATAGAON | J7: WS__BHATAGAON | K7: WD__BHATAGAON | L7: TEMP__BHATAGAON | M7: HUM__BHATAGAON | N7: SR__BHATAGAON | O7: RG__BHATAGAON | P7: CO__BHATAGAON | Q7: NH3__BHATAGAON
B8: ug/m3 | C8: ug/m3 | D8: ppb | E8: ug/m3 | F8: ug/m3 | G8: ug/m3 | H8: ug/m3 | I8: ug/m3 | J8: m/sec | K8: deg | L8: degreC | M8: % | N8: w/m2 | O8: mm | P8: mg/m3 | Q8: ug/m3
A9: 03/07/2024 00:15 | B9: 8.25 | C9: 3.21 | D9: 12.07 | E9: 4.54 | F9: 4.92 | G9: 23.79 | H9: 8.61 | I9: 3.07 | J9: 0.74 | K9: 13.51 | L9: 23.19 | M9: 97.41 | N9: 18 | O9: 0 | P9: 0.35 | Q9: 9.31
A10: 03/07/2024 00:30 | B10: 8.23 | C10: 3.23 | D10: 12.06 | E10: 4.29 | F10: 5.07 | G10: 23.79 | H10: 8.61 | I10: 2.58 | J10: 0.67 | K10: 10.56 | L10: 23.04 | M10: 97.88 | N10: 17.8 | O10: 0 | P10: 0.33 | Q10: 9.3
A11: 03/07/2024 00:45 | B11: 8.22 | C11: 3.24 | D11: 12.06 | E11: 4.54 | F11: 4.91 | G11: 19.84 | H11: 7.17 | I11: 2.17 | J11: 0.56 | K11: 5.91 | L11: 22.9 | M11: 98.3 | N11: 17.8 | O11: 0 | P11: 0.3 | Q11: 9.26
A12: 03/07/2024 01:00 | B12: 8.23 | C12: 3.26 | D12: 12.08 | E12: 4.72 | F12: 4.82 | G12: 17.44 | H12: 6.25 | I12: 1.92 | J12: 0.63 | K12: 5.84 | L12: 22.79 | M12: 98.32 | N12: 17.7 | O12: 0 | P12: 0.29 | Q12: 9.23
A13: 03/07/2024 01:15 | B13: 8.21 | C13: 3.16 | D13: 12.01 | E13: 4.68 | F13: 5.71 | G13: 17.44 | H13: 6.25 | I13: 1.76 | J13: 0.59 | K13: 16.07 | L13: 22.73 | M13: 98.32 | N13: 17.7 | O13: 0 | P13: 0.29 | Q13: 9.22
A14: 03/07/2024 01:30 | B14: 8.18 | C14: 3.15 | D14: 11.98 | E14: 4.57 | F14: 6.41 | G14: 17.44 | H14: 6.25 | I14: 1.68 | J14: 0.77 | K14: 19.52 | L14: 22.64 | M14: 98.33 | N14: 17.8 | O14: 0 | P14: 0.31 | Q14: 9.21
A15: 03/07/2024 01:45 | B15: 8.15 | C15: 3.11 | D15: 11.93 | E15: 4.53 | F15: 4.71 | G15: 15.73 | H15: 5.23 | I15: 1.59 | J15: 0.6 | K15: 8.44 | L15: 22.62 | M15: 98.33 | N15: 17.7 | O15: 0 | P15: 0.3 | Q15: 9.16
A16: 03/07/2024 02:00 | B16: 8.17 | C16: 3.21 | D16: 12.01 | E16: 4.52 | F16: 4.29 | G16: 14.64 | H16: 4.59 | I16: 1.5 | J16: 0.5 | K16: 25.9 | L16: 22.62 | M16: 98.33 | N16: 17.7 | O16: 0 | P16: 0.27 | Q16: 9.14
A17: 03/07/2024 02:15 | B17: 8.13 | C17: 3.09 | D17: 11.91 | E17: 4.49 | F17: 5.04 | G17: 14.64 | H17: 4.59 | I17: 1.38 | J17: 0.6 | K17: 14.13 | L17: 22.66 | M17: 98.33 | N17: 17.7 | O17: 0 | P17: 0.26 | Q17: 9.15
A18: 03/07/2024 02:30 | B18: 8.15 | C18: 3.12 | D18: 11.93 | E18: 4.64 | F18: 5.88 | G18: 14.64 | H18: 4.59 | I18: 1.23 | J18: 0.72 | K18: 11.18 | L18: 22.59 | M18: 98.33 | N18: 17.8 | O18: 0 | P18: 0.26 | Q18: 9.23
A19: 03/07/2024 02:45 | B19: 8.15 | C19: 3.1 | D19: 11.92 | E19: 4.78 | F19: 4.39 | G19: 12.3 | H19: 3.78 | I19: 1.13 | J19: 0.5 | K19: 13.69 | L19: 22.55 | M19: 98.33 | N19: 17.8 | O19: 0 | P19: 0.26 | Q19: 9.18
A20: 03/07/2024 03:00 | B20: 8.14 | C20: 3.12 | D20: 11.93 | E20: 4.34 | F20: 4.85 | G20: 10.81 | H20: 3.27 | I20: 1.06 | J20: 0.75 | K20: 11.78 | L20: 22.55 | M20: 98.32 | N20: 17.8 | O20: 0 | P20: 0.24 | Q20: 9.17
... A54: 03/07/2024 11:30 | B54: 8.17 | C54: 3.36 | D54: 12.08 | E54: 4.6 | F54: 5.47 | G54: 39.71 | H54: 9.92 | I54: 1.89 | J54: 0.52 | K54: 347.74 | L54: 28.07 | M54: 74.48 | N54: 381.3 | O54: 0 | P54: 0.76 | Q54: 9.28
A55: 03/07/2024 11:45 | B55: 8.19 | C55: 3.29 | D55: 12.05 | E55: 4.29 | F55: 4.94 | G55: Calib. | H55: Calib. | I55: 2.24 | J55: 0.54 | K55: 344.68 | L55: 27.75 | M55: 74.95 | N55: 247.8 | O55: 0 | P55: 0.74 | Q55: 9.28
A56: 03/07/2024 12:00 | B56: 8.2 | C56: 3.32 | D56: 12.08 | E56: 3.53 | F56: 5.32 | G56: Calib. | H56: Calib. | I56: 2.4 | J56: 0.57 | K56: 353.66 | L56: 27.36 | M56: 75.97 | N56: 365.6 | O56: 0 | P56: 0.73 | Q56: 9.3
A57: 03/07/2024 12:15 | B57: 8.18 | C57: 3.33 | D57: 12.08 | E57: 3.71 | F57: 4.19 | G57: Calib. | H57: Calib. | I57: 2.57 | J57: 0.52 | K57: 338.32 | L57: 28.16 | M57: 73.74 | N57: 374.4 | O57: 0 | P57: 0.7 | Q57: 9.29
A58: 03/07/2024 12:30 | B58: 8.19 | C58: 3.3 | D58: 12.07 | E58: 3.64 | F58: 4.47 | G58: 39.53 | H58: 13.33 | I58: 2.62 | J58: 0.55 | K58: 342.88 | L58: 28.21 | M58: 72.47 | N58: 391.8 | O58: 0 | P58: 0.69 | Q58: 9.27
A59: 03/07/2024 12:45 | B59: 8.26 | C59: 3.24 | D59: 12.09 | E59: 3.68 | F59: 4.83 | G59: 45.56 | H59: 14.43 | I59: 2.6 | J59: 0.58 | K59: 5.75 | L59: 27.88 | M59: 72.55 | N59: 348.6 | O59: 0 | P59: 0.67 | Q59: 9.25
A60: 03/07/2024 13:00 | B60: 8.29 | C60: 3.32 | D60: 12.16 | E60: 3.83 | F60: 5.02 | G60: 49.39 | H60: 15.13 | I60: 2.58 | J60: 0.53 | K60: 355.57 | L60: 27.92 | M60: 72.24 | N60: 356.7 | O60: 0 | P60: 0.65 | Q60: 9.27
A61: 03/07/2024 13:15 | B61: 8.34 | C61: 3.5 | D61: 12.29 | E61: 3.78 | F61: 4.72 | G61: 49.39 | H61: 15.13 | I61: 2.49 | J61: 0.51 | K61: 339.53 | L61: 28.13 | M61: 72.33 | N61: 209.7 | O61: 0 | P61: 0.55 | Q61: 9.27
A62: 03/07/2024 13:30 | B62: 8.29 | C62: 3.29 | D62: 12.14 | E62: 3.69 | F62: 4.47 | G62: 49.39 | H62: 15.13 | I62: 2.4 | J62: 0.61 | K62: 312.58 | L62: 28.94 | M62: 70.05 | N62: 314.7 | O62: 0 | P62: 0.57 | Q62: 9.24
A63: 03/07/2024 13:45 | B63: 8.28 | C63: 3.23 | D63: 12.1 | E63: 4.58 | F63: 5.74 | G63: 61.67 | H63: 16.48 | I63: 2.34 | J63: 0.59 | K63: 334.42 | L63: 29.19 | M63: 67.04 | N63: 504.7 | O63: 0 | P63: 0.55 | Q63: 9.23
A64: 03/07/2024 14:00 | B64: 8.27 | C64: 3.25 | D64: 12.1 | E64: 3.92 | F64: 5.79 | G64: 69.49 | H64: 17.34 | I64: 2.27 | J64: 0.55 | K64: 322.41 | L64: 30.22 | M64: 64.19 | N64: 693.8 | O64: 0 | P64: 0.52 | Q64: 9.25
A65: 03/07/2024 14:15 | B65: 8.27 | C65: 3.23 | D65: 12.09 | E65: 3.92 | F65: 8.75 | G65: 69.49 | H65: 17.34 | I65: 2.14 | J65: 0.53 | K65: 351.97 | L65: 30.83 | M65: 61.45 | N65: 627.9 | O65: 0 | P65: 0.47 | Q65: 9.24
A66: 03/07/2024 14:30 | B66: 8.25 | C66: 3.18 | D66: 12.05 | E66: 4.05 | F66: 6.9 | G66: 69.49 | H66: 17.34 | I66: 1.98 | J66: 0.53 | K66: 353.87 | L66: 29.67 | M66: 64.2 | N66: 356.1 | O66: 0 | P66: 0.45 | Q66: 9.25
A67: 03/07/2024 14:45 | B67: 8.27 | C67: 3.18 | D67: 12.07 | E67: 3.9 | F67: 5.28 | G67: 65.92 | H67: 18.82 | I67: 1.78 | J67: 0.61 | K67: 333.89 | L67: 29.67 | M67: 63.93 | N67: 288.1 | O67: 0 | P67: 0.42 | Q67: 9.26
A68: 03/07/2024 15:00 | B68: 8.27 | C68: 3.2 | D68: 12.08 | E68: 3.66 | F68: 4.76 | G68: 63.65 | H68: 19.76 | I68: 1.68 | J68: 0.57 | K68: 336.38 | L68: 29.46 | M68: 64.39 | N68: 275.7 | O68: 0 | P68: 0.43 | Q68: 9.24
A69: 03/07/2024 15:15 | B69: 8.27 | C69: 3.24 | D69: 12.1 | E69: 3.66 | F69: 5.39 | G69: 63.65 | H69: 19.76 | I69: 1.67 | J69: 0.63 | K69: 331.11 | L69: 29.84 | M69: 63.84 | N69: 281.4 | O69: 0 | P69: 0.43 | Q69: 9.26
... A104: 03/07/2024 24:00 | B104: 8.29 | C104: 3.24 | D104: 12.11 | E104: 3.03 | F104: 3.51 | G104: 34.43 | H104: 11.37 | I104: 4.04 | J104: 0.63 | K104: 151.36 | L104: 23.86 | M104: 90.13 | N104: 18.1 | O104: 0 | P104: 0.41 | Q104: 9.36
A106: Min | B106: =MIN(B9:B104) -> 8.08 | C106: =MIN(C9:C104) -> 3.01 | D106: =MIN(D9:D104) -> 11.83 | E106: =MIN(E9:E104) -> 2.91 | F106: =MIN(F9:F104) -> 2.7 | G106: =MIN(G9:G104) -> 8.52 | H106: =MIN(H9:H104) -> 1.53 | I106: =MIN(I9:I104) -> 0.57 | ... Q106: =MIN(Q9:Q104) -> 9.14
A107: Max | B107: =MAX(B9:B104) -> 8.42 | C107: =MAX(C9:C104) -> 3.59 | D107: =MAX(D9:D104) -> 12.4 | E107: =MAX(E9:E104) -> 4.98 | F107: =MAX(F9:F104) -> 8.75 | G107: =MAX(G9:G104) -> 69.49 | H107: =MAX(H9:H104) -> 19.76 | I107: =MAX(I9:I104) -> 4.04 | ... Q107: =MAX(Q9:Q104) -> 9.36
A108: Avg | B108: =AVERAGE(B9:B104) -> 8.2321875 | C108: =AVERAGE(C9:C104) -> 3.2198958 | D108: =AVERAGE(D9:D104) -> 12.058021 | E108: =AVERAGE(E9:E104) -> 4.0677083 | F108: =AVERAGE(F9:F104) -> 4.448125 | G108: =AVERAGE(G9:G104) -> 35.809462 | H108: =AVERAGE(H9:H104) -> 10.245161 | I108: =AVERAGE(I9:I104) -> 1.8420833 | ... Q108: =AVERAGE(Q9:Q104) -> 9.2434375
A109: Stdev | B109: =STDEV(B9:B104) -> 0.062089971 | C109: =STDEV(C9:C104) -> 0.11330903 | D109: =STDEV(D9:D104) -> 0.099447101 | E109: =STDEV(E9:E104) -> 0.58688917 | F109: =STDEV(F9:F104) -> 0.96928331 | G109: =STDEV(G9:G104) -> 17.899514 | H109: =STDEV(H9:H104) -> 5.8693483 | I109: =STDEV(I9:I104) -> 0.90756808 | ... Q109: =STDEV(Q9:Q104) -> 0.057598029
A110: Num | B110: =COUNT(B9:B104) -> 96 | C110: =COUNT(C9:C104) -> 96 | D110: =COUNT(D9:D104) -> 96 | E110: =COUNT(E9:E104) -> 96 | F110: =COUNT(F9:F104) -> 96 | G110: =COUNT(G9:G104)+3 -> 96 | H110: =COUNT(H9:H104)+3 -> 96 | I110: =COUNT(I9:I104) -> 96 | J110: =COUNT(J9:J104) -> 96 | K110: =COUNT(K9:K104) -> 96 | L110: =COUNT(L9:L104) -> 96 | M110: =COUNT(M9:M104) -> 96 | N110: =COUNT(N9:N104) -> 96 | O110: =COUNT(O9:O104) -> 96 | P110: =COUNT(P9:P104) -> 96 | Q110: =COUNT(Q9:Q104) -> 96
...

Sheet 04
A1: Station: | B1: BHATAGAON RAIPUR
A2: Date: | B2: =$A$9 -> 04/07/2024 00:15 | D2: Power Off | G2: Pw.Off | L2: Link Fail | N2: Link F | P2: Maintenance | R2: Maint.
A3: Report Type: | B3: Mean | D3: Calibration | G3: Calib. | L3: Data Fail | N3: Data F | P3: Invalid | R3: Invalid
A4: Time Base: | B4: 15 Min | D4: Zero Referrence | G4: Z.Ref | L4: Warm Up | N4: Wm. Up
A7: Date & Time | B7: NO_BHATAGAON | C7: NO2__BHATAGAON | D7: NOX_BHATAGAON | E7: SO2__BHATAGAON | F7: O3__BHATAGAON | G7: PM10__BHATAGAON | H7: PM2_5__BHATAGAON | I7: BENZ__BHATAGAON | J7: WS__BHATAGAON | K7: WD__BHATAGAON | L7: TEMP__BHATAGAON | M7: HUM__BHATAGAON | N7: SR__BHATAGAON | O7: RG__BHATAGAON | P7: CO__BHATAGAON | Q7: NH3__BHATAGAON
B8: ug/m3 | C8: ug/m3 | D8: ppb | E8: ug/m3 | F8: ug/m3 | G8: ug/m3 | H8: ug/m3 | I8: ug/m3 | J8: m/sec | K8: deg | L8: degreC | M8: % | N8: w/m2 | O8: mm | P8: mg/m3 | Q8: ug/m3
A9: 04/07/2024 00:15 | B9: 8.3 | C9: 3.22 | D9: 12.11 | E9: 4.32 | F9: 3.77 | G9: 34.43 | H9: 11.37 | I9: 4.22 | J9: 0.76 | K9: 162.68 | L9: 23.76 | M9: 90.4 | N9: 18.1 | O9: 0 | P9: 0.41 | Q9: 9.33
A10: 04/07/2024 00:30 | B10: 8.3 | C10: 3.2 | D10: 12.1 | E10: 4.86 | F10: 4.55 | G10: 34.43 | H10: 11.37 | I10: 4.36 | J10: 0.47 | K10: 163.8 | L10: 23.75 | M10: 89.54 | N10: 18.1 | O10: 0 | P10: 0.41 | Q10: 9.32
A11: 04/07/2024 00:45 | B11: 8.24 | C11: 3.14 | D11: 12.02 | E11: 4.84 | F11: 3.24 | G11: 32.31 | H11: 9.58 | I11: 4.4 | J11: 0.25 | K11: 234.56 | L11: 23.7 | M11: 89 | N11: 18.1 | O11: 0 | P11: 0.4 | Q11: 9.24
A12: 04/07/2024 01:00 | B12: 8.23 | C12: 3.11 | D12: 12 | E12: 4.56 | F12: 3.03 | G12: 30.95 | H12: 8.44 | I12: 4.33 | J12: 0.01 | K12: 195.57 | L12: 23.66 | M12: 89.83 | N12: 18.1 | O12: 0 | P12: 0.38 | Q12: 9.24
A13: 04/07/2024 01:15 | B13: 8.29 | C13: 3.24 | D13: 12.12 | E13: 4.53 | F13: 3.4 | G13: 30.95 | H13: 8.44 | I13: 4.22 | J13: 0.23 | K13: 341.82 | L13: 23.61 | M13: 90.91 | N13: 18.1 | O13: 0 | P13: 0.36 | Q13: 9.28
A14: 04/07/2024 01:30 | B14: 8.3 | C14: 3.22 | D14: 12.11 | E14: 4.27 | F14: 3.64 | G14: 30.95 | H14: 8.44 | I14: 4.08 | J14: 0.53 | K14: 335.87 | L14: 23.67 | M14: 90.6 | N14: 18.1 | O14: 0 | P14: 0.35 | Q14: 9.28
A15: 04/07/2024 01:45 | B15: 8.35 | C15: 3.31 | D15: 12.2 | E15: 4.54 | F15: 4.45 | G15: 30.4 | H15: 8.06 | I15: 4.02 | J15: 0.53 | K15: 343.03 | L15: 23.77 | M15: 90.3 | N15: 18.1 | O15: 0 | P15: 0.34 | Q15: 9.27
A16: 04/07/2024 02:00 | B16: 8.29 | C16: 3.25 | D16: 12.12 | E16: 4.65 | F16: 4.75 | G16: 30.04 | H16: 7.82 | I16: 3.71 | J16: 0.5 | K16: 344.62 | L16: 23.73 | M16: 90.6 | N16: 18.1 | O16: 0 | P16: 0.35 | Q16: 9.28
A17: 04/07/2024 02:15 | B17: 8.23 | C17: 3.13 | D17: 12.01 | E17: 4.8 | F17: 2.58 | G17: 30.04 | H17: 7.82 | I17: 3.51 | J17: 0.59 | K17: 13.58 | L17: 23.77 | M17: 91.09 | N17: 18.1 | O17: 0 | P17: 0.34 | Q17: 9.22
A18: 04/07/2024 02:30 | B18: 8.29 | C18: 3.27 | D18: 12.13 | E18: 4.81 | F18: 3.13 | G18: 30.04 | H18: 7.82 | I18: 3.31 | J18: 0.77 | K18: 319.6 | L18: 23.73 | M18: 92.34 | N18: 18.1 | O18: 0 | P18: 0.33 | Q18: 9.23
A19: 04/07/2024 02:45 | B19: 8.25 | C19: 3.13 | D19: 12.02 | E19: 4.75 | F19: 3.22 | G19: 28.11 | H19: 8 | I19: 3.17 | J19: 1.41 | K19: 329.69 | L19: 23.78 | M19: 93.82 | N19: 18.2 | O19: 0 | P19: 0.33 | Q19: 9.23
A20: 04/07/2024 03:00 | B20: 8.27 | C20: 3.15 | D20: 12.06 | E20: 4.36 | F20: 3.54 | G20: 26.88 | H20: 8.11 | I20: 3.13 | J20: 1.14 | K20: 314.18 | L20: 23.59 | M20: 97.41 | N20: 18.2 | O20: 0 | P20: 0.32 | Q20: 9.25
... A56: 04/07/2024 12:00 | B56: 8.32 | C56: 3.35 | D56: 12.2 | E56: 5.21 | F56: 2.73 | G56: 4.7 | H56: 1.76 | I56: 1.44 | J56: 0.55 | K56: 350.59 | L56: 25.55 | M56: 89.72 | N56: 315.4 | O56: 0 | P56: 0.4 | Q56: 9.15
A57: 04/07/2024 12:15 | B57: 8.31 | C57: 3.3 | D57: 12.16 | E57: 4.99 | F57: 4.49 | G57: Calib. | H57: Calib. | I57: 1.49 | J57: 0.27 | K57: 345.33 | L57: 25.86 | M57: 88.55 | N57: 513.3 | O57: 0 | P57: 0.39 | Q57: 9.19
A58: 04/07/2024 12:30 | B58: 8.28 | C58: 3.24 | D58: 12.11 | E58: 4.89 | F58: 5.27 | G58: Calib. | H58: Calib. | I58: 1.46 | J58: 0.36 | K58: 347.44 | L58: 26.2 | M58: 86.1 | N58: 467.7 | O58: 0 | P58: 0.38 | Q58: 9.2
A59: 04/07/2024 12:45 | B59: 8.28 | C59: 3.24 | D59: 12.11 | E59: 4.71 | F59: 7.32 | G59: Calib. | H59: Calib. | I59: 1.45 | J59: 0.46 | K59: 348.94 | L59: 26.69 | M59: 82.49 | N59: 541.5 | O59: 0 | P59: 0.37 | Q59: 9.19
A60: 04/07/2024 13:00 | B60: 8.27 | C60: 3.26 | D60: 12.1 | E60: 4.88 | F60: 8.23 | G60: 44.41 | H60: 16.32 | I60: 1.36 | J60: 0.6 | K60: 341.26 | L60: 26.78 | M60: 81.27 | N60: 416.9 | O60: 0 | P60: 0.36 | Q60: 9.19
A61: 04/07/2024 13:15 | B61: 8.3 | C61: 3.27 | D61: 12.14 | E61: 4.64 | F61: 8.63 | G61: 92.94 | H61: 34.17 | I61: 1.22 | J61: 0.54 | K61: 350.86 | L61: 26.7 | M61: 82.21 | N61: 431 | O61: 0 | P61: 0.35 | Q61: 9.21
A62: 04/07/2024 13:30 | B62: 8.29 | C62: 3.23 | D62: 12.11 | E62: 4.62 | F62: 7.68 | G62: 92.94 | H62: 34.17 | I62: 1.15 | J62: 0.66 | K62: 1.36 | L62: 26.38 | M62: 80.65 | N62: 308.6 | O62: 0 | P62: 0.35 | Q62: 9.21
A63: 04/07/2024 13:45 | B63: 8.27 | C63: 3.2 | D63: 12.08 | E63: 5.1 | F63: 6.53 | G63: 92.94 | H63: 34.17 | I63: 1.1 | J63: 0.61 | K63: 359.8 | L63: 26.24 | M63: 75.86 | N63: 393.3 | O63: 0 | P63: 0.34 | Q63: 9.18
A64: 04/07/2024 14:00 | B64: 8.27 | C64: 3.21 | D64: 12.08 | E64: 4.61 | F64: 7.19 | G64: 77.4 | H64: 29.52 | I64: 1.04 | J64: 0.63 | K64: 337.66 | L64: 27.33 | M64: 73.77 | N64: 644.9 | O64: 0 | P64: 0.34 | Q64: 9.2
A65: 04/07/2024 14:15 | B65: 8.24 | C65: 3.14 | D65: 12.02 | E65: 4.76 | F65: 7.12 | G65: 60.41 | H65: 24.43 | I65: 1 | J65: 0.6 | K65: 337.99 | L65: 27.7 | M65: 72.9 | N65: 511.4 | O65: 0 | P65: 0.35 | Q65: 9.23
A66: 04/07/2024 14:30 | B66: 8.21 | C66: 3.13 | D66: 11.99 | E66: 5.01 | F66: 5.42 | G66: 60.41 | H66: 24.43 | I66: 0.98 | J66: 0.58 | K66: 337.3 | L66: 27.26 | M66: 76.31 | N66: 339.5 | O66: 0 | P66: 0.34 | Q66: 9.22
A67: 04/07/2024 14:45 | B67: 8.3 | C67: 3.39 | D67: 12.2 | E67: 4.78 | F67: 5.16 | G67: 60.41 | H67: 24.43 | I67: 0.99 | J67: 0.59 | K67: 349.36 | L67: 27.34 | M67: 76.37 | N67: 261.9 | O67: 0 | P67: 0.33 | Q67: 9.22
A68: 04/07/2024 15:00 | B68: 8.31 | C68: 3.35 | D68: 12.18 | E68: 4.54 | F68: 4.92 | G68: 61.25 | H68: 23.5 | I68: 0.94 | J68: 0.45 | K68: 8.82 | L68: 27.07 | M68: 77.67 | N68: 262.7 | O68: 0 | P68: 0.34 | Q68: 9.2
A69: 04/07/2024 15:15 | B69: 8.35 | C69: 3.54 | D69: 12.32 | E69: 4.87 | F69: 4.75 | G69: 62.2 | H69: 22.43 | I69: 0.89 | J69: 0.3 | K69: 345.76 | L69: 27.28 | M69: 78.21 | N69: 257.4 | O69: 0 | P69: 0.33 | Q69: 9.2
A70: 04/07/2024 15:30 | B70: 8.25 | C70: 3.19 | D70: 12.05 | E70: 4.75 | F70: 4.65 | G70: 62.2 | H70: 22.43 | I70: 0.9 | J70: 0.27 | K70: 352.75 | L70: 26.98 | M70: 80.32 | N70: 133.4 | O70: 0 | P70: 0.33 | Q70: 9.21
A71: 04/07/2024 15:45 | B71: 8.23 | C71: 3.13 | D71: 12.01 | E71: 4.71 | F71: 4.41 | G71: 62.2 | H71: 22.43 | I71: 0.93 | J71: 0.3 | K71: 344.13 | L71: 26.66 | M71: 82.67 | N71: 185.5 | O71: 0 | P71: 0.32 | Q71: 9.22
... A104: 04/07/2024 24:00 | B104: 8.38 | C104: 3.45 | D104: 12.3 | E104: 3.99 | F104: 3.35 | G104: 41.27 | H104: 12.78 | I104: 4.35 | J104: 0.24 | K104: 153.41 | L104: 23.7 | M104: 95.71 | N104: 18.2 | O104: 0 | P104: 0.37 | Q104: 9.29
A106: Min | B106: =MIN(B9:B104) -> 8.21 | C106: =MIN(C9:C104) -> 3.08 | D106: =MIN(D9:D104) -> 11.97 | E106: =MIN(E9:E104) -> 3.22 | F106: =MIN(F9:F104) -> 2.33 | G106: =MIN(G9:G104) -> 4.7 | H106: =MIN(H9:H104) -> 1.76 | I106: =MIN(I9:I104) -> 0.89 | ... Q106: =MIN(Q9:Q104) -> 9.14
A107: Max | B107: =MAX(B9:B104) -> 8.41 | C107: =MAX(C9:C104) -> 3.59 | D107: =MAX(D9:D104) -> 12.39 | E107: =MAX(E9:E104) -> 5.21 | F107: =MAX(F9:F104) -> 8.63 | G107: =MAX(G9:G104) -> 92.94 | H107: =MAX(H9:H104) -> 34.17 | I107: =MAX(I9:I104) -> 4.52 | ... Q107: =MAX(Q9:Q104) -> 9.33
A108: Avg | B108: =AVERAGE(B9:B104) -> 8.2789583 | C108: =AVERAGE(C9:C104) -> 3.2295833 | D108: =AVERAGE(D9:D104) -> 12.100208 | E108: =AVERAGE(E9:E104) -> 4.205625 | F108: =AVERAGE(F9:F104) -> 4.1684375 | G108: =AVERAGE(G9:G104) -> 37.072688 | H108: =AVERAGE(H9:H104) -> 12.578495 | I108: =AVERAGE(I9:I104) -> 2.4829167 | ... Q108: =AVERAGE(Q9:Q104) -> 9.233125
A109: Stdev | B109: =STDEV(B9:B104) -> 0.039215442 | C109: =STDEV(C9:C104) -> 0.095000462 | D109: =STDEV(D9:D104) -> 0.078283952 | E109: =STDEV(E9:E104) -> 0.45381149 | F109: =STDEV(F9:F104) -> 1.1867925 | G109: =STDEV(G9:G104) -> 23.115405 | H109: =STDEV(H9:H104) -> 7.209418 | I109: =STDEV(I9:I104) -> 1.0887655 | ... Q109: =STDEV(Q9:Q104) -> 0.039691243
A110: Num | B110: =COUNT(B9:B104) -> 96 | C110: =COUNT(C9:C104) -> 96 | D110: =COUNT(D9:D104) -> 96 | E110: =COUNT(E9:E104) -> 96 | F110: =COUNT(F9:F104) -> 96 | G110: =COUNT(G9:G104)+3 -> 96 | H110: =COUNT(H9:H104)+3 -> 96 | I110: =COUNT(I9:I104) -> 96 | J110: =COUNT(J9:J104) -> 96 | K110: =COUNT(K9:K104) -> 96 | L110: =COUNT(L9:L104) -> 96 | M110: =COUNT(M9:M104) -> 96 | N110: =COUNT(N9:N104) -> 96 | O110: =COUNT(O9:O104) -> 96 | P110: =COUNT(P9:P104) -> 96 | Q110: =COUNT(Q9:Q104) -> 96
...

Sheet 05
A1: Station: | B1: BHATAGAON RAIPUR
A2: Date: | B2: =$A$9 -> 05/07/2024 00:15 | D2: Power Off | G2: Pw.Off | L2: Link Fail | N2: Link F | P2: Maintenance | R2: Maint.
A3: Report Type: | B3: Mean | D3: Calibration | G3: Calib. | L3: Data Fail | N3: Data F | P3: Invalid | R3: Invalid
A4: Time Base: | B4: 15 Min | D4: Zero Referrence | G4: Z.Ref | L4: Warm Up | N4: Wm. Up
A7: Date & Time | B7: NO_BHATAGAON | C7: NO2__BHATAGAON | D7: NOX_BHATAGAON | E7: SO2__BHATAGAON | F7: O3__BHATAGAON | G7: PM10__BHATAGAON | H7: PM2_5__BHATAGAON | I7: BENZ__BHATAGAON | J7: WS__BHATAGAON | K7: WD__BHATAGAON | L7: TEMP__BHATAGAON | M7: HUM__BHATAGAON | N7: SR__BHATAGAON | O7: RG__BHATAGAON | P7: CO__BHATAGAON | Q7: NH3__BHATAGAON
B8: ug/m3 | C8: ug/m3 | D8: ppb | E8: ug/m3 | F8: ug/m3 | G8: ug/m3 | H8: ug/m3 | I8: ug/m3 | J8: m/sec | K8: deg | L8: degreC | M8: % | N8: w/m2 | O8: mm | P8: mg/m3 | Q8: ug/m3
A9: 05/07/2024 00:15 | B9: 8.28 | C9: 3.23 | D9: 12.1 | E9: 4.36 | F9: 3.71 | G9: 36.33 | H9: 10.99 | I9: 4.23 | J9: 0.61 | K9: 179.27 | L9: 23.63 | M9: 96.34 | N9: 18.1 | O9: 0 | P9: 0.37 | Q9: 9.29
A10: 05/07/2024 00:30 | B10: 8.25 | C10: 3.14 | D10: 12.03 | E10: 4.58 | F10: 3.67 | G10: 36.33 | H10: 10.99 | I10: 4.16 | J10: 0.21 | K10: 152.52 | L10: 23.58 | M10: 96.32 | N10: 18.3 | O10: 0 | P10: 0.36 | Q10: 9.26
A11: 05/07/2024 00:45 | B11: 8.27 | C11: 3.2 | D11: 12.08 | E11: 4.78 | F11: 3.05 | G11: 36.33 | H11: 10.99 | I11: 4.05 | J11: 0.5 | K11: 156.84 | L11: 23.5 | M11: 96.62 | N11: 18.3 | O11: 0 | P11: 0.36 | Q11: 9.24
A12: 05/07/2024 01:00 | B12: 8.28 | C12: 3.18 | D12: 12.08 | E12: 4.76 | F12: 3.61 | G12: 34.31 | H12: 9.63 | I12: 3.95 | J12: 0.33 | K12: 157.43 | L12: 23.46 | M12: 96.55 | N12: 18.4 | O12: 0 | P12: 0.34 | Q12: 9.24
A13: 05/07/2024 01:15 | B13: 8.25 | C13: 3.18 | D13: 12.05 | E13: 4.54 | F13: 3.84 | G13: 32.1 | H13: 8.14 | I13: 3.85 | J13: 0.32 | K13: 200.31 | L13: 23.4 | M13: 95.82 | N13: 18.2 | O13: 0 | P13: 0.33 | Q13: 9.24
A14: 05/07/2024 01:30 | B14: 8.24 | C14: 3.12 | D14: 12.01 | E14: 4.67 | F14: 3.82 | G14: 32.1 | H14: 8.14 | I14: 3.78 | J14: 0.08 | K14: 231.44 | L14: 23.41 | M14: 95.19 | N14: 18.2 | O14: 0 | P14: 0.33 | Q14: 9.22
A15: 05/07/2024 01:45 | B15: 8.24 | C15: 3.18 | D15: 12.05 | E15: 4.53 | F15: 2.95 | G15: 32.1 | H15: 8.14 | I15: 3.68 | J15: 0.19 | K15: 186.73 | L15: 23.38 | M15: 95.04 | N15: 18.2 | O15: 0 | P15: 0.33 | Q15: 9.23
A16: 05/07/2024 02:00 | B16: 8.28 | C16: 3.22 | D16: 12.1 | E16: 4.48 | F16: 3.15 | G16: 30.17 | H16: 8.07 | I16: 3.56 | J16: 0.43 | K16: 157.36 | L16: 23.24 | M16: 95.94 | N16: 18.2 | O16: 0 | P16: 0.32 | Q16: 9.24
A17: 05/07/2024 02:15 | B17: 8.47 | C17: 3.58 | D17: 12.44 | E17: 4.38 | F17: 3.36 | G17: 27.96 | H17: 8 | I17: 3.57 | J17: 0.27 | K17: 151.28 | L17: 23.18 | M17: 96.44 | N17: 18.2 | O17: 0 | P17: 0.3 | Q17: 9.2
A18: 05/07/2024 02:30 | B18: 8.34 | C18: 3.3 | D18: 12.18 | E18: 4.39 | F18: 3.35 | G18: 27.96 | H18: 8 | I18: 3.75 | J18: 0.19 | K18: 218.16 | L18: 23.12 | M18: 97.21 | N18: 18.1 | O18: 0 | P18: 0.31 | Q18: 9.2
A19: 05/07/2024 02:45 | B19: 8.27 | C19: 3.18 | D19: 12.06 | E19: 4.47 | F19: 3.46 | G19: 27.96 | H19: 8 | I19: 3.81 | J19: 0.34 | K19: 172.02 | L19: 23.07 | M19: 97.89 | N19: 18.1 | O19: 0 | P19: 0.3 | Q19: 9.23
A20: 05/07/2024 03:00 | B20: 8.26 | C20: 3.14 | D20: 12.04 | E20: 4.55 | F20: 3.43 | G20: 25.9 | H20: 7.4 | I20: 4.03 | J20: 0.29 | K20: 341.34 | L20: 23.16 | M20: 97.65 | N20: 18.2 | O20: 0 | P20: 0.3 | Q20: 9.24
... A104: 05/07/2024 24:00 | B104: 8.25 | C104: 3.19 | D104: 12.06 | E104: 3.66 | F104: 3.71 | G104: 34.82 | H104: 9.08 | I104: 3.68 | J104: 0.59 | K104: 355.93 | L104: 24.28 | M104: 89.72 | N104: 17.8 | O104: 0 | P104: 0.34 | Q104: 9.22
A106: Min | B106: =MIN(B9:B104) -> 8.2 | C106: =MIN(C9:C104) -> 3.08 | D106: =MIN(D9:D104) -> 11.97 | E106: =MIN(E9:E104) -> 3.11 | F106: =MIN(F9:F104) -> 2.95 | G106: =MIN(G9:G104) -> 16.42 | H106: =MIN(H9:H104) -> 3.78 | I106: =MIN(I9:I104) -> 1.19 | ... Q106: =MIN(Q9:Q104) -> 9.12
A107: Max | B107: =MAX(B9:B104) -> 8.48 | C107: =MAX(C9:C104) -> 3.9 | D107: =MAX(D9:D104) -> 12.61 | E107: =MAX(E9:E104) -> 5.23 | F107: =MAX(F9:F104) -> 5.52 | G107: =MAX(G9:G104) -> 60.35 | H107: =MAX(H9:H104) -> 16.84 | I107: =MAX(I9:I104) -> 4.45 | ... Q107: =MAX(Q9:Q104) -> 9.29
A108: Avg | B108: =AVERAGE(B9:B104) -> 8.2627083 | C108: =AVERAGE(C9:C104) -> 3.213125 | D108: =AVERAGE(D9:D104) -> 12.079375 | E108: =AVERAGE(E9:E104) -> 4.1686458 | F108: =AVERAGE(F9:F104) -> 4.0208333 | G108: =AVERAGE(G9:G104) -> 35.034271 | H108: =AVERAGE(H9:H104) -> 9.0636458 | I108: =AVERAGE(I9:I104) -> 2.5894792 | ... Q108: =AVERAGE(Q9:Q104) -> 9.2036458
A109: Stdev | B109: =STDEV(B9:B104) -> 0.046757587 | C109: =STDEV(C9:C104) -> 0.12879451 | D109: =STDEV(D9:D104) -> 0.09968173 | E109: =STDEV(E9:E104) -> 0.55705923 | F109: =STDEV(F9:F104) -> 0.58130645 | G109: =STDEV(G9:G104) -> 11.284964 | H109: =STDEV(H9:H104) -> 3.208706 | I109: =STDEV(I9:I104) -> 1.0782748 | ... Q109: =STDEV(Q9:Q104) -> 0.043142842
A110: Num | B110: =COUNT(B9:B104) -> 96 | C110: =COUNT(C9:C104) -> 96 | D110: =COUNT(D9:D104) -> 96 | E110: =COUNT(E9:E104) -> 96 | F110: =COUNT(F9:F104) -> 96 | G110: =COUNT(G9:G104) -> 96 | H110: =COUNT(H9:H104) -> 96 | I110: =COUNT(I9:I104) -> 96 | ... Q110: =COUNT(Q9:Q104) -> 96
A111: DCR | B111: =IF(B110>=87,">90%",IF(B110<=87,"<90%")) -> >90% | C111: =IF(C110>=87,">90%",IF(C110<=87,"<90%")) -> >90% | D111: =IF(D110>=87,">90%",IF(D110<=87,"<90%")) -> >90% | E111: =IF(E110>=87,">90%",IF(E110<=87,"<90%")) -> >90% | F111: =IF(F110>=87,">90%",IF(F110<=87,"<90%")) -> >90% | G111: =IF(G110>=87,">90%",IF(G110<=87,"<90%")) -> >90% | H111: =IF(H110>=87,">90%",IF(H110<=87,"<90%")) -> >90% | I111: =IF(I110>=87,">90%",IF(I110<=87,"<90%")) -> >90% | ... Q111: =IF(Q110>=87,">90%",IF(Q110<=87,"<90%")) -> >90%
A112: Status | B112: =IF(B110>=87,"OK",IF(B110<=87,"LESS")) -> OK | C112: =IF(C110>=87,"OK",IF(C110<=87,"LESS")) -> OK | D112: =IF(D110>=87,"OK",IF(D110<=87,"LESS")) -> OK | E112: =IF(E110>=87,"OK",IF(E110<=87,"LESS")) -> OK | F112: =IF(F110>=87,"OK",IF(F110<=87,"LESS")) -> OK | G112: =IF(G110>=87,"OK",IF(G110<=87,"LESS")) -> OK | H112: =IF(H110>=87,"OK",IF(H110<=87,"LESS")) -> OK | I112: =IF(I110>=87,"OK",IF(I110<=87,"LESS")) -> OK | ... Q112: =IF(Q110>=87,"OK",IF(Q110<=87,"LESS")) -> OK
A115: Done by | B115: RK
A117: Comment

Sheet 06
A1: Station: | B1: BHATAGAON RAIPUR
A2: Date: | B2: =$A$9 -> 06/07/2024 00:15 | D2: Power Off | G2: Pw.Off | L2: Link Fail | N2: Link F | P2: Maintenance | R2: Maint.
A3: Report Type: | B3: Mean | D3: Calibration | G3: Calib. | L3: Data Fail | N3: Data F | P3: Invalid | R3: Invalid
A4: Time Base: | B4: 15 Min | D4: Zero Referrence | G4: Z.Ref | L4: Warm Up | N4: Wm. Up
A7: Date & Time | B7: NO_BHATAGAON | C7: NO2__BHATAGAON | D7: NOX_BHATAGAON | E7: SO2__BHATAGAON | F7: O3__BHATAGAON | G7: PM10__BHATAGAON | H7: PM2_5__BHATAGAON | I7: BENZ__BHATAGAON | J7: WS__BHATAGAON | K7: WD__BHATAGAON | L7: TEMP__BHATAGAON | M7: HUM__BHATAGAON | N7: SR__BHATAGAON | O7: RG__BHATAGAON | P7: CO__BHATAGAON | Q7: NH3__BHATAGAON
B8: ug/m3 | C8: ug/m3 | D8: ppb | E8: ug/m3 | F8: ug/m3 | G8: ug/m3 | H8: ug/m3 | I8: ug/m3 | J8: m/sec | K8: deg | L8: degreC | M8: % | N8: w/m2 | O8: mm | P8: mg/m3 | Q8: ug/m3
A9: 06/07/2024 00:15 | B9: 8.5 | C9: 3.78 | D9: 12.57 | E9: 3.04 | F9: 3.98 | G9: 36.24 | H9: 9.65 | I9: 3.51 | J9: 0.46 | K9: 3.79 | L9: 24.1 | M9: 91.34 | N9: 17.9 | O9: 0 | P9: 0.33 | Q9: 9.19
A10: 06/07/2024 00:30 | B10: 8.3 | C10: 3.29 | D10: 12.15 | E10: 3.23 | F10: 3.3 | G10: 36.24 | H10: 9.65 | I10: 3.29 | J10: 0.38 | K10: 351.29 | L10: 23.96 | M10: 92.64 | N10: 18 | O10: 0 | P10: 0.32 | Q10: 9.2
A11: 06/07/2024 00:45 | B11: 8.2 | C11: 3.13 | D11: 11.99 | E11: 2.9 | F11: 3.5 | G11: 36.24 | H11: 9.65 | I11: 3.12 | J11: 0.34 | K11: 16.91 | L11: 23.9 | M11: 93.29 | N11: 18 | O11: 0 | P11: 0.33 | Q11: 9.2
A12: 06/07/2024 01:00 | B12: 8.21 | C12: 3.1 | D12: 11.98 | E12: 2.84 | F12: 2.61 | G12: 34.47 | H12: 9.16 | I12: 2.91 | J12: 0.33 | K12: 239.2 | L12: 23.81 | M12: 93.89 | N12: 17.9 | O12: 0 | P12: 0.32 | Q12: 9.18
A13: 06/07/2024 01:15 | B13: 8.25 | C13: 3.14 | D13: 12.03 | E13: 2.66 | F13: 3.17 | G13: 32.54 | H13: 8.62 | I13: 2.79 | J13: 0.22 | K13: 317.61 | L13: 23.68 | M13: 95.3 | N13: 18 | O13: 0 | P13: 0.3 | Q13: 9.15
A14: 06/07/2024 01:30 | B14: 8.29 | C14: 3.13 | D14: 12.05 | E14: 3.09 | F14: 3.08 | G14: 32.54 | H14: 8.62 | I14: 2.92 | J14: 0.5 | K14: 322.97 | L14: 23.58 | M14: 96.13 | N14: 18 | O14: 0 | P14: 0.3 | Q14: 9.18
A15: 06/07/2024 01:45 | B15: 8.26 | C15: 3.14 | D15: 12.04 | E15: 3.21 | F15: 3.36 | G15: 32.54 | H15: 8.62 | I15: 3.05 | J15: 0.44 | K15: 343.94 | L15: 23.5 | M15: 97 | N15: 17.9 | O15: 0 | P15: 0.3 | Q15: 9.16
A16: 06/07/2024 02:00 | B16: 8.26 | C16: 3.15 | D16: 12.05 | E16: 3.04 | F16: 3.3 | G16: 29.52 | H16: 8.46 | I16: 3.1 | J16: 0.3 | K16: 335.84 | L16: 23.42 | M16: 97.28 | N16: 17.8 | O16: 0 | P16: 0.29 | Q16: 9.18
A17: 06/07/2024 02:15 | B17: 8.26 | C17: 3.11 | D17: 12.02 | E17: 2.81 | F17: 2.72 | G17: 26.05 | H17: 8.28 | I17: 3.07 | J17: 0.36 | K17: 334.27 | L17: 23.36 | M17: 97.24 | N17: 17.8 | O17: 0 | P17: 0.29 | Q17: 9.19
A18: 06/07/2024 02:30 | B18: 8.28 | C18: 3.13 | D18: 12.05 | E18: 3.02 | F18: 3.37 | G18: 26.05 | H18: 8.28 | I18: 3.08 | J18: 0.33 | K18: 336.98 | L18: 23.36 | M18: 97.55 | N18: 17.8 | O18: 0 | P18: 0.28 | Q18: 9.2
A19: 06/07/2024 02:45 | B19: 8.27 | C19: 3.15 | D19: 12.05 | E19: 2.91 | F19: 3.47 | G19: 26.05 | H19: 8.28 | I19: 3.11 | J19: 0.32 | K19: 193.45 | L19: 23.29 | M19: 98.28 | N19: 17.8 | O19: 0 | P19: 0.28 | Q19: 9.2
A20: 06/07/2024 03:00 | B20: 8.24 | C20: 3.13 | D20: 12.01 | E20: 3.24 | F20: 3.64 | G20: 25.18 | H20: 7.78 | I20: 3.14 | J20: 0.38 | K20: 352.16 | L20: 23.29 | M20: 98.3 | N20: 17.9 | O20: 0 | P20: 0.27 | Q20: 9.23
... A104: 06/07/2024 24:00 | B104: 8.15 | C104: 3.07 | D104: 11.92 | E104: 5.55 | F104: 4.06 | G104: 52.65 | H104: 13.1 | I104: 3.96 | J104: 0.59 | K104: 11.5 | L104: 25.11 | M104: 79.7 | N104: 17.8 | O104: 0 | P104: 0.34 | Q104: 9.27
A106: Min | B106: =MIN(B9:B104) -> 8.05 | C106: =MIN(C9:C104) -> 3.02 | D106: =MIN(D9:D104) -> 11.86 | E106: =MIN(E9:E104) -> 2.47 | F106: =MIN(F9:F104) -> 2.61 | G106: =MIN(G9:G104) -> 14.3 | H106: =MIN(H9:H104) -> 3.47 | I106: =MIN(I9:I104) -> 1.15 | ... Q106: =MIN(Q9:Q104) -> 9.1
A107: Max | B107: =MAX(B9:B104) -> 8.5 | C107: =MAX(C9:C104) -> 3.78 | D107: =MAX(D9:D104) -> 12.57 | E107: =MAX(E9:E104) -> 5.55 | F107: =MAX(F9:F104) -> 6.05 | G107: =MAX(G9:G104) -> 70.93 | H107: =MAX(H9:H104) -> 17.45 | I107: =MAX(I9:I104) -> 4.09 | ... Q107: =MAX(Q9:Q104) -> 9.29
A108: Avg | B108: =AVERAGE(B9:B104) -> 8.2139583 | C108: =AVERAGE(C9:C104) -> 3.1828125 | D108: =AVERAGE(D9:D104) -> 12.024167 | E108: =AVERAGE(E9:E104) -> 4.2347917 | F108: =AVERAGE(F9:F104) -> 4.0391667 | G108: =AVERAGE(G9:G104) -> 33.583646 | H108: =AVERAGE(H9:H104) -> 9.9008333 | I108: =AVERAGE(I9:I104) -> 2.6110417 | ... Q108: =AVERAGE(Q9:Q104) -> 9.2127083
A109: Stdev | B109: =STDEV(B9:B104) -> 0.076164354 | C109: =STDEV(C9:C104) -> 0.1306478 | D109: =STDEV(D9:D104) -> 0.11977757 | E109: =STDEV(E9:E104) -> 0.64635981 | F109: =STDEV(F9:F104) -> 0.75165175 | G109: =STDEV(G9:G104) -> 18.239958 | H109: =STDEV(H9:H104) -> 3.9307494 | I109: =STDEV(I9:I104) -> 0.8287295 | ... Q109: =STDEV(Q9:Q104) -> 0.045894138
A110: Num | B110: =COUNT(B9:B104) -> 96 | C110: =COUNT(C9:C104) -> 96 | D110: =COUNT(D9:D104) -> 96 | E110: =COUNT(E9:E104) -> 96 | F110: =COUNT(F9:F104) -> 96 | G110: =COUNT(G9:G104) -> 96 | H110: =COUNT(H9:H104) -> 96 | I110: =COUNT(I9:I104) -> 96 | ... Q110: =COUNT(Q9:Q104) -> 96
A111: DCR | B111: =IF(B110>=87,">90%",IF(B110<=87,"<90%")) -> >90% | C111: =IF(C110>=87,">90%",IF(C110<=87,"<90%")) -> >90% | D111: =IF(D110>=87,">90%",IF(D110<=87,"<90%")) -> >90% | E111: =IF(E110>=87,">90%",IF(E110<=87,"<90%")) -> >90% | F111: =IF(F110>=87,">90%",IF(F110<=87,"<90%")) -> >90% | G111: =IF(G110>=87,">90%",IF(G110<=87,"<90%")) -> >90% | H111: =IF(H110>=87,">90%",IF(H110<=87,"<90%")) -> >90% | I111: =IF(I110>=87,">90%",IF(I110<=87,"<90%")) -> >90% | ... Q111: =IF(Q110>=87,">90%",IF(Q110<=87,"<90%")) -> >90%
A112: Status | B112: =IF(B110>=87,"OK",IF(B110<=87,"LESS")) -> OK | C112: =IF(C110>=87,"OK",IF(C110<=87,"LESS")) -> OK | D112: =IF(D110>=87,"OK",IF(D110<=87,"LESS")) -> OK | E112: =IF(E110>=87,"OK",IF(E110<=87,"LESS")) -> OK | F112: =IF(F110>=87,"OK",IF(F110<=87,"LESS")) -> OK | G112: =IF(G110>=87,"OK",IF(G110<=87,"LESS")) -> OK | H112: =IF(H110>=87,"OK",IF(H110<=87,"LESS")) -> OK | I112: =IF(I110>=87,"OK",IF(I110<=87,"LESS")) -> OK | ... Q112: =IF(Q110>=87,"OK",IF(Q110<=87,"LESS")) -> OK
A115: Done by | B115: RK
A117: Comment

Sheet 07
A1: Station: | B1: BHATAGAON RAIPUR
A2: Date: | B2: =$A$9 -> 07/07/2024 00:15 | D2: Power Off | G2: Pw.Off | L2: Link Fail | N2: Link F | P2: Maintenance | R2: Maint.
A3: Report Type: | B3: Mean | D3: Calibration | G3: Calib. | L3: Data Fail | N3: Data F | P3: Invalid | R3: Invalid
A4: Time Base: | B4: 15 Min | D4: Zero Referrence | G4: Z.Ref | L4: Warm Up | N4: Wm. Up
A7: Date & Time | B7: NO_BHATAGAON | C7: NO2__BHATAGAON | D7: NOX_BHATAGAON | E7: SO2__BHATAGAON | F7: O3__BHATAGAON | G7: PM10__BHATAGAON | H7: PM2_5__BHATAGAON | I7: BENZ__BHATAGAON | J7: WS__BHATAGAON | K7: WD__BHATAGAON | L7: TEMP__BHATAGAON | M7: HUM__BHATAGAON | N7: SR__BHATAGAON | O7: RG__BHATAGAON | P7: CO__BHATAGAON | Q7: NH3__BHATAGAON
B8: ug/m3 | C8: ug/m3 | D8: ppb | E8: ug/m3 | F8: ug/m3 | G8: ug/m3 | H8: ug/m3 | I8: ug/m3 | J8: m/sec | K8: deg | L8: degreC | M8: % | N8: w/m2 | O8: mm | P8: mg/m3 | Q8: ug/m3
A9: 07/07/2024 00:15 | B9: 8.21 | C9: 3.16 | D9: 12.01 | E9: 5.79 | F9: 4.3 | G9: 52.32 | H9: 12.83 | I9: 3.69 | J9: 0.54 | K9: 11.55 | L9: 24.64 | M9: 79.23 | N9: 17.7 | O9: 0 | P9: 0.33 | Q9: 9.26
A10: 07/07/2024 00:30 | B10: 8.21 | C10: 3.17 | D10: 12.01 | E10: 5.65 | F10: 4.68 | G10: 52.32 | H10: 12.83 | I10: 3.34 | J10: 0.39 | K10: 18.17 | L10: 24.33 | M10: 81.61 | N10: 17.4 | O10: 0 | P10: 0.31 | Q10: 9.24
A11: 07/07/2024 00:45 | B11: 8.21 | C11: 3.17 | D11: 12.01 | E11: 5.65 | F11: 4.68 | G11: 52.32 | H11: 12.83 | I11: 3.34 | J11: 0.39 | K11: 18.17 | L11: 24.33 | M11: 81.61 | N11: 17.4 | O11: 0 | P11: 0.31 | Q11: 9.24
A12: 07/07/2024 01:00 | B12: 8.21 | C12: 3.17 | D12: 12.02 | E12: 5.59 | F12: 4.53 | G12: 50.65 | H12: 12.11 | I12: 2.89 | J12: 0.35 | K12: 0.49 | L12: 23.86 | M12: 84.92 | N12: 17.3 | O12: 0 | P12: 0.3 | Q12: 8.66
A13: 07/07/2024 01:15 | B13: 8.2 | C13: 3.16 | D13: 12 | E13: 5.88 | F13: 4.19 | G13: 44.28 | H13: 9.24 | I13: 2.53 | J13: 0.22 | K13: 342.41 | L13: 23.65 | M13: 87.96 | N13: 17.3 | O13: 0 | P13: 0.29 | Q13: 9.22
A14: 07/07/2024 01:30 | B14: 8.18 | C14: 3.15 | D14: 11.98 | E14: 5.96 | F14: 3.75 | G14: 44.28 | H14: 9.24 | I14: 2.4 | J14: 0.5 | K14: 159.76 | L14: 23.49 | M14: 89.67 | N14: 17.3 | O14: 0 | P14: 0.29 | Q14: 9.21
A15: 07/07/2024 01:45 | B15: 8.15 | C15: 3.11 | D15: 11.94 | E15: 5.93 | F15: 4.61 | G15: 44.28 | H15: 9.24 | I15: 2.37 | J15: 0.32 | K15: 343.66 | L15: 23.47 | M15: 90.63 | N15: 17.1 | O15: 0 | P15: 0.29 | Q15: 9.19
A16: 07/07/2024 02:00 | B16: 8.15 | C16: 3.1 | D16: 11.92 | E16: 6.05 | F16: 3.5 | G16: 40.39 | H16: 9.28 | I16: 2.54 | J16: 0.56 | K16: 13.59 | L16: 23.48 | M16: 91.16 | N16: 17 | O16: 0 | P16: 0.29 | Q16: 9.19
A17: 07/07/2024 02:15 | B17: 8.14 | C17: 3.08 | D17: 11.91 | E17: 5.83 | F17: 3.62 | G17: 35.93 | H17: 9.32 | I17: 2.63 | J17: 0.51 | K17: 6.55 | L17: 23.56 | M17: 91.52 | N17: 17 | O17: 0 | P17: 0.27 | Q17: 9.19
A18: 07/07/2024 02:30 | B18: 8.16 | C18: 3.18 | D18: 11.98 | E18: 5.75 | F18: 5.08 | G18: 35.93 | H18: 9.32 | I18: 2.49 | J18: 0.62 | K18: 3.9 | L18: 23.48 | M18: 92.81 | N18: 17 | O18: 0 | P18: 0.27 | Q18: 9.18
A19: 07/07/2024 02:45 | B19: 8.16 | C19: 3.13 | D19: 11.95 | E19: 5.49 | F19: 3.85 | G19: 35.93 | H19: 9.32 | I19: 2.37 | J19: 0.56 | K19: 359.75 | L19: 23.39 | M19: 93.86 | N19: 17.3 | O19: 0 | P19: 0.27 | Q19: 9.19
A20: 07/07/2024 03:00 | B20: 8.23 | C20: 3.27 | D20: 12.08 | E20: 5.81 | F20: 4.08 | G20: 30.44 | H20: 8.22 | I20: 2.25 | J20: 0.54 | K20: 357.63 | L20: 23.31 | M20: 94.82 | N20: 17.4 | O20: 0 | P20: 0.26 | Q20: 9.18
... A104: 07/07/2024 24:00 | B104: 8.33 | C104: 3.35 | D104: 12.21 | E104: 5.04 | F104: 3.34 | G104: 56.51 | H104: 15.94 | I104: 6.25 | J104: 0.49 | K104: 176.77 | L104: 25.03 | M104: 95.22 | N104: 17.5 | O104: 0 | P104: 0.69 | Q104: 9.66
A106: Min | B106: =MIN(B9:B104) -> 8.12 | C106: =MIN(C9:C104) -> 3.03 | D106: =MIN(D9:D104) -> 11.87 | E106: =MIN(E9:E104) -> 2.95 | F106: =MIN(F9:F104) -> 2.86 | G106: =MIN(G9:G104) -> 13.88 | H106: =MIN(H9:H104) -> 3.98 | I106: =MIN(I9:I104) -> 1.2 | ... Q106: =MIN(Q9:Q104) -> 8.66
A107: Max | B107: =MAX(B9:B104) -> 8.65 | C107: =MAX(C9:C104) -> 3.8 | D107: =MAX(D9:D104) -> 12.7 | E107: =MAX(E9:E104) -> 6.05 | F107: =MAX(F9:F104) -> 5.08 | G107: =MAX(G9:G104) -> 56.51 | H107: =MAX(H9:H104) -> 16.66 | I107: =MAX(I9:I104) -> 6.25 | ... Q107: =MAX(Q9:Q104) -> 9.66
A108: Avg | B108: =AVERAGE(B9:B104) -> 8.2048958 | C108: =AVERAGE(C9:C104) -> 3.1898958 | D108: =AVERAGE(D9:D104) -> 12.020417 | E108: =AVERAGE(E9:E104) -> 4.4485417 | F108: =AVERAGE(F9:F104) -> 3.8465625 | G108: =AVERAGE(G9:G104) -> 35.076042 | H108: =AVERAGE(H9:H104) -> 9.8484375 | I108: =AVERAGE(I9:I104) -> 2.9339583 | ... Q108: =AVERAGE(Q9:Q104) -> 9.2413542
A109: Stdev | B109: =STDEV(B9:B104) -> 0.071421577 | C109: =STDEV(C9:C104) -> 0.13001615 | D109: =STDEV(D9:D104) -> 0.12252533 | E109: =STDEV(E9:E104) -> 0.8023426 | F109: =STDEV(F9:F104) -> 0.47145872 | G109: =STDEV(G9:G104) -> 11.024286 | H109: =STDEV(H9:H104) -> 3.63055 | I109: =STDEV(I9:I104) -> 1.4239142 | ... Q109: =STDEV(Q9:Q104) -> 0.1086435
A110: Num | B110: =COUNT(B9:B104) -> 96 | C110: =COUNT(C9:C104) -> 96 | D110: =COUNT(D9:D104) -> 96 | E110: =COUNT(E9:E104) -> 96 | F110: =COUNT(F9:F104) -> 96 | G110: =COUNT(G9:G104) -> 96 | H110: =COUNT(H9:H104) -> 96 | I110: =COUNT(I9:I104) -> 96 | ... Q110: =COUNT(Q9:Q104) -> 96
A111: DCR | B111: =IF(B110>=87,">90%",IF(B110<=87,"<90%")) -> >90% | C111: =IF(C110>=87,">90%",IF(C110<=87,"<90%")) -> >90% | D111: =IF(D110>=87,">90%",IF(D110<=87,"<90%")) -> >90% | E111: =IF(E110>=87,">90%",IF(E110<=87,"<90%")) -> >90% | F111: =IF(F110>=87,">90%",IF(F110<=87,"<90%")) -> >90% | G111: =IF(G110>=87,">90%",IF(G110<=87,"<90%")) -> >90% | H111: =IF(H110>=87,">90%",IF(H110<=87,"<90%")) -> >90% | I111: =IF(I110>=87,">90%",IF(I110<=87,"<90%")) -> >90% | ... Q111: =IF(Q110>=87,">90%",IF(Q110<=87,"<90%")) -> >90%
A112: Status | B112: =IF(B110>=87,"OK",IF(B110<=87,"LESS")) -> OK | C112: =IF(C110>=87,"OK",IF(C110<=87,"LESS")) -> OK | D112: =IF(D110>=87,"OK",IF(D110<=87,"LESS")) -> OK | E112: =IF(E110>=87,"OK",IF(E110<=87,"LESS")) -> OK | F112: =IF(F110>=87,"OK",IF(F110<=87,"LESS")) -> OK | G112: =IF(G110>=87,"OK",IF(G110<=87,"LESS")) -> OK | H112: =IF(H110>=87,"OK",IF(H110<=87,"LESS")) -> OK | I112: =IF(I110>=87,"OK",IF(I110<=87,"LESS")) -> OK | ... Q112: =IF(Q110>=87,"OK",IF(Q110<=87,"LESS")) -> OK
A115: Done by | B115: RK
A117: Comment

Sheet 08
A1: Station: | B1: BHATAGAON RAIPUR
A2: Date: | B2: =$A$9 -> 08/07/2024 00:15 | D2: Power Off | G2: Pw.Off | L2: Link Fail | N2: Link F | P2: Maintenance | R2: Maint.
A3: Report Type: | B3: Mean | D3: Calibration | G3: Calib. | L3: Data Fail | N3: Data F | P3: Invalid | R3: Invalid
A4: Time Base: | B4: 15 Min | D4: Zero Referrence | G4: Z.Ref | L4: Warm Up | N4: Wm. Up
A7: Date & Time | B7: NO_BHATAGAON | C7: NO2__BHATAGAON | D7: NOX_BHATAGAON | E7: SO2__BHATAGAON | F7: O3__BHATAGAON | G7: PM10__BHATAGAON | H7: PM2_5__BHATAGAON | I7: BENZ__BHATAGAON | J7: WS__BHATAGAON | K7: WD__BHATAGAON | L7: TEMP__BHATAGAON | M7: HUM__BHATAGAON | N7: SR__BHATAGAON | O7: RG__BHATAGAON | P7: CO__BHATAGAON | Q7: NH3__BHATAGAON
B8: ug/m3 | C8: ug/m3 | D8: ppb | E8: ug/m3 | F8: ug/m3 | G8: ug/m3 | H8: ug/m3 | I8: ug/m3 | J8: m/sec | K8: deg | L8: degreC | M8: % | N8: w/m2 | O8: mm | P8: mg/m3 | Q8: ug/m3
A9: 08/07/2024 00:15 | B9: 8.42 | C9: 3.47 | D9: 12.33 | E9: 5.03 | F9: 3.4 | G9: 59.24 | H9: 18.79 | I9: 6.4 | J9: 0.5 | K9: 165.59 | L9: 24.95 | M9: 96.91 | N9: 17.3 | O9: 0 | P9: 0.69 | Q9: 9.66
A10: 08/07/2024 00:30 | B10: 8.37 | C10: 3.41 | D10: 12.27 | E10: 5.23 | F10: 3.39 | G10: 59.24 | H10: 18.79 | I10: 6.57 | J10: 0.36 | K10: 198.71 | L10: 24.94 | M10: 96.67 | N10: 17.7 | O10: 0 | P10: 0.68 | Q10: 9.68
A11: 08/07/2024 00:45 | B11: 8.3 | C11: 3.31 | D11: 12.17 | E11: 4.93 | F11: 3.78 | G11: 59.24 | H11: 18.79 | I11: 6.69 | J11: 1.05 | K11: 138.06 | L11: 24.88 | M11: 97.42 | N11: 17.6 | O11: 0 | P11: 0.67 | Q11: 9.65
A12: 08/07/2024 01:00 | B12: 8.25 | C12: 3.27 | D12: 12.1 | E12: 5.43 | F12: 3.02 | G12: 53.55 | H12: 16.79 | I12: 6.73 | J12: 1.35 | K12: 142.42 | L12: 24.82 | M12: 97.29 | N12: 17.6 | O12: 0 | P12: 0.65 | Q12: 9.63
A13: 08/07/2024 01:15 | B13: 8.24 | C13: 3.16 | D13: 12.03 | E13: 5.11 | F13: 3.8 | G13: 47.33 | H13: 14.61 | I13: 6.61 | J13: 1.18 | K13: 147.04 | L13: 24.85 | M13: 96.98 | N13: 17.7 | O13: 0 | P13: 0.6 | Q13: 9.6
A14: 08/07/2024 01:30 | B14: 8.23 | C14: 3.19 | D14: 12.04 | E14: 4.93 | F14: 3.31 | G14: 47.33 | H14: 14.61 | I14: 6.53 | J14: 0.87 | K14: 147.9 | L14: 24.82 | M14: 97.33 | N14: 17.7 | O14: 0 | P14: 0.61 | Q14: 9.53
A15: 08/07/2024 01:45 | B15: 8.23 | C15: 3.24 | D15: 12.06 | E15: 5.36 | F15: 3.16 | G15: 47.33 | H15: 14.61 | I15: 6.42 | J15: 0.62 | K15: 148.85 | L15: 24.73 | M15: 97.98 | N15: 17.8 | O15: 0 | P15: 0.57 | Q15: 9.48
A16: 08/07/2024 02:00 | B16: 8.24 | C16: 3.23 | D16: 12.07 | E16: 5.05 | F16: 3.56 | G16: 42.89 | H16: 13.79 | I16: 6.25 | J16: 0.16 | K16: 31.09 | L16: 24.67 | M16: 98.01 | N16: 17.6 | O16: 0 | P16: 0.55 | Q16: 9.48
A17: 08/07/2024 02:15 | B17: 8.35 | C17: 3.41 | D17: 12.26 | E17: 5.12 | F17: 3.44 | G17: 37.81 | H17: 12.9 | I17: 6.07 | J17: 0.34 | K17: 5.47 | L17: 24.5 | M17: 98.29 | N17: 17.6 | O17: 0 | P17: 0.53 | Q17: 9.48
A18: 08/07/2024 02:30 | B18: 8.41 | C18: 3.49 | D18: 12.35 | E18: 4.9 | F18: 2.84 | G18: 37.81 | H18: 12.9 | I18: 5.94 | J18: 0.33 | K18: 156.88 | L18: 24.53 | M18: 98.19 | N18: 17.4 | O18: 0 | P18: 0.51 | Q18: 9.46
A19: 08/07/2024 02:45 | B19: 8.22 | C19: 3.16 | D19: 12.02 | E19: 5.25 | F19: 3.38 | G19: 37.81 | H19: 12.9 | I19: 5.82 | J19: 0.66 | K19: 157 | L19: 24.57 | M19: 97.17 | N19: 17.4 | O19: 0 | P19: 0.49 | Q19: 9.41
A20: 08/07/2024 03:00 | B20: 8.2 | C20: 3.11 | D20: 11.98 | E20: 4.86 | F20: 3.97 | G20: 38.14 | H20: 12.71 | I20: 5.69 | J20: 0.94 | K20: 142.87 | L20: 24.6 | M20: 95.92 | N20: 17.6 | O20: 0 | P20: 0.49 | Q20: 9.4
... A104: 08/07/2024 24:00 | B104: 8.29 | C104: 3.19 | D104: 12.09 | E104: 4.33 | F104: 2.75 | G104: 64.88 | H104: 17.28 | I104: 7.04 | J104: 1.41 | K104: 148.45 | L104: 25.64 | M104: 96.83 | N104: 17.4 | O104: 0 | P104: 0.73 | Q104: 9.7
A106: Min | B106: =MIN(B9:B104) -> 8.11 | C106: =MIN(C9:C104) -> 3.06 | D106: =MIN(D9:D104) -> 11.88 | E106: =MIN(E9:E104) -> 2.36 | F106: =MIN(F9:F104) -> 2.58 | G106: =MIN(G9:G104) -> 9.25 | H106: =MIN(H9:H104) -> 3.95 | I106: =MIN(I9:I104) -> 2.89 | ... Q106: =MIN(Q9:Q104) -> 0
A107: Max | B107: =MAX(B9:B104) -> 8.42 | C107: =MAX(C9:C104) -> 3.49 | D107: =MAX(D9:D104) -> 12.35 | E107: =MAX(E9:E104) -> 5.93 | F107: =MAX(F9:F104) -> 8.26 | G107: =MAX(G9:G104) -> 85.52 | H107: =MAX(H9:H104) -> 23.29 | I107: =MAX(I9:I104) -> 7.13 | ... Q107: =MAX(Q9:Q104) -> 9.8
A108: Avg | B108: =AVERAGE(B9:B104) -> 8.2460417 | C108: =AVERAGE(C9:C104) -> 3.220625 | D108: =AVERAGE(D9:D104) -> 12.070208 | E108: =AVERAGE(E9:E104) -> 4.5475 | F108: =AVERAGE(F9:F104) -> 3.8488542 | G108: =AVERAGE(G9:G104) -> 40.199167 | H108: =AVERAGE(H9:H104) -> 13.021771 | I108: =AVERAGE(I9:I104) -> 5.4575 | ... Q108: =AVERAGE(Q9:Q104) -> 8.8040625
A109: Stdev | B109: =STDEV(B9:B104) -> 0.059585925 | C109: =STDEV(C9:C104) -> 0.097070918 | D109: =STDEV(D9:D104) -> 0.093425784 | E109: =STDEV(E9:E104) -> 0.52800718 | F109: =STDEV(F9:F104) -> 1.0722302 | G109: =STDEV(G9:G104) -> 21.767789 | H109: =STDEV(H9:H104) -> 6.1948697 | I109: =STDEV(I9:I104) -> 1.3450361 | ... Q109: =STDEV(Q9:Q104) -> 2.2914268
A110: Num | B110: =COUNT(B9:B104) -> 96 | C110: =COUNT(C9:C104) -> 96 | D110: =COUNT(D9:D104) -> 96 | E110: =COUNT(E9:E104) -> 96 | F110: =COUNT(F9:F104) -> 96 | G110: =COUNT(G9:G104) -> 96 | H110: =COUNT(H9:H104) -> 96 | I110: =COUNT(I9:I104) -> 96 | ... Q110: =COUNT(Q9:Q104) -> 96
A111: DCR | B111: =IF(B110>=87,">90%",IF(B110<=87,"<90%")) -> >90% | C111: =IF(C110>=87,">90%",IF(C110<=87,"<90%")) -> >90% | D111: =IF(D110>=87,">90%",IF(D110<=87,"<90%")) -> >90% | E111: =IF(E110>=87,">90%",IF(E110<=87,"<90%")) -> >90% | F111: =IF(F110>=87,">90%",IF(F110<=87,"<90%")) -> >90% | G111: =IF(G110>=87,">90%",IF(G110<=87,"<90%")) -> >90% | H111: =IF(H110>=87,">90%",IF(H110<=87,"<90%")) -> >90% | I111: =IF(I110>=87,">90%",IF(I110<=87,"<90%")) -> >90% | ... Q111: =IF(Q110>=87,">90%",IF(Q110<=87,"<90%")) -> >90%
A112: Status | B112: =IF(B110>=87,"OK",IF(B110<=87,"LESS")) -> OK | C112: =IF(C110>=87,"OK",IF(C110<=87,"LESS")) -> OK | D112: =IF(D110>=87,"OK",IF(D110<=87,"LESS")) -> OK | E112: =IF(E110>=87,"OK",IF(E110<=87,"LESS")) -> OK | F112: =IF(F110>=87,"OK",IF(F110<=87,"LESS")) -> OK | G112: =IF(G110>=87,"OK",IF(G110<=87,"LESS")) -> OK | H112: =IF(H110>=87,"OK",IF(H110<=87,"LESS")) -> OK | I112: =IF(I110>=87,"OK",IF(I110<=87,"LESS")) -> OK | ... Q112: =IF(Q110>=87,"OK",IF(Q110<=87,"LESS")) -> OK
A115: Done by | B115: RK
A117: Comment

Sheet 09
A1: Station: | B1: BHATAGAON RAIPUR
A2: Date: | B2: =$A$9 -> 09/07/2024 00:15 | D2: Power Off | G2: Pw.Off | L2: Link Fail | N2: Link F | P2: Maintenance | R2: Maint.
A3: Report Type: | B3: Mean | D3: Calibration | G3: Calib. | L3: Data Fail | N3: Data F | P3: Invalid | R3: Invalid
A4: Time Base: | B4: 15 Min | D4: Zero Referrence | G4: Z.Ref | L4: Warm Up | N4: Wm. Up
A7: Date & Time | B7: NO_BHATAGAON | C7: NO2__BHATAGAON | D7: NOX_BHATAGAON | E7: SO2__BHATAGAON | F7: O3__BHATAGAON | G7: PM10__BHATAGAON | H7: PM2_5__BHATAGAON | I7: BENZ__BHATAGAON | J7: WS__BHATAGAON | K7: WD__BHATAGAON | L7: TEMP__BHATAGAON | M7: HUM__BHATAGAON | N7: SR__BHATAGAON | O7: RG__BHATAGAON | P7: CO__BHATAGAON | Q7: NH3__BHATAGAON
B8: ug/m3 | C8: ug/m3 | D8: ppb | E8: ug/m3 | F8: ug/m3 | G8: ug/m3 | H8: ug/m3 | I8: ug/m3 | J8: m/sec | K8: deg | L8: degreC | M8: % | N8: w/m2 | O8: mm | P8: mg/m3 | Q8: ug/m3
A9: 09/07/2024 00:15 | B9: 8.29 | C9: 3.21 | D9: 12.1 | E9: 3.82 | F9: 3.18 | G9: 57.41 | H9: 16.48 | I9: 6.93 | J9: 1.29 | K9: 155.43 | L9: 25.2 | M9: 96.83 | N9: 18 | O9: 0 | P9: 0.7 | Q9: 9.7
A10: 09/07/2024 00:30 | B10: 8.37 | C10: 3.41 | D10: 12.26 | E10: 4.08 | F10: 4 | G10: 57.41 | H10: 16.48 | I10: 6.85 | J10: 1.7 | K10: 147.45 | L10: 24.6 | M10: 90.94 | N10: 18.3 | O10: 0 | P10: 0.67 | Q10: 9.72
A11: 09/07/2024 00:45 | B11: 8.34 | C11: 3.39 | D11: 12.24 | E11: 4.21 | F11: 3.35 | G11: 57.41 | H11: 16.48 | I11: 6.74 | J11: 0.66 | K11: 162.86 | L11: 24.16 | M11: 93.18 | N11: 18.2 | O11: 0 | P11: 0.65 | Q11: 9.63
A12: 09/07/2024 01:00 | B12: 8.33 | C12: 3.41 | D12: 12.24 | E12: 3.8 | F12: 3.11 | G12: 48.19 | H12: 14.31 | I12: 6.72 | J12: 0.3 | K12: 173.86 | L12: 23.75 | M12: 96.22 | N12: 18.2 | O12: 0 | P12: 0.61 | Q12: 9.58
A13: 09/07/2024 01:15 | B13: 8.26 | C13: 3.24 | D13: 12.1 | E13: 3.75 | F13: 3.63 | G13: 38.13 | H13: 11.95 | I13: 6.52 | J13: 0.48 | K13: 157.73 | L13: 23.48 | M13: 98.09 | N13: 17.8 | O13: 0 | P13: 0.53 | Q13: 9.59
A14: 09/07/2024 01:30 | B14: 8.25 | C14: 3.21 | D14: 12.07 | E14: 3.82 | F14: 4 | G14: 38.13 | H14: 11.95 | I14: 6.15 | J14: 0.08 | K14: 235.68 | L14: 23.29 | M14: 98.2 | N14: 17.4 | O14: 0 | P14: 0.54 | Q14: 9.58
A15: 09/07/2024 01:45 | B15: 8.23 | C15: 3.2 | D15: 12.05 | E15: 3.92 | F15: 2.6 | G15: 38.13 | H15: 11.95 | I15: 5.83 | J15: 0.4 | K15: 164.63 | L15: 23.15 | M15: 98.03 | N15: 17.4 | O15: 0 | P15: 0.51 | Q15: 9.5
A16: 09/07/2024 02:00 | B16: 8.21 | C16: 3.17 | D16: 12.01 | E16: 3.87 | F16: 3.19 | G16: 30.89 | H16: 10.32 | I16: 5.58 | J16: 0.58 | K16: 181 | L16: 23.04 | M16: 97.8 | N16: 17.2 | O16: 0 | P16: 0.48 | Q16: 9.5
A17: 09/07/2024 02:15 | B17: 8.21 | C17: 3.13 | D17: 12 | E17: 3.93 | F17: 3.68 | G17: 22.62 | H17: 8.46 | I17: 5.31 | J17: 0.67 | K17: 130.87 | L17: 23.06 | M17: 97.8 | N17: 17.2 | O17: 0 | P17: 0.46 | Q17: 9.52
A18: 09/07/2024 02:30 | B18: 8.23 | C18: 3.16 | D18: 12.03 | E18: 3.54 | F18: 3.89 | G18: 22.62 | H18: 8.46 | I18: 5.08 | J18: 0.21 | K18: 47.23 | L18: 23.03 | M18: 98.31 | N18: 17.2 | O18: 0 | P18: 0.45 | Q18: 9.47
A19: 09/07/2024 02:45 | B19: 8.25 | C19: 3.18 | D19: 12.05 | E19: 3.49 | F19: 3.87 | G19: 22.62 | H19: 8.46 | I19: 5.03 | J19: 0.72 | K19: 314.81 | L19: 22.97 | M19: 98.32 | N19: 17.4 | O19: 0 | P19: 0.44 | Q19: 9.45
A20: 09/07/2024 03:00 | B20: 8.26 | C20: 3.18 | D20: 12.05 | E20: 3.7 | F20: 3.08 | G20: 21.13 | H20: 7.42 | I20: 5.14 | J20: 0.53 | K20: 176.5 | L20: 22.9 | M20: 98.24 | N20: 17.2 | O20: 0 | P20: 0.43 | Q20: 9.48
... A104: 09/07/2024 24:00 | B104: 8.22 | C104: 3.2 | D104: 12.04 | E104: 4.65 | F104: 4.14 | G104: 22.57 | H104: 8.57 | I104: 4.77 | J104: 0.33 | K104: 349.99 | L104: 23.67 | M104: 96.53 | N104: 17.8 | O104: 0 | P104: 0.45 | Q104: 9.48
A106: Min | B106: =MIN(B9:B104) -> 8.18 | C106: =MIN(C9:C104) -> 3.1 | D106: =MIN(D9:D104) -> 11.95 | E106: =MIN(E9:E104) -> 3.2 | F106: =MIN(F9:F104) -> 2.41 | G106: =MIN(G9:G104) -> 10.6 | H106: =MIN(H9:H104) -> 1.19 | I106: =MIN(I9:I104) -> 2.89 | ... Q106: =MIN(Q9:Q104) -> 9.24
