Workbook

Sheet 01
A1: Station: | B1: BHATAGAON RAIPPUR
A2: Date: | B2: =$A$9 -> 01-04-2024 00:15 | D2: Power Off | G2: Pw.Off | L2: Link Fail | N2: Link F | P2: Maintenance | R2: Maint.
A3: Report Type: | B3: Mean | D3: Calibration | G3: Calib. | L3: Data Fail | N3: Data F | P3: Invalid | R3: Invalid
A4: Time Base: | B4: 15 Min | D4: Zero Referrence | G4: Z.Ref | L4: Warm Up | N4: Wm. Up
A7: Date & Time | B7: NO_BHATAGAON | C7: NO2__BHATAGAON | D7: NOX_BHATAGAON | E7: SO2__BHATAGAON | F7: O3__BHATAGAON | G7: PM10__BHATAGAON | H7: PM2_5__BHATAGAON | I7: BENZ__BHATAGAON | J7: WS__BHATAGAON | K7: WD__BHATAGAON | L7: TEMP__BHATAGAON | M7: HUM__BHATAGAON | N7: SR__BHATAGAON | O7: RG__BHATAGAON | P7: CO__BHATAGAON | Q7: NH3__BHATAGAON
B8: ug/m3 | C8: ug/m3 | D8: ppb | E8: ug/m3 | F8: ug/m3 | G8: ug/m3 | H8: ug/m3 | I8: ug/m3 | J8: m/sec | K8: deg | L8: degreC | M8: % | N8: w/m2 | O8: mm | P8: mg/m3 | Q8: ug/m3
A9: 01-04-2024 00:15 | B9: 5.93 | C9: 45.57 | D9: 28.49 | E9: 0.71 | F9: 3.98 | G9: 36.85 | H9: 20.48 | I9: 4.42 | J9: 0.02 | K9: 123.29 | L9: 25.37 | M9: 52.16 | N9: 26.4 | O9: 0 | P9: 0.51 | Q9: 9.63
A10: 01-04-2024 00:30 | B10: 6.1 | C10: 44.77 | D10: 28.2 | E10: 1.12 | F10: 3.82 | G10: 36.85 | H10: 20.48 | I10: 5.66 | J10: 0.09 | K10: 261.3 | L10: 24.97 | M10: 55.85 | N10: 26.4 | O10: 0 | P10: 0.51 | Q10: 9.56
A11: 01-04-2024 00:45 | B11: 6.64 | C11: 44.04 | D11: 28.25 | E11: 1.32 | F11: 3.76 | G11: 38.13 | H11: 21.51 | I11: 5.59 | J11: 0.38 | K11: 164.39 | L11: 25.01 | M11: 53.85 | N11: 25.7 | O11: 0 | P11: 0.51 | Q11: 9.67
A12: 01-04-2024 01:00 | B12: 6.68 | C12: 43.44 | D12: 27.97 | E12: 1.19 | F12: 3.84 | G12: 39.74 | H12: 22.78 | I12: 5.72 | J12: 0.06 | K12: 353.24 | L12: 24.61 | M12: 57.34 | N12: 26.6 | O12: 0 | P12: 0.5 | Q12: 9.63
A13: 01-04-2024 01:15 | B13: 6.52 | C13: 42.4 | D13: 27.3 | E13: 1.4 | F13: 3.69 | G13: 39.74 | H13: 22.78 | I13: 5.61 | J13: 0.06 | K13: 250.91 | L13: 24.34 | M13: 58.6 | N13: 26.3 | O13: 0 | P13: 0.49 | Q13: 9.71
A14: 01-04-2024 01:30 | B14: 6.39 | C14: 41.49 | D14: 26.72 | E14: 1.11 | F14: 3.79 | G14: 39.74 | H14: 22.78 | I14: 5.61 | J14: 0.02 | K14: 182.78 | L14: 24 | M14: 63.44 | N14: 26.4 | O14: 0 | P14: 0.51 | Q14: 9.54
A15: 01-04-2024 01:45 | B15: 6.4 | C15: 41 | D15: 26.48 | E15: 1.21 | F15: 3.77 | G15: 38.37 | H15: 21.81 | I15: 5.6 | J15: 0.25 | K15: 247.54 | L15: 24.12 | M15: 60.59 | N15: 25.9 | O15: 0 | P15: 0.51 | Q15: 9.49
A16: 01-04-2024 02:00 | B16: 6.54 | C16: 40.94 | D16: 26.55 | E16: 1.1 | F16: 3.91 | G16: 36.59 | H16: 20.6 | I16: 5.25 | J16: 0.23 | K16: 308.37 | L16: 23.78 | M16: 64.19 | N16: 26.5 | O16: 0 | P16: 0.5 | Q16: 9.56
A17: 01-04-2024 02:15 | B17: 6.69 | C17: 40.47 | D17: 26.43 | E17: 1.16 | F17: 3.49 | G17: 36.59 | H17: 20.6 | I17: 5.54 | J17: 0.22 | K17: 230.05 | L17: 23.57 | M17: 63.07 | N17: 26 | O17: 0 | P17: 0.51 | Q17: 9.67
A18: 01-04-2024 02:30 | B18: 6.7 | C18: 40.74 | D18: 26.58 | E18: 1.12 | F18: 3.54 | G18: 36.59 | H18: 20.6 | I18: 5.46 | J18: 0.24 | K18: 239.46 | L18: 24.04 | M18: 58.39 | N18: 26 | O18: 0 | P18: 0.5 | Q18: 9.59
A19: 01-04-2024 02:45 | B19: 6.61 | C19: 40.87 | D19: 26.58 | E19: 1.3 | F19: 3.39 | G19: 36.08 | H19: 20.29 | I19: 5.14 | J19: 0.23 | K19: 237.09 | L19: 23.94 | M19: 58.6 | N19: 26.2 | O19: 0 | P19: 0.49 | Q19: 9.45
A20: 01-04-2024 03:00 | B20: 6.7 | C20: 41.38 | D20: 26.91 | E20: 0.9 | F20: 3.56 | G20: 35.41 | H20: 19.9 | I20: 4.93 | J20: 0.26 | K20: 221.64 | L20: 23.94 | M20: 58.37 | N20: 26 | O20: 0 | P20: 0.48 | Q20: 9.53
... A54: 01-04-2024 11:30 | B54: 1.13 | C54: 42.3 | D54: 22.93 | E54: 2.75 | F54: 13.68 | G54: 54.24 | H54: 23.72 | I54: 2.68 | J54: 0.54 | K54: 324.66 | L54: 36.84 | M54: 26.27 | N54: 920.5 | O54: 0 | P54: 0.51 | Q54: 9.38
A55: 01-04-2024 11:45 | B55: 1.01 | C55: 43.48 | D55: 23.44 | E55: Calib. | F55: 17.41 | G55: 11.45 | H55: 5.01 | I55: 2.54 | J55: 0.45 | K55: 340.88 | L55: 36.69 | M55: 24.38 | N55: 922.7 | O55: 0 | P55: 0.51 | Q55: 9.44
A56: 01-04-2024 12:00 | B56: 0.78 | C56: 41.44 | D56: 22.19 | E56: Calib. | F56: 18.22 | G56: Calib. | H56: Calib. | I56: 2.71 | J56: 0.5 | K56: 332.72 | L56: 36.58 | M56: 23.78 | N56: 913.9 | O56: 0 | P56: 0.5 | Q56: 9.37
A57: 01-04-2024 12:15 | B57: Calib. | C57: Calib. | D57: Calib. | E57: 6 | F57: 18.06 | G57: Calib. | H57: Calib. | I57: 3.89 | J57: 0.34 | K57: 348.38 | L57: 35.78 | M57: 23.38 | N57: 913.9 | O57: 0 | P57: 0.48 | Q57: 9.3
A58: 01-04-2024 12:30 | B58: Calib. | C58: Calib. | D58: Calib. | E58: 2.39 | F58: 18.01 | G58: Calib. | H58: Calib. | I58: 5.34 | J58: 0.44 | K58: 343.22 | L58: 36.78 | M58: 22.34 | N58: 853.2 | O58: 0 | P58: 3.3 | Q58: 9.4
A59: 01-04-2024 12:45 | B59: 0.41 | C59: 44.29 | D59: 23.39 | E59: 2.43 | F59: 16.91 | G59: 66.43 | H59: 18.31 | I59: 6.08 | J59: 0.1 | K59: 350.52 | L59: 35.79 | M59: 21.97 | N59: 895.3 | O59: 0 | P59: 0.49 | Q59: 9.35
A60: 01-04-2024 13:00 | B60: 0.39 | C60: 42.06 | D60: 22.21 | E60: 2.69 | F60: 16.18 | G60: 66.43 | H60: 18.31 | I60: 6.43 | J60: 0.29 | K60: 5.03 | L60: 36.1 | M60: 21.59 | N60: 867 | O60: 0 | P60: 0.48 | Q60: 9.32
A61: 01-04-2024 13:15 | B61: 0.5 | C61: 41.2 | D61: 21.85 | E61: 2.45 | F61: 12.06 | G61: 66.43 | H61: 18.31 | I61: 6.25 | J61: 0.3 | K61: 332.06 | L61: 36.75 | M61: 21 | N61: 847 | O61: 0 | P61: 0.44 | Q61: 9.35
A62: 01-04-2024 13:30 | B62: 0.54 | C62: 39.52 | D62: 21.01 | E62: 2.21 | F62: 13.5 | G62: 66.43 | H62: 18.31 | I62: 5.41 | J62: 0.27 | K62: 2.95 | L62: 36.09 | M62: 20.99 | N62: 756.1 | O62: 0 | P62: 0.47 | Q62: 9.31
A63: 01-04-2024 13:45 | B63: 0.57 | C63: 50.62 | D63: 26.82 | E63: 3.2 | F63: 13.62 | G63: 64.1 | H63: 21.66 | I63: 5.11 | J63: 0.35 | K63: 355.44 | L63: 36.89 | M63: 20.86 | N63: 774.2 | O63: 0 | P63: 0.48 | Q63: 9.51
A64: 01-04-2024 14:00 | B64: 0.6 | C64: 57.78 | D64: 30.59 | E64: 2.08 | F64: 11.43 | G64: 63.51 | H64: 22.49 | I64: 4.78 | J64: 0.3 | K64: 347.51 | L64: 36.81 | M64: 20.97 | N64: 626.9 | O64: 0 | P64: 0.48 | Q64: 9.35
A65: 01-04-2024 14:15 | B65: 0.7 | C65: 58.45 | D65: 31.02 | E65: 2.2 | F65: 8.78 | G65: 63.51 | H65: 22.49 | I65: 4.41 | J65: 0.49 | K65: 338.87 | L65: 36.5 | M65: 21.59 | N65: 592.6 | O65: 0 | P65: 0.48 | Q65: 9.47
A66: 01-04-2024 14:30 | B66: 0.68 | C66: 57.65 | D66: 30.58 | E66: 2.54 | F66: 9.25 | G66: 63.51 | H66: 22.49 | I66: 4.17 | J66: 0.29 | K66: 349.33 | L66: 36.31 | M66: 21.62 | N66: 594 | O66: 0 | P66: 0.48 | Q66: 9.44
A67: 01-04-2024 14:45 | B67: 0.59 | C67: 40.87 | D67: 21.75 | E67: 2.25 | F67: 10.2 | G67: 56.36 | H67: 24.08 | I67: 3.97 | J67: 0.38 | K67: 327.34 | L67: 36.48 | M67: 21.79 | N67: 591.4 | O67: 0 | P67: 0.48 | Q67: 9.79
A68: 01-04-2024 15:00 | B68: 0.77 | C68: 55.97 | D68: 29.78 | E68: 2.77 | F68: 13.31 | G68: 54.58 | H68: 24.48 | I68: 3.72 | J68: 0.17 | K68: 339.31 | L68: 35.74 | M68: 22.1 | N68: 542.5 | O68: 0 | P68: 0.46 | Q68: 9.58
A69: 01-04-2024 15:15 | B69: 0.57 | C69: 35 | D69: 18.67 | E69: 2.73 | F69: 11.56 | G69: 54.58 | H69: 24.48 | I69: 3.52 | J69: 0.12 | K69: 336.84 | L69: 35.41 | M69: 22.94 | N69: 361.4 | O69: 0 | P69: 0.45 | Q69: 9.23
A70: 01-04-2024 15:30 | B70: 0.84 | C70: 58.09 | D70: 30.94 | E70: 2.64 | F70: 9.74 | G70: 54.58 | H70: 24.48 | I70: 3.29 | J70: 0.13 | K70: 333.39 | L70: 35.74 | M70: 21.42 | N70: 247 | O70: 0 | P70: 0.44 | Q70: 9.63
... A104: 01-04-2024 24:00 | B104: 44.59 | C104: 67.03 | D104: 70.7 | E104: 3.02 | F104: 4.01 | G104: 72.87 | H104: 16.39 | I104: 7.55 | J104: 0.18 | K104: 250.33 | L104: 26.14 | M104: 46.57 | N104: 39.4 | O104: 0 | P104: 1.29 | Q104: 10.39
A106: Min | B106: =MIN(B9:B104) -> 0.39 | C106: =MIN(C9:C104) -> 17.9 | D106: =MIN(D9:D104) -> 11.19 | E106: =MIN(E9:E104) -> 0.18 | F106: =MIN(F9:F104) -> 3.31 | G106: =MIN(G9:G104) -> 11.45 | H106: =MIN(H9:H104) -> 5.01 | I106: =MIN(I9:I104) -> 2.4 | ... Q106: =MIN(Q9:Q104) -> 9.16
A107: Max | B107: =MAX(B9:B104) -> 46.22 | C107: =MAX(C9:C104) -> 67.34 | D107: =MAX(D9:D104) -> 72.06 | E107: =MAX(E9:E104) -> 6 | F107: =MAX(F9:F104) -> 254.75 | G107: =MAX(G9:G104) -> 82.19 | H107: =MAX(H9:H104) -> 34.41 | I107: =MAX(I9:I104) -> 7.71 | ... Q107: =MAX(Q9:Q104) -> 10.45
A108: Avg | B108: =AVERAGE(B9:B104) -> 9.032234 | C108: =AVERAGE(C9:C104) -> 49.322872 | D108: =AVERAGE(D9:D104) -> 32.930638 | E108: =AVERAGE(E9:E104) -> 1.7726596 | F108: =AVERAGE(F9:F104) -> 18.798854 | G108: =AVERAGE(G9:G104) -> 52.116989 | H108: =AVERAGE(H9:H104) -> 22.197849 | I108: =AVERAGE(I9:I104) -> 4.916875 | ... Q108: =AVERAGE(Q9:Q104) -> 9.5986458
A109: Stdev | B109: =STDEV(B9:B104) -> 11.577264 | C109: =STDEV(C9:C104) -> 9.768675 | D109: =STDEV(D9:D104) -> 13.111015 | E109: =STDEV(E9:E104) -> 0.97610613 | F109: =STDEV(F9:F104) -> 50.981659 | G109: =STDEV(G9:G104) -> 15.515928 | H109: =STDEV(H9:H104) -> 4.7589273 | I109: =STDEV(I9:I104) -> 1.4217427 | ... Q109: =STDEV(Q9:Q104) -> 0.24148497
...

Sheet 02
A1: Station: | B1: BHATAGAON RAIPUR
A2: Date: | B2: =$A$9 -> 02-04-2024 00:15 | D2: Power Off | G2: Pw.Off | L2: Link Fail | N2: Link F | P2: Maintenance | R2: Maint.
A3: Report Type: | B3: Mean | D3: Calibration | G3: Calib. | L3: Data Fail | N3: Data F | P3: Invalid | R3: Invalid
A4: Time Base: | B4: 15 Min | D4: Zero Referrence | G4: Z.Ref | L4: Warm Up | N4: Wm. Up
A7: Date & Time | B7: NO_BHATAGAON | C7: NO2__BHATAGAON | D7: NOX_BHATAGAON | E7: SO2__BHATAGAON | F7: O3__BHATAGAON | G7: PM10__BHATAGAON | H7: PM2_5__BHATAGAON | I7: BENZ__BHATAGAON | J7: WS__BHATAGAON | K7: WD__BHATAGAON | L7: TEMP__BHATAGAON | M7: HUM__BHATAGAON | N7: SR__BHATAGAON | O7: RG__BHATAGAON | P7: CO__BHATAGAON | Q7: NH3__BHATAGAON
B8: ug/m3 | C8: ug/m3 | D8: ppb | E8: ug/m3 | F8: ug/m3 | G8: ug/m3 | H8: ug/m3 | I8: ug/m3 | J8: m/sec | K8: deg | L8: degreC | M8: % | N8: w/m2 | O8: mm | P8: mg/m3 | Q8: ug/m3
A9: 02-04-2024 00:15 | B9: 41.77 | C9: 65.98 | D9: 67.89 | E9: 2.66 | F9: 3.92 | G9: 72.87 | H9: 16.39 | I9: 7.44 | J9: 0.07 | K9: 273.89 | L9: 26.01 | M9: 47.67 | N9: 40 | O9: 0 | P9: 1.24 | Q9: 10.24
A10: 02-04-2024 00:30 | B10: 38.79 | C10: 64.79 | D10: 64.88 | E10: 2.85 | F10: 3.29 | G10: 72.87 | H10: 16.39 | I10: 8.23 | J10: 0.32 | K10: 340.08 | L10: 25.56 | M10: 51.22 | N10: 41.1 | O10: 0 | P10: 1.2 | Q10: 10.27
A11: 02-04-2024 00:45 | B11: 36.23 | C11: 63.98 | D11: 62.4 | E11: 2.46 | F11: 3.76 | G11: 64.92 | H11: 14.51 | I11: 7.97 | J11: 0.6 | K11: 345.25 | L11: 24.92 | M11: 55.15 | N11: 41.3 | O11: 0 | P11: 1.18 | Q11: 9.99
A12: 02-04-2024 01:00 | B12: 33.66 | C12: 63.34 | D12: 60.01 | E12: 2.57 | F12: 3.65 | G12: 62.93 | H12: 14.04 | I12: 7.71 | J12: 0.68 | K12: 332.17 | L12: 24.96 | M12: 51.94 | N12: 41.3 | O12: 0 | P12: 1.14 | Q12: 10.05
A13: 02-04-2024 01:15 | B13: 31.02 | C13: 62.81 | D13: 57.61 | E13: 2.4 | F13: 3.81 | G13: 62.93 | H13: 14.04 | I13: 7.86 | J13: 0.43 | K13: 330.08 | L13: 25.09 | M13: 50.43 | N13: 42.6 | O13: 0 | P13: 0.99 | Q13: 9.97
A14: 02-04-2024 01:30 | B14: 28.62 | C14: 62.54 | D14: 55.55 | E14: 2.5 | F14: 3.79 | G14: 62.93 | H14: 14.04 | I14: 7.75 | J14: 0.1 | K14: 341.68 | L14: 25.13 | M14: 48.49 | N14: 43.7 | O14: 0 | P14: 0.96 | Q14: 10.14
A15: 02-04-2024 01:45 | B15: 27.38 | C15: 55.12 | D15: 50.67 | E15: 2.32 | F15: 3.35 | G15: 61.82 | H15: 13.54 | I15: 7.49 | J15: 0.07 | K15: 61.71 | L15: 25.39 | M15: 46.12 | N15: 45.4 | O15: 0 | P15: 0.92 | Q15: 10.24
A16: 02-04-2024 02:00 | B16: 26.65 | C16: 52.4 | D16: 48.67 | E16: 2.41 | F16: 3.76 | G16: 61.54 | H16: 13.42 | I16: 6.62 | J16: 0.08 | K16: 264.68 | L16: 25.4 | M16: 45.66 | N16: 46.7 | O16: 0 | P16: 0.88 | Q16: 9.85
A17: 02-04-2024 02:15 | B17: 25.83 | C17: 52.26 | D17: 47.94 | E17: 2.06 | F17: 3.64 | G17: 61.54 | H17: 13.42 | I17: 6.35 | J17: 0.1 | K17: 276.22 | L17: 25.05 | M17: 47.35 | N17: 47.6 | O17: 0 | P17: 0.88 | Q17: 10.08
A18: 02-04-2024 02:30 | B18: 25.14 | C18: 53.05 | D18: 47.8 | E18: 2.19 | F18: 3.77 | G18: 61.54 | H18: 13.42 | I18: 6.3 | J18: 0.08 | K18: 233.36 | L18: 24.77 | M18: 46.4 | N18: 48 | O18: 0 | P18: 0.85 | Q18: 10.01
A19: 02-04-2024 02:45 | B19: 24.5 | C19: 53.77 | D19: 47.65 | E19: 2.48 | F19: 3.6 | G19: 60.75 | H19: 12.72 | I19: 6.36 | J19: 0.19 | K19: 205.61 | L19: 25.24 | M19: 44.48 | N19: 46.7 | O19: 0 | P19: 0.84 | Q19: 9.91
A20: 02-04-2024 03:00 | B20: 23.9 | C20: 53.7 | D20: 47.14 | E20: 2.26 | F20: 3.61 | G20: 60.56 | H20: 12.55 | I20: 6.24 | J20: 0.12 | K20: 321.45 | L20: 24.71 | M20: 50.58 | N20: 46.8 | O20: 0 | P20: 0.82 | Q20: 10.01
... A104: 02-04-2024 24:00 | B104: 134.24 | C104: 77.47 | D104: 148.04 | E104: 1.63 | F104: 3.51 | G104: 131.21 | H104: 63.44 | I104: 11.31 | J104: 0.35 | K104: 358.29 | L104: 24.67 | M104: 51.34 | N104: 20.7 | O104: 0 | P104: 1.96 | Q104: 12.04
A106: Min | B106: =MIN(B9:B104) -> 3.71 | C106: =MIN(C9:C104) -> 38.16 | D106: =MIN(D9:D104) -> 22.83 | E106: =MIN(E9:E104) -> 0.89 | F106: =MIN(F9:F104) -> 3.06 | G106: =MIN(G9:G104) -> 51.42 | H106: =MIN(H9:H104) -> 11.74 | I106: =MIN(I9:I104) -> 3.87 | ... Q106: =MIN(Q9:Q104) -> 9.22
A107: Max | B107: =MAX(B9:B104) -> 134.24 | C107: =MAX(C9:C104) -> 78.64 | D107: =MAX(D9:D104) -> 148.04 | E107: =MAX(E9:E104) -> 3.52 | F107: =MAX(F9:F104) -> 11.09 | G107: =MAX(G9:G104) -> 131.21 | H107: =MAX(H9:H104) -> 627.04 | I107: =MAX(I9:I104) -> 11.31 | ... Q107: =MAX(Q9:Q104) -> 12.04
A108: Avg | B108: =AVERAGE(B9:B104) -> 25.413229 | C108: =AVERAGE(C9:C104) -> 61.615833 | D108: =AVERAGE(D9:D104) -> 52.491354 | E108: =AVERAGE(E9:E104) -> 2.02 | F108: =AVERAGE(F9:F104) -> 5.0710417 | G108: =AVERAGE(G9:G104) -> 71.760208 | H108: =AVERAGE(H9:H104) -> 196.59823 | I108: =AVERAGE(I9:I104) -> 7.909375 | ... Q108: =AVERAGE(Q9:Q104) -> 9.9989583
A109: Stdev | B109: =STDEV(B9:B104) -> 27.793623 | C109: =STDEV(C9:C104) -> 8.002197 | D109: =STDEV(D9:D104) -> 24.900405 | E109: =STDEV(E9:E104) -> 0.55785869 | F109: =STDEV(F9:F104) -> 2.4769873 | G109: =STDEV(G9:G104) -> 18.194191 | H109: =STDEV(H9:H104) -> 192.90296 | I109: =STDEV(I9:I104) -> 2.0858131 | ... Q109: =STDEV(Q9:Q104) -> 0.54751011
A110: Num | B110: =COUNT(B9:B104) -> 96 | C110: =COUNT(C9:C104) -> 96 | D110: =COUNT(D9:D104) -> 96 | E110: =COUNT(E9:E104) -> 96 | F110: =COUNT(F9:F104) -> 96 | G110: =COUNT(G9:G104) -> 96 | H110: =COUNT(H9:H104) -> 96 | I110: =COUNT(I9:I104) -> 96 | ... Q110: =COUNT(Q9:Q104) -> 96
A111: DCR | B111: =IF(B110>=87,">90%",IF(B110<=87,"<90%")) -> >90% | C111: =IF(C110>=87,">90%",IF(C110<=87,"<90%")) -> >90% | D111: =IF(D110>=87,">90%",IF(D110<=87,"<90%")) -> >90% | E111: =IF(E110>=87,">90%",IF(E110<=87,"<90%")) -> >90% | F111: =IF(F110>=87,">90%",IF(F110<=87,"<90%")) -> >90% | G111: =IF(G110>=87,">90%",IF(G110<=87,"<90%")) -> >90% | H111: =IF(H110>=87,">90%",IF(H110<=87,"<90%")) -> >90% | I111: =IF(I110>=87,">90%",IF(I110<=87,"<90%")) -> >90% | ... Q111: =IF(Q110>=87,">90%",IF(Q110<=87,"<90%")) -> >90%
A112: Status | B112: =IF(B110>=87,"OK",IF(B110<=87,"LESS")) -> OK | C112: =IF(C110>=87,"OK",IF(C110<=87,"LESS")) -> OK | D112: =IF(D110>=87,"OK",IF(D110<=87,"LESS")) -> OK | E112: =IF(E110>=87,"OK",IF(E110<=87,"LESS")) -> OK | F112: =IF(F110>=87,"OK",IF(F110<=87,"LESS")) -> OK | G112: =IF(G110>=87,"OK",IF(G110<=87,"LESS")) -> OK | H112: =IF(H110>=87,"OK",IF(H110<=87,"LESS")) -> OK | I112: =IF(I110>=87,"OK",IF(I110<=87,"LESS")) -> OK | ... Q112: =IF(Q110>=87,"OK",IF(Q110<=87,"LESS")) -> OK
A115: Done by | B115: RK
A117: Comment

Sheet 03
A1: Station: | B1: BHATAGAON RAIPUR
A2: Date: | B2: =$A$9 -> 03-04-2024 00:15 | D2: Power Off | G2: Pw.Off | L2: Link Fail | N2: Link F | P2: Maintenance | R2: Maint.
A3: Report Type: | B3: Mean | D3: Calibration | G3: Calib. | L3: Data Fail | N3: Data F | P3: Invalid | R3: Invalid
A4: Time Base: | B4: 15 Min | D4: Zero Referrence | G4: Z.Ref | L4: Warm Up | N4: Wm. Up
A7: Date & Time | B7: NO_BHATAGAON | C7: NO2__BHATAGAON | D7: NOX_BHATAGAON | E7: SO2__BHATAGAON | F7: O3__BHATAGAON | G7: PM10__BHATAGAON | H7: PM2_5__BHATAGAON | I7: BENZ__BHATAGAON | J7: WS__BHATAGAON | K7: WD__BHATAGAON | L7: TEMP__BHATAGAON | M7: HUM__BHATAGAON | N7: SR__BHATAGAON | O7: RG__BHATAGAON | P7: CO__BHATAGAON | Q7: NH3__BHATAGAON
B8: ug/m3 | C8: ug/m3 | D8: ppb | E8: ug/m3 | F8: ug/m3 | G8: ug/m3 | H8: ug/m3 | I8: ug/m3 | J8: m/sec | K8: deg | L8: degreC | M8: % | N8: w/m2 | O8: mm | P8: mg/m3 | Q8: ug/m3
A9: 03-04-2024 00:15 | B9: 131.24 | C9: 76.82 | D9: 145.3 | E9: 3.2 | F9: 3.29 | G9: 131.21 | H9: 63.44 | I9: 11.58 | J9: 0.06 | K9: 97.77 | L9: 25.46 | M9: 43.29 | N9: 21.4 | O9: 0 | P9: 1.96 | Q9: 12.15
A10: 03-04-2024 00:30 | B10: 126.76 | C10: 72.74 | D10: 139.57 | E10: 3.22 | F10: 3.63 | G10: 131.21 | H10: 63.44 | I10: 11.51 | J10: 0.1 | K10: 206.68 | L10: 25.35 | M10: 44.81 | N10: 21.8 | O10: 0 | P10: 1.95 | Q10: 11.97
A11: 03-04-2024 00:45 | B11: 123.79 | C11: 68.69 | D11: 135.07 | E11: 2.58 | F11: 3.67 | G11: 130.13 | H11: 39.51 | I11: 11.31 | J11: 0.1 | K11: 287.34 | L11: 24.9 | M11: 47.88 | N11: 22 | O11: 0 | P11: 1.94 | Q11: 11.82
A12: 03-04-2024 01:00 | B12: 121.25 | C12: 68.64 | D12: 133.01 | E12: 2.43 | F12: 3.54 | G12: 129.86 | H12: 33.53 | I12: 10.88 | J12: 0.21 | K12: 254.02 | L12: 24.2 | M12: 51.2 | N12: 22.1 | O12: 0 | P12: 1.95 | Q12: 11.88
A13: 03-04-2024 01:15 | B13: 117.93 | C13: 68.09 | D13: 130.06 | E13: 2.48 | F13: 3.69 | G13: 129.86 | H13: 33.53 | I13: 10.94 | J13: 0.92 | K13: 199.99 | L13: 25.11 | M13: 43.71 | N13: 19.8 | O13: 0 | P13: 1.71 | Q13: 11.8
A14: 03-04-2024 01:30 | B14: 110.59 | C14: 67.14 | D14: 123.68 | E14: 2.49 | F14: 3.72 | G14: 129.86 | H14: 33.53 | I14: 11.37 | J14: 0.72 | K14: 207.95 | L14: 24.44 | M14: 47.94 | N14: 22.3 | O14: 0 | P14: 1.71 | Q14: 11.66
A15: 03-04-2024 01:45 | B15: 103.91 | C15: 65.61 | D15: 117.53 | E15: 2.72 | F15: 3.25 | G15: 124.73 | H15: 42.44 | I15: 11.82 | J15: 0.4 | K15: 162.56 | L15: 23.67 | M15: 51.58 | N15: 22.4 | O15: 0 | P15: 1.58 | Q15: 11.77
A16: 03-04-2024 02:00 | B16: 99.91 | C16: 64.36 | D16: 113.66 | E16: 2.46 | F16: 3.28 | G16: 123.45 | H16: 44.67 | I16: 11.45 | J16: 0.2 | K16: 218.18 | L16: 23.69 | M16: 49.04 | N16: 21.7 | O16: 0 | P16: 1.5 | Q16: 11.64
A17: 03-04-2024 02:15 | B17: 96.44 | C17: 62.99 | D17: 110.16 | E17: 2.28 | F17: 3.19 | G17: 123.45 | H17: 44.67 | I17: 9.87 | J17: 0.2 | K17: 338.48 | L17: 23.05 | M17: 54.63 | N17: 22.6 | O17: 0 | P17: 1.49 | Q17: 11.49
A18: 03-04-2024 02:30 | B18: 92.85 | C18: 61.43 | D18: 106.47 | E18: 2.32 | F18: 3.32 | G18: 123.45 | H18: 44.67 | I18: 9.05 | J18: 0.17 | K18: 321.76 | L18: 22.44 | M18: 57.33 | N18: 22.4 | O18: 0 | P18: 1.49 | Q18: 11.46
A19: 03-04-2024 02:45 | B19: 88.35 | C19: 60.67 | D19: 102.47 | E19: 2.39 | F19: 3.16 | G19: 102.82 | H19: 48.99 | I19: 9.82 | J19: 0.17 | K19: 306.64 | L19: 22.04 | M19: 58.89 | N19: 22.2 | O19: 0 | P19: 1.43 | Q19: 11.45
A20: 03-04-2024 03:00 | B20: 83.84 | C20: 59.91 | D20: 98.46 | E20: 2.44 | F20: 3.3 | G20: 97.66 | H20: 50.07 | I20: 11.21 | J20: 0.09 | K20: 60.44 | L20: 22.23 | M20: 59.5 | N20: 22.1 | O20: 0 | P20: 1.36 | Q20: 11.28
... A76: 03-04-2024 17:00 | B76: 5.16 | C76: 61.43 | D76: 36.15 | E76: 1.33 | F76: 7.71 | G76: 62.79 | H76: 0.51 | I76: 7.88 | J76: 0.55 | K76: 79.7 | L76: 34.12 | M76: 21.91 | N76: 91.1 | O76: 0 | P76: 0.66 | Q76: 9.91
A77: 03-04-2024 17:15 | B77: 4.88 | C77: 61.6 | D77: 36.02 | E77: 1.89 | F77: 19.98 | G77: Data F | H77: Data F | I77: 7.86 | J77: 0.54 | K77: 87.53 | L77: 33.84 | M77: 21.06 | N77: 69.9 | O77: 0 | P77: 0.58 | Q77: 9.77
A78: 03-04-2024 17:30 | B78: 4.55 | C78: 61.59 | D78: 35.75 | E78: 1.77 | F78: 16.4 | G78: Data F | H78: Data F | I78: 7.61 | J78: 0.57 | K78: 81.11 | L78: 33.84 | M78: 20.81 | N78: 53.5 | O78: 0 | P78: 0.53 | Q78: 9.63
A79: 03-04-2024 17:45 | B79: 4.7 | C79: 61.29 | D79: 35.72 | E79: 1.7 | F79: 9.43 | G79: Data F | H79: Data F | I79: 6.73 | J79: 0.3 | K79: 64.18 | L79: 33.35 | M79: 22.66 | N79: 41.8 | O79: 0 | P79: 0.55 | Q79: 9.69
A80: 03-04-2024 18:00 | B80: 4.98 | C80: 67.84 | D80: 39.36 | E80: 1.69 | F80: 10.16 | G80: Data F | H80: Data F | I80: 5.78 | J80: 0.34 | K80: 62.28 | L80: 32.99 | M80: 22.54 | N80: 29.6 | O80: 0 | P80: 0.67 | Q80: 9.29
A81: 03-04-2024 18:15 | B81: 4.68 | C81: 79.19 | D81: 45.05 | E81: 1.6 | F81: 11.72 | G81: Data F | H81: Data F | I81: 5.7 | J81: 0.33 | K81: 69.18 | L81: 32.52 | M81: 25 | N81: 21 | O81: 0 | P81: 0.81 | Q81: 9.46
A82: 03-04-2024 18:30 | B82: 6.01 | C82: 80.44 | D82: 46.77 | E82: 1.61 | F82: 6.18 | G82: Data F | H82: Data F | I82: 5.8 | J82: 0.2 | K82: 14.63 | L82: 31.69 | M82: 32.39 | N82: 19.3 | O82: 0 | P82: 0.9 | Q82: 9.85
A83: 03-04-2024 18:45 | B83: 10.47 | C83: 84.49 | D83: 52.46 | E83: 1.65 | F83: 3.89 | G83: Data F | H83: Data F | I83: 5.75 | J83: 0.17 | K83: 183.84 | L83: 31.15 | M83: 28.85 | N83: 18.2 | O83: 0 | P83: 1.04 | Q83: 9.66
A84: 03-04-2024 19:00 | B84: 13.4 | C84: 83.71 | D84: 54.4 | E84: 1.54 | F84: 3.67 | G84: Data F | H84: Data F | I84: 6.1 | J84: 0.28 | K84: 1.42 | L84: 30.79 | M84: 36.8 | N84: 19 | O84: 0 | P84: 1.17 | Q84: 10.05
A85: 03-04-2024 19:15 | B85: 18.14 | C85: 85.01 | D85: 58.88 | E85: 1.51 | F85: 3.55 | G85: 146.53 | H85: 93.49 | I85: 6.75 | J85: 0.06 | K85: 27.54 | L85: 29.96 | M85: 38.55 | N85: 18.7 | O85: 0 | P85: 1.31 | Q85: 9.84
A86: 03-04-2024 19:30 | B86: 23.52 | C86: 84.98 | D86: 63.18 | E86: 1.69 | F86: 3.56 | G86: 168.97 | H86: 93.49 | I86: 7.77 | J86: 0.16 | K86: 237.89 | L86: 29.58 | M86: 36.2 | N86: 18.5 | O86: 0 | P86: 1.52 | Q86: 10.01
A87: 03-04-2024 19:45 | B87: 28.02 | C87: 84.33 | D87: 66.45 | E87: 1.76 | F87: 3.59 | G87: 168.97 | H87: 93.49 | I87: 8.91 | J87: 0.24 | K87: 245.6 | L87: 29.72 | M87: 35.67 | N87: 18.1 | O87: 0 | P87: 1.55 | Q87: 10.23
A88: 03-04-2024 20:00 | B88: 32.17 | C88: 83.93 | D88: 69.57 | E88: 1.06 | F88: 3.03 | G88: 168.97 | H88: 93.49 | I88: 9.61 | J88: 0.35 | K88: 180.43 | L88: 30.06 | M88: 31.54 | N88: 17.2 | O88: 0 | P88: 1.6 | Q88: 10.42
A89: 03-04-2024 20:15 | B89: 33.2 | C89: 82.94 | D89: 69.88 | E89: 1.6 | F89: 3.07 | G89: 163.51 | H89: 59.58 | I89: 9.87 | J89: 1.02 | K89: 155.62 | L89: 30.3 | M89: 29.97 | N89: 16.9 | O89: 0 | P89: 1.59 | Q89: 10.55
A90: 03-04-2024 20:30 | B90: 32.21 | C90: 80.87 | D90: 68 | E90: 1.61 | F90: 3.27 | G90: 161.95 | H90: 49.89 | I90: 10.33 | J90: 0.46 | K90: 163.53 | L90: 30.31 | M90: 31.02 | N90: 18 | O90: 0 | P90: 1.54 | Q90: 10.58
A91: 03-04-2024 20:45 | B91: 30.81 | C91: 77.96 | D91: 65.36 | E91: 1.21 | F91: 3.36 | G91: 161.95 | H91: 49.89 | I91: 9.56 | J91: 0.14 | K91: 293.07 | L91: 29.81 | M91: 33.96 | N91: 18.8 | O91: 0 | P91: 1.53 | Q91: 10.18
A92: 03-04-2024 21:00 | B92: 30.64 | C92: 77.15 | D92: 64.8 | E92: 1.69 | F92: 3.63 | G92: 161.95 | H92: 49.89 | I92: 9 | J92: 0.01 | K92: 320.05 | L92: 28.94 | M92: 39.06 | N92: 19.1 | O92: 0 | P92: 1.55 | Q92: 10.28
A93: 03-04-2024 21:15 | B93: 32.32 | C93: 78.28 | D93: 66.73 | E93: 1.3 | F93: 3.5 | G93: 127.49 | H93: 42.06 | I93: 9.73 | J93: 0.17 | K93: 305.03 | L93: 28.28 | M93: 42.21 | N93: 18.8 | O93: 0 | P93: 1.58 | Q93: 10.34
A94: 03-04-2024 21:30 | B94: 33.96 | C94: 78.56 | D94: 68.2 | E94: 1.89 | F94: 3.36 | G94: 117.65 | H94: 39.82 | I94: 9.98 | J94: 0.09 | K94: 285.18 | L94: 28.35 | M94: 40.25 | N94: 18.2 | O94: 0 | P94: 1.61 | Q94: 10.41
A95: 03-04-2024 21:45 | B95: 32.37 | C95: 76.48 | D95: 65.84 | E95: 1.32 | F95: 3.53 | G95: 117.65 | H95: 39.82 | I95: 9.95 | J95: 0.83 | K95: 156.76 | L95: 28.74 | M95: 40.98 | N95: 16.9 | O95: 0 | P95: 1.56 | Q95: 10.07
A96: 03-04-2024 22:00 | B96: 29.31 | C96: 75.09 | D96: 62.65 | E96: 1.47 | F96: 3.45 | G96: 117.65 | H96: 39.82 | I96: 9.9 | J96: 0.64 | K96: 174.87 | L96: 28.78 | M96: 41.09 | N96: 17.7 | O96: 0 | P96: 1.5 | Q96: 10.5
... A104: 03-04-2024 24:00 | B104: 12.71 | C104: 61.45 | D104: 42.22 | E104: 0.47 | F104: 3.56 | G104: 62.79 | H104: 25.36 | I104: 7.64 | J104: 0.19 | K104: 183.44 | L104: 27.01 | M104: 47.94 | N104: 18.5 | O104: 0 | P104: 1.04 | Q104: 9.96
...

Sheet 04
A1: Station: | B1: BHATAGAON RAIPUR
A2: Date: | B2: =$A$9 -> 04-04-2024 00:15 | D2: Power Off | G2: Pw.Off | L2: Link Fail | N2: Link F | P2: Maintenance | R2: Maint.
A3: Report Type: | B3: Mean | D3: Calibration | G3: Calib. | L3: Data Fail | N3: Data F | P3: Invalid | R3: Invalid
A4: Time Base: | B4: 15 Min | D4: Zero Referrence | G4: Z.Ref | L4: Warm Up | N4: Wm. Up
A7: Date & Time | B7: NO_BHATAGAON | C7: NO2__BHATAGAON | D7: NOX_BHATAGAON | E7: SO2__BHATAGAON | F7: O3__BHATAGAON | G7: PM10__BHATAGAON | H7: PM2_5__BHATAGAON | I7: BENZ__BHATAGAON | J7: WS__BHATAGAON | K7: WD__BHATAGAON | L7: TEMP__BHATAGAON | M7: HUM__BHATAGAON | N7: SR__BHATAGAON | O7: RG__BHATAGAON | P7: CO__BHATAGAON | Q7: NH3__BHATAGAON
B8: ug/m3 | C8: ug/m3 | D8: ppb | E8: ug/m3 | F8: ug/m3 | G8: ug/m3 | H8: ug/m3 | I8: ug/m3 | J8: m/sec | K8: deg | L8: degreC | M8: % | N8: w/m2 | O8: mm | P8: mg/m3 | Q8: ug/m3
A9: 04-04-2024 00:15 | B9: 12.05 | C9: 60.82 | D9: 41.36 | E9: 0.81 | F9: 3.33 | G9: 53.07 | H9: 23.38 | I9: 7.5 | J9: 0.43 | K9: 208.53 | L9: 26.68 | M9: 49.54 | N9: 18.2 | O9: 0 | P9: 1 | Q9: 9.58
A10: 04-04-2024 00:30 | B10: 11.3 | C10: 59.95 | D10: 40.3 | E10: 0.89 | F10: 3.54 | G10: 50.29 | H10: 22.82 | I10: 7.25 | J10: 0.42 | K10: 202.91 | L10: 26.44 | M10: 51.14 | N10: 18.1 | O10: 0 | P10: 0.97 | Q10: 10.06
A11: 04-04-2024 00:45 | B11: 10.56 | C11: 58.27 | D11: 38.84 | E11: 0.99 | F11: 4.07 | G11: 50.29 | H11: 22.82 | I11: 7.15 | J11: 0.45 | K11: 190.38 | L11: 26.17 | M11: 52.64 | N11: 18.1 | O11: 0 | P11: 0.93 | Q11: 9.89
A12: 04-04-2024 01:00 | B12: 9.97 | C12: 57.14 | D12: 37.77 | E12: 0.81 | F12: 4.26 | G12: 50.29 | H12: 22.82 | I12: 7.34 | J12: 0.34 | K12: 226.11 | L12: 25.85 | M12: 53.8 | N12: 18.2 | O12: 0 | P12: 0.9 | Q12: 9.92
A13: 04-04-2024 01:15 | B13: 9.43 | C13: 53.91 | D13: 35.64 | E13: 0.82 | F13: 3.88 | G13: 45.51 | H13: 25.11 | I13: 7.17 | J13: 0.27 | K13: 184.11 | L13: 25.47 | M13: 56.32 | N13: 18.2 | O13: 0 | P13: 0.88 | Q13: 9.73
A14: 04-04-2024 01:30 | B14: 8.85 | C14: 52.17 | D14: 34.27 | E14: 0.64 | F14: 3.84 | G14: 44.15 | H14: 25.76 | I14: 7.03 | J14: 0.06 | K14: 245.83 | L14: 25.33 | M14: 56.72 | N14: 18.2 | O14: 0 | P14: 0.89 | Q14: 9.88
A15: 04-04-2024 01:45 | B15: 8.24 | C15: 53.4 | D15: 34.43 | E15: 0.79 | F15: 3.9 | G15: 44.15 | H15: 25.76 | I15: 7.37 | J15: 0.11 | K15: 291.04 | L15: 25.11 | M15: 57.46 | N15: 18.3 | O15: 0 | P15: 0.86 | Q15: 9.89
A16: 04-04-2024 02:00 | B16: 7.73 | C16: 53.85 | D16: 34.25 | E16: 1.04 | F16: 4.05 | G16: 44.15 | H16: 25.76 | I16: 7.34 | J16: 0.13 | K16: 265.22 | L16: 25.21 | M16: 57.65 | N16: 17.9 | O16: 0 | P16: 0.83 | Q16: 9.78
A17: 04-04-2024 02:15 | B17: 7.53 | C17: 53.73 | D17: 34.03 | E17: 0.79 | F17: 3.97 | G17: 44.42 | H17: 20.06 | I17: 7.05 | J17: 0.11 | K17: 296.26 | L17: 25.14 | M17: 58.6 | N17: 18.1 | O17: 0 | P17: 0.79 | Q17: 9.78
A18: 04-04-2024 02:30 | B18: 7.49 | C18: 53.52 | D18: 33.89 | E18: 0.96 | F18: 4.12 | G18: 44.5 | H18: 18.43 | I18: 6.84 | J18: 0.12 | K18: 314.29 | L18: 24.52 | M18: 63.36 | N18: 18.5 | O18: 0 | P18: 0.77 | Q18: 9.33
A19: 04-04-2024 02:45 | B19: 7.48 | C19: 53.72 | D19: 33.99 | E19: 0.93 | F19: 4.13 | G19: 44.5 | H19: 18.43 | I19: 6.39 | J19: 0.14 | K19: 352.41 | L19: 24.13 | M19: 64.76 | N19: 18.1 | O19: 0 | P19: 0.74 | Q19: 9.99
A20: 04-04-2024 03:00 | B20: 7.39 | C20: 52.67 | D20: 33.37 | E20: 0.99 | F20: 4.12 | G20: 44.5 | H20: 18.43 | I20: 6.61 | J20: 0.05 | K20: 34.66 | L20: 24.2 | M20: 63.41 | N20: 18.1 | O20: 0 | P20: 0.72 | Q20: 9.71
... A104: 04-04-2024 24:00 | B104: 16.7 | C104: 54.38 | D104: 41.72 | E104: 1.98 | F104: 3.97 | G104: 87.16 | H104: 30.66 | I104: 8.52 | J104: 0.03 | K104: 315.83 | L104: 27.65 | M104: 35.54 | N104: 18.1 | O104: 0 | P104: 1.22 | Q104: 9.94
A106: Min | B106: =MIN(B9:B104) -> 0.85 | C106: =MIN(C9:C104) -> 29.18 | D106: =MIN(D9:D104) -> 16.59 | E106: =MIN(E9:E104) -> 0.64 | F106: =MIN(F9:F104) -> 3.2 | G106: =MIN(G9:G104) -> 33.01 | H106: =MIN(H9:H104) -> 5.43 | I106: =MIN(I9:I104) -> 1.96 | ... Q106: =MIN(Q9:Q104) -> 9.2
A107: Max | B107: =MAX(B9:B104) -> 27.54 | C107: =MAX(C9:C104) -> 61 | D107: =MAX(D9:D104) -> 50.55 | E107: =MAX(E9:E104) -> 2.82 | F107: =MAX(F9:F104) -> 16.84 | G107: =MAX(G9:G104) -> 98.4 | H107: =MAX(H9:H104) -> 39.93 | I107: =MAX(I9:I104) -> 10.19 | ... Q107: =MAX(Q9:Q104) -> 10.12
A108: Avg | B108: =AVERAGE(B9:B104) -> 9.3713542 | C108: =AVERAGE(C9:C104) -> 50.840417 | D108: =AVERAGE(D9:D104) -> 33.996979 | E108: =AVERAGE(E9:E104) -> 1.49375 | F108: =AVERAGE(F9:F104) -> 6.0194792 | G108: =AVERAGE(G9:G104) -> 60.779583 | H108: =AVERAGE(H9:H104) -> 25.775729 | I108: =AVERAGE(I9:I104) -> 5.5376042 | ... Q108: =AVERAGE(Q9:Q104) -> 9.6323958
A109: Stdev | B109: =STDEV(B9:B104) -> 6.4612555 | C109: =STDEV(C9:C104) -> 5.6599868 | D109: =STDEV(D9:D104) -> 7.1372666 | E109: =STDEV(E9:E104) -> 0.55072631 | F109: =STDEV(F9:F104) -> 3.5337362 | G109: =STDEV(G9:G104) -> 17.880121 | H109: =STDEV(H9:H104) -> 8.0716426 | I109: =STDEV(I9:I104) -> 2.177795 | ... Q109: =STDEV(Q9:Q104) -> 0.23001485
A110: Num | B110: =COUNT(B9:B104) -> 96 | C110: =COUNT(C9:C104) -> 96 | D110: =COUNT(D9:D104) -> 96 | E110: =COUNT(E9:E104) -> 96 | F110: =COUNT(F9:F104) -> 96 | G110: =COUNT(G9:G104) -> 96 | H110: =COUNT(H9:H104) -> 96 | I110: =COUNT(I9:I104) -> 96 | ... Q110: =COUNT(Q9:Q104) -> 96
A111: DCR | B111: =IF(B110>=87,">90%",IF(B110<=87,"<90%")) -> >90% | C111: =IF(C110>=87,">90%",IF(C110<=87,"<90%")) -> >90% | D111: =IF(D110>=87,">90%",IF(D110<=87,"<90%")) -> >90% | E111: =IF(E110>=87,">90%",IF(E110<=87,"<90%")) -> >90% | F111: =IF(F110>=87,">90%",IF(F110<=87,"<90%")) -> >90% | G111: =IF(G110>=87,">90%",IF(G110<=87,"<90%")) -> >90% | H111: =IF(H110>=87,">90%",IF(H110<=87,"<90%")) -> >90% | I111: =IF(I110>=87,">90%",IF(I110<=87,"<90%")) -> >90% | ... Q111: =IF(Q110>=87,">90%",IF(Q110<=87,"<90%")) -> >90%
A112: Status | B112: =IF(B110>=87,"OK",IF(B110<=87,"LESS")) -> OK | C112: =IF(C110>=87,"OK",IF(C110<=87,"LESS")) -> OK | D112: =IF(D110>=87,"OK",IF(D110<=87,"LESS")) -> OK | E112: =IF(E110>=87,"OK",IF(E110<=87,"LESS")) -> OK | F112: =IF(F110>=87,"OK",IF(F110<=87,"LESS")) -> OK | G112: =IF(G110>=87,"OK",IF(G110<=87,"LESS")) -> OK | H112: =IF(H110>=87,"OK",IF(H110<=87,"LESS")) -> OK | I112: =IF(I110>=87,"OK",IF(I110<=87,"LESS")) -> OK | ... Q112: =IF(Q110>=87,"OK",IF(Q110<=87,"LESS")) -> OK
A115: Done by | B115: RK
A117: Comment

Sheet 05
A1: Station: | B1: BHATAGAON RAIPUR
A2: Date: | B2: =$A$9 -> 05-04-2024 00:15 | D2: Power Off | G2: Pw.Off | L2: Link Fail | N2: Link F | P2: Maintenance | R2: Maint.
A3: Report Type: | B3: Mean | D3: Calibration | G3: Calib. | L3: Data Fail | N3: Data F | P3: Invalid | R3: Invalid
A4: Time Base: | B4: 15 Min | D4: Zero Referrence | G4: Z.Ref | L4: Warm Up | N4: Wm. Up
A7: Date & Time | B7: NO_BHATAGAON | C7: NO2__BHATAGAON | D7: NOX_BHATAGAON | E7: SO2__BHATAGAON | F7: O3__BHATAGAON | G7: PM10__BHATAGAON | H7: PM2_5__BHATAGAON | I7: BENZ__BHATAGAON | J7: WS__BHATAGAON | K7: WD__BHATAGAON | L7: TEMP__BHATAGAON | M7: HUM__BHATAGAON | N7: SR__BHATAGAON | O7: RG__BHATAGAON | P7: CO__BHATAGAON | Q7: NH3__BHATAGAON
B8: ug/m3 | C8: ug/m3 | D8: ppb | E8: ug/m3 | F8: ug/m3 | G8: ug/m3 | H8: ug/m3 | I8: ug/m3 | J8: m/sec | K8: deg | L8: degreC | M8: % | N8: w/m2 | O8: mm | P8: mg/m3 | Q8: ug/m3
A9: 05-04-2024 00:15 | B9: 15.61 | C9: 56.81 | D9: 42.12 | E9: 1.28 | F9: 4.01 | G9: 82.71 | H9: 31.46 | I9: 8.52 | J9: 0.03 | K9: 117.54 | L9: 27.56 | M9: 35.81 | N9: 17.9 | O9: 0 | P9: 1.21 | Q9: 9.81
A10: 05-04-2024 00:30 | B10: 14.12 | C10: 58.12 | D10: 41.61 | E10: 1.24 | F10: 3.84 | G10: 81.44 | H10: 31.69 | I10: 8.85 | J10: 0.07 | K10: 72.87 | L10: 27.17 | M10: 37.71 | N10: 18.2 | O10: 0 | P10: 1.19 | Q10: 9.82
A11: 05-04-2024 00:45 | B11: 12.99 | C11: 58.66 | D11: 40.99 | E11: 1.27 | F11: 3.69 | G11: 81.44 | H11: 31.69 | I11: 9.23 | J11: 0.34 | K11: 184.71 | L11: 26.86 | M11: 37.8 | N11: 17.1 | O11: 0 | P11: 1.16 | Q11: 9.66
A12: 05-04-2024 01:00 | B12: 12.01 | C12: 60.72 | D12: 41.28 | E12: 1.55 | F12: 3.43 | G12: 81.44 | H12: 31.69 | I12: 9.56 | J12: 0.5 | K12: 207.06 | L12: 26.87 | M12: 43.25 | N12: 17.3 | O12: 0 | P12: 1.12 | Q12: 9.77
A13: 05-04-2024 01:15 | B13: 11.07 | C13: 60.54 | D13: 40.43 | E13: 1.46 | F13: 3.51 | G13: 77.55 | H13: 30.06 | I13: 9.35 | J13: 0.41 | K13: 179.26 | L13: 26.5 | M13: 45.52 | N13: 17.4 | O13: 0 | P13: 0.97 | Q13: 9.94
A14: 05-04-2024 01:30 | B14: 10.31 | C14: 57.21 | D14: 38.08 | E14: 1.07 | F14: 3.65 | G14: 76.44 | H14: 29.59 | I14: 9.1 | J14: 0.22 | K14: 223.08 | L14: 26.2 | M14: 45.65 | N14: 17.8 | O14: 0 | P14: 0.99 | Q14: 9.63
A15: 05-04-2024 01:45 | B15: 9.47 | C15: 53.59 | D15: 35.51 | E15: 1 | F15: 4.27 | G15: 76.44 | H15: 29.59 | I15: 8.93 | J15: 0.13 | K15: 231.21 | L15: 26.05 | M15: 45.9 | N15: 17.4 | O15: 0 | P15: 0.96 | Q15: 9.7
A16: 05-04-2024 02:00 | B16: 8.72 | C16: 50.74 | D16: 33.43 | E16: 1.45 | F16: 3.91 | G16: 76.44 | H16: 29.59 | I16: 8.73 | J16: 0.15 | K16: 306.18 | L16: 25.81 | M16: 46.26 | N16: 17.8 | O16: 0 | P16: 0.93 | Q16: 9.62
A17: 05-04-2024 02:15 | B17: 8.27 | C17: 49.72 | D17: 32.53 | E17: 1.05 | F17: 3.96 | G17: 72.36 | H17: 26 | I17: 8.51 | J17: 0.14 | K17: 26.31 | L17: 25.16 | M17: 48.56 | N17: 18.1 | O17: 0 | P17: 0.9 | Q17: 9.57
A18: 05-04-2024 02:30 | B18: 7.96 | C18: 49.45 | D18: 32.14 | E18: 1.11 | F18: 3.82 | G18: 71.19 | H18: 24.97 | I18: 8.29 | J18: 0.06 | K18: 232.94 | L18: 24.94 | M18: 46.3 | N18: 17.8 | O18: 0 | P18: 0.87 | Q18: 9.85
A19: 05-04-2024 02:45 | B19: 7.66 | C19: 49.49 | D19: 31.92 | E19: 1.31 | F19: 3.65 | G19: 71.19 | H19: 24.97 | I19: 8.16 | J19: 0.07 | K19: 45.52 | L19: 24.8 | M19: 47.59 | N19: 17.7 | O19: 0 | P19: 0.85 | Q19: 9.7
A20: 05-04-2024 03:00 | B20: 7.47 | C20: 45.44 | D20: 29.65 | E20: 1.27 | F20: 3.21 | G20: 71.19 | H20: 24.97 | I20: 8.02 | J20: 0.1 | K20: 301.68 | L20: 24.36 | M20: 52.52 | N20: 18.1 | O20: 0 | P20: 0.83 | Q20: 9.62
... A104: 05-04-2024 24:00 | B104: 60.44 | C104: 67.25 | D104: 83.53 | E104: 2.9 | F104: 3.58 | G104: 87.87 | H104: 81.48 | I104: 8.57 | J104: 0.18 | K104: 253.51 | L104: 25.43 | M104: 42.95 | N104: 16.8 | O104: 0 | P104: 1.33 | Q104: 10.48
A106: Min | B106: =MIN(B9:B104) -> 0.79 | C106: =MIN(C9:C104) -> 33.9 | D106: =MIN(D9:D104) -> 18.4 | E106: =MIN(E9:E104) -> 0.34 | F106: =MIN(F9:F104) -> 3.18 | G106: =MIN(G9:G104) -> 44.87 | H106: =MIN(H9:H104) -> 1.37 | I106: =MIN(I9:I104) -> 4.21 | ... Q106: =MIN(Q9:Q104) -> 9.23
A107: Max | B107: =MAX(B9:B104) -> 60.44 | C107: =MAX(C9:C104) -> 76.2 | D107: =MAX(D9:D104) -> 83.53 | E107: =MAX(E9:E104) -> 2.9 | F107: =MAX(F9:F104) -> 8.97 | G107: =MAX(G9:G104) -> 94.11 | H107: =MAX(H9:H104) -> 81.48 | I107: =MAX(I9:I104) -> 9.56 | ... Q107: =MAX(Q9:Q104) -> 10.52
A108: Avg | B108: =AVERAGE(B9:B104) -> 11.191771 | C108: =AVERAGE(C9:C104) -> 57.155 | D108: =AVERAGE(D9:D104) -> 38.756667 | E108: =AVERAGE(E9:E104) -> 1.3909375 | F108: =AVERAGE(F9:F104) -> 4.5580208 | G108: =AVERAGE(G9:G104) -> 67.13375 | H108: =AVERAGE(H9:H104) -> 22.685208 | I108: =AVERAGE(I9:I104) -> 7.2127083 | ... Q108: =AVERAGE(Q9:Q104) -> 9.6808333
A109: Stdev | B109: =STDEV(B9:B104) -> 12.308422 | C109: =STDEV(C9:C104) -> 7.3605989 | D109: =STDEV(D9:D104) -> 11.978553 | E109: =STDEV(E9:E104) -> 0.56425839 | F109: =STDEV(F9:F104) -> 1.4639662 | G109: =STDEV(G9:G104) -> 14.592155 | H109: =STDEV(H9:H104) -> 17.549242 | I109: =STDEV(I9:I104) -> 1.4704374 | ... Q109: =STDEV(Q9:Q104) -> 0.25393603
A110: Num | B110: =COUNT(B9:B104) -> 96 | C110: =COUNT(C9:C104) -> 96 | D110: =COUNT(D9:D104) -> 96 | E110: =COUNT(E9:E104) -> 96 | F110: =COUNT(F9:F104) -> 96 | G110: =COUNT(G9:G104) -> 96 | H110: =COUNT(H9:H104) -> 96 | I110: =COUNT(I9:I104) -> 96 | ... Q110: =COUNT(Q9:Q104) -> 96
A111: DCR | B111: =IF(B110>=87,">90%",IF(B110<=87,"<90%")) -> >90% | C111: =IF(C110>=87,">90%",IF(C110<=87,"<90%")) -> >90% | D111: =IF(D110>=87,">90%",IF(D110<=87,"<90%")) -> >90% | E111: =IF(E110>=87,">90%",IF(E110<=87,"<90%")) -> >90% | F111: =IF(F110>=87,">90%",IF(F110<=87,"<90%")) -> >90% | G111: =IF(G110>=87,">90%",IF(G110<=87,"<90%")) -> >90% | H111: =IF(H110>=87,">90%",IF(H110<=87,"<90%")) -> >90% | I111: =IF(I110>=87,">90%",IF(I110<=87,"<90%")) -> >90% | ... Q111: =IF(Q110>=87,">90%",IF(Q110<=87,"<90%")) -> >90%
A112: Status | B112: =IF(B110>=87,"OK",IF(B110<=87,"LESS")) -> OK | C112: =IF(C110>=87,"OK",IF(C110<=87,"LESS")) -> OK | D112: =IF(D110>=87,"OK",IF(D110<=87,"LESS")) -> OK | E112: =IF(E110>=87,"OK",IF(E110<=87,"LESS")) -> OK | F112: =IF(F110>=87,"OK",IF(F110<=87,"LESS")) -> OK | G112: =IF(G110>=87,"OK",IF(G110<=87,"LESS")) -> OK | H112: =IF(H110>=87,"OK",IF(H110<=87,"LESS")) -> OK | I112: =IF(I110>=87,"OK",IF(I110<=87,"LESS")) -> OK | ... Q112: =IF(Q110>=87,"OK",IF(Q110<=87,"LESS")) -> OK
A115: Done by | B115: RK
A117: Comment

Sheet 06
A1: Station: | B1: BHATAGAON RAIPUR
A2: Date: | B2: =$A$9 -> 06-04-2024 00:15 | D2: Power Off | G2: Pw.Off | L2: Link Fail | N2: Link F | P2: Maintenance | R2: Maint.
A3: Report Type: | B3: Mean | D3: Calibration | G3: Calib. | L3: Data Fail | N3: Data F | P3: Invalid | R3: Invalid
A4: Time Base: | B4: 15 Min | D4: Zero Referrence | G4: Z.Ref | L4: Warm Up | N4: Wm. Up
A7: Date & Time | B7: NO_BHATAGAON | C7: NO2__BHATAGAON | D7: NOX_BHATAGAON | E7: SO2__BHATAGAON | F7: O3__BHATAGAON | G7: PM10__BHATAGAON | H7: PM2_5__BHATAGAON | I7: BENZ__BHATAGAON | J7: WS__BHATAGAON | K7: WD__BHATAGAON | L7: TEMP__BHATAGAON | M7: HUM__BHATAGAON | N7: SR__BHATAGAON | O7: RG__BHATAGAON | P7: CO__BHATAGAON | Q7: NH3__BHATAGAON
B8: ug/m3 | C8: ug/m3 | D8: ppb | E8: ug/m3 | F8: ug/m3 | G8: ug/m3 | H8: ug/m3 | I8: ug/m3 | J8: m/sec | K8: deg | L8: degreC | M8: % | N8: w/m2 | O8: mm | P8: mg/m3 | Q8: ug/m3
A9: 06-04-2024 00:15 | B9: 60.89 | C9: 66.66 | D9: 83.58 | E9: 2.85 | F9: 3.43 | G9: 91.83 | H9: 55.4 | I9: 8.58 | J9: 0.2 | K9: 312.38 | L9: 25.34 | M9: 45.64 | N9: 17 | O9: 0 | P9: 1.32 | Q9: 10.6
A10: 06-04-2024 00:30 | B10: 62.12 | C10: 66.66 | D10: 84.56 | E10: 2.7 | F10: 3.3 | G10: 92.96 | H10: 47.95 | I10: 8.7 | J10: 0.33 | K10: 352.97 | L10: 24.82 | M10: 52.03 | N10: 17.1 | O10: 0 | P10: 1.36 | Q10: 10.65
A11: 06-04-2024 00:45 | B11: 62.32 | C11: 66.27 | D11: 84.52 | E11: 2.74 | F11: 3.47 | G11: 92.96 | H11: 47.95 | I11: 8.86 | J11: 0.43 | K11: 341.75 | L11: 24.91 | M11: 48.82 | N11: 16 | O11: 0 | P11: 1.35 | Q11: 10.72
A12: 06-04-2024 01:00 | B12: 60.16 | C12: 64.03 | D12: 81.62 | E12: 2.86 | F12: 3.58 | G12: 92.96 | H12: 47.95 | I12: 9.05 | J12: 0.71 | K12: 353.57 | L12: 25.58 | M12: 39.14 | N12: 15.8 | O12: 0 | P12: 1.34 | Q12: 10.7
A13: 06-04-2024 01:15 | B13: 56.91 | C13: 63.15 | D13: 78.55 | E13: 2.59 | F13: 3.39 | G13: 96.71 | H13: 33.41 | I13: 9.24 | J13: 0.76 | K13: 342.34 | L13: 26.01 | M13: 35.48 | N13: 15.8 | O13: 0 | P13: 1.18 | Q13: 10.23
A14: 06-04-2024 01:30 | B14: 53.16 | C14: 61.93 | D14: 74.91 | E14: 2.36 | F14: 3.52 | G14: 97.78 | H14: 29.26 | I14: 9.57 | J14: 0.6 | K14: 339.75 | L14: 26.14 | M14: 33.8 | N14: 16.4 | O14: 0 | P14: 1.18 | Q14: 10.37
A15: 06-04-2024 01:45 | B15: 49.11 | C15: 59.91 | D15: 70.6 | E15: 2.13 | F15: 3.51 | G15: 97.78 | H15: 29.26 | I15: 9.44 | J15: 0.45 | K15: 335.29 | L15: 26.21 | M15: 33.11 | N15: 16.8 | O15: 0 | P15: 1.07 | Q15: 10.15
A16: 06-04-2024 02:00 | B16: 46 | C16: 56.29 | D16: 66.22 | E16: 2.25 | F16: 3.77 | G16: 97.78 | H16: 29.26 | I16: 8.75 | J16: 0.18 | K16: 285.44 | L16: 26.01 | M16: 34.16 | N16: 17.4 | O16: 0 | P16: 0.97 | Q16: 10.2
A17: 06-04-2024 02:15 | B17: 43.72 | C17: 56.86 | D17: 64.69 | E17: 2.41 | F17: 3.5 | G17: 82.6 | H17: 26.16 | I17: 7.36 | J17: 0.18 | K17: 233.51 | L17: 25.98 | M17: 34.47 | N17: 17.3 | O17: 0 | P17: 0.93 | Q17: 10.1
A18: 06-04-2024 02:30 | B18: 41.54 | C18: 57.28 | D18: 63.16 | E18: 2.51 | F18: 3.36 | G18: 78.26 | H18: 25.27 | I18: 5.87 | J18: 0.06 | K18: 245.86 | L18: 25.88 | M18: 35.83 | N18: 17.3 | O18: 0 | P18: 0.92 | Q18: 9.96
A19: 06-04-2024 02:45 | B19: 39.62 | C19: 56.69 | D19: 61.31 | E19: 2.24 | F19: 3.46 | G19: 78.26 | H19: 25.27 | I19: 5.19 | J19: 0.55 | K19: 208.74 | L19: 25.49 | M19: 40.7 | N19: 16.7 | O19: 0 | P19: 0.96 | Q19: 9.74
A20: 06-04-2024 03:00 | B20: 38.21 | C20: 55.78 | D20: 59.71 | E20: 2.22 | F20: 3.58 | G20: 78.26 | H20: 25.27 | I20: 6.06 | J20: 0.12 | K20: 232.94 | L20: 24.74 | M20: 44.55 | N20: 17.7 | O20: 0 | P20: 0.94 | Q20: 9.92
... A47: 06-04-2024 09:45 | B47: 0.1 | C47: 0.97 | D47: 0.51 | E47: 1.79 | F47: 4.29 | G47: 95.38 | H47: 36.44 | I47: 10.49 | J47: 0.12 | K47: 220.69 | L47: 33.48 | M47: 26.07 | N47: 695.1 | O47: 0 | P47: 0.83 | Q47: 9.97
A48: 06-04-2024 10:00 | B48: Data F | C48: Data F | D48: Data F | E48: 1.68 | F48: 4.29 | G48: 95.38 | H48: 36.44 | I48: 10.04 | J48: 0.16 | K48: 293.47 | L48: 35.46 | M48: 23.87 | N48: 734.8 | O48: 0 | P48: 0.82 | Q48: 9.65
A49: 06-04-2024 10:15 | B49: Data F | C49: Data F | D49: Data F | E49: 1.66 | F49: 4.38 | G49: 86.75 | H49: 33.44 | I49: 9.85 | J49: 0.44 | K49: 199.6 | L49: 36.15 | M49: 21.37 | N49: 781.7 | O49: 0 | P49: 0.81 | Q49: 9.97
A50: 06-04-2024 10:30 | B50: Data F | C50: Data F | D50: Data F | E50: 1.66 | F50: 4.99 | G50: 84.28 | H50: 32.58 | I50: 9.67 | J50: 0.18 | K50: 311.85 | L50: 35.88 | M50: 20.66 | N50: 807.1 | O50: 0 | P50: 0.79 | Q50: 9.78
A51: 06-04-2024 10:45 | B51: Data F | C51: Data F | D51: Data F | E51: 1.49 | F51: 5.25 | G51: 84.28 | H51: 32.58 | I51: 9.37 | J51: 0.17 | K51: 89.87 | L51: 37.95 | M51: 18.6 | N51: 839.8 | O51: 0 | P51: 0.78 | Q51: 9.6
A52: 06-04-2024 11:00 | B52: Data F | C52: Data F | D52: Data F | E52: 1.48 | F52: 5.47 | G52: 84.28 | H52: 32.58 | I52: 9.26 | J52: 0.19 | K52: 357.67 | L52: 38.6 | M52: 17.36 | N52: 870 | O52: 0 | P52: 0.77 | Q52: 9.65
A53: 06-04-2024 11:15 | B53: Data F | C53: Data F | D53: Data F | E53: 1.01 | F53: 5.17 | G53: 79.4 | H53: 18.51 | I53: 9.24 | J53: 0.27 | K53: 75.67 | L53: 37.19 | M53: 18.23 | N53: 870 | O53: 0 | P53: 0.76 | Q53: 9.71
A54: 06-04-2024 11:30 | B54: Data F | C54: Data F | D54: Data F | E54: 1.27 | F54: 4.94 | G54: 78.01 | H54: 14.49 | I54: 9.08 | J54: 0.54 | K54: 5.9 | L54: 38.07 | M54: 18.36 | N54: 855.5 | O54: 0 | P54: 0.75 | Q54: 9.69
A55: 06-04-2024 11:45 | B55: Data F | C55: Data F | D55: Data F | E55: 1.58 | F55: 5.04 | G55: 78.01 | H55: 14.49 | I55: 9.62 | J55: 0.94 | K55: 336.65 | L55: 40.5 | M55: 16.03 | N55: 859 | O55: 0 | P55: 0.74 | Q55: 9.71
A56: 06-04-2024 12:00 | B56: Data F | C56: Data F | D56: Data F | E56: 0.63 | F56: 5.52 | G56: 78.01 | H56: 14.49 | I56: 10.3 | J56: 0.53 | K56: 346.41 | L56: 40.61 | M56: 15.08 | N56: 854.4 | O56: 0 | P56: 0.74 | Q56: 9.5
A57: 06-04-2024 12:15 | B57: Data F | C57: Data F | D57: Data F | E57: 1.08 | F57: 5.23 | G57: 73.76 | H57: 6.6 | I57: 10.32 | J57: 0.26 | K57: 38.44 | L57: 38.8 | M57: 16.53 | N57: 847.2 | O57: 0 | P57: 0.73 | Q57: 9.84
A58: 06-04-2024 12:30 | B58: Data F | C58: Data F | D58: Data F | E58: 0.83 | F58: 5.54 | G58: 72.54 | H58: 4.35 | I58: 10.42 | J58: 0.39 | K58: 325.13 | L58: 39.78 | M58: 16.52 | N58: 866.9 | O58: 0 | P58: 0.71 | Q58: 9.65
A59: 06-04-2024 12:45 | B59: Data F | C59: Data F | D59: Data F | E59: 0.65 | F59: 5.36 | G59: 72.54 | H59: 4.35 | I59: 10.72 | J59: 1.09 | K59: 344.15 | L59: 38.67 | M59: 18.23 | N59: 863.5 | O59: 0 | P59: 0.7 | Q59: 9.65
... A79: 06-04-2024 17:45 | B79: Data F | C79: Data F | D79: Data F | E79: 1.43 | F79: 4.67 | G79: 45.9 | H79: 19.5 | I79: 5.89 | J79: 0.17 | K79: 358.87 | L79: 34.05 | M79: 25.22 | N79: 45.8 | O79: 0 | P79: 0.63 | Q79: 9.59
A80: 06-04-2024 18:00 | B80: 2.32 | C80: 60.22 | D80: 33.25 | E80: 1.44 | F80: 4.02 | G80: 45.9 | H80: 19.5 | I80: 6.85 | J80: 0.1 | K80: 59.55 | L80: 32.85 | M80: 29.2 | N80: 28.7 | O80: 0 | P80: 0.8 | Q80: 9.67
A81: 06-04-2024 18:15 | B81: 4.45 | C81: 62.13 | D81: 35.95 | E81: 1.76 | F81: 3.56 | G81: 55.73 | H81: 22.11 | I81: 7.43 | J81: 0.23 | K81: 18.55 | L81: 31.92 | M81: 32.48 | N81: 23 | O81: 0 | P81: 0.92 | Q81: 9.74
A82: 06-04-2024 18:30 | B82: 8.25 | C82: 65.2 | D82: 40.6 | E82: 1.62 | F82: 3.83 | G82: 58.54 | H82: 22.86 | I82: 8.4 | J82: 0.04 | K82: 47.81 | L82: 31.22 | M82: 35.07 | N82: 20.9 | O82: 0 | P82: 1.04 | Q82: 9.84
A83: 06-04-2024 18:45 | B83: 12.16 | C83: 67.91 | D83: 45.15 | E83: 1.68 | F83: 3.78 | G83: 58.54 | H83: 22.86 | I83: 8.59 | J83: 0.23 | K83: 351.43 | L83: 30.91 | M83: 34.84 | N83: 20.6 | O83: 0 | P83: 1.33 | Q83: 9.83
A84: 06-04-2024 19:00 | B84: 15.84 | C84: 69.98 | D84: 49.19 | E84: 1.96 | F84: 3.67 | G84: 58.54 | H84: 22.86 | I84: 8.95 | J84: 0.41 | K84: 309.48 | L84: 30.87 | M84: 26.3 | N84: 19.2 | O84: 0 | P84: 1.2 | Q84: 10.06
A85: 06-04-2024 19:15 | B85: 15.85 | C85: 70.33 | D85: 49.37 | E85: 1.93 | F85: 3.56 | G85: 78.74 | H85: 26.94 | I85: 9.3 | J85: 0.55 | K85: 307.1 | L85: 31.13 | M85: 23.34 | N85: 19.2 | O85: 0 | P85: 1.08 | Q85: 10.12
A86: 06-04-2024 19:30 | B86: 14.51 | C86: 69.77 | D86: 48.01 | E86: 1.74 | F86: 3.74 | G86: 84.51 | H86: 28.11 | I86: 9.03 | J86: 0.84 | K86: 308.08 | L86: 31 | M86: 23.36 | N86: 19.1 | O86: 0 | P86: 1.12 | Q86: 10.03
A87: 06-04-2024 19:45 | B87: 13.07 | C87: 69.07 | D87: 46.49 | E87: 1.63 | F87: 3.53 | G87: 84.51 | H87: 28.11 | I87: 9.04 | J87: 0.98 | K87: 316.04 | L87: 30.77 | M87: 23.89 | N87: 19.8 | O87: 0 | P87: 1.1 | Q87: 9.73
...

Sheet 07
A1: Station: | B1: BHATAGAON RAIPUR
A2: Date: | B2: =$A$9 -> 07-04-2024 00:15 | D2: Power Off | G2: Pw.Off | L2: Link Fail | N2: Link F | P2: Maintenance | R2: Maint.
A3: Report Type: | B3: Mean | D3: Calibration | G3: Calib. | L3: Data Fail | N3: Data F | P3: Invalid | R3: Invalid
A4: Time Base: | B4: 15 Min | D4: Zero Referrence | G4: Z.Ref | L4: Warm Up | N4: Wm. Up
A7: Date & Time | B7: NO_BHATAGAON | C7: NO2__BHATAGAON | D7: NOX_BHATAGAON | E7: SO2__BHATAGAON | F7: O3__BHATAGAON | G7: PM10__BHATAGAON | H7: PM2_5__BHATAGAON | I7: BENZ__BHATAGAON | J7: WS__BHATAGAON | K7: WD__BHATAGAON | L7: TEMP__BHATAGAON | M7: HUM__BHATAGAON | N7: SR__BHATAGAON | O7: RG__BHATAGAON | P7: CO__BHATAGAON | Q7: NH3__BHATAGAON
B8: ug/m3 | C8: ug/m3 | D8: ppb | E8: ug/m3 | F8: ug/m3 | G8: ug/m3 | H8: ug/m3 | I8: ug/m3 | J8: m/sec | K8: deg | L8: degreC | M8: % | N8: w/m2 | O8: mm | P8: mg/m3 | Q8: ug/m3
A9: 07-04-2024 00:15 | B9: 41.47 | C9: 67.55 | D9: 68.47 | E9: 1.27 | F9: 3.1 | G9: 110.93 | H9: 39.29 | I9: 8.35 | J9: 0.54 | K9: 348.85 | L9: 26.41 | M9: 37.15 | N9: 19.2 | O9: 0 | P9: 1.37 | Q9: 10.17
A10: 07-04-2024 00:30 | B10: 39.63 | C10: 64.49 | D10: 65.4 | E10: 1.53 | F10: 3.43 | G10: 114.76 | H10: 41.05 | I10: 8.11 | J10: 0.2 | K10: 319.29 | L10: 26.92 | M10: 34.38 | N10: 20.4 | O10: 0 | P10: 1.35 | Q10: 10.44
A11: 07-04-2024 00:45 | B11: 37.4 | C11: 63.09 | D11: 62.87 | E11: 1.65 | F11: 3.62 | G11: 114.76 | H11: 41.05 | I11: 7.68 | J11: 0.06 | K11: 195.15 | L11: 26.79 | M11: 33.62 | N11: 20.7 | O11: 0 | P11: 1.17 | Q11: 10.27
A12: 07-04-2024 01:00 | B12: 35.82 | C12: 61.07 | D12: 60.55 | E12: 1.6 | F12: 3.54 | G12: 114.76 | H12: 41.05 | I12: 7.39 | J12: 0.17 | K12: 142.75 | L12: 26.47 | M12: 35.26 | N12: 20.7 | O12: 0 | P12: 1.18 | Q12: 10.28
A13: 07-04-2024 01:15 | B13: 34.65 | C13: 60.93 | D13: 59.54 | E13: 1.45 | F13: 3.23 | G13: 124.21 | H13: 46.38 | I13: 5.96 | J13: 0.15 | K13: 158.87 | L13: 25.95 | M13: 37.23 | N13: 20.5 | O13: 0 | P13: 1.11 | Q13: 10.14
A14: 07-04-2024 01:30 | B14: 33.69 | C14: 60.27 | D14: 58.42 | E14: 1.48 | F14: 3.14 | G14: 126.9 | H14: 47.91 | I14: 5.88 | J14: 0.08 | K14: 280.98 | L14: 25.39 | M14: 41.39 | N14: 20.9 | O14: 0 | P14: 1.14 | Q14: 10.25
A15: 07-04-2024 01:45 | B15: 32.82 | C15: 58.98 | D15: 57.05 | E15: 1.49 | F15: 3.1 | G15: 126.9 | H15: 47.91 | I15: 6.1 | J15: 0.24 | K15: 233.84 | L15: 25.12 | M15: 41.22 | N15: 20.4 | O15: 0 | P15: 1.11 | Q15: 10.06
A16: 07-04-2024 02:00 | B16: 31.78 | C16: 57.56 | D16: 55.47 | E16: 1.44 | F16: 3.33 | G16: 126.9 | H16: 47.91 | I16: 6.38 | J16: 0.23 | K16: 210.34 | L16: 25.38 | M16: 39.26 | N16: 20.1 | O16: 0 | P16: 1.04 | Q16: 10.25
A17: 07-04-2024 02:15 | B17: 30.95 | C17: 56.7 | D17: 54.37 | E17: 1.32 | F17: 3.2 | G17: 109.68 | H17: 43.64 | I17: 6.51 | J17: 0.17 | K17: 293.93 | L17: 25.17 | M17: 45.18 | N17: 20.5 | O17: 0 | P17: 1.05 | Q17: 10.22
A18: 07-04-2024 02:30 | B18: 30.79 | C18: 54.36 | D18: 53.02 | E18: 1.19 | F18: 3.38 | G18: 104.76 | H18: 42.42 | I18: 6.1 | J18: 0.23 | K18: 313.87 | L18: 24.24 | M18: 52.11 | N18: 20.9 | O18: 0 | P18: 1.07 | Q18: 10.1
A19: 07-04-2024 02:45 | B19: 30.96 | C19: 50.3 | D19: 51.03 | E19: 1.28 | F19: 3.25 | G19: 104.76 | H19: 42.42 | I19: 6.6 | J19: 0.22 | K19: 330.45 | L19: 23.56 | M19: 54.61 | N19: 21 | O19: 0 | P19: 1.08 | Q19: 10.06
A20: 07-04-2024 03:00 | B20: 30.12 | C20: 50.38 | D20: 50.39 | E20: 1.32 | F20: 3.22 | G20: 104.76 | H20: 42.42 | I20: 8.07 | J20: 0.22 | K20: 251.09 | L20: 23.71 | M20: 55.05 | N20: 20.3 | O20: 0 | P20: 1.03 | Q20: 10.15
... A104: 07-04-2024 24:00 | B104: 1.45 | C104: 47.06 | D104: 25.67 | E104: 1.18 | F104: 3.58 | G104: 32.01 | H104: 11.65 | I104: 7.3 | J104: 1.32 | K104: 1.29 | L104: 23.91 | M104: 46.38 | N104: 22.2 | O104: 0 | P104: 0.39 | Q104: 9.49
A106: Min | B106: =MIN(B9:B104) -> 0.1 | C106: =MIN(C9:C104) -> 47.06 | D106: =MIN(D9:D104) -> 25.16 | E106: =MIN(E9:E104) -> 0.6 | F106: =MIN(F9:F104) -> 2.81 | G106: =MIN(G9:G104) -> 32.01 | H106: =MIN(H9:H104) -> 11.04 | I106: =MIN(I9:I104) -> 5.88 | ... Q106: =MIN(Q9:Q104) -> 9.28
A107: Max | B107: =MAX(B9:B104) -> 41.47 | C107: =MAX(C9:C104) -> 67.55 | D107: =MAX(D9:D104) -> 68.47 | E107: =MAX(E9:E104) -> 2.64 | F107: =MAX(F9:F104) -> 6.18 | G107: =MAX(G9:G104) -> 126.9 | H107: =MAX(H9:H104) -> 47.91 | I107: =MAX(I9:I104) -> 10.95 | ... Q107: =MAX(Q9:Q104) -> 10.44
A108: Avg | B108: =AVERAGE(B9:B104) -> 12.551667 | C108: =AVERAGE(C9:C104) -> 54.561146 | D108: =AVERAGE(D9:D104) -> 38.49125 | E108: =AVERAGE(E9:E104) -> 1.565625 | F108: =AVERAGE(F9:F104) -> 3.6844792 | G108: =AVERAGE(G9:G104) -> 73.435208 | H108: =AVERAGE(H9:H104) -> 24.837708 | I108: =AVERAGE(I9:I104) -> 8.1647917 | ... Q108: =AVERAGE(Q9:Q104) -> 9.7905208
A109: Stdev | B109: =STDEV(B9:B104) -> 11.801779 | C109: =STDEV(C9:C104) -> 5.4037671 | D109: =STDEV(D9:D104) -> 10.497384 | E109: =STDEV(E9:E104) -> 0.52559302 | F109: =STDEV(F9:F104) -> 0.65060922 | G109: =STDEV(G9:G104) -> 26.157574 | H109: =STDEV(H9:H104) -> 9.9647041 | I109: =STDEV(I9:I104) -> 1.3169246 | ... Q109: =STDEV(Q9:Q104) -> 0.27058755
A110: Num | B110: =COUNT(B9:B104) -> 96 | C110: =COUNT(C9:C104) -> 96 | D110: =COUNT(D9:D104) -> 96 | E110: =COUNT(E9:E104) -> 96 | F110: =COUNT(F9:F104) -> 96 | G110: =COUNT(G9:G104) -> 96 | H110: =COUNT(H9:H104) -> 96 | I110: =COUNT(I9:I104) -> 96 | ... Q110: =COUNT(Q9:Q104) -> 96
A111: DCR | B111: =IF(B110>=87,">90%",IF(B110<=87,"<90%")) -> >90% | C111: =IF(C110>=87,">90%",IF(C110<=87,"<90%")) -> >90% | D111: =IF(D110>=87,">90%",IF(D110<=87,"<90%")) -> >90% | E111: =IF(E110>=87,">90%",IF(E110<=87,"<90%")) -> >90% | F111: =IF(F110>=87,">90%",IF(F110<=87,"<90%")) -> >90% | G111: =IF(G110>=87,">90%",IF(G110<=87,"<90%")) -> >90% | H111: =IF(H110>=87,">90%",IF(H110<=87,"<90%")) -> >90% | I111: =IF(I110>=87,">90%",IF(I110<=87,"<90%")) -> >90% | ... Q111: =IF(Q110>=87,">90%",IF(Q110<=87,"<90%")) -> >90%
A112: Status | B112: =IF(B110>=87,"OK",IF(B110<=87,"LESS")) -> OK | C112: =IF(C110>=87,"OK",IF(C110<=87,"LESS")) -> OK | D112: =IF(D110>=87,"OK",IF(D110<=87,"LESS")) -> OK | E112: =IF(E110>=87,"OK",IF(E110<=87,"LESS")) -> OK | F112: =IF(F110>=87,"OK",IF(F110<=87,"LESS")) -> OK | G112: =IF(G110>=87,"OK",IF(G110<=87,"LESS")) -> OK | H112: =IF(H110>=87,"OK",IF(H110<=87,"LESS")) -> OK | I112: =IF(I110>=87,"OK",IF(I110<=87,"LESS")) -> OK | ... Q112: =IF(Q110>=87,"OK",IF(Q110<=87,"LESS")) -> OK
A115: Done by | B115: RK
A117: Comment

Sheet 08
A1: Station: | B1: BHATAGAON RAIPUR
A2: Date: | B2: =$A$9 -> 08-04-2024 00:15 | D2: Power Off | G2: Pw.Off | L2: Link Fail | N2: Link F | P2: Maintenance | R2: Maint.
A3: Report Type: | B3: Mean | D3: Calibration | G3: Calib. | L3: Data Fail | N3: Data F | P3: Invalid | R3: Invalid
A4: Time Base: | B4: 15 Min | D4: Zero Referrence | G4: Z.Ref | L4: Warm Up | N4: Wm. Up
A7: Date & Time | B7: NO_BHATAGAON | C7: NO2__BHATAGAON | D7: NOX_BHATAGAON | E7: SO2__BHATAGAON | F7: O3__BHATAGAON | G7: PM10__BHATAGAON | H7: PM2_5__BHATAGAON | I7: BENZ__BHATAGAON | J7: WS__BHATAGAON | K7: WD__BHATAGAON | L7: TEMP__BHATAGAON | M7: HUM__BHATAGAON | N7: SR__BHATAGAON | O7: RG__BHATAGAON | P7: CO__BHATAGAON | Q7: NH3__BHATAGAON
B8: ug/m3 | C8: ug/m3 | D8: ppb | E8: ug/m3 | F8: ug/m3 | G8: ug/m3 | H8: ug/m3 | I8: ug/m3 | J8: m/sec | K8: deg | L8: degreC | M8: % | N8: w/m2 | O8: mm | P8: mg/m3 | Q8: ug/m3
A9: 08-04-2024 00:15 | B9: 1.6 | C9: 47.11 | D9: 25.82 | E9: 1.55 | F9: 3.79 | G9: 32.96 | H9: 9.43 | I9: 7.07 | J9: 0.77 | K9: 10.57 | L9: 23.38 | M9: 52.75 | N9: 23 | O9: 0 | P9: 0.38 | Q9: 9.58
A10: 08-04-2024 00:30 | B10: 1.74 | C10: 46.94 | D10: 25.84 | E10: 1.94 | F10: 3.36 | G10: 33.23 | H10: 8.79 | I10: 7.52 | J10: 1.23 | K10: 110.26 | L10: 22.9 | M10: 53.2 | N10: 18.9 | O10: 0 | P10: 0.38 | Q10: 9.49
A11: 08-04-2024 00:45 | B11: 1.87 | C11: 46.31 | D11: 25.61 | E11: 1.85 | F11: 3.45 | G11: 33.23 | H11: 8.79 | I11: 7.45 | J11: 1.35 | K11: 119.96 | L11: 23.11 | M11: 52 | N11: 21.1 | O11: 0 | P11: 0.37 | Q11: 9.53
A12: 08-04-2024 01:00 | B12: 1.81 | C12: 45.54 | D12: 25.16 | E12: 1.75 | F12: 3.29 | G12: 33.23 | H12: 8.79 | I12: 7.38 | J12: 0.49 | K12: 72.4 | L12: 22.39 | M12: 59.7 | N12: 19.9 | O12: 0 | P12: 0.36 | Q12: 9.56
A13: 08-04-2024 01:15 | B13: 1.93 | C13: 46 | D13: 25.5 | E13: 1.81 | F13: 3.34 | G13: 33.4 | H13: 11.35 | I13: 7.44 | J13: 0.59 | K13: 112.07 | L13: 21.55 | M13: 66.07 | N13: 19.7 | O13: 0.2 | P13: 0.39 | Q13: 9.55
A14: 08-04-2024 01:30 | B14: 2.08 | C14: 45.79 | D14: 25.51 | E14: 1.83 | F14: 3.76 | G14: 33.45 | H14: 12.08 | I14: 7.65 | J14: 0.27 | K14: 269.58 | L14: 21.19 | M14: 71.66 | N14: 19.8 | O14: 0 | P14: 0.41 | Q14: 9.57
A15: 08-04-2024 01:45 | B15: 1.89 | C15: 44.61 | D15: 24.74 | E15: 1.88 | F15: 3.7 | G15: 33.45 | H15: 12.08 | I15: 7.79 | J15: 1.04 | K15: 170.87 | L15: 20.3 | M15: 81.54 | N15: 22.8 | O15: 0.6 | P15: 0.4 | Q15: 9.57
A16: 08-04-2024 02:00 | B16: 1.64 | C16: 44.54 | D16: 24.51 | E16: 1.86 | F16: 3.59 | G16: 33.45 | H16: 12.08 | I16: 7.6 | J16: 1.22 | K16: 157.98 | L16: 19.29 | M16: 89.58 | N16: 22.3 | O16: 0.4 | P16: 0.39 | Q16: 9.59
A17: 08-04-2024 02:15 | B17: 1.48 | C17: 44.58 | D17: 24.4 | E17: 1.65 | F17: 3.79 | G17: 33.45 | H17: 22.11 | I17: 7.29 | J17: 1.54 | K17: 159.52 | L17: 18.99 | M17: 89.82 | N17: 21.6 | O17: 0.2 | P17: 0.38 | Q17: 9.6
A18: 08-04-2024 02:30 | B18: 1.12 | C18: 44.65 | D18: 24.15 | E18: 1.68 | F18: 3.97 | G18: 33.45 | H18: 25.16 | I18: 7.07 | J18: 0.94 | K18: 158.09 | L18: 18.65 | M18: 94.21 | N18: 21.6 | O18: 0.4 | P18: 0.37 | Q18: 9.62
A19: 08-04-2024 02:45 | B19: 0.64 | C19: 44.44 | D19: 23.66 | E19: 1.75 | F19: 4.14 | G19: 33.45 | H19: 25.16 | I19: 7.04 | J19: 1.47 | K19: 162.59 | L19: 18.34 | M19: 98.69 | N19: 21.9 | O19: 0.2 | P19: 0.36 | Q19: 9.57
A20: 08-04-2024 03:00 | B20: 0.29 | C20: 43.87 | D20: 23.07 | E20: 2.18 | F20: 3.72 | G20: 33.45 | H20: 25.16 | I20: 6.49 | J20: 1.48 | K20: 158.98 | L20: 18.02 | M20: 100.31 | N20: 22 | O20: 0.4 | P20: 0.35 | Q20: 9.52
... A104: 08-04-2024 24:00 | B104: 6.56 | C104: 45.45 | D104: 28.93 | E104: 1.05 | F104: 3.54 | G104: 31.35 | H104: 10.98 | I104: 7 | J104: 0.34 | K104: 55.16 | L104: 18.44 | M104: 92.31 | N104: 17.4 | O104: 0 | P104: 0.57 | Q104: 9.5
A106: Min | B106: =MIN(B9:B104) -> 0.1 | C106: =MIN(C9:C104) -> 35.65 | D106: =MIN(D9:D104) -> 18.63 | E106: =MIN(E9:E104) -> 0.76 | F106: =MIN(F9:F104) -> 2.72 | G106: =MIN(G9:G104) -> 15.45 | H106: =MIN(H9:H104) -> 5.91 | I106: =MIN(I9:I104) -> 2.14 | ... Q106: =MIN(Q9:Q104) -> 0
A107: Max | B107: =MAX(B9:B104) -> 6.67 | C107: =MAX(C9:C104) -> 48.54 | D107: =MAX(D9:D104) -> 29.33 | E107: =MAX(E9:E104) -> 2.18 | F107: =MAX(F9:F104) -> 7.43 | G107: =MAX(G9:G104) -> 38.5 | H107: =MAX(H9:H104) -> 25.16 | I107: =MAX(I9:I104) -> 8.43 | ... Q107: =MAX(Q9:Q104) -> 9.74
A108: Avg | B108: =AVERAGE(B9:B104) -> 1.443125 | C108: =AVERAGE(C9:C104) -> 42.314062 | D108: =AVERAGE(D9:D104) -> 23.185104 | E108: =AVERAGE(E9:E104) -> 1.6145833 | F108: =AVERAGE(F9:F104) -> 4.4673958 | G108: =AVERAGE(G9:G104) -> 24.416979 | H108: =AVERAGE(H9:H104) -> 10.3575 | I108: =AVERAGE(I9:I104) -> 5.5289583 | ... Q108: =AVERAGE(Q9:Q104) -> 9.084375
A109: Stdev | B109: =STDEV(B9:B104) -> 2.2239237 | C109: =STDEV(C9:C104) -> 3.714752 | D109: =STDEV(D9:D104) -> 3.3708962 | E109: =STDEV(E9:E104) -> 0.2898127 | F109: =STDEV(F9:F104) -> 1.1116666 | G109: =STDEV(G9:G104) -> 6.8690361 | H109: =STDEV(H9:H104) -> 4.0929524 | I109: =STDEV(I9:I104) -> 2.0651746 | ... Q109: =STDEV(Q9:Q104) -> 1.9068932
A110: Num | B110: =COUNT(B9:B104) -> 96 | C110: =COUNT(C9:C104) -> 96 | D110: =COUNT(D9:D104) -> 96 | E110: =COUNT(E9:E104) -> 96 | F110: =COUNT(F9:F104) -> 96 | G110: =COUNT(G9:G104) -> 96 | H110: =COUNT(H9:H104) -> 96 | I110: =COUNT(I9:I104) -> 96 | ... Q110: =COUNT(Q9:Q104) -> 96
A111: DCR | B111: =IF(B110>=87,">90%",IF(B110<=87,"<90%")) -> >90% | C111: =IF(C110>=87,">90%",IF(C110<=87,"<90%")) -> >90% | D111: =IF(D110>=87,">90%",IF(D110<=87,"<90%")) -> >90% | E111: =IF(E110>=87,">90%",IF(E110<=87,"<90%")) -> >90% | F111: =IF(F110>=87,">90%",IF(F110<=87,"<90%")) -> >90% | G111: =IF(G110>=87,">90%",IF(G110<=87,"<90%")) -> >90% | H111: =IF(H110>=87,">90%",IF(H110<=87,"<90%")) -> >90% | I111: =IF(I110>=87,">90%",IF(I110<=87,"<90%")) -> >90% | ... Q111: =IF(Q110>=87,">90%",IF(Q110<=87,"<90%")) -> >90%
A112: Status | B112: =IF(B110>=87,"OK",IF(B110<=87,"LESS")) -> OK | C112: =IF(C110>=87,"OK",IF(C110<=87,"LESS")) -> OK | D112: =IF(D110>=87,"OK",IF(D110<=87,"LESS")) -> OK | E112: =IF(E110>=87,"OK",IF(E110<=87,"LESS")) -> OK | F112: =IF(F110>=87,"OK",IF(F110<=87,"LESS")) -> OK | G112: =IF(G110>=87,"OK",IF(G110<=87,"LESS")) -> OK | H112: =IF(H110>=87,"OK",IF(H110<=87,"LESS")) -> OK | I112: =IF(I110>=87,"OK",IF(I110<=87,"LESS")) -> OK | ... Q112: =IF(Q110>=87,"OK",IF(Q110<=87,"LESS")) -> OK
A115: Done by | B115: RK
A117: Comment

Sheet 09
A1: Station: | B1: BHATAGAON RAIPUR
A2: Date: | B2: =$A$9 -> 09-04-2024 00:15 | D2: Power Off | G2: Pw.Off | L2: Link Fail | N2: Link F | P2: Maintenance | R2: Maint.
A3: Report Type: | B3: Mean | D3: Calibration | G3: Calib. | L3: Data Fail | N3: Data F | P3: Invalid | R3: Invalid
A4: Time Base: | B4: 15 Min | D4: Zero Referrence | G4: Z.Ref | L4: Warm Up | N4: Wm. Up
A7: Date & Time | B7: NO_BHATAGAON | C7: NO2__BHATAGAON | D7: NOX_BHATAGAON | E7: SO2__BHATAGAON | F7: O3__BHATAGAON | G7: PM10__BHATAGAON | H7: PM2_5__BHATAGAON | I7: BENZ__BHATAGAON | J7: WS__BHATAGAON | K7: WD__BHATAGAON | L7: TEMP__BHATAGAON | M7: HUM__BHATAGAON | N7: SR__BHATAGAON | O7: RG__BHATAGAON | P7: CO__BHATAGAON | Q7: NH3__BHATAGAON
B8: ug/m3 | C8: ug/m3 | D8: ppb | E8: ug/m3 | F8: ug/m3 | G8: ug/m3 | H8: ug/m3 | I8: ug/m3 | J8: m/sec | K8: deg | L8: degreC | M8: % | N8: w/m2 | O8: mm | P8: mg/m3 | Q8: ug/m3
A9: 09-04-2024 00:15 | B9: 6.68 | C9: 44.43 | D9: 28.49 | E9: 1.31 | F9: 3.07 | G9: 30.94 | H9: 12.67 | I9: 6.95 | J9: 0.51 | K9: 91.89 | L9: 18.53 | M9: 89.12 | N9: 17 | O9: 0 | P9: 0.58 | Q9: 9.32
A10: 09-04-2024 00:30 | B10: 6.7 | C10: 46.86 | D10: 29.77 | E10: 1.05 | F10: 2.65 | G10: 30.82 | H10: 13.16 | I10: 6.85 | J10: 1.48 | K10: 98.05 | L10: 18.91 | M10: 84.84 | N10: 16.4 | O10: 0 | P10: 0.56 | Q10: 9.59
A11: 09-04-2024 00:45 | B11: 6.12 | C11: 46.2 | D11: 28.96 | E11: 1.25 | F11: 3.45 | G11: 30.82 | H11: 13.16 | I11: 6.87 | J11: 0.67 | K11: 162.17 | L11: 18.99 | M11: 86.05 | N11: 16.6 | O11: 0 | P11: 0.55 | Q11: 9.4
A12: 09-04-2024 01:00 | B12: 5.28 | C12: 45.74 | D12: 28.05 | E12: 1.12 | F12: 3.58 | G12: 30.82 | H12: 13.16 | I12: 7.1 | J12: 0.04 | K12: 13.45 | L12: 18.88 | M12: 88.6 | N12: 16.7 | O12: 0 | P12: 0.53 | Q12: 9.58
A13: 09-04-2024 01:15 | B13: 4.78 | C13: 44.36 | D13: 26.93 | E13: 1.06 | F13: 3.38 | G13: 26.48 | H13: 12.09 | I13: 7.2 | J13: 0.3 | K13: 53.63 | L13: 18.6 | M13: 93.33 | N13: 17.4 | O13: 0.6 | P13: 0.42 | Q13: 9.29
A14: 09-04-2024 01:30 | B14: 4.42 | C14: 43.54 | D14: 26.21 | E14: 0.99 | F14: 3.1 | G14: 25.24 | H14: 11.79 | I14: 6.99 | J14: 0.24 | K14: 13.52 | L14: 18.01 | M14: 97.72 | N14: 17.3 | O14: 6.8 | P14: 0.44 | Q14: 9.63
A15: 09-04-2024 01:45 | B15: 4.06 | C15: 42.24 | D15: 25.24 | E15: 0.97 | F15: 3.32 | G15: 25.24 | H15: 11.79 | I15: 6.74 | J15: 0.59 | K15: 110.85 | L15: 16.82 | M15: 97.77 | N15: 17.5 | O15: 1 | P15: 0.43 | Q15: 9.47
