Workbook

Sheet 01
A1: Station: | B1: BHATAGAON ,RAIPUR
A2: Date: | B2: =$A$9 -> 01-01-2023 01:00 | D2: Power Off | G2: Pw.Off | L2: Link Fail | N2: Link F | P2: Maintenance | R2: Maint.
A3: Report Type: | B3: Mean | D3: Calibration | G3: Calib. | L3: Data Fail | N3: Data F | P3: Invalid | R3: Invalid
A4: Time Base: | B4: 01 Hour | D4: Zero Referrence | G4: Z.Ref | L4: Warm Up | N4: Wm. Up
A7: Date & Time | B7: NO_BHATAGAON | C7: NO2_BHATAGAON | D7: NOX_BHATAGAON | E7: SO2_BHATAGAON | F7: O3_BHATAGAON | G7: PM10_BHATAGAON | H7: PM2_5_BHATAGAON | I7: BENZ_BHATAGAON | J7: WS_BHATAGAON | K7: WD_BHATAGAON | L7: TEMP_BHATAGAON | M7: HUM BHATAGAON | N7: SR_BHATAGAON | O7: RG_BHATAGAON | P7: CO_BHATAGAON | Q7: NH3_BHATAGAON
B8: ug/m3 | C8: ug/m3 | D8: ppb | E8: ug/m3 | F8: ug/m3 | G8: mg/m3 | H8: ug/m3 | I8: ug/m3 | J8: m/sec | K8: deg | L8: degreC | M8: % | N8: w/m2 | O8: mm | P8: ug/m3 | Q8: ug/m3
A9: 01-01-2023 01:00 | B9: 26.9 | C9: 96.95 | D9: 75.08 | E9: 4.85 | F9: 2.54 | G9: 57.12 | H9: 29.84 | I9: 0.45 | J9: 1.01 | K9: 17.02 | L9: 20.76 | M9: 45 | N9: 24.2 | O9: 0 | P9: 1.48 | Q9: 34.62
A10: 01-01-2023 02:00 | B10: 16.55 | C10: 84 | D10: 59.4 | E10: 4.22 | F10: 1.43 | G10: 50.07 | H10: 27.63 | I10: 0.38 | J10: 0.93 | K10: 19.92 | L10: 20.01 | M10: 48 | N10: 24.2 | O10: 0 | P10: 1.15 | Q10: 33.07
A11: 01-01-2023 03:00 | B11: 10.96 | C11: 83.46 | D11: 54.85 | E11: 4.01 | F11: 0.42 | G11: 38.25 | H11: 24.16 | I11: 0.33 | J11: 0.45 | K11: 62.82 | L11: 19.09 | M11: 50 | N11: 24.3 | O11: 0 | P11: 1 | Q11: 32.85
A12: 01-01-2023 04:00 | B12: 7.21 | C12: 78.83 | D12: 49.29 | E12: 3.8 | F12: 0.54 | G12: 35.09 | H12: 19.24 | I12: 0.28 | J12: 0.38 | K12: 73.08 | L12: 18.25 | M12: 55 | N12: 24.2 | O12: 0 | P12: 0.85 | Q12: 32.32
A13: 01-01-2023 05:00 | B13: 5.9 | C13: 73.51 | D13: 45.3 | E13: 4.11 | F13: 0.54 | G13: 34.37 | H13: 17.23 | I13: 0.26 | J13: 0.82 | K13: 54.11 | L13: 17.57 | M13: 56 | N13: 24.1 | O13: 0 | P13: 0.77 | Q13: 31.65
A14: 01-01-2023 06:00 | B14: 5.23 | C14: 71.47 | D14: 43.21 | E14: 4.06 | F14: 1.17 | G14: 40.04 | H14: 19.53 | I14: 0.26 | J14: 0.92 | K14: 24.9 | L14: 17.49 | M14: 55 | N14: 24.3 | O14: 0 | P14: 0.7 | Q14: 32.16
A15: 01-01-2023 07:00 | B15: 6.42 | C15: 74.85 | D15: 46.46 | E15: 4.4 | F15: 0.61 | G15: 36.78 | H15: 19.38 | I15: 0.25 | J15: 0.91 | K15: 23.29 | L15: 17.18 | M15: 57 | N15: 33.8 | O15: 0 | P15: 0.69 | Q15: 31.57
A16: 01-01-2023 08:00 | B16: 7.9 | C16: 76.23 | D16: 48.3 | E16: 4.31 | F16: 0.69 | G16: 50.83 | H16: 21.47 | I16: 0.24 | J16: 1.27 | K16: 20.82 | L16: 19.31 | M16: 56 | N16: 151.9 | O16: 0 | P16: 0.75 | Q16: 29.7
A17: 01-01-2023 09:00 | B17: 8.64 | C17: 80.7 | D17: 51.46 | E17: 6.18 | F17: 0.6 | G17: 49.94 | H17: 24.72 | I17: 0.24 | J17: 1.41 | K17: 29.38 | L17: 23.35 | M17: 44 | N17: 255.7 | O17: 0 | P17: 0.82 | Q17: 29.33
A18: 01-01-2023 10:00 | B18: 13.1 | C18: 90.36 | D18: 60.37 | E18: 5.55 | F18: 0.78 | G18: 60.47 | H18: 26.2 | I18: 0.25 | J18: 0.97 | K18: 111.44 | L18: 26.02 | M18: 41 | N18: 309.7 | O18: 0 | P18: 0.88 | Q18: 30.37
A19: 01-01-2023 11:00 | B19: 13.2 | C19: 90.94 | D19: 60.72 | E19: 5.35 | F19: 1.84 | G19: 59.09 | H19: 25.98 | I19: 0.23 | J19: 1.56 | K19: 112.37 | L19: 25.65 | M19: 41 | N19: 340.2 | O19: 0 | P19: 0.87 | Q19: 30.48
A20: 01-01-2023 12:00 | B20: 12.99 | C20: 87.72 | D20: 58.83 | E20: 6.04 | F20: 3.52 | G20: 60.2 | H20: 27.97 | I20: 0.23 | J20: 1.37 | K20: 117.12 | L20: 26.55 | M20: 37 | N20: 349.5 | O20: 0 | P20: 0.84 | Q20: 29.91
... A32: 01-01-2023 24:00 | B32: 20.49 | C32: 109.29 | D32: 76.74 | E32: 6.08 | F32: 0.23 | G32: 86 | H32: 43.01 | I32: 0.51 | J32: 0.35 | K32: 34.19 | L32: 20.59 | M32: 51 | N32: 24.3 | O32: 0 | P32: 2.09 | Q32: 36.81
A34: Min | B34: =MIN(B9:B32) -> 3.51 | C34: =MIN(C9:C32) -> 71.47 | D34: =MIN(D9:D32) -> 43.21 | E34: =MIN(E9:E32) -> 3.8 | F34: =MIN(F9:F32) -> 0.23 | G34: =MIN(G9:G32) -> 34.37 | H34: =MIN(H9:H32) -> 17.23 | I34: =MIN(I9:I32) -> 0.19 | ... Q34: =MIN(Q9:Q32) -> 29.33
A35: Max | B35: =MAX(B9:B32) -> 26.9 | C35: =MAX(C9:C32) -> 118.35 | D35: =MAX(D9:D32) -> 82 | E35: =MAX(E9:E32) -> 9.14 | F35: =MAX(F9:F32) -> 6.74 | G35: =MAX(G9:G32) -> 99.85 | H35: =MAX(H9:H32) -> 44.53 | I35: =MAX(I9:I32) -> 0.51 | ... Q35: =MAX(Q9:Q32) -> 36.84
A36: Avg | B36: =AVERAGE(B9:B32) -> 11.988333 | C36: =AVERAGE(C9:C32) -> 90.7175 | D36: =AVERAGE(D9:D32) -> 59.514583 | E36: =AVERAGE(E9:E32) -> 5.7554167 | F36: =AVERAGE(F9:F32) -> 1.87125 | G36: =AVERAGE(G9:G32) -> 58.849167 | H36: =AVERAGE(H9:H32) -> 29.020833 | I36: =AVERAGE(I9:I32) -> 0.3 | ... Q36: =AVERAGE(Q9:Q32) -> 33.111667
A37: Stdev | B37: =STDEV(B9:B32) -> 6.6692517 | C37: =STDEV(C9:C32) -> 14.128175 | D37: =STDEV(D9:D32) -> 12.407132 | E37: =STDEV(E9:E32) -> 1.5369478 | F37: =STDEV(F9:F32) -> 1.8303797 | G37: =STDEV(G9:G32) -> 19.938149 | H37: =STDEV(H9:H32) -> 8.1581679 | I37: =STDEV(I9:I32) -> 0.1 | ... Q37: =STDEV(Q9:Q32) -> 2.4015098
A38: Num | B38: =COUNT(B9:B32) -> 24 | C38: =COUNT(C9:C32) -> 24 | D38: =COUNT(D9:D32) -> 24 | E38: =COUNT(E9:E32) -> 24 | F38: =COUNT(F9:F32) -> 24 | G38: =COUNT(G9:G32) -> 24 | H38: 24 | I38: =COUNT(I9:I32) -> 24 | J38: =COUNT(J9:J32) -> 24 | K38: =COUNT(K9:K32) -> 24 | L38: =COUNT(L9:L32) -> 24 | M38: =COUNT(M9:M32) -> 24 | N38: =COUNT(N9:N32) -> 24 | O38: =COUNT(O9:O32) -> 24 | P38: =COUNT(P9:P32) -> 24 | Q38: =COUNT(Q9:Q32) -> 24
A39: DCR | B39: =IF(B38>=22,">90%",IF(B38<=22,"<90%")) -> >90% | C39: =IF(C38>=22,">90%",IF(C38<=22,"<90%")) -> >90% | D39: =IF(D38>=22,">90%",IF(D38<=22,"<90%")) -> >90% | E39: =IF(E38>=22,">90%",IF(E38<=22,"<90%")) -> >90% | F39: =IF(F38>=22,">90%",IF(F38<=22,"<90%")) -> >90% | G39: =IF(G38>=22,">90%",IF(G38<=22,"<90%")) -> >90% | H39: =IF(H38>=22,">90%",IF(H38<=22,"<90%")) -> >90% | I39: =IF(I38>=22,">90%",IF(I38<=22,"<90%")) -> >90% | ... Q39: =IF(Q38>=22,">90%",IF(Q38<=22,"<90%")) -> >90%
A40: Status | B40: =IF(B38>=22,"OK",IF(B38<=22,"LESS")) -> OK | C40: =IF(C38>=22,"OK",IF(C38<=22,"LESS")) -> OK | D40: =IF(D38>=22,"OK",IF(D38<=22,"LESS")) -> OK | E40: =IF(E38>=22,"OK",IF(E38<=22,"LESS")) -> OK | F40: =IF(F38>=22,"OK",IF(F38<=22,"LESS")) -> OK | G40: =IF(G38>=22,"OK",IF(G38<=22,"LESS")) -> OK | H40: =IF(H38>=22,"OK",IF(H38<=22,"LESS")) -> OK | I40: =IF(I38>=22,"OK",IF(I38<=22,"LESS")) -> OK | ... Q40: =IF(Q38>=22,"OK",IF(Q38<=22,"LESS")) -> OK
A43: Done by | B43: RAHUL
A45: Comment

Sheet 02
A1: Station: | B1: BHATAGAON RAIPUR
A2: Date: | B2: =$A$9 -> 02-01-2023 01:00 | D2: Power Off | G2: Pw.Off | L2: Link Fail | N2: Link F | P2: Maintenance | R2: Maint.
A3: Report Type: | B3: Mean | D3: Calibration | G3: Calib. | L3: Data Fail | N3: Data F | P3: Invalid | R3: Invalid
A4: Time Base: | B4: 01 Hour | D4: Zero Referrence | G4: Z.Ref | L4: Warm Up | N4: Wm. Up
A7: Date & Time | B7: NO_BHATAGAON | C7: NO2_BHATAGAON | D7: NOX_BHATAGAON | E7: SO2_BHATAGAON | F7: O3_BHATAGAON | G7: PM10_BHATAGAON | H7: PM2_5_BHATAGAON | I7: BENZ_BHATAGAON | J7: WS_BHATAGAON | K7: WD_BHATAGAON | L7: TEMP_BHATAGAON | M7: HUM BHATAGAON | N7: SR_BHATAGAON | O7: RG_BHATAGAON | P7: CO_BHATAGAON | Q7: NH3_BHATAGAON
B8: ug/m3 | C8: ug/m3 | D8: ppb | E8: ug/m3 | F8: ug/m3 | G8: mg/m3 | H8: ug/m3 | I8: ug/m3 | J8: m/sec | K8: deg | L8: degreC | M8: % | N8: w/m2 | O8: mm | P8: ug/m3 | Q8: ug/m3
A9: 02-01-2023 01:00 | B9: 13.73 | C9: 100.62 | D9: 66.54 | E9: 4.95 | F9: 1.7 | G9: 83.21 | H9: 41.96 | I9: 0.46 | J9: 0.86 | K9: 19.13 | L9: 19.62 | M9: 52 | N9: 24.1 | O9: 0 | P9: 1.79 | Q9: 35.54
A10: 02-01-2023 02:00 | B10: 7.39 | C10: 89.93 | D10: 55.55 | E10: 6.62 | F10: 0.96 | G10: 77.05 | H10: 41.27 | I10: 0.37 | J10: 0.55 | K10: 37.77 | L10: 19.41 | M10: 53 | N10: 24.3 | O10: 0 | P10: 1.44 | Q10: 32.11
A11: 02-01-2023 03:00 | B11: 4.72 | C11: 81.27 | D11: 48.63 | E11: 5.12 | F11: 0.73 | G11: 63.02 | H11: 37.36 | I11: 0.35 | J11: 0.91 | K11: 52.95 | L11: 18.52 | M11: 57 | N11: 24.4 | O11: 0 | P11: 1.29 | Q11: 32.43
A12: 02-01-2023 04:00 | B12: 3.24 | C12: 76.77 | D12: 44.97 | E12: 5.2 | F12: 1.46 | G12: 58.68 | H12: 31.68 | I12: 0.33 | J12: 0.87 | K12: 41.91 | L12: 18.07 | M12: 59 | N12: 24.5 | O12: 0 | P12: 1.13 | Q12: 31.89
A13: 02-01-2023 05:00 | B13: 2.22 | C13: 70.73 | D13: 40.41 | E13: 3.84 | F13: 2.06 | G13: 56.28 | H13: 31.03 | I13: 0.27 | J13: 0.39 | K13: 58.13 | L13: 17.09 | M13: 63 | N13: 24.2 | O13: 0 | P13: 0.98 | Q13: 29.89
A14: 02-01-2023 06:00 | B14: 3.16 | C14: 68.69 | D14: 40.37 | E14: 3.83 | F14: 0.43 | G14: 51.96 | H14: 30.34 | I14: 0.25 | J14: 0.36 | K14: 70.24 | L14: 16.48 | M14: 64 | N14: 24.1 | O14: 0 | P14: 0.92 | Q14: 28.75
A15: 02-01-2023 07:00 | B15: 5.57 | C15: 74.26 | D15: 45.45 | E15: 3.63 | F15: 0.21 | G15: 51.19 | H15: 28.35 | I15: 0.25 | J15: 0.73 | K15: 69.09 | L15: 16.12 | M15: 67 | N15: 32.7 | O15: 0 | P15: 0.92 | Q15: 30.07
A16: 02-01-2023 08:00 | B16: 9.33 | C16: 83.16 | D16: 53.38 | E16: 3.79 | F16: 0.24 | G16: 57.88 | H16: 30.09 | I16: 0.24 | J16: 0.91 | K16: 57.1 | L16: 17.87 | M16: 65 | N16: 128.4 | O16: 0 | P16: 0.96 | Q16: 29.88
A17: 02-01-2023 09:00 | B17: 11.97 | C17: 89.91 | D17: 59.22 | E17: 5.2 | F17: 0.94 | G17: 61.29 | H17: 35.58 | I17: 0.24 | J17: 0.86 | K17: 47.12 | L17: 21.51 | M17: 56 | N17: 228.9 | O17: 0 | P17: 1.04 | Q17: 28.7
A18: 02-01-2023 10:00 | B18: 12.29 | C18: 90.95 | D18: 60.05 | E18: 5.22 | F18: 0.24 | G18: 64.09 | H18: 36.65 | I18: 0.26 | J18: 1.18 | K18: 118.8 | L18: 22.24 | M18: 54 | N18: 293.9 | O18: 0 | P18: 1.05 | Q18: 29.92
A19: 02-01-2023 11:00 | B19: 9.67 | C19: 89.04 | D19: 56.89 | E19: 14.32 | F19: 22.45 | G19: 217.71 | H19: 39.12 | I19: 0.26 | J19: 1.51 | K19: 118.11 | L19: 24.81 | M19: 49 | N19: 331.1 | O19: 0 | P19: 1.02 | Q19: 30.2
A20: 02-01-2023 12:00 | B20: 2.86 | C20: 70.83 | D20: 40.41 | E20: 7.71 | F20: 15.12 | G20: 173.52 | H20: 38.56 | I20: 0.19 | J20: 0.74 | K20: 90.51 | L20: 27.93 | M20: 39 | N20: 338.8 | O20: 0 | P20: 1.01 | Q20: 16.93
... A32: 02-01-2023 24:00 | B32: 6.43 | C32: 94.38 | D32: 56.66 | E32: 4.32 | F32: 1 | G32: 71.14 | H32: 48.78 | I32: 0.39 | J32: 0.37 | K32: 31.65 | L32: 20.01 | M32: 63 | N32: 24.4 | O32: 0 | P32: 1.65 | Q32: 33.55
A34: Min | B34: =MIN(B9:B32) -> 0.5 | C34: =MIN(C9:C32) -> 62.14 | D34: =MIN(D9:D32) -> 34.62 | E34: =MIN(E9:E32) -> 3.63 | F34: =MIN(F9:F32) -> 0.21 | G34: =MIN(G9:G32) -> 43.74 | H34: =MIN(H9:H32) -> 28.35 | I34: =MIN(I9:I32) -> 0.12 | ... Q34: =MIN(Q9:Q32) -> 16.68
A35: Max | B35: =MAX(B9:B32) -> 13.73 | C35: =MAX(C9:C32) -> 113.61 | D35: =MAX(D9:D32) -> 70.93 | E35: =MAX(E9:E32) -> 19.07 | F35: =MAX(F9:F32) -> 38.69 | G35: =MAX(G9:G32) -> 217.71 | H35: =MAX(H9:H32) -> 50.23 | I35: =MAX(I9:I32) -> 0.46 | ... Q35: =MAX(Q9:Q32) -> 35.54
A36: Avg | B36: =AVERAGE(B9:B32) -> 6.3666667 | C36: =AVERAGE(C9:C32) -> 86.445833 | D36: =AVERAGE(D9:D32) -> 52.615833 | E36: =AVERAGE(E9:E32) -> 6.6695833 | F36: =AVERAGE(F9:F32) -> 6.8533333 | G36: =AVERAGE(G9:G32) -> 88.050417 | H36: =AVERAGE(H9:H32) -> 38.462083 | I36: =AVERAGE(I9:I32) -> 0.27125 | ... Q36: =AVERAGE(Q9:Q32) -> 28.370833
A37: Stdev | B37: =STDEV(B9:B32) -> 3.7396741 | C37: =STDEV(C9:C32) -> 15.075708 | D37: =STDEV(D9:D32) -> 10.684282 | E37: =STDEV(E9:E32) -> 3.7288551 | F37: =STDEV(F9:F32) -> 10.192024 | G37: =STDEV(G9:G32) -> 42.786291 | H37: =STDEV(H9:H32) -> 6.6042832 | I37: =STDEV(I9:I32) -> 0.10224916 | ... Q37: =STDEV(Q9:Q32) -> 5.0973957
A38: Num | B38: =COUNT(B9:B32) -> 24 | C38: =COUNT(C9:C32) -> 24 | D38: =COUNT(D9:D32) -> 24 | E38: =COUNT(E9:E32) -> 24 | F38: 24 | G38: =COUNT(G9:G32) -> 24 | H38: =COUNT(H9:H32) -> 24 | I38: =COUNT(I9:I32) -> 24 | J38: =COUNT(J9:J32) -> 24 | K38: =COUNT(K9:K32) -> 24 | L38: =COUNT(L9:L32) -> 24 | M38: =COUNT(M9:M32) -> 24 | N38: =COUNT(N9:N32) -> 24 | ... Q38: =COUNT(Q9:Q32) -> 24
A39: DCR | B39: =IF(B38>=22,">90%",IF(B38<=22,"<90%")) -> >90% | C39: =IF(C38>=22,">90%",IF(C38<=22,"<90%")) -> >90% | D39: =IF(D38>=22,">90%",IF(D38<=22,"<90%")) -> >90% | E39: =IF(E38>=22,">90%",IF(E38<=22,"<90%")) -> >90% | F39: =IF(F38>=22,">90%",IF(F38<=22,"<90%")) -> >90% | G39: =IF(G38>=22,">90%",IF(G38<=22,"<90%")) -> >90% | H39: =IF(H38>=22,">90%",IF(H38<=22,"<90%")) -> >90% | I39: =IF(I38>=22,">90%",IF(I38<=22,"<90%")) -> >90% | ... Q39: =IF(Q38>=22,">90%",IF(Q38<=22,"<90%")) -> >90%
A40: Status | B40: =IF(B38>=22,"OK",IF(B38<=22,"LESS")) -> OK | C40: =IF(C38>=22,"OK",IF(C38<=22,"LESS")) -> OK | D40: =IF(D38>=22,"OK",IF(D38<=22,"LESS")) -> OK | E40: =IF(E38>=22,"OK",IF(E38<=22,"LESS")) -> OK | F40: =IF(F38>=22,"OK",IF(F38<=22,"LESS")) -> OK | G40: =IF(G38>=22,"OK",IF(G38<=22,"LESS")) -> OK | H40: =IF(H38>=22,"OK",IF(H38<=22,"LESS")) -> OK | I40: =IF(I38>=22,"OK",IF(I38<=22,"LESS")) -> OK | ... Q40: =IF(Q38>=22,"OK",IF(Q38<=22,"LESS")) -> OK
A43: Done by | B43: RAHUL
A45: Comment

Sheet 03
A1: Station: | B1: BHATAGAON RAIPUR
A2: Date: | B2: =$A$9 -> 03-01-2023 01:00 | D2: Power Off | G2: Pw.Off | L2: Link Fail | N2: Link F | P2: Maintenance | R2: Maint.
A3: Report Type: | B3: Mean | D3: Calibration | G3: Calib. | L3: Data Fail | N3: Data F | P3: Invalid | R3: Invalid
A4: Time Base: | B4: 01 Hour | D4: Zero Referrence | G4: Z.Ref | L4: Warm Up | N4: Wm. Up
A7: Date & Time | B7: NO_BHATAGAON | C7: NO2_BHATAGAON | D7: NOX_BHATAGAON | E7: SO2_BHATAGAON | F7: O3_BHATAGAON | G7: PM10_BHATAGAON | H7: PM2_5_BHATAGAON | I7: BENZ_BHATAGAON | J7: WS_BHATAGAON | K7: WD_BHATAGAON | L7: TEMP_BHATAGAON | M7: HUM BHATAGAON | N7: SR_BHATAGAON | O7: RG_BHATAGAON | P7: CO_BHATAGAON | Q7: NH3_BHATAGAON
B8: ug/m3 | C8: ug/m3 | D8: ppb | E8: ug/m3 | F8: ug/m3 | G8: mg/m3 | H8: ug/m3 | I8: ug/m3 | J8: m/sec | K8: deg | L8: degreC | M8: % | N8: w/m2 | O8: mm | P8: ug/m3 | Q8: ug/m3
A9: 03-01-2023 01:00 | B9: 5.69 | C9: 90.4 | D9: 54.45 | E9: 3.84 | F9: 0.93 | G9: 75.79 | H9: 44.01 | I9: 0.4 | J9: 0.58 | K9: 73.9 | L9: 19.28 | M9: 69 | N9: 24.3 | O9: 0 | P9: 1.54 | Q9: 34.86
A10: 03-01-2023 02:00 | B10: 2.44 | C10: 82.77 | D10: 47.63 | E10: 4.06 | F10: 0.96 | G10: 80.5 | H10: 44.71 | I10: 0.35 | J10: 0.54 | K10: 75.51 | L10: 18.66 | M10: 69 | N10: 24.4 | O10: 0 | P10: 1.37 | Q10: 33.85
A11: 03-01-2023 03:00 | B11: 3.25 | C11: 75.38 | D11: 43.32 | E11: 3.95 | F11: 0.56 | G11: 77.48 | H11: 44.77 | I11: 0.31 | J11: 0.48 | K11: 62.66 | L11: 18.15 | M11: 69 | N11: 24.3 | O11: 0 | P11: 1.27 | Q11: 31.45
A12: 03-01-2023 04:00 | B12: 4.61 | C12: 73.81 | D12: 44.37 | E12: 4.03 | F12: 2.86 | G12: 75.25 | H12: 44.76 | I12: 0.3 | J12: 0.99 | K12: 16.22 | L12: 17.56 | M12: 71 | N12: 24.3 | O12: 0 | P12: 1.21 | Q12: 33.41
A13: 03-01-2023 05:00 | B13: 4.34 | C13: 74.57 | D13: 44.57 | E13: 4.38 | F13: 7.48 | G13: 75.07 | H13: 45.09 | I13: 0.28 | J13: 0.76 | K13: 16.14 | L13: 17.38 | M13: 73 | N13: 24.5 | O13: 0 | P13: 1.16 | Q13: 32.86
A14: 03-01-2023 06:00 | B14: 5.01 | C14: 74.51 | D14: 45.04 | E14: 4.29 | F14: 0.18 | G14: 76.66 | H14: 45.01 | I14: 0.26 | J14: 0.61 | K14: 39.04 | L14: 16.91 | M14: 74 | N14: 24.4 | O14: 0 | P14: 1.15 | Q14: 31.37
A15: 03-01-2023 07:00 | B15: 9.12 | C15: 77.65 | D15: 50.16 | E15: 4.68 | F15: 0.13 | G15: 74.59 | H15: 44.26 | I15: 0.25 | J15: 0.82 | K15: 25.17 | L15: 16.51 | M15: 74 | N15: 31.9 | O15: 0 | P15: 1.2 | Q15: 29.68
A16: 03-01-2023 08:00 | B16: 10.41 | C16: 80.55 | D16: 52.8 | E16: 4.73 | F16: 0.57 | G16: 82.11 | H16: 43.59 | I16: 0.26 | J16: 0.52 | K16: 67.92 | L16: 17.39 | M16: 73 | N16: 96.9 | O16: 0 | P16: 1.26 | Q16: 31.81
A17: 03-01-2023 09:00 | B17: 10.15 | C17: 81.24 | D17: 52.8 | E17: 3.76 | F17: 0.28 | G17: 110.65 | H17: 51.23 | I17: 0.26 | J17: 1.14 | K17: 102.16 | L17: 18.79 | M17: 71 | N17: 157.9 | O17: 0 | P17: 1.29 | Q17: 31.56
A18: 03-01-2023 10:00 | B18: 10.22 | C18: 81.56 | D18: 53.21 | E18: 3.43 | F18: 0.04 | G18: 107.72 | H18: 51.2 | I18: 0.27 | J18: 0.88 | K18: 99.48 | L18: 22.06 | M18: 66 | N18: 227.6 | O18: 0 | P18: 1.32 | Q18: 30.38
A19: 03-01-2023 11:00 | B19: 9.15 | C19: 81.26 | D19: 52.18 | E19: 4.19 | F19: 0.66 | G19: 92.31 | H19: 52.57 | I19: 0.29 | J19: 0.78 | K19: 101.52 | L19: 24.27 | M19: 62 | N19: 278.6 | O19: 0 | P19: 1.36 | Q19: 33.2
A20: 03-01-2023 12:00 | B20: 5.64 | C20: 82.2 | D20: 49.76 | E20: 4.21 | F20: 2.16 | G20: 92 | H20: 52.43 | I20: 0.28 | J20: 0.97 | K20: 113.67 | L20: 25.54 | M20: 59 | N20: 284.2 | O20: 0 | P20: 1.37 | Q20: 34.04
... A32: 03-01-2023 24:00 | B32: 9.77 | C32: 94.69 | D32: 60.1 | E32: 4.51 | F32: 0.69 | G32: 80.05 | H32: 51.05 | I32: 0.39 | J32: 0.44 | K32: 89.23 | L32: 20.36 | M32: 78 | N32: 24.7 | O32: 0 | P32: 1.62 | Q32: 37.27
A34: Min | B34: =MIN(B9:B32) -> 2.44 | C34: =MIN(C9:C32) -> 73.81 | D34: =MIN(D9:D32) -> 43.32 | E34: =MIN(E9:E32) -> 3.43 | F34: =MIN(F9:F32) -> 0.04 | G34: =MIN(G9:G32) -> 61.69 | H34: =MIN(H9:H32) -> 43.59 | I34: =MIN(I9:I32) -> 0.25 | ... Q34: =MIN(Q9:Q32) -> 29.68
A35: Max | B35: =MAX(B9:B32) -> 23.42 | C35: =MAX(C9:C32) -> 114.62 | D35: =MAX(D9:D32) -> 81.36 | E35: =MAX(E9:E32) -> 6.86 | F35: =MAX(F9:F32) -> 7.48 | G35: =MAX(G9:G32) -> 197.83 | H35: =MAX(H9:H32) -> 52.57 | I35: =MAX(I9:I32) -> 0.48 | ... Q35: =MAX(Q9:Q32) -> 40.68
A36: Avg | B36: =AVERAGE(B9:B32) -> 9.0775 | C36: =AVERAGE(C9:C32) -> 89.501667 | D36: =AVERAGE(D9:D32) -> 56.519583 | E36: =AVERAGE(E9:E32) -> 4.6029167 | F36: =AVERAGE(F9:F32) -> 1.9675 | G36: =AVERAGE(G9:G32) -> 103.30833 | H36: =AVERAGE(H9:H32) -> 48.367083 | I36: =AVERAGE(I9:I32) -> 0.32833333 | ... Q36: =AVERAGE(Q9:Q32) -> 35.254583
A37: Stdev | B37: =STDEV(B9:B32) -> 6.3163496 | C37: =STDEV(C9:C32) -> 12.968152 | D37: =STDEV(D9:D32) -> 11.531269 | E37: =STDEV(E9:E32) -> 0.82659321 | F37: =STDEV(F9:F32) -> 2.1956484 | G37: =STDEV(G9:G32) -> 38.256889 | H37: =STDEV(H9:H32) -> 3.1900122 | I37: =STDEV(I9:I32) -> 0.078334104 | ... Q37: =STDEV(Q9:Q32) -> 3.5198258
A38: Num | B38: =COUNT(B9:B32) -> 24 | C38: =COUNT(C9:C32) -> 24 | D38: =COUNT(D9:D32) -> 24 | E38: 24 | F38: 24 | G38: =COUNT(G9:G32) -> 24 | H38: =COUNT(H9:H32) -> 24 | I38: 24 | J38: =COUNT(J9:J32) -> 24 | K38: =COUNT(K9:K32) -> 24 | L38: =COUNT(L9:L32) -> 24 | M38: =COUNT(M9:M32) -> 24 | N38: =COUNT(N9:N32) -> 24 | O38: =COUNT(O9:O32) -> 24 | P38: =COUNT(P9:P32) -> 24 | Q38: =COUNT(Q9:Q32) -> 24
A39: DCR | B39: =IF(B38>=22,">90%",IF(B38<=22,"<90%")) -> >90% | C39: =IF(C38>=22,">90%",IF(C38<=22,"<90%")) -> >90% | D39: =IF(D38>=22,">90%",IF(D38<=22,"<90%")) -> >90% | E39: =IF(E38>=22,">90%",IF(E38<=22,"<90%")) -> >90% | F39: =IF(F38>=22,">90%",IF(F38<=22,"<90%")) -> >90% | G39: =IF(G38>=22,">90%",IF(G38<=22,"<90%")) -> >90% | H39: =IF(H38>=22,">90%",IF(H38<=22,"<90%")) -> >90% | I39: =IF(I38>=22,">90%",IF(I38<=22,"<90%")) -> >90% | ... Q39: =IF(Q38>=22,">90%",IF(Q38<=22,"<90%")) -> >90%
A40: Status | B40: =IF(B38>=22,"OK",IF(B38<=22,"LESS")) -> OK | C40: =IF(C38>=22,"OK",IF(C38<=22,"LESS")) -> OK | D40: =IF(D38>=22,"OK",IF(D38<=22,"LESS")) -> OK | E40: =IF(E38>=22,"OK",IF(E38<=22,"LESS")) -> OK | F40: =IF(F38>=22,"OK",IF(F38<=22,"LESS")) -> OK | G40: =IF(G38>=22,"OK",IF(G38<=22,"LESS")) -> OK | H40: =IF(H38>=22,"OK",IF(H38<=22,"LESS")) -> OK | I40: =IF(I38>=22,"OK",IF(I38<=22,"LESS")) -> OK | ... Q40: =IF(Q38>=22,"OK",IF(Q38<=22,"LESS")) -> OK
A43: Done by | B43: RAHUL
A45: Comment

Sheet 04
A1: Station: | B1: BHATAGAON RAIPUR
A2: Date: | B2: =$A$9 -> 04-01-2023 01:00 | D2: Power Off | G2: Pw.Off | L2: Link Fail | N2: Link F | P2: Maintenance | R2: Maint.
A3: Report Type: | B3: Mean | D3: Calibration | G3: Calib. | L3: Data Fail | N3: Data F | P3: Invalid | R3: Invalid
A4: Time Base: | B4: 01 Hour | D4: Zero Referrence | G4: Z.Ref | L4: Warm Up | N4: Wm. Up
A7: Date & Time | B7: NO_BHATAGAON | C7: NO2_BHATAGAON | D7: NOX_BHATAGAON | E7: SO2_BHATAGAON | F7: O3_BHATAGAON | G7: PM10_BHATAGAON | H7: PM2_5_BHATAGAON | I7: BENZ_BHATAGAON | J7: WS_BHATAGAON | K7: WD_BHATAGAON | L7: TEMP_BHATAGAON | M7: HUM BHATAGAON | N7: SR_BHATAGAON | O7: RG_BHATAGAON | P7: CO_BHATAGAON | Q7: NH3_BHATAGAON
B8: ug/m3 | C8: ug/m3 | D8: ppb | E8: ug/m3 | F8: ug/m3 | G8: mg/m3 | H8: ug/m3 | I8: ug/m3 | J8: m/sec | K8: deg | L8: degreC | M8: % | N8: w/m2 | O8: mm | P8: ug/m3 | Q8: ug/m3
A9: 04-01-2023 01:00 | B9: 8.49 | C9: 87.93 | D9: 55.34 | E9: 4.48 | F9: 0.55 | G9: 76.72 | H9: 50.62 | I9: 0.37 | J9: 0.8 | K9: 88.35 | L9: 20.18 | M9: 79 | N9: 25 | O9: 0 | P9: 1.51 | Q9: 37.33
A10: 04-01-2023 02:00 | B10: 5.4 | C10: 80.17 | D10: 48.58 | E10: 4.28 | F10: 1.14 | G10: 63.37 | H10: 50.22 | I10: 0.36 | J10: 0.93 | K10: 92.34 | L10: 20.03 | M10: 80 | N10: 25.2 | O10: 0 | P10: 1.36 | Q10: 38.28
A11: 04-01-2023 03:00 | B11: 2.53 | C11: 76.17 | D11: 44.06 | E11: 4.27 | F11: 1.39 | G11: 80.45 | H11: 49.92 | I11: 0.31 | J11: 0.92 | K11: 95.03 | L11: 19.55 | M11: 81 | N11: 25 | O11: 0 | P11: 1.29 | Q11: 36.69
A12: 04-01-2023 04:00 | B12: 3.07 | C12: 72.96 | D12: 42.35 | E12: 4.59 | F12: 0.19 | G12: 84.21 | H12: 51.53 | I12: 0.28 | J12: 1.24 | K12: 97.51 | L12: 18.87 | M12: 81 | N12: 24.6 | O12: 0 | P12: 1.23 | Q12: 34.58
A13: 04-01-2023 05:00 | B13: 3.23 | C13: 70.59 | D13: 41.54 | E13: 4.02 | F13: 0.34 | G13: 81.21 | H13: 51.15 | I13: 0.28 | J13: 0.7 | K13: 93.85 | L13: 18.34 | M13: 81 | N13: 24.6 | O13: 0 | P13: 1.19 | Q13: 36.29
A14: 04-01-2023 06:00 | B14: 3.84 | C14: 71.92 | D14: 42.77 | E14: 3.58 | F14: 0.55 | G14: 73.12 | H14: 49.41 | I14: 0.27 | J14: 0.53 | K14: 90.35 | L14: 18.21 | M14: 81 | N14: 25 | O14: 0 | P14: 1.17 | Q14: 36.16
A15: 04-01-2023 07:00 | B15: 6.15 | C15: 74.2 | D15: 45.88 | E15: 3.5 | F15: 0.63 | G15: 80 | H15: 48.12 | I15: 0.25 | J15: 0.68 | K15: 49.52 | L15: 18.51 | M15: 81 | N15: 27.6 | O15: 0 | P15: 1.19 | Q15: 35.08
A16: 04-01-2023 08:00 | B16: 11.12 | C16: 77.15 | D16: 51.49 | E16: 3.63 | F16: 0.19 | G16: 79.49 | H16: 51.81 | I16: 0.26 | J16: 1.1 | K16: 14.44 | L16: 18.47 | M16: 81 | N16: 27.6 | O16: 0 | P16: 1.33 | Q16: 33.27
A17: 04-01-2023 09:00 | B17: 17.35 | C17: 82.84 | D17: 59.63 | E17: 3.37 | F17: 1.35 | G17: 95.68 | H17: 53.13 | I17: 0.27 | J17: 1.06 | K17: 11.34 | L17: 17.83 | M17: 91 | N17: 40.9 | O17: 0.4 | P17: 1.47 | Q17: 34.8
A18: 04-01-2023 10:00 | B18: 28.02 | C18: 90.01 | D18: 72.15 | E18: 3.54 | F18: 0.63 | G18: 98.6 | H18: 55.34 | I18: 0.26 | J18: 0.93 | K18: 347.56 | L18: 17.61 | M18: 92 | N18: 48 | O18: 0.4 | P18: 1.75 | Q18: 34.27
A19: 04-01-2023 11:00 | B19: 55.13 | C19: 109.65 | D19: 104.72 | E19: 13.73 | F19: 0.74 | G19: 117.78 | H19: 63.27 | I19: 0.27 | J19: 0.97 | K19: 353.38 | L19: 17.54 | M19: 93 | N19: 69.3 | O19: 0.2 | P19: 2.63 | Q19: 32.66
A20: 04-01-2023 12:00 | B20: 57.81 | C20: 113.39 | D20: 108.13 | E20: 7.74 | F20: 4.46 | G20: 135.54 | H20: 67.57 | I20: 0.26 | J20: 1.46 | K20: 117.58 | L20: 17.51 | M20: 94 | N20: 59 | O20: 0.4 | P20: 2.6 | Q20: 26.06
... A32: 04-01-2023 24:00 | B32: 39.34 | C32: 97.46 | D32: 85.33 | E32: 5.01 | F32: 4.18 | G32: 110.06 | H32: 66.67 | I32: 0.39 | J32: 0.57 | K32: 90.64 | L32: 17.62 | M32: 83 | N32: 25 | O32: 0 | P32: 2.29 | Q32: 36.34
A34: Min | B34: =MIN(B9:B32) -> 2.53 | C34: =MIN(C9:C32) -> 70.59 | D34: =MIN(D9:D32) -> 41.54 | E34: =MIN(E9:E32) -> 2.06 | F34: =MIN(F9:F32) -> 0.19 | G34: =MIN(G9:G32) -> 63.37 | H34: =MIN(H9:H32) -> 48.12 | I34: =MIN(I9:I32) -> 0.21 | ... Q34: =MIN(Q9:Q32) -> 24.73
A35: Max | B35: =MAX(B9:B32) -> 57.81 | C35: =MAX(C9:C32) -> 113.39 | D35: =MAX(D9:D32) -> 108.13 | E35: =MAX(E9:E32) -> 13.73 | F35: =MAX(F9:F32) -> 5.27 | G35: =MAX(G9:G32) -> 135.54 | H35: =MAX(H9:H32) -> 67.57 | I35: =MAX(I9:I32) -> 0.44 | ... Q35: =MAX(Q9:Q32) -> 38.28
A36: Avg | B36: =AVERAGE(B9:B32) -> 28.960417 | C36: =AVERAGE(C9:C32) -> 92.045 | D36: =AVERAGE(D9:D32) -> 73.680833 | E36: =AVERAGE(E9:E32) -> 4.3595833 | F36: =AVERAGE(F9:F32) -> 2.7766667 | G36: =AVERAGE(G9:G32) -> 92.51875 | H36: =AVERAGE(H9:H32) -> 58.105833 | I36: =AVERAGE(I9:I32) -> 0.29458333 | ... Q36: =AVERAGE(Q9:Q32) -> 32.405417
A37: Stdev | B37: =STDEV(B9:B32) -> 19.026814 | C37: =STDEV(C9:C32) -> 13.227811 | D37: =STDEV(D9:D32) -> 22.109568 | E37: =STDEV(E9:E32) -> 2.3481565 | F37: =STDEV(F9:F32) -> 1.9918261 | G37: =STDEV(G9:G32) -> 17.042369 | H37: =STDEV(H9:H32) -> 6.8357932 | I37: =STDEV(I9:I32) -> 0.064469687 | ... Q37: =STDEV(Q9:Q32) -> 4.4102854
A38: Num | B38: =COUNT(B9:B32) -> 24 | C38: =COUNT(C9:C32) -> 24 | D38: =COUNT(D9:D32) -> 24 | E38: =COUNT(E9:E32) -> 24 | F38: 24 | G38: 24 | H38: 24 | I38: 24 | J38: =COUNT(J9:J32) -> 24 | K38: =COUNT(K9:K32) -> 24 | L38: =COUNT(L9:L32) -> 24 | M38: =COUNT(M9:M32) -> 24 | N38: =COUNT(N9:N32) -> 24 | O38: =COUNT(O9:O32) -> 24 | P38: =COUNT(P9:P32) -> 24 | Q38: =COUNT(Q9:Q32) -> 24
A39: DCR | B39: =IF(B38>=22,">90%",IF(B38<=22,"<90%")) -> >90% | C39: =IF(C38>=22,">90%",IF(C38<=22,"<90%")) -> >90% | D39: =IF(D38>=22,">90%",IF(D38<=22,"<90%")) -> >90% | E39: =IF(E38>=22,">90%",IF(E38<=22,"<90%")) -> >90% | F39: =IF(F38>=22,">90%",IF(F38<=22,"<90%")) -> >90% | G39: =IF(G38>=22,">90%",IF(G38<=22,"<90%")) -> >90% | H39: =IF(H38>=22,">90%",IF(H38<=22,"<90%")) -> >90% | I39: =IF(I38>=22,">90%",IF(I38<=22,"<90%")) -> >90% | ... Q39: =IF(Q38>=22,">90%",IF(Q38<=22,"<90%")) -> >90%
A40: Status | B40: =IF(B38>=22,"OK",IF(B38<=22,"LESS")) -> OK | C40: =IF(C38>=22,"OK",IF(C38<=22,"LESS")) -> OK | D40: =IF(D38>=22,"OK",IF(D38<=22,"LESS")) -> OK | E40: =IF(E38>=22,"OK",IF(E38<=22,"LESS")) -> OK | F40: =IF(F38>=22,"OK",IF(F38<=22,"LESS")) -> OK | G40: =IF(G38>=22,"OK",IF(G38<=22,"LESS")) -> OK | H40: =IF(H38>=22,"OK",IF(H38<=22,"LESS")) -> OK | I40: =IF(I38>=22,"OK",IF(I38<=22,"LESS")) -> OK | ... Q40: =IF(Q38>=22,"OK",IF(Q38<=22,"LESS")) -> OK
A43: Done by | B43: RAHUL
A45: Comment

Sheet 05
A1: Station: | B1: BHATAGAON RAIPUR
A2: Date: | B2: =$A$9 -> 05-01-2023 01:00 | D2: Power Off | G2: Pw.Off | L2: Link Fail | N2: Link F | P2: Maintenance | R2: Maint.
A3: Report Type: | B3: Mean | D3: Calibration | G3: Calib. | L3: Data Fail | N3: Data F | P3: Invalid | R3: Invalid
A4: Time Base: | B4: 01 Hour | D4: Zero Referrence | G4: Z.Ref | L4: Warm Up | N4: Wm. Up
A7: Date & Time | B7: NO_BHATAGAON | C7: NO2_BHATAGAON | D7: NOX_BHATAGAON | E7: SO2_BHATAGAON | F7: O3_BHATAGAON | G7: PM10_BHATAGAON | H7: PM2_5_BHATAGAON | I7: BENZ_BHATAGAON | J7: WS_BHATAGAON | K7: WD_BHATAGAON | L7: TEMP_BHATAGAON | M7: HUM BHATAGAON | N7: SR_BHATAGAON | O7: RG_BHATAGAON | P7: CO_BHATAGAON | Q7: NH3_BHATAGAON
B8: ug/m3 | C8: ug/m3 | D8: ppb | E8: ug/m3 | F8: ug/m3 | G8: mg/m3 | H8: ug/m3 | I8: ug/m3 | J8: m/sec | K8: deg | L8: degreC | M8: % | N8: w/m2 | O8: mm | P8: ug/m3 | Q8: ug/m3
A9: 05-01-2023 01:00 | B9: 30.11 | C9: 89.65 | D9: 73.62 | E9: 4.06 | F9: 4.02 | G9: 102.31 | H9: 64.25 | I9: 0.34 | J9: 0.62 | K9: 123.89 | L9: 17.69 | M9: 84 | N9: 25.3 | O9: 0 | P9: 2.06 | Q9: 35.21
A10: 05-01-2023 02:00 | B10: 24.22 | C10: 81.46 | D10: 64.38 | E10: 3.89 | F10: 4.21 | G10: 89.41 | H10: 63.35 | I10: 0.31 | J10: 0.33 | K10: 73.54 | L10: 17.46 | M10: 84 | N10: 25.3 | O10: 0 | P10: 1.83 | Q10: 34.46
A11: 05-01-2023 03:00 | B11: 18.08 | C11: 76.64 | D11: 56.8 | E11: 4.22 | F11: 4.16 | G11: 78.57 | H11: 59.11 | I11: 0.3 | J11: 0.68 | K11: 73.62 | L11: 16.86 | M11: 86 | N11: 25 | O11: 0 | P11: 1.7 | Q11: 36.32
A12: 05-01-2023 04:00 | B12: 12.77 | C12: 71.73 | D12: 49.83 | E12: 3.91 | F12: 4.02 | G12: 70.04 | H12: 55.73 | I12: 0.26 | J12: 1.32 | K12: 31.6 | L12: 16.82 | M12: 84 | N12: 25 | O12: 0 | P12: 1.54 | Q12: 34.6
A13: 05-01-2023 05:00 | B13: 10.35 | C13: 71.64 | D13: 47.73 | E13: 3.55 | F13: 4.25 | G13: 78.72 | H13: 55.35 | I13: 0.22 | J13: 0.97 | K13: 43.8 | L13: 16.7 | M13: 85 | N13: 25.3 | O13: 0 | P13: 1.68 | Q13: 33.36
A14: 05-01-2023 06:00 | B14: 10.34 | C14: 70.07 | D14: 46.75 | E14: 3.42 | F14: 4.15 | G14: 79.83 | H14: 56.87 | I14: 0.22 | J14: 1.14 | K14: 28.97 | L14: 16.01 | M14: 87 | N14: 25 | O14: 0 | P14: 1.67 | Q14: 33.74
A15: 05-01-2023 07:00 | B15: 12.34 | C15: 70.51 | D15: 48.81 | E15: 3.04 | F15: 4.05 | G15: 79.82 | H15: 56.47 | I15: 0.21 | J15: 0.81 | K15: 30.17 | L15: 16.07 | M15: 87 | N15: 31.4 | O15: 0 | P15: 1.56 | Q15: 34.25
A16: 05-01-2023 08:00 | B16: 16.12 | C16: 72.2 | D16: 52.77 | E16: 3.24 | F16: 4.15 | G16: 82.51 | H16: 57.61 | I16: 0.19 | J16: 1.09 | K16: 24.44 | L16: 16.49 | M16: 85 | N16: 106.3 | O16: 0 | P16: 1.5 | Q16: 33.21
A17: 05-01-2023 09:00 | B17: 20.52 | C17: 75.37 | D17: 57.93 | E17: 3.66 | F17: 4.25 | G17: 87.48 | H17: 57.5 | I17: 0.21 | J17: 0.98 | K17: 36.34 | L17: 18.14 | M17: 81 | N17: 232.4 | O17: 0 | P17: 1.53 | Q17: 32.45
A18: 05-01-2023 10:00 | B18: 21.03 | C18: 78.98 | D18: 60.26 | E18: 3.75 | F18: 4.24 | G18: 86.92 | H18: 58.46 | I18: 0.21 | J18: 1.06 | K18: 113.72 | L18: 19.08 | M18: 75 | N18: 374.6 | O18: 0 | P18: 1.54 | Q18: 37.75
A19: 05-01-2023 11:00 | B19: 22.23 | C19: 88.88 | D19: 65.66 | E19: 4.89 | F19: 4.58 | G19: 84.75 | H19: 57.65 | I19: 0.22 | J19: 1.2 | K19: 84.39 | L19: 22.37 | M19: 69 | N19: 446.1 | O19: 0 | P19: 1.6 | Q19: 38.05
A20: 05-01-2023 12:00 | B20: 17.31 | C20: 88.91 | D20: 62.94 | E20: Calib. | F20: 3.92 | G20: Calib. | H20: Calib. | I20: 0.21 | J20: 1.25 | K20: 136.84 | L20: 22.2 | M20: 67 | N20: 508.1 | O20: 0 | P20: 1.53 | Q20: 30.07
A21: 05-01-2023 13:00 | B21: 8.96 | C21: 89.15 | D21: 52.84 | E21: 4.8 | F21: 4.43 | G21: Calib. | H21: Calib. | I21: 0.15 | J21: 0.9 | K21: 90.01 | L21: 25.23 | M21: 63 | N21: 515.5 | O21: 0 | P21: Maint. | Q21: 29.23
A22: 05-01-2023 14:00 | B22: 5.17 | C22: 85.69 | D22: 51.05 | E22: 6.06 | F22: 3.51 | G22: 106.36 | H22: 45.77 | I22: 0.16 | J22: 0.68 | K22: 76.68 | L22: 25.03 | M22: 59 | N22: 454.2 | O22: 0 | P22: Maint. | Q22: 31.83
A23: 05-01-2023 15:00 | B23: 6.15 | C23: 75.85 | D23: 45.44 | E23: 9.99 | F23: 10.39 | G23: 106.36 | H23: 50.28 | I23: 0.15 | J23: 0.98 | K23: 129.55 | L23: 26.16 | M23: 60 | N23: 359.1 | O23: 0 | P23: Maint. | Q23: 34.28
A24: 05-01-2023 16:00 | B24: 8.86 | C24: 89.35 | D24: 55.82 | E24: 11.88 | F24: 17.33 | G24: 106.31 | H24: 50.28 | I24: 0.14 | J24: 0.84 | K24: 58.08 | L24: 25.6 | M24: 60 | N24: 225.7 | O24: 0 | P24: Maint. | Q24: 30.01
A25: 05-01-2023 17:00 | B25: 8.61 | C25: 98.83 | D25: 61.26 | E25: 14.35 | F25: 5.1 | G25: 98.99 | H25: 54.18 | I25: 0.16 | J25: 1.37 | K25: 351.58 | L25: 24.5 | M25: 64 | N25: 89.2 | O25: 0 | P25: Maint. | Q25: 32.37
A26: 05-01-2023 18:00 | B26: 7.04 | C26: 98.05 | D26: 59.76 | E26: 4.24 | F26: 1.93 | G26: 102.83 | H26: 56.32 | I26: 0.17 | J26: 1.16 | K26: 350.69 | L26: 22.53 | M26: 69 | N26: 38.6 | O26: 0 | P26: Maint. | Q26: 33.89
A27: 05-01-2023 19:00 | B27: 9.87 | C27: 97.46 | D27: 61.63 | E27: 3.13 | F27: 0.64 | G27: 109.87 | H27: 59.78 | I27: 0.23 | J27: 1.44 | K27: 20.16 | L27: 21.47 | M27: 70 | N27: 24.7 | O27: 0 | P27: Maint. | Q27: 34.3
A28: 05-01-2023 20:00 | B28: 14.03 | C28: 100.5 | D28: 66.72 | E28: 4.05 | F28: 0.4 | G28: 119.01 | H28: 65.42 | I28: 0.29 | J28: 1.22 | K28: 21.72 | L28: 21.01 | M28: 70 | N28: 25 | O28: 0 | P28: Maint. | Q28: 35.29
A29: 05-01-2023 21:00 | B29: 17.45 | C29: 104.53 | D29: 71.68 | E29: 2.94 | F29: 0.14 | G29: 123.3 | H29: 66.68 | I29: 0.34 | J29: 0.85 | K29: 24.49 | L29: 20.97 | M29: 69 | N29: 25.2 | O29: 0 | P29: Maint. | Q29: 38.65
A30: 05-01-2023 22:00 | B30: 19.11 | C30: 104.51 | D30: 72.54 | E30: 4.08 | F30: 1.08 | G30: 124.5 | H30: 66.68 | I30: 0.35 | J30: 0.93 | K30: 23.9 | L30: 20.66 | M30: 70 | N30: 25 | O30: 0 | P30: Maint. | Q30: 39.84
A31: 05-01-2023 23:00 | B31: 18.1 | C31: 96.52 | D31: 67.78 | E31: 3.28 | F31: 0.42 | G31: 124.5 | H31: 65.8 | I31: 0.35 | J31: 0.95 | K31: 77.97 | L31: 20.09 | M31: 73 | N31: 25 | O31: 0 | P31: Maint. | Q31: 37.77
A32: 05-01-2023 24:00 | B32: 17.04 | C32: 91.57 | D32: 64.05 | E32: 3.07 | F32: 0.04 | G32: 118.47 | H32: 65.8 | I32: 0.34 | J32: 0.35 | K32: 57.44 | L32: 19.14 | M32: 76 | N32: 24.9 | O32: 0 | P32: Maint. | Q32: 41.87
A34: Min | B34: =MIN(B9:B32) -> 5.17 | C34: =MIN(C9:C32) -> 70.07 | D34: =MIN(D9:D32) -> 45.44 | E34: =MIN(E9:E32) -> 2.94 | F34: =MIN(F9:F32) -> 0.04 | G34: =MIN(G9:G32) -> 70.04 | H34: =MIN(H9:H32) -> 45.77 | I34: =MIN(I9:I32) -> 0.14 | ... Q34: =MIN(Q9:Q32) -> 29.23
A35: Max | B35: =MAX(B9:B32) -> 30.11 | C35: =MAX(C9:C32) -> 104.53 | D35: =MAX(D9:D32) -> 73.62 | E35: =MAX(E9:E32) -> 14.35 | F35: =MAX(F9:F32) -> 17.33 | G35: =MAX(G9:G32) -> 124.5 | H35: =MAX(H9:H32) -> 66.68 | I35: =MAX(I9:I32) -> 0.35 | ... Q35: =MAX(Q9:Q32) -> 41.87
A36: Avg | B36: =AVERAGE(B9:B32) -> 14.825417 | C36: =AVERAGE(C9:C32) -> 86.16875 | D36: =AVERAGE(D9:D32) -> 59.085417 | E36: =AVERAGE(E9:E32) -> 4.9347826 | F36: =AVERAGE(F9:F32) -> 3.9754167 | G36: =AVERAGE(G9:G32) -> 98.220909 | H36: =AVERAGE(H9:H32) -> 58.606364 | I36: =AVERAGE(I9:I32) -> 0.23875 | ... Q36: =AVERAGE(Q9:Q32) -> 34.7
A37: Stdev | B37: =STDEV(B9:B32) -> 6.3259541 | C37: =STDEV(C9:C32) -> 11.415513 | D37: =STDEV(D9:D32) -> 8.4127703 | E37: =STDEV(E9:E32) -> 2.9870446 | F37: =STDEV(F9:F32) -> 3.6190522 | G37: =STDEV(G9:G32) -> 17.197686 | H37: =STDEV(H9:H32) -> 5.7492513 | I37: =STDEV(I9:I32) -> 0.071280981 | ... Q37: =STDEV(Q9:Q32) -> 3.1269905
A38: Num | B38: =COUNT(B9:B32) -> 24 | C38: =COUNT(C9:C32) -> 24 | D38: =COUNT(D9:D32) -> 24 | E38: =COUNT(E9:E32)+1 -> 24 | F38: =COUNT(F9:F32) -> 24 | G38: =COUNT(G9:G32)+2 -> 24 | H38: =COUNT(H9:H32)+2 -> 24 | I38: =COUNT(I9:I32) -> 24 | J38: =COUNT(J9:J32) -> 24 | K38: =COUNT(K9:K32) -> 24 | L38: =COUNT(L9:L32) -> 24 | M38: =COUNT(M9:M32) -> 24 | N38: =COUNT(N9:N32) -> 24 | O38: =COUNT(O9:O32) -> 24 | P38: =COUNT(P9:P32)+12 -> 24 | Q38: =COUNT(Q9:Q32) -> 24
A39: DCR | B39: =IF(B38>=22,">90%",IF(B38<=22,"<90%")) -> >90% | C39: =IF(C38>=22,">90%",IF(C38<=22,"<90%")) -> >90% | D39: =IF(D38>=22,">90%",IF(D38<=22,"<90%")) -> >90% | E39: =IF(E38>=22,">90%",IF(E38<=22,"<90%")) -> >90% | F39: =IF(F38>=22,">90%",IF(F38<=22,"<90%")) -> >90% | G39: =IF(G38>=22,">90%",IF(G38<=22,"<90%")) -> >90% | H39: =IF(H38>=22,">90%",IF(H38<=22,"<90%")) -> >90% | I39: =IF(I38>=22,">90%",IF(I38<=22,"<90%")) -> >90% | ... Q39: =IF(Q38>=22,">90%",IF(Q38<=22,"<90%")) -> >90%
A40: Status | B40: =IF(B38>=22,"OK",IF(B38<=22,"LESS")) -> OK | C40: =IF(C38>=22,"OK",IF(C38<=22,"LESS")) -> OK | D40: =IF(D38>=22,"OK",IF(D38<=22,"LESS")) -> OK | E40: =IF(E38>=22,"OK",IF(E38<=22,"LESS")) -> OK | F40: =IF(F38>=22,"OK",IF(F38<=22,"LESS")) -> OK | G40: =IF(G38>=22,"OK",IF(G38<=22,"LESS")) -> OK | H40: =IF(H38>=22,"OK",IF(H38<=22,"LESS")) -> OK | I40: =IF(I38>=22,"OK",IF(I38<=22,"LESS")) -> OK | ... Q40: =IF(Q38>=22,"OK",IF(Q38<=22,"LESS")) -> OK
A43: Done by | B43: RAHUL
A45: Comment

Sheet 06
A1: Station: | B1: BHATAGAON RAIPUR
A2: Date: | B2: =$A$9 -> 06-01-2023 01:00 | D2: Power Off | G2: Pw.Off | L2: Link Fail | N2: Link F | P2: Maintenance | R2: Maint.
A3: Report Type: | B3: Mean | D3: Calibration | G3: Calib. | L3: Data Fail | N3: Data F | P3: Invalid | R3: Invalid
A4: Time Base: | B4: 01 Hour | D4: Zero Referrence | G4: Z.Ref | L4: Warm Up | N4: Wm. Up
A7: Date & Time | B7: NO_BHATAGAON | C7: NO2_BHATAGAON | D7: NOX_BHATAGAON | E7: SO2_BHATAGAON | F7: O3_BHATAGAON | G7: PM10_BHATAGAON | H7: PM2_5_BHATAGAON | I7: BENZ_BHATAGAON | J7: WS_BHATAGAON | K7: WD_BHATAGAON | L7: TEMP_BHATAGAON | M7: HUM BHATAGAON | N7: SR_BHATAGAON | O7: RG_BHATAGAON | P7: CO_BHATAGAON | Q7: NH3_BHATAGAON
B8: ug/m3 | C8: ug/m3 | D8: ppb | E8: ug/m3 | F8: ug/m3 | G8: mg/m3 | H8: ug/m3 | I8: ug/m3 | J8: m/sec | K8: deg | L8: degreC | M8: % | N8: w/m2 | O8: mm | P8: ug/m3 | Q8: ug/m3
A9: 06-01-2023 01:00 | B9: 15.01 | C9: 89.84 | D9: 61.08 | E9: 2.87 | F9: 0.1 | G9: 109.84 | H9: 64.17 | I9: 0.33 | J9: 0.79 | K9: 76.75 | L9: 18.5 | M9: 77 | N9: 24.8 | O9: 0 | P9: Maint. | Q9: 41.23
A10: 06-01-2023 02:00 | B10: 13.39 | C10: 84.26 | D10: 55.96 | E10: 2.87 | F10: 0.54 | G10: 104.83 | H10: 58.18 | I10: 0.29 | J10: 1.16 | K10: 27.98 | L10: 18.37 | M10: 75 | N10: 24.9 | O10: 0 | P10: Maint. | Q10: 39.83
A11: 06-01-2023 03:00 | B11: 9.8 | C11: 81.32 | D11: 52.74 | E11: 2.97 | F11: 0.34 | G11: 97.16 | H11: 56.42 | I11: 0.26 | J11: 1.1 | K11: 46.76 | L11: 17.9 | M11: 70 | N11: 25 | O11: 0 | P11: Maint. | Q11: 39.21
A12: 06-01-2023 04:00 | B12: 6.69 | C12: 76.39 | D12: 47.52 | E12: 2.78 | F12: 0.29 | G12: 91.73 | H12: 53.89 | I12: 0.24 | J12: 0.65 | K12: 50.04 | L12: 17.57 | M12: 72 | N12: 25.3 | O12: 0 | P12: Maint. | Q12: 39.59
A13: 06-01-2023 05:00 | B13: 6.69 | C13: 72.8 | D13: 44.91 | E13: 3.02 | F13: 0.28 | G13: 83.61 | H13: 51.97 | I13: 0.21 | J13: 0.53 | K13: 58.13 | L13: 16.74 | M13: 69 | N13: 24.7 | O13: 0 | P13: Maint. | Q13: 39.62
A14: 06-01-2023 06:00 | B14: 10.63 | C14: 74.41 | D14: 49.29 | E14: 3.21 | F14: 0.15 | G14: 75.9 | H14: 45.89 | I14: 0.19 | J14: 0.76 | K14: 50.7 | L14: 16.29 | M14: 71 | N14: 24.9 | O14: 0 | P14: Maint. | Q14: 37.19
A15: 06-01-2023 07:00 | B15: 12.42 | C15: 75.54 | D15: 51.65 | E15: 3.46 | F15: 0.04 | G15: 78.47 | H15: 45.08 | I15: 0.2 | J15: 0.36 | K15: 73.15 | L15: 15.71 | M15: 72 | N15: 37.7 | O15: 0 | P15: Maint. | Q15: 40.04
A16: 06-01-2023 08:00 | B16: 14.73 | C16: 80.36 | D16: 56.15 | E16: 3.52 | F16: 0.07 | G16: 78.47 | H16: 46.15 | I16: 0.2 | J16: 0.55 | K16: 68.55 | L16: 16.6 | M16: 71 | N16: 100.8 | O16: 0 | P16: Maint. | Q16: 39.97
A17: 06-01-2023 09:00 | B17: 19.03 | C17: 85.5 | D17: 62.44 | E17: 3.75 | F17: 0.29 | G17: 80.53 | H17: 47.75 | I17: 0.2 | J17: 0.57 | K17: 77.79 | L17: 17.5 | M17: 61 | N17: 145.8 | O17: 0 | P17: Maint. | Q17: 39.12
A18: 06-01-2023 10:00 | B18: 19.94 | C18: 85.97 | D18: 63.41 | E18: 4.27 | F18: 0.27 | G18: 80.63 | H18: 47.75 | I18: 0.22 | J18: 0.87 | K18: 99.13 | L18: 20.43 | M18: 58 | N18: 449.1 | O18: 0 | P18: Maint. | Q18: 37.81
A19: 06-01-2023 11:00 | B19: 22.72 | C19: 90.55 | D19: 68.08 | E19: 4.26 | F19: 0.3 | G19: 80.73 | H19: 45.89 | I19: 0.23 | J19: 1.69 | K19: 115.87 | L19: 22.73 | M19: 45 | N19: 591.7 | O19: 0 | P19: Maint. | Q19: 39.48
A20: 06-01-2023 12:00 | B20: 22.31 | C20: 90.92 | D20: 68.07 | E20: 4.36 | F20: 0.63 | G20: 80.73 | H20: 45 | I20: 0.22 | J20: 1.4 | K20: 124.7 | L20: 25.1 | M20: 38 | N20: 668.8 | O20: 0 | P20: Maint. | Q20: 40.05
... A24: 06-01-2023 16:00 | B24: 9.54 | C24: 87.07 | D24: 55.26 | E24: 13.39 | F24: 3.72 | G24: 64.58 | H24: 35.73 | I24: 0.2 | J24: 1.06 | K24: 72.83 | L24: 26.7 | M24: 34 | N24: 310.5 | O24: 0 | P24: Maint. | Q24: 40.94
A25: 06-01-2023 17:00 | B25: 10.85 | C25: 89.48 | D25: 58.08 | E25: 7.76 | F25: 4.18 | G25: 71.36 | H25: 35.71 | I25: 0.2 | J25: 1.34 | K25: 30.84 | L25: 25.33 | M25: 51 | N25: 106.9 | O25: 0 | P25: 0.88 | Q25: 37.77
A26: 06-01-2023 18:00 | B26: 10.03 | C26: 93.47 | D26: 59.63 | E26: 4.43 | F26: 0.81 | G26: 71.36 | H26: 35.58 | I26: 0.23 | J26: 1.06 | K26: 38.36 | L26: 22.96 | M26: 52 | N26: 43 | O26: 0 | P26: 1.04 | Q26: 39.61
A27: 06-01-2023 19:00 | B27: 25.19 | C27: 109.83 | D27: 80.82 | E27: 4.22 | F27: 0.07 | G27: 88.03 | H27: 41.92 | I27: 0.28 | J27: 0.42 | K27: 91.47 | L27: 20.95 | M27: 51 | N27: 24.8 | O27: 0 | P27: 1.51 | Q27: 40.51
A28: 06-01-2023 20:00 | B28: 30.99 | C28: 110.25 | D28: 84.66 | E28: 3.57 | F28: 0.12 | G28: 98.13 | H28: 44.46 | I28: 0.36 | J28: 0.3 | K28: 223.71 | L28: 19.83 | M28: 59 | N28: 24.9 | O28: 0 | P28: 1.71 | Q28: 41.09
A29: 06-01-2023 21:00 | B29: 38.79 | C29: 111.92 | D29: 92.87 | E29: 5.82 | F29: 0.24 | G29: 105.17 | H29: 46.74 | I29: 0.51 | J29: 0.38 | K29: 276.57 | L29: 18.49 | M29: 61 | N29: 24.8 | O29: 0 | P29: 2 | Q29: 44.91
A30: 06-01-2023 22:00 | B30: 82.01 | C30: 137.09 | D30: 141.42 | E30: 5.82 | F30: 0.33 | G30: 131.55 | H30: 54.52 | I30: 0.72 | J30: 0.15 | K30: 343.15 | L30: 16.91 | M30: 73 | N30: 24.9 | O30: 0 | P30: 2.53 | Q30: 47.29
A31: 06-01-2023 23:00 | B31: 102.82 | C31: 149.16 | D31: 164.77 | E31: 6.06 | F31: 0.14 | G31: 133.43 | H31: 57.94 | I31: 0.99 | J31: 0.16 | K31: 107.83 | L31: 16.06 | M31: 73 | N31: 24.6 | O31: 0 | P31: 2.73 | Q31: 48.11
A32: 06-01-2023 24:00 | B32: 116.93 | C32: 153.91 | D32: 178.54 | E32: 6.13 | F32: 0.16 | G32: 208.02 | H32: 63.61 | I32: 1.05 | J32: 0.2 | K32: 154.65 | L32: 15.11 | M32: 67 | N32: 24.6 | O32: 0 | P32: 2.82 | Q32: 47.65
A34: Min | B34: =MIN(B9:B32) -> 6.69 | C34: =MIN(C9:C32) -> 72.8 | D34: =MIN(D9:D32) -> 44.91 | E34: =MIN(E9:E32) -> 2.78 | F34: =MIN(F9:F32) -> 0.04 | G34: =MIN(G9:G32) -> 62.27 | H34: =MIN(H9:H32) -> 35.58 | I34: =MIN(I9:I32) -> 0.19 | ... Q34: =MIN(Q9:Q32) -> 37.19
A35: Max | B35: =MAX(B9:B32) -> 116.93 | C35: =MAX(C9:C32) -> 153.91 | D35: =MAX(D9:D32) -> 178.54 | E35: =MAX(E9:E32) -> 13.39 | F35: =MAX(F9:F32) -> 4.18 | G35: =MAX(G9:G32) -> 208.02 | H35: =MAX(H9:H32) -> 64.17 | I35: =MAX(I9:I32) -> 1.05 | ... Q35: =MAX(Q9:Q32) -> 48.11
A36: Avg | B36: =AVERAGE(B9:B32) -> 26.5725 | C36: =AVERAGE(C9:C32) -> 95.0075 | D36: =AVERAGE(D9:D32) -> 73.521667 | E36: =AVERAGE(E9:E32) -> 4.6733333 | F36: =AVERAGE(F9:F32) -> 0.67625 | G36: =AVERAGE(G9:G32) -> 92.294167 | H36: =AVERAGE(H9:H32) -> 47.637917 | I36: =AVERAGE(I9:I32) -> 0.33 | ... Q36: =AVERAGE(Q9:Q32) -> 40.794583
A37: Stdev | B37: =STDEV(B9:B32) -> 30.059289 | C37: =STDEV(C9:C32) -> 22.673927 | D37: =STDEV(D9:D32) -> 36.312205 | E37: =STDEV(E9:E32) -> 2.2440311 | F37: =STDEV(F9:F32) -> 1.0761356 | G37: =STDEV(G9:G32) -> 31.084876 | H37: =STDEV(H9:H32) -> 8.4190725 | I37: =STDEV(I9:I32) -> 0.24429134 | ... Q37: =STDEV(Q9:Q32) -> 3.0534043
A38: Num | B38: =COUNT(B9:B32) -> 24 | C38: =COUNT(C9:C32) -> 24 | D38: =COUNT(D9:D32) -> 24 | E38: =COUNT(E9:E32) -> 24 | F38: =COUNT(F9:F32) -> 24 | G38: =COUNT(G9:G32) -> 24 | H38: =COUNT(H9:H32) -> 24 | I38: 24 | J38: =COUNT(J9:J32) -> 24 | K38: =COUNT(K9:K32) -> 24 | L38: =COUNT(L9:L32) -> 24 | M38: =COUNT(M9:M32) -> 24 | N38: =COUNT(N9:N32) -> 24 | O38: =COUNT(O9:O32) -> 24 | P38: =COUNT(P9:P32)+16 -> 24 | Q38: =COUNT(Q9:Q32) -> 24
A39: DCR | B39: =IF(B38>=22,">90%",IF(B38<=22,"<90%")) -> >90% | C39: =IF(C38>=22,">90%",IF(C38<=22,"<90%")) -> >90% | D39: =IF(D38>=22,">90%",IF(D38<=22,"<90%")) -> >90% | E39: =IF(E38>=22,">90%",IF(E38<=22,"<90%")) -> >90% | F39: =IF(F38>=22,">90%",IF(F38<=22,"<90%")) -> >90% | G39: =IF(G38>=22,">90%",IF(G38<=22,"<90%")) -> >90% | H39: =IF(H38>=22,">90%",IF(H38<=22,"<90%")) -> >90% | I39: =IF(I38>=22,">90%",IF(I38<=22,"<90%")) -> >90% | ... Q39: =IF(Q38>=22,">90%",IF(Q38<=22,"<90%")) -> >90%
A40: Status | B40: =IF(B38>=22,"OK",IF(B38<=22,"LESS")) -> OK | C40: =IF(C38>=22,"OK",IF(C38<=22,"LESS")) -> OK | D40: =IF(D38>=22,"OK",IF(D38<=22,"LESS")) -> OK | E40: =IF(E38>=22,"OK",IF(E38<=22,"LESS")) -> OK | F40: =IF(F38>=22,"OK",IF(F38<=22,"LESS")) -> OK | G40: =IF(G38>=22,"OK",IF(G38<=22,"LESS")) -> OK | H40: =IF(H38>=22,"OK",IF(H38<=22,"LESS")) -> OK | I40: =IF(I38>=22,"OK",IF(I38<=22,"LESS")) -> OK | ... Q40: =IF(Q38>=22,"OK",IF(Q38<=22,"LESS")) -> OK
A43: Done by | B43: RAHUL
A45: Comment

Sheet 07
A1: Station: | B1: BHATAGAON RAIPUR
A2: Date: | B2: =$A$9 -> 07-01-2023 01:00 | D2: Power Off | G2: Pw.Off | L2: Link Fail | N2: Link F | P2: Maintenance | R2: Maint.
A3: Report Type: | B3: Mean | D3: Calibration | G3: Calib. | L3: Data Fail | N3: Data F | P3: Invalid | R3: Invalid
A4: Time Base: | B4: 01 Hour | D4: Zero Referrence | G4: Z.Ref | L4: Warm Up | N4: Wm. Up
A7: Date & Time | B7: NO_BHATAGAON | C7: NO2_BHATAGAON | D7: NOX_BHATAGAON | E7: SO2_BHATAGAON | F7: O3_BHATAGAON | G7: PM10_BHATAGAON | H7: PM2_5_BHATAGAON | I7: BENZ_BHATAGAON | J7: WS_BHATAGAON | K7: WD_BHATAGAON | L7: TEMP_BHATAGAON | M7: HUM BHATAGAON | N7: SR_BHATAGAON | O7: RG_BHATAGAON | P7: CO_BHATAGAON | Q7: NH3_BHATAGAON
B8: ug/m3 | C8: ug/m3 | D8: ppb | E8: ug/m3 | F8: ug/m3 | G8: mg/m3 | H8: ug/m3 | I8: ug/m3 | J8: m/sec | K8: deg | L8: degreC | M8: % | N8: w/m2 | O8: mm | P8: ug/m3 | Q8: ug/m3
A9: 07-01-2023 01:00 | B9: 108.55 | C9: 145.71 | D9: 167.46 | E9: 5.21 | F9: 0.24 | G9: 208.02 | H9: 63.61 | I9: 1.04 | J9: 0.33 | K9: 89.2 | L9: 15.74 | M9: 46 | N9: 24.2 | O9: 0 | P9: 2.61 | Q9: 47.06
A10: 07-01-2023 02:00 | B10: 78.42 | C10: 124.37 | D10: 131.52 | E10: 4.5 | F10: 0.04 | G10: 52.03 | H10: 51.31 | I10: 0.77 | J10: 0.44 | K10: 34.87 | L10: 15.53 | M10: 50 | N10: 24.3 | O10: 0 | P10: 2.05 | Q10: 44.65
A11: 07-01-2023 03:00 | B11: 51.91 | C11: 107.65 | D11: 101.04 | E11: 4.01 | F11: 0.09 | G11: 50.41 | H11: 39.8 | I11: 0.57 | J11: 0.62 | K11: 81.97 | L11: 14.88 | M11: 52 | N11: 24.4 | O11: 0 | P11: 1.66 | Q11: 40.47
A12: 07-01-2023 04:00 | B12: 36.17 | C12: 97.56 | D12: 82.85 | E12: 4.13 | F12: 0.08 | G12: 50.41 | H12: 34.11 | I12: 0.44 | J12: 0.41 | K12: 80.39 | L12: 14.16 | M12: 55 | N12: 24.4 | O12: 0 | P12: 1.33 | Q12: 37.34
A13: 07-01-2023 05:00 | B13: 25.14 | C13: 84.71 | D13: 66.91 | E13: 4.19 | F13: 0.41 | G13: 52.69 | H13: 32.55 | I13: 0.37 | J13: 0.39 | K13: 55.87 | L13: 13.58 | M13: 56 | N13: 24.2 | O13: 0 | P13: 1.08 | Q13: 36.8
A14: 07-01-2023 06:00 | B14: 19.72 | C14: 82.62 | D14: 61.41 | E14: 4.27 | F14: 0.14 | G14: 52.69 | H14: 28.68 | I14: 0.29 | J14: 0.38 | K14: 67.3 | L14: 13.34 | M14: 55 | N14: 24.3 | O14: 0 | P14: 0.9 | Q14: 35.86
A15: 07-01-2023 07:00 | B15: 19.49 | C15: 82.04 | D15: 60.91 | E15: 4.31 | F15: 0.12 | G15: 47.12 | H15: 25.79 | I15: 0.25 | J15: 0.45 | K15: 78.08 | L15: 12.66 | M15: 58 | N15: 40.6 | O15: 0 | P15: 0.79 | Q15: 33.1
A16: 07-01-2023 08:00 | B16: 28.38 | C16: 88.91 | D16: 71.83 | E16: 4.78 | F16: 0.06 | G16: 64.39 | H16: 27.97 | I16: 0.23 | J16: 0.87 | K16: 61.35 | L16: 14.94 | M16: 57 | N16: 225.8 | O16: 0 | P16: 0.87 | Q16: 34.59
A17: 07-01-2023 09:00 | B17: 29.57 | C17: 91.88 | D17: 74.09 | E17: 4.12 | F17: 0.73 | G17: 64.39 | H17: 29.64 | I17: 0.23 | J17: 1.22 | K17: 68.15 | L17: 19.6 | M17: 44 | N17: 470.2 | O17: 0 | P17: 0.88 | Q17: 34.71
A18: 07-01-2023 10:00 | B18: 26.71 | C18: 98.56 | D18: 73.88 | E18: 29.55 | F18: 0.76 | G18: 132.86 | H18: 29.64 | I18: 0.22 | J18: 1.09 | K18: 37.96 | L18: 22.75 | M18: 40 | N18: 645.9 | O18: 0 | P18: 0.89 | Q18: 33.84
A19: 07-01-2023 11:00 | B19: 26.82 | C19: 107.28 | D19: 80.71 | E19: 28.28 | F19: 2.11 | G19: 132.86 | H19: 29.24 | I19: 0.2 | J19: 0.83 | K19: 95.62 | L19: 24.12 | M19: 30 | N19: 759.8 | O19: 0 | P19: 0.91 | Q19: 26.85
A20: 07-01-2023 12:00 | B20: 21.39 | C20: 100.41 | D20: 72.57 | E20: 12.58 | F20: 1.51 | G20: 98.13 | H20: 29.06 | I20: 0.15 | J20: 0.95 | K20: 146.94 | L20: 24.43 | M20: 30 | N20: 802 | O20: 0 | P20: 0.77 | Q20: 25.2
... A32: 07-01-2023 24:00 | B32: 186.44 | C32: 189.89 | D32: 254.31 | E32: 6.52 | F32: 0.08 | G32: 211 | H32: 76.5 | I32: 1.19 | J32: 0.17 | K32: 303.33 | L32: 13.79 | M32: 68 | N32: 24.6 | O32: 0 | P32: 3.29 | Q32: 47.09
A34: Min | B34: =MIN(B9:B32) -> 13.95 | C34: =MIN(C9:C32) -> 82.04 | D34: =MIN(D9:D32) -> 60.91 | E34: =MIN(E9:E32) -> 4.01 | F34: =MIN(F9:F32) -> 0.04 | G34: =MIN(G9:G32) -> 45.84 | H34: =MIN(H9:H32) -> 25.79 | I34: =MIN(I9:I32) -> 0.12 | ... Q34: =MIN(Q9:Q32) -> 23.11
A35: Max | B35: =MAX(B9:B32) -> 189.76 | C35: =MAX(C9:C32) -> 194.23 | D35: =MAX(D9:D32) -> 259.37 | E35: =MAX(E9:E32) -> 29.55 | F35: =MAX(F9:F32) -> 2.85 | G35: =MAX(G9:G32) -> 211 | H35: =MAX(H9:H32) -> 76.5 | I35: =MAX(I9:I32) -> 1.19 | ... Q35: =MAX(Q9:Q32) -> 47.22
A36: Avg | B36: =AVERAGE(B9:B32) -> 58.599583 | C36: =AVERAGE(C9:C32) -> 117.65583 | D36: =AVERAGE(D9:D32) -> 111.62625 | E36: =AVERAGE(E9:E32) -> 10.010417 | F36: =AVERAGE(F9:F32) -> 0.70375 | G36: =AVERAGE(G9:G32) -> 99.233333 | H36: =AVERAGE(H9:H32) -> 39.343333 | I36: =AVERAGE(I9:I32) -> 0.43833333 | ... Q36: =AVERAGE(Q9:Q32) -> 34.639167
A37: Stdev | B37: =STDEV(B9:B32) -> 56.094862 | C37: =STDEV(C9:C32) -> 33.324025 | D37: =STDEV(D9:D32) -> 63.089685 | E37: =STDEV(E9:E32) -> 7.4728206 | F37: =STDEV(F9:F32) -> 0.79512543 | G37: =STDEV(G9:G32) -> 58.993296 | H37: =STDEV(H9:H32) -> 16.697184 | I37: =STDEV(I9:I32) -> 0.35796122 | ... Q37: =STDEV(Q9:Q32) -> 7.6058284
A38: Num | B38: =COUNT(B9:B32) -> 24 | C38: =COUNT(C9:C32) -> 24 | D38: =COUNT(D9:D32) -> 24 | E38: =COUNT(E9:E32) -> 24 | F38: =COUNT(F9:F32) -> 24 | G38: =COUNT(G9:G32) -> 24 | H38: =COUNT(H9:H32) -> 24 | I38: 24 | J38: =COUNT(J9:J32) -> 24 | K38: =COUNT(K9:K32) -> 24 | L38: =COUNT(L9:L32) -> 24 | M38: =COUNT(M9:M32) -> 24 | N38: =COUNT(N9:N32) -> 24 | O38: =COUNT(O9:O32) -> 24 | P38: =COUNT(P9:P32) -> 24 | Q38: =COUNT(Q9:Q32) -> 24
A39: DCR | B39: =IF(B38>=22,">90%",IF(B38<=22,"<90%")) -> >90% | C39: =IF(C38>=22,">90%",IF(C38<=22,"<90%")) -> >90% | D39: =IF(D38>=22,">90%",IF(D38<=22,"<90%")) -> >90% | E39: =IF(E38>=22,">90%",IF(E38<=22,"<90%")) -> >90% | F39: =IF(F38>=22,">90%",IF(F38<=22,"<90%")) -> >90% | G39: =IF(G38>=22,">90%",IF(G38<=22,"<90%")) -> >90% | H39: =IF(H38>=22,">90%",IF(H38<=22,"<90%")) -> >90% | I39: =IF(I38>=22,">90%",IF(I38<=22,"<90%")) -> >90% | ... Q39: =IF(Q38>=22,">90%",IF(Q38<=22,"<90%")) -> >90%
A40: Status | B40: =IF(B38>=22,"OK",IF(B38<=22,"LESS")) -> OK | C40: =IF(C38>=22,"OK",IF(C38<=22,"LESS")) -> OK | D40: =IF(D38>=22,"OK",IF(D38<=22,"LESS")) -> OK | E40: =IF(E38>=22,"OK",IF(E38<=22,"LESS")) -> OK | F40: =IF(F38>=22,"OK",IF(F38<=22,"LESS")) -> OK | G40: =IF(G38>=22,"OK",IF(G38<=22,"LESS")) -> OK | H40: =IF(H38>=22,"OK",IF(H38<=22,"LESS")) -> OK | I40: =IF(I38>=22,"OK",IF(I38<=22,"LESS")) -> OK | ... Q40: =IF(Q38>=22,"OK",IF(Q38<=22,"LESS")) -> OK
A43: Done by | B43: RAHUL
A45: Comment

Sheet 08
A1: Station: | B1: BHATAGAON RAIPUR
A2: Date: | B2: =$A$9 -> 08-01-2023 01:00 | D2: Power Off | G2: Pw.Off | L2: Link Fail | N2: Link F | P2: Maintenance | R2: Maint.
A3: Report Type: | B3: Mean | D3: Calibration | G3: Calib. | L3: Data Fail | N3: Data F | P3: Invalid | R3: Invalid
A4: Time Base: | B4: 01 Hour | D4: Zero Referrence | G4: Z.Ref | L4: Warm Up | N4: Wm. Up
A7: Date & Time | B7: NO_BHATAGAON | C7: NO2_BHATAGAON | D7: NOX_BHATAGAON | E7: SO2_BHATAGAON | F7: O3_BHATAGAON | G7: PM10_BHATAGAON | H7: PM2_5_BHATAGAON | I7: BENZ_BHATAGAON | J7: WS_BHATAGAON | K7: WD_BHATAGAON | L7: TEMP_BHATAGAON | M7: HUM BHATAGAON | N7: SR_BHATAGAON | O7: RG_BHATAGAON | P7: CO_BHATAGAON | Q7: NH3_BHATAGAON
B8: ug/m3 | C8: ug/m3 | D8: ppb | E8: ug/m3 | F8: ug/m3 | G8: mg/m3 | H8: ug/m3 | I8: ug/m3 | J8: m/sec | K8: deg | L8: degreC | M8: % | N8: w/m2 | O8: mm | P8: ug/m3 | Q8: ug/m3
A9: 08-01-2023 01:00 | B9: 165.97 | C9: 172.84 | D9: 228.48 | E9: 6.35 | F9: 0.1 | G9: 143.73 | H9: 76.5 | I9: 1.07 | J9: 0.18 | K9: 350.26 | L9: 13.04 | M9: 76 | N9: 24.4 | O9: 0 | P9: 2.91 | Q9: 42.8
A10: 08-01-2023 02:00 | B10: 160.75 | C10: 165.42 | D10: 220.2 | E10: 7.27 | F10: 0.17 | G10: 143.73 | H10: 75.42 | I10: 0.96 | J10: 0.48 | K10: 119.13 | L10: 14.75 | M10: 69 | N10: 24.3 | O10: 0 | P10: 2.62 | Q10: 43.81
A11: 08-01-2023 03:00 | B11: 135.73 | C11: 149.44 | D11: 191.32 | E11: 6.87 | F11: 0.35 | G11: 145.07 | H11: 76 | I11: 0.89 | J11: 0.27 | K11: 98.32 | L11: 14.54 | M11: 52 | N11: 24.3 | O11: 0 | P11: 2.59 | Q11: 43.43
A12: 08-01-2023 04:00 | B12: 101.18 | C12: 131.71 | D12: 153.82 | E12: 6.08 | F12: 0.89 | G12: 145.07 | H12: 76 | I12: 0.75 | J12: 0.35 | K12: 234.15 | L12: 14.25 | M12: 46 | N12: 24.3 | O12: 0 | P12: 2.22 | Q12: 40.19
A13: 08-01-2023 05:00 | B13: 71.42 | C13: 113.42 | D13: 119.87 | E13: 4.84 | F13: 0.25 | G13: 65.72 | H13: 63.23 | I13: 0.6 | J13: 0.36 | K13: 336.34 | L13: 13.16 | M13: 80 | N13: 24.9 | O13: 0 | P13: 1.74 | Q13: 35.42
A14: 08-01-2023 06:00 | B14: 66.82 | C14: 104.94 | D14: 111.49 | E14: 4.23 | F14: 0.09 | G14: 75.56 | H14: 47.64 | I14: 0.48 | J14: 0.15 | K14: 353.88 | L14: 10.65 | M14: 80 | N14: 24.5 | O14: 0 | P14: 1.6 | Q14: 36.75
A15: 08-01-2023 07:00 | B15: 71.8 | C15: 113.03 | D15: 119.82 | E15: 4.33 | F15: 0.1 | G15: 95.47 | H15: 47.39 | I15: 0.44 | J15: 0.3 | K15: 112.51 | L15: 12.05 | M15: 59 | N15: 38.9 | O15: 0 | P15: 1.58 | Q15: 36.96
A16: 08-01-2023 08:00 | B16: 67.91 | C16: 113.45 | D16: 116.67 | E16: 3.85 | F16: 0.24 | G16: 75.78 | H16: 47.39 | I16: 0.38 | J16: 1.18 | K16: 118.43 | L16: 14.68 | M16: 52 | N16: 227.7 | O16: 0 | P16: 1.31 | Q16: 33.84
A17: 08-01-2023 09:00 | B17: 54.38 | C17: 107.12 | D17: 102.73 | E17: 4.82 | F17: 0.43 | G17: 68.39 | H17: 41.85 | I17: 0.32 | J17: 1.47 | K17: 134.18 | L17: 18.94 | M17: 39 | N17: 472.3 | O17: 0 | P17: 1.14 | Q17: 33.92
A18: 08-01-2023 10:00 | B18: 41.48 | C18: 98.27 | D18: 87.49 | E18: 4.71 | F18: 0.28 | G18: 39.51 | H18: 37.31 | I18: 0.28 | J18: 1.18 | K18: 128.47 | L18: 22.67 | M18: 33 | N18: 645.7 | O18: 0 | P18: 0.98 | Q18: 34.54
A19: 08-01-2023 11:00 | B19: 30.24 | C19: 96.6 | D19: 77.56 | E19: 4.68 | F19: 0.45 | G19: 42.85 | H19: 31.36 | I19: 0.25 | J19: 1.7 | K19: 135.93 | L19: 23.67 | M19: 24 | N19: 763.3 | O19: 0 | P19: 0.85 | Q19: 33.8
A20: 08-01-2023 12:00 | B20: 22.43 | C20: 90.18 | D20: 67.48 | E20: 5 | F20: 0.58 | G20: 42.85 | H20: 27.33 | I20: 0.23 | J20: 0.87 | K20: 356.83 | L20: 29.88 | M20: 17 | N20: 797.6 | O20: 0 | P20: 0.75 | Q20: 31.91
... A32: 08-01-2023 24:00 | B32: 204.06 | C32: 215.17 | D32: 281.73 | E32: 7.02 | F32: 1.17 | G32: 238.79 | H32: 117.96 | I32: 1.3 | J32: 0.22 | K32: 309.66 | L32: 14.69 | M32: 67 | N32: 24.8 | O32: 0 | P32: 4.28 | Q32: 50.81
A34: Min | B34: =MIN(B9:B32) -> 9.93 | C34: =MIN(C9:C32) -> 89.61 | D34: =MIN(D9:D32) -> 58.99 | E34: =MIN(E9:E32) -> 3.85 | F34: =MIN(F9:F32) -> 0.09 | G34: =MIN(G9:G32) -> 30.92 | H34: =MIN(H9:H32) -> 21.07 | I34: =MIN(I9:I32) -> 0.22 | ... Q34: =MIN(Q9:Q32) -> 31.91
A35: Max | B35: =MAX(B9:B32) -> 204.06 | C35: =MAX(C9:C32) -> 215.17 | D35: =MAX(D9:D32) -> 281.73 | E35: =MAX(E9:E32) -> 15.77 | F35: =MAX(F9:F32) -> 4.34 | G35: =MAX(G9:G32) -> 238.79 | H35: =MAX(H9:H32) -> 117.96 | I35: =MAX(I9:I32) -> 1.3 | ... Q35: =MAX(Q9:Q32) -> 50.81
A36: Avg | B36: =AVERAGE(B9:B32) -> 71.552083 | C36: =AVERAGE(C9:C32) -> 124.53917 | D36: =AVERAGE(D9:D32) -> 125.84708 | E36: =AVERAGE(E9:E32) -> 6.5 | F36: =AVERAGE(F9:F32) -> 0.83958333 | G36: =AVERAGE(G9:G32) -> 100.2225 | H36: =AVERAGE(H9:H32) -> 49.628333 | I36: =AVERAGE(I9:I32) -> 0.50208333 | ... Q36: =AVERAGE(Q9:Q32) -> 37.895
A37: Stdev | B37: =STDEV(B9:B32) -> 60.150309 | C37: =STDEV(C9:C32) -> 37.156208 | D37: =STDEV(D9:D32) -> 68.169524 | E37: =STDEV(E9:E32) -> 2.5066711 | F37: =STDEV(F9:F32) -> 1.0129959 | G37: =STDEV(G9:G32) -> 61.653421 | H37: =STDEV(H9:H32) -> 25.668043 | I37: =STDEV(I9:I32) -> 0.32548264 | ... Q37: =STDEV(Q9:Q32) -> 4.8596377
A38: Num | B38: =COUNT(B9:B32) -> 24 | C38: =COUNT(C9:C32) -> 24 | D38: =COUNT(D9:D32) -> 24 | E38: =COUNT(E9:E32) -> 24 | F38: =COUNT(F9:F32) -> 24 | G38: 24 | H38: 24 | I38: =COUNT(I9:I32) -> 24 | J38: =COUNT(J9:J32) -> 24 | K38: =COUNT(K9:K32) -> 24 | L38: =COUNT(L9:L32) -> 24 | M38: =COUNT(M9:M32) -> 24 | N38: 24 | O38: =COUNT(O9:O32) -> 24 | P38: =COUNT(P9:P32) -> 24 | Q38: =COUNT(Q9:Q32) -> 24
A39: DCR | B39: =IF(B38>=22,">90%",IF(B38<=22,"<90%")) -> >90% | C39: =IF(C38>=22,">90%",IF(C38<=22,"<90%")) -> >90% | D39: =IF(D38>=22,">90%",IF(D38<=22,"<90%")) -> >90% | E39: =IF(E38>=22,">90%",IF(E38<=22,"<90%")) -> >90% | F39: =IF(F38>=22,">90%",IF(F38<=22,"<90%")) -> >90% | G39: =IF(G38>=22,">90%",IF(G38<=22,"<90%")) -> >90% | H39: =IF(H38>=22,">90%",IF(H38<=22,"<90%")) -> >90% | I39: =IF(I38>=22,">90%",IF(I38<=22,"<90%")) -> >90% | ... Q39: =IF(Q38>=22,">90%",IF(Q38<=22,"<90%")) -> >90%
A40: Status | B40: =IF(B38>=22,"OK",IF(B38<=22,"LESS")) -> OK | C40: =IF(C38>=22,"OK",IF(C38<=22,"LESS")) -> OK | D40: =IF(D38>=22,"OK",IF(D38<=22,"LESS")) -> OK | E40: =IF(E38>=22,"OK",IF(E38<=22,"LESS")) -> OK | F40: =IF(F38>=22,"OK",IF(F38<=22,"LESS")) -> OK | G40: =IF(G38>=22,"OK",IF(G38<=22,"LESS")) -> OK | H40: =IF(H38>=22,"OK",IF(H38<=22,"LESS")) -> OK | I40: =IF(I38>=22,"OK",IF(I38<=22,"LESS")) -> OK | ... Q40: =IF(Q38>=22,"OK",IF(Q38<=22,"LESS")) -> OK
A43: Done by | B43: RAHUL
A45: Comment

Sheet 09
A1: Station: | B1: BHATAGAON RAIPUR
A2: Date: | B2: =$A$9 -> 09-01-2023 01:00 | D2: Power Off | G2: Pw.Off | L2: Link Fail | N2: Link F | P2: Maintenance | R2: Maint.
A3: Report Type: | B3: Mean | D3: Calibration | G3: Calib. | L3: Data Fail | N3: Data F | P3: Invalid | R3: Invalid
A4: Time Base: | B4: 01 Hour | D4: Zero Referrence | G4: Z.Ref | L4: Warm Up | N4: Wm. Up
A7: Date & Time | B7: NO_BHATAGAON | C7: NO2_BHATAGAON | D7: NOX_BHATAGAON | E7: SO2_BHATAGAON | F7: O3_BHATAGAON | G7: PM10_BHATAGAON | H7: PM2_5_BHATAGAON | I7: BENZ_BHATAGAON | J7: WS_BHATAGAON | K7: WD_BHATAGAON | L7: TEMP_BHATAGAON | M7: HUM BHATAGAON | N7: SR_BHATAGAON | O7: RG_BHATAGAON | P7: CO_BHATAGAON | Q7: NH3_BHATAGAON
B8: ug/m3 | C8: ug/m3 | D8: ppb | E8: ug/m3 | F8: ug/m3 | G8: mg/m3 | H8: ug/m3 | I8: ug/m3 | J8: m/sec | K8: deg | L8: degreC | M8: % | N8: w/m2 | O8: mm | P8: ug/m3 | Q8: ug/m3
A9: 09-01-2023 01:00 | B9: 207.96 | C9: 208.1 | D9: 281.38 | E9: 6.25 | F9: 0.26 | G9: 203.59 | H9: 117.96 | I9: 1.34 | J9: 0.11 | K9: 330.12 | L9: 13.43 | M9: 78 | N9: 24.6 | O9: 0 | P9: 4.5 | Q9: 50.12
A10: 09-01-2023 02:00 | B10: 207.26 | C10: 205.83 | D10: 279.8 | E10: 6.41 | F10: 0.18 | G10: 203.59 | H10: 111.25 | I10: 1.42 | J10: 0.12 | K10: 341.44 | L10: 13.18 | M10: 77 | N10: 24.4 | O10: 0 | P10: 4.33 | Q10: 48.14
A11: 09-01-2023 03:00 | B11: 191.61 | C11: 190.05 | D11: 258.55 | E11: 6.4 | F11: 1.48 | G11: 209.25 | H11: 109.29 | I11: 1.41 | J11: 0.41 | K11: 72.64 | L11: 13.98 | M11: 63 | N11: 24.2 | O11: 0 | P11: 4.26 | Q11: 47.59
A12: 09-01-2023 04:00 | B12: 144.04 | C12: 163.08 | D12: 205.51 | E12: 7.02 | F12: 2.11 | G12: 209.25 | H12: 109.29 | I12: 1.24 | J12: 0.44 | K12: 105.09 | L12: 14.63 | M12: 53 | N12: 24.5 | O12: 0 | P12: 3.63 | Q12: 45.86
A13: 09-01-2023 05:00 | B13: 102.31 | C13: 140.18 | D13: 159.4 | E13: 5.82 | F13: 0.12 | G13: 182.74 | H13: 97.77 | I13: 0.95 | J13: 0.28 | K13: 285.33 | L13: 13.68 | M13: 71 | N13: 24.9 | O13: 0 | P13: 3.12 | Q13: 42.27
A14: 09-01-2023 06:00 | B14: 86.43 | C14: 128.01 | D14: 139.95 | E14: 5.62 | F14: 0.39 | G14: 144.72 | H14: 96.73 | I14: 0.73 | J14: 0.18 | K14: 358.99 | L14: 11.58 | M14: 77 | N14: 24.6 | O14: 0 | P14: 2.72 | Q14: 37.49
A15: 09-01-2023 07:00 | B15: 73.23 | C15: 114.12 | D15: 121.7 | E15: 5.26 | F15: 0.23 | G15: 120.5 | H15: 79.64 | I15: 0.59 | J15: 0.15 | K15: 340.2 | L15: 10.67 | M15: 82 | N15: 38.9 | O15: 0 | P15: 2.27 | Q15: 36.57
A16: 09-01-2023 08:00 | B16: 87.75 | C16: 127.83 | D16: 140.91 | E16: 5.28 | F16: 0.41 | G16: 130.47 | H16: 67.46 | I16: 0.44 | J16: 0.18 | K16: 144.62 | L16: 14.61 | M16: 82 | N16: 196 | O16: 0 | P16: 2.15 | Q16: 36.92
A17: 09-01-2023 09:00 | B17: 88.96 | C17: 134.03 | D17: 145.07 | E17: 7 | F17: 0.44 | G17: 161.2 | H17: 75.96 | I17: 0.4 | J17: 0.67 | K17: 359.86 | L17: 23.11 | M17: 51 | N17: 431.6 | O17: 0 | P17: 2.17 | Q17: 35.5
A18: 09-01-2023 10:00 | B18: 80.82 | C18: 132.73 | D18: 137.94 | E18: 7.77 | F18: 0.5 | G18: 161.2 | H18: 75.96 | I18: 0.36 | J18: 0.84 | K18: 54.28 | L18: 25.36 | M18: 28 | N18: 607.2 | O18: 0 | P18: 2.15 | Q18: 36.52
A19: 09-01-2023 11:00 | B19: 68.56 | C19: 131.5 | D19: 127.52 | E19: 6.94 | F19: 0.54 | G19: 141.45 | H19: 69.32 | I19: 0.34 | J19: 0.96 | K19: 83.68 | L19: 29.41 | M19: 21 | N19: 734 | O19: 0 | P19: 1.91 | Q19: 36.76
A20: 09-01-2023 12:00 | B20: 54.03 | C20: 130.67 | D20: 115.44 | E20: 7.03 | F20: 0.43 | G20: 94.9 | H20: 60 | I20: 0.3 | J20: 0.66 | K20: 137.91 | L20: 30.98 | M20: 21 | N20: 757.9 | O20: 0 | P20: 1.7 | Q20: 35.54
... A25: 09-01-2023 17:00 | B25: 21.73 | C25: 107.84 | D25: 76.63 | E25: 27.67 | F25: 6.3 | G25: 50.13 | H25: 27.93 | I25: 0.24 | J25: 0.73 | K25: 120.95 | L25: 26.9 | M25: 28 | N25: 3.1 | O25: 0 | P25: 1.06 | Q25: 38.32
A26: 09-01-2023 18:00 | B26: 32.97 | C26: 122.66 | D26: 94.13 | E26: 9.28 | F26: 0.32 | G26: 88.35 | H26: 38.56 | I26: 0.3 | J26: 0.38 | K26: 24.35 | L26: 25.3 | M26: 31 | N26: Maint. | O26: 0 | P26: 1.44 | Q26: 40.85
A27: 09-01-2023 19:00 | B27: 42.89 | C27: 135.68 | D27: 108.98 | E27: 10.68 | F27: 2.06 | G27: 112.15 | H27: 43.62 | I27: 0.38 | J27: 0.37 | K27: 93.32 | L27: 22.47 | M27: 37 | N27: Maint. | O27: 0 | P27: 1.78 | Q27: 41
A28: 09-01-2023 20:00 | B28: 54.12 | C28: 135.74 | D28: 116.62 | E28: 10.67 | F28: 0.46 | G28: 128.95 | H28: 57.05 | I28: 0.56 | J28: 0.34 | K28: 293.18 | L28: 21.66 | M28: 43 | N28: Maint. | O28: 0 | P28: 1.99 | Q28: 39.28
A29: 09-01-2023 21:00 | B29: 87.41 | C29: 149.52 | D29: 152.61 | E29: 7.62 | F29: 0.18 | G29: 218.29 | H29: 66.26 | I29: 0.79 | J29: 0.14 | K29: 328.96 | L29: 18.78 | M29: 51 | N29: Maint. | O29: 0 | P29: 2.77 | Q29: 44.03
A30: 09-01-2023 22:00 | B30: 160.82 | C30: 194.44 | D30: 236.28 | E30: 8.55 | F30: 0.03 | G30: 218.29 | H30: 79.26 | I30: 1.08 | J30: 0.15 | K30: 324.6 | L30: 17.99 | M30: 57 | N30: Maint. | O30: 0 | P30: 3.5 | Q30: 48.16
A31: 09-01-2023 23:00 | B31: 200.86 | C31: 213.57 | D31: 278.94 | E31: 8.4 | F31: 0.19 | G31: 235.76 | H31: 87.76 | I31: 1.27 | J31: 0.15 | K31: 359.97 | L31: 16.34 | M31: 64 | N31: Maint. | O31: 0 | P31: 3.93 | Q31: 49.16
