Workbook

Sheet 01
A1: Station: | B1: IGKV RAIPUR
A2: Date: | B2: =$A$9 -> 0 | C2: Power Off | G2: Pw.Off | J2: Link Fail | L2: Link F | N2: Maintenance | P2: Maint.
A3: Report Type: | B3: Mean | C3: Calibration | G3: Calib. | J3: Data Fail | L3: Data F | N3: Invalid | P3: Invalid
A4: Time Base: | B4: 15 Min | C4: Zero Referrence | G4: Z.Ref | J4: Warm Up | L4: Wm. Up
A7: Date & Time | B7: NO | C7: NO2 | D7: NOX | E7: SO2 | F7: O3 | G7: PM 10 | H7: PM 2.5 | I7: BENZ | J7: WS | K7: WD | L7: TEMP | M7: HUM | N7: SR | O7: RG | P7: CO | Q7: NH3
B8: ug/m3 | C8: ug/m3 | D8: ppb | E8: ug/m3 | F8: ug/m3 | G8: ug/m3 | H8: ug/m3 | I8: ug/m3 | J8: m/sec | K8: deg | L8: degreC | M8: % | N8: w/m2 | O8: mm | P8: mg/m3 | Q8: ug/m3
A106: Min | B106: =MIN(B9:B104) -> 0 | C106: =MIN(C9:C104) -> 0 | D106: =MIN(D9:D104) -> 0 | E106: =MIN(E9:E104) -> 0 | F106: =MIN(F9:F104) -> 0 | G106: =MIN(G9:G104) -> 0 | H106: =MIN(H9:H104) -> 0 | I106: =MIN(I9:I104) -> 0 | ... Q106: =MIN(Q9:Q104) -> 0
A107: Max | B107: =MAX(B9:B104) -> 0 | C107: =MAX(C9:C104) -> 0 | D107: =MAX(D9:D104) -> 0 | E107: =MAX(E9:E104) -> 0 | F107: =MAX(F9:F104) -> 0 | G107: =MAX(G9:G104) -> 0 | H107: =MAX(H9:H104) -> 0 | I107: =MAX(I9:I104) -> 0 | ... Q107: =MAX(Q9:Q104) -> 0
A108: Avg | B108: =AVERAGE(B9:B104) -> #DIV/0! | C108: =AVERAGE(C9:C104) -> #DIV/0! | D108: =AVERAGE(D9:D104) -> #DIV/0! | E108: =AVERAGE(E9:E104) -> #DIV/0! | F108: =AVERAGE(F9:F104) -> #DIV/0! | G108: =AVERAGE(G9:G104) -> #DIV/0! | H108: =AVERAGE(H9:H104) -> #DIV/0! | I108: =AVERAGE(I9:I104) -> #DIV/0! | ... Q108: =AVERAGE(Q9:Q104) -> #DIV/0!
A109: Stdev | B109: =STDEV(B9:B104) -> #DIV/0! | C109: =STDEV(C9:C104) -> #DIV/0! | D109: =STDEV(D9:D104) -> #DIV/0! | E109: =STDEV(E9:E104) -> #DIV/0! | F109: =STDEV(F9:F104) -> #DIV/0! | G109: =STDEV(G9:G104) -> #DIV/0! | H109: =STDEV(H9:H104) -> #DIV/0! | I109: =STDEV(I9:I104) -> #DIV/0! | ... Q109: =STDEV(Q9:Q104) -> #DIV/0!
A110: Num | B110: =COUNT(B9:B104) -> 0 | C110: =COUNT(C9:C104) -> 0 | D110: =COUNT(D9:D104) -> 0 | E110: =COUNT(E9:E104) -> 0 | F110: =COUNT(F9:F104) -> 0 | G110: =COUNT(G9:G104) -> 0 | H110: =COUNT(H9:H104) -> 0 | I110: =COUNT(I9:I104) -> 0 | ... Q110: =COUNT(Q9:Q104) -> 0
A111: DCR | B111: =IF(B110>=87,">90%",IF(B110<=87,"<90%")) -> <90% | C111: =IF(C110>=87,">90%",IF(C110<=87,"<90%")) -> <90% | D111: =IF(D110>=87,">90%",IF(D110<=87,"<90%")) -> <90% | E111: =IF(E110>=87,">90%",IF(E110<=87,"<90%")) -> <90% | F111: =IF(F110>=87,">90%",IF(F110<=87,"<90%")) -> <90% | G111: =IF(G110>=87,">90%",IF(G110<=87,"<90%")) -> <90% | H111: =IF(H110>=87,">90%",IF(H110<=87,"<90%")) -> <90% | I111: =IF(I110>=87,">90%",IF(I110<=87,"<90%")) -> <90% | ... Q111: =IF(Q110>=87,">90%",IF(Q110<=87,"<90%")) -> <90%
A112: Status | B112: =IF(B110>=87,"OK",IF(B110<=87,"LESS")) -> LESS | C112: =IF(C110>=87,"OK",IF(C110<=87,"LESS")) -> LESS | D112: =IF(D110>=87,"OK",IF(D110<=87,"LESS")) -> LESS | E112: =IF(E110>=87,"OK",IF(E110<=87,"LESS")) -> LESS | F112: =IF(F110>=87,"OK",IF(F110<=87,"LESS")) -> LESS | G112: =IF(G110>=87,"OK",IF(G110<=87,"LESS")) -> LESS | H112: =IF(H110>=87,"OK",IF(H110<=87,"LESS")) -> LESS | I112: =IF(I110>=87,"OK",IF(I110<=87,"LESS")) -> LESS | ... Q112: =IF(Q110>=87,"OK",IF(Q110<=87,"LESS")) -> LESS
A115: Done by | B115: AKASH
A117: Comment

Sheet 02
A1: Station: | B1: IGKV RAIPUR
A2: Date: | B2: =$A$9 -> 0 | C2: Power Off | G2: Pw.Off | J2: Link Fail | L2: Link F | N2: Maintenance | P2: Maint.
A3: Report Type: | B3: Mean | C3: Calibration | G3: Calib. | J3: Data Fail | L3: Data F | N3: Invalid | P3: Invalid
A4: Time Base: | B4: 15 Min | C4: Zero Referrence | G4: Z.Ref | J4: Warm Up | L4: Wm. Up
A7: Date & Time | B7: NO | C7: NO2 | D7: NOX | E7: SO2 | F7: O3 | G7: PM 10 | H7: PM 2.5 | I7: BENZ | J7: WS | K7: WD | L7: TEMP | M7: HUM | N7: SR | O7: RG | P7: CO | Q7: NH3
B8: ug/m3 | C8: ug/m3 | D8: ppb | E8: ug/m3 | F8: ug/m3 | G8: ug/m3 | H8: ug/m3 | I8: ug/m3 | J8: m/sec | K8: deg | L8: degreC | M8: % | N8: w/m2 | O8: mm | P8: mg/m3 | Q8: ug/m3
A106: Min | B106: =MIN(B9:B104) -> 0 | C106: =MIN(C9:C104) -> 0 | D106: =MIN(D9:D104) -> 0 | E106: =MIN(E9:E104) -> 0 | F106: =MIN(F9:F104) -> 0 | G106: =MIN(G9:G104) -> 0 | H106: =MIN(H9:H104) -> 0 | I106: =MIN(I9:I104) -> 0 | ... Q106: =MIN(Q9:Q104) -> 0
A107: Max | B107: =MAX(B9:B104) -> 0 | C107: =MAX(C9:C104) -> 0 | D107: =MAX(D9:D104) -> 0 | E107: =MAX(E9:E104) -> 0 | F107: =MAX(F9:F104) -> 0 | G107: =MAX(G9:G104) -> 0 | H107: =MAX(H9:H104) -> 0 | I107: =MAX(I9:I104) -> 0 | ... Q107: =MAX(Q9:Q104) -> 0
A108: Avg | B108: =AVERAGE(B9:B104) -> #DIV/0! | C108: =AVERAGE(C9:C104) -> #DIV/0! | D108: =AVERAGE(D9:D104) -> #DIV/0! | E108: =AVERAGE(E9:E104) -> #DIV/0! | F108: =AVERAGE(F9:F104) -> #DIV/0! | G108: =AVERAGE(G9:G104) -> #DIV/0! | H108: =AVERAGE(H9:H104) -> #DIV/0! | I108: =AVERAGE(I9:I104) -> #DIV/0! | ... Q108: =AVERAGE(Q9:Q104) -> #DIV/0!
A109: Stdev | B109: =STDEV(B9:B104) -> #DIV/0! | C109: =STDEV(C9:C104) -> #DIV/0! | D109: =STDEV(D9:D104) -> #DIV/0! | E109: =STDEV(E9:E104) -> #DIV/0! | F109: =STDEV(F9:F104) -> #DIV/0! | G109: =STDEV(G9:G104) -> #DIV/0! | H109: =STDEV(H9:H104) -> #DIV/0! | I109: =STDEV(I9:I104) -> #DIV/0! | ... Q109: =STDEV(Q9:Q104) -> #DIV/0!
A110: Num | B110: =COUNT(B9:B104) -> 0 | C110: =COUNT(C9:C104) -> 0 | D110: =COUNT(D9:D104) -> 0 | E110: =COUNT(E9:E104) -> 0 | F110: =COUNT(F9:F104) -> 0 | G110: =COUNT(G9:G104) -> 0 | H110: =COUNT(H9:H104) -> 0 | I110: =COUNT(I9:I104) -> 0 | ... Q110: =COUNT(Q9:Q104) -> 0
A111: DCR | B111: =IF(B110>=87,">90%",IF(B110<=87,"<90%")) -> <90% | C111: =IF(C110>=87,">90%",IF(C110<=87,"<90%")) -> <90% | D111: =IF(D110>=87,">90%",IF(D110<=87,"<90%")) -> <90% | E111: =IF(E110>=87,">90%",IF(E110<=87,"<90%")) -> <90% | F111: =IF(F110>=87,">90%",IF(F110<=87,"<90%")) -> <90% | G111: =IF(G110>=87,">90%",IF(G110<=87,"<90%")) -> <90% | H111: =IF(H110>=87,">90%",IF(H110<=87,"<90%")) -> <90% | I111: =IF(I110>=87,">90%",IF(I110<=87,"<90%")) -> <90% | ... Q111: =IF(Q110>=87,">90%",IF(Q110<=87,"<90%")) -> <90%
A112: Status | B112: =IF(B110>=87,"OK",IF(B110<=87,"LESS")) -> LESS | C112: =IF(C110>=87,"OK",IF(C110<=87,"LESS")) -> LESS | D112: =IF(D110>=87,"OK",IF(D110<=87,"LESS")) -> LESS | E112: =IF(E110>=87,"OK",IF(E110<=87,"LESS")) -> LESS | F112: =IF(F110>=87,"OK",IF(F110<=87,"LESS")) -> LESS | G112: =IF(G110>=87,"OK",IF(G110<=87,"LESS")) -> LESS | H112: =IF(H110>=87,"OK",IF(H110<=87,"LESS")) -> LESS | I112: =IF(I110>=87,"OK",IF(I110<=87,"LESS")) -> LESS | ... Q112: =IF(Q110>=87,"OK",IF(Q110<=87,"LESS")) -> LESS
A115: Done by | B115: SUROJIT
A117: Comment

Sheet 03
A1: Station: | B1: IGKV RAIPUR
A2: Date: | B2: =$A$9 -> 0 | C2: Power Off | G2: Pw.Off | J2: Link Fail | L2: Link F | N2: Maintenance | P2: Maint.
A3: Report Type: | B3: Mean | C3: Calibration | G3: Calib. | J3: Data Fail | L3: Data F | N3: Invalid | P3: Invalid
A4: Time Base: | B4: 15 Min | C4: Zero Referrence | G4: Z.Ref | J4: Warm Up | L4: Wm. Up
A7: Date & Time | B7: NO | C7: NO2 | D7: NOX | E7: SO2 | F7: O3 | G7: PM 10 | H7: PM 2.5 | I7: BENZ | J7: WS | K7: WD | L7: TEMP | M7: HUM | N7: SR | O7: RG | P7: CO | Q7: NH3
B8: ug/m3 | C8: ug/m3 | D8: ppb | E8: ug/m3 | F8: ug/m3 | G8: ug/m3 | H8: ug/m3 | I8: ug/m3 | J8: m/sec | K8: deg | L8: degreC | M8: % | N8: w/m2 | O8: mm | P8: mg/m3 | Q8: ug/m3
A106: Min | B106: =MIN(B9:B104) -> 0 | C106: =MIN(C9:C104) -> 0 | D106: =MIN(D9:D104) -> 0 | E106: =MIN(E9:E104) -> 0 | F106: =MIN(F9:F104) -> 0 | G106: =MIN(G9:G104) -> 0 | H106: =MIN(H9:H104) -> 0 | I106: =MIN(I9:I104) -> 0 | ... Q106: =MIN(Q9:Q104) -> 0
A107: Max | B107: =MAX(B9:B104) -> 0 | C107: =MAX(C9:C104) -> 0 | D107: =MAX(D9:D104) -> 0 | E107: =MAX(E9:E104) -> 0 | F107: =MAX(F9:F104) -> 0 | G107: =MAX(G9:G104) -> 0 | H107: =MAX(H9:H104) -> 0 | I107: =MAX(I9:I104) -> 0 | ... Q107: =MAX(Q9:Q104) -> 0
A108: Avg | B108: =AVERAGE(B9:B104) -> #DIV/0! | C108: =AVERAGE(C9:C104) -> #DIV/0! | D108: =AVERAGE(D9:D104) -> #DIV/0! | E108: =AVERAGE(E9:E104) -> #DIV/0! | F108: =AVERAGE(F9:F104) -> #DIV/0! | G108: =AVERAGE(G9:G104) -> #DIV/0! | H108: =AVERAGE(H9:H104) -> #DIV/0! | I108: =AVERAGE(I9:I104) -> #DIV/0! | ... Q108: =AVERAGE(Q9:Q104) -> #DIV/0!
A109: Stdev | B109: =STDEV(B9:B104) -> #DIV/0! | C109: =STDEV(C9:C104) -> #DIV/0! | D109: =STDEV(D9:D104) -> #DIV/0! | E109: =STDEV(E9:E104) -> #DIV/0! | F109: =STDEV(F9:F104) -> #DIV/0! | G109: =STDEV(G9:G104) -> #DIV/0! | H109: =STDEV(H9:H104) -> #DIV/0! | I109: =STDEV(I9:I104) -> #DIV/0! | ... Q109: =STDEV(Q9:Q104) -> #DIV/0!
A110: Num | B110: =COUNT(B9:B104) -> 0 | C110: =COUNT(C9:C104) -> 0 | D110: =COUNT(D9:D104) -> 0 | E110: =COUNT(E9:E104) -> 0 | F110: =COUNT(F9:F104) -> 0 | G110: =COUNT(G9:G104) -> 0 | H110: =COUNT(H9:H104) -> 0 | I110: =COUNT(I9:I104) -> 0 | ... Q110: =COUNT(Q9:Q104) -> 0
A111: DCR | B111: =IF(B110>=87,">90%",IF(B110<=87,"<90%")) -> <90% | C111: =IF(C110>=87,">90%",IF(C110<=87,"<90%")) -> <90% | D111: =IF(D110>=87,">90%",IF(D110<=87,"<90%")) -> <90% | E111: =IF(E110>=87,">90%",IF(E110<=87,"<90%")) -> <90% | F111: =IF(F110>=87,">90%",IF(F110<=87,"<90%")) -> <90% | G111: =IF(G110>=87,">90%",IF(G110<=87,"<90%")) -> <90% | H111: =IF(H110>=87,">90%",IF(H110<=87,"<90%")) -> <90% | I111: =IF(I110>=87,">90%",IF(I110<=87,"<90%")) -> <90% | ... Q111: =IF(Q110>=87,">90%",IF(Q110<=87,"<90%")) -> <90%
A112: Status | B112: =IF(B110>=87,"OK",IF(B110<=87,"LESS")) -> LESS | C112: =IF(C110>=87,"OK",IF(C110<=87,"LESS")) -> LESS | D112: =IF(D110>=87,"OK",IF(D110<=87,"LESS")) -> LESS | E112: =IF(E110>=87,"OK",IF(E110<=87,"LESS")) -> LESS | F112: =IF(F110>=87,"OK",IF(F110<=87,"LESS")) -> LESS | G112: =IF(G110>=87,"OK",IF(G110<=87,"LESS")) -> LESS | H112: =IF(H110>=87,"OK",IF(H110<=87,"LESS")) -> LESS | I112: =IF(I110>=87,"OK",IF(I110<=87,"LESS")) -> LESS | ... Q112: =IF(Q110>=87,"OK",IF(Q110<=87,"LESS")) -> LESS
A115: Done by | B115: AKASH
A117: Comment

Sheet 04
A1: Station: | B1: IGKV RAIPUR
A2: Date: | B2: =$A$9 -> 0 | C2: Power Off | G2: Pw.Off | J2: Link Fail | L2: Link F | N2: Maintenance | P2: Maint.
A3: Report Type: | B3: Mean | C3: Calibration | G3: Calib. | J3: Data Fail | L3: Data F | N3: Invalid | P3: Invalid
A4: Time Base: | B4: 15 Min | C4: Zero Referrence | G4: Z.Ref | J4: Warm Up | L4: Wm. Up
A7: Date & Time | B7: NO | C7: NO2 | D7: NOX | E7: SO2 | F7: O3 | G7: PM 10 | H7: PM 2.5 | I7: BENZ | J7: WS | K7: WD | L7: TEMP | M7: HUM | N7: SR | O7: RG | P7: CO | Q7: NH3
B8: ug/m3 | C8: ug/m3 | D8: ppb | E8: ug/m3 | F8: ug/m3 | G8: ug/m3 | H8: ug/m3 | I8: ug/m3 | J8: m/sec | K8: deg | L8: degreC | M8: % | N8: w/m2 | O8: mm | P8: mg/m3 | Q8: ug/m3
A106: Min | B106: =MIN(B9:B104) -> 0 | C106: =MIN(C9:C104) -> 0 | D106: =MIN(D9:D104) -> 0 | E106: =MIN(E9:E104) -> 0 | F106: =MIN(F9:F104) -> 0 | G106: =MIN(G9:G104) -> 0 | H106: =MIN(H9:H104) -> 0 | I106: =MIN(I9:I104) -> 0 | ... Q106: =MIN(Q9:Q104) -> 0
A107: Max | B107: =MAX(B9:B104) -> 0 | C107: =MAX(C9:C104) -> 0 | D107: =MAX(D9:D104) -> 0 | E107: =MAX(E9:E104) -> 0 | F107: =MAX(F9:F104) -> 0 | G107: =MAX(G9:G104) -> 0 | H107: =MAX(H9:H104) -> 0 | I107: =MAX(I9:I104) -> 0 | ... Q107: =MAX(Q9:Q104) -> 0
A108: Avg | B108: =AVERAGE(B9:B104) -> #DIV/0! | C108: =AVERAGE(C9:C104) -> #DIV/0! | D108: =AVERAGE(D9:D104) -> #DIV/0! | E108: =AVERAGE(E9:E104) -> #DIV/0! | F108: =AVERAGE(F9:F104) -> #DIV/0! | G108: =AVERAGE(G9:G104) -> #DIV/0! | H108: =AVERAGE(H9:H104) -> #DIV/0! | I108: =AVERAGE(I9:I104) -> #DIV/0! | ... Q108: =AVERAGE(Q9:Q104) -> #DIV/0!
A109: Stdev | B109: =STDEV(B9:B104) -> #DIV/0! | C109: =STDEV(C9:C104) -> #DIV/0! | D109: =STDEV(D9:D104) -> #DIV/0! | E109: =STDEV(E9:E104) -> #DIV/0! | F109: =STDEV(F9:F104) -> #DIV/0! | G109: =STDEV(G9:G104) -> #DIV/0! | H109: =STDEV(H9:H104) -> #DIV/0! | I109: =STDEV(I9:I104) -> #DIV/0! | ... Q109: =STDEV(Q9:Q104) -> #DIV/0!
A110: Num | B110: =COUNT(B9:B104) -> 0 | C110: =COUNT(C9:C104) -> 0 | D110: =COUNT(D9:D104) -> 0 | E110: =COUNT(E9:E104) -> 0 | F110: =COUNT(F9:F104) -> 0 | G110: =COUNT(G9:G104) -> 0 | H110: =COUNT(H9:H104) -> 0 | I110: =COUNT(I9:I104) -> 0 | ... Q110: =COUNT(Q9:Q104) -> 0
A111: DCR | B111: =IF(B110>=87,">90%",IF(B110<=87,"<90%")) -> <90% | C111: =IF(C110>=87,">90%",IF(C110<=87,"<90%")) -> <90% | D111: =IF(D110>=87,">90%",IF(D110<=87,"<90%")) -> <90% | E111: =IF(E110>=87,">90%",IF(E110<=87,"<90%")) -> <90% | F111: =IF(F110>=87,">90%",IF(F110<=87,"<90%")) -> <90% | G111: =IF(G110>=87,">90%",IF(G110<=87,"<90%")) -> <90% | H111: =IF(H110>=87,">90%",IF(H110<=87,"<90%")) -> <90% | I111: =IF(I110>=87,">90%",IF(I110<=87,"<90%")) -> <90% | ... Q111: =IF(Q110>=87,">90%",IF(Q110<=87,"<90%")) -> <90%
A112: Status | B112: =IF(B110>=87,"OK",IF(B110<=87,"LESS")) -> LESS | C112: =IF(C110>=87,"OK",IF(C110<=87,"LESS")) -> LESS | D112: =IF(D110>=87,"OK",IF(D110<=87,"LESS")) -> LESS | E112: =IF(E110>=87,"OK",IF(E110<=87,"LESS")) -> LESS | F112: =IF(F110>=87,"OK",IF(F110<=87,"LESS")) -> LESS | G112: =IF(G110>=87,"OK",IF(G110<=87,"LESS")) -> LESS | H112: =IF(H110>=87,"OK",IF(H110<=87,"LESS")) -> LESS | I112: =IF(I110>=87,"OK",IF(I110<=87,"LESS")) -> LESS | ... Q112: =IF(Q110>=87,"OK",IF(Q110<=87,"LESS")) -> LESS
A115: Done by | B115: AKASH
A117: Comment

Sheet 05
A1: Station: | B1: IGKV RAIPUR
A2: Date: | B2: =$A$9 -> 0 | C2: Power Off | G2: Pw.Off | J2: Link Fail | L2: Link F | N2: Maintenance | P2: Maint.
A3: Report Type: | B3: Mean | C3: Calibration | G3: Calib. | J3: Data Fail | L3: Data F | N3: Invalid | P3: Invalid
A4: Time Base: | B4: 15 Min | C4: Zero Referrence | G4: Z.Ref | J4: Warm Up | L4: Wm. Up
A7: Date & Time | B7: NO | C7: NO2 | D7: NOX | E7: SO2 | F7: O3 | G7: PM 10 | H7: PM 2.5 | I7: BENZ | J7: WS | K7: WD | L7: TEMP | M7: HUM | N7: SR | O7: RG | P7: CO | Q7: NH3
B8: ug/m3 | C8: ug/m3 | D8: ppb | E8: ug/m3 | F8: ug/m3 | G8: ug/m3 | H8: ug/m3 | I8: ug/m3 | J8: m/sec | K8: deg | L8: degreC | M8: % | N8: w/m2 | O8: mm | P8: mg/m3 | Q8: ug/m3
A106: Min | B106: =MIN(B9:B104) -> 0 | C106: =MIN(C9:C104) -> 0 | D106: =MIN(D9:D104) -> 0 | E106: =MIN(E9:E104) -> 0 | F106: =MIN(F9:F104) -> 0 | G106: =MIN(G9:G104) -> 0 | H106: =MIN(H9:H104) -> 0 | I106: =MIN(I9:I104) -> 0 | ... Q106: =MIN(Q9:Q104) -> 0
A107: Max | B107: =MAX(B9:B104) -> 0 | C107: =MAX(C9:C104) -> 0 | D107: =MAX(D9:D104) -> 0 | E107: =MAX(E9:E104) -> 0 | F107: =MAX(F9:F104) -> 0 | G107: =MAX(G9:G104) -> 0 | H107: =MAX(H9:H104) -> 0 | I107: =MAX(I9:I104) -> 0 | ... Q107: =MAX(Q9:Q104) -> 0
A108: Avg | B108: =AVERAGE(B9:B104) -> #DIV/0! | C108: =AVERAGE(C9:C104) -> #DIV/0! | D108: =AVERAGE(D9:D104) -> #DIV/0! | E108: =AVERAGE(E9:E104) -> #DIV/0! | F108: =AVERAGE(F9:F104) -> #DIV/0! | G108: =AVERAGE(G9:G104) -> #DIV/0! | H108: =AVERAGE(H9:H104) -> #DIV/0! | I108: =AVERAGE(I9:I104) -> #DIV/0! | ... Q108: =AVERAGE(Q9:Q104) -> #DIV/0!
A109: Stdev | B109: =STDEV(B9:B104) -> #DIV/0! | C109: =STDEV(C9:C104) -> #DIV/0! | D109: =STDEV(D9:D104) -> #DIV/0! | E109: =STDEV(E9:E104) -> #DIV/0! | F109: =STDEV(F9:F104) -> #DIV/0! | G109: =STDEV(G9:G104) -> #DIV/0! | H109: =STDEV(H9:H104) -> #DIV/0! | I109: =STDEV(I9:I104) -> #DIV/0! | ... Q109: =STDEV(Q9:Q104) -> #DIV/0!
A110: Num | B110: =COUNT(B9:B104) -> 0 | C110: =COUNT(C9:C104) -> 0 | D110: =COUNT(D9:D104) -> 0 | E110: =COUNT(E9:E104) -> 0 | F110: =COUNT(F9:F104) -> 0 | G110: =COUNT(G9:G104) -> 0 | H110: =COUNT(H9:H104) -> 0 | I110: =COUNT(I9:I104) -> 0 | ... Q110: =COUNT(Q9:Q104) -> 0
A111: DCR | B111: =IF(B110>=87,">90%",IF(B110<=87,"<90%")) -> <90% | C111: =IF(C110>=87,">90%",IF(C110<=87,"<90%")) -> <90% | D111: =IF(D110>=87,">90%",IF(D110<=87,"<90%")) -> <90% | E111: =IF(E110>=87,">90%",IF(E110<=87,"<90%")) -> <90% | F111: =IF(F110>=87,">90%",IF(F110<=87,"<90%")) -> <90% | G111: =IF(G110>=87,">90%",IF(G110<=87,"<90%")) -> <90% | H111: =IF(H110>=87,">90%",IF(H110<=87,"<90%")) -> <90% | I111: =IF(I110>=87,">90%",IF(I110<=87,"<90%")) -> <90% | ... Q111: =IF(Q110>=87,">90%",IF(Q110<=87,"<90%")) -> <90%
A112: Status | B112: =IF(B110>=87,"OK",IF(B110<=87,"LESS")) -> LESS | C112: =IF(C110>=87,"OK",IF(C110<=87,"LESS")) -> LESS | D112: =IF(D110>=87,"OK",IF(D110<=87,"LESS")) -> LESS | E112: =IF(E110>=87,"OK",IF(E110<=87,"LESS")) -> LESS | F112: =IF(F110>=87,"OK",IF(F110<=87,"LESS")) -> LESS | G112: =IF(G110>=87,"OK",IF(G110<=87,"LESS")) -> LESS | H112: =IF(H110>=87,"OK",IF(H110<=87,"LESS")) -> LESS | I112: =IF(I110>=87,"OK",IF(I110<=87,"LESS")) -> LESS | ... Q112: =IF(Q110>=87,"OK",IF(Q110<=87,"LESS")) -> LESS
A115: Done by | B115: AKASH
A117: Comment

Sheet 06
A1: Station: | B1: IGKV RAIPUR
A2: Date: | B2: =$A$9 -> 0 | C2: Power Off | G2: Pw.Off | J2: Link Fail | L2: Link F | N2: Maintenance | P2: Maint.
A3: Report Type: | B3: Mean | C3: Calibration | G3: Calib. | J3: Data Fail | L3: Data F | N3: Invalid | P3: Invalid
A4: Time Base: | B4: 15 Min | C4: Zero Referrence | G4: Z.Ref | J4: Warm Up | L4: Wm. Up
A7: Date & Time | B7: NO | C7: NO2 | D7: NOX | E7: SO2 | F7: O3 | G7: PM 10 | H7: PM 2.5 | I7: BENZ | J7: WS | K7: WD | L7: TEMP | M7: HUM | N7: SR | O7: RG | P7: CO | Q7: NH3
B8: ug/m3 | C8: ug/m3 | D8: ppb | E8: ug/m3 | F8: ug/m3 | G8: ug/m3 | H8: ug/m3 | I8: ug/m3 | J8: m/sec | K8: deg | L8: degreC | M8: % | N8: w/m2 | O8: mm | P8: mg/m3 | Q8: ug/m3
A106: Min | B106: =MIN(B9:B104) -> 0 | C106: =MIN(C9:C104) -> 0 | D106: =MIN(D9:D104) -> 0 | E106: =MIN(E9:E104) -> 0 | F106: =MIN(F9:F104) -> 0 | G106: =MIN(G9:G104) -> 0 | H106: =MIN(H9:H104) -> 0 | I106: =MIN(I9:I104) -> 0 | ... Q106: =MIN(Q9:Q104) -> 0
A107: Max | B107: =MAX(B9:B104) -> 0 | C107: =MAX(C9:C104) -> 0 | D107: =MAX(D9:D104) -> 0 | E107: =MAX(E9:E104) -> 0 | F107: =MAX(F9:F104) -> 0 | G107: =MAX(G9:G104) -> 0 | H107: =MAX(H9:H104) -> 0 | I107: =MAX(I9:I104) -> 0 | ... Q107: =MAX(Q9:Q104) -> 0
A108: Avg | B108: =AVERAGE(B9:B104) -> #DIV/0! | C108: =AVERAGE(C9:C104) -> #DIV/0! | D108: =AVERAGE(D9:D104) -> #DIV/0! | E108: =AVERAGE(E9:E104) -> #DIV/0! | F108: =AVERAGE(F9:F104) -> #DIV/0! | G108: =AVERAGE(G9:G104) -> #DIV/0! | H108: =AVERAGE(H9:H104) -> #DIV/0! | I108: =AVERAGE(I9:I104) -> #DIV/0! | ... Q108: =AVERAGE(Q9:Q104) -> #DIV/0!
A109: Stdev | B109: =STDEV(B9:B104) -> #DIV/0! | C109: =STDEV(C9:C104) -> #DIV/0! | D109: =STDEV(D9:D104) -> #DIV/0! | E109: =STDEV(E9:E104) -> #DIV/0! | F109: =STDEV(F9:F104) -> #DIV/0! | G109: =STDEV(G9:G104) -> #DIV/0! | H109: =STDEV(H9:H104) -> #DIV/0! | I109: =STDEV(I9:I104) -> #DIV/0! | ... Q109: =STDEV(Q9:Q104) -> #DIV/0!
A110: Num | B110: =COUNT(B9:B104) -> 0 | C110: =COUNT(C9:C104) -> 0 | D110: =COUNT(D9:D104) -> 0 | E110: =COUNT(E9:E104) -> 0 | F110: =COUNT(F9:F104) -> 0 | G110: =COUNT(G9:G104) -> 0 | H110: =COUNT(H9:H104) -> 0 | I110: =COUNT(I9:I104) -> 0 | ... Q110: =COUNT(Q9:Q104) -> 0
A111: DCR | B111: =IF(B110>=87,">90%",IF(B110<=87,"<90%")) -> <90% | C111: =IF(C110>=87,">90%",IF(C110<=87,"<90%")) -> <90% | D111: =IF(D110>=87,">90%",IF(D110<=87,"<90%")) -> <90% | E111: =IF(E110>=87,">90%",IF(E110<=87,"<90%")) -> <90% | F111: =IF(F110>=87,">90%",IF(F110<=87,"<90%")) -> <90% | G111: =IF(G110>=87,">90%",IF(G110<=87,"<90%")) -> <90% | H111: =IF(H110>=87,">90%",IF(H110<=87,"<90%")) -> <90% | I111: =IF(I110>=87,">90%",IF(I110<=87,"<90%")) -> <90% | ... Q111: =IF(Q110>=87,">90%",IF(Q110<=87,"<90%")) -> <90%
A112: Status | B112: =IF(B110>=87,"OK",IF(B110<=87,"LESS")) -> LESS | C112: =IF(C110>=87,"OK",IF(C110<=87,"LESS")) -> LESS | D112: =IF(D110>=87,"OK",IF(D110<=87,"LESS")) -> LESS | E112: =IF(E110>=87,"OK",IF(E110<=87,"LESS")) -> LESS | F112: =IF(F110>=87,"OK",IF(F110<=87,"LESS")) -> LESS | G112: =IF(G110>=87,"OK",IF(G110<=87,"LESS")) -> LESS | H112: =IF(H110>=87,"OK",IF(H110<=87,"LESS")) -> LESS | I112: =IF(I110>=87,"OK",IF(I110<=87,"LESS")) -> LESS | ... Q112: =IF(Q110>=87,"OK",IF(Q110<=87,"LESS")) -> LESS
A115: Done by | B115: AKASH
A117: Comment

Sheet 07
A1: Station: | B1: IGKV RAIPUR
A2: Date: | B2: =$A$9 -> 0 | C2: Power Off | G2: Pw.Off | J2: Link Fail | L2: Link F | N2: Maintenance | P2: Maint.
A3: Report Type: | B3: Mean | C3: Calibration | G3: Calib. | J3: Data Fail | L3: Data F | N3: Invalid | P3: Invalid
A4: Time Base: | B4: 15 Min | C4: Zero Referrence | G4: Z.Ref | J4: Warm Up | L4: Wm. Up
A7: Date & Time | B7: NO | C7: NO2 | D7: NOX | E7: SO2 | F7: O3 | G7: PM 10 | H7: PM 2.5 | I7: BENZ | J7: WS | K7: WD | L7: TEMP | M7: HUM | N7: SR | O7: RG | P7: CO | Q7: NH3
B8: ug/m3 | C8: ug/m3 | D8: ppb | E8: ug/m3 | F8: ug/m3 | G8: ug/m3 | H8: ug/m3 | I8: ug/m3 | J8: m/sec | K8: deg | L8: degreC | M8: % | N8: w/m2 | O8: mm | P8: mg/m3 | Q8: ug/m3
A106: Min | B106: =MIN(B9:B104) -> 0 | C106: =MIN(C9:C104) -> 0 | D106: =MIN(D9:D104) -> 0 | E106: =MIN(E9:E104) -> 0 | F106: =MIN(F9:F104) -> 0 | G106: =MIN(G9:G104) -> 0 | H106: =MIN(H9:H104) -> 0 | I106: =MIN(I9:I104) -> 0 | ... Q106: =MIN(Q9:Q104) -> 0
A107: Max | B107: =MAX(B9:B104) -> 0 | C107: =MAX(C9:C104) -> 0 | D107: =MAX(D9:D104) -> 0 | E107: =MAX(E9:E104) -> 0 | F107: =MAX(F9:F104) -> 0 | G107: =MAX(G9:G104) -> 0 | H107: =MAX(H9:H104) -> 0 | I107: =MAX(I9:I104) -> 0 | ... Q107: =MAX(Q9:Q104) -> 0
A108: Avg | B108: =AVERAGE(B9:B104) -> #DIV/0! | C108: =AVERAGE(C9:C104) -> #DIV/0! | D108: =AVERAGE(D9:D104) -> #DIV/0! | E108: =AVERAGE(E9:E104) -> #DIV/0! | F108: =AVERAGE(F9:F104) -> #DIV/0! | G108: =AVERAGE(G9:G104) -> #DIV/0! | H108: =AVERAGE(H9:H104) -> #DIV/0! | I108: =AVERAGE(I9:I104) -> #DIV/0! | ... Q108: =AVERAGE(Q9:Q104) -> #DIV/0!
A109: Stdev | B109: =STDEV(B9:B104) -> #DIV/0! | C109: =STDEV(C9:C104) -> #DIV/0! | D109: =STDEV(D9:D104) -> #DIV/0! | E109: =STDEV(E9:E104) -> #DIV/0! | F109: =STDEV(F9:F104) -> #DIV/0! | G109: =STDEV(G9:G104) -> #DIV/0! | H109: =STDEV(H9:H104) -> #DIV/0! | I109: =STDEV(I9:I104) -> #DIV/0! | ... Q109: =STDEV(Q9:Q104) -> #DIV/0!
A110: Num | B110: =COUNT(B9:B104) -> 0 | C110: =COUNT(C9:C104) -> 0 | D110: =COUNT(D9:D104) -> 0 | E110: =COUNT(E9:E104) -> 0 | F110: =COUNT(F9:F104) -> 0 | G110: =COUNT(G9:G104) -> 0 | H110: =COUNT(H9:H104) -> 0 | I110: =COUNT(I9:I104) -> 0 | ... Q110: =COUNT(Q9:Q104) -> 0
A111: DCR | B111: =IF(B110>=87,">90%",IF(B110<=87,"<90%")) -> <90% | C111: =IF(C110>=87,">90%",IF(C110<=87,"<90%")) -> <90% | D111: =IF(D110>=87,">90%",IF(D110<=87,"<90%")) -> <90% | E111: =IF(E110>=87,">90%",IF(E110<=87,"<90%")) -> <90% | F111: =IF(F110>=87,">90%",IF(F110<=87,"<90%")) -> <90% | G111: =IF(G110>=87,">90%",IF(G110<=87,"<90%")) -> <90% | H111: =IF(H110>=87,">90%",IF(H110<=87,"<90%")) -> <90% | I111: =IF(I110>=87,">90%",IF(I110<=87,"<90%")) -> <90% | ... Q111: =IF(Q110>=87,">90%",IF(Q110<=87,"<90%")) -> <90%
A112: Status | B112: =IF(B110>=87,"OK",IF(B110<=87,"LESS")) -> LESS | C112: =IF(C110>=87,"OK",IF(C110<=87,"LESS")) -> LESS | D112: =IF(D110>=87,"OK",IF(D110<=87,"LESS")) -> LESS | E112: =IF(E110>=87,"OK",IF(E110<=87,"LESS")) -> LESS | F112: =IF(F110>=87,"OK",IF(F110<=87,"LESS")) -> LESS | G112: =IF(G110>=87,"OK",IF(G110<=87,"LESS")) -> LESS | H112: =IF(H110>=87,"OK",IF(H110<=87,"LESS")) -> LESS | I112: =IF(I110>=87,"OK",IF(I110<=87,"LESS")) -> LESS | ... Q112: =IF(Q110>=87,"OK",IF(Q110<=87,"LESS")) -> LESS
A115: Done by | B115: AKASH
A117: Comment

Sheet 08
A1: Station: | B1: IGKV RAIPUR
A2: Date: | B2: =$A$9 -> 0 | C2: Power Off | G2: Pw.Off | J2: Link Fail | L2: Link F | N2: Maintenance | P2: Maint.
A3: Report Type: | B3: Mean | C3: Calibration | G3: Calib. | J3: Data Fail | L3: Data F | N3: Invalid | P3: Invalid
A4: Time Base: | B4: 15 Min | C4: Zero Referrence | G4: Z.Ref | J4: Warm Up | L4: Wm. Up
A7: Date & Time | B7: NO | C7: NO2 | D7: NOX | E7: SO2 | F7: O3 | G7: PM 10 | H7: PM 2.5 | I7: BENZ | J7: WS | K7: WD | L7: TEMP | M7: HUM | N7: SR | O7: RG | P7: CO | Q7: NH3
B8: ug/m3 | C8: ug/m3 | D8: ppb | E8: ug/m3 | F8: ug/m3 | G8: ug/m3 | H8: ug/m3 | I8: ug/m3 | J8: m/sec | K8: deg | L8: degreC | M8: % | N8: w/m2 | O8: mm | P8: mg/m3 | Q8: ug/m3
A106: Min | B106: =MIN(B9:B104) -> 0 | C106: =MIN(C9:C104) -> 0 | D106: =MIN(D9:D104) -> 0 | E106: =MIN(E9:E104) -> 0 | F106: =MIN(F9:F104) -> 0 | G106: =MIN(G9:G104) -> 0 | H106: =MIN(H9:H104) -> 0 | I106: =MIN(I9:I104) -> 0 | ... Q106: =MIN(Q9:Q104) -> 0
A107: Max | B107: =MAX(B9:B104) -> 0 | C107: =MAX(C9:C104) -> 0 | D107: =MAX(D9:D104) -> 0 | E107: =MAX(E9:E104) -> 0 | F107: =MAX(F9:F104) -> 0 | G107: =MAX(G9:G104) -> 0 | H107: =MAX(H9:H104) -> 0 | I107: =MAX(I9:I104) -> 0 | ... Q107: =MAX(Q9:Q104) -> 0
A108: Avg | B108: =AVERAGE(B9:B104) -> #DIV/0! | C108: =AVERAGE(C9:C104) -> #DIV/0! | D108: =AVERAGE(D9:D104) -> #DIV/0! | E108: =AVERAGE(E9:E104) -> #DIV/0! | F108: =AVERAGE(F9:F104) -> #DIV/0! | G108: =AVERAGE(G9:G104) -> #DIV/0! | H108: =AVERAGE(H9:H104) -> #DIV/0! | I108: =AVERAGE(I9:I104) -> #DIV/0! | ... Q108: =AVERAGE(Q9:Q104) -> #DIV/0!
A109: Stdev | B109: =STDEV(B9:B104) -> #DIV/0! | C109: =STDEV(C9:C104) -> #DIV/0! | D109: =STDEV(D9:D104) -> #DIV/0! | E109: =STDEV(E9:E104) -> #DIV/0! | F109: =STDEV(F9:F104) -> #DIV/0! | G109: =STDEV(G9:G104) -> #DIV/0! | H109: =STDEV(H9:H104) -> #DIV/0! | I109: =STDEV(I9:I104) -> #DIV/0! | ... Q109: =STDEV(Q9:Q104) -> #DIV/0!
A110: Num | B110: =COUNT(B9:B104) -> 0 | C110: =COUNT(C9:C104) -> 0 | D110: =COUNT(D9:D104) -> 0 | E110: =COUNT(E9:E104) -> 0 | F110: =COUNT(F9:F104) -> 0 | G110: =COUNT(G9:G104) -> 0 | H110: =COUNT(H9:H104) -> 0 | I110: =COUNT(I9:I104) -> 0 | ... Q110: =COUNT(Q9:Q104) -> 0
A111: DCR | B111: =IF(B110>=87,">90%",IF(B110<=87,"<90%")) -> <90% | C111: =IF(C110>=87,">90%",IF(C110<=87,"<90%")) -> <90% | D111: =IF(D110>=87,">90%",IF(D110<=87,"<90%")) -> <90% | E111: =IF(E110>=87,">90%",IF(E110<=87,"<90%")) -> <90% | F111: =IF(F110>=87,">90%",IF(F110<=87,"<90%")) -> <90% | G111: =IF(G110>=87,">90%",IF(G110<=87,"<90%")) -> <90% | H111: =IF(H110>=87,">90%",IF(H110<=87,"<90%")) -> <90% | I111: =IF(I110>=87,">90%",IF(I110<=87,"<90%")) -> <90% | ... Q111: =IF(Q110>=87,">90%",IF(Q110<=87,"<90%")) -> <90%
A112: Status | B112: =IF(B110>=87,"OK",IF(B110<=87,"LESS")) -> LESS | C112: =IF(C110>=87,"OK",IF(C110<=87,"LESS")) -> LESS | D112: =IF(D110>=87,"OK",IF(D110<=87,"LESS")) -> LESS | E112: =IF(E110>=87,"OK",IF(E110<=87,"LESS")) -> LESS | F112: =IF(F110>=87,"OK",IF(F110<=87,"LESS")) -> LESS | G112: =IF(G110>=87,"OK",IF(G110<=87,"LESS")) -> LESS | H112: =IF(H110>=87,"OK",IF(H110<=87,"LESS")) -> LESS | I112: =IF(I110>=87,"OK",IF(I110<=87,"LESS")) -> LESS | ... Q112: =IF(Q110>=87,"OK",IF(Q110<=87,"LESS")) -> LESS
A115: Done by | B115: AKASH
A117: Comment

Sheet 09
A1: Station: | B1: IGKV RAIPUR
A2: Date: | B2: =$A$9 -> 0 | C2: Power Off | G2: Pw.Off | J2: Link Fail | L2: Link F | N2: Maintenance | P2: Maint.
A3: Report Type: | B3: Mean | C3: Calibration | G3: Calib. | J3: Data Fail | L3: Data F | N3: Invalid | P3: Invalid
A4: Time Base: | B4: 15 Min | C4: Zero Referrence | G4: Z.Ref | J4: Warm Up | L4: Wm. Up
A7: Date & Time | B7: NO | C7: NO2 | D7: NOX | E7: SO2 | F7: O3 | G7: PM 10 | H7: PM 2.5 | I7: BENZ | J7: WS | K7: WD | L7: TEMP | M7: HUM | N7: SR | O7: RG | P7: CO | Q7: NH3
B8: ug/m3 | C8: ug/m3 | D8: ppb | E8: ug/m3 | F8: ug/m3 | G8: ug/m3 | H8: ug/m3 | I8: ug/m3 | J8: m/sec | K8: deg | L8: degreC | M8: % | N8: w/m2 | O8: mm | P8: mg/m3 | Q8: ug/m3
A106: Min | B106: =MIN(B9:B104) -> 0 | C106: =MIN(C9:C104) -> 0 | D106: =MIN(D9:D104) -> 0 | E106: =MIN(E9:E104) -> 0 | F106: =MIN(F9:F104) -> 0 | G106: =MIN(G9:G104) -> 0 | H106: =MIN(H9:H104) -> 0 | I106: =MIN(I9:I104) -> 0 | ... Q106: =MIN(Q9:Q104) -> 0
A107: Max | B107: =MAX(B9:B104) -> 0 | C107: =MAX(C9:C104) -> 0 | D107: =MAX(D9:D104) -> 0 | E107: =MAX(E9:E104) -> 0 | F107: =MAX(F9:F104) -> 0 | G107: =MAX(G9:G104) -> 0 | H107: =MAX(H9:H104) -> 0 | I107: =MAX(I9:I104) -> 0 | ... Q107: =MAX(Q9:Q104) -> 0
A108: Avg | B108: =AVERAGE(B9:B104) -> #DIV/0! | C108: =AVERAGE(C9:C104) -> #DIV/0! | D108: =AVERAGE(D9:D104) -> #DIV/0! | E108: =AVERAGE(E9:E104) -> #DIV/0! | F108: =AVERAGE(F9:F104) -> #DIV/0! | G108: =AVERAGE(G9:G104) -> #DIV/0! | H108: =AVERAGE(H9:H104) -> #DIV/0! | I108: =AVERAGE(I9:I104) -> #DIV/0! | ... Q108: =AVERAGE(Q9:Q104) -> #DIV/0!
A109: Stdev | B109: =STDEV(B9:B104) -> #DIV/0! | C109: =STDEV(C9:C104) -> #DIV/0! | D109: =STDEV(D9:D104) -> #DIV/0! | E109: =STDEV(E9:E104) -> #DIV/0! | F109: =STDEV(F9:F104) -> #DIV/0! | G109: =STDEV(G9:G104) -> #DIV/0! | H109: =STDEV(H9:H104) -> #DIV/0! | I109: =STDEV(I9:I104) -> #DIV/0! | ... Q109: =STDEV(Q9:Q104) -> #DIV/0!
A110: Num | B110: =COUNT(B9:B104) -> 0 | C110: =COUNT(C9:C104) -> 0 | D110: =COUNT(D9:D104) -> 0 | E110: =COUNT(E9:E104) -> 0 | F110: =COUNT(F9:F104) -> 0 | G110: =COUNT(G9:G104) -> 0 | H110: =COUNT(H9:H104) -> 0 | I110: =COUNT(I9:I104) -> 0 | ... Q110: =COUNT(Q9:Q104) -> 0
A111: DCR | B111: =IF(B110>=87,">90%",IF(B110<=87,"<90%")) -> <90% | C111: =IF(C110>=87,">90%",IF(C110<=87,"<90%")) -> <90% | D111: =IF(D110>=87,">90%",IF(D110<=87,"<90%")) -> <90% | E111: =IF(E110>=87,">90%",IF(E110<=87,"<90%")) -> <90% | F111: =IF(F110>=87,">90%",IF(F110<=87,"<90%")) -> <90% | G111: =IF(G110>=87,">90%",IF(G110<=87,"<90%")) -> <90% | H111: =IF(H110>=87,">90%",IF(H110<=87,"<90%")) -> <90% | I111: =IF(I110>=87,">90%",IF(I110<=87,"<90%")) -> <90% | ... Q111: =IF(Q110>=87,">90%",IF(Q110<=87,"<90%")) -> <90%
A112: Status | B112: =IF(B110>=87,"OK",IF(B110<=87,"LESS")) -> LESS | C112: =IF(C110>=87,"OK",IF(C110<=87,"LESS")) -> LESS | D112: =IF(D110>=87,"OK",IF(D110<=87,"LESS")) -> LESS | E112: =IF(E110>=87,"OK",IF(E110<=87,"LESS")) -> LESS | F112: =IF(F110>=87,"OK",IF(F110<=87,"LESS")) -> LESS | G112: =IF(G110>=87,"OK",IF(G110<=87,"LESS")) -> LESS | H112: =IF(H110>=87,"OK",IF(H110<=87,"LESS")) -> LESS | I112: =IF(I110>=87,"OK",IF(I110<=87,"LESS")) -> LESS | ... Q112: =IF(Q110>=87,"OK",IF(Q110<=87,"LESS")) -> LESS
A115: Done by | B115: AKASH
A117: Comment

Sheet 10
A1: Station: | B1: IGKV RAIPUR
A2: Date: | B2: =$A$9 -> 0 | C2: Power Off | G2: Pw.Off | J2: Link Fail | L2: Link F | N2: Maintenance | P2: Maint.
A3: Report Type: | B3: Mean | C3: Calibration | G3: Calib. | J3: Data Fail | L3: Data F | N3: Invalid | P3: Invalid
A4: Time Base: | B4: 15 Min | C4: Zero Referrence | G4: Z.Ref | J4: Warm Up | L4: Wm. Up
A7: Date & Time | B7: NO | C7: NO2 | D7: NOX | E7: SO2 | F7: O3 | G7: PM 10 | H7: PM 2.5 | I7: BENZ | J7: WS | K7: WD | L7: TEMP | M7: HUM | N7: SR | O7: RG | P7: CO | Q7: NH3
B8: ug/m3 | C8: ug/m3 | D8: ppb | E8: ug/m3 | F8: ug/m3 | G8: ug/m3 | H8: ug/m3 | I8: ug/m3 | J8: m/sec | K8: deg | L8: degreC | M8: % | N8: w/m2 | O8: mm | P8: mg/m3 | Q8: ug/m3
A106: Min | B106: =MIN(B9:B104) -> 0 | C106: =MIN(C9:C104) -> 0 | D106: =MIN(D9:D104) -> 0 | E106: =MIN(E9:E104) -> 0 | F106: =MIN(F9:F104) -> 0 | G106: =MIN(G9:G104) -> 0 | H106: =MIN(H9:H104) -> 0 | I106: =MIN(I9:I104) -> 0 | ... Q106: =MIN(Q9:Q104) -> 0
A107: Max | B107: =MAX(B9:B104) -> 0 | C107: =MAX(C9:C104) -> 0 | D107: =MAX(D9:D104) -> 0 | E107: =MAX(E9:E104) -> 0 | F107: =MAX(F9:F104) -> 0 | G107: =MAX(G9:G104) -> 0 | H107: =MAX(H9:H104) -> 0 | I107: =MAX(I9:I104) -> 0 | ... Q107: =MAX(Q9:Q104) -> 0
A108: Avg | B108: =AVERAGE(B9:B104) -> #DIV/0! | C108: =AVERAGE(C9:C104) -> #DIV/0! | D108: =AVERAGE(D9:D104) -> #DIV/0! | E108: =AVERAGE(E9:E104) -> #DIV/0! | F108: =AVERAGE(F9:F104) -> #DIV/0! | G108: =AVERAGE(G9:G104) -> #DIV/0! | H108: =AVERAGE(H9:H104) -> #DIV/0! | I108: =AVERAGE(I9:I104) -> #DIV/0! | ... Q108: =AVERAGE(Q9:Q104) -> #DIV/0!
A109: Stdev | B109: =STDEV(B9:B104) -> #DIV/0! | C109: =STDEV(C9:C104) -> #DIV/0! | D109: =STDEV(D9:D104) -> #DIV/0! | E109: =STDEV(E9:E104) -> #DIV/0! | F109: =STDEV(F9:F104) -> #DIV/0! | G109: =STDEV(G9:G104) -> #DIV/0! | H109: =STDEV(H9:H104) -> #DIV/0! | I109: =STDEV(I9:I104) -> #DIV/0! | ... Q109: =STDEV(Q9:Q104) -> #DIV/0!
A110: Num | B110: =COUNT(B9:B104) -> 0 | C110: =COUNT(C9:C104) -> 0 | D110: =COUNT(D9:D104) -> 0 | E110: =COUNT(E9:E104) -> 0 | F110: =COUNT(F9:F104) -> 0 | G110: =COUNT(G9:G104) -> 0 | H110: =COUNT(H9:H104) -> 0 | I110: =COUNT(I9:I104) -> 0 | ... Q110: =COUNT(Q9:Q104) -> 0
A111: DCR | B111: =IF(B110>=87,">90%",IF(B110<=87,"<90%")) -> <90% | C111: =IF(C110>=87,">90%",IF(C110<=87,"<90%")) -> <90% | D111: =IF(D110>=87,">90%",IF(D110<=87,"<90%")) -> <90% | E111: =IF(E110>=87,">90%",IF(E110<=87,"<90%")) -> <90% | F111: =IF(F110>=87,">90%",IF(F110<=87,"<90%")) -> <90% | G111: =IF(G110>=87,">90%",IF(G110<=87,"<90%")) -> <90% | H111: =IF(H110>=87,">90%",IF(H110<=87,"<90%")) -> <90% | I111: =IF(I110>=87,">90%",IF(I110<=87,"<90%")) -> <90% | ... Q111: =IF(Q110>=87,">90%",IF(Q110<=87,"<90%")) -> <90%
A112: Status | B112: =IF(B110>=87,"OK",IF(B110<=87,"LESS")) -> LESS | C112: =IF(C110>=87,"OK",IF(C110<=87,"LESS")) -> LESS | D112: =IF(D110>=87,"OK",IF(D110<=87,"LESS")) -> LESS | E112: =IF(E110>=87,"OK",IF(E110<=87,"LESS")) -> LESS | F112: =IF(F110>=87,"OK",IF(F110<=87,"LESS")) -> LESS | G112: =IF(G110>=87,"OK",IF(G110<=87,"LESS")) -> LESS | H112: =IF(H110>=87,"OK",IF(H110<=87,"LESS")) -> LESS | I112: =IF(I110>=87,"OK",IF(I110<=87,"LESS")) -> LESS | ... Q112: =IF(Q110>=87,"OK",IF(Q110<=87,"LESS")) -> LESS
A115: Done by | B115: AKASH
A117: Comment

Sheet 11
A1: Station: | B1: IGKV RAIPUR
A2: Date: | B2: =$A$9 -> 0 | C2: Power Off | G2: Pw.Off | J2: Link Fail | L2: Link F | N2: Maintenance | P2: Maint.
A3: Report Type: | B3: Mean | C3: Calibration | G3: Calib. | J3: Data Fail | L3: Data F | N3: Invalid | P3: Invalid
A4: Time Base: | B4: 15 Min | C4: Zero Referrence | G4: Z.Ref | J4: Warm Up | L4: Wm. Up
A7: Date & Time | B7: NO | C7: NO2 | D7: NOX | E7: SO2 | F7: O3 | G7: PM 10 | H7: PM 2.5 | I7: BENZ | J7: WS | K7: WD | L7: TEMP | M7: HUM | N7: SR | O7: RG | P7: CO | Q7: NH3
B8: ug/m3 | C8: ug/m3 | D8: ppb | E8: ug/m3 | F8: ug/m3 | G8: ug/m3 | H8: ug/m3 | I8: ug/m3 | J8: m/sec | K8: deg | L8: degreC | M8: % | N8: w/m2 | O8: mm | P8: mg/m3 | Q8: ug/m3
A106: Min | B106: =MIN(B9:B104) -> 0 | C106: =MIN(C9:C104) -> 0 | D106: =MIN(D9:D104) -> 0 | E106: =MIN(E9:E104) -> 0 | F106: =MIN(F9:F104) -> 0 | G106: =MIN(G9:G104) -> 0 | H106: =MIN(H9:H104) -> 0 | I106: =MIN(I9:I104) -> 0 | ... Q106: =MIN(Q9:Q104) -> 0
A107: Max | B107: =MAX(B9:B104) -> 0 | C107: =MAX(C9:C104) -> 0 | D107: =MAX(D9:D104) -> 0 | E107: =MAX(E9:E104) -> 0 | F107: =MAX(F9:F104) -> 0 | G107: =MAX(G9:G104) -> 0 | H107: =MAX(H9:H104) -> 0 | I107: =MAX(I9:I104) -> 0 | ... Q107: =MAX(Q9:Q104) -> 0
A108: Avg | B108: =AVERAGE(B9:B104) -> #DIV/0! | C108: =AVERAGE(C9:C104) -> #DIV/0! | D108: =AVERAGE(D9:D104) -> #DIV/0! | E108: =AVERAGE(E9:E104) -> #DIV/0! | F108: =AVERAGE(F9:F104) -> #DIV/0! | G108: =AVERAGE(G9:G104) -> #DIV/0! | H108: =AVERAGE(H9:H104) -> #DIV/0! | I108: =AVERAGE(I9:I104) -> #DIV/0! | ... Q108: =AVERAGE(Q9:Q104) -> #DIV/0!
A109: Stdev | B109: =STDEV(B9:B104) -> #DIV/0! | C109: =STDEV(C9:C104) -> #DIV/0! | D109: =STDEV(D9:D104) -> #DIV/0! | E109: =STDEV(E9:E104) -> #DIV/0! | F109: =STDEV(F9:F104) -> #DIV/0! | G109: =STDEV(G9:G104) -> #DIV/0! | H109: =STDEV(H9:H104) -> #DIV/0! | I109: =STDEV(I9:I104) -> #DIV/0! | ... Q109: =STDEV(Q9:Q104) -> #DIV/0!
A110: Num | B110: =COUNT(B9:B104) -> 0 | C110: =COUNT(C9:C104) -> 0 | D110: =COUNT(D9:D104) -> 0 | E110: =COUNT(E9:E104) -> 0 | F110: =COUNT(F9:F104) -> 0 | G110: =COUNT(G9:G104) -> 0 | H110: =COUNT(H9:H104) -> 0 | I110: =COUNT(I9:I104) -> 0 | ... Q110: =COUNT(Q9:Q104) -> 0
A111: DCR | B111: =IF(B110>=87,">90%",IF(B110<=87,"<90%")) -> <90% | C111: =IF(C110>=87,">90%",IF(C110<=87,"<90%")) -> <90% | D111: =IF(D110>=87,">90%",IF(D110<=87,"<90%")) -> <90% | E111: =IF(E110>=87,">90%",IF(E110<=87,"<90%")) -> <90% | F111: =IF(F110>=87,">90%",IF(F110<=87,"<90%")) -> <90% | G111: =IF(G110>=87,">90%",IF(G110<=87,"<90%")) -> <90% | H111: =IF(H110>=87,">90%",IF(H110<=87,"<90%")) -> <90% | I111: =IF(I110>=87,">90%",IF(I110<=87,"<90%")) -> <90% | ... Q111: =IF(Q110>=87,">90%",IF(Q110<=87,"<90%")) -> <90%
A112: Status | B112: =IF(B110>=87,"OK",IF(B110<=87,"LESS")) -> LESS | C112: =IF(C110>=87,"OK",IF(C110<=87,"LESS")) -> LESS | D112: =IF(D110>=87,"OK",IF(D110<=87,"LESS")) -> LESS | E112: =IF(E110>=87,"OK",IF(E110<=87,"LESS")) -> LESS | F112: =IF(F110>=87,"OK",IF(F110<=87,"LESS")) -> LESS | G112: =IF(G110>=87,"OK",IF(G110<=87,"LESS")) -> LESS | H112: =IF(H110>=87,"OK",IF(H110<=87,"LESS")) -> LESS | I112: =IF(I110>=87,"OK",IF(I110<=87,"LESS")) -> LESS | ... Q112: =IF(Q110>=87,"OK",IF(Q110<=87,"LESS")) -> LESS
A115: Done by | B115: AKASH
A117: Comment

Sheet 12
A1: Station: | B1: IGKV RAIPUR
A2: Date: | B2: =$A$9 -> 0 | C2: Power Off | G2: Pw.Off | J2: Link Fail | L2: Link F | N2: Maintenance | P2: Maint.
A3: Report Type: | B3: Mean | C3: Calibration | G3: Calib. | J3: Data Fail | L3: Data F | N3: Invalid | P3: Invalid
A4: Time Base: | B4: 15 Min | C4: Zero Referrence | G4: Z.Ref | J4: Warm Up | L4: Wm. Up
A7: Date & Time | B7: NO | C7: NO2 | D7: NOX | E7: SO2 | F7: O3 | G7: PM 10 | H7: PM 2.5 | I7: BENZ | J7: WS | K7: WD | L7: TEMP | M7: HUM | N7: SR | O7: RG | P7: CO | Q7: NH3
B8: ug/m3 | C8: ug/m3 | D8: ppb | E8: ug/m3 | F8: ug/m3 | G8: ug/m3 | H8: ug/m3 | I8: ug/m3 | J8: m/sec | K8: deg | L8: degreC | M8: % | N8: w/m2 | O8: mm | P8: mg/m3 | Q8: ug/m3
A106: Min | B106: =MIN(B9:B104) -> 0 | C106: =MIN(C9:C104) -> 0 | D106: =MIN(D9:D104) -> 0 | E106: =MIN(E9:E104) -> 0 | F106: =MIN(F9:F104) -> 0 | G106: =MIN(G9:G104) -> 0 | H106: =MIN(H9:H104) -> 0 | I106: =MIN(I9:I104) -> 0 | ... Q106: =MIN(Q9:Q104) -> 0
A107: Max | B107: =MAX(B9:B104) -> 0 | C107: =MAX(C9:C104) -> 0 | D107: =MAX(D9:D104) -> 0 | E107: =MAX(E9:E104) -> 0 | F107: =MAX(F9:F104) -> 0 | G107: =MAX(G9:G104) -> 0 | H107: =MAX(H9:H104) -> 0 | I107: =MAX(I9:I104) -> 0 | ... Q107: =MAX(Q9:Q104) -> 0
A108: Avg | B108: =AVERAGE(B9:B104) -> #DIV/0! | C108: =AVERAGE(C9:C104) -> #DIV/0! | D108: =AVERAGE(D9:D104) -> #DIV/0! | E108: =AVERAGE(E9:E104) -> #DIV/0! | F108: =AVERAGE(F9:F104) -> #DIV/0! | G108: =AVERAGE(G9:G104) -> #DIV/0! | H108: =AVERAGE(H9:H104) -> #DIV/0! | I108: =AVERAGE(I9:I104) -> #DIV/0! | ... Q108: =AVERAGE(Q9:Q104) -> #DIV/0!
A109: Stdev | B109: =STDEV(B9:B104) -> #DIV/0! | C109: =STDEV(C9:C104) -> #DIV/0! | D109: =STDEV(D9:D104) -> #DIV/0! | E109: =STDEV(E9:E104) -> #DIV/0! | F109: =STDEV(F9:F104) -> #DIV/0! | G109: =STDEV(G9:G104) -> #DIV/0! | H109: =STDEV(H9:H104) -> #DIV/0! | I109: =STDEV(I9:I104) -> #DIV/0! | ... Q109: =STDEV(Q9:Q104) -> #DIV/0!
A110: Num | B110: =COUNT(B9:B104) -> 0 | C110: =COUNT(C9:C104) -> 0 | D110: =COUNT(D9:D104) -> 0 | E110: =COUNT(E9:E104) -> 0 | F110: =COUNT(F9:F104) -> 0 | G110: =COUNT(G9:G104) -> 0 | H110: =COUNT(H9:H104) -> 0 | I110: =COUNT(I9:I104) -> 0 | ... Q110: =COUNT(Q9:Q104) -> 0
A111: DCR | B111: =IF(B110>=87,">90%",IF(B110<=87,"<90%")) -> <90% | C111: =IF(C110>=87,">90%",IF(C110<=87,"<90%")) -> <90% | D111: =IF(D110>=87,">90%",IF(D110<=87,"<90%")) -> <90% | E111: =IF(E110>=87,">90%",IF(E110<=87,"<90%")) -> <90% | F111: =IF(F110>=87,">90%",IF(F110<=87,"<90%")) -> <90% | G111: =IF(G110>=87,">90%",IF(G110<=87,"<90%")) -> <90% | H111: =IF(H110>=87,">90%",IF(H110<=87,"<90%")) -> <90% | I111: =IF(I110>=87,">90%",IF(I110<=87,"<90%")) -> <90% | ... Q111: =IF(Q110>=87,">90%",IF(Q110<=87,"<90%")) -> <90%
A112: Status | B112: =IF(B110>=87,"OK",IF(B110<=87,"LESS")) -> LESS | C112: =IF(C110>=87,"OK",IF(C110<=87,"LESS")) -> LESS | D112: =IF(D110>=87,"OK",IF(D110<=87,"LESS")) -> LESS | E112: =IF(E110>=87,"OK",IF(E110<=87,"LESS")) -> LESS | F112: =IF(F110>=87,"OK",IF(F110<=87,"LESS")) -> LESS | G112: =IF(G110>=87,"OK",IF(G110<=87,"LESS")) -> LESS | H112: =IF(H110>=87,"OK",IF(H110<=87,"LESS")) -> LESS | I112: =IF(I110>=87,"OK",IF(I110<=87,"LESS")) -> LESS | ... Q112: =IF(Q110>=87,"OK",IF(Q110<=87,"LESS")) -> LESS
A115: Done by | B115: AKASH
A117: Comment

Sheet 13
A1: Station: | B1: IGKV RAIPUR
A2: Date: | B2: =$A$9 -> 0 | C2: Power Off | G2: Pw.Off | J2: Link Fail | L2: Link F | N2: Maintenance | P2: Maint.
A3: Report Type: | B3: Mean | C3: Calibration | G3: Calib. | J3: Data Fail | L3: Data F | N3: Invalid | P3: Invalid
A4: Time Base: | B4: 15 Min | C4: Zero Referrence | G4: Z.Ref | J4: Warm Up | L4: Wm. Up
A7: Date & Time | B7: NO | C7: NO2 | D7: NOX | E7: SO2 | F7: O3 | G7: PM 10 | H7: PM 2.5 | I7: BENZ | J7: WS | K7: WD | L7: TEMP | M7: HUM | N7: SR | O7: RG | P7: CO | Q7: NH3
B8: ug/m3 | C8: ug/m3 | D8: ppb | E8: ug/m3 | F8: ug/m3 | G8: ug/m3 | H8: ug/m3 | I8: ug/m3 | J8: m/sec | K8: deg | L8: degreC | M8: % | N8: w/m2 | O8: mm | P8: mg/m3 | Q8: ug/m3
A106: Min | B106: =MIN(B9:B104) -> 0 | C106: =MIN(C9:C104) -> 0 | D106: =MIN(D9:D104) -> 0 | E106: =MIN(E9:E104) -> 0 | F106: =MIN(F9:F104) -> 0 | G106: =MIN(G9:G104) -> 0 | H106: =MIN(H9:H104) -> 0 | I106: =MIN(I9:I104) -> 0 | ... Q106: =MIN(Q9:Q104) -> 0
A107: Max | B107: =MAX(B9:B104) -> 0 | C107: =MAX(C9:C104) -> 0 | D107: =MAX(D9:D104) -> 0 | E107: =MAX(E9:E104) -> 0 | F107: =MAX(F9:F104) -> 0 | G107: =MAX(G9:G104) -> 0 | H107: =MAX(H9:H104) -> 0 | I107: =MAX(I9:I104) -> 0 | ... Q107: =MAX(Q9:Q104) -> 0
A108: Avg | B108: =AVERAGE(B9:B104) -> #DIV/0! | C108: =AVERAGE(C9:C104) -> #DIV/0! | D108: =AVERAGE(D9:D104) -> #DIV/0! | E108: =AVERAGE(E9:E104) -> #DIV/0! | F108: =AVERAGE(F9:F104) -> #DIV/0! | G108: =AVERAGE(G9:G104) -> #DIV/0! | H108: =AVERAGE(H9:H104) -> #DIV/0! | I108: =AVERAGE(I9:I104) -> #DIV/0! | ... Q108: =AVERAGE(Q9:Q104) -> #DIV/0!
A109: Stdev | B109: =STDEV(B9:B104) -> #DIV/0! | C109: =STDEV(C9:C104) -> #DIV/0! | D109: =STDEV(D9:D104) -> #DIV/0! | E109: =STDEV(E9:E104) -> #DIV/0! | F109: =STDEV(F9:F104) -> #DIV/0! | G109: =STDEV(G9:G104) -> #DIV/0! | H109: =STDEV(H9:H104) -> #DIV/0! | I109: =STDEV(I9:I104) -> #DIV/0! | ... Q109: =STDEV(Q9:Q104) -> #DIV/0!
A110: Num | B110: =COUNT(B9:B104) -> 0 | C110: =COUNT(C9:C104) -> 0 | D110: =COUNT(D9:D104) -> 0 | E110: =COUNT(E9:E104) -> 0 | F110: =COUNT(F9:F104) -> 0 | G110: =COUNT(G9:G104) -> 0 | H110: =COUNT(H9:H104) -> 0 | I110: =COUNT(I9:I104) -> 0 | ... Q110: =COUNT(Q9:Q104) -> 0
A111: DCR | B111: =IF(B110>=87,">90%",IF(B110<=87,"<90%")) -> <90% | C111: =IF(C110>=87,">90%",IF(C110<=87,"<90%")) -> <90% | D111: =IF(D110>=87,">90%",IF(D110<=87,"<90%")) -> <90% | E111: =IF(E110>=87,">90%",IF(E110<=87,"<90%")) -> <90% | F111: =IF(F110>=87,">90%",IF(F110<=87,"<90%")) -> <90% | G111: =IF(G110>=87,">90%",IF(G110<=87,"<90%")) -> <90% | H111: =IF(H110>=87,">90%",IF(H110<=87,"<90%")) -> <90% | I111: =IF(I110>=87,">90%",IF(I110<=87,"<90%")) -> <90% | ... Q111: =IF(Q110>=87,">90%",IF(Q110<=87,"<90%")) -> <90%
A112: Status | B112: =IF(B110>=87,"OK",IF(B110<=87,"LESS")) -> LESS | C112: =IF(C110>=87,"OK",IF(C110<=87,"LESS")) -> LESS | D112: =IF(D110>=87,"OK",IF(D110<=87,"LESS")) -> LESS | E112: =IF(E110>=87,"OK",IF(E110<=87,"LESS")) -> LESS | F112: =IF(F110>=87,"OK",IF(F110<=87,"LESS")) -> LESS | G112: =IF(G110>=87,"OK",IF(G110<=87,"LESS")) -> LESS | H112: =IF(H110>=87,"OK",IF(H110<=87,"LESS")) -> LESS | I112: =IF(I110>=87,"OK",IF(I110<=87,"LESS")) -> LESS | ... Q112: =IF(Q110>=87,"OK",IF(Q110<=87,"LESS")) -> LESS
A115: Done by | B115: AKASH
A117: Comment

Sheet 14
A1: Station: | B1: IGKV RAIPUR
A2: Date: | B2: =$A$9 -> 0 | C2: Power Off | G2: Pw.Off | J2: Link Fail | L2: Link F | N2: Maintenance | P2: Maint.
A3: Report Type: | B3: Mean | C3: Calibration | G3: Calib. | J3: Data Fail | L3: Data F | N3: Invalid | P3: Invalid
A4: Time Base: | B4: 15 Min | C4: Zero Referrence | G4: Z.Ref | J4: Warm Up | L4: Wm. Up
A7: Date & Time | B7: NO | C7: NO2 | D7: NOX | E7: SO2 | F7: O3 | G7: PM 10 | H7: PM 2.5 | I7: BENZ | J7: WS | K7: WD | L7: TEMP | M7: HUM | N7: SR | O7: RG | P7: CO | Q7: NH3
B8: ug/m3 | C8: ug/m3 | D8: ppb | E8: ug/m3 | F8: ug/m3 | G8: ug/m3 | H8: ug/m3 | I8: ug/m3 | J8: m/sec | K8: deg | L8: degreC | M8: % | N8: w/m2 | O8: mm | P8: mg/m3 | Q8: ug/m3
A106: Min | B106: =MIN(B9:B104) -> 0 | C106: =MIN(C9:C104) -> 0 | D106: =MIN(D9:D104) -> 0 | E106: =MIN(E9:E104) -> 0 | F106: =MIN(F9:F104) -> 0 | G106: =MIN(G9:G104) -> 0 | H106: =MIN(H9:H104) -> 0 | I106: =MIN(I9:I104) -> 0 | ... Q106: =MIN(Q9:Q104) -> 0
A107: Max | B107: =MAX(B9:B104) -> 0 | C107: =MAX(C9:C104) -> 0 | D107: =MAX(D9:D104) -> 0 | E107: =MAX(E9:E104) -> 0 | F107: =MAX(F9:F104) -> 0 | G107: =MAX(G9:G104) -> 0 | H107: =MAX(H9:H104) -> 0 | I107: =MAX(I9:I104) -> 0 | ... Q107: =MAX(Q9:Q104) -> 0
A108: Avg | B108: =AVERAGE(B9:B104) -> #DIV/0! | C108: =AVERAGE(C9:C104) -> #DIV/0! | D108: =AVERAGE(D9:D104) -> #DIV/0! | E108: =AVERAGE(E9:E104) -> #DIV/0! | F108: =AVERAGE(F9:F104) -> #DIV/0! | G108: =AVERAGE(G9:G104) -> #DIV/0! | H108: =AVERAGE(H9:H104) -> #DIV/0! | I108: =AVERAGE(I9:I104) -> #DIV/0! | ... Q108: =AVERAGE(Q9:Q104) -> #DIV/0!
A109: Stdev | B109: =STDEV(B9:B104) -> #DIV/0! | C109: =STDEV(C9:C104) -> #DIV/0! | D109: =STDEV(D9:D104) -> #DIV/0! | E109: =STDEV(E9:E104) -> #DIV/0! | F109: =STDEV(F9:F104) -> #DIV/0! | G109: =STDEV(G9:G104) -> #DIV/0! | H109: =STDEV(H9:H104) -> #DIV/0! | I109: =STDEV(I9:I104) -> #DIV/0! | ... Q109: =STDEV(Q9:Q104) -> #DIV/0!
A110: Num | B110: =COUNT(B9:B104) -> 0 | C110: =COUNT(C9:C104) -> 0 | D110: =COUNT(D9:D104) -> 0 | E110: =COUNT(E9:E104) -> 0 | F110: =COUNT(F9:F104) -> 0 | G110: =COUNT(G9:G104) -> 0 | H110: =COUNT(H9:H104) -> 0 | I110: =COUNT(I9:I104) -> 0 | ... Q110: =COUNT(Q9:Q104) -> 0
A111: DCR | B111: =IF(B110>=87,">90%",IF(B110<=87,"<90%")) -> <90% | C111: =IF(C110>=87,">90%",IF(C110<=87,"<90%")) -> <90% | D111: =IF(D110>=87,">90%",IF(D110<=87,"<90%")) -> <90% | E111: =IF(E110>=87,">90%",IF(E110<=87,"<90%")) -> <90% | F111: =IF(F110>=87,">90%",IF(F110<=87,"<90%")) -> <90% | G111: =IF(G110>=87,">90%",IF(G110<=87,"<90%")) -> <90% | H111: =IF(H110>=87,">90%",IF(H110<=87,"<90%")) -> <90% | I111: =IF(I110>=87,">90%",IF(I110<=87,"<90%")) -> <90% | ... Q111: =IF(Q110>=87,">90%",IF(Q110<=87,"<90%")) -> <90%
A112: Status | B112: =IF(B110>=87,"OK",IF(B110<=87,"LESS")) -> LESS | C112: =IF(C110>=87,"OK",IF(C110<=87,"LESS")) -> LESS | D112: =IF(D110>=87,"OK",IF(D110<=87,"LESS")) -> LESS | E112: =IF(E110>=87,"OK",IF(E110<=87,"LESS")) -> LESS | F112: =IF(F110>=87,"OK",IF(F110<=87,"LESS")) -> LESS | G112: =IF(G110>=87,"OK",IF(G110<=87,"LESS")) -> LESS | H112: =IF(H110>=87,"OK",IF(H110<=87,"LESS")) -> LESS | I112: =IF(I110>=87,"OK",IF(I110<=87,"LESS")) -> LESS | ... Q112: =IF(Q110>=87,"OK",IF(Q110<=87,"LESS")) -> LESS
A115: Done by | B115: AKASH
A117: Comment

Sheet 15
A1: Station: | B1: IGKV RAIPUR
A2: Date: | B2: =$A$9 -> 0 | C2: Power Off | G2: Pw.Off | J2: Link Fail | L2: Link F | N2: Maintenance | P2: Maint.
A3: Report Type: | B3: Mean | C3: Calibration | G3: Calib. | J3: Data Fail | L3: Data F | N3: Invalid | P3: Invalid
A4: Time Base: | B4: 15 Min | C4: Zero Referrence | G4: Z.Ref | J4: Warm Up | L4: Wm. Up
A7: Date & Time | B7: NO | C7: NO2 | D7: NOX | E7: SO2 | F7: O3 | G7: PM 10 | H7: PM 2.5 | I7: BENZ | J7: WS | K7: WD | L7: TEMP | M7: HUM | N7: SR | O7: RG | P7: CO | Q7: NH3
B8: ug/m3 | C8: ug/m3 | D8: ppb | E8: ug/m3 | F8: ug/m3 | G8: ug/m3 | H8: ug/m3 | I8: ug/m3 | J8: m/sec | K8: deg | L8: degreC | M8: % | N8: w/m2 | O8: mm | P8: mg/m3 | Q8: ug/m3
A106: Min | B106: =MIN(B9:B104) -> 0 | C106: =MIN(C9:C104) -> 0 | D106: =MIN(D9:D104) -> 0 | E106: =MIN(E9:E104) -> 0 | F106: =MIN(F9:F104) -> 0 | G106: =MIN(G9:G104) -> 0 | H106: =MIN(H9:H104) -> 0 | I106: =MIN(I9:I104) -> 0 | ... Q106: =MIN(Q9:Q104) -> 0
A107: Max | B107: =MAX(B9:B104) -> 0 | C107: =MAX(C9:C104) -> 0 | D107: =MAX(D9:D104) -> 0 | E107: =MAX(E9:E104) -> 0 | F107: =MAX(F9:F104) -> 0 | G107: =MAX(G9:G104) -> 0 | H107: =MAX(H9:H104) -> 0 | I107: =MAX(I9:I104) -> 0 | ... Q107: =MAX(Q9:Q104) -> 0
A108: Avg | B108: =AVERAGE(B9:B104) -> #DIV/0! | C108: =AVERAGE(C9:C104) -> #DIV/0! | D108: =AVERAGE(D9:D104) -> #DIV/0! | E108: =AVERAGE(E9:E104) -> #DIV/0! | F108: =AVERAGE(F9:F104) -> #DIV/0! | G108: =AVERAGE(G9:G104) -> #DIV/0! | H108: =AVERAGE(H9:H104) -> #DIV/0! | I108: =AVERAGE(I9:I104) -> #DIV/0! | ... Q108: =AVERAGE(Q9:Q104) -> #DIV/0!
A109: Stdev | B109: =STDEV(B9:B104) -> #DIV/0! | C109: =STDEV(C9:C104) -> #DIV/0! | D109: =STDEV(D9:D104) -> #DIV/0! | E109: =STDEV(E9:E104) -> #DIV/0! | F109: =STDEV(F9:F104) -> #DIV/0! | G109: =STDEV(G9:G104) -> #DIV/0! | H109: =STDEV(H9:H104) -> #DIV/0! | I109: =STDEV(I9:I104) -> #DIV/0! | ... Q109: =STDEV(Q9:Q104) -> #DIV/0!
A110: Num | B110: =COUNT(B9:B104) -> 0 | C110: =COUNT(C9:C104) -> 0 | D110: =COUNT(D9:D104) -> 0 | E110: =COUNT(E9:E104) -> 0 | F110: =COUNT(F9:F104) -> 0 | G110: =COUNT(G9:G104) -> 0 | H110: =COUNT(H9:H104) -> 0 | I110: =COUNT(I9:I104) -> 0 | ... Q110: =COUNT(Q9:Q104) -> 0
A111: DCR | B111: =IF(B110>=87,">90%",IF(B110<=87,"<90%")) -> <90% | C111: =IF(C110>=87,">90%",IF(C110<=87,"<90%")) -> <90% | D111: =IF(D110>=87,">90%",IF(D110<=87,"<90%")) -> <90% | E111: =IF(E110>=87,">90%",IF(E110<=87,"<90%")) -> <90% | F111: =IF(F110>=87,">90%",IF(F110<=87,"<90%")) -> <90% | G111: =IF(G110>=87,">90%",IF(G110<=87,"<90%")) -> <90% | H111: =IF(H110>=87,">90%",IF(H110<=87,"<90%")) -> <90% | I111: =IF(I110>=87,">90%",IF(I110<=87,"<90%")) -> <90% | ... Q111: =IF(Q110>=87,">90%",IF(Q110<=87,"<90%")) -> <90%
A112: Status | B112: =IF(B110>=87,"OK",IF(B110<=87,"LESS")) -> LESS | C112: =IF(C110>=87,"OK",IF(C110<=87,"LESS")) -> LESS | D112: =IF(D110>=87,"OK",IF(D110<=87,"LESS")) -> LESS | E112: =IF(E110>=87,"OK",IF(E110<=87,"LESS")) -> LESS | F112: =IF(F110>=87,"OK",IF(F110<=87,"LESS")) -> LESS | G112: =IF(G110>=87,"OK",IF(G110<=87,"LESS")) -> LESS | H112: =IF(H110>=87,"OK",IF(H110<=87,"LESS")) -> LESS | I112: =IF(I110>=87,"OK",IF(I110<=87,"LESS")) -> LESS | ... Q112: =IF(Q110>=87,"OK",IF(Q110<=87,"LESS")) -> LESS
A115: Done by | B115: AKASH
A117: Comment

Sheet 16
A1: Station: | B1: IGKV RAIPUR
A2: Date: | B2: =$A$9 -> 0 | C2: Power Off | G2: Pw.Off | J2: Link Fail | L2: Link F | N2: Maintenance | P2: Maint.
A3: Report Type: | B3: Mean | C3: Calibration | G3: Calib. | J3: Data Fail | L3: Data F | N3: Invalid | P3: Invalid
A4: Time Base: | B4: 15 Min | C4: Zero Referrence | G4: Z.Ref | J4: Warm Up | L4: Wm. Up
A7: Date & Time | B7: NO | C7: NO2 | D7: NOX | E7: SO2 | F7: O3 | G7: PM 10 | H7: PM 2.5 | I7: BENZ | J7: WS | K7: WD | L7: TEMP | M7: HUM | N7: SR | O7: RG | P7: CO | Q7: NH3
B8: ug/m3 | C8: ug/m3 | D8: ppb | E8: ug/m3 | F8: ug/m3 | G8: ug/m3 | H8: ug/m3 | I8: ug/m3 | J8: m/sec | K8: deg | L8: degreC | M8: % | N8: w/m2 | O8: mm | P8: mg/m3 | Q8: ug/m3
A106: Min | B106: =MIN(B9:B104) -> 0 | C106: =MIN(C9:C104) -> 0 | D106: =MIN(D9:D104) -> 0 | E106: =MIN(E9:E104) -> 0 | F106: =MIN(F9:F104) -> 0 | G106: =MIN(G9:G104) -> 0 | H106: =MIN(H9:H104) -> 0 | I106: =MIN(I9:I104) -> 0 | ... Q106: =MIN(Q9:Q104) -> 0
A107: Max | B107: =MAX(B9:B104) -> 0 | C107: =MAX(C9:C104) -> 0 | D107: =MAX(D9:D104) -> 0 | E107: =MAX(E9:E104) -> 0 | F107: =MAX(F9:F104) -> 0 | G107: =MAX(G9:G104) -> 0 | H107: =MAX(H9:H104) -> 0 | I107: =MAX(I9:I104) -> 0 | ... Q107: =MAX(Q9:Q104) -> 0
A108: Avg | B108: =AVERAGE(B9:B104) -> #DIV/0! | C108: =AVERAGE(C9:C104) -> #DIV/0! | D108: =AVERAGE(D9:D104) -> #DIV/0! | E108: =AVERAGE(E9:E104) -> #DIV/0! | F108: =AVERAGE(F9:F104) -> #DIV/0! | G108: =AVERAGE(G9:G104) -> #DIV/0! | H108: =AVERAGE(H9:H104) -> #DIV/0! | I108: =AVERAGE(I9:I104) -> #DIV/0! | ... Q108: =AVERAGE(Q9:Q104) -> #DIV/0!
A109: Stdev | B109: =STDEV(B9:B104) -> #DIV/0! | C109: =STDEV(C9:C104) -> #DIV/0! | D109: =STDEV(D9:D104) -> #DIV/0! | E109: =STDEV(E9:E104) -> #DIV/0! | F109: =STDEV(F9:F104) -> #DIV/0! | G109: =STDEV(G9:G104) -> #DIV/0! | H109: =STDEV(H9:H104) -> #DIV/0! | I109: =STDEV(I9:I104) -> #DIV/0! | ... Q109: =STDEV(Q9:Q104) -> #DIV/0!
A110: Num | B110: =COUNT(B9:B104) -> 0 | C110: =COUNT(C9:C104) -> 0 | D110: =COUNT(D9:D104) -> 0 | E110: =COUNT(E9:E104) -> 0 | F110: =COUNT(F9:F104) -> 0 | G110: =COUNT(G9:G104) -> 0 | H110: =COUNT(H9:H104) -> 0 | I110: =COUNT(I9:I104) -> 0 | ... Q110: =COUNT(Q9:Q104) -> 0
A111: DCR | B111: =IF(B110>=87,">90%",IF(B110<=87,"<90%")) -> <90% | C111: =IF(C110>=87,">90%",IF(C110<=87,"<90%")) -> <90% | D111: =IF(D110>=87,">90%",IF(D110<=87,"<90%")) -> <90% | E111: =IF(E110>=87,">90%",IF(E110<=87,"<90%")) -> <90% | F111: =IF(F110>=87,">90%",IF(F110<=87,"<90%")) -> <90% | G111: =IF(G110>=87,">90%",IF(G110<=87,"<90%")) -> <90% | H111: =IF(H110>=87,">90%",IF(H110<=87,"<90%")) -> <90% | I111: =IF(I110>=87,">90%",IF(I110<=87,"<90%")) -> <90% | ... Q111: =IF(Q110>=87,">90%",IF(Q110<=87,"<90%")) -> <90%
A112: Status | B112: =IF(B110>=87,"OK",IF(B110<=87,"LESS")) -> LESS | C112: =IF(C110>=87,"OK",IF(C110<=87,"LESS")) -> LESS | D112: =IF(D110>=87,"OK",IF(D110<=87,"LESS")) -> LESS | E112: =IF(E110>=87,"OK",IF(E110<=87,"LESS")) -> LESS | F112: =IF(F110>=87,"OK",IF(F110<=87,"LESS")) -> LESS | G112: =IF(G110>=87,"OK",IF(G110<=87,"LESS")) -> LESS | H112: =IF(H110>=87,"OK",IF(H110<=87,"LESS")) -> LESS | I112: =IF(I110>=87,"OK",IF(I110<=87,"LESS")) -> LESS | ... Q112: =IF(Q110>=87,"OK",IF(Q110<=87,"LESS")) -> LESS
A115: Done by | B115: AKASH
A117: Comment

Sheet 17
A1: Station: | B1: IGKV RAIPUR
A2: Date: | B2: =$A$9 -> 0 | C2: Power Off | G2: Pw.Off | J2: Link Fail | L2: Link F | N2: Maintenance | P2: Maint.
A3: Report Type: | B3: Mean | C3: Calibration | G3: Calib. | J3: Data Fail | L3: Data F | N3: Invalid | P3: Invalid
A4: Time Base: | B4: 15 Min | C4: Zero Referrence | G4: Z.Ref | J4: Warm Up | L4: Wm. Up
A7: Date & Time | B7: NO | C7: NO2 | D7: NOX | E7: SO2 | F7: O3 | G7: PM 10 | H7: PM 2.5 | I7: BENZ | J7: WS | K7: WD | L7: TEMP | M7: HUM | N7: SR | O7: RG | P7: CO | Q7: NH3
B8: ug/m3 | C8: ug/m3 | D8: ppb | E8: ug/m3 | F8: ug/m3 | G8: ug/m3 | H8: ug/m3 | I8: ug/m3 | J8: m/sec | K8: deg | L8: degreC | M8: % | N8: w/m2 | O8: mm | P8: mg/m3 | Q8: ug/m3
A106: Min | B106: =MIN(B9:B104) -> 0 | C106: =MIN(C9:C104) -> 0 | D106: =MIN(D9:D104) -> 0 | E106: =MIN(E9:E104) -> 0 | F106: =MIN(F9:F104) -> 0 | G106: =MIN(G9:G104) -> 0 | H106: =MIN(H9:H104) -> 0 | I106: =MIN(I9:I104) -> 0 | ... Q106: =MIN(Q9:Q104) -> 0
A107: Max | B107: =MAX(B9:B104) -> 0 | C107: =MAX(C9:C104) -> 0 | D107: =MAX(D9:D104) -> 0 | E107: =MAX(E9:E104) -> 0 | F107: =MAX(F9:F104) -> 0 | G107: =MAX(G9:G104) -> 0 | H107: =MAX(H9:H104) -> 0 | I107: =MAX(I9:I104) -> 0 | ... Q107: =MAX(Q9:Q104) -> 0
A108: Avg | B108: =AVERAGE(B9:B104) -> #DIV/0! | C108: =AVERAGE(C9:C104) -> #DIV/0! | D108: =AVERAGE(D9:D104) -> #DIV/0! | E108: =AVERAGE(E9:E104) -> #DIV/0! | F108: =AVERAGE(F9:F104) -> #DIV/0! | G108: =AVERAGE(G9:G104) -> #DIV/0! | H108: =AVERAGE(H9:H104) -> #DIV/0! | I108: =AVERAGE(I9:I104) -> #DIV/0! | ... Q108: =AVERAGE(Q9:Q104) -> #DIV/0!
A109: Stdev | B109: =STDEV(B9:B104) -> #DIV/0! | C109: =STDEV(C9:C104) -> #DIV/0! | D109: =STDEV(D9:D104) -> #DIV/0! | E109: =STDEV(E9:E104) -> #DIV/0! | F109: =STDEV(F9:F104) -> #DIV/0! | G109: =STDEV(G9:G104) -> #DIV/0! | H109: =STDEV(H9:H104) -> #DIV/0! | I109: =STDEV(I9:I104) -> #DIV/0! | ... Q109: =STDEV(Q9:Q104) -> #DIV/0!
A110: Num | B110: =COUNT(B9:B104) -> 0 | C110: =COUNT(C9:C104) -> 0 | D110: =COUNT(D9:D104) -> 0 | E110: =COUNT(E9:E104) -> 0 | F110: =COUNT(F9:F104) -> 0 | G110: =COUNT(G9:G104) -> 0 | H110: =COUNT(H9:H104) -> 0 | I110: =COUNT(I9:I104) -> 0 | ... Q110: =COUNT(Q9:Q104) -> 0
A111: DCR | B111: =IF(B110>=87,">90%",IF(B110<=87,"<90%")) -> <90% | C111: =IF(C110>=87,">90%",IF(C110<=87,"<90%")) -> <90% | D111: =IF(D110>=87,">90%",IF(D110<=87,"<90%")) -> <90% | E111: =IF(E110>=87,">90%",IF(E110<=87,"<90%")) -> <90% | F111: =IF(F110>=87,">90%",IF(F110<=87,"<90%")) -> <90% | G111: =IF(G110>=87,">90%",IF(G110<=87,"<90%")) -> <90% | H111: =IF(H110>=87,">90%",IF(H110<=87,"<90%")) -> <90% | I111: =IF(I110>=87,">90%",IF(I110<=87,"<90%")) -> <90% | ... Q111: =IF(Q110>=87,">90%",IF(Q110<=87,"<90%")) -> <90%
A112: Status | B112: =IF(B110>=87,"OK",IF(B110<=87,"LESS")) -> LESS | C112: =IF(C110>=87,"OK",IF(C110<=87,"LESS")) -> LESS | D112: =IF(D110>=87,"OK",IF(D110<=87,"LESS")) -> LESS | E112: =IF(E110>=87,"OK",IF(E110<=87,"LESS")) -> LESS | F112: =IF(F110>=87,"OK",IF(F110<=87,"LESS")) -> LESS | G112: =IF(G110>=87,"OK",IF(G110<=87,"LESS")) -> LESS | H112: =IF(H110>=87,"OK",IF(H110<=87,"LESS")) -> LESS | I112: =IF(I110>=87,"OK",IF(I110<=87,"LESS")) -> LESS | ... Q112: =IF(Q110>=87,"OK",IF(Q110<=87,"LESS")) -> LESS
A115: Done by | B115: AKASH
A117: Comment

Sheet 18
A1: Station: | B1: IGKV RAIPUR
A2: Date: | B2: =$A$9 -> 0 | C2: Power Off | G2: Pw.Off | J2: Link Fail | L2: Link F | N2: Maintenance | P2: Maint.
A3: Report Type: | B3: Mean | C3: Calibration | G3: Calib. | J3: Data Fail | L3: Data F | N3: Invalid | P3: Invalid
A4: Time Base: | B4: 15 Min | C4: Zero Referrence | G4: Z.Ref | J4: Warm Up | L4: Wm. Up
A7: Date & Time | B7: NO | C7: NO2 | D7: NOX | E7: SO2 | F7: O3 | G7: PM 10 | H7: PM 2.5 | I7: BENZ | J7: WS | K7: WD | L7: TEMP | M7: HUM | N7: SR | O7: RG | P7: CO | Q7: NH3
B8: ug/m3 | C8: ug/m3 | D8: ppb | E8: ug/m3 | F8: ug/m3 | G8: ug/m3 | H8: ug/m3 | I8: ug/m3 | J8: m/sec | K8: deg | L8: degreC | M8: % | N8: w/m2 | O8: mm | P8: mg/m3 | Q8: ug/m3
A106: Min | B106: =MIN(B9:B104) -> 0 | C106: =MIN(C9:C104) -> 0 | D106: =MIN(D9:D104) -> 0 | E106: =MIN(E9:E104) -> 0 | F106: =MIN(F9:F104) -> 0 | G106: =MIN(G9:G104) -> 0 | H106: =MIN(H9:H104) -> 0 | I106: =MIN(I9:I104) -> 0 | ... Q106: =MIN(Q9:Q104) -> 0
A107: Max | B107: =MAX(B9:B104) -> 0 | C107: =MAX(C9:C104) -> 0 | D107: =MAX(D9:D104) -> 0 | E107: =MAX(E9:E104) -> 0 | F107: =MAX(F9:F104) -> 0 | G107: =MAX(G9:G104) -> 0 | H107: =MAX(H9:H104) -> 0 | I107: =MAX(I9:I104) -> 0 | ... Q107: =MAX(Q9:Q104) -> 0
A108: Avg | B108: =AVERAGE(B9:B104) -> #DIV/0! | C108: =AVERAGE(C9:C104) -> #DIV/0! | D108: =AVERAGE(D9:D104) -> #DIV/0! | E108: =AVERAGE(E9:E104) -> #DIV/0! | F108: =AVERAGE(F9:F104) -> #DIV/0! | G108: =AVERAGE(G9:G104) -> #DIV/0! | H108: =AVERAGE(H9:H104) -> #DIV/0! | I108: =AVERAGE(I9:I104) -> #DIV/0! | ... Q108: =AVERAGE(Q9:Q104) -> #DIV/0!
A109: Stdev | B109: =STDEV(B9:B104) -> #DIV/0! | C109: =STDEV(C9:C104) -> #DIV/0! | D109: =STDEV(D9:D104) -> #DIV/0! | E109: =STDEV(E9:E104) -> #DIV/0! | F109: =STDEV(F9:F104) -> #DIV/0! | G109: =STDEV(G9:G104) -> #DIV/0! | H109: =STDEV(H9:H104) -> #DIV/0! | I109: =STDEV(I9:I104) -> #DIV/0! | ... Q109: =STDEV(Q9:Q104) -> #DIV/0!
A110: Num | B110: =COUNT(B9:B104) -> 0 | C110: =COUNT(C9:C104) -> 0 | D110: =COUNT(D9:D104) -> 0 | E110: =COUNT(E9:E104) -> 0 | F110: =COUNT(F9:F104) -> 0 | G110: =COUNT(G9:G104) -> 0 | H110: =COUNT(H9:H104) -> 0 | I110: =COUNT(I9:I104) -> 0 | ... Q110: =COUNT(Q9:Q104) -> 0
A111: DCR | B111: =IF(B110>=87,">90%",IF(B110<=87,"<90%")) -> <90% | C111: =IF(C110>=87,">90%",IF(C110<=87,"<90%")) -> <90% | D111: =IF(D110>=87,">90%",IF(D110<=87,"<90%")) -> <90% | E111: =IF(E110>=87,">90%",IF(E110<=87,"<90%")) -> <90% | F111: =IF(F110>=87,">90%",IF(F110<=87,"<90%")) -> <90% | G111: =IF(G110>=87,">90%",IF(G110<=87,"<90%")) -> <90% | H111: =IF(H110>=87,">90%",IF(H110<=87,"<90%")) -> <90% | I111: =IF(I110>=87,">90%",IF(I110<=87,"<90%")) -> <90% | ... Q111: =IF(Q110>=87,">90%",IF(Q110<=87,"<90%")) -> <90%
A112: Status | B112: =IF(B110>=87,"OK",IF(B110<=87,"LESS")) -> LESS | C112: =IF(C110>=87,"OK",IF(C110<=87,"LESS")) -> LESS | D112: =IF(D110>=87,"OK",IF(D110<=87,"LESS")) -> LESS | E112: =IF(E110>=87,"OK",IF(E110<=87,"LESS")) -> LESS | F112: =IF(F110>=87,"OK",IF(F110<=87,"LESS")) -> LESS | G112: =IF(G110>=87,"OK",IF(G110<=87,"LESS")) -> LESS | H112: =IF(H110>=87,"OK",IF(H110<=87,"LESS")) -> LESS | I112: =IF(I110>=87,"OK",IF(I110<=87,"LESS")) -> LESS | ... Q112: =IF(Q110>=87,"OK",IF(Q110<=87,"LESS")) -> LESS
A115: Done by | B115: AKASH
A117: Comment

Sheet 19
A1: Station: | B1: IGKV RAIPUR
A2: Date: | B2: =$A$9 -> 0 | C2: Power Off | G2: Pw.Off | J2: Link Fail | L2: Link F | N2: Maintenance | P2: Maint.
A3: Report Type: | B3: Mean | C3: Calibration | G3: Calib. | J3: Data Fail | L3: Data F | N3: Invalid | P3: Invalid
A4: Time Base: | B4: 15 Min | C4: Zero Referrence | G4: Z.Ref | J4: Warm Up | L4: Wm. Up
A7: Date & Time | B7: NO | C7: NO2 | D7: NOX | E7: SO2 | F7: O3 | G7: PM 10 | H7: PM 2.5 | I7: BENZ | J7: WS | K7: WD | L7: TEMP | M7: HUM | N7: SR | O7: RG | P7: CO | Q7: NH3
B8: ug/m3 | C8: ug/m3 | D8: ppb | E8: ug/m3 | F8: ug/m3 | G8: ug/m3 | H8: ug/m3 | I8: ug/m3 | J8: m/sec | K8: deg | L8: degreC | M8: % | N8: w/m2 | O8: mm | P8: mg/m3 | Q8: ug/m3
A106: Min | B106: =MIN(B9:B104) -> 0 | C106: =MIN(C9:C104) -> 0 | D106: =MIN(D9:D104) -> 0 | E106: =MIN(E9:E104) -> 0 | F106: =MIN(F9:F104) -> 0 | G106: =MIN(G9:G104) -> 0 | H106: =MIN(H9:H104) -> 0 | I106: =MIN(I9:I104) -> 0 | ... Q106: =MIN(Q9:Q104) -> 0
