Workbook

Sheet 01
A1: Station: | B1: BHATAGAON ,RAIPUR
A2: Date: | B2: =$A$9 -> 01-06-2024 01:00 | D2: Power Off | G2: Pw.Off | L2: Link Fail | N2: Link F | P2: Maintenance | R2: Maint.
A3: Report Type: | B3: Mean | D3: Calibration | G3: Calib. | L3: Data Fail | N3: Data F | P3: Invalid | R3: Invalid
A4: Time Base: | B4: 01 Hour | D4: Zero Referrence | G4: Z.Ref | L4: Warm Up | N4: Wm. Up
A7: Date & Time | B7: NO_BHATAGAON | C7: NO2_BHATAGAON | D7: NOX_BHATAGAON | E7: SO2_BHATAGAON | F7: O3_BHATAGAON | G7: PM10_BHATAGAON | H7: PM2_5_BHATAGAON | I7: BENZ_BHATAGAON | J7: WS_BHATAGAON | K7: WD_BHATAGAON | L7: TEMP_BHATAGAON | M7: HUM BHATAGAON | N7: SR_BHATAGAON | O7: RG_BHATAGAON | P7: CO_BHATAGAON | Q7: NH3_BHATAGAON
B8: ug/m3 | C8: ug/m3 | D8: ppb | E8: ug/m3 | F8: ug/m3 | G8: mg/m3 | H8: ug/m3 | I8: ug/m3 | J8: m/sec | K8: deg | L8: degreC | M8: % | N8: w/m2 | O8: mm | P8: ug/m3 | Q8: ug/m3
A9: 01-06-2024 01:00 | B9: 4.36 | C9: 6.72 | D9: 8.16 | E9: 1.25 | F9: 3.5 | G9: 88.56 | H9: 33.82 | I9: 12.8 | J9: 0.58 | K9: 337.09 | L9: 32.19 | M9: 32.37 | N9: 11.6 | O9: 0 | P9: 0.98 | Q9: 10.47
A10: 01-06-2024 02:00 | B10: 3.98 | C10: 5.8 | D10: 7.37 | E10: 1.28 | F10: 3.66 | G10: 87.79 | H10: 30.27 | I10: 11.55 | J10: 1.07 | K10: 327.29 | L10: 31.88 | M10: 31.78 | N10: 11.4 | O10: 0 | P10: 0.91 | Q10: 10.19
A11: 01-06-2024 03:00 | B11: 3.17 | C11: 3.13 | D11: 5.32 | E11: 1.29 | F11: 3.81 | G11: 87.79 | H11: 32.01 | I11: 12.92 | J11: 1.32 | K11: 357.4 | L11: 32.43 | M11: 29.07 | N11: 11.9 | O11: 0 | P11: 0.86 | Q11: 10.09
A12: 01-06-2024 04:00 | B12: 3.67 | C12: 5.03 | D12: 6.72 | E12: 1.61 | F12: 3.99 | G12: 91.36 | H12: 34.18 | I12: 12.05 | J12: 0.64 | K12: 316.23 | L12: 31.26 | M12: 36.29 | N12: 12.1 | O12: 0 | P12: 0.77 | Q12: 10.21
A13: 01-06-2024 05:00 | B13: 4.06 | C13: 5.06 | D13: 7.05 | E13: 1.32 | F13: 3.58 | G13: 95.47 | H13: 35.2 | I13: 11.92 | J13: 0.57 | K13: 317.17 | L13: 30.27 | M13: 43.65 | N13: 11.9 | O13: 0 | P13: 0.66 | Q13: 10.26
A14: 01-06-2024 06:00 | B14: 4.68 | C14: 5.46 | D14: 7.59 | E14: 1.58 | F14: 3.69 | G14: 95.47 | H14: 35.2 | I14: 10.18 | J14: 0.71 | K14: 354.94 | L14: 28.59 | M14: 46.73 | N14: 54.8 | O14: 0 | P14: 0.7 | Q14: 10.36
A15: 01-06-2024 07:00 | B15: 6.45 | C15: 8.2 | D15: 10.61 | E15: 1.64 | F15: 3.51 | G15: 100.39 | H15: 38.53 | I15: 9.41 | J15: 1.14 | K15: 345.69 | L15: 33.59 | M15: 44.33 | N15: 215.1 | O15: 0 | P15: 0.72 | Q15: 10.47
A16: 01-06-2024 08:00 | B16: 6.08 | C16: 7.48 | D16: 9.93 | E16: 1.9 | F16: 4.01 | G16: 100.39 | H16: 38.53 | I16: 10.17 | J16: 1.24 | K16: 329.61 | L16: 36.96 | M16: 29.06 | N16: 411.7 | O16: 0 | P16: 0.7 | Q16: 10.5
A17: 01-06-2024 09:00 | B17: 3.87 | C17: 4.16 | D17: 6.42 | E17: 1.75 | F17: 4.26 | G17: 99.63 | H17: 38.36 | I17: 9.78 | J17: 1.35 | K17: 348.69 | L17: 40.25 | M17: 27.7 | N17: 579.8 | O17: 0 | P17: 0.71 | Q17: 10.44
A18: 01-06-2024 10:00 | B18: 2.75 | C18: 2.81 | D18: 4.81 | E18: 1.79 | F18: 5.55 | G18: 105.72 | H18: 43.04 | I18: 8.56 | J18: 2.54 | K18: 350.15 | L18: 41.8 | M18: 25.39 | N18: 698.3 | O18: 0 | P18: 0.8 | Q18: 10.26
A19: 01-06-2024 11:00 | B19: 2.63 | C19: 2.64 | D19: 4.63 | E19: 1.81 | F19: 6.13 | G19: 107.43 | H19: 43.38 | I19: 8.29 | J19: 2.09 | K19: 341.83 | L19: 43.04 | M19: 24.8 | N19: 771.4 | O19: 0 | P19: 0.78 | Q19: 10.03
A20: 01-06-2024 12:00 | B20: 2.61 | C20: 2.92 | D20: 4.76 | E20: 2 | F20: 6.46 | G20: 107.43 | H20: 43.38 | I20: 7.65 | J20: 1.61 | K20: 339.79 | L20: 43.36 | M20: 23.86 | N20: 790.7 | O20: 0 | P20: 0.76 | Q20: 9.7
... A32: 01-06-2024 24:00 | B32: 3.94 | C32: 8.21 | D32: 8.59 | E32: 1.94 | F32: 4.17 | G32: 82.3 | H32: 30.13 | I32: 13.62 | J32: 1.86 | K32: 168.68 | L32: 32.38 | M32: 38.51 | N32: 11.7 | O32: 0 | P32: 0.83 | Q32: 10.21
A34: Min | B34: =MIN(B9:B32) -> 2.57 | C34: =MIN(C9:C32) -> 2.17 | D34: =MIN(D9:D32) -> 4.35 | E34: =MIN(E9:E32) -> 0.76 | F34: =MIN(F9:F32) -> 3.5 | G34: =MIN(G9:G32) -> 46.71 | H34: =MIN(H9:H32) -> 19.61 | I34: =MIN(I9:I32) -> 4.62 | ... Q34: =MIN(Q9:Q32) -> 9.56
A35: Max | B35: =MAX(B9:B32) -> 6.45 | C35: =MAX(C9:C32) -> 9.69 | D35: =MAX(D9:D32) -> 10.69 | E35: =MAX(E9:E32) -> 2.06 | F35: =MAX(F9:F32) -> 6.6 | G35: =MAX(G9:G32) -> 107.43 | H35: =MAX(H9:H32) -> 43.38 | I35: =MAX(I9:I32) -> 14.4 | ... Q35: =MAX(Q9:Q32) -> 10.52
A36: Avg | B36: =AVERAGE(B9:B32) -> 3.6829167 | C36: =AVERAGE(C9:C32) -> 4.7104167 | D36: =AVERAGE(D9:D32) -> 6.5454167 | E36: =AVERAGE(E9:E32) -> 1.4966667 | F36: =AVERAGE(F9:F32) -> 4.6658333 | G36: =AVERAGE(G9:G32) -> 84.398333 | H36: =AVERAGE(H9:H32) -> 32.490417 | I36: =AVERAGE(I9:I32) -> 9.4125 | ... Q36: =AVERAGE(Q9:Q32) -> 10.082083
A37: Stdev | B37: =STDEV(B9:B32) -> 1.2178366 | C37: =STDEV(C9:C32) -> 2.4638755 | D37: =STDEV(D9:D32) -> 2.1991698 | E37: =STDEV(E9:E32) -> 0.42415816 | F37: =STDEV(F9:F32) -> 1.1155459 | G37: =STDEV(G9:G32) -> 20.560187 | H37: =STDEV(H9:H32) -> 7.1628902 | I37: =STDEV(I9:I32) -> 2.9237576 | ... Q37: =STDEV(Q9:Q32) -> 0.31696906
A38: Num | B38: =COUNT(B9:B32) -> 24 | C38: =COUNT(C9:C32) -> 24 | D38: =COUNT(D9:D32) -> 24 | E38: =COUNT(E9:E32) -> 24 | F38: =COUNT(F9:F32) -> 24 | G38: =COUNT(G9:G32) -> 24 | H38: =COUNT(H9:H32) -> 24 | I38: =COUNT(I9:I32) -> 24 | ... M38: =COUNT(M9:M32) -> 24 | N38: =COUNT(N9:N32)+12 -> 36 | O38: =COUNT(O9:O32) -> 24 | P38: =COUNT(P9:P32) -> 24 | Q38: =COUNT(Q9:Q32) -> 24
A39: DCR | B39: =IF(B38>=22,">90%",IF(B38<=22,"<90%")) -> >90% | C39: =IF(C38>=22,">90%",IF(C38<=22,"<90%")) -> >90% | D39: =IF(D38>=22,">90%",IF(D38<=22,"<90%")) -> >90% | E39: =IF(E38>=22,">90%",IF(E38<=22,"<90%")) -> >90% | F39: =IF(F38>=22,">90%",IF(F38<=22,"<90%")) -> >90% | G39: =IF(G38>=22,">90%",IF(G38<=22,"<90%")) -> >90% | H39: =IF(H38>=22,">90%",IF(H38<=22,"<90%")) -> >90% | I39: =IF(I38>=22,">90%",IF(I38<=22,"<90%")) -> >90% | ... Q39: =IF(Q38>=22,">90%",IF(Q38<=22,"<90%")) -> >90%
A40: Status | B40: =IF(B38>=22,"OK",IF(B38<=22,"LESS")) -> OK | C40: =IF(C38>=22,"OK",IF(C38<=22,"LESS")) -> OK | D40: =IF(D38>=22,"OK",IF(D38<=22,"LESS")) -> OK | E40: =IF(E38>=22,"OK",IF(E38<=22,"LESS")) -> OK | F40: =IF(F38>=22,"OK",IF(F38<=22,"LESS")) -> OK | G40: =IF(G38>=22,"OK",IF(G38<=22,"LESS")) -> OK | H40: =IF(H38>=22,"OK",IF(H38<=22,"LESS")) -> OK | I40: =IF(I38>=22,"OK",IF(I38<=22,"LESS")) -> OK | ... Q40: =IF(Q38>=22,"OK",IF(Q38<=22,"LESS")) -> OK
A43: Done by | B43: RAHUL
A45: Comment

Sheet 02
A1: Station: | B1: BHATAGAON RAIPUR
A2: Date: | B2: =$A$9 -> 02-06-2024 01:00 | D2: Power Off | G2: Pw.Off | L2: Link Fail | N2: Link F | P2: Maintenance | R2: Maint.
A3: Report Type: | B3: Mean | D3: Calibration | G3: Calib. | L3: Data Fail | N3: Data F | P3: Invalid | R3: Invalid
A4: Time Base: | B4: 01 Hour | D4: Zero Referrence | G4: Z.Ref | L4: Warm Up | N4: Wm. Up
A7: Date & Time | B7: NO_BHATAGAON | C7: NO2_BHATAGAON | D7: NOX_BHATAGAON | E7: SO2_BHATAGAON | F7: O3_BHATAGAON | G7: PM10_BHATAGAON | H7: PM2_5_BHATAGAON | I7: BENZ_BHATAGAON | J7: WS_BHATAGAON | K7: WD_BHATAGAON | L7: TEMP_BHATAGAON | M7: HUM BHATAGAON | N7: SR_BHATAGAON | O7: RG_BHATAGAON | P7: CO_BHATAGAON | Q7: NH3_BHATAGAON
B8: ug/m3 | C8: ug/m3 | D8: ppb | E8: ug/m3 | F8: ug/m3 | G8: mg/m3 | H8: ug/m3 | I8: ug/m3 | J8: m/sec | K8: deg | L8: degreC | M8: % | N8: w/m2 | O8: mm | P8: ug/m3 | Q8: ug/m3
A9: 02-06-2024 01:00 | B9: 3.23 | C9: 6.51 | D9: 7.14 | E9: 1.77 | F9: 4.2 | G9: 55.15 | H9: 24.84 | I9: 12.72 | J9: 1.19 | K9: 158.42 | L9: 31.46 | M9: 43.43 | N9: 11.9 | O9: 0 | P9: 0.65 | Q9: 9.9
A10: 02-06-2024 02:00 | B10: 3.14 | C10: 4.98 | D10: 6.23 | E10: 2.33 | F10: 4.05 | G10: 48.96 | H10: 22.19 | I10: 9.3 | J10: 0.94 | K10: 166.43 | L10: 30.84 | M10: 48.67 | N10: 11.7 | O10: 0 | P10: 0.56 | Q10: 9.82
A11: 02-06-2024 03:00 | B11: 3.23 | C11: 5.05 | D11: 6.36 | E11: 2.4 | F11: 4.49 | G11: 43.21 | H11: 21.24 | I11: 9.37 | J11: 0.97 | K11: 170.03 | L11: 30.25 | M11: 53.83 | N11: 11.9 | O11: 0 | P11: 0.52 | Q11: 9.87
A12: 02-06-2024 04:00 | B12: 3.2 | C12: 4.89 | D12: 6.27 | E12: 2.01 | F12: 4.15 | G12: 41.58 | H12: 20.24 | I12: 9.29 | J12: 1.18 | K12: 165.26 | L12: 29.56 | M12: 58.57 | N12: 11.9 | O12: 0 | P12: 0.46 | Q12: 9.78
A13: 02-06-2024 05:00 | B13: 3.2 | C13: 4.92 | D13: 6.25 | E13: 1.46 | F13: 4.16 | G13: 41.58 | H13: 17.66 | I13: 8.46 | J13: 1.25 | K13: 179.64 | L13: 29.2 | M13: 60.56 | N13: 11.6 | O13: 0 | P13: 0.4 | Q13: 9.72
A14: 02-06-2024 06:00 | B14: 3.34 | C14: 4.54 | D14: 6.19 | E14: 1.55 | F14: 4.24 | G14: 39.29 | H14: 15.73 | I14: 7.22 | J14: 1.66 | K14: 159.83 | L14: 29.03 | M14: 62.68 | N14: 53.6 | O14: 0 | P14: 0.38 | Q14: 9.59
A15: 02-06-2024 07:00 | B15: 3.45 | C15: 5.35 | D15: 6.7 | E15: 1.58 | F15: 4.26 | G15: 39.29 | H15: 16.53 | I15: 6.9 | J15: 0.45 | K15: 354.57 | L15: 30.92 | M15: 60.75 | N15: 196.3 | O15: 0 | P15: 0.4 | Q15: 9.71
A16: 02-06-2024 08:00 | B16: 3.45 | C16: 5.34 | D16: 6.7 | E16: 3.32 | F16: 4.38 | G16: 53.57 | H16: 17.4 | I16: 7.56 | J16: 0.81 | K16: 177.66 | L16: 32.1 | M16: 51.59 | N16: 373.3 | O16: 0 | P16: 0.44 | Q16: 9.73
A17: 02-06-2024 09:00 | B17: 3.14 | C17: 5.24 | D17: 6.37 | E17: 2.61 | F17: 6.11 | G17: 53.91 | H17: 18 | I17: 6.75 | J17: 0.54 | K17: 350.44 | L17: 34.61 | M17: 44.31 | N17: 527 | O17: 0 | P17: 0.48 | Q17: 9.66
A18: 02-06-2024 10:00 | B18: 2.96 | C18: 4.81 | D18: 6.03 | E18: 2.45 | F18: 8.19 | G18: 59.72 | H18: 21.61 | I18: 6.48 | J18: 0.54 | K18: 357.99 | L18: 36.41 | M18: 42.45 | N18: 702.1 | O18: 0 | P18: 0.49 | Q18: 9.57
A19: 02-06-2024 11:00 | B19: 2.89 | C19: 4.14 | D19: 5.63 | E19: 2.56 | F19: 9.49 | G19: 60.94 | H19: 23.29 | I19: 6.1 | J19: 0.91 | K19: 345.37 | L19: 38.22 | M19: 38.52 | N19: 743.7 | O19: 0 | P19: 0.48 | Q19: 9.46
A20: 02-06-2024 12:00 | B20: 2.92 | C20: 5.14 | D20: 6.17 | E20: 2.62 | F20: 9.09 | G20: 61.04 | H20: 26.41 | I20: 4.63 | J20: 1.32 | K20: 339.49 | L20: 40.91 | M20: 32.58 | N20: 769.7 | O20: 0 | P20: 0.54 | Q20: 9.6
... A32: 02-06-2024 24:00 | B32: 2.83 | C32: 3.09 | D32: 5.03 | E32: 0.98 | F32: 4.37 | G32: 45.44 | H32: 19.69 | I32: 8.67 | J32: 3.35 | K32: 108.14 | L32: 28.56 | M32: 65.91 | N32: 13.4 | O32: 0 | P32: 0.4 | Q32: 9.45
A34: Min | B34: =MIN(B9:B32) -> 2.77 | C34: =MIN(C9:C32) -> 3.09 | D34: =MIN(D9:D32) -> 5.03 | E34: =MIN(E9:E32) -> 0.71 | F34: =MIN(F9:F32) -> 4.05 | G34: =MIN(G9:G32) -> 39.29 | H34: =MIN(H9:H32) -> 15.73 | I34: =MIN(I9:I32) -> 4.19 | ... Q34: =MIN(Q9:Q32) -> 9.36
A35: Max | B35: =MAX(B9:B32) -> 3.45 | C35: =MAX(C9:C32) -> 6.51 | D35: =MAX(D9:D32) -> 7.14 | E35: =MAX(E9:E32) -> 3.32 | F35: =MAX(F9:F32) -> 12.05 | G35: =MAX(G9:G32) -> 89.79 | H35: =MAX(H9:H32) -> 29.34 | I35: =MAX(I9:I32) -> 12.72 | ... Q35: =MAX(Q9:Q32) -> 9.9
A36: Avg | B36: =AVERAGE(B9:B32) -> 3.0420833 | C36: =AVERAGE(C9:C32) -> 4.6416667 | D36: =AVERAGE(D9:D32) -> 6.0033333 | E36: =AVERAGE(E9:E32) -> 1.7070833 | F36: =AVERAGE(F9:F32) -> 5.9020833 | G36: =AVERAGE(G9:G32) -> 58.43875 | H36: =AVERAGE(H9:H32) -> 22.969583 | I36: =AVERAGE(I9:I32) -> 7.4179167 | ... Q36: =AVERAGE(Q9:Q32) -> 9.6175
A37: Stdev | B37: =STDEV(B9:B32) -> 0.19666743 | C37: =STDEV(C9:C32) -> 0.73459049 | D37: =STDEV(D9:D32) -> 0.49980576 | E37: =STDEV(E9:E32) -> 0.67864622 | F37: =STDEV(F9:F32) -> 2.2323257 | G37: =STDEV(G9:G32) -> 15.07785 | H37: =STDEV(H9:H32) -> 4.1094245 | I37: =STDEV(I9:I32) -> 2.0432816 | ... Q37: =STDEV(Q9:Q32) -> 0.13869736
A38: Num | B38: =COUNT(B9:B32) -> 24 | C38: =COUNT(C9:C32) -> 24 | D38: =COUNT(D9:D32) -> 24 | E38: =COUNT(E9:E32) -> 24 | F38: =COUNT(F9:F32) -> 24 | G38: =COUNT(G9:G32) -> 24 | H38: =COUNT(H9:H32) -> 24 | I38: =COUNT(I9:I32) -> 24 | ... Q38: =COUNT(Q9:Q32) -> 24
A39: DCR | B39: =IF(B38>=22,">90%",IF(B38<=22,"<90%")) -> >90% | C39: =IF(C38>=22,">90%",IF(C38<=22,"<90%")) -> >90% | D39: =IF(D38>=22,">90%",IF(D38<=22,"<90%")) -> >90% | E39: =IF(E38>=22,">90%",IF(E38<=22,"<90%")) -> >90% | F39: =IF(F38>=22,">90%",IF(F38<=22,"<90%")) -> >90% | G39: =IF(G38>=22,">90%",IF(G38<=22,"<90%")) -> >90% | H39: =IF(H38>=22,">90%",IF(H38<=22,"<90%")) -> >90% | I39: =IF(I38>=22,">90%",IF(I38<=22,"<90%")) -> >90% | ... Q39: =IF(Q38>=22,">90%",IF(Q38<=22,"<90%")) -> >90%
A40: Status | B40: =IF(B38>=22,"OK",IF(B38<=22,"LESS")) -> OK | C40: =IF(C38>=22,"OK",IF(C38<=22,"LESS")) -> OK | D40: =IF(D38>=22,"OK",IF(D38<=22,"LESS")) -> OK | E40: =IF(E38>=22,"OK",IF(E38<=22,"LESS")) -> OK | F40: =IF(F38>=22,"OK",IF(F38<=22,"LESS")) -> OK | G40: =IF(G38>=22,"OK",IF(G38<=22,"LESS")) -> OK | H40: =IF(H38>=22,"OK",IF(H38<=22,"LESS")) -> OK | I40: =IF(I38>=22,"OK",IF(I38<=22,"LESS")) -> OK | ... Q40: =IF(Q38>=22,"OK",IF(Q38<=22,"LESS")) -> OK
A43: Done by | B43: RAHUL
A45: Comment

Sheet 03
A1: Station: | B1: BHATAGAON RAIPUR
A2: Date: | B2: =$A$9 -> 03-06-2024 01:00 | D2: Power Off | G2: Pw.Off | L2: Link Fail | N2: Link F | P2: Maintenance | R2: Maint.
A3: Report Type: | B3: Mean | D3: Calibration | G3: Calib. | L3: Data Fail | N3: Data F | P3: Invalid | R3: Invalid
A4: Time Base: | B4: 01 Hour | D4: Zero Referrence | G4: Z.Ref | L4: Warm Up | N4: Wm. Up
A7: Date & Time | B7: NO_BHATAGAON | C7: NO2_BHATAGAON | D7: NOX_BHATAGAON | E7: SO2_BHATAGAON | F7: O3_BHATAGAON | G7: PM10_BHATAGAON | H7: PM2_5_BHATAGAON | I7: BENZ_BHATAGAON | J7: WS_BHATAGAON | K7: WD_BHATAGAON | L7: TEMP_BHATAGAON | M7: HUM BHATAGAON | N7: SR_BHATAGAON | O7: RG_BHATAGAON | P7: CO_BHATAGAON | Q7: NH3_BHATAGAON
B8: ug/m3 | C8: ug/m3 | D8: ppb | E8: ug/m3 | F8: ug/m3 | G8: mg/m3 | H8: ug/m3 | I8: ug/m3 | J8: m/sec | K8: deg | L8: degreC | M8: % | N8: w/m2 | O8: mm | P8: ug/m3 | Q8: ug/m3
A9: 03-06-2024 01:00 | B9: 2.8 | C9: 2.47 | D9: 4.68 | E9: 0.85 | F9: 4.22 | G9: 39.24 | H9: 18.41 | I9: 9.06 | J9: 2.99 | K9: 109.15 | L9: 26.5 | M9: 73.57 | N9: 13.1 | O9: 0 | P9: 0.36 | Q9: 9.49
A10: 03-06-2024 02:00 | B10: 2.81 | C10: 2.53 | D10: 4.72 | E10: 0.94 | F10: 4.42 | G10: 34.98 | H10: 17.03 | I10: 8.98 | J10: 2.46 | K10: 102.44 | L10: 26.1 | M10: 70.86 | N10: 12.5 | O10: 0 | P10: 0.36 | Q10: 9.55
A11: 03-06-2024 03:00 | B11: 2.85 | C11: 2.53 | D11: 4.76 | E11: 0.64 | F11: 4.95 | G11: 27.01 | H11: 15.16 | I11: 8.17 | J11: 2.44 | K11: 156.9 | L11: 26.59 | M11: 68.52 | N11: 12 | O11: 0 | P11: 0.34 | Q11: 9.52
A12: 03-06-2024 04:00 | B12: 2.85 | C12: 2.82 | D12: 4.91 | E12: 1.12 | F12: 5.34 | G12: 23.63 | H12: 13.75 | I12: 7.2 | J12: 2.47 | K12: 166.05 | L12: 26.79 | M12: 59.43 | N12: 12.1 | O12: 0 | P12: 0.31 | Q12: 9.49
A13: 03-06-2024 05:00 | B13: 2.77 | C13: 2.07 | D13: 4.45 | E13: 1.08 | F13: 4.45 | G13: 20.55 | H13: 11.94 | I13: 6.47 | J13: 2.47 | K13: 212.77 | L13: 26.97 | M13: 59.87 | N13: 12.1 | O13: 0 | P13: 0.28 | Q13: 9.41
A14: 03-06-2024 06:00 | B14: 2.82 | C14: 2.69 | D14: 4.81 | E14: 1.11 | F14: 5.27 | G14: 19.05 | H14: 9.26 | I14: 6.3 | J14: 0.76 | K14: 218.02 | L14: 26.97 | M14: 61.3 | N14: 55 | O14: 0 | P14: 0.26 | Q14: 9.46
A15: 03-06-2024 07:00 | B15: 2.71 | C15: 2.13 | D15: 4.43 | E15: 1.11 | F15: 5.52 | G15: 20.87 | H15: 9.26 | I15: 5.27 | J15: 0.82 | K15: 229.88 | L15: 27.56 | M15: 61.31 | N15: 187.4 | O15: 0 | P15: 0.26 | Q15: 9.48
A16: 03-06-2024 08:00 | B16: 2.67 | C16: 1.65 | D16: 4.15 | E16: 1.76 | F16: 5.91 | G16: 22.75 | H16: 11.06 | I16: 4.2 | J16: 0.69 | K16: 206.54 | L16: 28.84 | M16: 58.36 | N16: 402.6 | O16: 0 | P16: 0.27 | Q16: 9.48
A17: 03-06-2024 09:00 | B17: 2.58 | C17: 1.24 | D17: 3.86 | E17: 1.79 | F17: 9.62 | G17: 23.66 | H17: 11.29 | I17: 3.58 | J17: 0.56 | K17: 330.52 | L17: 30.2 | M17: 52.21 | N17: 550.7 | O17: 0 | P17: 0.28 | Q17: 9.39
A18: 03-06-2024 10:00 | B18: 2.58 | C18: 1.24 | D18: 3.86 | E18: 2.23 | F18: 11.92 | G18: 28.74 | H18: 11.29 | I18: 2.43 | J18: 0.76 | K18: 21.86 | L18: 31.98 | M18: 48.69 | N18: 730.6 | O18: 0 | P18: 0.31 | Q18: 9.37
A19: 03-06-2024 11:00 | B19: 2.54 | C19: 1.34 | D19: 3.89 | E19: 2.33 | F19: 14.31 | G19: 28.74 | H19: 11.28 | I19: 1.84 | J19: 0.83 | K19: 340.06 | L19: 34.08 | M19: 42.93 | N19: 852.3 | O19: 0 | P19: 0.34 | Q19: 9.47
A20: 03-06-2024 12:00 | B20: 2.63 | C20: 1.56 | D20: 4.07 | E20: Calib. | F20: 16.59 | G20: Calib. | H20: Calib. | I20: 3.28 | J20: 0.96 | K20: 328.25 | L20: 35.6 | M20: 38.77 | N20: 844.6 | O20: 0 | P20: 0.35 | Q20: 9.42
A21: 03-06-2024 13:00 | B21: 2.81 | C21: 0.96 | D21: 3.68 | E21: 2.96 | F21: 12.94 | G21: 74.14 | H21: 7.71 | I21: 7.7 | J21: 0.82 | K21: 357.12 | L21: 35.87 | M21: 35.02 | N21: 703.4 | O21: 0 | P21: 0.37 | Q21: 9.3
A22: 03-06-2024 14:00 | B22: 2.47 | C22: 1.1 | D22: 3.48 | E22: 3.99 | F22: 18.54 | G22: 74.14 | H22: 9.98 | I22: 9.85 | J22: 0.75 | K22: 352.58 | L22: 36.25 | M22: 33.64 | N22: 737.1 | O22: 0 | P22: 0.43 | Q22: 9.33
A23: 03-06-2024 15:00 | B23: 2.59 | C23: 1.66 | D23: 4.16 | E23: 3.13 | F23: 12.62 | G23: 57.14 | H23: 16.9 | I23: 7.64 | J23: 1.22 | K23: 348.95 | L23: 37.6 | M23: 31.04 | N23: 587.2 | O23: 0 | P23: 0.49 | Q23: 9.42
A24: 03-06-2024 16:00 | B24: 2.54 | C24: 1.31 | D24: 3.76 | E24: 3.07 | F24: 11.69 | G24: 57.14 | H24: 16.9 | I24: 5.94 | J24: 0.99 | K24: 359.48 | L24: 36.73 | M24: 31.32 | N24: 342.1 | O24: 0 | P24: 0.46 | Q24: 9.39
A25: 03-06-2024 17:00 | B25: 2.47 | C25: 0.96 | D25: 3.34 | E25: 0.66 | F25: 9.46 | G25: 46.61 | H25: 16.05 | I25: 4.42 | J25: 0.95 | K25: 351.16 | L25: 36.28 | M25: 31.39 | N25: 113.5 | O25: 0 | P25: 0.39 | Q25: 9.38
A26: 03-06-2024 18:00 | B26: 2.56 | C26: 1.55 | D26: 4.02 | E26: 0.62 | F26: 9.78 | G26: 43.83 | H26: 15.89 | I26: 3.24 | J26: 0.69 | K26: 353.75 | L26: 35.66 | M26: 32.02 | N26: 71 | O26: 0 | P26: 0.44 | Q26: 9.43
A27: 03-06-2024 19:00 | B27: 2.57 | C27: 1.35 | D27: 3.84 | E27: 0.88 | F27: 6.28 | G27: 45.02 | H27: 15.89 | I27: 3.08 | J27: 0.63 | K27: 352.21 | L27: 34.69 | M27: 36.6 | N27: 28.8 | O27: 0 | P27: 0.5 | Q27: 9.4
A28: 03-06-2024 20:00 | B28: 2.47 | C28: 1.01 | D28: 3.39 | E28: 1.02 | F28: 4.91 | G28: 49.38 | H28: 17.54 | I28: 3.92 | J28: 1.55 | K28: 336.34 | L28: 33.48 | M28: 38.54 | N28: 12.9 | O28: 0 | P28: 0.64 | Q28: 9.49
A29: 03-06-2024 21:00 | B29: 2.61 | C29: 1.67 | D29: 4.19 | E29: 0.53 | F29: 5.14 | G29: 50.82 | H29: 17.54 | I29: 4.31 | J29: 0.87 | K29: 326.25 | L29: 31.99 | M29: 40.55 | N29: 13 | O29: 0 | P29: 0.71 | Q29: 9.49
A30: 03-06-2024 22:00 | B30: 2.6 | C30: 1.6 | D30: 4.11 | E30: 0.56 | F30: 4.72 | G30: 55.48 | H30: 19.41 | I30: 5.06 | J30: 1.8 | K30: 194.52 | L30: 31.56 | M30: 45.77 | N30: 13 | O30: 0 | P30: 0.69 | Q30: 9.46
A31: 03-06-2024 23:00 | B31: 2.62 | C31: 1.26 | D31: 3.78 | E31: 0.43 | F31: 4.32 | G31: 55.48 | H31: 19.47 | I31: 5.76 | J31: 1.38 | K31: 164.41 | L31: 30.52 | M31: 49.27 | N31: 13 | O31: 0 | P31: 0.64 | Q31: 9.4
A32: 03-06-2024 24:00 | B32: 2.66 | C32: 1.48 | D32: 4.06 | E32: 0.69 | F32: 4.76 | G32: 50.13 | H32: 19.47 | I32: 5.66 | J32: 1.24 | K32: 162.85 | L32: 29.97 | M32: 50.68 | N32: 12.8 | O32: 0 | P32: 0.58 | Q32: 9.46
A34: Min | B34: =MIN(B9:B32) -> 2.47 | C34: =MIN(C9:C32) -> 0.96 | D34: =MIN(D9:D32) -> 3.34 | E34: =MIN(E9:E32) -> 0.43 | F34: =MIN(F9:F32) -> 4.22 | G34: =MIN(G9:G32) -> 19.05 | H34: =MIN(H9:H32) -> 7.71 | I34: =MIN(I9:I32) -> 1.84 | ... Q34: =MIN(Q9:Q32) -> 9.3
A35: Max | B35: =MAX(B9:B32) -> 2.85 | C35: =MAX(C9:C32) -> 2.82 | D35: =MAX(D9:D32) -> 4.91 | E35: =MAX(E9:E32) -> 3.99 | F35: =MAX(F9:F32) -> 18.54 | G35: =MAX(G9:G32) -> 74.14 | H35: =MAX(H9:H32) -> 19.47 | I35: =MAX(I9:I32) -> 9.85 | ... Q35: =MAX(Q9:Q32) -> 9.55
A36: Avg | B36: =AVERAGE(B9:B32) -> 2.6491667 | C36: =AVERAGE(C9:C32) -> 1.6741667 | D36: =AVERAGE(D9:D32) -> 4.1 | E36: =AVERAGE(E9:E32) -> 1.4565217 | F36: =AVERAGE(F9:F32) -> 8.2366667 | G36: =AVERAGE(G9:G32) -> 41.240435 | H36: =AVERAGE(H9:H32) -> 14.455652 | I36: =AVERAGE(I9:I32) -> 5.5566667 | ... Q36: =AVERAGE(Q9:Q32) -> 9.4366667
A37: Stdev | B37: =STDEV(B9:B32) -> 0.12437379 | C37: =STDEV(C9:C32) -> 0.5736528 | D37: =STDEV(D9:D32) -> 0.45005314 | E37: =STDEV(E9:E32) -> 1.013646 | F37: =STDEV(F9:F32) -> 4.35165 | G37: =STDEV(G9:G32) -> 16.811164 | H37: =STDEV(H9:H32) -> 3.7126024 | I37: =STDEV(I9:I32) -> 2.229743 | ... Q37: =STDEV(Q9:Q32) -> 0.060337217
A38: Num | B38: =COUNT(B9:B32) -> 24 | C38: =COUNT(C9:C32) -> 24 | D38: =COUNT(D9:D32) -> 24 | E38: =COUNT(E9:E32)+1 -> 24 | F38: =COUNT(F9:F32) -> 24 | G38: =COUNT(G9:G32)+1 -> 24 | H38: =COUNT(H9:H32)+1 -> 24 | I38: =COUNT(I9:I32) -> 24 | J38: =COUNT(J9:J32) -> 24 | K38: =COUNT(K9:K32) -> 24 | L38: =COUNT(L9:L32) -> 24 | M38: =COUNT(M9:M32) -> 24 | N38: =COUNT(N9:N32) -> 24 | O38: =COUNT(O9:O32) -> 24 | P38: =COUNT(P9:P32) -> 24 | Q38: =COUNT(Q9:Q32) -> 24
A39: DCR | B39: =IF(B38>=22,">90%",IF(B38<=22,"<90%")) -> >90% | C39: =IF(C38>=22,">90%",IF(C38<=22,"<90%")) -> >90% | D39: =IF(D38>=22,">90%",IF(D38<=22,"<90%")) -> >90% | E39: =IF(E38>=22,">90%",IF(E38<=22,"<90%")) -> >90% | F39: =IF(F38>=22,">90%",IF(F38<=22,"<90%")) -> >90% | G39: =IF(G38>=22,">90%",IF(G38<=22,"<90%")) -> >90% | H39: =IF(H38>=22,">90%",IF(H38<=22,"<90%")) -> >90% | I39: =IF(I38>=22,">90%",IF(I38<=22,"<90%")) -> >90% | ... Q39: =IF(Q38>=22,">90%",IF(Q38<=22,"<90%")) -> >90%
A40: Status | B40: =IF(B38>=22,"OK",IF(B38<=22,"LESS")) -> OK | C40: =IF(C38>=22,"OK",IF(C38<=22,"LESS")) -> OK | D40: =IF(D38>=22,"OK",IF(D38<=22,"LESS")) -> OK | E40: =IF(E38>=22,"OK",IF(E38<=22,"LESS")) -> OK | F40: =IF(F38>=22,"OK",IF(F38<=22,"LESS")) -> OK | G40: =IF(G38>=22,"OK",IF(G38<=22,"LESS")) -> OK | H40: =IF(H38>=22,"OK",IF(H38<=22,"LESS")) -> OK | I40: =IF(I38>=22,"OK",IF(I38<=22,"LESS")) -> OK | ... Q40: =IF(Q38>=22,"OK",IF(Q38<=22,"LESS")) -> OK
A43: Done by | B43: RAHUL
A45: Comment

Sheet 04
A1: Station: | B1: BHATAGAON RAIPUR
A2: Date: | B2: =$A$9 -> 04-06-2024 01:00 | D2: Power Off | G2: Pw.Off | L2: Link Fail | N2: Link F | P2: Maintenance | R2: Maint.
A3: Report Type: | B3: Mean | D3: Calibration | G3: Calib. | L3: Data Fail | N3: Data F | P3: Invalid | R3: Invalid
A4: Time Base: | B4: 01 Hour | D4: Zero Referrence | G4: Z.Ref | L4: Warm Up | N4: Wm. Up
A7: Date & Time | B7: NO_BHATAGAON | C7: NO2_BHATAGAON | D7: NOX_BHATAGAON | E7: SO2_BHATAGAON | F7: O3_BHATAGAON | G7: PM10_BHATAGAON | H7: PM2_5_BHATAGAON | I7: BENZ_BHATAGAON | J7: WS_BHATAGAON | K7: WD_BHATAGAON | L7: TEMP_BHATAGAON | M7: HUM BHATAGAON | N7: SR_BHATAGAON | O7: RG_BHATAGAON | P7: CO_BHATAGAON | Q7: NH3_BHATAGAON
B8: ug/m3 | C8: ug/m3 | D8: ppb | E8: ug/m3 | F8: ug/m3 | G8: mg/m3 | H8: ug/m3 | I8: ug/m3 | J8: m/sec | K8: deg | L8: degreC | M8: % | N8: w/m2 | O8: mm | P8: ug/m3 | Q8: ug/m3
A9: 04-06-2024 01:00 | B9: 2.98 | C9: 3.2 | D9: 6.08 | E9: 1.05 | F9: 4.83 | G9: 44.13 | H9: 17.8 | I9: 6.28 | J9: 1.12 | K9: 183.84 | L9: 29.18 | M9: 52.3 | N9: 13 | O9: 0 | P9: 0.55 | Q9: 9.44
A10: 04-06-2024 02:00 | B10: 2.99 | C10: 3.75 | D10: 6.65 | E10: 0.94 | F10: 5.54 | G10: 38.92 | H10: 13.85 | I10: 5.81 | J10: 0.81 | K10: 163.32 | L10: 28.76 | M10: 57.67 | N10: 13.3 | O10: 0 | P10: 0.47 | Q10: 9.42
A11: 04-06-2024 03:00 | B11: 3.04 | C11: 3.58 | D11: 6.53 | E11: 1.17 | F11: 4.43 | G11: 34.02 | H11: 13.67 | I11: 5.3 | J11: 0.89 | K11: 241.02 | L11: 27.66 | M11: 58.97 | N11: 13 | O11: 0 | P11: 0.43 | Q11: 9.39
A12: 04-06-2024 04:00 | B12: 3.12 | C12: 3.28 | D12: 6.3 | E12: 1.55 | F12: 4.18 | G12: 31.97 | H12: 13.26 | I12: 4.6 | J12: 0.73 | K12: 235.52 | L12: 27.44 | M12: 60.77 | N12: 13 | O12: 0 | P12: 0.4 | Q12: 9.41
A13: 04-06-2024 05:00 | B13: 3.28 | C13: 4.25 | D13: 7.44 | E13: 2.01 | F13: 4.7 | G13: 31.04 | H13: 12.58 | I13: 5.11 | J13: 0.46 | K13: 263.29 | L13: 27.04 | M13: 63.23 | N13: 13.2 | O13: 0 | P13: 0.38 | Q13: 9.4
A14: 04-06-2024 06:00 | B14: 3.25 | C14: 4.45 | D14: 7.6 | E14: 1.99 | F14: 4.86 | G14: 21.31 | H14: 10.59 | I14: 5.21 | J14: 0.36 | K14: 348.1 | L14: 27.34 | M14: 63.08 | N14: 44.4 | O14: 0 | P14: 0.36 | Q14: 9.43
A15: 04-06-2024 07:00 | B15: 3.18 | C15: 4.7 | D15: 7.75 | E15: 2.05 | F15: 5.58 | G15: 26.15 | H15: 11.37 | I15: 4.58 | J15: 0.5 | K15: 353.41 | L15: 28.6 | M15: 61.4 | N15: 199.6 | O15: 0 | P15: 0.35 | Q15: 9.41
A16: 04-06-2024 08:00 | B16: 3.07 | C16: 4.52 | D16: 7.51 | E16: 1.74 | F16: 8.78 | G16: 26.15 | H16: 11.94 | I16: 3.74 | J16: 0.63 | K16: 355.6 | L16: 29.46 | M16: 57.24 | N16: 312.2 | O16: 0 | P16: 0.33 | Q16: 9.36
A17: 04-06-2024 09:00 | B17: 2.91 | C17: 3.73 | D17: 6.55 | E17: 1.13 | F17: 7.92 | G17: 26.65 | H17: 11.94 | I17: 2.96 | J17: 0.69 | K17: 343.3 | L17: 33.5 | M17: 50.95 | N17: 589.4 | O17: 0 | P17: 0.4 | Q17: 9.38
A18: 04-06-2024 10:00 | B18: 2.97 | C18: 4.69 | D18: 7.57 | E18: 1.19 | F18: 7.39 | G18: 30.74 | H18: 14.42 | I18: 3.73 | J18: 1.26 | K18: 331.83 | L18: 36.54 | M18: 39.49 | N18: 730 | O18: 0 | P18: 0.53 | Q18: 9.39
A19: 04-06-2024 11:00 | B19: 2.91 | C19: 4.13 | D19: 6.95 | E19: 1.09 | F19: 7.34 | G19: 35.73 | H19: 17.14 | I19: 3.78 | J19: 1.57 | K19: 331.27 | L19: 39.96 | M19: 32.31 | N19: 816.4 | O19: 0 | P19: 0.53 | Q19: 9.4
A20: 04-06-2024 12:00 | B20: 2.87 | C20: 3.72 | D20: 6.5 | E20: 2.55 | F20: 7.29 | G20: 35.73 | H20: 17.14 | I20: 3.17 | J20: 2.24 | K20: 333.74 | L20: 40.23 | M20: 26.88 | N20: 841.7 | O20: 0 | P20: 0.51 | Q20: 9.39
... A32: 04-06-2024 24:00 | B32: 2.7 | C32: 1.81 | D32: 4.42 | E32: 1.61 | F32: 5.75 | G32: 38.46 | H32: 15.82 | I32: 7.53 | J32: 2.5 | K32: 196.14 | L32: 27.13 | M32: 63.05 | N32: 15.1 | O32: 0 | P32: 0.38 | Q32: 9.48
A34: Min | B34: =MIN(B9:B32) -> 2.57 | C34: =MIN(C9:C32) -> 1.27 | D34: =MIN(D9:D32) -> 3.84 | E34: =MIN(E9:E32) -> 0.9 | F34: =MIN(F9:F32) -> 4.18 | G34: =MIN(G9:G32) -> 21.31 | H34: =MIN(H9:H32) -> 10.59 | I34: =MIN(I9:I32) -> 2.96 | ... Q34: =MIN(Q9:Q32) -> 9.32
A35: Max | B35: =MAX(B9:B32) -> 3.28 | C35: =MAX(C9:C32) -> 4.7 | D35: =MAX(D9:D32) -> 7.75 | E35: =MAX(E9:E32) -> 2.55 | F35: =MAX(F9:F32) -> 11.25 | G35: =MAX(G9:G32) -> 62.37 | H35: =MAX(H9:H32) -> 21.18 | I35: =MAX(I9:I32) -> 7.74 | ... Q35: =MAX(Q9:Q32) -> 9.48
A36: Avg | B36: =AVERAGE(B9:B32) -> 2.885 | C36: =AVERAGE(C9:C32) -> 3.06375 | D36: =AVERAGE(D9:D32) -> 5.8541667 | E36: =AVERAGE(E9:E32) -> 1.5766667 | F36: =AVERAGE(F9:F32) -> 6.5141667 | G36: =AVERAGE(G9:G32) -> 38.784583 | H36: =AVERAGE(H9:H32) -> 16.288333 | I36: =AVERAGE(I9:I32) -> 4.8629167 | ... Q36: =AVERAGE(Q9:Q32) -> 9.3995833
A37: Stdev | B37: =STDEV(B9:B32) -> 0.19960831 | C37: =STDEV(C9:C32) -> 1.1153779 | D37: =STDEV(D9:D32) -> 1.2922004 | E37: =STDEV(E9:E32) -> 0.48117308 | F37: =STDEV(F9:F32) -> 1.9553403 | G37: =STDEV(G9:G32) -> 10.91171 | H37: =STDEV(H9:H32) -> 3.3069764 | I37: =STDEV(I9:I32) -> 1.4254106 | ... Q37: =STDEV(Q9:Q32) -> 0.04298424
A38: Num | B38: =COUNT(B9:B32) -> 24 | C38: =COUNT(C9:C32) -> 24 | D38: =COUNT(D9:D32) -> 24 | E38: =COUNT(E9:E32) -> 24 | F38: =COUNT(F9:F32) -> 24 | G38: =COUNT(G9:G32) -> 24 | H38: =COUNT(H9:H32) -> 24 | I38: =COUNT(I9:I32) -> 24 | ... Q38: =COUNT(Q9:Q32) -> 24
A39: DCR | B39: =IF(B38>=22,">90%",IF(B38<=22,"<90%")) -> >90% | C39: =IF(C38>=22,">90%",IF(C38<=22,"<90%")) -> >90% | D39: =IF(D38>=22,">90%",IF(D38<=22,"<90%")) -> >90% | E39: =IF(E38>=22,">90%",IF(E38<=22,"<90%")) -> >90% | F39: =IF(F38>=22,">90%",IF(F38<=22,"<90%")) -> >90% | G39: =IF(G38>=22,">90%",IF(G38<=22,"<90%")) -> >90% | H39: =IF(H38>=22,">90%",IF(H38<=22,"<90%")) -> >90% | I39: =IF(I38>=22,">90%",IF(I38<=22,"<90%")) -> >90% | ... Q39: =IF(Q38>=22,">90%",IF(Q38<=22,"<90%")) -> >90%
A40: Status | B40: =IF(B38>=22,"OK",IF(B38<=22,"LESS")) -> OK | C40: =IF(C38>=22,"OK",IF(C38<=22,"LESS")) -> OK | D40: =IF(D38>=22,"OK",IF(D38<=22,"LESS")) -> OK | E40: =IF(E38>=22,"OK",IF(E38<=22,"LESS")) -> OK | F40: =IF(F38>=22,"OK",IF(F38<=22,"LESS")) -> OK | G40: =IF(G38>=22,"OK",IF(G38<=22,"LESS")) -> OK | H40: =IF(H38>=22,"OK",IF(H38<=22,"LESS")) -> OK | I40: =IF(I38>=22,"OK",IF(I38<=22,"LESS")) -> OK | ... Q40: =IF(Q38>=22,"OK",IF(Q38<=22,"LESS")) -> OK
A43: Done by | B43: RAHUL
A45: Comment

Sheet 05
A1: Station: | B1: BHATAGAON RAIPUR
A2: Date: | B2: =$A$9 -> 05-06-2024 01:00 | D2: Power Off | G2: Pw.Off | L2: Link Fail | N2: Link F | P2: Maintenance | R2: Maint.
A3: Report Type: | B3: Mean | D3: Calibration | G3: Calib. | L3: Data Fail | N3: Data F | P3: Invalid | R3: Invalid
A4: Time Base: | B4: 01 Hour | D4: Zero Referrence | G4: Z.Ref | L4: Warm Up | N4: Wm. Up
A7: Date & Time | B7: NO_BHATAGAON | C7: NO2_BHATAGAON | D7: NOX_BHATAGAON | E7: SO2_BHATAGAON | F7: O3_BHATAGAON | G7: PM10_BHATAGAON | H7: PM2_5_BHATAGAON | I7: BENZ_BHATAGAON | J7: WS_BHATAGAON | K7: WD_BHATAGAON | L7: TEMP_BHATAGAON | M7: HUM BHATAGAON | N7: SR_BHATAGAON | O7: RG_BHATAGAON | P7: CO_BHATAGAON | Q7: NH3_BHATAGAON
B8: ug/m3 | C8: ug/m3 | D8: ppb | E8: ug/m3 | F8: ug/m3 | G8: mg/m3 | H8: ug/m3 | I8: ug/m3 | J8: m/sec | K8: deg | L8: degreC | M8: % | N8: w/m2 | O8: mm | P8: ug/m3 | Q8: ug/m3
A9: 05-06-2024 01:00 | B9: 2.75 | C9: 2.1 | D9: 4.76 | E9: 1.07 | F9: 5.31 | G9: 33.99 | H9: 15.51 | I9: 6.69 | J9: 3.15 | K9: 348.31 | L9: 27.38 | M9: 60.64 | N9: 14.9 | O9: 0 | P9: 0.35 | Q9: 9.46
A10: 05-06-2024 02:00 | B10: 2.58 | C10: 1.28 | D10: 3.77 | E10: 1.25 | F10: 7.4 | G10: 42.73 | H10: 16 | I10: 5.42 | J10: 2.63 | K10: 343.38 | L10: 27.35 | M10: 64.11 | N10: 17.1 | O10: 0 | P10: 0.34 | Q10: 9.46
A11: 05-06-2024 03:00 | B11: 2.55 | C11: 0.87 | D11: 3.33 | E11: 1.39 | F11: 7.09 | G11: 42.73 | H11: 16 | I11: 4.14 | J11: 0.86 | K11: 149.48 | L11: 25.3 | M11: 77.16 | N11: 15.7 | O11: 0.2 | P11: 0.29 | Q11: 9.41
A12: 05-06-2024 04:00 | B12: 2.65 | C12: 1.23 | D12: 3.79 | E12: 1.3 | F12: 4.37 | G12: 36.97 | H12: 13.66 | I12: 4.76 | J12: 1.34 | K12: 161.86 | L12: 25.77 | M12: 70.15 | N12: 16 | O12: 0 | P12: 0.28 | Q12: 9.45
A13: 05-06-2024 05:00 | B13: 2.61 | C13: 1.28 | D13: 3.79 | E13: 1.18 | F13: 4.41 | G13: 48.17 | H13: 13.66 | I13: 4.99 | J13: 1.71 | K13: 348.26 | L13: 25.97 | M13: 72.57 | N13: 16 | O13: 0 | P13: 0.29 | Q13: 9.44
A14: 05-06-2024 06:00 | B14: 2.73 | C14: 1.71 | D14: 4.35 | E14: 1.51 | F14: 5.04 | G14: 52.12 | H14: 13.5 | I14: 4.74 | J14: 3.4 | K14: 347.41 | L14: 25.29 | M14: 76.05 | N14: 40.6 | O14: 0 | P14: 0.34 | Q14: 9.51
A15: 05-06-2024 07:00 | B15: 2.64 | C15: 1.4 | D15: 3.95 | E15: 1.05 | F15: 5.99 | G15: 52.12 | H15: 16.26 | I15: 4.26 | J15: 3.3 | K15: 344.06 | L15: 24.58 | M15: 76.69 | N15: 83.5 | O15: 0 | P15: 0.34 | Q15: 9.42
A16: 05-06-2024 08:00 | B16: 2.57 | C16: 1.16 | D16: 3.65 | E16: 1.81 | F16: 6.66 | G16: 49.07 | H16: 16.26 | I16: 3.32 | J16: 3.13 | K16: 336 | L16: 29.74 | M16: 66.98 | N16: 419.1 | O16: 0 | P16: 0.33 | Q16: 9.44
A17: 05-06-2024 09:00 | B17: 2.73 | C17: 1.96 | D17: 4.6 | E17: 1.51 | F17: 6.82 | G17: 40.33 | H17: 11.93 | I17: 2.6 | J17: 1.84 | K17: 314.96 | L17: 32.83 | M17: 50.87 | N17: 598.2 | O17: 0 | P17: 0.32 | Q17: 9.47
A18: 05-06-2024 10:00 | B18: 2.5 | C18: 1.05 | D18: 3.46 | E18: 1.45 | F18: 7.58 | G18: 29.59 | H18: 9.05 | I18: 2.24 | J18: 0.95 | K18: 351.02 | L18: 33.78 | M18: 44.96 | N18: 849.7 | O18: 0 | P18: 0.32 | Q18: 9.45
A19: 05-06-2024 11:00 | B19: 2.64 | C19: 1.55 | D19: 4.11 | E19: 1.73 | F19: 13.15 | G19: 26.94 | H19: 9.85 | I19: 2.74 | J19: 0.66 | K19: 357.21 | L19: 33.4 | M19: 46.2 | N19: 923 | O19: 0 | P19: 0.71 | Q19: 9.5
A20: 05-06-2024 12:00 | B20: 2.62 | C20: 1.76 | D20: 4.29 | E20: 1.62 | F20: 11.14 | G20: 25.93 | H20: 13.46 | I20: 4.61 | J20: 1.41 | K20: 342.54 | L20: 35.15 | M20: 44.59 | N20: 630.2 | O20: 0 | P20: 0.71 | Q20: 9.38
... A32: 05-06-2024 24:00 | B32: 2.6 | C32: 1.63 | D32: 4.08 | E32: 2.32 | F32: 4.7 | G32: 40.56 | H32: 20.73 | I32: 5.99 | J32: 0.63 | K32: 169.81 | L32: 28.09 | M32: 51.81 | N32: 19.9 | O32: 0 | P32: 0.48 | Q32: 9.53
A34: Min | B34: =MIN(B9:B32) -> 2.42 | C34: =MIN(C9:C32) -> 0.87 | D34: =MIN(D9:D32) -> 3.33 | E34: =MIN(E9:E32) -> 1.05 | F34: =MIN(F9:F32) -> 4.05 | G34: =MIN(G9:G32) -> 25.93 | H34: =MIN(H9:H32) -> 9.05 | I34: =MIN(I9:I32) -> 2.24 | ... Q34: =MIN(Q9:Q32) -> 9.38
A35: Max | B35: =MAX(B9:B32) -> 2.79 | C35: =MAX(C9:C32) -> 2.89 | D35: =MAX(D9:D32) -> 4.78 | E35: =MAX(E9:E32) -> 2.41 | F35: =MAX(F9:F32) -> 21.49 | G35: =MAX(G9:G32) -> 52.12 | H35: =MAX(H9:H32) -> 20.73 | I35: =MAX(I9:I32) -> 6.94 | ... Q35: =MAX(Q9:Q32) -> 9.7
A36: Avg | B36: =AVERAGE(B9:B32) -> 2.5866667 | C36: =AVERAGE(C9:C32) -> 1.6125 | D36: =AVERAGE(D9:D32) -> 4.0508333 | E36: =AVERAGE(E9:E32) -> 1.7525 | F36: =AVERAGE(F9:F32) -> 7.1679167 | G36: =AVERAGE(G9:G32) -> 39.185417 | H36: =AVERAGE(H9:H32) -> 15.805833 | I36: =AVERAGE(I9:I32) -> 4.9516667 | ... Q36: =AVERAGE(Q9:Q32) -> 9.4841667
A37: Stdev | B37: =STDEV(B9:B32) -> 0.097162646 | C37: =STDEV(C9:C32) -> 0.47436227 | D37: =STDEV(D9:D32) -> 0.38310989 | E37: =STDEV(E9:E32) -> 0.43165254 | F37: =STDEV(F9:F32) -> 3.9468777 | G37: =STDEV(G9:G32) -> 7.3851155 | H37: =STDEV(H9:H32) -> 2.8646161 | I37: =STDEV(I9:I32) -> 1.3227201 | ... Q37: =STDEV(Q9:Q32) -> 0.065136423
A38: Num | B38: =COUNT(B9:B32) -> 24 | C38: =COUNT(C9:C32) -> 24 | D38: =COUNT(D9:D32) -> 24 | E38: =COUNT(E9:E32) -> 24 | F38: =COUNT(F9:F32) -> 24 | G38: =COUNT(G9:G32) -> 24 | H38: =COUNT(H9:H32) -> 24 | I38: =COUNT(I9:I32) -> 24 | ... Q38: =COUNT(Q9:Q32) -> 24
A39: DCR | B39: =IF(B38>=22,">90%",IF(B38<=22,"<90%")) -> >90% | C39: =IF(C38>=22,">90%",IF(C38<=22,"<90%")) -> >90% | D39: =IF(D38>=22,">90%",IF(D38<=22,"<90%")) -> >90% | E39: =IF(E38>=22,">90%",IF(E38<=22,"<90%")) -> >90% | F39: =IF(F38>=22,">90%",IF(F38<=22,"<90%")) -> >90% | G39: =IF(G38>=22,">90%",IF(G38<=22,"<90%")) -> >90% | H39: =IF(H38>=22,">90%",IF(H38<=22,"<90%")) -> >90% | I39: =IF(I38>=22,">90%",IF(I38<=22,"<90%")) -> >90% | ... Q39: =IF(Q38>=22,">90%",IF(Q38<=22,"<90%")) -> >90%
A40: Status | B40: =IF(B38>=22,"OK",IF(B38<=22,"LESS")) -> OK | C40: =IF(C38>=22,"OK",IF(C38<=22,"LESS")) -> OK | D40: =IF(D38>=22,"OK",IF(D38<=22,"LESS")) -> OK | E40: =IF(E38>=22,"OK",IF(E38<=22,"LESS")) -> OK | F40: =IF(F38>=22,"OK",IF(F38<=22,"LESS")) -> OK | G40: =IF(G38>=22,"OK",IF(G38<=22,"LESS")) -> OK | H40: =IF(H38>=22,"OK",IF(H38<=22,"LESS")) -> OK | I40: =IF(I38>=22,"OK",IF(I38<=22,"LESS")) -> OK | ... Q40: =IF(Q38>=22,"OK",IF(Q38<=22,"LESS")) -> OK
A43: Done by | B43: RAHUL
A45: Comment

Sheet 06
A1: Station: | B1: BHATAGAON RAIPUR
A2: Date: | B2: =$A$9 -> 06-06-2024 01:00 | D2: Power Off | G2: Pw.Off | L2: Link Fail | N2: Link F | P2: Maintenance | R2: Maint.
A3: Report Type: | B3: Mean | D3: Calibration | G3: Calib. | L3: Data Fail | N3: Data F | P3: Invalid | R3: Invalid
A4: Time Base: | B4: 01 Hour | D4: Zero Referrence | G4: Z.Ref | L4: Warm Up | N4: Wm. Up
A7: Date & Time | B7: NO_BHATAGAON | C7: NO2_BHATAGAON | D7: NOX_BHATAGAON | E7: SO2_BHATAGAON | F7: O3_BHATAGAON | G7: PM10_BHATAGAON | H7: PM2_5_BHATAGAON | I7: BENZ_BHATAGAON | J7: WS_BHATAGAON | K7: WD_BHATAGAON | L7: TEMP_BHATAGAON | M7: HUM BHATAGAON | N7: SR_BHATAGAON | O7: RG_BHATAGAON | P7: CO_BHATAGAON | Q7: NH3_BHATAGAON
B8: ug/m3 | C8: ug/m3 | D8: ppb | E8: ug/m3 | F8: ug/m3 | G8: mg/m3 | H8: ug/m3 | I8: ug/m3 | J8: m/sec | K8: deg | L8: degreC | M8: % | N8: w/m2 | O8: mm | P8: ug/m3 | Q8: ug/m3
A9: 06-06-2024 01:00 | B9: 2.55 | C9: 1.34 | D9: 3.89 | E9: 0.32 | F9: 4.16 | G9: 34.57 | H9: 20.73 | I9: 5.45 | J9: 0.69 | K9: 221.08 | L9: 28.19 | M9: 53.9 | N9: 20 | O9: 0 | P9: 0.45 | Q9: 9.47
A10: 06-06-2024 02:00 | B10: 2.6 | C10: 1.32 | D10: 3.92 | E10: 0.49 | F10: 3.94 | G10: 32.15 | H10: 17.72 | I10: 4.41 | J10: 0.66 | K10: 344.87 | L10: 27.83 | M10: 57.34 | N10: 20.3 | O10: 0 | P10: 0.44 | Q10: 9.46
A11: 06-06-2024 03:00 | B11: 2.66 | C11: 1.45 | D11: 4.04 | E11: 0.71 | F11: 4.71 | G11: 30.54 | H11: 16.36 | I11: 5.29 | J11: 1.02 | K11: 341.3 | L11: 27.49 | M11: 60.51 | N11: 20.3 | O11: 0 | P11: 0.43 | Q11: 9.52
A12: 06-06-2024 04:00 | B12: 2.68 | C12: 1.74 | D12: 4.2 | E12: 1.56 | F12: 4.79 | G12: 28.55 | H12: 15.55 | I12: 5.87 | J12: 0.51 | K12: 239.72 | L12: 26.97 | M12: 63 | N12: 20.2 | O12: 0 | P12: 0.41 | Q12: 9.5
A13: 06-06-2024 05:00 | B13: 2.68 | C13: 1.61 | D13: 4.14 | E13: 2.14 | F13: 4.16 | G13: 26.93 | H13: 13.49 | I13: 5.62 | J13: 0.46 | K13: 34.55 | L13: 26.9 | M13: 61.82 | N13: 20.5 | O13: 0 | P13: 0.41 | Q13: 9.47
A14: 06-06-2024 06:00 | B14: 2.59 | C14: 1.3 | D14: 3.9 | E14: 1.87 | F14: 4.03 | G14: 31.95 | H14: 11.98 | I14: 5.31 | J14: 0.2 | K14: 244.92 | L14: 26.59 | M14: 65.44 | N14: 63.6 | O14: 0 | P14: 0.4 | Q14: 9.51
A15: 06-06-2024 07:00 | B15: 2.61 | C15: 1.1 | D15: 3.81 | E15: 2.36 | F15: 3.68 | G15: 32.09 | H15: 12.36 | I15: 5.37 | J15: 0.42 | K15: 244.2 | L15: 28.38 | M15: 64.64 | N15: 219.8 | O15: 0 | P15: 0.4 | Q15: 9.48
A16: 06-06-2024 08:00 | B16: 2.68 | C16: 1.76 | D16: 4.21 | E16: 2.23 | F16: 6.95 | G16: 34.16 | H16: 12.36 | I16: 5.92 | J16: 0.44 | K16: 26.95 | L16: 30.13 | M16: 60.07 | N16: 427 | O16: 0 | P16: 0.41 | Q16: 9.52
A17: 06-06-2024 09:00 | B17: 2.54 | C17: 1.32 | D17: 3.88 | E17: 2.08 | F17: 6.85 | G17: 34.59 | H17: 12.55 | I17: 5.16 | J17: 0.54 | K17: 352.04 | L17: 32.59 | M17: 52.4 | N17: 506.8 | O17: 0 | P17: 0.38 | Q17: 9.48
A18: 06-06-2024 10:00 | B18: 2.45 | C18: 0.95 | D18: 3.6 | E18: 2 | F18: 8.44 | G18: 34.59 | H18: 12.55 | I18: 3.72 | J18: 0.64 | K18: 354.83 | L18: 34.79 | M18: 44.9 | N18: 761.6 | O18: 0 | P18: 0.44 | Q18: 9.43
A19: 06-06-2024 11:00 | B19: 2.46 | C19: 1.01 | D19: 3.65 | E19: 1.88 | F19: 10.08 | G19: 36.35 | H19: 15.45 | I19: 4.61 | J19: 1 | K19: 357.11 | L19: 36.06 | M19: 40.61 | N19: 844.9 | O19: 0 | P19: 0.59 | Q19: 9.43
A20: 06-06-2024 12:00 | B20: 2.46 | C20: 1.06 | D20: 3.67 | E20: 2.17 | F20: 8.87 | G20: 41.05 | H20: 17.25 | I20: 5.01 | J20: 1.49 | K20: 329.03 | L20: 38.98 | M20: 33.12 | N20: 852.2 | O20: 0 | P20: 0.61 | Q20: 9.43
... A32: 06-06-2024 24:00 | B32: 2.68 | C32: 1.76 | D32: 4.21 | E32: 1.21 | F32: 4.42 | G32: 40.88 | H32: 17.17 | I32: 4.52 | J32: 1.12 | K32: 194.06 | L32: 27.44 | M32: 62.52 | N32: 19 | O32: 0 | P32: 0.43 | Q32: 9.42
A34: Min | B34: =MIN(B9:B32) -> 2.38 | C34: =MIN(C9:C32) -> 0.87 | D34: =MIN(D9:D32) -> 3.51 | E34: =MIN(E9:E32) -> 0.32 | F34: =MIN(F9:F32) -> 3.68 | G34: =MIN(G9:G32) -> 26.93 | H34: =MIN(H9:H32) -> 11.98 | I34: =MIN(I9:I32) -> 3.72 | ... Q34: =MIN(Q9:Q32) -> 9.36
A35: Max | B35: =MAX(B9:B32) -> 2.7 | C35: =MAX(C9:C32) -> 1.79 | D35: =MAX(D9:D32) -> 4.23 | E35: =MAX(E9:E32) -> 2.36 | F35: =MAX(F9:F32) -> 10.08 | G35: =MAX(G9:G32) -> 45.44 | H35: =MAX(H9:H32) -> 20.73 | I35: =MAX(I9:I32) -> 6.75 | ... Q35: =MAX(Q9:Q32) -> 9.52
A36: Avg | B36: =AVERAGE(B9:B32) -> 2.56125 | C36: =AVERAGE(C9:C32) -> 1.3279167 | D36: =AVERAGE(D9:D32) -> 3.8925 | E36: =AVERAGE(E9:E32) -> 1.5179167 | F36: =AVERAGE(F9:F32) -> 6.2545833 | G36: =AVERAGE(G9:G32) -> 37.388333 | H36: =AVERAGE(H9:H32) -> 16.292083 | I36: =AVERAGE(I9:I32) -> 5.1679167 | ... Q36: =AVERAGE(Q9:Q32) -> 9.4370833
A37: Stdev | B37: =STDEV(B9:B32) -> 0.096922762 | C37: =STDEV(C9:C32) -> 0.28734132 | D37: =STDEV(D9:D32) -> 0.22130542 | E37: =STDEV(E9:E32) -> 0.5659158 | F37: =STDEV(F9:F32) -> 1.9892974 | G37: =STDEV(G9:G32) -> 5.7071372 | H37: =STDEV(H9:H32) -> 2.634883 | I37: =STDEV(I9:I32) -> 0.74905145 | ... Q37: =STDEV(Q9:Q32) -> 0.049998188
A38: Num | B38: =COUNT(B9:B32) -> 24 | C38: =COUNT(C9:C32) -> 24 | D38: =COUNT(D9:D32) -> 24 | E38: =COUNT(E9:E32) -> 24 | F38: =COUNT(F9:F32) -> 24 | G38: =COUNT(G9:G32) -> 24 | H38: =COUNT(H9:H32) -> 24 | I38: =COUNT(I9:I32) -> 24 | ... Q38: =COUNT(Q9:Q32) -> 24
A39: DCR | B39: =IF(B38>=22,">90%",IF(B38<=22,"<90%")) -> >90% | C39: =IF(C38>=22,">90%",IF(C38<=22,"<90%")) -> >90% | D39: =IF(D38>=22,">90%",IF(D38<=22,"<90%")) -> >90% | E39: =IF(E38>=22,">90%",IF(E38<=22,"<90%")) -> >90% | F39: =IF(F38>=22,">90%",IF(F38<=22,"<90%")) -> >90% | G39: =IF(G38>=22,">90%",IF(G38<=22,"<90%")) -> >90% | H39: =IF(H38>=22,">90%",IF(H38<=22,"<90%")) -> >90% | I39: =IF(I38>=22,">90%",IF(I38<=22,"<90%")) -> >90% | ... Q39: =IF(Q38>=22,">90%",IF(Q38<=22,"<90%")) -> >90%
A40: Status | B40: =IF(B38>=22,"OK",IF(B38<=22,"LESS")) -> OK | C40: =IF(C38>=22,"OK",IF(C38<=22,"LESS")) -> OK | D40: =IF(D38>=22,"OK",IF(D38<=22,"LESS")) -> OK | E40: =IF(E38>=22,"OK",IF(E38<=22,"LESS")) -> OK | F40: =IF(F38>=22,"OK",IF(F38<=22,"LESS")) -> OK | G40: =IF(G38>=22,"OK",IF(G38<=22,"LESS")) -> OK | H40: =IF(H38>=22,"OK",IF(H38<=22,"LESS")) -> OK | I40: =IF(I38>=22,"OK",IF(I38<=22,"LESS")) -> OK | ... Q40: =IF(Q38>=22,"OK",IF(Q38<=22,"LESS")) -> OK
A43: Done by | B43: RAHUL
A45: Comment

Sheet 07
A1: Station: | B1: BHATAGAON RAIPUR
A2: Date: | B2: =$A$9 -> 07-06-2024 01:00 | D2: Power Off | G2: Pw.Off | L2: Link Fail | N2: Link F | P2: Maintenance | R2: Maint.
A3: Report Type: | B3: Mean | D3: Calibration | G3: Calib. | L3: Data Fail | N3: Data F | P3: Invalid | R3: Invalid
A4: Time Base: | B4: 01 Hour | D4: Zero Referrence | G4: Z.Ref | L4: Warm Up | N4: Wm. Up
A7: Date & Time | B7: NO_BHATAGAON | C7: NO2_BHATAGAON | D7: NOX_BHATAGAON | E7: SO2_BHATAGAON | F7: O3_BHATAGAON | G7: PM10_BHATAGAON | H7: PM2_5_BHATAGAON | I7: BENZ_BHATAGAON | J7: WS_BHATAGAON | K7: WD_BHATAGAON | L7: TEMP_BHATAGAON | M7: HUM BHATAGAON | N7: SR_BHATAGAON | O7: RG_BHATAGAON | P7: CO_BHATAGAON | Q7: NH3_BHATAGAON
B8: ug/m3 | C8: ug/m3 | D8: ppb | E8: ug/m3 | F8: ug/m3 | G8: mg/m3 | H8: ug/m3 | I8: ug/m3 | J8: m/sec | K8: deg | L8: degreC | M8: % | N8: w/m2 | O8: mm | P8: ug/m3 | Q8: ug/m3
A9: 07-06-2024 01:00 | B9: 2.57 | C9: 1.1 | D9: 3.78 | E9: 1.57 | F9: 3.91 | G9: 37.36 | H9: 17.17 | I9: 4.56 | J9: 0.64 | K9: 262.56 | L9: 27.14 | M9: 61.44 | N9: 18.8 | O9: 0 | P9: 0.39 | Q9: 9.42
A10: 07-06-2024 02:00 | B10: 2.62 | C10: 1.4 | D10: 3.98 | E10: 1.88 | F10: 5.78 | G10: 35.99 | H10: 14.22 | I10: 4.69 | J10: 0.4 | K10: 348.93 | L10: 26.93 | M10: 61.89 | N10: 18.9 | O10: 0 | P10: 0.38 | Q10: 9.44
A11: 07-06-2024 03:00 | B11: 2.64 | C11: 1.5 | D11: 4.04 | E11: 1.6 | F11: 5.02 | G11: 30.59 | H11: 14.36 | I11: 4.63 | J11: 0.26 | K11: 321.87 | L11: 26.87 | M11: 63.1 | N11: 18.8 | O11: 0 | P11: 0.36 | Q11: 9.42
A12: 07-06-2024 04:00 | B12: 2.6 | C12: 1.08 | D12: 3.79 | E12: 1.75 | F12: 4.53 | G12: 31.35 | H12: 14.36 | I12: 4.05 | J12: 0.84 | K12: 255.92 | L12: 26.64 | M12: 65.63 | N12: 18.8 | O12: 0 | P12: 0.34 | Q12: 9.44
A13: 07-06-2024 05:00 | B13: 2.48 | C13: 0.82 | D13: 3.56 | E13: 1.36 | F13: 5.08 | G13: 31.35 | H13: 11.02 | I13: 3.84 | J13: 0.86 | K13: 193.51 | L13: 26.14 | M13: 67.95 | N13: 19.1 | O13: 0 | P13: 0.31 | Q13: 9.39
A14: 07-06-2024 06:00 | B14: 2.65 | C14: 1.21 | D14: 3.9 | E14: 1.62 | F14: 3.83 | G14: 31.13 | H14: 11.39 | I14: 4.45 | J14: 0.78 | K14: 231.62 | L14: 25.74 | M14: 70.71 | N14: 65.9 | O14: 0 | P14: 0.3 | Q14: 9.42
A15: 07-06-2024 07:00 | B15: 2.65 | C15: 1.59 | D15: 4.1 | E15: 1.81 | F15: 5.62 | G15: 28 | H15: 11.39 | I15: 4.9 | J15: 0.79 | K15: 200.21 | L15: 27.81 | M15: 67.99 | N15: 219.4 | O15: 0 | P15: 0.36 | Q15: 9.42
A16: 07-06-2024 08:00 | B16: 2.49 | C16: 1.14 | D16: 3.73 | E16: 2.05 | F16: 7.15 | G16: 31.6 | H16: 12.3 | I16: 4.75 | J16: 0.63 | K16: 23.69 | L16: 29.92 | M16: 58.32 | N16: 425.3 | O16: 0 | P16: 0.39 | Q16: 9.48
A17: 07-06-2024 09:00 | B17: 2.5 | C17: 1.13 | D17: 3.74 | E17: 1.83 | F17: 8.53 | G17: 31.6 | H17: 12.3 | I17: 3.98 | J17: 0.75 | K17: 30.84 | L17: 32.46 | M17: 51.64 | N17: 625 | O17: 0 | P17: 0.37 | Q17: 9.39
A18: 07-06-2024 10:00 | B18: 2.53 | C18: 1.08 | D18: 3.74 | E18: 2.22 | F18: 8.98 | G18: 30.05 | H18: 12.08 | I18: 3.12 | J18: 0.65 | K18: 357.05 | L18: 34.06 | M18: 44.47 | N18: 771.5 | O18: 0 | P18: 0.38 | Q18: 9.38
A19: 07-06-2024 11:00 | B19: 2.51 | C19: 1.35 | D19: 3.86 | E19: 2.16 | F19: 8.66 | G19: 32.7 | H19: 16.16 | I19: 3.01 | J19: 0.63 | K19: 356.54 | L19: 35.05 | M19: 40.08 | N19: 835 | O19: 0 | P19: 0.49 | Q19: 9.41
A20: 07-06-2024 12:00 | B20: 2.54 | C20: 1.46 | D20: 3.94 | E20: 2.23 | F20: 9.37 | G20: 38.97 | H20: 16.27 | I20: 3.81 | J20: 0.49 | K20: 328.67 | L20: 35.9 | M20: 37.97 | N20: 858 | O20: 0 | P20: 0.57 | Q20: 9.42
... A32: 07-06-2024 24:00 | B32: 2.32 | C32: 0.37 | D32: 3.19 | E32: 2.64 | F32: 6.06 | G32: 25.49 | H32: 10.74 | I32: 3.83 | J32: 0.3 | K32: 351.16 | L32: 26.54 | M32: 59.85 | N32: 16.6 | O32: 0 | P32: 0.27 | Q32: 9.41
A34: Min | B34: =MIN(B9:B32) -> 2.32 | C34: =MIN(C9:C32) -> 0.37 | D34: =MIN(D9:D32) -> 3.19 | E34: =MIN(E9:E32) -> 1.36 | F34: =MIN(F9:F32) -> 3.83 | G34: =MIN(G9:G32) -> 25.49 | H34: =MIN(H9:H32) -> 10.74 | I34: =MIN(I9:I32) -> 3.01 | ... Q34: =MIN(Q9:Q32) -> 9.34
A35: Max | B35: =MAX(B9:B32) -> 2.72 | C35: =MAX(C9:C32) -> 1.97 | D35: =MAX(D9:D32) -> 4.36 | E35: =MAX(E9:E32) -> 2.88 | F35: =MAX(F9:F32) -> 9.37 | G35: =MAX(G9:G32) -> 52.51 | H35: =MAX(H9:H32) -> 20.05 | I35: =MAX(I9:I32) -> 6.43 | ... Q35: =MAX(Q9:Q32) -> 9.48
A36: Avg | B36: =AVERAGE(B9:B32) -> 2.5483333 | C36: =AVERAGE(C9:C32) -> 1.22 | D36: =AVERAGE(D9:D32) -> 3.8241667 | E36: =AVERAGE(E9:E32) -> 2.1104167 | F36: =AVERAGE(F9:F32) -> 6.60125 | G36: =AVERAGE(G9:G32) -> 36.936667 | H36: =AVERAGE(H9:H32) -> 15.457083 | I36: =AVERAGE(I9:I32) -> 4.59375 | ... Q36: =AVERAGE(Q9:Q32) -> 9.4116667
A37: Stdev | B37: =STDEV(B9:B32) -> 0.096804 | C37: =STDEV(C9:C32) -> 0.35148134 | D37: =STDEV(D9:D32) -> 0.25647979 | E37: =STDEV(E9:E32) -> 0.46650858 | F37: =STDEV(F9:F32) -> 1.602781 | G37: =STDEV(G9:G32) -> 7.3090472 | H37: =STDEV(H9:H32) -> 3.2978207 | I37: =STDEV(I9:I32) -> 0.88158855 | ... Q37: =STDEV(Q9:Q32) -> 0.039305566
A38: Num | B38: =COUNT(B9:B32) -> 24 | C38: =COUNT(C9:C32) -> 24 | D38: =COUNT(D9:D32) -> 24 | E38: =COUNT(E9:E32) -> 24 | F38: =COUNT(F9:F32) -> 24 | G38: =COUNT(G9:G32) -> 24 | H38: =COUNT(H9:H32) -> 24 | I38: =COUNT(I9:I32) -> 24 | ... Q38: =COUNT(Q9:Q32) -> 24
A39: DCR | B39: =IF(B38>=22,">90%",IF(B38<=22,"<90%")) -> >90% | C39: =IF(C38>=22,">90%",IF(C38<=22,"<90%")) -> >90% | D39: =IF(D38>=22,">90%",IF(D38<=22,"<90%")) -> >90% | E39: =IF(E38>=22,">90%",IF(E38<=22,"<90%")) -> >90% | F39: =IF(F38>=22,">90%",IF(F38<=22,"<90%")) -> >90% | G39: =IF(G38>=22,">90%",IF(G38<=22,"<90%")) -> >90% | H39: =IF(H38>=22,">90%",IF(H38<=22,"<90%")) -> >90% | I39: =IF(I38>=22,">90%",IF(I38<=22,"<90%")) -> >90% | ... Q39: =IF(Q38>=22,">90%",IF(Q38<=22,"<90%")) -> >90%
A40: Status | B40: =IF(B38>=22,"OK",IF(B38<=22,"LESS")) -> OK | C40: =IF(C38>=22,"OK",IF(C38<=22,"LESS")) -> OK | D40: =IF(D38>=22,"OK",IF(D38<=22,"LESS")) -> OK | E40: =IF(E38>=22,"OK",IF(E38<=22,"LESS")) -> OK | F40: =IF(F38>=22,"OK",IF(F38<=22,"LESS")) -> OK | G40: =IF(G38>=22,"OK",IF(G38<=22,"LESS")) -> OK | H40: =IF(H38>=22,"OK",IF(H38<=22,"LESS")) -> OK | I40: =IF(I38>=22,"OK",IF(I38<=22,"LESS")) -> OK | ... Q40: =IF(Q38>=22,"OK",IF(Q38<=22,"LESS")) -> OK
A43: Done by | B43: RAHUL
A45: Comment

Sheet 08
A1: Station: | B1: BHATAGAON RAIPUR
A2: Date: | B2: =$A$9 -> 08-06-2024 01:00 | D2: Power Off | G2: Pw.Off | L2: Link Fail | N2: Link F | P2: Maintenance | R2: Maint.
A3: Report Type: | B3: Mean | D3: Calibration | G3: Calib. | L3: Data Fail | N3: Data F | P3: Invalid | R3: Invalid
A4: Time Base: | B4: 01 Hour | D4: Zero Referrence | G4: Z.Ref | L4: Warm Up | N4: Wm. Up
A7: Date & Time | B7: NO_BHATAGAON | C7: NO2_BHATAGAON | D7: NOX_BHATAGAON | E7: SO2_BHATAGAON | F7: O3_BHATAGAON | G7: PM10_BHATAGAON | H7: PM2_5_BHATAGAON | I7: BENZ_BHATAGAON | J7: WS_BHATAGAON | K7: WD_BHATAGAON | L7: TEMP_BHATAGAON | M7: HUM BHATAGAON | N7: SR_BHATAGAON | O7: RG_BHATAGAON | P7: CO_BHATAGAON | Q7: NH3_BHATAGAON
B8: ug/m3 | C8: ug/m3 | D8: ppb | E8: ug/m3 | F8: ug/m3 | G8: mg/m3 | H8: ug/m3 | I8: ug/m3 | J8: m/sec | K8: deg | L8: degreC | M8: % | N8: w/m2 | O8: mm | P8: ug/m3 | Q8: ug/m3
A9: 08-06-2024 01:00 | B9: 2.66 | C9: 1.22 | D9: 3.91 | E9: 2.8 | F9: 5.07 | G9: 21.51 | H9: 8.84 | I9: 3.46 | J9: 0.54 | K9: 352 | L9: 27.14 | M9: 52.83 | N9: 16.3 | O9: 0 | P9: 0.26 | Q9: 9.44
A10: 08-06-2024 02:00 | B10: 2.48 | C10: 1.03 | D10: 3.68 | E10: 2.49 | F10: 5.74 | G10: 21.51 | H10: 8.84 | I10: 3.63 | J10: 0.66 | K10: 207.58 | L10: 27.02 | M10: 60.14 | N10: 16.3 | O10: 0 | P10: 0.25 | Q10: 9.43
A11: 08-06-2024 03:00 | B11: 2.46 | C11: 0.84 | D11: 3.55 | E11: 2.44 | F11: 5.27 | G11: 22.1 | H11: 7.94 | I11: 3.34 | J11: 0.75 | K11: 349.76 | L11: 26.37 | M11: 65.52 | N11: 16.6 | O11: 0 | P11: 0.24 | Q11: 9.43
A12: 08-06-2024 04:00 | B12: 2.58 | C12: 1.22 | D12: 3.85 | E12: 2.17 | F12: 4.04 | G12: 22.1 | H12: 8.13 | I12: 3.13 | J12: 1.26 | K12: 210.93 | L12: 26.3 | M12: 69.85 | N12: 16.6 | O12: 0 | P12: 0.23 | Q12: 9.34
A13: 08-06-2024 05:00 | B13: 2.57 | C13: 0.93 | D13: 3.7 | E13: 1.31 | F13: 4.1 | G13: 20.43 | H13: 8.13 | I13: 3.97 | J13: 0.88 | K13: 218.39 | L13: 26.13 | M13: 72.35 | N13: 16.6 | O13: 0 | P13: 0.24 | Q13: 9.42
A14: 08-06-2024 06:00 | B14: 2.44 | C14: 0.78 | D14: 3.51 | E14: 1.62 | F14: 4.51 | G14: 22.41 | H14: 6.34 | I14: 4.53 | J14: 1.41 | K14: 284.02 | L14: 26.14 | M14: 73.74 | N14: 58.1 | O14: 0 | P14: 0.25 | Q14: 9.46
A15: 08-06-2024 07:00 | B15: 2.55 | C15: 1.06 | D15: 3.74 | E15: 1.29 | F15: 4.88 | G15: 23.05 | H15: 9.38 | I15: 4.4 | J15: 0.58 | K15: 351.09 | L15: 28.12 | M15: 72.82 | N15: 171.8 | O15: 0 | P15: 0.28 | Q15: 9.44
A16: 08-06-2024 08:00 | B16: 2.59 | C16: 1.35 | D16: 3.93 | E16: 3.03 | F16: 7.29 | G16: 26.97 | H16: 10.52 | I16: 4.02 | J16: 0.8 | K16: 30.49 | L16: 29.76 | M16: 63.18 | N16: 418.2 | O16: 0 | P16: 0.32 | Q16: 9.4
A17: 08-06-2024 09:00 | B17: 2.49 | C17: 0.89 | D17: 3.6 | E17: 2.47 | F17: 9.56 | G17: 26.97 | H17: 10.52 | I17: 3.01 | J17: 0.59 | K17: 22.85 | L17: 30.76 | M17: 57.4 | N17: 489.4 | O17: 0 | P17: 0.31 | Q17: 9.34
A18: 08-06-2024 10:00 | B18: 2.31 | C18: 0.43 | D18: 3.21 | E18: 2.84 | F18: 8.7 | G18: 26.2 | H18: 9.66 | I18: 2.2 | J18: 0.39 | K18: 349.91 | L18: 32.08 | M18: 57.27 | N18: 663.1 | O18: 0 | P18: 0.38 | Q18: 9.38
A19: 08-06-2024 11:00 | B19: 2.48 | C19: 1.06 | D19: 3.69 | E19: 2.47 | F19: 8.82 | G19: 29.59 | H19: 11.46 | I19: 2.68 | J19: 0.68 | K19: 327.56 | L19: 34.2 | M19: 48.49 | N19: 796.2 | O19: 0 | P19: 0.47 | Q19: 9.41
A20: 08-06-2024 12:00 | B20: 2.38 | C20: 0.65 | D20: 3.39 | E20: 2.63 | F20: 8.71 | G20: 29.73 | H20: 15.06 | I20: 2.72 | J20: 0.69 | K20: 340.31 | L20: 35.79 | M20: 41.7 | N20: 843 | O20: 0 | P20: 0.47 | Q20: 9.39
... A32: 08-06-2024 24:00 | B32: 2.71 | C32: 1.94 | D32: 4.34 | E32: 1.26 | F32: 6.81 | G32: 55.99 | H32: 18.38 | I32: 3.48 | J32: 1.74 | K32: 230.96 | L32: 24.79 | M32: 76.61 | N32: 17.1 | O32: 0 | P32: 0.46 | Q32: 9.43
A34: Min | B34: =MIN(B9:B32) -> 2.3 | C34: =MIN(C9:C32) -> 0.37 | D34: =MIN(D9:D32) -> 3.16 | E34: =MIN(E9:E32) -> 0.74 | F34: =MIN(F9:F32) -> 4.04 | G34: =MIN(G9:G32) -> 20.43 | H34: =MIN(H9:H32) -> 6.34 | I34: =MIN(I9:I32) -> 2.2 | ... Q34: =MIN(Q9:Q32) -> 9.31
A35: Max | B35: =MAX(B9:B32) -> 2.71 | C35: =MAX(C9:C32) -> 1.94 | D35: =MAX(D9:D32) -> 4.34 | E35: =MAX(E9:E32) -> 3.03 | F35: =MAX(F9:F32) -> 9.56 | G35: =MAX(G9:G32) -> 63.11 | H35: =MAX(H9:H32) -> 20.95 | I35: =MAX(I9:I32) -> 5.44 | ... Q35: =MAX(Q9:Q32) -> 9.49
A36: Avg | B36: =AVERAGE(B9:B32) -> 2.51 | C36: =AVERAGE(C9:C32) -> 1.0866667 | D36: =AVERAGE(D9:D32) -> 3.7229167 | E36: =AVERAGE(E9:E32) -> 1.9783333 | F36: =AVERAGE(F9:F32) -> 6.74125 | G36: =AVERAGE(G9:G32) -> 35.482083 | H36: =AVERAGE(H9:H32) -> 13.594583 | I36: =AVERAGE(I9:I32) -> 3.70625 | ... Q36: =AVERAGE(Q9:Q32) -> 9.4016667
A37: Stdev | B37: =STDEV(B9:B32) -> 0.11500473 | C37: =STDEV(C9:C32) -> 0.41990337 | D37: =STDEV(D9:D32) -> 0.31160844 | E37: =STDEV(E9:E32) -> 0.69832512 | F37: =STDEV(F9:F32) -> 1.7147729 | G37: =STDEV(G9:G32) -> 14.267279 | H37: =STDEV(H9:H32) -> 4.6492318 | I37: =STDEV(I9:I32) -> 0.83252269 | ... Q37: =STDEV(Q9:Q32) -> 0.050705172
A38: Num | B38: =COUNT(B9:B32) -> 24 | C38: =COUNT(C9:C32) -> 24 | D38: =COUNT(D9:D32) -> 24 | E38: =COUNT(E9:E32) -> 24 | F38: =COUNT(F9:F32) -> 24 | G38: =COUNT(G9:G32) -> 24 | H38: =COUNT(H9:H32) -> 24 | I38: =COUNT(I9:I32) -> 24 | ... Q38: =COUNT(Q9:Q32) -> 24
A39: DCR | B39: =IF(B38>=22,">90%",IF(B38<=22,"<90%")) -> >90% | C39: =IF(C38>=22,">90%",IF(C38<=22,"<90%")) -> >90% | D39: =IF(D38>=22,">90%",IF(D38<=22,"<90%")) -> >90% | E39: =IF(E38>=22,">90%",IF(E38<=22,"<90%")) -> >90% | F39: =IF(F38>=22,">90%",IF(F38<=22,"<90%")) -> >90% | G39: =IF(G38>=22,">90%",IF(G38<=22,"<90%")) -> >90% | H39: =IF(H38>=22,">90%",IF(H38<=22,"<90%")) -> >90% | I39: =IF(I38>=22,">90%",IF(I38<=22,"<90%")) -> >90% | ... Q39: =IF(Q38>=22,">90%",IF(Q38<=22,"<90%")) -> >90%
A40: Status | B40: =IF(B38>=22,"OK",IF(B38<=22,"LESS")) -> OK | C40: =IF(C38>=22,"OK",IF(C38<=22,"LESS")) -> OK | D40: =IF(D38>=22,"OK",IF(D38<=22,"LESS")) -> OK | E40: =IF(E38>=22,"OK",IF(E38<=22,"LESS")) -> OK | F40: =IF(F38>=22,"OK",IF(F38<=22,"LESS")) -> OK | G40: =IF(G38>=22,"OK",IF(G38<=22,"LESS")) -> OK | H40: =IF(H38>=22,"OK",IF(H38<=22,"LESS")) -> OK | I40: =IF(I38>=22,"OK",IF(I38<=22,"LESS")) -> OK | ... Q40: =IF(Q38>=22,"OK",IF(Q38<=22,"LESS")) -> OK
A43: Done by | B43: RAHUL
A45: Comment

Sheet 09
A1: Station: | B1: BHATAGAON RAIPUR
A2: Date: | B2: =$A$9 -> 09-06-2024 01:00 | D2: Power Off | G2: Pw.Off | L2: Link Fail | N2: Link F | P2: Maintenance | R2: Maint.
A3: Report Type: | B3: Mean | D3: Calibration | G3: Calib. | L3: Data Fail | N3: Data F | P3: Invalid | R3: Invalid
A4: Time Base: | B4: 01 Hour | D4: Zero Referrence | G4: Z.Ref | L4: Warm Up | N4: Wm. Up
A7: Date & Time | B7: NO_BHATAGAON | C7: NO2_BHATAGAON | D7: NOX_BHATAGAON | E7: SO2_BHATAGAON | F7: O3_BHATAGAON | G7: PM10_BHATAGAON | H7: PM2_5_BHATAGAON | I7: BENZ_BHATAGAON | J7: WS_BHATAGAON | K7: WD_BHATAGAON | L7: TEMP_BHATAGAON | M7: HUM BHATAGAON | N7: SR_BHATAGAON | O7: RG_BHATAGAON | P7: CO_BHATAGAON | Q7: NH3_BHATAGAON
B8: ug/m3 | C8: ug/m3 | D8: ppb | E8: ug/m3 | F8: ug/m3 | G8: mg/m3 | H8: ug/m3 | I8: ug/m3 | J8: m/sec | K8: deg | L8: degreC | M8: % | N8: w/m2 | O8: mm | P8: ug/m3 | Q8: ug/m3
A9: 09-06-2024 01:00 | B9: 2.69 | C9: 1.68 | D9: 4.18 | E9: 1.89 | F9: 5.5 | G9: 42.22 | H9: 16.14 | I9: 3.19 | J9: 0.38 | K9: 314.8 | L9: 24.61 | M9: 76.28 | N9: 16.5 | O9: 0 | P9: 0.41 | Q9: 9.45
A10: 09-06-2024 02:00 | B10: 2.88 | C10: 2.85 | D10: 4.94 | E10: 1.87 | F10: 5.71 | G10: 30.13 | H10: 13.36 | I10: 3.02 | J10: 0.43 | K10: 198.99 | L10: 24.82 | M10: 74.87 | N10: 16.6 | O10: 0 | P10: 0.36 | Q10: 9.42
A11: 09-06-2024 03:00 | B11: 2.77 | C11: 2 | D11: 4.41 | E11: 1.54 | F11: 5 | G11: 24.62 | H11: 9.78 | I11: 3.04 | J11: 1.14 | K11: 202.57 | L11: 24.59 | M11: 80.29 | N11: 16.9 | O11: 0 | P11: 0.33 | Q11: 9.36
A12: 09-06-2024 04:00 | B12: 2.65 | C12: 1.19 | D12: 3.89 | E12: 1.66 | F12: 4.56 | G12: 20.96 | H12: 10.56 | I12: 3.38 | J12: 1.2 | K12: 200.55 | L12: 23.97 | M12: 85.88 | N12: 16.7 | O12: 0 | P12: 0.3 | Q12: 9.41
A13: 09-06-2024 05:00 | B13: 2.73 | C13: 1.83 | D13: 4.28 | E13: 0.95 | F13: 4.92 | G13: 20.96 | H13: 10.56 | I13: 3.64 | J13: 0.63 | K13: 257.4 | L13: 23.79 | M13: 86.78 | N13: 16.7 | O13: 0 | P13: 0.3 | Q13: 9.42
A14: 09-06-2024 06:00 | B14: 2.73 | C14: 1.91 | D14: 4.33 | E14: 0.83 | F14: 4.96 | G14: 17.96 | H14: 9.51 | I14: 3.38 | J14: 1.26 | K14: 192.93 | L14: 24.04 | M14: 86.79 | N14: 43.6 | O14: 0 | P14: 0.3 | Q14: 9.38
A15: 09-06-2024 07:00 | B15: 2.75 | C15: 1.79 | D15: 4.28 | E15: 0.59 | F15: 4.8 | G15: 17.96 | H15: 7.45 | I15: 3.22 | J15: 1.27 | K15: 199.85 | L15: 25.72 | M15: 84.77 | N15: 169.8 | O15: 0 | P15: 0.29 | Q15: 9.43
A16: 09-06-2024 08:00 | B16: 2.33 | C16: 0.46 | D16: 3.25 | E16: 1.33 | F16: 4.69 | G16: 18.79 | H16: 9.35 | I16: 3.45 | J16: 0.9 | K16: 188.65 | L16: 28.79 | M16: 75.9 | N16: 446.3 | O16: 0 | P16: 0.29 | Q16: 9.4
A17: 09-06-2024 09:00 | B17: 2.69 | C17: 1.53 | D17: 4.1 | E17: 2.07 | F17: 5.8 | G17: 23.87 | H17: 9.35 | I17: 3.57 | J17: 0.53 | K17: 357.01 | L17: 31.21 | M17: 61.2 | N17: 619.7 | O17: 0 | P17: 0.32 | Q17: 9.44
A18: 09-06-2024 10:00 | B18: 2.4 | C18: 0.87 | D18: 3.53 | E18: 1.82 | F18: 7.33 | G18: 24.18 | H18: 9.32 | I18: 3.37 | J18: 0.71 | K18: 340.43 | L18: 36.09 | M18: 52.3 | N18: 754.6 | O18: 0 | P18: 0.38 | Q18: 9.41
A19: 09-06-2024 11:00 | B19: 2.51 | C19: 1.21 | D19: 3.79 | E19: 1.64 | F19: 7 | G19: 26.58 | H19: 9.28 | I19: 3.15 | J19: 1.41 | K19: 340.75 | L19: 38.18 | M19: 42.6 | N19: 847.9 | O19: 0 | P19: 0.49 | Q19: 9.37
A20: 09-06-2024 12:00 | B20: 2.44 | C20: 0.99 | D20: 3.62 | E20: 1.66 | F20: 7.03 | G20: 30.44 | H20: 14.78 | I20: 3.19 | J20: 0.92 | K20: 343.91 | L20: 38.43 | M20: 37.94 | N20: 881.4 | O20: 0 | P20: 0.49 | Q20: 9.37
... A32: 09-06-2024 24:00 | B32: 4.47 | C32: 6.31 | D32: 8.02 | E32: 2.45 | F32: 4.03 | G32: 48.09 | H32: 16.37 | I32: 7.76 | J32: 0.63 | K32: 302.38 | L32: 26.4 | M32: 78.67 | N32: 15.9 | O32: 0 | P32: 0.74 | Q32: 9.68
A34: Min | B34: =MIN(B9:B32) -> 2.33 | C34: =MIN(C9:C32) -> 0.46 | D34: =MIN(D9:D32) -> 3.25 | E34: =MIN(E9:E32) -> 0.59 | F34: =MIN(F9:F32) -> 3.68 | G34: =MIN(G9:G32) -> 17.96 | H34: =MIN(H9:H32) -> 7.45 | I34: =MIN(I9:I32) -> 3.02 | ... Q34: =MIN(Q9:Q32) -> 9.29
A35: Max | B35: =MAX(B9:B32) -> 4.47 | C35: =MAX(C9:C32) -> 6.31 | D35: =MAX(D9:D32) -> 8.02 | E35: =MAX(E9:E32) -> 2.45 | F35: =MAX(F9:F32) -> 10.77 | G35: =MAX(G9:G32) -> 64.42 | H35: =MAX(H9:H32) -> 20.2 | I35: =MAX(I9:I32) -> 9.1 | ... Q35: =MAX(Q9:Q32) -> 9.69
A36: Avg | B36: =AVERAGE(B9:B32) -> 2.75375 | C36: =AVERAGE(C9:C32) -> 1.7795833 | D36: =AVERAGE(D9:D32) -> 4.28125 | E36: =AVERAGE(E9:E32) -> 1.6825 | F36: =AVERAGE(F9:F32) -> 5.7375 | G36: =AVERAGE(G9:G32) -> 37.6925 | H36: =AVERAGE(H9:H32) -> 14.045417 | I36: =AVERAGE(I9:I32) -> 4.8525 | ... Q36: =AVERAGE(Q9:Q32) -> 9.4441667
A37: Stdev | B37: =STDEV(B9:B32) -> 0.47469727 | C37: =STDEV(C9:C32) -> 1.2574698 | D37: =STDEV(D9:D32) -> 1.032314 | E37: =STDEV(E9:E32) -> 0.4508181 | F37: =STDEV(F9:F32) -> 1.7353693 | G37: =STDEV(G9:G32) -> 17.221939 | H37: =STDEV(H9:H32) -> 4.0740803 | I37: =STDEV(I9:I32) -> 2.1851082 | ... Q37: =STDEV(Q9:Q32) -> 0.11549202
A38: Num | B38: =COUNT(B9:B32) -> 24 | C38: =COUNT(C9:C32) -> 24 | D38: =COUNT(D9:D32) -> 24 | E38: =COUNT(E9:E32) -> 24 | F38: =COUNT(F9:F32) -> 24 | G38: =COUNT(G9:G32) -> 24 | H38: =COUNT(H9:H32) -> 24 | I38: =COUNT(I9:I32) -> 24 | ... Q38: =COUNT(Q9:Q32) -> 24
A39: DCR | B39: =IF(B38>=22,">90%",IF(B38<=22,"<90%")) -> >90% | C39: =IF(C38>=22,">90%",IF(C38<=22,"<90%")) -> >90% | D39: =IF(D38>=22,">90%",IF(D38<=22,"<90%")) -> >90% | E39: =IF(E38>=22,">90%",IF(E38<=22,"<90%")) -> >90% | F39: =IF(F38>=22,">90%",IF(F38<=22,"<90%")) -> >90% | G39: =IF(G38>=22,">90%",IF(G38<=22,"<90%")) -> >90% | H39: =IF(H38>=22,">90%",IF(H38<=22,"<90%")) -> >90% | I39: =IF(I38>=22,">90%",IF(I38<=22,"<90%")) -> >90% | ... Q39: =IF(Q38>=22,">90%",IF(Q38<=22,"<90%")) -> >90%
A40: Status | B40: =IF(B38>=22,"OK",IF(B38<=22,"LESS")) -> OK | C40: =IF(C38>=22,"OK",IF(C38<=22,"LESS")) -> OK | D40: =IF(D38>=22,"OK",IF(D38<=22,"LESS")) -> OK | E40: =IF(E38>=22,"OK",IF(E38<=22,"LESS")) -> OK | F40: =IF(F38>=22,"OK",IF(F38<=22,"LESS")) -> OK | G40: =IF(G38>=22,"OK",IF(G38<=22,"LESS")) -> OK | H40: =IF(H38>=22,"OK",IF(H38<=22,"LESS")) -> OK | I40: =IF(I38>=22,"OK",IF(I38<=22,"LESS")) -> OK | ... Q40: =IF(Q38>=22,"OK",IF(Q38<=22,"LESS")) -> OK
A43: Done by | B43: RAHUL
A45: Comment

Sheet 10
A1: Station: | B1: BHATAGAON RAIPUR
A2: Date: | B2: =$A$9 -> 10-06-2024 01:00 | D2: Power Off | G2: Pw.Off | L2: Link Fail | N2: Link F | P2: Maintenance | R2: Maint.
A3: Report Type: | B3: Mean | D3: Calibration | G3: Calib. | L3: Data Fail | N3: Data F | P3: Invalid | R3: Invalid
A4: Time Base: | B4: 01 Hour | D4: Zero Referrence | G4: Z.Ref | L4: Warm Up | N4: Wm. Up
A7: Date & Time | B7: NO_BHATAGAON | C7: NO2_BHATAGAON | D7: NOX_BHATAGAON | E7: SO2_BHATAGAON | F7: O3_BHATAGAON | G7: PM10_BHATAGAON | H7: PM2_5_BHATAGAON | I7: BENZ_BHATAGAON | J7: WS_BHATAGAON | K7: WD_BHATAGAON | L7: TEMP_BHATAGAON | M7: HUM BHATAGAON | N7: SR_BHATAGAON | O7: RG_BHATAGAON | P7: CO_BHATAGAON | Q7: NH3_BHATAGAON
B8: ug/m3 | C8: ug/m3 | D8: ppb | E8: ug/m3 | F8: ug/m3 | G8: mg/m3 | H8: ug/m3 | I8: ug/m3 | J8: m/sec | K8: deg | L8: degreC | M8: % | N8: w/m2 | O8: mm | P8: ug/m3 | Q8: ug/m3
A9: 10-06-2024 01:00 | B9: 4.52 | C9: 6.61 | D9: 8.18 | E9: 2.87 | F9: 4.58 | G9: 50.69 | H9: 17.6 | I9: 7.58 | J9: 0.43 | K9: 262.07 | L9: 26.62 | M9: 75.51 | N9: 15.8 | O9: 0 | P9: 0.68 | Q9: 9.64
A10: 10-06-2024 02:00 | B10: 4.54 | C10: 6.65 | D10: 8.26 | E10: 2.46 | F10: 3.57 | G10: 50.69 | H10: 18.66 | I10: 6.79 | J10: 0.44 | K10: 359.13 | L10: 26.35 | M10: 80.48 | N10: 16 | O10: 0 | P10: 0.61 | Q10: 9.53
A11: 10-06-2024 03:00 | B11: 4.31 | C11: 4.82 | D11: 7.12 | E11: 2.47 | F11: 3.69 | G11: 49.16 | H11: 18.66 | I11: 7.37 | J11: 0.69 | K11: 191.7 | L11: 25.8 | M11: 80.03 | N11: 15.8 | O11: 0 | P11: 0.59 | Q11: 9.57
A12: 10-06-2024 04:00 | B12: 4.2 | C12: 5.35 | D12: 7.29 | E12: 2.72 | F12: 3.99 | G12: 43.36 | H12: 16.9 | I12: 7.52 | J12: 0.53 | K12: 205.86 | L12: 25.38 | M12: 78.64 | N12: 15.9 | O12: 0 | P12: 0.54 | Q12: 9.56
