Workbook

Sheet 01
A1: Station: | B1: BHATAGAON RAIPUR
A2: Date: | B2: =$A$9 -> 01/01/2025 01:00 | D2: Power Off | G2: Pw.Off | L2: Link Fail | N2: Link F | P2: Maintenance | R2: Maint.
A3: Report Type: | B3: Mean | D3: Calibration | G3: Calib. | L3: Data Fail | N3: Data F | P3: Invalid | R3: Invalid
A4: Time Base: | B4: 01 Hour | D4: Zero Referrence | G4: Z.Ref | L4: Warm Up | N4: Wm. Up
A7: Date & Time | B7: NO_BHATAGAON | C7: NO2__BHATAGAON | D7: NOX_BHATAGAON | E7: SO2__BHATAGAON | F7: O3__BHATAGAON | G7: PM10__BHATAGAON | H7: PM2_5__BHATAGAON | I7: BENZ__BHATAGAON | J7: WS__BHATAGAON | K7: WD__BHATAGAON | L7: TEMP__BHATAGAON | M7: HUM__BHATAGAON | N7: SR__BHATAGAON | O7: RG__BHATAGAON | P7: CO__BHATAGAON | Q7: NH3__BHATAGAON
B8: ug/m3 | C8: ug/m3 | D8: ppb | E8: ug/m3 | F8: ug/m3 | G8: mg/m3 | H8: ug/m3 | I8: ug/m3 | J8: m/sec | K8: deg | L8: degreC | M8: % | N8: w/m2 | O8: mm | P8: ug/m3 | Q8: ug/m3
A9: 01/01/2025 01:00 | B9: 72.09 | C9: 54.16 | D9: 84.73 | E9: 8.37 | F9: 2.13 | G9: 108.12 | H9: 36.06 | I9: Invalid | J9: 1.42 | K9: 301.73 | L9: 13.72 | M9: 83.36 | N9: 84.5 | O9: 0 | P9: 1.58 | Q9: 9.61
A10: 01/01/2025 02:00 | B10: 62.45 | C10: 52.15 | D10: 75.95 | E10: 8.16 | F10: 2.13 | G10: 91.82 | H10: 36.06 | I10: Invalid | J10: 2.6 | K10: 267.24 | L10: 14.19 | M10: 75.3 | N10: 87.5 | O10: 0 | P10: 1.39 | Q10: 9.54
A11: 01/01/2025 03:00 | B11: 47.97 | C11: 51.09 | D11: 63.73 | E11: 7.42 | F11: 2.13 | G11: 81.3 | H11: 34.07 | I11: Invalid | J11: 2.77 | K11: 108.16 | L11: 14.17 | M11: 62.76 | N11: 87.7 | O11: 0 | P11: 1.23 | Q11: 8.68
A12: 01/01/2025 04:00 | B12: 34.93 | C12: 49.24 | D12: 52.23 | E12: 7.28 | F12: 2.13 | G12: 58.72 | H12: 32.25 | I12: Invalid | J12: 2.45 | K12: 105.85 | L12: 13.93 | M12: 68.9 | N12: 96.3 | O12: 0 | P12: 1.05 | Q12: 8.21
A13: 01/01/2025 05:00 | B13: 27.16 | C13: 48.4 | D13: 45.69 | E13: 7.17 | F13: 2.13 | G13: 57.13 | H13: 29.92 | I13: Invalid | J13: 1.03 | K13: 332.5 | L13: 12.98 | M13: 70.88 | N13: 99.5 | O13: 0 | P13: 0.89 | Q13: 8.21
A14: 01/01/2025 06:00 | B14: 25.89 | C14: 50.29 | D14: 45.66 | E14: 7.16 | F14: 2.13 | G14: 63.22 | H14: 28.58 | I14: Invalid | J14: 1.25 | K14: 321.58 | L14: 12.14 | M14: 81.27 | N14: 95.1 | O14: 0 | P14: 0.83 | Q14: 8.21
A15: 01/01/2025 07:00 | B15: 26.78 | C15: 50.6 | D15: 46.54 | E15: 7.39 | F15: 2.13 | G15: 80.81 | H15: 27.96 | I15: Invalid | J15: 3.16 | K15: 116.95 | L15: 12.04 | M15: 83.1 | N15: 105 | O15: 0 | P15: 0.78 | Q15: 8.21
A16: 01/01/2025 08:00 | B16: 21.79 | C16: 48.75 | D16: 41.22 | E16: 7.34 | F16: 2.13 | G16: 85.81 | H16: 33.64 | I16: Invalid | J16: 3.2 | K16: 122.38 | L16: 13.16 | M16: 75.84 | N16: 206.8 | O16: 0 | P16: 0.85 | Q16: 8.21
A17: 01/01/2025 09:00 | B17: 17.04 | C17: 48.61 | D17: 37.68 | E17: 6.12 | F17: 2.13 | G17: 85.81 | H17: 33.64 | I17: Invalid | J17: 2.78 | K17: 154.92 | L17: 16.47 | M17: 68.31 | N17: 381.6 | O17: 0 | P17: 0.82 | Q17: 8.21
A18: 01/01/2025 10:00 | B18: 12.97 | C18: 49.88 | D18: 34.42 | E18: 5.91 | F18: 2.13 | G18: 72.32 | H18: 30.48 | I18: Invalid | J18: 1.74 | K18: 280.04 | L18: 20.46 | M18: 57.41 | N18: 445.6 | O18: 0 | P18: 0.78 | Q18: 8.21
A19: 01/01/2025 11:00 | B19: 9.21 | C19: 51.35 | D19: 32.61 | E19: 6.01 | F19: 2.13 | G19: 66.46 | H19: 27.97 | I19: Invalid | J19: 1.4 | K19: 236.56 | L19: 20.48 | M19: 49.53 | N19: 544.3 | O19: 0 | P19: 0.76 | Q19: 8.21
A20: 01/01/2025 12:00 | B20: Pw.Off | C20: Pw.Off | D20: Pw.Off | E20: Pw.Off | F20: Pw.Off | G20: Pw.Off | H20: Pw.Off | I20: Pw.Off | J20: Pw.Off | K20: Pw.Off | L20: Pw.Off | M20: Pw.Off | N20: Pw.Off | O20: Pw.Off | P20: Pw.Off | Q20: Pw.Off
A21: 01/01/2025 13:00 | B21: Pw.Off | C21: Pw.Off | D21: Pw.Off | E21: Pw.Off | F21: Pw.Off | G21: Pw.Off | H21: Pw.Off | I21: Pw.Off | J21: Pw.Off | K21: Pw.Off | L21: Pw.Off | M21: Pw.Off | N21: Pw.Off | O21: Pw.Off | P21: Pw.Off | Q21: Pw.Off
A22: 01/01/2025 14:00 | B22: Pw.Off | C22: Pw.Off | D22: Pw.Off | E22: Pw.Off | F22: Pw.Off | G22: Pw.Off | H22: Pw.Off | I22: Pw.Off | J22: Pw.Off | K22: Pw.Off | L22: Pw.Off | M22: Pw.Off | N22: Pw.Off | O22: Pw.Off | P22: Pw.Off | Q22: Pw.Off
A23: 01/01/2025 15:00 | B23: Pw.Off | C23: Pw.Off | D23: Pw.Off | E23: Pw.Off | F23: Pw.Off | G23: Pw.Off | H23: Pw.Off | I23: Pw.Off | J23: Pw.Off | K23: Pw.Off | L23: Pw.Off | M23: Pw.Off | N23: Pw.Off | O23: Pw.Off | P23: Pw.Off | Q23: Pw.Off
A24: 01/01/2025 16:00 | B24: Pw.Off | C24: Pw.Off | D24: Pw.Off | E24: Pw.Off | F24: Pw.Off | G24: Pw.Off | H24: Pw.Off | I24: Pw.Off | J24: Pw.Off | K24: Pw.Off | L24: Pw.Off | M24: Pw.Off | N24: Pw.Off | O24: Pw.Off | P24: Pw.Off | Q24: Pw.Off
A25: 01/01/2025 17:00 | B25: Pw.Off | C25: Pw.Off | D25: Pw.Off | E25: Pw.Off | F25: Pw.Off | G25: Pw.Off | H25: Pw.Off | I25: Pw.Off | J25: Pw.Off | K25: Pw.Off | L25: Pw.Off | M25: Pw.Off | N25: Pw.Off | O25: Pw.Off | P25: Pw.Off | Q25: Pw.Off
A26: 01/01/2025 18:00 | B26: Pw.Off | C26: Pw.Off | D26: Pw.Off | E26: Pw.Off | F26: Pw.Off | G26: Pw.Off | H26: Pw.Off | I26: Pw.Off | J26: Pw.Off | K26: Pw.Off | L26: Pw.Off | M26: Pw.Off | N26: Pw.Off | O26: Pw.Off | P26: Pw.Off | Q26: Pw.Off
A27: 01/01/2025 19:00 | B27: Pw.Off | C27: Pw.Off | D27: Pw.Off | E27: Pw.Off | F27: Pw.Off | G27: Pw.Off | H27: Pw.Off | I27: Pw.Off | J27: Pw.Off | K27: Pw.Off | L27: Pw.Off | M27: Pw.Off | N27: Pw.Off | O27: Pw.Off | P27: Pw.Off | Q27: Pw.Off
A28: 01/01/2025 20:00 | B28: Pw.Off | C28: Pw.Off | D28: Pw.Off | E28: Pw.Off | F28: Pw.Off | G28: Pw.Off | H28: Pw.Off | I28: Pw.Off | J28: Pw.Off | K28: Pw.Off | L28: Pw.Off | M28: Pw.Off | N28: Pw.Off | O28: Pw.Off | P28: Pw.Off | Q28: Pw.Off
A29: 01/01/2025 21:00 | B29: Pw.Off | C29: Pw.Off | D29: Pw.Off | E29: Pw.Off | F29: Pw.Off | G29: Pw.Off | H29: Pw.Off | I29: Pw.Off | J29: Pw.Off | K29: Pw.Off | L29: Pw.Off | M29: Pw.Off | N29: Pw.Off | O29: Pw.Off | P29: Pw.Off | Q29: Pw.Off
A30: 01/01/2025 22:00 | B30: Pw.Off | C30: Pw.Off | D30: Pw.Off | E30: Pw.Off | F30: Pw.Off | G30: Pw.Off | H30: Pw.Off | I30: Pw.Off | J30: Pw.Off | K30: Pw.Off | L30: Pw.Off | M30: Pw.Off | N30: Pw.Off | O30: Pw.Off | P30: Pw.Off | Q30: Pw.Off
A31: 01/01/2025 23:00 | B31: Pw.Off | C31: Pw.Off | D31: Pw.Off | E31: Pw.Off | F31: Pw.Off | G31: Pw.Off | H31: Pw.Off | I31: Pw.Off | J31: Pw.Off | K31: Pw.Off | L31: Pw.Off | M31: Pw.Off | N31: Pw.Off | O31: Pw.Off | P31: Pw.Off | Q31: Pw.Off
A32: 01/01/2025 24:00 | B32: Pw.Off | C32: Pw.Off | D32: Pw.Off | E32: Pw.Off | F32: Pw.Off | G32: Pw.Off | H32: Pw.Off | I32: Pw.Off | J32: Pw.Off | K32: Pw.Off | L32: Pw.Off | M32: Pw.Off | N32: Pw.Off | O32: Pw.Off | P32: Pw.Off | Q32: Pw.Off
A34: Min | B34: =MIN(B9:B32) -> 9.21 | C34: =MIN(C9:C32) -> 48.4 | D34: =MIN(D9:D32) -> 32.61 | E34: =MIN(E9:E32) -> 5.91 | F34: =MIN(F9:F32) -> 2.13 | G34: =MIN(G9:G32) -> 57.13 | H34: =MIN(H9:H32) -> 27.96 | I34: =MIN(I9:I32) -> 0 | ... Q34: =MIN(Q9:Q32) -> 8.21
A35: Max | B35: =MAX(B9:B32) -> 72.09 | C35: =MAX(C9:C32) -> 54.16 | D35: =MAX(D9:D32) -> 84.73 | E35: =MAX(E9:E32) -> 8.37 | F35: =MAX(F9:F32) -> 2.13 | G35: =MAX(G9:G32) -> 108.12 | H35: =MAX(H9:H32) -> 36.06 | I35: =MAX(I9:I32) -> 0 | ... Q35: =MAX(Q9:Q32) -> 9.61
A36: Avg | B36: =AVERAGE(B9:B32) -> 32.570909 | C36: =AVERAGE(C9:C32) -> 50.410909 | D36: =AVERAGE(D9:D32) -> 50.950909 | E36: =AVERAGE(E9:E32) -> 7.1209091 | F36: =AVERAGE(F9:F32) -> 2.13 | G36: =AVERAGE(G9:G32) -> 77.410909 | H36: =AVERAGE(H9:H32) -> 31.875455 | I36: =AVERAGE(I9:I32) -> #DIV/0! | ... Q36: =AVERAGE(Q9:Q32) -> 8.5009091
A37: Stdev | B37: =STDEV(B9:B32) -> 20.228761 | C37: =STDEV(C9:C32) -> 1.7370115 | D37: =STDEV(D9:D32) -> 16.989754 | E37: =STDEV(E9:E32) -> 0.81125156 | F37: =STDEV(F9:F32) -> 4.6576469e-16 | G37: =STDEV(G9:G32) -> 15.576667 | H37: =STDEV(H9:H32) -> 3.0564501 | I37: =STDEV(I9:I32) -> #DIV/0! | ... Q37: =STDEV(Q9:Q32) -> 0.54944435
A38: Num | B38: =COUNT(B9:B32)+13 -> 24 | C38: =COUNT(C9:C32)+13 -> 24 | D38: =COUNT(D9:D32)+13 -> 24 | E38: =COUNT(E9:E32)+13 -> 24 | F38: =COUNT(F9:F32)+13 -> 24 | G38: =COUNT(G9:G32)+13 -> 24 | H38: =COUNT(H9:H32)+13 -> 24 | I38: =COUNT(I9:I32) -> 0 | J38: =COUNT(J9:J32)+13 -> 24 | K38: =COUNT(K9:K32)+13 -> 24 | L38: =COUNT(L9:L32)+13 -> 24 | M38: =COUNT(M9:M32)+13 -> 24 | N38: =COUNT(N9:N32)+13 -> 24 | O38: =COUNT(O9:O32)+13 -> 24 | P38: =COUNT(P9:P32)+13 -> 24 | Q38: =COUNT(Q9:Q32)+13 -> 24
A39: DCR | B39: =IF(B38>=22,">90%",IF(B38<=22,"<90%")) -> >90% | C39: =IF(C38>=22,">90%",IF(C38<=22,"<90%")) -> >90% | D39: =IF(D38>=22,">90%",IF(D38<=22,"<90%")) -> >90% | E39: =IF(E38>=22,">90%",IF(E38<=22,"<90%")) -> >90% | F39: =IF(F38>=22,">90%",IF(F38<=22,"<90%")) -> >90% | G39: =IF(G38>=22,">90%",IF(G38<=22,"<90%")) -> >90% | H39: =IF(H38>=22,">90%",IF(H38<=22,"<90%")) -> >90% | I39: =IF(I38>=22,">90%",IF(I38<=22,"<90%")) -> <90% | ... Q39: =IF(Q38>=22,">90%",IF(Q38<=22,"<90%")) -> >90%
A40: Status | B40: =IF(B38>=22,"OK",IF(B38<=22,"LESS")) -> OK | C40: =IF(C38>=22,"OK",IF(C38<=22,"LESS")) -> OK | D40: =IF(D38>=22,"OK",IF(D38<=22,"LESS")) -> OK | E40: =IF(E38>=22,"OK",IF(E38<=22,"LESS")) -> OK | F40: =IF(F38>=22,"OK",IF(F38<=22,"LESS")) -> OK | G40: =IF(G38>=22,"OK",IF(G38<=22,"LESS")) -> OK | H40: =IF(H38>=22,"OK",IF(H38<=22,"LESS")) -> OK | I40: =IF(I38>=22,"OK",IF(I38<=22,"LESS")) -> LESS | ... Q40: =IF(Q38>=22,"OK",IF(Q38<=22,"LESS")) -> OK
A43: Done by | B43: RAHUL
A45: Comment

Sheet 02
A1: Station: | B1: BHATAGAON RAIPUR
A2: Date: | B2: =$A$9 -> 02/01/2025 01:00 | D2: Power Off | G2: Pw.Off | L2: Link Fail | N2: Link F | P2: Maintenance | R2: Maint.
A3: Report Type: | B3: Mean | D3: Calibration | G3: Calib. | L3: Data Fail | N3: Data F | P3: Invalid | R3: Invalid
A4: Time Base: | B4: 01 Hour | D4: Zero Referrence | G4: Z.Ref | L4: Warm Up | N4: Wm. Up
A7: Date & Time | B7: NO_BHATAGAON | C7: NO2__BHATAGAON | D7: NOX_BHATAGAON | E7: SO2__BHATAGAON | F7: O3__BHATAGAON | G7: PM10__BHATAGAON | H7: PM2_5__BHATAGAON | I7: BENZ__BHATAGAON | J7: WS__BHATAGAON | K7: WD__BHATAGAON | L7: TEMP__BHATAGAON | M7: HUM__BHATAGAON | N7: SR__BHATAGAON | O7: RG__BHATAGAON | P7: CO__BHATAGAON | Q7: NH3__BHATAGAON
B8: ug/m3 | C8: ug/m3 | D8: ppb | E8: ug/m3 | F8: ug/m3 | G8: mg/m3 | H8: ug/m3 | I8: ug/m3 | J8: m/sec | K8: deg | L8: degreC | M8: % | N8: w/m2 | O8: mm | P8: ug/m3 | Q8: ug/m3
A9: 02/01/2025 01:00 | B9: 133.76 | C9: 47.92 | D9: 130.86 | E9: 8.41 | F9: 2.15 | G9: 186.39 | H9: 59.15 | I9: Invalid | J9: 2.55 | K9: 346.84 | L9: 11.01 | M9: 92.85 | N9: 98.2 | O9: 0 | P9: 2.1 | Q9: 10.31
A10: 02/01/2025 02:00 | B10: 129.21 | C10: 43.52 | D10: 124.82 | E10: 8.45 | F10: 2.13 | G10: 144.84 | H10: 59.15 | I10: Invalid | J10: 2.51 | K10: 348.63 | L10: 10.75 | M10: 97.35 | N10: 98.6 | O10: 0 | P10: 1.85 | Q10: 10.27
A11: 02/01/2025 03:00 | B11: 121.1 | C11: 42.57 | D11: 117.98 | E11: 7.57 | F11: 2.26 | G11: 132.8 | H11: 45.18 | I11: Invalid | J11: 2.61 | K11: 237.58 | L11: 11.31 | M11: 89.97 | N11: 99.1 | O11: 0 | P11: 1.69 | Q11: 10.24
A12: 02/01/2025 04:00 | B12: 100.24 | C12: 42.18 | D12: 101.03 | E12: 6.64 | F12: 2.13 | G12: 78.26 | H12: 39.87 | I12: Invalid | J12: 2.53 | K12: 227.19 | L12: 9.47 | M12: 94.23 | N12: 98.9 | O12: 0 | P12: 1.52 | Q12: 10
A13: 02/01/2025 05:00 | B13: 85.68 | C13: 40.44 | D13: 88.46 | E13: 5.9 | F13: 2.13 | G13: 78.26 | H13: 39.87 | I13: Invalid | J13: 2.18 | K13: 348.03 | L13: 9.6 | M13: 97.47 | N13: 99 | O13: 0 | P13: 1.34 | Q13: 9.93
A14: 02/01/2025 06:00 | B14: 69.85 | C14: 38.93 | D14: 74.76 | E14: 5.54 | F14: 2.13 | G14: 77.66 | H14: 16.69 | I14: Invalid | J14: 1.63 | K14: 79.94 | L14: 9.58 | M14: 79.06 | N14: 99.1 | O14: 0 | P14: 1.11 | Q14: 9.8
A15: 02/01/2025 07:00 | B15: 56.27 | C15: 39.07 | D15: 63.95 | E15: 4.77 | F15: 2.13 | G15: 47.99 | H15: 3 | I15: Invalid | J15: 1.81 | K15: 352 | L15: 9.4 | M15: 82.43 | N15: 110.5 | O15: 0 | P15: 0.92 | Q15: 9.66
A16: 02/01/2025 08:00 | B16: 50.51 | C16: 41.5 | D16: 60.29 | E16: 5.22 | F16: 2.13 | G16: 57.55 | H16: 16.29 | I16: Invalid | J16: 1.52 | K16: 328.11 | L16: 11.55 | M16: 83.65 | N16: 291.5 | O16: 0 | P16: 1 | Q16: 8.88
A17: 02/01/2025 09:00 | B17: 45.47 | C17: 43.63 | D17: 56.97 | E17: 5.53 | F17: 2.13 | G17: 59.63 | H17: 42.48 | I17: Invalid | J17: 2.94 | K17: 352.45 | L17: 16.63 | M17: 62.4 | N17: 543.6 | O17: 0 | P17: 0.93 | Q17: 8.67
A18: 02/01/2025 10:00 | B18: 41.02 | C18: 45.93 | D18: 54.69 | E18: 5.61 | F18: 2.13 | G18: 59.63 | H18: 42.48 | I18: Invalid | J18: 3.75 | K18: 338.07 | L18: 23.43 | M18: 45.28 | N18: 659.5 | O18: 0 | P18: 0.83 | Q18: 8.49
A19: 02/01/2025 11:00 | B19: 35.35 | C19: 69.39 | D19: 53.09 | E19: 8.11 | F19: 2.15 | G19: 48.81 | H19: 20.44 | I19: Invalid | J19: 3.2 | K19: 338.12 | L19: 25.49 | M19: 33.07 | N19: 732.2 | O19: 0 | P19: 0.78 | Q19: 8.21
A20: 02/01/2025 12:00 | B20: 16.28 | C20: 68.58 | D20: 47.51 | E20: 7.59 | F20: 2.13 | G20: 74.73 | H20: 27.47 | I20: Invalid | J20: 2.94 | K20: 341.83 | L20: 25.87 | M20: 32.35 | N20: 783.5 | O20: 0 | P20: 0.7 | Q20: 8.21
... A32: 02/01/2025 24:00 | B32: 112.27 | C32: 49.46 | D32: 114.49 | E32: 7.9 | F32: 2.13 | G32: 101.65 | H32: 45.07 | I32: Invalid | J32: 2.02 | K32: 339.17 | L32: 14.38 | M32: 45.36 | N32: 147.3 | O32: 0 | P32: 2.1 | Q32: 10.09
A34: Min | B34: =MIN(B9:B32) -> 5.56 | C34: =MIN(C9:C32) -> 38.93 | D34: =MIN(D9:D32) -> 35.49 | E34: =MIN(E9:E32) -> 4.77 | F34: =MIN(F9:F32) -> 2.13 | G34: =MIN(G9:G32) -> 47.99 | H34: =MIN(H9:H32) -> 3 | I34: =MIN(I9:I32) -> 0 | ... Q34: =MIN(Q9:Q32) -> 8.21
A35: Max | B35: =MAX(B9:B32) -> 134.33 | C35: =MAX(C9:C32) -> 74.67 | D35: =MAX(D9:D32) -> 136.27 | E35: =MAX(E9:E32) -> 12.13 | F35: =MAX(F9:F32) -> 5 | G35: =MAX(G9:G32) -> 242.04 | H35: =MAX(H9:H32) -> 65.25 | I35: =MAX(I9:I32) -> 0 | ... Q35: =MAX(Q9:Q32) -> 10.31
A36: Avg | B36: =AVERAGE(B9:B32) -> 66.332083 | C36: =AVERAGE(C9:C32) -> 54.432083 | D36: =AVERAGE(D9:D32) -> 79.375833 | E36: =AVERAGE(E9:E32) -> 7.54875 | F36: =AVERAGE(F9:F32) -> 2.2904167 | G36: =AVERAGE(G9:G32) -> 117.3625 | H36: =AVERAGE(H9:H32) -> 39.5325 | I36: =AVERAGE(I9:I32) -> #DIV/0! | ... Q36: =AVERAGE(Q9:Q32) -> 9.25625
A37: Stdev | B37: =STDEV(B9:B32) -> 48.098129 | C37: =STDEV(C9:C32) -> 11.637792 | D37: =STDEV(D9:D32) -> 36.183278 | E37: =STDEV(E9:E32) -> 1.991524 | F37: =STDEV(F9:F32) -> 0.59153065 | G37: =STDEV(G9:G32) -> 60.387786 | H37: =STDEV(H9:H32) -> 16.961856 | I37: =STDEV(I9:I32) -> #DIV/0! | ... Q37: =STDEV(Q9:Q32) -> 0.89493168
A38: Num | B38: =COUNT(B9:B32) -> 24 | C38: =COUNT(C9:C32) -> 24 | D38: =COUNT(D9:D32) -> 24 | E38: =COUNT(E9:E32) -> 24 | F38: =COUNT(F9:F32) -> 24 | G38: =COUNT(G9:G32) -> 24 | H38: =COUNT(H9:H32) -> 24 | I38: =COUNT(I9:I32) -> 0 | ... Q38: =COUNT(Q9:Q32) -> 24
A39: DCR | B39: =IF(B38>=22,">90%",IF(B38<=22,"<90%")) -> >90% | C39: =IF(C38>=22,">90%",IF(C38<=22,"<90%")) -> >90% | D39: =IF(D38>=22,">90%",IF(D38<=22,"<90%")) -> >90% | E39: =IF(E38>=22,">90%",IF(E38<=22,"<90%")) -> >90% | F39: =IF(F38>=22,">90%",IF(F38<=22,"<90%")) -> >90% | G39: =IF(G38>=22,">90%",IF(G38<=22,"<90%")) -> >90% | H39: =IF(H38>=22,">90%",IF(H38<=22,"<90%")) -> >90% | I39: =IF(I38>=22,">90%",IF(I38<=22,"<90%")) -> <90% | ... Q39: =IF(Q38>=22,">90%",IF(Q38<=22,"<90%")) -> >90%
A40: Status | B40: =IF(B38>=22,"OK",IF(B38<=22,"LESS")) -> OK | C40: =IF(C38>=22,"OK",IF(C38<=22,"LESS")) -> OK | D40: =IF(D38>=22,"OK",IF(D38<=22,"LESS")) -> OK | E40: =IF(E38>=22,"OK",IF(E38<=22,"LESS")) -> OK | F40: =IF(F38>=22,"OK",IF(F38<=22,"LESS")) -> OK | G40: =IF(G38>=22,"OK",IF(G38<=22,"LESS")) -> OK | H40: =IF(H38>=22,"OK",IF(H38<=22,"LESS")) -> OK | I40: =IF(I38>=22,"OK",IF(I38<=22,"LESS")) -> LESS | ... Q40: =IF(Q38>=22,"OK",IF(Q38<=22,"LESS")) -> OK
A43: Done by | B43: RAHUL
A45: Comment

Sheet 03
A1: Station: | B1: BHATAGAON RAIPUR
A2: Date: | B2: =$A$9 -> 03/01/2025 01:00 | D2: Power Off | G2: Pw.Off | L2: Link Fail | N2: Link F | P2: Maintenance | R2: Maint.
A3: Report Type: | B3: Mean | D3: Calibration | G3: Calib. | L3: Data Fail | N3: Data F | P3: Invalid | R3: Invalid
A4: Time Base: | B4: 01 Hour | D4: Zero Referrence | G4: Z.Ref | L4: Warm Up | N4: Wm. Up
A7: Date & Time | B7: NO_BHATAGAON | C7: NO2__BHATAGAON | D7: NOX_BHATAGAON | E7: SO2__BHATAGAON | F7: O3__BHATAGAON | G7: PM10__BHATAGAON | H7: PM2_5__BHATAGAON | I7: BENZ__BHATAGAON | J7: WS__BHATAGAON | K7: WD__BHATAGAON | L7: TEMP__BHATAGAON | M7: HUM__BHATAGAON | N7: SR__BHATAGAON | O7: RG__BHATAGAON | P7: CO__BHATAGAON | Q7: NH3__BHATAGAON
B8: ug/m3 | C8: ug/m3 | D8: ppb | E8: ug/m3 | F8: ug/m3 | G8: mg/m3 | H8: ug/m3 | I8: ug/m3 | J8: m/sec | K8: deg | L8: degreC | M8: % | N8: w/m2 | O8: mm | P8: ug/m3 | Q8: ug/m3
A9: 03/01/2025 01:00 | B9: 96.43 | C9: 47.6 | D9: 100.82 | E9: 6.63 | F9: 2.13 | G9: 79.14 | H9: 45.07 | I9: Invalid | J9: 2.42 | K9: 311.14 | L9: 13.26 | M9: 53.52 | N9: 147.3 | O9: 0 | P9: 1.96 | Q9: 9.93
A10: 03/01/2025 02:00 | B10: 77.85 | C10: 46.86 | D10: 85.51 | E10: 5.99 | F10: 2.13 | G10: 72.22 | H10: 33.25 | I10: Invalid | J10: 1.79 | K10: 344.76 | L10: 13.27 | M10: 44.91 | N10: 148.2 | O10: 0 | P10: 1.5 | Q10: 9.79
A11: 03/01/2025 03:00 | B11: 62.03 | C11: 44.17 | D11: 71.45 | E11: 5.51 | F11: 2.13 | G11: 53.15 | H11: 13.68 | I11: Invalid | J11: 2.76 | K11: 306.17 | L11: 12.3 | M11: 55.79 | N11: 148.6 | O11: 0 | P11: 1.26 | Q11: 9.67
A12: 03/01/2025 04:00 | B12: 51.67 | C12: 41.9 | D12: 61.95 | E12: 5.26 | F12: 2.13 | G12: 77.23 | H12: 13.68 | I12: Invalid | J12: 2.72 | K12: 357.18 | L12: 10.89 | M12: 61.58 | N12: 147.8 | O12: 0 | P12: 1.07 | Q12: 9.52
A13: 03/01/2025 05:00 | B13: 44.81 | C13: 41.4 | D13: 55.86 | E13: 5.11 | F13: 2.13 | G13: 77.23 | H13: 14.61 | I13: Invalid | J13: 2.9 | K13: 320.5 | L13: 10.64 | M13: 63.88 | N13: 148.2 | O13: 0 | P13: 0.92 | Q13: 8.78
A14: 03/01/2025 06:00 | B14: 50.99 | C14: 42.94 | D14: 61.65 | E14: 5.5 | F14: 2.13 | G14: 88.26 | H14: 150.14 | I14: Invalid | J14: 2.92 | K14: 328.62 | L14: 9.42 | M14: 94.7 | N14: 149 | O14: 0 | P14: 0.78 | Q14: 9.19
A15: 03/01/2025 07:00 | B15: 64.69 | C15: 41.34 | D15: 71.74 | E15: 6.59 | F15: 2.13 | G15: 103.14 | H15: 150.14 | I15: Invalid | J15: 2.92 | K15: 357.36 | L15: 8.53 | M15: 93.81 | N15: 160.1 | O15: 0 | P15: 0.77 | Q15: 9.76
A16: 03/01/2025 08:00 | B16: 76.64 | C16: 40.49 | D16: 81.12 | E16: 6.55 | F16: 2.13 | G16: 103.14 | H16: 37.79 | I16: Invalid | J16: 4.32 | K16: 328.18 | L16: 12.01 | M16: 77.46 | N16: 352.9 | O16: 0 | P16: 0.93 | Q16: 9.86
A17: 03/01/2025 09:00 | B17: 72.78 | C17: 42.41 | D17: 77.92 | E17: 6.9 | F17: 2.13 | G17: 98.26 | H17: 0.76 | I17: Invalid | J17: 2.36 | K17: 131.17 | L17: 18.03 | M17: 48.7 | N17: 602.3 | O17: 0 | P17: 0.89 | Q17: 9.83
A18: 03/01/2025 10:00 | B18: 59.86 | C18: 48.07 | D18: 69.37 | E18: 6.01 | F18: 2.13 | G18: 76.35 | H18: 59.39 | I18: Invalid | J18: 1.58 | K18: 141.33 | L18: 20.81 | M18: 36.13 | N18: 707.3 | O18: 0 | P18: 0.84 | Q18: 9.68
A19: 03/01/2025 11:00 | B19: 50.02 | C19: 51.71 | D19: 64.68 | E19: 5.71 | F19: 2.13 | G19: 76.35 | H19: 59.39 | I19: Invalid | J19: 1.75 | K19: 353.33 | L19: 26.68 | M19: 27.08 | N19: 733.1 | O19: 0 | P19: 0.8 | Q19: 9.73
A20: 03/01/2025 12:00 | B20: 44.3 | C20: 54.07 | D20: 61.59 | E20: 6.04 | F20: 2.13 | G20: 65.3 | H20: 23.54 | I20: Invalid | J20: 1.53 | K20: 335.28 | L20: 27.98 | M20: 20.87 | N20: 750.4 | O20: 0 | P20: 0.78 | Q20: 9.75
... A32: 03/01/2025 24:00 | B32: 226.64 | C32: 52.96 | D32: 206.7 | E32: 13.14 | F32: 2.13 | G32: 224.96 | H32: 65.28 | I32: Invalid | J32: 0.9 | K32: 315.01 | L32: 12.2 | M32: 84.38 | N32: 53.7 | O32: 0 | P32: 2.34 | Q32: 10.83
A34: Min | B34: =MIN(B9:B32) -> 16.62 | C34: =MIN(C9:C32) -> 40.49 | D34: =MIN(D9:D32) -> 42.51 | E34: =MIN(E9:E32) -> 5.11 | F34: =MIN(F9:F32) -> 2.13 | G34: =MIN(G9:G32) -> 53.15 | H34: =MIN(H9:H32) -> 0.76 | I34: =MIN(I9:I32) -> 0 | ... Q34: =MIN(Q9:Q32) -> 8.41
A35: Max | B35: =MAX(B9:B32) -> 226.64 | C35: =MAX(C9:C32) -> 62.26 | D35: =MAX(D9:D32) -> 206.7 | E35: =MAX(E9:E32) -> 13.14 | F35: =MAX(F9:F32) -> 2.13 | G35: =MAX(G9:G32) -> 224.96 | H35: =MAX(H9:H32) -> 150.14 | I35: =MAX(I9:I32) -> 0 | ... Q35: =MAX(Q9:Q32) -> 10.83
A36: Avg | B36: =AVERAGE(B9:B32) -> 74.867083 | C36: =AVERAGE(C9:C32) -> 51.56875 | D36: =AVERAGE(D9:D32) -> 84.940417 | E36: =AVERAGE(E9:E32) -> 7.4383333 | F36: =AVERAGE(F9:F32) -> 2.13 | G36: =AVERAGE(G9:G32) -> 112.40875 | H36: =AVERAGE(H9:H32) -> 43.950417 | I36: =AVERAGE(I9:I32) -> #DIV/0! | ... Q36: =AVERAGE(Q9:Q32) -> 9.65625
A37: Stdev | B37: =STDEV(B9:B32) -> 55.950512 | C37: =STDEV(C9:C32) -> 7.4418583 | D37: =STDEV(D9:D32) -> 44.737937 | E37: =STDEV(E9:E32) -> 2.5330642 | F37: =STDEV(F9:F32) -> 4.5364061e-16 | G37: =STDEV(G9:G32) -> 53.687721 | H37: =STDEV(H9:H32) -> 36.631846 | I37: =STDEV(I9:I32) -> #DIV/0! | ... Q37: =STDEV(Q9:Q32) -> 0.59552543
A38: Num | B38: =COUNT(B9:B32) -> 24 | C38: =COUNT(C9:C32) -> 24 | D38: =COUNT(D9:D32) -> 24 | E38: =COUNT(E9:E32) -> 24 | F38: =COUNT(F9:F32) -> 24 | G38: =COUNT(G9:G32) -> 24 | H38: =COUNT(H9:H32) -> 24 | I38: =COUNT(I9:I32) -> 0 | ... Q38: =COUNT(Q9:Q32) -> 24
A39: DCR | B39: =IF(B38>=22,">90%",IF(B38<=22,"<90%")) -> >90% | C39: =IF(C38>=22,">90%",IF(C38<=22,"<90%")) -> >90% | D39: =IF(D38>=22,">90%",IF(D38<=22,"<90%")) -> >90% | E39: =IF(E38>=22,">90%",IF(E38<=22,"<90%")) -> >90% | F39: =IF(F38>=22,">90%",IF(F38<=22,"<90%")) -> >90% | G39: =IF(G38>=22,">90%",IF(G38<=22,"<90%")) -> >90% | H39: =IF(H38>=22,">90%",IF(H38<=22,"<90%")) -> >90% | I39: =IF(I38>=22,">90%",IF(I38<=22,"<90%")) -> <90% | ... Q39: =IF(Q38>=22,">90%",IF(Q38<=22,"<90%")) -> >90%
A40: Status | B40: =IF(B38>=22,"OK",IF(B38<=22,"LESS")) -> OK | C40: =IF(C38>=22,"OK",IF(C38<=22,"LESS")) -> OK | D40: =IF(D38>=22,"OK",IF(D38<=22,"LESS")) -> OK | E40: =IF(E38>=22,"OK",IF(E38<=22,"LESS")) -> OK | F40: =IF(F38>=22,"OK",IF(F38<=22,"LESS")) -> OK | G40: =IF(G38>=22,"OK",IF(G38<=22,"LESS")) -> OK | H40: =IF(H38>=22,"OK",IF(H38<=22,"LESS")) -> OK | I40: =IF(I38>=22,"OK",IF(I38<=22,"LESS")) -> LESS | ... Q40: =IF(Q38>=22,"OK",IF(Q38<=22,"LESS")) -> OK
A43: Done by | B43: RAHUL
A45: Comment

Sheet 04
A1: Station: | B1: BHATAGAON RAIPUR
A2: Date: | B2: =$A$9 -> 04/01/2025 01:00 | D2: Power Off | G2: Pw.Off | L2: Link Fail | N2: Link F | P2: Maintenance | R2: Maint.
A3: Report Type: | B3: Mean | D3: Calibration | G3: Calib. | L3: Data Fail | N3: Data F | P3: Invalid | R3: Invalid
A4: Time Base: | B4: 01 Hour | D4: Zero Referrence | G4: Z.Ref | L4: Warm Up | N4: Wm. Up
A7: Date & Time | B7: NO_BHATAGAON | C7: NO2__BHATAGAON | D7: NOX_BHATAGAON | E7: SO2__BHATAGAON | F7: O3__BHATAGAON | G7: PM10__BHATAGAON | H7: PM2_5__BHATAGAON | I7: BENZ__BHATAGAON | J7: WS__BHATAGAON | K7: WD__BHATAGAON | L7: TEMP__BHATAGAON | M7: HUM__BHATAGAON | N7: SR__BHATAGAON | O7: RG__BHATAGAON | P7: CO__BHATAGAON | Q7: NH3__BHATAGAON
B8: ug/m3 | C8: ug/m3 | D8: ppb | E8: ug/m3 | F8: ug/m3 | G8: mg/m3 | H8: ug/m3 | I8: ug/m3 | J8: m/sec | K8: deg | L8: degreC | M8: % | N8: w/m2 | O8: mm | P8: ug/m3 | Q8: ug/m3
A9: 04/01/2025 01:00 | B9: 223.38 | C9: 49.09 | D9: 203.41 | E9: 9.97 | F9: 2.13 | G9: 224.96 | H9: 65.28 | I9: Invalid | J9: 0.76 | K9: 269.66 | L9: 11.83 | M9: 78.87 | N9: 53.9 | O9: 0 | P9: 2.26 | Q9: 10.83
A10: 04/01/2025 02:00 | B10: 205.03 | C10: 45.1 | D10: 186.6 | E10: 9.15 | F10: 2.13 | G10: 158.62 | H10: 48.95 | I10: Invalid | J10: 0.77 | K10: 337.29 | L10: 10.69 | M10: 79.12 | N10: 53.9 | O10: 0 | P10: 1.97 | Q10: 10.62
A11: 04/01/2025 03:00 | B11: 172.42 | C11: 44.08 | D11: 159.76 | E11: 7.76 | F11: 2.13 | G11: 101.17 | H11: 36.14 | I11: Invalid | J11: 0.96 | K11: 313.19 | L11: 10.13 | M11: 88.1 | N11: 53.8 | O11: 0 | P11: 1.82 | Q11: 10.27
A12: 04/01/2025 04:00 | B12: 145.84 | C12: 42.16 | D12: 137.6 | E12: 7.9 | F12: 2.13 | G12: 110.22 | H12: 42.27 | I12: Invalid | J12: 0.93 | K12: 311.31 | L12: 9.55 | M12: 93.95 | N12: 53.8 | O12: 0 | P12: 1.65 | Q12: 10.1
A13: 04/01/2025 05:00 | B13: 131.11 | C13: 40.78 | D13: 125.07 | E13: 8.06 | F13: 2.13 | G13: 139.29 | H13: 42.27 | I13: Invalid | J13: 0.96 | K13: 312.69 | L13: 9.58 | M13: 96.92 | N13: 54.2 | O13: 0 | P13: 1.51 | Q13: 10
A14: 04/01/2025 06:00 | B14: 121.63 | C14: 39.25 | D14: 116.44 | E14: 7.82 | F14: 2.13 | G14: 139.29 | H14: 40.26 | I14: Invalid | J14: 0.94 | K14: 311.32 | L14: 8.69 | M14: 97.25 | N14: 54.2 | O14: 0 | P14: 1.42 | Q14: 9.91
A15: 04/01/2025 07:00 | B15: 114.07 | C15: 41.19 | D15: 112.22 | E15: 7.84 | F15: 2.13 | G15: 122.07 | H15: 39.02 | I15: Invalid | J15: 0.96 | K15: 321.9 | L15: 8.79 | M15: 97.1 | N15: 67.5 | O15: 0 | P15: 1.29 | Q15: 9.77
A16: 04/01/2025 08:00 | B16: 120.64 | C16: 41.45 | D16: 116.88 | E16: 7.88 | F16: 2.13 | G16: 127.98 | H16: 43.8 | I16: Invalid | J16: 1 | K16: 354.75 | L16: 12.07 | M16: 88.78 | N16: 219.1 | O16: 0 | P16: 1.4 | Q16: 9.9
A17: 04/01/2025 09:00 | B17: 119.38 | C17: 42.57 | D17: 116.29 | E17: 8.22 | F17: 2.13 | G17: 127.98 | H17: 43.8 | I17: Invalid | J17: 1.63 | K17: 117.48 | L17: 17.59 | M17: 52.03 | N17: 493.3 | O17: 0 | P17: 1.38 | Q17: 9.9
A18: 04/01/2025 10:00 | B18: 104.86 | C18: 45.42 | D18: 104.84 | E18: 6.61 | F18: 2.13 | G18: 102.4 | H18: 37.69 | I18: Invalid | J18: 1.51 | K18: 110.26 | L18: 20.44 | M18: 40.09 | N18: 640.7 | O18: 0 | P18: 1.23 | Q18: 9.83
A19: 04/01/2025 11:00 | B19: 84.85 | C19: 50.83 | D19: 91.2 | E19: 6.09 | F19: 2.13 | G19: 70.12 | H19: 26.76 | I19: Invalid | J19: 2 | K19: 340.7 | L19: 26.72 | M19: 32.34 | N19: 653.2 | O19: 0 | P19: 1.07 | Q19: 9.59
A20: 04/01/2025 12:00 | B20: 69.55 | C20: 53.83 | D20: 81.39 | E20: 6.36 | F20: 2.13 | G20: 77.76 | H20: 23.4 | I20: Invalid | J20: 2.6 | K20: 348.47 | L20: 27.73 | M20: 25.21 | N20: 805.3 | O20: 0 | P20: 0.98 | Q20: 9.5
... A32: 04/01/2025 24:00 | B32: 287.88 | C32: 51.8 | D32: 254.35 | E32: 13.81 | F32: 2.13 | G32: 261.71 | H32: 58.65 | I32: Invalid | J32: 1.04 | K32: 337.27 | L32: 11.69 | M32: 90.73 | N32: 52.9 | O32: 0 | P32: 2.93 | Q32: 10.97
A34: Min | B34: =MIN(B9:B32) -> 22.56 | C34: =MIN(C9:C32) -> 39.25 | D34: =MIN(D9:D32) -> 45.94 | E34: =MIN(E9:E32) -> 4.99 | F34: =MIN(F9:F32) -> 2.13 | G34: =MIN(G9:G32) -> 46.2 | H34: =MIN(H9:H32) -> 13.73 | I34: =MIN(I9:I32) -> 0 | ... Q34: =MIN(Q9:Q32) -> 8.21
A35: Max | B35: =MAX(B9:B32) -> 287.88 | C35: =MAX(C9:C32) -> 57.64 | D35: =MAX(D9:D32) -> 254.35 | E35: =MAX(E9:E32) -> 13.81 | F35: =MAX(F9:F32) -> 2.13 | G35: =MAX(G9:G32) -> 261.71 | H35: =MAX(H9:H32) -> 65.28 | I35: =MAX(I9:I32) -> 0 | ... Q35: =MAX(Q9:Q32) -> 10.97
A36: Avg | B36: =AVERAGE(B9:B32) -> 114.04667 | C36: =AVERAGE(C9:C32) -> 50.041667 | D36: =AVERAGE(D9:D32) -> 115.76208 | E36: =AVERAGE(E9:E32) -> 7.9416667 | F36: =AVERAGE(F9:F32) -> 2.13 | G36: =AVERAGE(G9:G32) -> 126.06417 | H36: =AVERAGE(H9:H32) -> 34.800417 | I36: =AVERAGE(I9:I32) -> #DIV/0! | ... Q36: =AVERAGE(Q9:Q32) -> 9.6879167
A37: Stdev | B37: =STDEV(B9:B32) -> 73.783608 | C37: =STDEV(C9:C32) -> 6.4514816 | D37: =STDEV(D9:D32) -> 57.743745 | E37: =STDEV(E9:E32) -> 2.2109366 | F37: =STDEV(F9:F32) -> 4.5364061e-16 | G37: =STDEV(G9:G32) -> 65.412929 | H37: =STDEV(H9:H32) -> 14.430866 | I37: =STDEV(I9:I32) -> #DIV/0! | ... Q37: =STDEV(Q9:Q32) -> 0.7702116
A38: Num | B38: =COUNT(B9:B32) -> 24 | C38: =COUNT(C9:C32) -> 24 | D38: =COUNT(D9:D32) -> 24 | E38: =COUNT(E9:E32) -> 24 | F38: =COUNT(F9:F32) -> 24 | G38: =COUNT(G9:G32) -> 24 | H38: =COUNT(H9:H32) -> 24 | I38: =COUNT(I9:I32) -> 0 | ... Q38: =COUNT(Q9:Q32) -> 24
A39: DCR | B39: =IF(B38>=22,">90%",IF(B38<=22,"<90%")) -> >90% | C39: =IF(C38>=22,">90%",IF(C38<=22,"<90%")) -> >90% | D39: =IF(D38>=22,">90%",IF(D38<=22,"<90%")) -> >90% | E39: =IF(E38>=22,">90%",IF(E38<=22,"<90%")) -> >90% | F39: =IF(F38>=22,">90%",IF(F38<=22,"<90%")) -> >90% | G39: =IF(G38>=22,">90%",IF(G38<=22,"<90%")) -> >90% | H39: =IF(H38>=22,">90%",IF(H38<=22,"<90%")) -> >90% | I39: =IF(I38>=22,">90%",IF(I38<=22,"<90%")) -> <90% | ... Q39: =IF(Q38>=22,">90%",IF(Q38<=22,"<90%")) -> >90%
A40: Status | B40: =IF(B38>=22,"OK",IF(B38<=22,"LESS")) -> OK | C40: =IF(C38>=22,"OK",IF(C38<=22,"LESS")) -> OK | D40: =IF(D38>=22,"OK",IF(D38<=22,"LESS")) -> OK | E40: =IF(E38>=22,"OK",IF(E38<=22,"LESS")) -> OK | F40: =IF(F38>=22,"OK",IF(F38<=22,"LESS")) -> OK | G40: =IF(G38>=22,"OK",IF(G38<=22,"LESS")) -> OK | H40: =IF(H38>=22,"OK",IF(H38<=22,"LESS")) -> OK | I40: =IF(I38>=22,"OK",IF(I38<=22,"LESS")) -> LESS | ... Q40: =IF(Q38>=22,"OK",IF(Q38<=22,"LESS")) -> OK
A43: Done by | B43: RAHUL
A45: Comment

Sheet 05
A1: Station: | B1: BHATAGAON RAIPUR
A2: Date: | B2: =$A$9 -> 05/01/2025 01:00 | D2: Power Off | G2: Pw.Off | L2: Link Fail | N2: Link F | P2: Maintenance | R2: Maint.
A3: Report Type: | B3: Mean | D3: Calibration | G3: Calib. | L3: Data Fail | N3: Data F | P3: Invalid | R3: Invalid
A4: Time Base: | B4: 01 Hour | D4: Zero Referrence | G4: Z.Ref | L4: Warm Up | N4: Wm. Up
A7: Date & Time | B7: NO_BHATAGAON | C7: NO2__BHATAGAON | D7: NOX_BHATAGAON | E7: SO2__BHATAGAON | F7: O3__BHATAGAON | G7: PM10__BHATAGAON | H7: PM2_5__BHATAGAON | I7: BENZ__BHATAGAON | J7: WS__BHATAGAON | K7: WD__BHATAGAON | L7: TEMP__BHATAGAON | M7: HUM__BHATAGAON | N7: SR__BHATAGAON | O7: RG__BHATAGAON | P7: CO__BHATAGAON | Q7: NH3__BHATAGAON
B8: ug/m3 | C8: ug/m3 | D8: ppb | E8: ug/m3 | F8: ug/m3 | G8: mg/m3 | H8: ug/m3 | I8: ug/m3 | J8: m/sec | K8: deg | L8: degreC | M8: % | N8: w/m2 | O8: mm | P8: ug/m3 | Q8: ug/m3
A9: 05/01/2025 01:00 | B9: 294.09 | C9: 46.65 | D9: 258.76 | E9: 12.29 | F9: 2.13 | G9: 215.06 | H9: 59.02 | I9: Invalid | J9: 1.03 | K9: 308.71 | L9: 11.76 | M9: 86.61 | N9: 52.8 | O9: 0 | P9: 2.92 | Q9: 11.15
A10: 05/01/2025 02:00 | B10: 272.69 | C10: 44.53 | D10: 240.56 | E10: 10.91 | F10: 2.13 | G10: 174.46 | H10: 59.02 | I10: Invalid | J10: 1.04 | K10: 333.18 | L10: 11.32 | M10: 87.17 | N10: 53.1 | O10: 0 | P10: 2.38 | Q10: 11.04
A11: 05/01/2025 03:00 | B11: 235.67 | C11: 42.75 | D11: 209.95 | E11: 9.58 | F11: 2.13 | G11: 131.12 | H11: 50.55 | I11: Invalid | J11: 1 | K11: 320.41 | L11: 10.17 | M11: 97.88 | N11: 53.1 | O11: 0 | P11: 2.18 | Q11: 10.75
A12: 05/01/2025 04:00 | B12: 200.6 | C12: 42.34 | D12: 181.61 | E12: 8.73 | F12: 2.13 | G12: 116.61 | H12: 46.95 | I12: Invalid | J12: 1.04 | K12: 346.64 | L12: 9.15 | M12: 103.6 | N12: 53.2 | O12: 0 | P12: 1.88 | Q12: 10.43
A13: 05/01/2025 05:00 | B13: 172.67 | C13: 39.85 | D13: 157.48 | E13: 8.4 | F13: 2.13 | G13: 119.44 | H13: 44.26 | I13: Invalid | J13: 1.06 | K13: 315.15 | L13: 8.72 | M13: 101.43 | N13: 53.4 | O13: 0 | P13: 1.63 | Q13: 10.24
A14: 05/01/2025 06:00 | B14: 167.47 | C14: 39.64 | D14: 153.44 | E14: 8.46 | F14: 2.13 | G14: 134.23 | H14: 43.33 | I14: Invalid | J14: 1.07 | K14: 307.86 | L14: 8.57 | M14: 103.11 | N14: 53.3 | O14: 0 | P14: 1.47 | Q14: 10.25
A15: 05/01/2025 07:00 | B15: 190.92 | C15: 40.26 | D15: 172.76 | E15: 8.97 | F15: 2.13 | G15: 152.76 | H15: 43.49 | I15: Invalid | J15: 1.07 | K15: 335.25 | L15: 8.57 | M15: 102.72 | N15: 62.3 | O15: 0 | P15: 1.36 | Q15: 10.28
A16: 05/01/2025 08:00 | B16: 196.72 | C16: 43.31 | D16: 178.19 | E16: 9.38 | F16: 2.13 | G16: 152.76 | H16: 43.49 | I16: Invalid | J16: 1.94 | K16: 307.64 | L16: 12.5 | M16: 97.69 | N16: 207.2 | O16: 0 | P16: 1.52 | Q16: 10.34
A17: 05/01/2025 09:00 | B17: 172.65 | C17: 48.88 | D17: 162.18 | E17: 8.61 | F17: 2.13 | G17: 130.35 | H17: 43.34 | I17: Invalid | J17: 1.93 | K17: 112.48 | L17: 16.56 | M17: 65.11 | N17: 451.2 | O17: 0 | P17: 1.39 | Q17: 10.26
A18: 05/01/2025 10:00 | B18: 141.19 | C18: 51.05 | D18: 136.41 | E18: 8.11 | F18: 2.13 | G18: 90.05 | H18: 41.71 | I18: Invalid | J18: 1.68 | K18: 345.56 | L18: 23.97 | M18: 44.16 | N18: 565.2 | O18: 0 | P18: 1.22 | Q18: 10.12
A19: 05/01/2025 11:00 | B19: 112.91 | C19: 57.02 | D19: 116.67 | E19: 7.82 | F19: 2.13 | G19: 85.28 | H19: 32.88 | I19: Invalid | J19: 1.89 | K19: 124.97 | L19: 21.98 | M19: 41.08 | N19: 636.7 | O19: 0 | P19: 1.1 | Q19: 9.88
A20: 05/01/2025 12:00 | B20: 84.36 | C20: 62.89 | D20: 96.79 | E20: 7.23 | F20: 2.13 | G20: 72.89 | H20: 31.05 | I20: Invalid | J20: 1.12 | K20: 107.76 | L20: 23.25 | M20: 36.32 | N20: 716 | O20: 0 | P20: 0.97 | Q20: 9.6
... A32: 05/01/2025 24:00 | B32: 60.99 | C32: 65.3 | D32: 81.65 | E32: 8.56 | F32: 2.13 | G32: 156.48 | H32: 65.12 | I32: Invalid | J32: 1.08 | K32: 345.11 | L32: 14.14 | M32: 71.27 | N32: 106.8 | O32: 0 | P32: 1.94 | Q32: 9.46
A34: Min | B34: =MIN(B9:B32) -> 10.45 | C34: =MIN(C9:C32) -> 39.64 | D34: =MIN(D9:D32) -> 44.27 | E34: =MIN(E9:E32) -> 6.11 | F34: =MIN(F9:F32) -> 2.13 | G34: =MIN(G9:G32) -> 64.89 | H34: =MIN(H9:H32) -> 25.5 | I34: =MIN(I9:I32) -> 0 | ... Q34: =MIN(Q9:Q32) -> 8.21
A35: Max | B35: =MAX(B9:B32) -> 294.09 | C35: =MAX(C9:C32) -> 76.38 | D35: =MAX(D9:D32) -> 258.76 | E35: =MAX(E9:E32) -> 12.29 | F35: =MAX(F9:F32) -> 2.13 | G35: =MAX(G9:G32) -> 420.55 | H35: =MAX(H9:H32) -> 66.49 | I35: =MAX(I9:I32) -> 0 | ... Q35: =MAX(Q9:Q32) -> 11.15
A36: Avg | B36: =AVERAGE(B9:B32) -> 113.23458 | C36: =AVERAGE(C9:C32) -> 58.530417 | D36: =AVERAGE(D9:D32) -> 119.33917 | E36: =AVERAGE(E9:E32) -> 8.2754167 | F36: =AVERAGE(F9:F32) -> 2.13 | G36: =AVERAGE(G9:G32) -> 150.61583 | H36: =AVERAGE(H9:H32) -> 42.662917 | I36: =AVERAGE(I9:I32) -> #DIV/0! | ... Q36: =AVERAGE(Q9:Q32) -> 9.6120833
A37: Stdev | B37: =STDEV(B9:B32) -> 87.148601 | C37: =STDEV(C9:C32) -> 13.433637 | D37: =STDEV(D9:D32) -> 63.832314 | E37: =STDEV(E9:E32) -> 1.4580004 | F37: =STDEV(F9:F32) -> 4.5364061e-16 | G37: =STDEV(G9:G32) -> 96.688096 | H37: =STDEV(H9:H32) -> 13.165409 | I37: =STDEV(I9:I32) -> #DIV/0! | ... Q37: =STDEV(Q9:Q32) -> 0.91910627
A38: Num | B38: =COUNT(B9:B32) -> 24 | C38: =COUNT(C9:C32) -> 24 | D38: =COUNT(D9:D32) -> 24 | E38: =COUNT(E9:E32) -> 24 | F38: =COUNT(F9:F32) -> 24 | G38: =COUNT(G9:G32) -> 24 | H38: =COUNT(H9:H32) -> 24 | I38: =COUNT(I9:I32) -> 0 | ... Q38: =COUNT(Q9:Q32) -> 24
A39: DCR | B39: =IF(B38>=22,">90%",IF(B38<=22,"<90%")) -> >90% | C39: =IF(C38>=22,">90%",IF(C38<=22,"<90%")) -> >90% | D39: =IF(D38>=22,">90%",IF(D38<=22,"<90%")) -> >90% | E39: =IF(E38>=22,">90%",IF(E38<=22,"<90%")) -> >90% | F39: =IF(F38>=22,">90%",IF(F38<=22,"<90%")) -> >90% | G39: =IF(G38>=22,">90%",IF(G38<=22,"<90%")) -> >90% | H39: =IF(H38>=22,">90%",IF(H38<=22,"<90%")) -> >90% | I39: =IF(I38>=22,">90%",IF(I38<=22,"<90%")) -> <90% | ... Q39: =IF(Q38>=22,">90%",IF(Q38<=22,"<90%")) -> >90%
A40: Status | B40: =IF(B38>=22,"OK",IF(B38<=22,"LESS")) -> OK | C40: =IF(C38>=22,"OK",IF(C38<=22,"LESS")) -> OK | D40: =IF(D38>=22,"OK",IF(D38<=22,"LESS")) -> OK | E40: =IF(E38>=22,"OK",IF(E38<=22,"LESS")) -> OK | F40: =IF(F38>=22,"OK",IF(F38<=22,"LESS")) -> OK | G40: =IF(G38>=22,"OK",IF(G38<=22,"LESS")) -> OK | H40: =IF(H38>=22,"OK",IF(H38<=22,"LESS")) -> OK | I40: =IF(I38>=22,"OK",IF(I38<=22,"LESS")) -> LESS | ... Q40: =IF(Q38>=22,"OK",IF(Q38<=22,"LESS")) -> OK
A43: Done by | B43: RAHUL
A45: Comment

Sheet 06
A1: Station: | B1: BHATAGAON RAIPUR
A2: Date: | B2: =$A$9 -> 06/01/2025 01:00 | D2: Power Off | G2: Pw.Off | L2: Link Fail | N2: Link F | P2: Maintenance | R2: Maint.
A3: Report Type: | B3: Mean | D3: Calibration | G3: Calib. | L3: Data Fail | N3: Data F | P3: Invalid | R3: Invalid
A4: Time Base: | B4: 01 Hour | D4: Zero Referrence | G4: Z.Ref | L4: Warm Up | N4: Wm. Up
A7: Date & Time | B7: NO_BHATAGAON | C7: NO2__BHATAGAON | D7: NOX_BHATAGAON | E7: SO2__BHATAGAON | F7: O3__BHATAGAON | G7: PM10__BHATAGAON | H7: PM2_5__BHATAGAON | I7: BENZ__BHATAGAON | J7: WS__BHATAGAON | K7: WD__BHATAGAON | L7: TEMP__BHATAGAON | M7: HUM__BHATAGAON | N7: SR__BHATAGAON | O7: RG__BHATAGAON | P7: CO__BHATAGAON | Q7: NH3__BHATAGAON
B8: ug/m3 | C8: ug/m3 | D8: ppb | E8: ug/m3 | F8: ug/m3 | G8: mg/m3 | H8: ug/m3 | I8: ug/m3 | J8: m/sec | K8: deg | L8: degreC | M8: % | N8: w/m2 | O8: mm | P8: ug/m3 | Q8: ug/m3
A9: 06/01/2025 01:00 | B9: 49.59 | C9: 65.06 | D9: 72 | E9: 7.66 | F9: 2.13 | G9: 134.12 | H9: 57.79 | I9: Invalid | J9: 1.17 | K9: 333.41 | L9: 13.35 | M9: 78.97 | N9: 106.5 | O9: 0 | P9: 1.8 | Q9: 9.35
A10: 06/01/2025 02:00 | B10: 40.82 | C10: 63.74 | D10: 64.63 | E10: 7.03 | F10: 2.13 | G10: 131.52 | H10: 56.36 | I10: Invalid | J10: 1.11 | K10: 335.2 | L10: 12.99 | M10: 86.53 | N10: 106.8 | O10: 0 | P10: 1.52 | Q10: 8.98
A11: 06/01/2025 03:00 | B11: 34.11 | C11: 61.96 | D11: 58.35 | E11: 7.23 | F11: 2.13 | G11: 131.52 | H11: 52.55 | I11: Invalid | J11: 1.16 | K11: 319.86 | L11: 11.28 | M11: 97.03 | N11: 106.7 | O11: 0 | P11: 1.43 | Q11: 8.48
A12: 06/01/2025 04:00 | B12: 28.36 | C12: 59.38 | D12: 52.39 | E12: 7.23 | F12: 2.13 | G12: 118.36 | H12: 53.38 | I12: Invalid | J12: 1.1 | K12: 333.85 | L12: 10.82 | M12: 98.77 | N12: 107 | O12: 0 | P12: 1.32 | Q12: 8.21
A13: 06/01/2025 05:00 | B13: 22.96 | C13: 58.67 | D13: 47.46 | E13: 7.07 | F13: 2.13 | G13: 106.51 | H13: 53.38 | I13: Invalid | J13: 1.12 | K13: 292.95 | L13: 10.62 | M13: 100.46 | N13: 106.7 | O13: 0 | P13: 1.18 | Q13: 8.21
A14: 06/01/2025 06:00 | B14: 32.66 | C14: 54.73 | D14: 52.75 | E14: 7.79 | F14: 2.13 | G14: 142.63 | H14: 53.87 | I14: Invalid | J14: 1.15 | K14: 355.66 | L14: 10.35 | M14: 101.75 | N14: 106 | O14: 0 | P14: 1.22 | Q14: 8.21
A15: 06/01/2025 07:00 | B15: 54.11 | C15: 53.21 | D15: 69.21 | E15: 8.79 | F15: 2.29 | G15: 170.3 | H15: 61.23 | I15: Invalid | J15: 1.13 | K15: 329.29 | L15: 9.77 | M15: 102.62 | N15: 115.2 | O15: 0 | P15: 1.26 | Q15: 9.32
A16: 06/01/2025 08:00 | B16: 65.04 | C16: 53.18 | D16: 78.34 | E16: 9.28 | F16: 2.13 | G16: 170.3 | H16: 61.23 | I16: Invalid | J16: 1.22 | K16: 286.21 | L16: 11.67 | M16: 102.62 | N16: 220.2 | O16: 0 | P16: 1.38 | Q16: 9.49
A17: 06/01/2025 09:00 | B17: 60.44 | C17: 56.42 | D17: 75.51 | E17: 8.93 | F17: 2.13 | G17: 160.19 | H17: 60.64 | I17: Invalid | J17: 1.36 | K17: 197.99 | L17: 15.41 | M17: 81.12 | N17: 397.7 | O17: 0 | P17: 1.32 | Q17: 9.42
A18: 06/01/2025 10:00 | B18: 49.92 | C18: 59.25 | D18: 68.5 | E18: 8.43 | F18: 2.13 | G18: 139.4 | H18: 56.68 | I18: Invalid | J18: 1.28 | K18: 179.06 | L18: 17.91 | M18: 71.56 | N18: 518.8 | O18: 0 | P18: 1.28 | Q18: 9.34
A19: 06/01/2025 11:00 | B19: 37.41 | C19: 63.15 | D19: 60.22 | E19: 8.07 | F19: 2.13 | G19: 139.4 | H19: 56.68 | I19: Invalid | J19: 1.28 | K19: 194.66 | L19: 21.34 | M19: 53.95 | N19: 594.2 | O19: 0 | P19: 1.24 | Q19: 8.57
A20: 06/01/2025 12:00 | B20: 24.41 | C20: 69.77 | D20: 51.75 | E20: 8.42 | F20: 2.13 | G20: 107.63 | H20: 56.33 | I20: Invalid | J20: 1.5 | K20: 352.55 | L20: 24.73 | M20: 39.04 | N20: 657.3 | O20: 0 | P20: 1.16 | Q20: 8.21
... A32: 06/01/2025 24:00 | B32: 76.85 | C32: 70.1 | D32: 96.03 | E32: 7.86 | F32: 2.13 | G32: 172.12 | H32: 53.59 | I32: Invalid | J32: 1.08 | K32: 281.57 | L32: 13.76 | M32: 87.31 | N32: 91.7 | O32: 0 | P32: 1.72 | Q32: 9.62
A34: Min | B34: =MIN(B9:B32) -> 2.34 | C34: =MIN(C9:C32) -> 53.18 | D34: =MIN(D9:D32) -> 29.1 | E34: =MIN(E9:E32) -> 7.03 | F34: =MIN(F9:F32) -> 2.13 | G34: =MIN(G9:G32) -> 83.88 | H34: =MIN(H9:H32) -> 38.85 | I34: =MIN(I9:I32) -> 0 | ... Q34: =MIN(Q9:Q32) -> 8.21
A35: Max | B35: =MAX(B9:B32) -> 76.85 | C35: =MAX(C9:C32) -> 79.99 | D35: =MAX(D9:D32) -> 96.03 | E35: =MAX(E9:E32) -> 15.77 | F35: =MAX(F9:F32) -> 27.21 | G35: =MAX(G9:G32) -> 207.95 | H35: =MAX(H9:H32) -> 61.23 | I35: =MAX(I9:I32) -> 0 | ... Q35: =MAX(Q9:Q32) -> 9.62
A36: Avg | B36: =AVERAGE(B9:B32) -> 33.119167 | C36: =AVERAGE(C9:C32) -> 67.085 | D36: =AVERAGE(D9:D32) -> 59.512083 | E36: =AVERAGE(E9:E32) -> 8.9054167 | F36: =AVERAGE(F9:F32) -> 5.4454167 | G36: =AVERAGE(G9:G32) -> 140.02875 | H36: =AVERAGE(H9:H32) -> 51.967083 | I36: =AVERAGE(I9:I32) -> #DIV/0! | ... Q36: =AVERAGE(Q9:Q32) -> 8.6733333
A37: Stdev | B37: =STDEV(B9:B32) -> 22.084141 | C37: =STDEV(C9:C32) -> 9.3749852 | D37: =STDEV(D9:D32) -> 16.473348 | E37: =STDEV(E9:E32) -> 2.2000415 | F37: =STDEV(F9:F32) -> 6.98955 | G37: =STDEV(G9:G32) -> 34.408719 | H37: =STDEV(H9:H32) -> 6.5980422 | I37: =STDEV(I9:I32) -> #DIV/0! | ... Q37: =STDEV(Q9:Q32) -> 0.57268754
A38: Num | B38: =COUNT(B9:B32) -> 24 | C38: =COUNT(C9:C32) -> 24 | D38: =COUNT(D9:D32) -> 24 | E38: =COUNT(E9:E32) -> 24 | F38: =COUNT(F9:F32) -> 24 | G38: =COUNT(G9:G32) -> 24 | H38: =COUNT(H9:H32) -> 24 | I38: =COUNT(I9:I32) -> 0 | ... Q38: =COUNT(Q9:Q32) -> 24
A39: DCR | B39: =IF(B38>=22,">90%",IF(B38<=22,"<90%")) -> >90% | C39: =IF(C38>=22,">90%",IF(C38<=22,"<90%")) -> >90% | D39: =IF(D38>=22,">90%",IF(D38<=22,"<90%")) -> >90% | E39: =IF(E38>=22,">90%",IF(E38<=22,"<90%")) -> >90% | F39: =IF(F38>=22,">90%",IF(F38<=22,"<90%")) -> >90% | G39: =IF(G38>=22,">90%",IF(G38<=22,"<90%")) -> >90% | H39: =IF(H38>=22,">90%",IF(H38<=22,"<90%")) -> >90% | I39: =IF(I38>=22,">90%",IF(I38<=22,"<90%")) -> <90% | ... Q39: =IF(Q38>=22,">90%",IF(Q38<=22,"<90%")) -> >90%
A40: Status | B40: =IF(B38>=22,"OK",IF(B38<=22,"LESS")) -> OK | C40: =IF(C38>=22,"OK",IF(C38<=22,"LESS")) -> OK | D40: =IF(D38>=22,"OK",IF(D38<=22,"LESS")) -> OK | E40: =IF(E38>=22,"OK",IF(E38<=22,"LESS")) -> OK | F40: =IF(F38>=22,"OK",IF(F38<=22,"LESS")) -> OK | G40: =IF(G38>=22,"OK",IF(G38<=22,"LESS")) -> OK | H40: =IF(H38>=22,"OK",IF(H38<=22,"LESS")) -> OK | I40: =IF(I38>=22,"OK",IF(I38<=22,"LESS")) -> LESS | ... Q40: =IF(Q38>=22,"OK",IF(Q38<=22,"LESS")) -> OK
A43: Done by | B43: RAHUL
A45: Comment

Sheet 07
A1: Station: | B1: BHATAGAON RAIPUR
A2: Date: | B2: =$A$9 -> 07/01/2025 01:00 | D2: Power Off | G2: Pw.Off | L2: Link Fail | N2: Link F | P2: Maintenance | R2: Maint.
A3: Report Type: | B3: Mean | D3: Calibration | G3: Calib. | L3: Data Fail | N3: Data F | P3: Invalid | R3: Invalid
A4: Time Base: | B4: 01 Hour | D4: Zero Referrence | G4: Z.Ref | L4: Warm Up | N4: Wm. Up
A7: Date & Time | B7: NO_BHATAGAON | C7: NO2__BHATAGAON | D7: NOX_BHATAGAON | E7: SO2__BHATAGAON | F7: O3__BHATAGAON | G7: PM10__BHATAGAON | H7: PM2_5__BHATAGAON | I7: BENZ__BHATAGAON | J7: WS__BHATAGAON | K7: WD__BHATAGAON | L7: TEMP__BHATAGAON | M7: HUM__BHATAGAON | N7: SR__BHATAGAON | O7: RG__BHATAGAON | P7: CO__BHATAGAON | Q7: NH3__BHATAGAON
B8: ug/m3 | C8: ug/m3 | D8: ppb | E8: ug/m3 | F8: ug/m3 | G8: mg/m3 | H8: ug/m3 | I8: ug/m3 | J8: m/sec | K8: deg | L8: degreC | M8: % | N8: w/m2 | O8: mm | P8: ug/m3 | Q8: ug/m3
A9: 07/01/2025 01:00 | B9: 69.93 | C9: 66.42 | D9: 89.4 | E9: 7.63 | F9: 2.13 | G9: 162.32 | H9: 53.59 | I9: Invalid | J9: 1.24 | K9: 349.08 | L9: 13.34 | M9: 93.31 | N9: 96.8 | O9: 0 | P9: 1.6 | Q9: 9.59
A10: 07/01/2025 02:00 | B10: 55.13 | C10: 63.62 | D10: 76.07 | E10: 7.32 | F10: 2.13 | G10: 107.11 | H10: 50.33 | I10: Invalid | J10: 1.21 | K10: 324.87 | L10: 12 | M10: 95.38 | N10: 107.7 | O10: 0 | P10: 1.46 | Q10: 9.44
A11: 07/01/2025 03:00 | B11: 43.31 | C11: 59.11 | D11: 64.14 | E11: 6.81 | F11: 2.13 | G11: 107.11 | H11: 49.47 | I11: Invalid | J11: 0.95 | K11: 350.9 | L11: 12.17 | M11: 94.24 | N11: 102.5 | O11: 0 | P11: 1.39 | Q11: 8.94
A12: 07/01/2025 04:00 | B12: 34.97 | C12: 57.25 | D12: 56.58 | E12: 6.78 | F12: 2.13 | G12: 88.74 | H12: 49.46 | I12: Invalid | J12: 1.28 | K12: 256.45 | L12: 11.82 | M12: 96.76 | N12: 111.1 | O12: 0 | P12: 1.28 | Q12: 8.29
A13: 07/01/2025 05:00 | B13: 28.12 | C13: 55.06 | D13: 49.94 | E13: 6.67 | F13: 2.13 | G13: 80.04 | H13: 46.38 | I13: Invalid | J13: 1.25 | K13: 226.48 | L13: 11.27 | M13: 100.27 | N13: 104 | O13: 0 | P13: 1.21 | Q13: 8.21
A14: 07/01/2025 06:00 | B14: 23.1 | C14: 52.97 | D14: 44.83 | E14: 6.32 | F14: 2.13 | G14: 338.23 | H14: 43.12 | I14: Invalid | J14: 1.26 | K14: 305.86 | L14: 10.77 | M14: 102.6 | N14: 89.8 | O14: 0 | P14: 1.16 | Q14: 8.21
A15: 07/01/2025 07:00 | B15: 24.94 | C15: 50.94 | D15: 44.85 | E15: 6.27 | F15: 2.13 | G15: 338.23 | H15: 39.66 | I15: Invalid | J15: 1.19 | K15: 318.96 | L15: 10.37 | M15: 102.58 | N15: 95.7 | O15: 0 | P15: 1.11 | Q15: 8.21
A16: 07/01/2025 08:00 | B16: 32.39 | C16: 50.12 | D16: 50.62 | E16: 6.73 | F16: 2.13 | G16: 108.12 | H16: 39.98 | I16: Invalid | J16: 1.69 | K16: 336.37 | L16: 12.63 | M16: 102.58 | N16: 200.9 | O16: 0 | P16: 1.12 | Q16: 8.21
A17: 07/01/2025 09:00 | B17: 36.28 | C17: 56.19 | D17: 57.08 | E17: 8.48 | F17: 2.13 | G17: 145.15 | H17: 50.17 | I17: Invalid | J17: 2.03 | K17: 352 | L17: 20.21 | M17: 79.1 | N17: 363.8 | O17: 0 | P17: 1.18 | Q17: 8.21
A18: 07/01/2025 10:00 | B18: 35.6 | C18: 66.87 | D18: 59.85 | E18: 9.45 | F18: 2.13 | G18: 201.92 | H18: 61.13 | I18: Invalid | J18: 2.2 | K18: 346.7 | L18: 23.8 | M18: 51.59 | N18: 460.2 | O18: 0 | P18: 1.3 | Q18: 8.21
A19: 07/01/2025 11:00 | B19: 31.73 | C19: 71.49 | D19: 60.37 | E19: 9.74 | F19: 2.16 | G19: 214.82 | H19: 62.49 | I19: Invalid | J19: 2.06 | K19: 345 | L19: 26.09 | M19: 44.26 | N19: 571.8 | O19: 0 | P19: 1.34 | Q19: 8.21
A20: 07/01/2025 12:00 | B20: 29.35 | C20: 74.19 | D20: 59.94 | E20: 9.15 | F20: 2.13 | G20: 214.82 | H20: 65.1 | I20: Invalid | J20: 2.65 | K20: 340.15 | L20: 27.14 | M20: 36.69 | N20: 630.5 | O20: 0 | P20: 1.33 | Q20: 8.21
... A32: 07/01/2025 24:00 | B32: 18.82 | C32: 58.97 | D32: 44.49 | E32: 6.45 | F32: 2.13 | G32: 92.39 | H32: 28.32 | I32: Invalid | J32: 2.43 | K32: 338.15 | L32: 13.62 | M32: 56.28 | N32: 55.1 | O32: 0 | P32: 0.84 | Q32: 8.21
A34: Min | B34: =MIN(B9:B32) -> 4.11 | C34: =MIN(C9:C32) -> 50.12 | D34: =MIN(D9:D32) -> 32.71 | E34: =MIN(E9:E32) -> 5.84 | F34: =MIN(F9:F32) -> 2.13 | G34: =MIN(G9:G32) -> 52.86 | H34: =MIN(H9:H32) -> 21.83 | I34: =MIN(I9:I32) -> 0 | ... Q34: =MIN(Q9:Q32) -> 8.21
A35: Max | B35: =MAX(B9:B32) -> 69.93 | C35: =MAX(C9:C32) -> 76.06 | D35: =MAX(D9:D32) -> 89.4 | E35: =MAX(E9:E32) -> 9.74 | F35: =MAX(F9:F32) -> 2.16 | G35: =MAX(G9:G32) -> 338.23 | H35: =MAX(H9:H32) -> 65.1 | I35: =MAX(I9:I32) -> 0 | ... Q35: =MAX(Q9:Q32) -> 9.59
A36: Avg | B36: =AVERAGE(B9:B32) -> 24.489583 | C36: =AVERAGE(C9:C32) -> 62.127917 | D36: =AVERAGE(D9:D32) -> 50.4075 | E36: =AVERAGE(E9:E32) -> 7.1854167 | F36: =AVERAGE(F9:F32) -> 2.1316667 | G36: =AVERAGE(G9:G32) -> 128.27042 | H36: =AVERAGE(H9:H32) -> 41.950417 | I36: =AVERAGE(I9:I32) -> #DIV/0! | ... Q36: =AVERAGE(Q9:Q32) -> 8.3525
A37: Stdev | B37: =STDEV(B9:B32) -> 16.362183 | C37: =STDEV(C9:C32) -> 7.2158937 | D37: =STDEV(D9:D32) -> 13.492138 | E37: =STDEV(E9:E32) -> 1.1347016 | F37: =STDEV(F9:F32) -> 0.0063702206 | G37: =STDEV(G9:G32) -> 81.470961 | H37: =STDEV(H9:H32) -> 14.576406 | I37: =STDEV(I9:I32) -> #DIV/0! | ... Q37: =STDEV(Q9:Q32) -> 0.38837734
A38: Num | B38: =COUNT(B9:B32) -> 24 | C38: =COUNT(C9:C32) -> 24 | D38: =COUNT(D9:D32) -> 24 | E38: =COUNT(E9:E32) -> 24 | F38: =COUNT(F9:F32) -> 24 | G38: =COUNT(G9:G32) -> 24 | H38: =COUNT(H9:H32) -> 24 | I38: =COUNT(I9:I32) -> 0 | ... Q38: =COUNT(Q9:Q32) -> 24
A39: DCR | B39: =IF(B38>=22,">90%",IF(B38<=22,"<90%")) -> >90% | C39: =IF(C38>=22,">90%",IF(C38<=22,"<90%")) -> >90% | D39: =IF(D38>=22,">90%",IF(D38<=22,"<90%")) -> >90% | E39: =IF(E38>=22,">90%",IF(E38<=22,"<90%")) -> >90% | F39: =IF(F38>=22,">90%",IF(F38<=22,"<90%")) -> >90% | G39: =IF(G38>=22,">90%",IF(G38<=22,"<90%")) -> >90% | H39: =IF(H38>=22,">90%",IF(H38<=22,"<90%")) -> >90% | I39: =IF(I38>=22,">90%",IF(I38<=22,"<90%")) -> <90% | ... Q39: =IF(Q38>=22,">90%",IF(Q38<=22,"<90%")) -> >90%
A40: Status | B40: =IF(B38>=22,"OK",IF(B38<=22,"LESS")) -> OK | C40: =IF(C38>=22,"OK",IF(C38<=22,"LESS")) -> OK | D40: =IF(D38>=22,"OK",IF(D38<=22,"LESS")) -> OK | E40: =IF(E38>=22,"OK",IF(E38<=22,"LESS")) -> OK | F40: =IF(F38>=22,"OK",IF(F38<=22,"LESS")) -> OK | G40: =IF(G38>=22,"OK",IF(G38<=22,"LESS")) -> OK | H40: =IF(H38>=22,"OK",IF(H38<=22,"LESS")) -> OK | I40: =IF(I38>=22,"OK",IF(I38<=22,"LESS")) -> LESS | ... Q40: =IF(Q38>=22,"OK",IF(Q38<=22,"LESS")) -> OK
A43: Done by | B43: RAHUL
A45: Comment

Sheet 08
A1: Station: | B1: BHATAGAON RAIPUR
A2: Date: | B2: =$A$9 -> 08/01/2025 01:00 | D2: Power Off | G2: Pw.Off | L2: Link Fail | N2: Link F | P2: Maintenance | R2: Maint.
A3: Report Type: | B3: Mean | D3: Calibration | G3: Calib. | L3: Data Fail | N3: Data F | P3: Invalid | R3: Invalid
A4: Time Base: | B4: 01 Hour | D4: Zero Referrence | G4: Z.Ref | L4: Warm Up | N4: Wm. Up
A7: Date & Time | B7: NO_BHATAGAON | C7: NO2__BHATAGAON | D7: NOX_BHATAGAON | E7: SO2__BHATAGAON | F7: O3__BHATAGAON | G7: PM10__BHATAGAON | H7: PM2_5__BHATAGAON | I7: BENZ__BHATAGAON | J7: WS__BHATAGAON | K7: WD__BHATAGAON | L7: TEMP__BHATAGAON | M7: HUM__BHATAGAON | N7: SR__BHATAGAON | O7: RG__BHATAGAON | P7: CO__BHATAGAON | Q7: NH3__BHATAGAON
B8: ug/m3 | C8: ug/m3 | D8: ppb | E8: ug/m3 | F8: ug/m3 | G8: mg/m3 | H8: ug/m3 | I8: ug/m3 | J8: m/sec | K8: deg | L8: degreC | M8: % | N8: w/m2 | O8: mm | P8: ug/m3 | Q8: ug/m3
A9: 08/01/2025 01:00 | B9: 17.88 | C9: 55.23 | D9: 41.82 | E9: 6.61 | F9: 2.13 | G9: 94.54 | H9: 29.02 | I9: Invalid | J9: 2.68 | K9: 352.94 | L9: 12.86 | M9: 61.48 | N9: 55.4 | O9: 0 | P9: 0.77 | Q9: 8.21
A10: 08/01/2025 02:00 | B10: 15.43 | C10: 52.55 | D10: 38.45 | E10: 6.58 | F10: 2.13 | G10: 94.54 | H10: 30.43 | I10: Invalid | J10: 2.37 | K10: 350.69 | L10: 12.14 | M10: 63.36 | N10: 55.5 | O10: 0 | P10: 0.74 | Q10: 8.21
A11: 08/01/2025 03:00 | B11: 13.3 | C11: 51.68 | D11: 36.29 | E11: 6.21 | F11: 2.13 | G11: 92.3 | H11: 30.43 | I11: Invalid | J11: 1.62 | K11: 348.16 | L11: 11.61 | M11: 70.15 | N11: 55.7 | O11: 0 | P11: 0.75 | Q11: 8.21
A12: 08/01/2025 04:00 | B12: 11.83 | C12: 49.49 | D12: 33.78 | E12: 5.78 | F12: 2.13 | G12: 79.27 | H12: 28.26 | I12: Invalid | J12: 1.16 | K12: 118.3 | L12: 10.56 | M12: 76.55 | N12: 55.5 | O12: 0 | P12: 0.79 | Q12: 8.21
A13: 08/01/2025 05:00 | B13: 11.85 | C13: 48.44 | D13: 33.43 | E13: 6.21 | F13: 2.13 | G13: 79.07 | H13: 30.38 | I13: Invalid | J13: 0.99 | K13: 105.45 | L13: 9.83 | M13: 78.23 | N13: 55.2 | O13: 0 | P13: 0.78 | Q13: 8.21
A14: 08/01/2025 06:00 | B14: 11.33 | C14: 47.17 | D14: 32.35 | E14: 5.73 | F14: 2.13 | G14: 79.07 | H14: 30.38 | I14: Invalid | J14: 1.1 | K14: 68.74 | L14: 9.52 | M14: 81.72 | N14: 55.5 | O14: 0 | P14: 0.74 | Q14: 8.21
A15: 08/01/2025 07:00 | B15: 12.63 | C15: 49.92 | D15: 34.83 | E15: 5.68 | F15: 2.13 | G15: 60.95 | H15: 27.62 | I15: Invalid | J15: 0.93 | K15: 334.07 | L15: 9.15 | M15: 79.93 | N15: 65 | O15: 0 | P15: 0.7 | Q15: 8.21
A16: 08/01/2025 08:00 | B16: 17.82 | C16: 52.64 | D16: 40.42 | E16: 5.72 | F16: 2.13 | G16: 68.25 | H16: 27.76 | I16: Invalid | J16: 0.77 | K16: 296.49 | L16: 11.15 | M16: 80.33 | N16: 186.7 | O16: 0 | P16: 0.69 | Q16: 8.21
A17: 08/01/2025 09:00 | B17: 19.43 | C17: 54.95 | D17: 42.91 | E17: 5.9 | F17: 2.13 | G17: 68.25 | H17: 29 | I17: Invalid | J17: 2.09 | K17: 351.08 | L17: 18.25 | M17: 54.97 | N17: 435.5 | O17: 0 | P17: 0.69 | Q17: 8.21
A18: 08/01/2025 10:00 | B18: 19 | C18: 56.03 | D18: 42.94 | E18: 5.35 | F18: 2.13 | G18: 60.4 | H18: 29.66 | I18: Invalid | J18: 2.2 | K18: 339.23 | L18: 18.83 | M18: 44.93 | N18: 588.6 | O18: 0 | P18: 0.68 | Q18: 8.21
A19: 08/01/2025 11:00 | B19: 15.65 | C19: 66.48 | D19: 43.17 | E19: 8.27 | F19: 2.14 | G19: 62.22 | H19: 29.66 | I19: Invalid | J19: 2.43 | K19: 342.55 | L19: 23.99 | M19: 34.36 | N19: 676.6 | O19: 0 | P19: 0.79 | Q19: 8.21
A20: 08/01/2025 12:00 | B20: 9.32 | C20: 70.55 | D20: 42.96 | E20: 7.47 | F20: 2.49 | G20: 62.22 | H20: 28.14 | I20: Invalid | J20: 1.75 | K20: 339.22 | L20: 24.34 | M20: 29.06 | N20: 718.6 | O20: 0 | P20: 0.79 | Q20: 8.21
... A32: 08/01/2025 24:00 | B32: 169.27 | C32: 58.42 | D32: 164.89 | E32: 12.63 | F32: 2.13 | G32: 197.67 | H32: 57.61 | I32: Invalid | J32: 1.5 | K32: 309.85 | L32: 10.5 | M32: 81.4 | N32: 57.6 | O32: 0 | P32: 2.27 | Q32: 10.16
A34: Min | B34: =MIN(B9:B32) -> 4.19 | C34: =MIN(C9:C32) -> 47.17 | D34: =MIN(D9:D32) -> 32.35 | E34: =MIN(E9:E32) -> 5.35 | F34: =MIN(F9:F32) -> 2.13 | G34: =MIN(G9:G32) -> 45.39 | H34: =MIN(H9:H32) -> 24.15 | I34: =MIN(I9:I32) -> 0 | ... Q34: =MIN(Q9:Q32) -> 8.21
A35: Max | B35: =MAX(B9:B32) -> 175.66 | C35: =MAX(C9:C32) -> 77.41 | D35: =MAX(D9:D32) -> 172.16 | E35: =MAX(E9:E32) -> 13.06 | F35: =MAX(F9:F32) -> 5.02 | G35: =MAX(G9:G32) -> 237.2 | H35: =MAX(H9:H32) -> 57.61 | I35: =MAX(I9:I32) -> 0 | ... Q35: =MAX(Q9:Q32) -> 10.2
A36: Avg | B36: =AVERAGE(B9:B32) -> 36.59625 | C36: =AVERAGE(C9:C32) -> 60.832917 | D36: =AVERAGE(D9:D32) -> 59.360833 | E36: =AVERAGE(E9:E32) -> 8.16625 | F36: =AVERAGE(F9:F32) -> 2.42125 | G36: =AVERAGE(G9:G32) -> 104.80417 | H36: =AVERAGE(H9:H32) -> 33.49125 | I36: =AVERAGE(I9:I32) -> #DIV/0! | ... Q36: =AVERAGE(Q9:Q32) -> 8.55375
A37: Stdev | B37: =STDEV(B9:B32) -> 53.590962 | C37: =STDEV(C9:C32) -> 9.1066991 | D37: =STDEV(D9:D32) -> 43.623944 | E37: =STDEV(E9:E32) -> 2.5133864 | F37: =STDEV(F9:F32) -> 0.80969298 | G37: =STDEV(G9:G32) -> 62.367615 | H37: =STDEV(H9:H32) -> 10.280586 | I37: =STDEV(I9:I32) -> #DIV/0! | ... Q37: =STDEV(Q9:Q32) -> 0.70701954
A38: Num | B38: =COUNT(B9:B32) -> 24 | C38: =COUNT(C9:C32) -> 24 | D38: =COUNT(D9:D32) -> 24 | E38: =COUNT(E9:E32) -> 24 | F38: =COUNT(F9:F32) -> 24 | G38: =COUNT(G9:G32) -> 24 | H38: =COUNT(H9:H32) -> 24 | I38: =COUNT(I9:I32) -> 0 | ... Q38: =COUNT(Q9:Q32) -> 24
A39: DCR | B39: =IF(B38>=22,">90%",IF(B38<=22,"<90%")) -> >90% | C39: =IF(C38>=22,">90%",IF(C38<=22,"<90%")) -> >90% | D39: =IF(D38>=22,">90%",IF(D38<=22,"<90%")) -> >90% | E39: =IF(E38>=22,">90%",IF(E38<=22,"<90%")) -> >90% | F39: =IF(F38>=22,">90%",IF(F38<=22,"<90%")) -> >90% | G39: =IF(G38>=22,">90%",IF(G38<=22,"<90%")) -> >90% | H39: =IF(H38>=22,">90%",IF(H38<=22,"<90%")) -> >90% | I39: =IF(I38>=22,">90%",IF(I38<=22,"<90%")) -> <90% | ... Q39: =IF(Q38>=22,">90%",IF(Q38<=22,"<90%")) -> >90%
A40: Status | B40: =IF(B38>=22,"OK",IF(B38<=22,"LESS")) -> OK | C40: =IF(C38>=22,"OK",IF(C38<=22,"LESS")) -> OK | D40: =IF(D38>=22,"OK",IF(D38<=22,"LESS")) -> OK | E40: =IF(E38>=22,"OK",IF(E38<=22,"LESS")) -> OK | F40: =IF(F38>=22,"OK",IF(F38<=22,"LESS")) -> OK | G40: =IF(G38>=22,"OK",IF(G38<=22,"LESS")) -> OK | H40: =IF(H38>=22,"OK",IF(H38<=22,"LESS")) -> OK | I40: =IF(I38>=22,"OK",IF(I38<=22,"LESS")) -> LESS | ... Q40: =IF(Q38>=22,"OK",IF(Q38<=22,"LESS")) -> OK
A43: Done by | B43: RAHUL
A45: Comment

Sheet 09
A1: Station: | B1: BHATAGAON RAIPUR
A2: Date: | B2: =$A$9 -> 09/01/2025 01:00 | D2: Power Off | G2: Pw.Off | L2: Link Fail | N2: Link F | P2: Maintenance | R2: Maint.
A3: Report Type: | B3: Mean | D3: Calibration | G3: Calib. | L3: Data Fail | N3: Data F | P3: Invalid | R3: Invalid
A4: Time Base: | B4: 01 Hour | D4: Zero Referrence | G4: Z.Ref | L4: Warm Up | N4: Wm. Up
A7: Date & Time | B7: NO_BHATAGAON | C7: NO2__BHATAGAON | D7: NOX_BHATAGAON | E7: SO2__BHATAGAON | F7: O3__BHATAGAON | G7: PM10__BHATAGAON | H7: PM2_5__BHATAGAON | I7: BENZ__BHATAGAON | J7: WS__BHATAGAON | K7: WD__BHATAGAON | L7: TEMP__BHATAGAON | M7: HUM__BHATAGAON | N7: SR__BHATAGAON | O7: RG__BHATAGAON | P7: CO__BHATAGAON | Q7: NH3__BHATAGAON
B8: ug/m3 | C8: ug/m3 | D8: ppb | E8: ug/m3 | F8: ug/m3 | G8: mg/m3 | H8: ug/m3 | I8: ug/m3 | J8: m/sec | K8: deg | L8: degreC | M8: % | N8: w/m2 | O8: mm | P8: ug/m3 | Q8: ug/m3
A9: 09/01/2025 01:00 | B9: 151.15 | C9: 51.16 | D9: 146.57 | E9: 9.03 | F9: 2.13 | G9: 163.7 | H9: 57.43 | I9: Invalid | J9: 1.43 | K9: 309.03 | L9: 9.8 | M9: 88.31 | N9: 57.5 | O9: 0 | P9: 2.1 | Q9: 10.07
A10: 09/01/2025 02:00 | B10: 129.75 | C10: 48.37 | D10: 127.76 | E10: 8.74 | F10: 2.13 | G10: 143.75 | H10: 52.2 | I10: Invalid | J10: 1.09 | K10: 283.68 | L10: 9.9 | M10: 91.79 | N10: 57.7 | O10: 0 | P10: 1.75 | Q10: 9.99
A11: 09/01/2025 03:00 | B11: 109.49 | C11: 47.77 | D11: 111.39 | E11: 8.3 | F11: 2.13 | G11: 137.14 | H11: 49.16 | I11: Invalid | J11: 0.8 | K11: 338.97 | L11: 9.36 | M11: 96.49 | N11: 57.8 | O11: 0 | P11: 1.68 | Q11: 9.81
A12: 09/01/2025 04:00 | B12: 95.34 | C12: 46.08 | D12: 99.16 | E12: 8.36 | F12: 2.13 | G12: 165.09 | H12: 53.7 | I12: Invalid | J12: 1.55 | K12: 340.76 | L12: 8.91 | M12: 95.62 | N12: 58 | O12: 0 | P12: 1.61 | Q12: 9.71
A13: 09/01/2025 05:00 | B13: 85.7 | C13: 42.64 | D13: 89.63 | E13: 8.89 | F13: 2.13 | G13: 165.09 | H13: 57.54 | I13: Invalid | J13: 1.4 | K13: 355.9 | L13: 8.27 | M13: 100.67 | N13: 58 | O13: 0 | P13: 1.57 | Q13: 9.66
A14: 09/01/2025 06:00 | B14: 87.63 | C14: 41.52 | D14: 90.26 | E14: 9.32 | F14: 2.13 | G14: 201.67 | H14: 63.83 | I14: Invalid | J14: 1.23 | K14: 344.71 | L14: 8.67 | M14: 95.35 | N14: 57.7 | O14: 0 | P14: 1.63 | Q14: 9.68
A15: 09/01/2025 07:00 | B15: 81.62 | C15: 42.11 | D15: 85.55 | E15: 8.79 | F15: 2.13 | G15: 201.67 | H15: 63.83 | I15: Invalid | J15: 1.5 | K15: 359.04 | L15: 8.72 | M15: 79.5 | N15: 66.7 | O15: 0 | P15: 1.6 | Q15: 9.65
A16: 09/01/2025 08:00 | B16: 70.16 | C16: 44.04 | D16: 77.16 | E16: 7.63 | F16: 2.13 | G16: 138.69 | H16: 59.2 | I16: Invalid | J16: 1.32 | K16: 322.97 | L16: 10.2 | M16: 74.16 | N16: 188.9 | O16: 0 | P16: 1.39 | Q16: 9.53
A17: 09/01/2025 09:00 | B17: 61.83 | C17: 44.1 | D17: 70.86 | E17: 6.42 | F17: 2.13 | G17: 99.04 | H17: 47.51 | I17: Invalid | J17: 2.03 | K17: 347.03 | L17: 14.68 | M17: 61.27 | N17: 434.6 | O17: 0 | P17: 1.25 | Q17: 9.44
A18: 09/01/2025 10:00 | B18: 52.17 | C18: 46.85 | D18: 63.86 | E18: 5.97 | F18: 2.13 | G18: 96.85 | H18: 45.83 | I18: Invalid | J18: 2.89 | K18: 121.05 | L18: 16.94 | M18: 48.7 | N18: 567.3 | O18: 0 | P18: 1.12 | Q18: 8.93
A19: 09/01/2025 11:00 | B19: 47.44 | C19: 51.86 | D19: 62.45 | E19: 6.17 | F19: 2.13 | G19: 77.47 | H19: 39.14 | I19: Invalid | J19: 2.35 | K19: 122.62 | L19: 18.81 | M19: 37.31 | N19: 655.4 | O19: 0 | P19: 0.98 | Q19: 8.59
A20: 09/01/2025 12:00 | B20: 34.33 | C20: 64.27 | D20: 55.63 | E20: 8.38 | F20: 2.13 | G20: 71.82 | H20: 35.02 | I20: Invalid | J20: 2.18 | K20: 119.69 | L20: 21.96 | M20: 30.93 | N20: 731 | O20: 0 | P20: 0.78 | Q20: 8.22
... A32: 09/01/2025 24:00 | B32: 102.32 | C32: 59.57 | D32: 110.81 | E32: 8.68 | F32: 2.13 | G32: 182.58 | H32: 45.69 | I32: Invalid | J32: 1.54 | K32: 279.54 | L32: 10.89 | M32: 79.5 | N32: 79.6 | O32: 0 | P32: 1.76 | Q32: 9.69
A34: Min | B34: =MIN(B9:B32) -> 2.36 | C34: =MIN(C9:C32) -> 41.52 | D34: =MIN(D9:D32) -> 25.57 | E34: =MIN(E9:E32) -> 5.97 | F34: =MIN(F9:F32) -> 2.13 | G34: =MIN(G9:G32) -> 50.59 | H34: =MIN(H9:H32) -> 18.94 | I34: =MIN(I9:I32) -> 0 | ... Q34: =MIN(Q9:Q32) -> 8.21
A35: Max | B35: =MAX(B9:B32) -> 151.15 | C35: =MAX(C9:C32) -> 87.93 | D35: =MAX(D9:D32) -> 146.57 | E35: =MAX(E9:E32) -> 10.37 | F35: =MAX(F9:F32) -> 14.9 | G35: =MAX(G9:G32) -> 201.67 | H35: =MAX(H9:H32) -> 63.83 | I35: =MAX(I9:I32) -> 0 | ... Q35: =MAX(Q9:Q32) -> 10.07
A36: Avg | B36: =AVERAGE(B9:B32) -> 60.114167 | C36: =AVERAGE(C9:C32) -> 57.989583 | D36: =AVERAGE(D9:D32) -> 76.345417 | E36: =AVERAGE(E9:E32) -> 8.1116667 | F36: =AVERAGE(F9:F32) -> 3.7020833 | G36: =AVERAGE(G9:G32) -> 121.715 | H36: =AVERAGE(H9:H32) -> 40.891667 | I36: =AVERAGE(I9:I32) -> #DIV/0! | ... Q36: =AVERAGE(Q9:Q32) -> 9.1058333
A37: Stdev | B37: =STDEV(B9:B32) -> 40.572535 | C37: =STDEV(C9:C32) -> 14.145633 | D37: =STDEV(D9:D32) -> 30.138624 | E37: =STDEV(E9:E32) -> 1.2107944 | F37: =STDEV(F9:F32) -> 3.4240022 | G37: =STDEV(G9:G32) -> 51.302257 | H37: =STDEV(H9:H32) -> 14.368129 | I37: =STDEV(I9:I32) -> #DIV/0! | ... Q37: =STDEV(Q9:Q32) -> 0.67138349
A38: Num | B38: =COUNT(B9:B32) -> 24 | C38: =COUNT(C9:C32) -> 24 | D38: =COUNT(D9:D32) -> 24 | E38: =COUNT(E9:E32) -> 24 | F38: =COUNT(F9:F32) -> 24 | G38: =COUNT(G9:G32) -> 24 | H38: =COUNT(H9:H32) -> 24 | I38: =COUNT(I9:I32) -> 0 | ... Q38: =COUNT(Q9:Q32) -> 24
A39: DCR | B39: =IF(B38>=22,">90%",IF(B38<=22,"<90%")) -> >90% | C39: =IF(C38>=22,">90%",IF(C38<=22,"<90%")) -> >90% | D39: =IF(D38>=22,">90%",IF(D38<=22,"<90%")) -> >90% | E39: =IF(E38>=22,">90%",IF(E38<=22,"<90%")) -> >90% | F39: =IF(F38>=22,">90%",IF(F38<=22,"<90%")) -> >90% | G39: =IF(G38>=22,">90%",IF(G38<=22,"<90%")) -> >90% | H39: =IF(H38>=22,">90%",IF(H38<=22,"<90%")) -> >90% | I39: =IF(I38>=22,">90%",IF(I38<=22,"<90%")) -> <90% | ... Q39: =IF(Q38>=22,">90%",IF(Q38<=22,"<90%")) -> >90%
A40: Status | B40: =IF(B38>=22,"OK",IF(B38<=22,"LESS")) -> OK | C40: =IF(C38>=22,"OK",IF(C38<=22,"LESS")) -> OK | D40: =IF(D38>=22,"OK",IF(D38<=22,"LESS")) -> OK | E40: =IF(E38>=22,"OK",IF(E38<=22,"LESS")) -> OK | F40: =IF(F38>=22,"OK",IF(F38<=22,"LESS")) -> OK | G40: =IF(G38>=22,"OK",IF(G38<=22,"LESS")) -> OK | H40: =IF(H38>=22,"OK",IF(H38<=22,"LESS")) -> OK | I40: =IF(I38>=22,"OK",IF(I38<=22,"LESS")) -> LESS | ... Q40: =IF(Q38>=22,"OK",IF(Q38<=22,"LESS")) -> OK
A43: Done by | B43: RAHUL
A45: Comment

Sheet 10
A1: Station: | B1: BHATAGAON RAIPUR
A2: Date: | B2: =$A$9 -> 10/01/2025 01:00 | D2: Power Off | G2: Pw.Off | L2: Link Fail | N2: Link F | P2: Maintenance | R2: Maint.
A3: Report Type: | B3: Mean | D3: Calibration | G3: Calib. | L3: Data Fail | N3: Data F | P3: Invalid | R3: Invalid
A4: Time Base: | B4: 01 Hour | D4: Zero Referrence | G4: Z.Ref | L4: Warm Up | N4: Wm. Up
