Workbook

Sheet 01
A1: Station: | B1: BHATAGAON RAIPUR
A2: Date: | B2: =$A$9 -> 01/01/2025 00:15 | D2: Power Off | G2: Pw.Off | L2: Link Fail | N2: Link F | P2: Maintenance | R2: Maint.
A3: Report Type: | B3: Mean | D3: Calibration | G3: Calib. | L3: Data Fail | N3: Data F | P3: Invalid | R3: Invalid
A4: Time Base: | B4: 15 Min | D4: Zero Referrence | G4: Z.Ref | L4: Warm Up | N4: Wm. Up
A7: Date & Time | B7: NO_BHATAGAON | C7: NO2__BHATAGAON | D7: NOX_BHATAGAON | E7: SO2__BHATAGAON | F7: O3__BHATAGAON | G7: PM10__BHATAGAON | H7: PM2_5__BHATAGAON | I7: BENZ__BHATAGAON | J7: WS__BHATAGAON | K7: WD__BHATAGAON | L7: TEMP__BHATAGAON | M7: HUM__BHATAGAON | N7: SR__BHATAGAON | O7: RG__BHATAGAON | P7: CO__BHATAGAON | Q7: NH3__BHATAGAON
B8: ug/m3 | C8: ug/m3 | D8: ppb | E8: ug/m3 | F8: ug/m3 | G8: ug/m3 | H8: ug/m3 | I8: ug/m3 | J8: m/sec | K8: deg | L8: degreC | M8: % | N8: w/m2 | O8: mm | P8: mg/m3 | Q8: ug/m3
A9: 01/01/2025 00:15 | B9: 72.09 | C9: 54.16 | D9: 84.73 | E9: 8.03 | F9: 2.13 | G9: 108.12 | H9: 33.38 | I9: Invalid | J9: 1.42 | K9: 56.29 | L9: 13.72 | M9: 69.27 | N9: 80.7 | O9: 0 | P9: 1.54 | Q9: 9.61
A10: 01/01/2025 00:30 | B10: 69.21 | C10: 53.03 | D10: 81.83 | E10: 8.21 | F10: 2.13 | G10: 108.12 | H10: 33.38 | I10: Invalid | J10: 0.33 | K10: 24.58 | L10: 13.56 | M10: 70.82 | N10: 84.5 | O10: 0 | P10: 1.51 | Q10: 9.59
A11: 01/01/2025 00:45 | B11: 66.95 | C11: 53.09 | D11: 80.05 | E11: 8.23 | F11: 2.13 | G11: 93.45 | H11: 35.8 | I11: Invalid | J11: 0.77 | K11: 286.95 | L11: 13.15 | M11: 75.91 | N11: 82.8 | O11: 0 | P11: 1.58 | Q11: 9.57
A12: 01/01/2025 01:00 | B12: 64.97 | C12: 52.6 | D12: 78.21 | E12: 8.37 | F12: 2.13 | G12: 91.82 | H12: 36.06 | I12: Invalid | J12: 1.37 | K12: 301.73 | L12: 12.84 | M12: 83.36 | N12: 83.2 | O12: 0 | P12: 1.5 | Q12: 9.57
A13: 01/01/2025 01:15 | B13: 62.45 | C13: 52.15 | D13: 75.95 | E13: 8.16 | F13: 2.13 | G13: 91.82 | H13: 36.06 | I13: Invalid | J13: 1.07 | K13: 267.24 | L13: 12.94 | M13: 75.3 | N13: 84.8 | O13: 0 | P13: 1.39 | Q13: 9.54
A14: 01/01/2025 01:30 | B14: 58.96 | C14: 51.74 | D14: 72.94 | E14: 7.93 | F14: 2.13 | G14: 91.82 | H14: 36.06 | I14: Invalid | J14: 0.69 | K14: 120.69 | L14: 13.43 | M14: 68.93 | N14: 84 | O14: 0 | P14: 1.37 | Q14: 9.42
A15: 01/01/2025 01:45 | B15: 55.45 | C15: 51.3 | D15: 69.89 | E15: 7.49 | F15: 2.13 | G15: 84.46 | H15: 34.69 | I15: Invalid | J15: 1.85 | K15: 99.55 | L15: 14.12 | M15: 63.16 | N15: 87 | O15: 0 | P15: 1.32 | Q15: 9.18
A16: 01/01/2025 02:00 | B16: 51.84 | C16: 51.16 | D16: 66.92 | E16: 7.68 | F16: 2.13 | G16: 81.3 | H16: 34.07 | I16: Invalid | J16: 2.6 | K16: 99.34 | L16: 14.19 | M16: 62.25 | N16: 87.5 | O16: 0 | P16: 1.28 | Q16: 8.94
A17: 01/01/2025 02:15 | B17: 47.97 | C17: 50.99 | D17: 63.73 | E17: 7.42 | F17: 2.13 | G17: 81.3 | H17: 34.07 | I17: Invalid | J17: 2.68 | K17: 104.02 | L17: 14.17 | M17: 62.21 | N17: 82.7 | O17: 0 | P17: 1.23 | Q17: 8.68
A18: 01/01/2025 02:30 | B18: 44.46 | C18: 51.09 | D18: 60.97 | E18: 7.21 | F18: 2.13 | G18: 81.3 | H18: 34.07 | I18: Invalid | J18: 2.24 | K18: 100.77 | L18: 14.09 | M18: 62.76 | N18: 83.3 | O18: 0 | P18: 1.19 | Q18: 8.43
A19: 01/01/2025 02:45 | B19: 41.36 | C19: 50.85 | D19: 58.36 | E19: 7.19 | F19: 2.13 | G19: 65.75 | H19: 32.82 | I19: Invalid | J19: 2.77 | K19: 108.16 | L19: 14.05 | M19: 62.16 | N19: 86 | O19: 0 | P19: 1.15 | Q19: 8.23
A20: 01/01/2025 03:00 | B20: 38.22 | C20: 50.12 | D20: 55.46 | E20: 7.08 | F20: 2.13 | G20: 58.72 | H20: 32.25 | I20: Invalid | J20: 2.32 | K20: 99.4 | L20: 14.04 | M20: 61.7 | N20: 87.7 | O20: 0 | P20: 1.1 | Q20: 8.21
... A52: 01/01/2025 11:00 | B52: 6.27 | C52: 50.84 | D52: 30.22 | E52: 5.13 | F52: 2.13 | G52: 61.84 | H52: 27.81 | I52: Invalid | J52: 1.4 | K52: 156.17 | L52: 20.48 | M52: 44.87 | N52: 544.3 | O52: 0 | P52: 0.73 | Q52: 8.21
A53: 01/01/2025 11:15 | B53: Pw.Off | C53: Pw.Off | D53: Pw.Off | E53: Pw.Off | F53: Pw.Off | G53: Pw.Off | H53: Pw.Off | I53: Pw.Off | J53: Pw.Off | K53: Pw.Off | L53: Pw.Off | M53: Pw.Off | N53: Pw.Off | O53: Pw.Off | P53: Pw.Off | Q53: Pw.Off
A54: 01/01/2025 11:30 | B54: Pw.Off | C54: Pw.Off | D54: Pw.Off | E54: Pw.Off | F54: Pw.Off | G54: Pw.Off | H54: Pw.Off | I54: Pw.Off | J54: Pw.Off | K54: Pw.Off | L54: Pw.Off | M54: Pw.Off | N54: Pw.Off | O54: Pw.Off | P54: Pw.Off | Q54: Pw.Off
A55: 01/01/2025 11:45 | B55: Pw.Off | C55: Pw.Off | D55: Pw.Off | E55: Pw.Off | F55: Pw.Off | G55: Pw.Off | H55: Pw.Off | I55: Pw.Off | J55: Pw.Off | K55: Pw.Off | L55: Pw.Off | M55: Pw.Off | N55: Pw.Off | O55: Pw.Off | P55: Pw.Off | Q55: Pw.Off
A56: 01/01/2025 12:00 | B56: Pw.Off | C56: Pw.Off | D56: Pw.Off | E56: Pw.Off | F56: Pw.Off | G56: Pw.Off | H56: Pw.Off | I56: Pw.Off | J56: Pw.Off | K56: Pw.Off | L56: Pw.Off | M56: Pw.Off | N56: Pw.Off | O56: Pw.Off | P56: Pw.Off | Q56: Pw.Off
A57: 01/01/2025 12:15 | B57: Pw.Off | C57: Pw.Off | D57: Pw.Off | E57: Pw.Off | F57: Pw.Off | G57: Pw.Off | H57: Pw.Off | I57: Pw.Off | J57: Pw.Off | K57: Pw.Off | L57: Pw.Off | M57: Pw.Off | N57: Pw.Off | O57: Pw.Off | P57: Pw.Off | Q57: Pw.Off
A58: 01/01/2025 12:30 | B58: Pw.Off | C58: Pw.Off | D58: Pw.Off | E58: Pw.Off | F58: Pw.Off | G58: Pw.Off | H58: Pw.Off | I58: Pw.Off | J58: Pw.Off | K58: Pw.Off | L58: Pw.Off | M58: Pw.Off | N58: Pw.Off | O58: Pw.Off | P58: Pw.Off | Q58: Pw.Off
A59: 01/01/2025 12:45 | B59: Pw.Off | C59: Pw.Off | D59: Pw.Off | E59: Pw.Off | F59: Pw.Off | G59: Pw.Off | H59: Pw.Off | I59: Pw.Off | J59: Pw.Off | K59: Pw.Off | L59: Pw.Off | M59: Pw.Off | N59: Pw.Off | O59: Pw.Off | P59: Pw.Off | Q59: Pw.Off
A60: 01/01/2025 13:00 | B60: Pw.Off | C60: Pw.Off | D60: Pw.Off | E60: Pw.Off | F60: Pw.Off | G60: Pw.Off | H60: Pw.Off | I60: Pw.Off | J60: Pw.Off | K60: Pw.Off | L60: Pw.Off | M60: Pw.Off | N60: Pw.Off | O60: Pw.Off | P60: Pw.Off | Q60: Pw.Off
A61: 01/01/2025 13:15 | B61: Pw.Off | C61: Pw.Off | D61: Pw.Off | E61: Pw.Off | F61: Pw.Off | G61: Pw.Off | H61: Pw.Off | I61: Pw.Off | J61: Pw.Off | K61: Pw.Off | L61: Pw.Off | M61: Pw.Off | N61: Pw.Off | O61: Pw.Off | P61: Pw.Off | Q61: Pw.Off
A62: 01/01/2025 13:30 | B62: Pw.Off | C62: Pw.Off | D62: Pw.Off | E62: Pw.Off | F62: Pw.Off | G62: Pw.Off | H62: Pw.Off | I62: Pw.Off | J62: Pw.Off | K62: Pw.Off | L62: Pw.Off | M62: Pw.Off | N62: Pw.Off | O62: Pw.Off | P62: Pw.Off | Q62: Pw.Off
A63: 01/01/2025 13:45 | B63: Pw.Off | C63: Pw.Off | D63: Pw.Off | E63: Pw.Off | F63: Pw.Off | G63: Pw.Off | H63: Pw.Off | I63: Pw.Off | J63: Pw.Off | K63: Pw.Off | L63: Pw.Off | M63: Pw.Off | N63: Pw.Off | O63: Pw.Off | P63: Pw.Off | Q63: Pw.Off
A64: 01/01/2025 14:00 | B64: Pw.Off | C64: Pw.Off | D64: Pw.Off | E64: Pw.Off | F64: Pw.Off | G64: Pw.Off | H64: Pw.Off | I64: Pw.Off | J64: Pw.Off | K64: Pw.Off | L64: Pw.Off | M64: Pw.Off | N64: Pw.Off | O64: Pw.Off | P64: Pw.Off | Q64: Pw.Off
... A104: 01/01/2025 24:00 | B104: Pw.Off | C104: Pw.Off | D104: Pw.Off | E104: Pw.Off | F104: Pw.Off | G104: Pw.Off | H104: Pw.Off | I104: Pw.Off | J104: Pw.Off | K104: Pw.Off | L104: Pw.Off | M104: Pw.Off | N104: Pw.Off | O104: Pw.Off | P104: Pw.Off | Q104: Pw.Off
A106: Min | B106: =MIN(B9:B104) -> 6.27 | C106: =MIN(C9:C104) -> 47.58 | D106: =MIN(D9:D104) -> 30.22 | E106: =MIN(E9:E104) -> 5.13 | F106: =MIN(F9:F104) -> 2.13 | G106: =MIN(G9:G104) -> 44.16 | H106: =MIN(H9:H104) -> 26.06 | I106: =MIN(I9:I104) -> 0 | ... Q106: =MIN(Q9:Q104) -> 8.21
A107: Max | B107: =MAX(B9:B104) -> 72.09 | C107: =MAX(C9:C104) -> 54.16 | D107: =MAX(D9:D104) -> 84.73 | E107: =MAX(E9:E104) -> 8.37 | F107: =MAX(F9:F104) -> 2.13 | G107: =MAX(G9:G104) -> 108.12 | H107: =MAX(H9:H104) -> 36.06 | I107: =MAX(I9:I104) -> 0 | ... Q107: =MAX(Q9:Q104) -> 9.61
A108: Avg | B108: =AVERAGE(B9:B104) -> 29.749091 | C108: =AVERAGE(C9:C104) -> 49.881591 | D108: =AVERAGE(D9:D104) -> 48.541364 | E108: =AVERAGE(E9:E104) -> 6.8454545 | F108: =AVERAGE(F9:F104) -> 2.13 | G108: =AVERAGE(G9:G104) -> 71.768182 | H108: =AVERAGE(H9:H104) -> 30.74 | I108: =AVERAGE(I9:I104) -> #DIV/0! | ... Q108: =AVERAGE(Q9:Q104) -> 8.4475
A109: Stdev | B109: =STDEV(B9:B104) -> 18.526613 | C109: =STDEV(C9:C104) -> 1.6203789 | D109: =STDEV(D9:D104) -> 15.461061 | E109: =STDEV(E9:E104) -> 0.870732 | F109: =STDEV(F9:F104) -> 4.4922336e-16 | G109: =STDEV(G9:G104) -> 15.78505 | H109: =STDEV(H9:H104) -> 3.0116418 | I109: =STDEV(I9:I104) -> #DIV/0! | ... Q109: =STDEV(Q9:Q104) -> 0.48364471
A110: Num | B110: =COUNT(B9:B104)+52 -> 96 | C110: =COUNT(C9:C104)+52 -> 96 | D110: =COUNT(D9:D104)+52 -> 96 | E110: =COUNT(E9:E104)+52 -> 96 | F110: =COUNT(F9:F104)+52 -> 96 | G110: =COUNT(G9:G104)+52 -> 96 | H110: =COUNT(H9:H104)+52 -> 96 | I110: =COUNT(I9:I104) -> 0 | J110: =COUNT(J9:J104)+52 -> 96 | K110: =COUNT(K9:K104)+52 -> 96 | L110: =COUNT(L9:L104)+52 -> 96 | M110: =COUNT(M9:M104)+52 -> 96 | N110: =COUNT(N9:N104)+52 -> 96 | O110: =COUNT(O9:O104)+52 -> 96 | P110: =COUNT(P9:P104)+52 -> 96 | Q110: =COUNT(Q9:Q104)+52 -> 96
A111: DCR | B111: =IF(B110>=87,">90%",IF(B110<=87,"<90%")) -> >90% | C111: =IF(C110>=87,">90%",IF(C110<=87,"<90%")) -> >90% | D111: =IF(D110>=87,">90%",IF(D110<=87,"<90%")) -> >90% | E111: =IF(E110>=87,">90%",IF(E110<=87,"<90%")) -> >90% | F111: =IF(F110>=87,">90%",IF(F110<=87,"<90%")) -> >90% | G111: =IF(G110>=87,">90%",IF(G110<=87,"<90%")) -> >90% | H111: =IF(H110>=87,">90%",IF(H110<=87,"<90%")) -> >90% | I111: =IF(I110>=87,">90%",IF(I110<=87,"<90%")) -> <90% | ... Q111: =IF(Q110>=87,">90%",IF(Q110<=87,"<90%")) -> >90%
A112: Status | B112: =IF(B110>=87,"OK",IF(B110<=87,"LESS")) -> OK | C112: =IF(C110>=87,"OK",IF(C110<=87,"LESS")) -> OK | D112: =IF(D110>=87,"OK",IF(D110<=87,"LESS")) -> OK | E112: =IF(E110>=87,"OK",IF(E110<=87,"LESS")) -> OK | F112: =IF(F110>=87,"OK",IF(F110<=87,"LESS")) -> OK | G112: =IF(G110>=87,"OK",IF(G110<=87,"LESS")) -> OK | H112: =IF(H110>=87,"OK",IF(H110<=87,"LESS")) -> OK | I112: =IF(I110>=87,"OK",IF(I110<=87,"LESS")) -> LESS | ... Q112: =IF(Q110>=87,"OK",IF(Q110<=87,"LESS")) -> OK
A115: Done by | B115: RK
...

Sheet 02
A1: Station: | B1: BHATAGAON RAIPUR
A2: Date: | B2: =$A$9 -> 02/01/2025 00:15 | D2: Power Off | G2: Pw.Off | L2: Link Fail | N2: Link F | P2: Maintenance | R2: Maint.
A3: Report Type: | B3: Mean | D3: Calibration | G3: Calib. | L3: Data Fail | N3: Data F | P3: Invalid | R3: Invalid
A4: Time Base: | B4: 15 Min | D4: Zero Referrence | G4: Z.Ref | L4: Warm Up | N4: Wm. Up
A7: Date & Time | B7: NO_BHATAGAON | C7: NO2__BHATAGAON | D7: NOX_BHATAGAON | E7: SO2__BHATAGAON | F7: O3__BHATAGAON | G7: PM10__BHATAGAON | H7: PM2_5__BHATAGAON | I7: BENZ__BHATAGAON | J7: WS__BHATAGAON | K7: WD__BHATAGAON | L7: TEMP__BHATAGAON | M7: HUM__BHATAGAON | N7: SR__BHATAGAON | O7: RG__BHATAGAON | P7: CO__BHATAGAON | Q7: NH3__BHATAGAON
B8: ug/m3 | C8: ug/m3 | D8: ppb | E8: ug/m3 | F8: ug/m3 | G8: ug/m3 | H8: ug/m3 | I8: ug/m3 | J8: m/sec | K8: deg | L8: degreC | M8: % | N8: w/m2 | O8: mm | P8: mg/m3 | Q8: ug/m3
A9: 02/01/2025 00:15 | B9: 132.98 | C9: 47.92 | D9: 130.3 | E9: 8.41 | F9: 2.13 | G9: 186.39 | H9: 45.08 | I9: Invalid | J9: 0.98 | K9: 316.04 | L9: 11.01 | M9: 86.97 | N9: 97.9 | O9: 0 | P9: 2.1 | Q9: 10.29
A10: 02/01/2025 00:30 | B10: 133.76 | C10: 47.79 | D10: 130.86 | E10: 8.32 | F10: 2.13 | G10: 186.39 | H10: 45.08 | I10: Invalid | J10: 2.55 | K10: 346.84 | L10: 10.62 | M10: 91.03 | N10: 98.1 | O10: 0 | P10: 2.1 | Q10: 10.31
A11: 02/01/2025 00:45 | B11: 132.57 | C11: 47.21 | D11: 129.59 | E11: 7.88 | F11: 2.13 | G11: 157.3 | H11: 54.93 | I11: Invalid | J11: 1.63 | K11: 250.29 | L11: 10.54 | M11: 92.36 | N11: 97.7 | O11: 0 | P11: 2.08 | Q11: 10.28
A12: 02/01/2025 01:00 | B12: 130.25 | C12: 45.73 | D12: 126.96 | E12: 7.98 | F12: 2.15 | G12: 144.84 | H12: 59.15 | I12: Invalid | J12: 2.43 | K12: 334.39 | L12: 10.54 | M12: 92.85 | N12: 98.2 | O12: 0 | P12: 2.04 | Q12: 10.29
A13: 02/01/2025 01:15 | B13: 128.5 | C13: 43.39 | D13: 124.34 | E13: 8.45 | F13: 2.13 | G13: 144.84 | H13: 59.15 | I13: Invalid | J13: 2.17 | K13: 300.51 | L13: 10.18 | M13: 95.33 | N13: 98.4 | O13: 0 | P13: 1.77 | Q13: 10.25
A14: 02/01/2025 01:30 | B14: 128.67 | C14: 43.52 | D14: 124.55 | E14: 8.09 | F14: 2.13 | G14: 144.84 | H14: 59.15 | I14: Invalid | J14: 2.51 | K14: 322.3 | L14: 9.92 | M14: 97.35 | N14: 98.6 | O14: 0 | P14: 1.85 | Q14: 10.25
A15: 02/01/2025 01:45 | B15: 129.21 | C15: 43.22 | D15: 124.82 | E15: 7.88 | F15: 2.13 | G15: 136.41 | H15: 49.53 | I15: Invalid | J15: 1.17 | K15: 348.63 | L15: 9.87 | M15: 91.05 | N15: 98.3 | O15: 0 | P15: 1.81 | Q15: 10.27
A16: 02/01/2025 02:00 | B16: 126.47 | C16: 42.7 | D16: 122.35 | E16: 8.19 | F16: 2.13 | G16: 132.8 | H16: 45.18 | I16: Invalid | J16: 1.63 | K16: 58.14 | L16: 10.75 | M16: 66.94 | N16: 97.7 | O16: 0 | P16: 1.75 | Q16: 10.26
A17: 02/01/2025 02:15 | B17: 121.1 | C17: 42.57 | D17: 117.98 | E17: 7.57 | F17: 2.26 | G17: 132.8 | H17: 45.18 | I17: Invalid | J17: 0.85 | K17: 15.03 | L17: 11.31 | M17: 56.96 | N17: 98 | O17: 0 | P17: 1.69 | Q17: 10.24
A18: 02/01/2025 02:30 | B18: 114.96 | C18: 42.09 | D18: 112.8 | E18: 7.48 | F18: 2.13 | G18: 132.8 | H18: 45.18 | I18: Invalid | J18: 2.13 | K18: 237.58 | L18: 11.1 | M18: 61.34 | N18: 98.3 | O18: 0 | P18: 1.66 | Q18: 10.18
A19: 02/01/2025 02:45 | B19: 108.96 | C19: 41.92 | D19: 107.9 | E19: 6.99 | F19: 2.13 | G19: 92.59 | H19: 31.68 | I19: Invalid | J19: 2.61 | K19: 197.7 | L19: 10.8 | M19: 72.47 | N19: 98.3 | O19: 0 | P19: 1.6 | Q19: 10.14
A20: 02/01/2025 03:00 | B20: 103.97 | C20: 41.97 | D20: 103.92 | E20: 6.79 | F20: 2.13 | G20: 75.36 | H20: 25.58 | I20: Invalid | J20: 2.35 | K20: 212.8 | L20: 9.95 | M20: 89.97 | N20: 99.1 | O20: 0 | P20: 1.56 | Q20: 10.09
... A104: 02/01/2025 24:00 | B104: 100.98 | C104: 48.03 | D104: 104.69 | E104: 6.33 | F104: 2.13 | G104: 79.14 | H104: 45.07 | I104: Invalid | J104: 0.97 | K104: 339.17 | L104: 13.77 | M104: 45.36 | N104: 147.3 | O104: 0 | P104: 2.03 | Q104: 9.97
A106: Min | B106: =MIN(B9:B104) -> 3.34 | C106: =MIN(C9:C104) -> 38.11 | D106: =MIN(D9:D104) -> 34.21 | E106: =MIN(E9:E104) -> 4.65 | F106: =MIN(F9:F104) -> 2.13 | G106: =MIN(G9:G104) -> 34.91 | H106: =MIN(H9:H104) -> 0.6 | I106: =MIN(I9:I104) -> 0 | ... Q106: =MIN(Q9:Q104) -> 8.21
A107: Max | B107: =MAX(B9:B104) -> 134.33 | C107: =MAX(C9:C104) -> 74.67 | D107: =MAX(D9:D104) -> 136.27 | E107: =MAX(E9:E104) -> 12.13 | F107: =MAX(F9:F104) -> 5 | G107: =MAX(G9:G104) -> 242.04 | H107: =MAX(H9:H104) -> 65.25 | I107: =MAX(I9:I104) -> 0 | ... Q107: =MAX(Q9:Q104) -> 10.31
A108: Avg | B108: =AVERAGE(B9:B104) -> 61.586458 | C108: =AVERAGE(C9:C104) -> 53.068021 | D108: =AVERAGE(D9:D104) -> 75.7375 | E108: =AVERAGE(E9:E104) -> 7.0536458 | F108: =AVERAGE(F9:F104) -> 2.2005208 | G108: =AVERAGE(G9:G104) -> 103.9949 | H108: =AVERAGE(H9:H104) -> 32.914688 | I108: =AVERAGE(I9:I104) -> #DIV/0! | ... Q108: =AVERAGE(Q9:Q104) -> 9.1742708
A109: Stdev | B109: =STDEV(B9:B104) -> 46.401342 | C109: =STDEV(C9:C104) -> 10.736706 | D109: =STDEV(D9:D104) -> 34.504851 | E109: =STDEV(E9:E104) -> 1.7759849 | F109: =STDEV(F9:F104) -> 0.38280233 | G109: =STDEV(G9:G104) -> 55.37641 | H109: =STDEV(H9:H104) -> 17.316285 | I109: =STDEV(I9:I104) -> #DIV/0! | ... Q109: =STDEV(Q9:Q104) -> 0.87251933
A110: Num | B110: =COUNT(B9:B104) -> 96 | C110: =COUNT(C9:C104) -> 96 | D110: =COUNT(D9:D104) -> 96 | E110: =COUNT(E9:E104) -> 96 | F110: =COUNT(F9:F104) -> 96 | G110: =COUNT(G9:G104) -> 96 | H110: =COUNT(H9:H104) -> 96 | I110: =COUNT(I9:I104) -> 0 | ... Q110: =COUNT(Q9:Q104) -> 96
A111: DCR | B111: =IF(B110>=87,">90%",IF(B110<=87,"<90%")) -> >90% | C111: =IF(C110>=87,">90%",IF(C110<=87,"<90%")) -> >90% | D111: =IF(D110>=87,">90%",IF(D110<=87,"<90%")) -> >90% | E111: =IF(E110>=87,">90%",IF(E110<=87,"<90%")) -> >90% | F111: =IF(F110>=87,">90%",IF(F110<=87,"<90%")) -> >90% | G111: =IF(G110>=87,">90%",IF(G110<=87,"<90%")) -> >90% | H111: =IF(H110>=87,">90%",IF(H110<=87,"<90%")) -> >90% | I111: =IF(I110>=87,">90%",IF(I110<=87,"<90%")) -> <90% | ... Q111: =IF(Q110>=87,">90%",IF(Q110<=87,"<90%")) -> >90%
A112: Status | B112: =IF(B110>=87,"OK",IF(B110<=87,"LESS")) -> OK | C112: =IF(C110>=87,"OK",IF(C110<=87,"LESS")) -> OK | D112: =IF(D110>=87,"OK",IF(D110<=87,"LESS")) -> OK | E112: =IF(E110>=87,"OK",IF(E110<=87,"LESS")) -> OK | F112: =IF(F110>=87,"OK",IF(F110<=87,"LESS")) -> OK | G112: =IF(G110>=87,"OK",IF(G110<=87,"LESS")) -> OK | H112: =IF(H110>=87,"OK",IF(H110<=87,"LESS")) -> OK | I112: =IF(I110>=87,"OK",IF(I110<=87,"LESS")) -> LESS | ... Q112: =IF(Q110>=87,"OK",IF(Q110<=87,"LESS")) -> OK
A115: Done by | B115: RK
A117: Comment

Sheet 03
A1: Station: | B1: BHATAGAON RAIPUR
A2: Date: | B2: =$A$9 -> 03/01/2025 00:15 | D2: Power Off | G2: Pw.Off | L2: Link Fail | N2: Link F | P2: Maintenance | R2: Maint.
A3: Report Type: | B3: Mean | D3: Calibration | G3: Calib. | L3: Data Fail | N3: Data F | P3: Invalid | R3: Invalid
A4: Time Base: | B4: 15 Min | D4: Zero Referrence | G4: Z.Ref | L4: Warm Up | N4: Wm. Up
A7: Date & Time | B7: NO_BHATAGAON | C7: NO2__BHATAGAON | D7: NOX_BHATAGAON | E7: SO2__BHATAGAON | F7: O3__BHATAGAON | G7: PM10__BHATAGAON | H7: PM2_5__BHATAGAON | I7: BENZ__BHATAGAON | J7: WS__BHATAGAON | K7: WD__BHATAGAON | L7: TEMP__BHATAGAON | M7: HUM__BHATAGAON | N7: SR__BHATAGAON | O7: RG__BHATAGAON | P7: CO__BHATAGAON | Q7: NH3__BHATAGAON
B8: ug/m3 | C8: ug/m3 | D8: ppb | E8: ug/m3 | F8: ug/m3 | G8: ug/m3 | H8: ug/m3 | I8: ug/m3 | J8: m/sec | K8: deg | L8: degreC | M8: % | N8: w/m2 | O8: mm | P8: mg/m3 | Q8: ug/m3
A9: 03/01/2025 00:15 | B9: 96.43 | C9: 47.6 | D9: 100.82 | E9: 6.6 | F9: 2.13 | G9: 79.14 | H9: 45.07 | I9: Invalid | J9: 2.42 | K9: 266.13 | L9: 13.11 | M9: 50.36 | N9: 147.3 | O9: 0 | P9: 1.96 | Q9: 9.93
A10: 03/01/2025 00:30 | B10: 91.28 | C10: 47.53 | D10: 96.66 | E10: 6.63 | F10: 2.13 | G10: 79.14 | H10: 45.07 | I10: Invalid | J10: 2.26 | K10: 311.14 | L10: 12.6 | M10: 53.52 | N10: 146.9 | O10: 0 | P10: 1.88 | Q10: 9.91
A11: 03/01/2025 00:45 | B11: 86.72 | C11: 47.38 | D11: 92.92 | E11: 5.93 | F11: 2.13 | G11: 74.3 | H11: 36.8 | I11: Invalid | J11: 0.84 | K11: 38.73 | L11: 12.79 | M11: 47.74 | N11: 145.9 | O11: 0 | P11: 1.83 | Q11: 9.87
A12: 03/01/2025 01:00 | B12: 82.51 | C12: 46.73 | D12: 89.21 | E12: 6.15 | F12: 2.13 | G12: 72.22 | H12: 33.25 | I12: Invalid | J12: 0.98 | K12: 7.41 | L12: 13.26 | M12: 44.41 | N12: 146 | O12: 0 | P12: 1.75 | Q12: 9.83
A13: 03/01/2025 01:15 | B13: 77.85 | C13: 46.81 | D13: 85.51 | E13: 5.99 | F13: 2.13 | G13: 72.22 | H13: 33.25 | I13: Invalid | J13: 1.06 | K13: 312.45 | L13: 13.27 | M13: 44.04 | N13: 146.4 | O13: 0 | P13: 1.49 | Q13: 9.79
A14: 03/01/2025 01:30 | B14: 73.33 | C14: 46.86 | D14: 81.91 | E14: 5.64 | F14: 2.13 | G14: 72.22 | H14: 33.25 | I14: Invalid | J14: 1.79 | K14: 333.37 | L14: 13.17 | M14: 43.43 | N14: 146.8 | O14: 0 | P14: 1.5 | Q14: 9.77
A15: 03/01/2025 01:45 | B15: 69.47 | C15: 46.32 | D15: 78.53 | E15: 5.57 | F15: 2.13 | G15: 58.87 | H15: 19.51 | I15: Invalid | J15: 1.15 | K15: 334.49 | L15: 13.05 | M15: 44.22 | N15: 147.6 | O15: 0 | P15: 1.43 | Q15: 9.73
A16: 03/01/2025 02:00 | B16: 65.8 | C16: 45.5 | D16: 75.16 | E16: 5.08 | F16: 2.13 | G16: 53.15 | H16: 13.62 | I16: Invalid | J16: 1.34 | K16: 344.76 | L16: 12.64 | M16: 44.91 | N16: 148.2 | O16: 0 | P16: 1.32 | Q16: 9.71
A17: 03/01/2025 02:15 | B17: 62.03 | C17: 44.17 | D17: 71.45 | E17: 5.15 | F17: 2.13 | G17: 53.15 | H17: 13.62 | I17: Invalid | J17: 1.45 | K17: 9.9 | L17: 12.3 | M17: 45.67 | N17: 148.6 | O17: 0 | P17: 1.26 | Q17: 9.67
A18: 03/01/2025 02:30 | B18: 58.97 | C18: 44.11 | D18: 68.96 | E18: 5.51 | F18: 2.13 | G18: 53.15 | H18: 13.62 | I18: Invalid | J18: 2.02 | K18: 306.17 | L18: 11.9 | M18: 52.31 | N18: 148.6 | O18: 0 | P18: 1.23 | Q18: 9.63
A19: 03/01/2025 02:45 | B19: 56.4 | C19: 43.47 | D19: 66.56 | E19: 5.28 | F19: 2.13 | G19: 48.83 | H19: 13.66 | I19: Invalid | J19: 2.76 | K19: 270.73 | L19: 11.29 | M19: 55.79 | N19: 148 | O19: 0 | P19: 1.19 | Q19: 9.64
A20: 03/01/2025 03:00 | B20: 54.06 | C20: 42.52 | D20: 64.19 | E20: 4.91 | F20: 2.13 | G20: 46.98 | H20: 13.68 | I20: Invalid | J20: 2.18 | K20: 296.96 | L20: 11.24 | M20: 55.73 | N20: 147.6 | O20: 0 | P20: 1.12 | Q20: 9.64
... A104: 03/01/2025 24:00 | B104: 226.64 | C104: 50.35 | D104: 206.68 | E104: 9.39 | F104: 2.13 | G104: 224.96 | H104: 65.28 | I104: Invalid | J104: 0.9 | K104: 295.71 | L104: 12.2 | M104: 72.02 | N104: 53.5 | O104: 0 | P104: 2.29 | Q104: 10.83
A106: Min | B106: =MIN(B9:B104) -> 15.93 | C106: =MIN(C9:C104) -> 40.07 | D106: =MIN(D9:D104) -> 41.34 | E106: =MIN(E9:E104) -> 4.71 | F106: =MIN(F9:F104) -> 2.13 | G106: =MIN(G9:G104) -> 31.07 | H106: =MIN(H9:H104) -> 0.03 | I106: =MIN(I9:I104) -> 0 | ... Q106: =MIN(Q9:Q104) -> 8.34
A107: Max | B107: =MAX(B9:B104) -> 226.64 | C107: =MAX(C9:C104) -> 62.26 | D107: =MAX(D9:D104) -> 206.7 | E107: =MAX(E9:E104) -> 13.14 | F107: =MAX(F9:F104) -> 2.13 | G107: =MAX(G9:G104) -> 224.96 | H107: =MAX(H9:H104) -> 150.14 | I107: =MAX(I9:I104) -> 0 | ... Q107: =MAX(Q9:Q104) -> 10.83
A108: Avg | B108: =AVERAGE(B9:B104) -> 69.267396 | C108: =AVERAGE(C9:C104) -> 50.73625 | D108: =AVERAGE(D9:D104) -> 80.67875 | E108: =AVERAGE(E9:E104) -> 7.0464583 | F108: =AVERAGE(F9:F104) -> 2.13 | G108: =AVERAGE(G9:G104) -> 101.83896 | H108: =AVERAGE(H9:H104) -> 33.39 | I108: =AVERAGE(I9:I104) -> #DIV/0! | ... Q108: =AVERAGE(Q9:Q104) -> 9.5439583
A109: Stdev | B109: =STDEV(B9:B104) -> 52.640385 | C109: =STDEV(C9:C104) -> 7.2583005 | D109: =STDEV(D9:D104) -> 42.161371 | E109: =STDEV(E9:E104) -> 2.4419112 | F109: =STDEV(F9:F104) -> 2.6785224e-15 | G109: =STDEV(G9:G104) -> 54.277709 | H109: =STDEV(H9:H104) -> 28.101194 | I109: =STDEV(I9:I104) -> #DIV/0! | ... Q109: =STDEV(Q9:Q104) -> 0.63873473
A110: Num | B110: =COUNT(B9:B104) -> 96 | C110: =COUNT(C9:C104) -> 96 | D110: =COUNT(D9:D104) -> 96 | E110: =COUNT(E9:E104) -> 96 | F110: =COUNT(F9:F104) -> 96 | G110: =COUNT(G9:G104) -> 96 | H110: =COUNT(H9:H104) -> 96 | I110: =COUNT(I9:I104) -> 0 | ... Q110: =COUNT(Q9:Q104) -> 96
A111: DCR | B111: =IF(B110>=87,">90%",IF(B110<=87,"<90%")) -> >90% | C111: =IF(C110>=87,">90%",IF(C110<=87,"<90%")) -> >90% | D111: =IF(D110>=87,">90%",IF(D110<=87,"<90%")) -> >90% | E111: =IF(E110>=87,">90%",IF(E110<=87,"<90%")) -> >90% | F111: =IF(F110>=87,">90%",IF(F110<=87,"<90%")) -> >90% | G111: =IF(G110>=87,">90%",IF(G110<=87,"<90%")) -> >90% | H111: =IF(H110>=87,">90%",IF(H110<=87,"<90%")) -> >90% | I111: =IF(I110>=87,">90%",IF(I110<=87,"<90%")) -> <90% | ... Q111: =IF(Q110>=87,">90%",IF(Q110<=87,"<90%")) -> >90%
A112: Status | B112: =IF(B110>=87,"OK",IF(B110<=87,"LESS")) -> OK | C112: =IF(C110>=87,"OK",IF(C110<=87,"LESS")) -> OK | D112: =IF(D110>=87,"OK",IF(D110<=87,"LESS")) -> OK | E112: =IF(E110>=87,"OK",IF(E110<=87,"LESS")) -> OK | F112: =IF(F110>=87,"OK",IF(F110<=87,"LESS")) -> OK | G112: =IF(G110>=87,"OK",IF(G110<=87,"LESS")) -> OK | H112: =IF(H110>=87,"OK",IF(H110<=87,"LESS")) -> OK | I112: =IF(I110>=87,"OK",IF(I110<=87,"LESS")) -> LESS | ... Q112: =IF(Q110>=87,"OK",IF(Q110<=87,"LESS")) -> OK
A115: Done by | B115: RK
A117: Comment

Sheet 04
A1: Station: | B1: BHATAGAON RAIPUR
A2: Date: | B2: =$A$9 -> 04/01/2025 00:15 | D2: Power Off | G2: Pw.Off | L2: Link Fail | N2: Link F | P2: Maintenance | R2: Maint.
A3: Report Type: | B3: Mean | D3: Calibration | G3: Calib. | L3: Data Fail | N3: Data F | P3: Invalid | R3: Invalid
A4: Time Base: | B4: 15 Min | D4: Zero Referrence | G4: Z.Ref | L4: Warm Up | N4: Wm. Up
A7: Date & Time | B7: NO_BHATAGAON | C7: NO2__BHATAGAON | D7: NOX_BHATAGAON | E7: SO2__BHATAGAON | F7: O3__BHATAGAON | G7: PM10__BHATAGAON | H7: PM2_5__BHATAGAON | I7: BENZ__BHATAGAON | J7: WS__BHATAGAON | K7: WD__BHATAGAON | L7: TEMP__BHATAGAON | M7: HUM__BHATAGAON | N7: SR__BHATAGAON | O7: RG__BHATAGAON | P7: CO__BHATAGAON | Q7: NH3__BHATAGAON
B8: ug/m3 | C8: ug/m3 | D8: ppb | E8: ug/m3 | F8: ug/m3 | G8: ug/m3 | H8: ug/m3 | I8: ug/m3 | J8: m/sec | K8: deg | L8: degreC | M8: % | N8: w/m2 | O8: mm | P8: mg/m3 | Q8: ug/m3
A9: 04/01/2025 00:15 | B9: 223.38 | C9: 49.09 | D9: 203.41 | E9: 9.97 | F9: 2.13 | G9: 224.96 | H9: 65.28 | I9: Invalid | J9: 0.76 | K9: 222.84 | L9: 11.83 | M9: 72.23 | N9: 53.9 | O9: 0 | P9: 2.26 | Q9: 10.83
A10: 04/01/2025 00:30 | B10: 218.56 | C10: 47.67 | D10: 198.8 | E10: 9.77 | F10: 2.13 | G10: 224.96 | H10: 65.28 | I10: Invalid | J10: 0.61 | K10: 242.09 | L10: 11.39 | M10: 78.17 | N10: 53.7 | O10: 0 | P10: 2.24 | Q10: 10.82
A11: 04/01/2025 00:45 | B11: 215.03 | C11: 47.01 | D11: 195.62 | E11: 9.43 | F11: 2.13 | G11: 178.52 | H11: 53.85 | I11: Invalid | J11: 0.27 | K11: 188.65 | L11: 11.12 | M11: 78.84 | N11: 53.7 | O11: 0 | P11: 2.22 | Q11: 10.76
A12: 04/01/2025 01:00 | B12: 211.11 | C12: 45.73 | D12: 191.81 | E12: 9.34 | F12: 2.13 | G12: 158.62 | H12: 48.95 | I12: Invalid | J12: 0.61 | K12: 269.66 | L12: 11 | M12: 78.87 | N12: 53.8 | O12: 0 | P12: 2.2 | Q12: 10.7
A13: 04/01/2025 01:15 | B13: 205.03 | C13: 45.1 | D13: 186.6 | E13: 9.15 | F13: 2.13 | G13: 158.62 | H13: 48.95 | I13: Invalid | J13: 0.13 | K13: 337.29 | L13: 10.69 | M13: 77.75 | N13: 53.9 | O13: 0 | P13: 1.91 | Q13: 10.62
A14: 04/01/2025 01:30 | B14: 197.62 | C14: 44.43 | D14: 180.32 | E14: 8.8 | F14: 2.13 | G14: 158.62 | H14: 48.95 | I14: Invalid | J14: 0.37 | K14: 198.45 | L14: 10.54 | M14: 79.12 | N14: 53.6 | O14: 0 | P14: 1.97 | Q14: 10.53
A15: 04/01/2025 01:45 | B15: 189.63 | C15: 43.77 | D15: 173.56 | E15: 8.37 | F15: 2.13 | G15: 115.1 | H15: 38.7 | I15: Invalid | J15: 0.77 | K15: 280.72 | L15: 10.49 | M15: 77.55 | N15: 53.7 | O15: 0 | P15: 1.92 | Q15: 10.46
A16: 04/01/2025 02:00 | B16: 181.07 | C16: 43.36 | D16: 166.48 | E16: 7.89 | F16: 2.13 | G16: 96.45 | H16: 34.31 | I16: Invalid | J16: 0.63 | K16: 152.88 | L16: 10.28 | M16: 77 | N16: 53.7 | O16: 0 | P16: 1.87 | Q16: 10.36
A17: 04/01/2025 02:15 | B17: 172.42 | C17: 43.77 | D17: 159.76 | E17: 7.63 | F17: 2.13 | G17: 96.45 | H17: 34.31 | I17: Invalid | J17: 0.34 | K17: 196.32 | L17: 10.13 | M17: 80.2 | N17: 53.6 | O17: 0 | P17: 1.82 | Q17: 10.27
A18: 04/01/2025 02:30 | B18: 164.27 | C18: 43.81 | D18: 153.24 | E18: 7.36 | F18: 2.13 | G18: 96.45 | H18: 34.31 | I18: Invalid | J18: 0.88 | K18: 313.19 | L18: 9.93 | M18: 85.54 | N18: 53.8 | O18: 0 | P18: 1.77 | Q18: 10.17
A19: 04/01/2025 02:45 | B19: 157.49 | C19: 44.08 | D19: 147.94 | E19: 7.47 | F19: 2.13 | G19: 99.7 | H19: 35.57 | I19: Invalid | J19: 0.96 | K19: 240.8 | L19: 9.79 | M19: 86.69 | N19: 53.8 | O19: 0 | P19: 1.73 | Q19: 10.12
A20: 04/01/2025 03:00 | B20: 151.52 | C20: 44.08 | D20: 143.16 | E20: 7.76 | F20: 2.13 | G20: 101.17 | H20: 36.14 | I20: Invalid | J20: 0.86 | K20: 226.11 | L20: 9.59 | M20: 88.1 | N20: 53.8 | O20: 0 | P20: 1.67 | Q20: 10.08
... A104: 04/01/2025 24:00 | B104: 287.88 | C104: 47.59 | D104: 254.35 | E104: 10.74 | F104: 2.13 | G104: 215.06 | H104: 58.65 | I104: Invalid | J104: 1.03 | K104: 308.4 | L104: 11.32 | M104: 90.73 | N104: 52.9 | O104: 0 | P104: 2.93 | Q104: 10.97
A106: Min | B106: =MIN(B9:B104) -> 21.23 | C106: =MIN(C9:C104) -> 38.43 | D106: =MIN(D9:D104) -> 44.04 | E106: =MIN(E9:E104) -> 4.1 | F106: =MIN(F9:F104) -> 2.13 | G106: =MIN(G9:G104) -> 45.12 | H106: =MIN(H9:H104) -> 12.86 | I106: =MIN(I9:I104) -> 0 | ... Q106: =MIN(Q9:Q104) -> 8.21
A107: Max | B107: =MAX(B9:B104) -> 287.88 | C107: =MAX(C9:C104) -> 57.64 | D107: =MAX(D9:D104) -> 254.35 | E107: =MAX(E9:E104) -> 13.81 | F107: =MAX(F9:F104) -> 2.13 | G107: =MAX(G9:G104) -> 261.71 | H107: =MAX(H9:H104) -> 65.28 | I107: =MAX(I9:I104) -> 0 | ... Q107: =MAX(Q9:Q104) -> 10.97
A108: Avg | B108: =AVERAGE(B9:B104) -> 106.26854 | C108: =AVERAGE(C9:C104) -> 49.285417 | D108: =AVERAGE(D9:D104) -> 109.59844 | E108: =AVERAGE(E9:E104) -> 7.5254167 | F108: =AVERAGE(F9:F104) -> 2.13 | G108: =AVERAGE(G9:G104) -> 113.23771 | H108: =AVERAGE(H9:H104) -> 32.180833 | I108: =AVERAGE(I9:I104) -> #DIV/0! | ... Q108: =AVERAGE(Q9:Q104) -> 9.603125
A109: Stdev | B109: =STDEV(B9:B104) -> 68.963644 | C109: =STDEV(C9:C104) -> 6.4337461 | D109: =STDEV(D9:D104) -> 53.810313 | E109: =STDEV(E9:E104) -> 2.1755618 | F109: =STDEV(F9:F104) -> 2.6785224e-15 | G109: =STDEV(G9:G104) -> 59.403146 | H109: =STDEV(H9:H104) -> 13.301545 | I109: =STDEV(I9:I104) -> #DIV/0! | ... Q109: =STDEV(Q9:Q104) -> 0.75826021
A110: Num | B110: =COUNT(B9:B104) -> 96 | C110: =COUNT(C9:C104) -> 96 | D110: =COUNT(D9:D104) -> 96 | E110: =COUNT(E9:E104) -> 96 | F110: =COUNT(F9:F104) -> 96 | G110: =COUNT(G9:G104) -> 96 | H110: =COUNT(H9:H104) -> 96 | I110: =COUNT(I9:I104) -> 0 | ... Q110: =COUNT(Q9:Q104) -> 96
A111: DCR | B111: =IF(B110>=87,">90%",IF(B110<=87,"<90%")) -> >90% | C111: =IF(C110>=87,">90%",IF(C110<=87,"<90%")) -> >90% | D111: =IF(D110>=87,">90%",IF(D110<=87,"<90%")) -> >90% | E111: =IF(E110>=87,">90%",IF(E110<=87,"<90%")) -> >90% | F111: =IF(F110>=87,">90%",IF(F110<=87,"<90%")) -> >90% | G111: =IF(G110>=87,">90%",IF(G110<=87,"<90%")) -> >90% | H111: =IF(H110>=87,">90%",IF(H110<=87,"<90%")) -> >90% | I111: =IF(I110>=87,">90%",IF(I110<=87,"<90%")) -> <90% | ... Q111: =IF(Q110>=87,">90%",IF(Q110<=87,"<90%")) -> >90%
A112: Status | B112: =IF(B110>=87,"OK",IF(B110<=87,"LESS")) -> OK | C112: =IF(C110>=87,"OK",IF(C110<=87,"LESS")) -> OK | D112: =IF(D110>=87,"OK",IF(D110<=87,"LESS")) -> OK | E112: =IF(E110>=87,"OK",IF(E110<=87,"LESS")) -> OK | F112: =IF(F110>=87,"OK",IF(F110<=87,"LESS")) -> OK | G112: =IF(G110>=87,"OK",IF(G110<=87,"LESS")) -> OK | H112: =IF(H110>=87,"OK",IF(H110<=87,"LESS")) -> OK | I112: =IF(I110>=87,"OK",IF(I110<=87,"LESS")) -> LESS | ... Q112: =IF(Q110>=87,"OK",IF(Q110<=87,"LESS")) -> OK
A115: Done by | B115: RK
A117: Comment

Sheet 05
A1: Station: | B1: BHATAGAON RAIPUR
A2: Date: | B2: =$A$9 -> 05/01/2025 00:15 | D2: Power Off | G2: Pw.Off | L2: Link Fail | N2: Link F | P2: Maintenance | R2: Maint.
A3: Report Type: | B3: Mean | D3: Calibration | G3: Calib. | L3: Data Fail | N3: Data F | P3: Invalid | R3: Invalid
A4: Time Base: | B4: 15 Min | D4: Zero Referrence | G4: Z.Ref | L4: Warm Up | N4: Wm. Up
A7: Date & Time | B7: NO_BHATAGAON | C7: NO2__BHATAGAON | D7: NOX_BHATAGAON | E7: SO2__BHATAGAON | F7: O3__BHATAGAON | G7: PM10__BHATAGAON | H7: PM2_5__BHATAGAON | I7: BENZ__BHATAGAON | J7: WS__BHATAGAON | K7: WD__BHATAGAON | L7: TEMP__BHATAGAON | M7: HUM__BHATAGAON | N7: SR__BHATAGAON | O7: RG__BHATAGAON | P7: CO__BHATAGAON | Q7: NH3__BHATAGAON
B8: ug/m3 | C8: ug/m3 | D8: ppb | E8: ug/m3 | F8: ug/m3 | G8: ug/m3 | H8: ug/m3 | I8: ug/m3 | J8: m/sec | K8: deg | L8: degreC | M8: % | N8: w/m2 | O8: mm | P8: mg/m3 | Q8: ug/m3
A9: 05/01/2025 00:15 | B9: 293.81 | C9: 46.65 | D9: 258.61 | E9: 12.29 | F9: 2.13 | G9: 215.06 | H9: 58.65 | I9: Invalid | J9: 1.03 | K9: 308.71 | L9: 11.16 | M9: 86.61 | N9: 52.8 | O9: 0 | P9: 2.92 | Q9: 11.09
A10: 05/01/2025 00:30 | B10: 294.09 | C10: 46.5 | D10: 258.76 | E10: 11.43 | F10: 2.13 | G10: 215.06 | H10: 58.65 | I10: Invalid | J10: 0.91 | K10: 267.35 | L10: 11.38 | M10: 79.55 | N10: 52.6 | O10: 0 | P10: 2.91 | Q10: 11.15
A11: 05/01/2025 00:45 | B11: 289.44 | C11: 46.19 | D11: 254.86 | E11: 11.17 | F11: 2.13 | G11: 186.92 | H11: 58.91 | I11: Invalid | J11: 0.87 | K11: 260.76 | L11: 11.67 | M11: 72.3 | N11: 52.6 | O11: 0 | P11: 2.81 | Q11: 11.13
A12: 05/01/2025 01:00 | B12: 281.95 | C12: 45.31 | D12: 248.4 | E12: 11.33 | F12: 2.13 | G12: 174.46 | H12: 59.02 | I12: Invalid | J12: 1.03 | K12: 217.96 | L12: 11.76 | M12: 72.64 | N12: 52.7 | O12: 0 | P12: 2.81 | Q12: 11.1
A13: 05/01/2025 01:15 | B13: 272.69 | C13: 44.53 | D13: 240.56 | E13: 10.91 | F13: 2.13 | G13: 174.46 | H13: 59.02 | I13: Invalid | J13: 0.62 | K13: 333.18 | L13: 11.32 | M13: 77.1 | N13: 53.1 | O13: 0 | P13: 2.34 | Q13: 11.04
A14: 05/01/2025 01:30 | B14: 262.74 | C14: 44.36 | D14: 232.5 | E14: 10.71 | F14: 2.13 | G14: 174.46 | H14: 59.02 | I14: Invalid | J14: 0.59 | K14: 310.29 | L14: 10.79 | M14: 80.99 | N14: 52.9 | O14: 0 | P14: 2.38 | Q14: 11.02
A15: 05/01/2025 01:45 | B15: 253.94 | C15: 44.1 | D15: 225.31 | E15: 10.72 | F15: 2.13 | G15: 144.12 | H15: 53.19 | I15: Invalid | J15: 0.65 | K15: 275.16 | L15: 10.59 | M15: 85.4 | N15: 52.8 | O15: 0 | P15: 2.3 | Q15: 10.94
A16: 05/01/2025 02:00 | B16: 245.83 | C16: 43.17 | D16: 218.31 | E16: 10.13 | F16: 2.13 | G16: 131.12 | H16: 50.55 | I16: Invalid | J16: 1.04 | K16: 238.41 | L16: 10.47 | M16: 87.17 | N16: 52.9 | O16: 0 | P16: 2.25 | Q16: 10.85
A17: 05/01/2025 02:15 | B17: 235.67 | C17: 42.75 | D17: 209.95 | E17: 9.58 | F17: 2.13 | G17: 131.12 | H17: 50.55 | I17: Invalid | J17: 0.89 | K17: 274.36 | L17: 10.17 | M17: 89.53 | N17: 53.1 | O17: 0 | P17: 2.18 | Q17: 10.75
A18: 05/01/2025 02:30 | B18: 225.57 | C18: 42.21 | D18: 201.57 | E18: 9.47 | F18: 2.13 | G18: 131.12 | H18: 50.55 | I18: Invalid | J18: 0.46 | K18: 68.94 | L18: 9.74 | M18: 93.36 | N18: 53.1 | O18: 0 | P18: 2.09 | Q18: 10.65
A19: 05/01/2025 02:45 | B19: 216.28 | C19: 41.89 | D19: 193.95 | E19: 9.04 | F19: 2.13 | G19: 109.08 | H19: 48.03 | I19: Invalid | J19: 1 | K19: 269.03 | L19: 9.44 | M19: 96.42 | N19: 53.1 | O19: 0 | P19: 2.03 | Q19: 10.55
A20: 05/01/2025 03:00 | B20: 208.27 | C20: 42.04 | D20: 187.6 | E20: 8.94 | F20: 2.13 | G20: 99.64 | H20: 46.95 | I20: Invalid | J20: 0.61 | K20: 320.41 | L20: 9.4 | M20: 97.88 | N20: 53.1 | O20: 0 | P20: 1.96 | Q20: 10.49
... A104: 05/01/2025 24:00 | B104: 52.3 | C104: 64.23 | D104: 74.12 | E104: 6.08 | F104: 2.13 | G104: 134.12 | H104: 57.79 | I104: Invalid | J104: 1.08 | K104: 302.3 | L104: 13.51 | M104: 71.27 | N104: 106.8 | O104: 0 | P104: 1.83 | Q104: 9.38
A106: Min | B106: =MIN(B9:B104) -> 6.07 | C106: =MIN(C9:C104) -> 39.03 | D106: =MIN(D9:D104) -> 38.32 | E106: =MIN(E9:E104) -> 5.49 | F106: =MIN(F9:F104) -> 2.13 | G106: =MIN(G9:G104) -> 59.97 | H106: =MIN(H9:H104) -> 24.51 | I106: =MIN(I9:I104) -> 0 | ... Q106: =MIN(Q9:Q104) -> 8.21
A107: Max | B107: =MAX(B9:B104) -> 294.09 | C107: =MAX(C9:C104) -> 76.38 | D107: =MAX(D9:D104) -> 258.76 | E107: =MAX(E9:E104) -> 12.29 | F107: =MAX(F9:F104) -> 2.13 | G107: =MAX(G9:G104) -> 420.55 | H107: =MAX(H9:H104) -> 66.49 | I107: =MAX(I9:I104) -> 0 | ... Q107: =MAX(Q9:Q104) -> 11.15
A108: Avg | B108: =AVERAGE(B9:B104) -> 106.57 | C108: =AVERAGE(C9:C104) -> 57.460208 | D108: =AVERAGE(D9:D104) -> 114.1051 | E108: =AVERAGE(E9:E104) -> 7.9254167 | F108: =AVERAGE(F9:F104) -> 2.13 | G108: =AVERAGE(G9:G104) -> 129.45458 | H108: =AVERAGE(H9:H104) -> 40.844792 | I108: =AVERAGE(I9:I104) -> #DIV/0! | ... Q108: =AVERAGE(Q9:Q104) -> 9.5405208
A109: Stdev | B109: =STDEV(B9:B104) -> 83.885101 | C109: =STDEV(C9:C104) -> 13.0391 | D109: =STDEV(D9:D104) -> 61.269686 | E109: =STDEV(E9:E104) -> 1.4312629 | F109: =STDEV(F9:F104) -> 2.6785224e-15 | G109: =STDEV(G9:G104) -> 72.974145 | H109: =STDEV(H9:H104) -> 12.338413 | I109: =STDEV(I9:I104) -> #DIV/0! | ... Q109: =STDEV(Q9:Q104) -> 0.91458633
A110: Num | B110: =COUNT(B9:B104) -> 96 | C110: =COUNT(C9:C104) -> 96 | D110: =COUNT(D9:D104) -> 96 | E110: =COUNT(E9:E104) -> 96 | F110: =COUNT(F9:F104) -> 96 | G110: =COUNT(G9:G104) -> 96 | H110: =COUNT(H9:H104) -> 96 | I110: =COUNT(I9:I104) -> 0 | ... Q110: =COUNT(Q9:Q104) -> 96
A111: DCR | B111: =IF(B110>=87,">90%",IF(B110<=87,"<90%")) -> >90% | C111: =IF(C110>=87,">90%",IF(C110<=87,"<90%")) -> >90% | D111: =IF(D110>=87,">90%",IF(D110<=87,"<90%")) -> >90% | E111: =IF(E110>=87,">90%",IF(E110<=87,"<90%")) -> >90% | F111: =IF(F110>=87,">90%",IF(F110<=87,"<90%")) -> >90% | G111: =IF(G110>=87,">90%",IF(G110<=87,"<90%")) -> >90% | H111: =IF(H110>=87,">90%",IF(H110<=87,"<90%")) -> >90% | I111: =IF(I110>=87,">90%",IF(I110<=87,"<90%")) -> <90% | ... Q111: =IF(Q110>=87,">90%",IF(Q110<=87,"<90%")) -> >90%
A112: Status | B112: =IF(B110>=87,"OK",IF(B110<=87,"LESS")) -> OK | C112: =IF(C110>=87,"OK",IF(C110<=87,"LESS")) -> OK | D112: =IF(D110>=87,"OK",IF(D110<=87,"LESS")) -> OK | E112: =IF(E110>=87,"OK",IF(E110<=87,"LESS")) -> OK | F112: =IF(F110>=87,"OK",IF(F110<=87,"LESS")) -> OK | G112: =IF(G110>=87,"OK",IF(G110<=87,"LESS")) -> OK | H112: =IF(H110>=87,"OK",IF(H110<=87,"LESS")) -> OK | I112: =IF(I110>=87,"OK",IF(I110<=87,"LESS")) -> LESS | ... Q112: =IF(Q110>=87,"OK",IF(Q110<=87,"LESS")) -> OK
A115: Done by | B115: RK
A117: Comment

Sheet 06
A1: Station: | B1: BHATAGAON RAIPUR
A2: Date: | B2: =$A$9 -> 06/01/2025 00:15 | D2: Power Off | G2: Pw.Off | L2: Link Fail | N2: Link F | P2: Maintenance | R2: Maint.
A3: Report Type: | B3: Mean | D3: Calibration | G3: Calib. | L3: Data Fail | N3: Data F | P3: Invalid | R3: Invalid
A4: Time Base: | B4: 15 Min | D4: Zero Referrence | G4: Z.Ref | L4: Warm Up | N4: Wm. Up
A7: Date & Time | B7: NO_BHATAGAON | C7: NO2__BHATAGAON | D7: NOX_BHATAGAON | E7: SO2__BHATAGAON | F7: O3__BHATAGAON | G7: PM10__BHATAGAON | H7: PM2_5__BHATAGAON | I7: BENZ__BHATAGAON | J7: WS__BHATAGAON | K7: WD__BHATAGAON | L7: TEMP__BHATAGAON | M7: HUM__BHATAGAON | N7: SR__BHATAGAON | O7: RG__BHATAGAON | P7: CO__BHATAGAON | Q7: NH3__BHATAGAON
B8: ug/m3 | C8: ug/m3 | D8: ppb | E8: ug/m3 | F8: ug/m3 | G8: ug/m3 | H8: ug/m3 | I8: ug/m3 | J8: m/sec | K8: deg | L8: degreC | M8: % | N8: w/m2 | O8: mm | P8: mg/m3 | Q8: ug/m3
A9: 06/01/2025 00:15 | B9: 49.59 | C9: 64.32 | D9: 72 | E9: 6.94 | F9: 2.13 | G9: 134.12 | H9: 57.79 | I9: Invalid | J9: 1.06 | K9: 291.37 | L9: 12.95 | M9: 75.39 | N9: 106.5 | O9: 0 | P9: 1.8 | Q9: 9.35
A10: 06/01/2025 00:30 | B10: 47.13 | C10: 64.85 | D10: 70.3 | E10: 7.46 | F10: 2.13 | G10: 134.12 | H10: 57.79 | I10: Invalid | J10: 1.17 | K10: 333.41 | L10: 12.91 | M10: 78.97 | N10: 105.6 | O10: 0 | P10: 1.77 | Q10: 9.33
A11: 06/01/2025 00:45 | B11: 45.52 | C11: 65.06 | D11: 69.12 | E11: 7.57 | F11: 2.13 | G11: 124.61 | H11: 56.79 | I11: Invalid | J11: 0.76 | K11: 289.74 | L11: 13.35 | M11: 71.83 | N11: 105.6 | O11: 0 | P11: 1.75 | Q11: 9.33
A12: 06/01/2025 01:00 | B12: 43.13 | C12: 64.45 | D12: 66.88 | E12: 7.66 | F12: 2.13 | G12: 120.53 | H12: 56.36 | I12: Invalid | J12: 0.94 | K12: 290.07 | L12: 13.29 | M12: 72.56 | N12: 106.4 | O12: 0 | P12: 1.65 | Q12: 9.18
A13: 06/01/2025 01:15 | B13: 40.82 | C13: 63.69 | D13: 64.63 | E13: 7.03 | F13: 2.13 | G13: 120.53 | H13: 56.36 | I13: Invalid | J13: 0.33 | K13: 297.8 | L13: 12.99 | M13: 74.61 | N13: 106.5 | O13: 0 | P13: 1.51 | Q13: 8.98
A14: 06/01/2025 01:30 | B14: 38.75 | C14: 63.74 | D14: 63 | E14: 6.98 | F14: 2.13 | G14: 120.53 | H14: 56.36 | I14: Invalid | J14: 0.97 | K14: 335.2 | L14: 12.31 | M14: 81.35 | N14: 106.6 | O14: 0 | P14: 1.52 | Q14: 8.83
A15: 06/01/2025 01:45 | B15: 37.01 | C15: 63.46 | D15: 61.46 | E15: 7.03 | F15: 2.13 | G15: 128.22 | H15: 53.69 | I15: Invalid | J15: 1.11 | K15: 314.05 | L15: 11.78 | M15: 84.15 | N15: 106.4 | O15: 0 | P15: 1.49 | Q15: 8.71
A16: 06/01/2025 02:00 | B16: 35.66 | C16: 63.02 | D16: 60.15 | E16: 7 | F16: 2.13 | G16: 131.52 | H16: 52.55 | I16: Invalid | J16: 0.78 | K16: 268.53 | L16: 11.46 | M16: 86.53 | N16: 106.8 | O16: 0 | P16: 1.46 | Q16: 8.59
A17: 06/01/2025 02:15 | B17: 34.11 | C17: 61.96 | D17: 58.35 | E17: 7.23 | F17: 2.13 | G17: 131.52 | H17: 52.55 | I17: Invalid | J17: 0.3 | K17: 212.78 | L17: 11.28 | M17: 89.09 | N17: 106.7 | O17: 0 | P17: 1.43 | Q17: 8.48
A18: 06/01/2025 02:30 | B18: 32.66 | C18: 61.13 | D18: 56.75 | E18: 6.89 | F18: 2.13 | G18: 131.52 | H18: 52.55 | I18: Invalid | J18: 1.1 | K18: 319.83 | L18: 11.13 | M18: 91.97 | N18: 106.5 | O18: 0 | P18: 1.41 | Q18: 8.38
A19: 06/01/2025 02:45 | B19: 31.31 | C19: 60.3 | D19: 55.24 | E19: 6.85 | F19: 2.13 | G19: 122.31 | H19: 52.34 | I19: Invalid | J19: 1.16 | K19: 319.86 | L19: 10.91 | M19: 95.11 | N19: 106.3 | O19: 0 | P19: 1.35 | Q19: 8.26
A20: 06/01/2025 03:00 | B20: 29.97 | C20: 60.18 | D20: 54.1 | E20: 6.94 | F20: 2.13 | G20: 118.36 | H20: 52.24 | I20: Invalid | J20: 1.11 | K20: 300.16 | L20: 10.86 | M20: 97.03 | N20: 106.1 | O20: 0 | P20: 1.35 | Q20: 8.21
... A104: 06/01/2025 24:00 | B104: 74.41 | C104: 67.41 | D104: 93.52 | E104: 7.41 | F104: 2.13 | G104: 162.32 | H104: 53.59 | I104: Invalid | J104: 0.3 | K104: 245.84 | L104: 13.76 | M104: 76.64 | N104: 91.7 | O104: 0 | P104: 1.65 | Q104: 9.61
A106: Min | B106: =MIN(B9:B104) -> 1.93 | C106: =MIN(C9:C104) -> 52.04 | D106: =MIN(D9:D104) -> 28.11 | E106: =MIN(E9:E104) -> 6.52 | F106: =MIN(F9:F104) -> 2.13 | G106: =MIN(G9:G104) -> 67.03 | H106: =MIN(H9:H104) -> 38.82 | I106: =MIN(I9:I104) -> 0 | ... Q106: =MIN(Q9:Q104) -> 8.21
A107: Max | B107: =MAX(B9:B104) -> 76.85 | C107: =MAX(C9:C104) -> 79.99 | D107: =MAX(D9:D104) -> 96.03 | E107: =MAX(E9:E104) -> 15.77 | F107: =MAX(F9:F104) -> 27.21 | G107: =MAX(G9:G104) -> 207.95 | H107: =MAX(H9:H104) -> 61.23 | I107: =MAX(I9:I104) -> 0 | ... Q107: =MAX(Q9:Q104) -> 9.62
A108: Avg | B108: =AVERAGE(B9:B104) -> 29.942812 | C108: =AVERAGE(C9:C104) -> 65.447604 | D108: =AVERAGE(D9:D104) -> 56.829479 | E108: =AVERAGE(E9:E104) -> 8.3008333 | F108: =AVERAGE(F9:F104) -> 3.8686458 | G108: =AVERAGE(G9:G104) -> 127.565 | H108: =AVERAGE(H9:H104) -> 50.505937 | I108: =AVERAGE(I9:I104) -> #DIV/0! | ... Q108: =AVERAGE(Q9:Q104) -> 8.58625
A109: Stdev | B109: =STDEV(B9:B104) -> 20.829073 | C109: =STDEV(C9:C104) -> 8.9628946 | D109: =STDEV(D9:D104) -> 16.085205 | E109: =STDEV(E9:E104) -> 1.6855795 | F109: =STDEV(F9:F104) -> 4.6887187 | G109: =STDEV(G9:G104) -> 33.391623 | H109: =STDEV(H9:H104) -> 6.6877654 | I109: =STDEV(I9:I104) -> #DIV/0! | ... Q109: =STDEV(Q9:Q104) -> 0.52525132
A110: Num | B110: =COUNT(B9:B104) -> 96 | C110: =COUNT(C9:C104) -> 96 | D110: =COUNT(D9:D104) -> 96 | E110: =COUNT(E9:E104) -> 96 | F110: =COUNT(F9:F104) -> 96 | G110: =COUNT(G9:G104) -> 96 | H110: =COUNT(H9:H104) -> 96 | I110: =COUNT(I9:I104) -> 0 | ... Q110: =COUNT(Q9:Q104) -> 96
A111: DCR | B111: =IF(B110>=87,">90%",IF(B110<=87,"<90%")) -> >90% | C111: =IF(C110>=87,">90%",IF(C110<=87,"<90%")) -> >90% | D111: =IF(D110>=87,">90%",IF(D110<=87,"<90%")) -> >90% | E111: =IF(E110>=87,">90%",IF(E110<=87,"<90%")) -> >90% | F111: =IF(F110>=87,">90%",IF(F110<=87,"<90%")) -> >90% | G111: =IF(G110>=87,">90%",IF(G110<=87,"<90%")) -> >90% | H111: =IF(H110>=87,">90%",IF(H110<=87,"<90%")) -> >90% | I111: =IF(I110>=87,">90%",IF(I110<=87,"<90%")) -> <90% | ... Q111: =IF(Q110>=87,">90%",IF(Q110<=87,"<90%")) -> >90%
A112: Status | B112: =IF(B110>=87,"OK",IF(B110<=87,"LESS")) -> OK | C112: =IF(C110>=87,"OK",IF(C110<=87,"LESS")) -> OK | D112: =IF(D110>=87,"OK",IF(D110<=87,"LESS")) -> OK | E112: =IF(E110>=87,"OK",IF(E110<=87,"LESS")) -> OK | F112: =IF(F110>=87,"OK",IF(F110<=87,"LESS")) -> OK | G112: =IF(G110>=87,"OK",IF(G110<=87,"LESS")) -> OK | H112: =IF(H110>=87,"OK",IF(H110<=87,"LESS")) -> OK | I112: =IF(I110>=87,"OK",IF(I110<=87,"LESS")) -> LESS | ... Q112: =IF(Q110>=87,"OK",IF(Q110<=87,"LESS")) -> OK
A115: Done by | B115: RK
A117: Comment

Sheet 07
A1: Station: | B1: BHATAGAON RAIPUR
A2: Date: | B2: =$A$9 -> 07/01/2025 00:15 | D2: Power Off | G2: Pw.Off | L2: Link Fail | N2: Link F | P2: Maintenance | R2: Maint.
A3: Report Type: | B3: Mean | D3: Calibration | G3: Calib. | L3: Data Fail | N3: Data F | P3: Invalid | R3: Invalid
A4: Time Base: | B4: 15 Min | D4: Zero Referrence | G4: Z.Ref | L4: Warm Up | N4: Wm. Up
A7: Date & Time | B7: NO_BHATAGAON | C7: NO2__BHATAGAON | D7: NOX_BHATAGAON | E7: SO2__BHATAGAON | F7: O3__BHATAGAON | G7: PM10__BHATAGAON | H7: PM2_5__BHATAGAON | I7: BENZ__BHATAGAON | J7: WS__BHATAGAON | K7: WD__BHATAGAON | L7: TEMP__BHATAGAON | M7: HUM__BHATAGAON | N7: SR__BHATAGAON | O7: RG__BHATAGAON | P7: CO__BHATAGAON | Q7: NH3__BHATAGAON
B8: ug/m3 | C8: ug/m3 | D8: ppb | E8: ug/m3 | F8: ug/m3 | G8: ug/m3 | H8: ug/m3 | I8: ug/m3 | J8: m/sec | K8: deg | L8: degreC | M8: % | N8: w/m2 | O8: mm | P8: mg/m3 | Q8: ug/m3
A9: 07/01/2025 00:15 | B9: 69.93 | C9: 66.42 | D9: 89.4 | E9: 7.53 | F9: 2.13 | G9: 162.32 | H9: 53.59 | I9: Invalid | J9: 1.05 | K9: 304.88 | L9: 13.34 | M9: 79.87 | N9: 87.8 | O9: 0 | P9: 1.6 | Q9: 9.59
A10: 07/01/2025 00:30 | B10: 65.22 | C10: 65.34 | D10: 85.07 | E10: 7.47 | F10: 2.13 | G10: 162.32 | H10: 53.59 | I10: Invalid | J10: 0.54 | K10: 147.32 | L10: 12.88 | M10: 83.58 | N10: 96.5 | O10: 0 | P10: 1.57 | Q10: 9.51
A11: 07/01/2025 00:45 | B11: 61.24 | C11: 64.76 | D11: 81.57 | E11: 7.63 | F11: 2.13 | G11: 104.76 | H11: 51.31 | I11: Invalid | J11: 1.24 | K11: 306.99 | L11: 12.58 | M11: 86.3 | N11: 96.8 | O11: 0 | P11: 1.54 | Q11: 9.47
A12: 07/01/2025 01:00 | B12: 58.44 | C12: 64.38 | D12: 79.12 | E12: 6.83 | F12: 2.13 | G12: 80.09 | H12: 50.33 | I12: Invalid | J12: 0.88 | K12: 349.08 | L12: 12.35 | M12: 93.31 | N12: 96.6 | O12: 0 | P12: 1.51 | Q12: 9.44
A13: 07/01/2025 01:15 | B13: 55.13 | C13: 63.62 | D13: 76.07 | E13: 7.03 | F13: 2.13 | G13: 80.09 | H13: 50.33 | I13: Invalid | J13: 0.56 | K13: 319.21 | L13: 12 | M13: 92.86 | N13: 97.8 | O13: 0 | P13: 1.45 | Q13: 9.44
A14: 07/01/2025 01:30 | B14: 51.72 | C14: 63.03 | D14: 73.03 | E14: 6.94 | F14: 2.13 | G14: 80.09 | H14: 50.33 | I14: Invalid | J14: 0.13 | K14: 118.68 | L14: 11.92 | M14: 92 | N14: 107.7 | O14: 0 | P14: 1.46 | Q14: 9.42
A15: 07/01/2025 01:45 | B15: 48.59 | C15: 62.75 | D15: 70.37 | E15: 6.93 | F15: 2.13 | G15: 99 | H15: 49.73 | I15: Invalid | J15: 1.19 | K15: 324.87 | L15: 11.82 | M15: 94.96 | N15: 99.5 | O15: 0 | P15: 1.43 | Q15: 9.37
A16: 07/01/2025 02:00 | B16: 45.91 | C16: 61.06 | D16: 67.34 | E16: 7.32 | F16: 2.13 | G16: 107.11 | H16: 49.47 | I16: Invalid | J16: 1.21 | K16: 283.93 | L16: 11.6 | M16: 95.38 | N16: 102.5 | O16: 0 | P16: 1.4 | Q16: 9.19
A17: 07/01/2025 02:15 | B17: 43.31 | C17: 58.93 | D17: 64.14 | E17: 6.81 | F17: 2.13 | G17: 107.11 | H17: 49.47 | I17: Invalid | J17: 0.73 | K17: 290.68 | L17: 11.51 | M17: 94.24 | N17: 97 | O17: 0 | P17: 1.39 | Q17: 8.94
A18: 07/01/2025 02:30 | B18: 41.09 | C18: 59.11 | D18: 62.46 | E18: 6.57 | F18: 2.13 | G18: 107.11 | H18: 49.47 | I18: Invalid | J18: 0.72 | K18: 224.69 | L18: 11.67 | M18: 91.98 | N18: 100.7 | O18: 0 | P18: 1.34 | Q18: 8.76
A19: 07/01/2025 02:45 | B19: 39.06 | C19: 58.91 | D19: 60.73 | E19: 6.47 | F19: 2.13 | G19: 94.25 | H19: 49.46 | I19: Invalid | J19: 0.95 | K19: 240.93 | L19: 12.17 | M19: 88.26 | N19: 102.1 | O19: 0 | P19: 1.33 | Q19: 8.6
A20: 07/01/2025 03:00 | B20: 37.01 | C20: 58.46 | D20: 58.85 | E20: 6.71 | F20: 2.13 | G20: 88.74 | H20: 49.46 | I20: Invalid | J20: 0.65 | K20: 350.9 | L20: 12.09 | M20: 89.24 | N20: 102.5 | O20: 0 | P20: 1.29 | Q20: 8.44
... A104: 07/01/2025 24:00 | B104: 18.49 | C104: 56.18 | D104: 42.8 | E104: 6.45 | F104: 2.13 | G104: 92.39 | H104: 28.32 | I104: Invalid | J104: 2.39 | K104: 338.15 | L104: 13.06 | M104: 56.28 | N104: 55.1 | O104: 0 | P104: 0.8 | Q104: 8.21
A106: Min | B106: =MIN(B9:B104) -> 4.07 | C106: =MIN(C9:C104) -> 49.8 | D106: =MIN(D9:D104) -> 31.55 | E106: =MIN(E9:E104) -> 5.29 | F106: =MIN(F9:F104) -> 2.13 | G106: =MIN(G9:G104) -> 49.24 | H106: =MIN(H9:H104) -> 19.51 | I106: =MIN(I9:I104) -> 0 | ... Q106: =MIN(Q9:Q104) -> 8.21
A107: Max | B107: =MAX(B9:B104) -> 69.93 | C107: =MAX(C9:C104) -> 76.06 | D107: =MAX(D9:D104) -> 89.4 | E107: =MAX(E9:E104) -> 9.74 | F107: =MAX(F9:F104) -> 2.16 | G107: =MAX(G9:G104) -> 338.23 | H107: =MAX(H9:H104) -> 65.1 | I107: =MAX(I9:I104) -> 0 | ... Q107: =MAX(Q9:Q104) -> 9.59
A108: Avg | B108: =AVERAGE(B9:B104) -> 22.674271 | C108: =AVERAGE(C9:C104) -> 61.074167 | D108: =AVERAGE(D9:D104) -> 48.716146 | E108: =AVERAGE(E9:E104) -> 6.9370833 | F108: =AVERAGE(F9:F104) -> 2.1304167 | G108: =AVERAGE(G9:G104) -> 107.95938 | H108: =AVERAGE(H9:H104) -> 39.995729 | I108: =AVERAGE(I9:I104) -> #DIV/0! | ... Q108: =AVERAGE(Q9:Q104) -> 8.3321875
A109: Stdev | B109: =STDEV(B9:B104) -> 15.034199 | C109: =STDEV(C9:C104) -> 6.9211091 | D109: =STDEV(D9:D104) -> 12.410719 | E109: =STDEV(E9:E104) -> 1.1092975 | F109: =STDEV(F9:F104) -> 0.0032172779 | G109: =STDEV(G9:G104) -> 63.190981 | H109: =STDEV(H9:H104) -> 13.957463 | I109: =STDEV(I9:I104) -> #DIV/0! | ... Q109: =STDEV(Q9:Q104) -> 0.34930669
A110: Num | B110: =COUNT(B9:B104) -> 96 | C110: =COUNT(C9:C104) -> 96 | D110: =COUNT(D9:D104) -> 96 | E110: =COUNT(E9:E104) -> 96 | F110: =COUNT(F9:F104) -> 96 | G110: =COUNT(G9:G104) -> 96 | H110: =COUNT(H9:H104) -> 96 | I110: =COUNT(I9:I104) -> 0 | ... Q110: =COUNT(Q9:Q104) -> 96
A111: DCR | B111: =IF(B110>=87,">90%",IF(B110<=87,"<90%")) -> >90% | C111: =IF(C110>=87,">90%",IF(C110<=87,"<90%")) -> >90% | D111: =IF(D110>=87,">90%",IF(D110<=87,"<90%")) -> >90% | E111: =IF(E110>=87,">90%",IF(E110<=87,"<90%")) -> >90% | F111: =IF(F110>=87,">90%",IF(F110<=87,"<90%")) -> >90% | G111: =IF(G110>=87,">90%",IF(G110<=87,"<90%")) -> >90% | H111: =IF(H110>=87,">90%",IF(H110<=87,"<90%")) -> >90% | I111: =IF(I110>=87,">90%",IF(I110<=87,"<90%")) -> <90% | ... Q111: =IF(Q110>=87,">90%",IF(Q110<=87,"<90%")) -> >90%
A112: Status | B112: =IF(B110>=87,"OK",IF(B110<=87,"LESS")) -> OK | C112: =IF(C110>=87,"OK",IF(C110<=87,"LESS")) -> OK | D112: =IF(D110>=87,"OK",IF(D110<=87,"LESS")) -> OK | E112: =IF(E110>=87,"OK",IF(E110<=87,"LESS")) -> OK | F112: =IF(F110>=87,"OK",IF(F110<=87,"LESS")) -> OK | G112: =IF(G110>=87,"OK",IF(G110<=87,"LESS")) -> OK | H112: =IF(H110>=87,"OK",IF(H110<=87,"LESS")) -> OK | I112: =IF(I110>=87,"OK",IF(I110<=87,"LESS")) -> LESS | ... Q112: =IF(Q110>=87,"OK",IF(Q110<=87,"LESS")) -> OK
A115: Done by | B115: RK
A117: Comment

Sheet 08
A1: Station: | B1: BHATAGAON RAIPUR
A2: Date: | B2: =$A$9 -> 08/01/2025 00:15 | D2: Power Off | G2: Pw.Off | L2: Link Fail | N2: Link F | P2: Maintenance | R2: Maint.
A3: Report Type: | B3: Mean | D3: Calibration | G3: Calib. | L3: Data Fail | N3: Data F | P3: Invalid | R3: Invalid
A4: Time Base: | B4: 15 Min | D4: Zero Referrence | G4: Z.Ref | L4: Warm Up | N4: Wm. Up
A7: Date & Time | B7: NO_BHATAGAON | C7: NO2__BHATAGAON | D7: NOX_BHATAGAON | E7: SO2__BHATAGAON | F7: O3__BHATAGAON | G7: PM10__BHATAGAON | H7: PM2_5__BHATAGAON | I7: BENZ__BHATAGAON | J7: WS__BHATAGAON | K7: WD__BHATAGAON | L7: TEMP__BHATAGAON | M7: HUM__BHATAGAON | N7: SR__BHATAGAON | O7: RG__BHATAGAON | P7: CO__BHATAGAON | Q7: NH3__BHATAGAON
B8: ug/m3 | C8: ug/m3 | D8: ppb | E8: ug/m3 | F8: ug/m3 | G8: ug/m3 | H8: ug/m3 | I8: ug/m3 | J8: m/sec | K8: deg | L8: degreC | M8: % | N8: w/m2 | O8: mm | P8: mg/m3 | Q8: ug/m3
A9: 08/01/2025 00:15 | B9: 17.88 | C9: 55.23 | D9: 41.82 | E9: 6.32 | F9: 2.13 | G9: 92.39 | H9: 28.32 | I9: Invalid | J9: 2.57 | K9: 338.76 | L9: 12.86 | M9: 57.21 | N9: 55.2 | O9: 0 | P9: 0.77 | Q9: 8.21
A10: 08/01/2025 00:30 | B10: 17.05 | C10: 54.23 | D10: 40.63 | E10: 6.61 | F10: 2.13 | G10: 92.39 | H10: 28.32 | I10: Invalid | J10: 2.68 | K10: 336.01 | L10: 12.65 | M10: 58.03 | N10: 55.2 | O10: 0 | P10: 0.76 | Q10: 8.21
A11: 08/01/2025 00:45 | B11: 16.19 | C11: 53.77 | D11: 39.7 | E11: 6.37 | F11: 2.13 | G11: 93.9 | H11: 28.81 | I11: Invalid | J11: 2.17 | K11: 343.16 | L11: 12.33 | M11: 60.23 | N11: 55.4 | O11: 0 | P11: 0.74 | Q11: 8.21
A12: 08/01/2025 01:00 | B12: 15.8 | C12: 53.35 | D12: 39.16 | E12: 6.37 | F12: 2.13 | G12: 94.54 | H12: 29.02 | I12: Invalid | J12: 1.97 | K12: 352.94 | L12: 12.14 | M12: 61.48 | N12: 55.2 | O12: 0 | P12: 0.73 | Q12: 8.21
A13: 08/01/2025 01:15 | B13: 15.43 | C13: 52.55 | D13: 38.45 | E13: 6.42 | F13: 2.13 | G13: 94.54 | H13: 29.02 | I13: Invalid | J13: 2.37 | K13: 349.82 | L13: 12.14 | M13: 60.87 | N13: 54.9 | O13: 0 | P13: 0.71 | Q13: 8.21
A14: 08/01/2025 01:30 | B14: 14.7 | C14: 52.04 | D14: 37.6 | E14: 6.58 | F14: 2.13 | G14: 94.54 | H14: 29.02 | I14: Invalid | J14: 1.81 | K14: 350.69 | L14: 12.09 | M14: 61.21 | N14: 55.5 | O14: 0 | P14: 0.73 | Q14: 8.21
A15: 08/01/2025 01:45 | B15: 14.1 | C15: 51.59 | D15: 36.88 | E15: 6.42 | F15: 2.13 | G15: 93 | H15: 30.01 | I15: Invalid | J15: 1.51 | K15: 343.24 | L15: 11.96 | M15: 62.68 | N15: 55.4 | O15: 0 | P15: 0.73 | Q15: 8.21
A16: 08/01/2025 02:00 | B16: 13.77 | C16: 51.68 | D16: 36.67 | E16: 6.38 | F16: 2.13 | G16: 92.3 | H16: 30.43 | I16: Invalid | J16: 2 | K16: 348.6 | L16: 11.77 | M16: 63.36 | N16: 55.2 | O16: 0 | P16: 0.74 | Q16: 8.21
A17: 08/01/2025 02:15 | B17: 13.3 | C17: 51.68 | D17: 36.29 | E17: 6.21 | F17: 2.13 | G17: 92.3 | H17: 30.43 | I17: Invalid | J17: 1.62 | K17: 348.16 | L17: 11.61 | M17: 64.08 | N17: 55.5 | O17: 0 | P17: 0.75 | Q17: 8.21
A18: 08/01/2025 02:30 | B18: 12.59 | C18: 51.46 | D18: 35.6 | E18: 6.19 | F18: 2.13 | G18: 92.3 | H18: 30.43 | I18: Invalid | J18: 0.85 | K18: 25.64 | L18: 11.26 | M18: 66.31 | N18: 55.7 | O18: 0 | P18: 0.74 | Q18: 8.21
A19: 08/01/2025 02:45 | B19: 11.97 | C19: 51.29 | D19: 35.02 | E19: 5.75 | F19: 2.13 | G19: 83.18 | H19: 27.88 | I19: Invalid | J19: 0.51 | K19: 38.16 | L19: 10.87 | M19: 68.86 | N19: 55.6 | O19: 0 | P19: 0.74 | Q19: 8.21
A20: 08/01/2025 03:00 | B20: 11.61 | C20: 50.77 | D20: 34.46 | E20: 5.47 | F20: 2.13 | G20: 79.27 | H20: 26.79 | I20: Invalid | J20: 0.9 | K20: 33.36 | L20: 10.73 | M20: 70.15 | N20: 55.4 | O20: 0 | P20: 0.73 | Q20: 8.21
... A104: 08/01/2025 24:00 | B104: 155.27 | C104: 52.17 | D104: 150.4 | E104: 8.92 | F104: 2.13 | G104: 163.7 | H104: 57.43 | I104: Invalid | J104: 1.5 | K104: 282.82 | L104: 9.86 | M104: 81.03 | N104: 57.5 | O104: 0 | P104: 2.12 | Q104: 10.08
A106: Min | B106: =MIN(B9:B104) -> 3.05 | C106: =MIN(C9:C104) -> 45.2 | D106: =MIN(D9:D104) -> 31.27 | E106: =MIN(E9:E104) -> 5 | F106: =MIN(F9:F104) -> 2.13 | G106: =MIN(G9:G104) -> 44.44 | H106: =MIN(H9:H104) -> 21.1 | I106: =MIN(I9:I104) -> 0 | ... Q106: =MIN(Q9:Q104) -> 8.21
A107: Max | B107: =MAX(B9:B104) -> 175.66 | C107: =MAX(C9:C104) -> 77.41 | D107: =MAX(D9:D104) -> 172.16 | E107: =MAX(E9:E104) -> 13.06 | F107: =MAX(F9:F104) -> 5.02 | G107: =MAX(G9:G104) -> 237.2 | H107: =MAX(H9:H104) -> 57.61 | I107: =MAX(I9:I104) -> 0 | ... Q107: =MAX(Q9:Q104) -> 10.2
A108: Avg | B108: =AVERAGE(B9:B104) -> 33.159583 | C108: =AVERAGE(C9:C104) -> 59.299896 | D108: =AVERAGE(D9:D104) -> 56.196562 | E108: =AVERAGE(E9:E104) -> 7.6178125 | F108: =AVERAGE(F9:F104) -> 2.2346875 | G108: =AVERAGE(G9:G104) -> 96.172917 | H108: =AVERAGE(H9:H104) -> 31.853438 | I108: =AVERAGE(I9:I104) -> #DIV/0! | ... Q108: =AVERAGE(Q9:Q104) -> 8.5217708
A109: Stdev | B109: =STDEV(B9:B104) -> 49.296675 | C109: =STDEV(C9:C104) -> 8.591783 | D109: =STDEV(D9:D104) -> 40.138863 | E109: =STDEV(E9:E104) -> 2.3448026 | F109: =STDEV(F9:F104) -> 0.4387637 | G109: =STDEV(G9:G104) -> 57.23226 | H109: =STDEV(H9:H104) -> 9.8654815 | I109: =STDEV(I9:I104) -> #DIV/0! | ... Q109: =STDEV(Q9:Q104) -> 0.66054681
A110: Num | B110: =COUNT(B9:B104) -> 96 | C110: =COUNT(C9:C104) -> 96 | D110: =COUNT(D9:D104) -> 96 | E110: =COUNT(E9:E104) -> 96 | F110: =COUNT(F9:F104) -> 96 | G110: =COUNT(G9:G104) -> 96 | H110: =COUNT(H9:H104) -> 96 | I110: =COUNT(I9:I104) -> 0 | ... Q110: =COUNT(Q9:Q104) -> 96
A111: DCR | B111: =IF(B110>=87,">90%",IF(B110<=87,"<90%")) -> >90% | C111: =IF(C110>=87,">90%",IF(C110<=87,"<90%")) -> >90% | D111: =IF(D110>=87,">90%",IF(D110<=87,"<90%")) -> >90% | E111: =IF(E110>=87,">90%",IF(E110<=87,"<90%")) -> >90% | F111: =IF(F110>=87,">90%",IF(F110<=87,"<90%")) -> >90% | G111: =IF(G110>=87,">90%",IF(G110<=87,"<90%")) -> >90% | H111: =IF(H110>=87,">90%",IF(H110<=87,"<90%")) -> >90% | I111: =IF(I110>=87,">90%",IF(I110<=87,"<90%")) -> <90% | ... Q111: =IF(Q110>=87,">90%",IF(Q110<=87,"<90%")) -> >90%
A112: Status | B112: =IF(B110>=87,"OK",IF(B110<=87,"LESS")) -> OK | C112: =IF(C110>=87,"OK",IF(C110<=87,"LESS")) -> OK | D112: =IF(D110>=87,"OK",IF(D110<=87,"LESS")) -> OK | E112: =IF(E110>=87,"OK",IF(E110<=87,"LESS")) -> OK | F112: =IF(F110>=87,"OK",IF(F110<=87,"LESS")) -> OK | G112: =IF(G110>=87,"OK",IF(G110<=87,"LESS")) -> OK | H112: =IF(H110>=87,"OK",IF(H110<=87,"LESS")) -> OK | I112: =IF(I110>=87,"OK",IF(I110<=87,"LESS")) -> LESS | ... Q112: =IF(Q110>=87,"OK",IF(Q110<=87,"LESS")) -> OK
A115: Done by | B115: RK
A117: Comment

Sheet 09
A1: Station: | B1: BHATAGAON RAIPUR
A2: Date: | B2: =$A$9 -> 09/01/2025 00:15 | D2: Power Off | G2: Pw.Off | L2: Link Fail | N2: Link F | P2: Maintenance | R2: Maint.
A3: Report Type: | B3: Mean | D3: Calibration | G3: Calib. | L3: Data Fail | N3: Data F | P3: Invalid | R3: Invalid
A4: Time Base: | B4: 15 Min | D4: Zero Referrence | G4: Z.Ref | L4: Warm Up | N4: Wm. Up
A7: Date & Time | B7: NO_BHATAGAON | C7: NO2__BHATAGAON | D7: NOX_BHATAGAON | E7: SO2__BHATAGAON | F7: O3__BHATAGAON | G7: PM10__BHATAGAON | H7: PM2_5__BHATAGAON | I7: BENZ__BHATAGAON | J7: WS__BHATAGAON | K7: WD__BHATAGAON | L7: TEMP__BHATAGAON | M7: HUM__BHATAGAON | N7: SR__BHATAGAON | O7: RG__BHATAGAON | P7: CO__BHATAGAON | Q7: NH3__BHATAGAON
B8: ug/m3 | C8: ug/m3 | D8: ppb | E8: ug/m3 | F8: ug/m3 | G8: ug/m3 | H8: ug/m3 | I8: ug/m3 | J8: m/sec | K8: deg | L8: degreC | M8: % | N8: w/m2 | O8: mm | P8: mg/m3 | Q8: ug/m3
A9: 09/01/2025 00:15 | B9: 151.15 | C9: 51.16 | D9: 146.57 | E9: 9.02 | F9: 2.13 | G9: 163.7 | H9: 57.43 | I9: Invalid | J9: 1.43 | K9: 309.03 | L9: 9.79 | M9: 85.47 | N9: 57.4 | O9: 0 | P9: 2.1 | Q9: 10.07
A10: 09/01/2025 00:30 | B10: 146.85 | C10: 50.66 | D10: 142.86 | E10: 9.03 | F10: 2.13 | G10: 163.7 | H10: 57.43 | I10: Invalid | J10: 1.21 | K10: 279.26 | L10: 9.73 | M10: 85.07 | N10: 57.4 | O10: 0 | P10: 2.05 | Q10: 10.06
A11: 09/01/2025 00:45 | B11: 141.26 | C11: 50.08 | D11: 138.07 | E11: 8.9 | F11: 2.13 | G11: 149.73 | H11: 53.77 | I11: Invalid | J11: 1.01 | K11: 250.36 | L11: 9.8 | M11: 86.88 | N11: 57.4 | O11: 0 | P11: 2 | Q11: 10.06
A12: 09/01/2025 01:00 | B12: 135.71 | C12: 48.81 | D12: 132.95 | E12: 8.49 | F12: 2.13 | G12: 143.75 | H12: 52.2 | I12: Invalid | J12: 1.15 | K12: 287.81 | L12: 9.6 | M12: 88.31 | N12: 57.5 | O12: 0 | P12: 1.98 | Q12: 10.03
A13: 09/01/2025 01:15 | B13: 129.75 | C13: 48.02 | D13: 127.76 | E13: 8.42 | F13: 2.13 | G13: 143.75 | H13: 52.2 | I13: Invalid | J13: 0.52 | K13: 221.85 | L13: 9.88 | M13: 85.29 | N13: 56.9 | O13: 0 | P13: 1.71 | Q13: 9.99
A14: 09/01/2025 01:30 | B14: 123.7 | C14: 47.66 | D14: 122.72 | E14: 8.55 | F14: 2.13 | G14: 143.75 | H14: 52.2 | I14: Invalid | J14: 0.86 | K14: 274.63 | L14: 9.9 | M14: 84.86 | N14: 57.5 | O14: 0 | P14: 1.75 | Q14: 9.96
A15: 09/01/2025 01:45 | B15: 118.17 | C15: 48.37 | D15: 118.66 | E15: 8.16 | F15: 2.13 | G15: 129.56 | H15: 50.07 | I15: Invalid | J15: 1.09 | K15: 283.68 | L15: 9.63 | M15: 88.04 | N15: 57.7 | O15: 0 | P15: 1.73 | Q15: 9.93
A16: 09/01/2025 02:00 | B16: 113.9 | C16: 48.36 | D16: 115.23 | E16: 8.74 | F16: 2.13 | G16: 123.48 | H16: 49.16 | I16: Invalid | J16: 0.5 | K16: 270.3 | L16: 9.32 | M16: 91.79 | N16: 57.6 | O16: 0 | P16: 1.7 | Q16: 9.88
A17: 09/01/2025 02:15 | B17: 109.49 | C17: 47.77 | D17: 111.39 | E17: 8.3 | F17: 2.13 | G17: 123.48 | H17: 49.16 | I17: Invalid | J17: 0.25 | K17: 338.97 | L17: 9.36 | M17: 92.98 | N17: 57.6 | O17: 0 | P17: 1.68 | Q17: 9.81
A18: 09/01/2025 02:30 | B18: 105.34 | C18: 47.04 | D18: 107.68 | E18: 7.98 | F18: 2.13 | G18: 123.48 | H18: 49.16 | I18: Invalid | J18: 0.8 | K18: 320.39 | L18: 9.17 | M18: 95.47 | N18: 57.7 | O18: 0 | P18: 1.66 | Q18: 9.75
A19: 09/01/2025 02:45 | B19: 101.88 | C19: 46.44 | D19: 104.58 | E19: 8.13 | F19: 2.13 | G19: 133.05 | H19: 48.44 | I19: Invalid | J19: 0.77 | K19: 225.31 | L19: 9.14 | M19: 95.16 | N19: 57.8 | O19: 0 | P19: 1.64 | Q19: 9.75
A20: 09/01/2025 03:00 | B20: 98.54 | C20: 46.42 | D20: 101.9 | E20: 7.92 | F20: 2.13 | G20: 137.14 | H20: 48.13 | I20: Invalid | J20: 0.7 | K20: 325.17 | L20: 8.86 | M20: 96.49 | N20: 57.8 | O20: 0 | P20: 1.62 | Q20: 9.74
... A104: 09/01/2025 24:00 | B104: 102.32 | C104: 57.69 | D104: 110.81 | E104: 8.63 | F104: 2.13 | G104: 182.58 | H104: 45.69 | I104: Invalid | J104: 1.03 | K104: 269.34 | L104: 10.3 | M104: 79.5 | N104: 76.5 | O104: 0 | P104: 1.76 | Q104: 9.66
A106: Min | B106: =MIN(B9:B104) -> 1.93 | C106: =MIN(C9:C104) -> 40.42 | D106: =MIN(D9:D104) -> 23.94 | E106: =MIN(E9:E104) -> 5.26 | F106: =MIN(F9:F104) -> 2.13 | G106: =MIN(G9:G104) -> 44.84 | H106: =MIN(H9:H104) -> 17.72 | I106: =MIN(I9:I104) -> 0 | ... Q106: =MIN(Q9:Q104) -> 8.21
A107: Max | B107: =MAX(B9:B104) -> 151.15 | C107: =MAX(C9:C104) -> 87.93 | D107: =MAX(D9:D104) -> 146.57 | E107: =MAX(E9:E104) -> 10.37 | F107: =MAX(F9:F104) -> 14.9 | G107: =MAX(G9:G104) -> 201.67 | H107: =MAX(H9:H104) -> 63.83 | I107: =MAX(I9:I104) -> 0 | ... Q107: =MAX(Q9:Q104) -> 10.07
A108: Avg | B108: =AVERAGE(B9:B104) -> 55.630937 | C108: =AVERAGE(C9:C104) -> 55.562604 | D108: =AVERAGE(D9:D104) -> 72.264271 | E108: =AVERAGE(E9:E104) -> 7.5753125 | F108: =AVERAGE(F9:F104) -> 2.7861458 | G108: =AVERAGE(G9:G104) -> 108.90927 | H108: =AVERAGE(H9:H104) -> 38.814375 | I108: =AVERAGE(I9:I104) -> #DIV/0! | ... Q108: =AVERAGE(Q9:Q104) -> 9.0280208
