Workbook

Sheet 01
A1: Station: | B1: IGKV ,RAIPUR
A2: Date: | B2: =$A$9 -> 45078.042 | D2: Power Off | G2: Pw.Off | L2: Link Fail | N2: Link F | P2: Maintenance | R2: Maint.
A3: Report Type: | B3: Mean | D3: Calibration | G3: Calib. | L3: Data Fail | N3: Data F | P3: Invalid | R3: Invalid
A4: Time Base: | B4: 01 Hour | D4: Zero Referrence | G4: Z.Ref | L4: Warm Up | N4: Wm. Up
A7: Date & Time | B7: NO | C7: NO2 | D7: NOX | E7: SO2 | F7: O3 | G7: PM 10 | H7: PM 2.5 | I7: BENZ | J7: WS | K7: WD | L7: TEMP | M7: HUM | N7: SR | O7: RG | P7: CO | Q7: NH3
B8: ug/m3 | C8: ug/m3 | D8: ppb | E8: ug/m3 | F8: ug/m3 | G8: ug/m3 | H8: ug/m3 | I8: ug/m3 | J8: m/sec | K8: deg | L8: degreC | M8: % | N8: w/m2 | O8: mm | P8: mg/m3 | Q8: ug/m3
A9: 45078.042 | B9: 47.45 | C9: 68.26 | D9: 72.67 | E9: 6.68 | F9: 4.95 | G9: 100.58 | H9: 31.4 | I9: 7.12 | J9: 0.27 | K9: 248.6 | L9: 30.52 | M9: 44.63 | N9: 0 | O9: 0 | P9: 0.89 | Q9: 6.05
A10: 01/06/2023 02:00 | B10: 30.63 | C10: 63.59 | D10: 55.72 | E10: 7.33 | F10: 5.13 | G10: 112.38 | H10: 32.99 | I10: 7.52 | J10: 0.25 | K10: 205.32 | L10: 30.65 | M10: 47.63 | N10: 0 | O10: 0 | P10: 0.85 | Q10: 6.31
A11: 01/06/2023 03:00 | B11: 35.51 | C11: 62.32 | D11: 59.11 | E11: 15.82 | F11: 6.59 | G11: 112.38 | H11: 32.99 | I11: 8.97 | J11: 0.55 | K11: 175.87 | L11: 30.27 | M11: 48.77 | N11: 0 | O11: 0 | P11: 0.87 | Q11: 6.46
A12: 01/06/2023 04:00 | B12: 38.42 | C12: 61.93 | D12: 62.12 | E12: 18.11 | F12: 6.2 | G12: 104.24 | H12: 32.56 | I12: 9.32 | J12: 0.51 | K12: 72.34 | L12: 30.16 | M12: 41.45 | N12: 0 | O12: 0 | P12: 0.85 | Q12: 6.58
A13: 01/06/2023 05:00 | B13: 42.5 | C13: 64.07 | D13: 66.51 | E13: 9.69 | F13: 4.28 | G13: 104.24 | H13: 31.86 | I13: 8.12 | J13: 0.2 | K13: 168.61 | L13: 28.58 | M13: 49.66 | N13: 0 | O13: 0 | P13: 0.85 | Q13: 6.68
A14: 01/06/2023 06:00 | B14: 47 | C14: 65.31 | D14: 70.77 | E14: 9.01 | F14: 3.8 | G14: 99.78 | H14: 31.11 | I14: 8.33 | J14: 0.27 | K14: 167.93 | L14: 27.89 | M14: 51.6 | N14: 22.3 | O14: 0 | P14: 0.85 | Q14: 6.89
A15: 01/06/2023 07:00 | B15: 47.95 | C15: 66.15 | D15: 71.97 | E15: 15.39 | F15: 6.69 | G15: 104.72 | H15: 33.37 | I15: 8.66 | J15: 0.32 | K15: 340.83 | L15: 30.75 | M15: 50.13 | N15: 62.9 | O15: 0 | P15: 0.93 | Q15: 7.04
A16: 01/06/2023 08:00 | B16: 41.3 | C16: 62.79 | D16: 63.4 | E16: 19.53 | F16: 17.75 | G16: 123.82 | H16: 37.78 | I16: 9.28 | J16: 0.72 | K16: 27.5 | L16: 34.21 | M16: 39.18 | N16: 92.3 | O16: 0 | P16: 0.97 | Q16: 7.01
A17: 01/06/2023 09:00 | B17: 34.51 | C17: 63.45 | D17: 58.02 | E17: 22.1 | F17: 27.09 | G17: 123.82 | H17: 37.78 | I17: 9.08 | J17: 1.39 | K17: 47.31 | L17: 36.65 | M17: 32.06 | N17: 133.9 | O17: 0 | P17: 0.9 | Q17: 6.77
A18: 01/06/2023 10:00 | B18: 25.12 | C18: 58.97 | D18: 48.31 | E18: 16.6 | F18: 26.89 | G18: 109.24 | H18: 35.46 | I18: 7.93 | J18: 1.41 | K18: 42.73 | L18: 38.37 | M18: 25.29 | N18: 173 | O18: 0 | P18: 0.84 | Q18: 6.31
A19: 01/06/2023 11:00 | B19: 18.59 | C19: 56.18 | D19: 43.22 | E19: 13.59 | F19: 27.72 | G19: 101.61 | H19: 35.27 | I19: 7.64 | J19: 1.47 | K19: 40.07 | L19: 39.37 | M19: 19.57 | N19: 213.4 | O19: 0 | P19: 0.78 | Q19: 5.89
A20: 01/06/2023 12:00 | B20: 13.96 | C20: 50.88 | D20: 36.34 | E20: 13.37 | F20: 32.53 | G20: 91.87 | H20: 32.34 | I20: 6.82 | J20: 1.31 | K20: 53.61 | L20: 40.59 | M20: 15.75 | N20: 756.2 | O20: 0 | P20: 0.72 | Q20: 5.54
A21: 01/06/2023 13:00 | B21: 9.14 | C21: 51.62 | D21: 32.11 | E21: 13.23 | F21: 32.03 | G21: 89.94 | H21: 32.24 | I21: 6.55 | J21: 1.36 | K21: 304.18 | L21: 41.45 | M21: 13.37 | N21: 782.6 | O21: 0 | P21: 0.67 | Q21: 5.26
... A32: 01/06/2023 24:00 | B32: 44.93 | C32: 66.99 | D32: 69.99 | E32: 20.04 | F32: 4.08 | G32: 132.13 | H32: 35.92 | I32: 9.44 | J32: 0.29 | K32: 237.9 | L32: 30.28 | M32: 35.58 | N32: 0 | O32: 0 | P32: 1.04 | Q32: 6.57
A34: Min | B34: =MIN(B9:B32) -> 3.48 | C34: =MIN(C9:C32) -> 50.88 | D34: =MIN(D9:D32) -> 32.11 | E34: =MIN(E9:E32) -> 6.68 | F34: =MIN(F9:F32) -> 3.8 | G34: =MIN(G9:G32) -> 68.37 | H34: =MIN(H9:H32) -> 19.26 | I34: =MIN(I9:I32) -> 3.59 | ... Q34: =MIN(Q9:Q32) -> 5.19
A35: Max | B35: =MAX(B9:B32) -> 47.95 | C35: =MAX(C9:C32) -> 74.32 | D35: =MAX(D9:D32) -> 72.67 | E35: =MAX(E9:E32) -> 35.07 | F35: =MAX(F9:F32) -> 51.75 | G35: =MAX(G9:G32) -> 132.13 | H35: =MAX(H9:H32) -> 37.78 | I35: =MAX(I9:I32) -> 9.49 | ... Q35: =MAX(Q9:Q32) -> 7.04
A36: Avg | B36: =AVERAGE(B9:B32) -> 26.481667 | C36: =AVERAGE(C9:C32) -> 63.257083 | D36: =AVERAGE(D9:D32) -> 52.53375 | E36: =AVERAGE(E9:E32) -> 15.250833 | F36: =AVERAGE(F9:F32) -> 19.224583 | G36: =AVERAGE(G9:G32) -> 99.514167 | H36: =AVERAGE(H9:H32) -> 30.383333 | I36: =AVERAGE(I9:I32) -> 7.4270833 | ... Q36: =AVERAGE(Q9:Q32) -> 6.0833333
A37: Stdev | B37: =STDEV(B9:B32) -> 15.606115 | C37: =STDEV(C9:C32) -> 6.0892353 | D37: =STDEV(D9:D32) -> 14.360094 | E37: =STDEV(E9:E32) -> 6.5312912 | F37: =STDEV(F9:F32) -> 14.999469 | G37: =STDEV(G9:G32) -> 17.477445 | H37: =STDEV(H9:H32) -> 5.5370591 | I37: =STDEV(I9:I32) -> 1.8259303 | ... Q37: =STDEV(Q9:Q32) -> 0.58067926
A38: Num | B38: =COUNT(B9:B32) -> 24 | C38: =COUNT(C9:C32) -> 24 | D38: =COUNT(D9:D32) -> 24 | E38: =COUNT(E9:E32) -> 24 | F38: =COUNT(F9:F32) -> 24 | G38: =COUNT(G9:G32) -> 24 | H38: =COUNT(H9:H32) -> 24 | I38: =COUNT(I9:I32) -> 24 | ... Q38: =COUNT(Q9:Q32) -> 24
A39: DCR | B39: =IF(B38>=22,">90%",IF(B38<=22,"<90%")) -> >90% | C39: =IF(C38>=22,">90%",IF(C38<=22,"<90%")) -> >90% | D39: =IF(D38>=22,">90%",IF(D38<=22,"<90%")) -> >90% | E39: =IF(E38>=22,">90%",IF(E38<=22,"<90%")) -> >90% | F39: =IF(F38>=22,">90%",IF(F38<=22,"<90%")) -> >90% | G39: =IF(G38>=22,">90%",IF(G38<=22,"<90%")) -> >90% | H39: =IF(H38>=22,">90%",IF(H38<=22,"<90%")) -> >90% | I39: =IF(I38>=22,">90%",IF(I38<=22,"<90%")) -> >90% | ... Q39: =IF(Q38>=22,">90%",IF(Q38<=22,"<90%")) -> >90%
A40: Status | B40: =IF(B38>=22,"OK",IF(B38<=22,"LESS")) -> OK | C40: =IF(C38>=22,"OK",IF(C38<=22,"LESS")) -> OK | D40: =IF(D38>=22,"OK",IF(D38<=22,"LESS")) -> OK | E40: =IF(E38>=22,"OK",IF(E38<=22,"LESS")) -> OK | F40: =IF(F38>=22,"OK",IF(F38<=22,"LESS")) -> OK | G40: =IF(G38>=22,"OK",IF(G38<=22,"LESS")) -> OK | H40: =IF(H38>=22,"OK",IF(H38<=22,"LESS")) -> OK | I40: =IF(I38>=22,"OK",IF(I38<=22,"LESS")) -> OK | ... Q40: =IF(Q38>=22,"OK",IF(Q38<=22,"LESS")) -> OK
A43: Done by | B43: AKASH
A45: Comment

Sheet 02
A1: Station: | B1: IGKV ,RAIPUR
A2: Date: | B2: =$A$9 -> 02/06/2023 01:00 | D2: Power Off | G2: Pw.Off | L2: Link Fail | N2: Link F | P2: Maintenance | R2: Maint.
A3: Report Type: | B3: Mean | D3: Calibration | G3: Calib. | L3: Data Fail | N3: Data F | P3: Invalid | R3: Invalid
A4: Time Base: | B4: 01 Hour | D4: Zero Referrence | G4: Z.Ref | L4: Warm Up | N4: Wm. Up
A7: Date & Time | B7: NO | C7: NO2 | D7: NOX | E7: SO2 | F7: O3 | G7: PM 10 | H7: PM 2.5 | I7: BENZ | J7: WS | K7: WD | L7: TEMP | M7: HUM | N7: SR | O7: RG | P7: CO | Q7: NH3
B8: ug/m3 | C8: ug/m3 | D8: ppb | E8: ug/m3 | F8: ug/m3 | G8: ug/m3 | H8: ug/m3 | I8: ug/m3 | J8: m/sec | K8: deg | L8: degreC | M8: % | N8: w/m2 | O8: mm | P8: mg/m3 | Q8: ug/m3
A9: 02/06/2023 01:00 | B9: 54.09 | C9: 67.02 | D9: 77.35 | E9: 23.65 | F9: 3.99 | G9: 132.13 | H9: 40.07 | I9: 11.06 | J9: 0.2 | K9: 212.43 | L9: 29.84 | M9: 35.22 | N9: 0 | O9: 0 | P9: 1.15 | Q9: 6.91
A10: 02/06/2023 02:00 | B10: 56.98 | C10: 65.74 | D10: 79 | E10: 28.48 | F10: 3.89 | G10: 149.04 | H10: 43.81 | I10: 11.63 | J10: 0.22 | K10: 193.74 | L10: 29.97 | M10: 37.74 | N10: 0 | O10: 0 | P10: 1.18 | Q10: 7.25
A11: 02/06/2023 03:00 | B11: 70.25 | C11: 64.92 | D11: 89.2 | E11: 27.48 | F11: 4.48 | G11: 150.46 | H11: 43.81 | I11: 11.66 | J11: 0.29 | K11: 212.11 | L11: 29.89 | M11: 35.95 | N11: 0 | O11: 0 | P11: 1.13 | Q11: 7.53
A12: 02/06/2023 04:00 | B12: 54.26 | C12: 62.72 | D12: 74.77 | E12: 23.31 | F12: 4.38 | G12: 150.46 | H12: 42.76 | I12: 11.21 | J12: 0.37 | K12: 163.06 | L12: 29.35 | M12: 37.54 | N12: 0 | O12: 0 | P12: 1.07 | Q12: 7.55
A13: 02/06/2023 05:00 | B13: 57.14 | C13: 64.57 | D13: 78.51 | E13: 20.68 | F13: 4.46 | G13: 144.42 | H13: 50.1 | I13: 10.98 | J13: 0.6 | K13: 69.67 | L13: 29.31 | M13: 29.29 | N13: 0 | O13: 0 | P13: 1.07 | Q13: 7.51
A14: 02/06/2023 06:00 | B14: 58.71 | C14: 64.63 | D14: 79.8 | E14: 7.88 | F14: 4.05 | G14: 137.79 | H14: 77.51 | I14: 10.75 | J14: 0.21 | K14: 238.09 | L14: 28.16 | M14: 41.95 | N14: 21.7 | O14: 0 | P14: 1.07 | Q14: 7.47
A15: 02/06/2023 07:00 | B15: 53.38 | C15: 62.1 | D15: 74.21 | E15: 11.76 | F15: 4.89 | G15: 136.7 | H15: 85.9 | I15: 10.54 | J15: 0.21 | K15: 320.07 | L15: 30.51 | M15: 42.41 | N15: 61.6 | O15: 0 | P15: 1.04 | Q15: 7.35
A16: 02/06/2023 08:00 | B16: 49.44 | C16: 61.33 | D16: 70.65 | E16: 12.96 | F16: 14.85 | G16: 128.29 | H16: 85.9 | I16: 10.33 | J16: 0.43 | K16: 296.79 | L16: 35.4 | M16: 29.02 | N16: 86.9 | O16: 0 | P16: 1 | Q16: 7.27
A17: 02/06/2023 09:00 | B17: 36.55 | C17: 63.6 | D17: 59.4 | E17: 41.59 | F17: 26.64 | G17: 115.95 | H17: 85.51 | I17: 9.48 | J17: 0.8 | K17: 335.27 | L17: 36.95 | M17: 23.53 | N17: 120.5 | O17: 0 | P17: 0.95 | Q17: 6.96
A18: 02/06/2023 10:00 | B18: 24.89 | C18: 65.66 | D18: 52.03 | E18: 45.1 | F18: 41.14 | G18: 124.48 | H18: 75.92 | I18: 9.64 | J18: 0.85 | K18: 314.88 | L18: 39.5 | M18: 20.1 | N18: 141.4 | O18: 0 | P18: 0.94 | Q18: 6.49
A19: 02/06/2023 11:00 | B19: 15.36 | C19: 62.11 | D19: 43.73 | E19: 32.55 | F19: 44.69 | G19: 124.48 | H19: 75.92 | I19: 9.07 | J19: 0.48 | K19: 338.58 | L19: 40.62 | M19: 16.61 | N19: 185.1 | O19: 0 | P19: 0.87 | Q19: 6.04
A20: 02/06/2023 12:00 | B20: 8.83 | C20: 58.86 | D20: 36.79 | E20: 30.85 | F20: 56.37 | G20: 121.41 | H20: 63.45 | I20: 7.78 | J20: 1.05 | K20: 310.15 | L20: 41.52 | M20: 13.73 | N20: 692.8 | O20: 0 | P20: 0.77 | Q20: 5.54
... A32: 02/06/2023 24:00 | B32: 32.69 | C32: 62.81 | D32: 57.99 | E32: 27.78 | F32: 7.13 | G32: 100 | H32: 27.74 | I32: 9.1 | J32: 0.24 | K32: 320.1 | L32: 34.19 | M32: 30.37 | N32: 0 | O32: 0 | P32: 0.75 | Q32: 6.18
A34: Min | B34: =MIN(B9:B32) -> 4.65 | C34: =MIN(C9:C32) -> 44.7 | D34: =MIN(D9:D32) -> 26.08 | E34: =MIN(E9:E32) -> 7.88 | F34: =MIN(F9:F32) -> 3.89 | G34: =MIN(G9:G32) -> 45.48 | H34: =MIN(H9:H32) -> 16.05 | I34: =MIN(I9:I32) -> 4.29 | ... Q34: =MIN(Q9:Q32) -> 4.77
A35: Max | B35: =MAX(B9:B32) -> 70.25 | C35: =MAX(C9:C32) -> 67.02 | D35: =MAX(D9:D32) -> 89.2 | E35: =MAX(E9:E32) -> 45.1 | F35: =MAX(F9:F32) -> 60.38 | G35: =MAX(G9:G32) -> 150.46 | H35: =MAX(H9:H32) -> 85.9 | I35: =MAX(I9:I32) -> 11.66 | ... Q35: =MAX(Q9:Q32) -> 7.55
A36: Avg | B36: =AVERAGE(B9:B32) -> 29.46125 | C36: =AVERAGE(C9:C32) -> 59.095 | D36: =AVERAGE(D9:D32) -> 53.214167 | E36: =AVERAGE(E9:E32) -> 22.662083 | F36: =AVERAGE(F9:F32) -> 24.888333 | G36: =AVERAGE(G9:G32) -> 103.01708 | H36: =AVERAGE(H9:H32) -> 44.930833 | I36: =AVERAGE(I9:I32) -> 8.3358333 | ... Q36: =AVERAGE(Q9:Q32) -> 6.0995833
A37: Stdev | B37: =STDEV(B9:B32) -> 22.249832 | C37: =STDEV(C9:C32) -> 7.1116011 | D37: =STDEV(D9:D32) -> 20.762403 | E37: =STDEV(E9:E32) -> 11.286599 | F37: =STDEV(F9:F32) -> 20.039584 | G37: =STDEV(G9:G32) -> 36.458288 | H37: =STDEV(H9:H32) -> 24.709697 | I37: =STDEV(I9:I32) -> 2.4652311 | ... Q37: =STDEV(Q9:Q32) -> 1.0666342
A38: Num | B38: =COUNT(B9:B32) -> 24 | C38: =COUNT(C9:C32) -> 24 | D38: =COUNT(D9:D32) -> 24 | E38: =COUNT(E9:E32) -> 24 | F38: =COUNT(F9:F32) -> 24 | G38: =COUNT(G9:G32) -> 24 | H38: =COUNT(H9:H32) -> 24 | I38: =COUNT(I9:I32) -> 24 | ... Q38: =COUNT(Q9:Q32) -> 24
A39: DCR | B39: =IF(B38>=22,">90%",IF(B38<=22,"<90%")) -> >90% | C39: =IF(C38>=22,">90%",IF(C38<=22,"<90%")) -> >90% | D39: =IF(D38>=22,">90%",IF(D38<=22,"<90%")) -> >90% | E39: =IF(E38>=22,">90%",IF(E38<=22,"<90%")) -> >90% | F39: =IF(F38>=22,">90%",IF(F38<=22,"<90%")) -> >90% | G39: =IF(G38>=22,">90%",IF(G38<=22,"<90%")) -> >90% | H39: =IF(H38>=22,">90%",IF(H38<=22,"<90%")) -> >90% | I39: =IF(I38>=22,">90%",IF(I38<=22,"<90%")) -> >90% | ... Q39: =IF(Q38>=22,">90%",IF(Q38<=22,"<90%")) -> >90%
A40: Status | B40: =IF(B38>=22,"OK",IF(B38<=22,"LESS")) -> OK | C40: =IF(C38>=22,"OK",IF(C38<=22,"LESS")) -> OK | D40: =IF(D38>=22,"OK",IF(D38<=22,"LESS")) -> OK | E40: =IF(E38>=22,"OK",IF(E38<=22,"LESS")) -> OK | F40: =IF(F38>=22,"OK",IF(F38<=22,"LESS")) -> OK | G40: =IF(G38>=22,"OK",IF(G38<=22,"LESS")) -> OK | H40: =IF(H38>=22,"OK",IF(H38<=22,"LESS")) -> OK | I40: =IF(I38>=22,"OK",IF(I38<=22,"LESS")) -> OK | ... Q40: =IF(Q38>=22,"OK",IF(Q38<=22,"LESS")) -> OK
A43: Done by | B43: AKASH
A45: Comment

Sheet 03
A1: Station: | B1: IGKV ,RAIPUR
A2: Date: | B2: =$A$9 -> 03/06/2023 01:00 | D2: Power Off | G2: Pw.Off | L2: Link Fail | N2: Link F | P2: Maintenance | R2: Maint.
A3: Report Type: | B3: Mean | D3: Calibration | G3: Calib. | L3: Data Fail | N3: Data F | P3: Invalid | R3: Invalid
A4: Time Base: | B4: 01 Hour | D4: Zero Referrence | G4: Z.Ref | L4: Warm Up | N4: Wm. Up
A7: Date & Time | B7: NO | C7: NO2 | D7: NOX | E7: SO2 | F7: O3 | G7: PM 10 | H7: PM 2.5 | I7: BENZ | J7: WS | K7: WD | L7: TEMP | M7: HUM | N7: SR | O7: RG | P7: CO | Q7: NH3
B8: ug/m3 | C8: ug/m3 | D8: ppb | E8: ug/m3 | F8: ug/m3 | G8: ug/m3 | H8: ug/m3 | I8: ug/m3 | J8: m/sec | K8: deg | L8: degreC | M8: % | N8: w/m2 | O8: mm | P8: mg/m3 | Q8: ug/m3
A9: 03/06/2023 01:00 | B9: 31.29 | C9: 63.07 | D9: 56.18 | E9: 23.33 | F9: 6.29 | G9: 107.55 | H9: 31.56 | I9: 8.95 | J9: 0.28 | K9: 234.18 | L9: 32.19 | M9: 32.63 | N9: 0 | O9: 0 | P9: 0.79 | Q9: 6.28
A10: 03/06/2023 02:00 | B10: 32.96 | C10: 61.23 | D10: 57.38 | E10: 33.93 | F10: 8.04 | G10: 107.55 | H10: 33 | I10: 9.12 | J10: 0.13 | K10: 221.78 | L10: 32.16 | M10: 33.83 | N10: 0 | O10: 0 | P10: 0.78 | Q10: 6.34
A11: 03/06/2023 03:00 | B11: 34.56 | C11: 60.29 | D11: 58.17 | E11: 41.46 | F11: 7.91 | G11: 118.17 | H11: 34.27 | I11: 8.98 | J11: 0.39 | K11: 72.01 | L11: 31.32 | M11: 31.05 | N11: 0 | O11: 0 | P11: 0.78 | Q11: 6.39
A12: 03/06/2023 04:00 | B12: 30.35 | C12: 58.85 | D12: 53.9 | E12: 39.33 | F12: 10.49 | G12: 118.17 | H12: 34.27 | I12: 8.31 | J12: 0.59 | K12: 64.04 | L12: 30.79 | M12: 30.38 | N12: 0 | O12: 0 | P12: 0.78 | Q12: 6.39
A13: 03/06/2023 05:00 | B13: 36.52 | C13: 60.97 | D13: 60.1 | E13: 37.33 | F13: 8.96 | G13: 107.45 | H13: 33.68 | I13: 7.61 | J13: 0.55 | K13: 56.18 | L13: 30.67 | M13: 32.87 | N13: 0 | O13: 0 | P13: 0.79 | Q13: 6.36
A14: 03/06/2023 06:00 | B14: 34.41 | C14: 59.93 | D14: 57.27 | E14: 15.29 | F14: 6.87 | G14: 106.36 | H14: 32.83 | I14: 7.38 | J14: 0.39 | K14: 70.95 | L14: 30.05 | M14: 36.35 | N14: 16.9 | O14: 0 | P14: 0.75 | Q14: 6.45
A15: 03/06/2023 07:00 | B15: 35.17 | C15: 59.98 | D15: 58.5 | E15: 13.09 | F15: 8.36 | G15: 95.42 | H15: 28.99 | I15: 7.72 | J15: 0.27 | K15: 36.67 | L15: 31.12 | M15: 35.57 | N15: 59.8 | O15: 0 | P15: 0.83 | Q15: 6.5
A16: 03/06/2023 08:00 | B16: 36.15 | C16: 61.84 | D16: 60.25 | E16: 17.14 | F16: 14.06 | G16: 92.78 | H16: 28.37 | I16: 8.34 | J16: 0.57 | K16: 49.71 | L16: 33.32 | M16: 36.44 | N16: 148.5 | O16: 0 | P16: 0.86 | Q16: 6.55
A17: 03/06/2023 09:00 | B17: 28.14 | C17: 58.79 | D17: 52.24 | E17: 32.86 | F17: 26.14 | G17: 93.65 | H17: 28.37 | I17: 8.12 | J17: 0.76 | K17: 61.97 | L17: 36.45 | M17: 31.85 | N17: 174.9 | O17: 0 | P17: 0.8 | Q17: 6.49
A18: 03/06/2023 10:00 | B18: 22.57 | C18: 65.17 | D18: 50.05 | E18: 50.99 | F18: 18.7 | G18: 93.65 | H18: 28.26 | I18: 7.39 | J18: 1.02 | K18: 76.47 | L18: 37.61 | M18: 27.97 | N18: 195.1 | O18: 0 | P18: 0.78 | Q18: 6.25
A19: 03/06/2023 11:00 | B19: 18.95 | C19: 63.67 | D19: 45.36 | E19: 15.56 | F19: 23.95 | G19: 93.51 | H19: 26.71 | I19: 7.25 | J19: 1.24 | K19: 91.35 | L19: 39.78 | M19: 25.04 | N19: 185.1 | O19: 0 | P19: 0.75 | Q19: 5.99
A20: 03/06/2023 12:00 | B20: 10.63 | C20: 57.3 | D20: 37.42 | E20: 10.81 | F20: 36.94 | G20: 90.03 | H20: 25.88 | I20: 6.91 | J20: 1.03 | K20: 81.28 | L20: 41.2 | M20: 21.26 | N20: 782.8 | O20: 0 | P20: 0.65 | Q20: 5.57
... A32: 03/06/2023 24:00 | B32: 50.04 | C32: 74.51 | D32: 76.77 | E32: 33.35 | F32: 6.54 | G32: 233.53 | H32: 136.79 | I32: 17.03 | J32: 0.35 | K32: 295.95 | L32: 32.46 | M32: 36.71 | N32: 0 | O32: 0 | P32: 1.67 | Q32: 7.24
A34: Min | B34: =MIN(B9:B32) -> 3.29 | C34: =MIN(C9:C32) -> 48.94 | D34: =MIN(D9:D32) -> 27.16 | E34: =MIN(E9:E32) -> 9.44 | F34: =MIN(F9:F32) -> 4.1 | G34: =MIN(G9:G32) -> 62.94 | H34: =MIN(H9:H32) -> 23.13 | I34: =MIN(I9:I32) -> 4.68 | ... Q34: =MIN(Q9:Q32) -> 4.85
A35: Max | B35: =MAX(B9:B32) -> 62.22 | C35: =MAX(C9:C32) -> 75.93 | D35: =MAX(D9:D32) -> 88.68 | E35: =MAX(E9:E32) -> 50.99 | F35: =MAX(F9:F32) -> 62.74 | G35: =MAX(G9:G32) -> 233.53 | H35: =MAX(H9:H32) -> 136.79 | I35: =MAX(I9:I32) -> 17.03 | ... Q35: =MAX(Q9:Q32) -> 7.24
A36: Avg | B36: =AVERAGE(B9:B32) -> 24.02 | C36: =AVERAGE(C9:C32) -> 61.845 | D36: =AVERAGE(D9:D32) -> 50.322917 | E36: =AVERAGE(E9:E32) -> 22.315833 | F36: =AVERAGE(F9:F32) -> 24.739583 | G36: =AVERAGE(G9:G32) -> 96.346667 | H36: =AVERAGE(H9:H32) -> 41.160833 | I36: =AVERAGE(I9:I32) -> 7.8933333 | ... Q36: =AVERAGE(Q9:Q32) -> 5.8658333
A37: Stdev | B37: =STDEV(B9:B32) -> 18.029238 | C37: =STDEV(C9:C32) -> 8.256877 | D37: =STDEV(D9:D32) -> 17.316553 | E37: =STDEV(E9:E32) -> 11.660752 | F37: =STDEV(F9:F32) -> 20.389397 | G37: =STDEV(G9:G32) -> 34.290115 | H37: =STDEV(H9:H32) -> 23.294525 | I37: =STDEV(I9:I32) -> 2.7714016 | ... Q37: =STDEV(Q9:Q32) -> 0.71975187
A38: Num | B38: =COUNT(B9:B32) -> 24 | C38: =COUNT(C9:C32) -> 24 | D38: =COUNT(D9:D32) -> 24 | E38: =COUNT(E9:E32) -> 24 | F38: =COUNT(F9:F32) -> 24 | G38: =COUNT(G9:G32) -> 24 | H38: =COUNT(H9:H32) -> 24 | I38: =COUNT(I9:I32) -> 24 | ... Q38: =COUNT(Q9:Q32) -> 24
A39: DCR | B39: =IF(B38>=22,">90%",IF(B38<=22,"<90%")) -> >90% | C39: =IF(C38>=22,">90%",IF(C38<=22,"<90%")) -> >90% | D39: =IF(D38>=22,">90%",IF(D38<=22,"<90%")) -> >90% | E39: =IF(E38>=22,">90%",IF(E38<=22,"<90%")) -> >90% | F39: =IF(F38>=22,">90%",IF(F38<=22,"<90%")) -> >90% | G39: =IF(G38>=22,">90%",IF(G38<=22,"<90%")) -> >90% | H39: =IF(H38>=22,">90%",IF(H38<=22,"<90%")) -> >90% | I39: =IF(I38>=22,">90%",IF(I38<=22,"<90%")) -> >90% | ... Q39: =IF(Q38>=22,">90%",IF(Q38<=22,"<90%")) -> >90%
A40: Status | B40: =IF(B38>=22,"OK",IF(B38<=22,"LESS")) -> OK | C40: =IF(C38>=22,"OK",IF(C38<=22,"LESS")) -> OK | D40: =IF(D38>=22,"OK",IF(D38<=22,"LESS")) -> OK | E40: =IF(E38>=22,"OK",IF(E38<=22,"LESS")) -> OK | F40: =IF(F38>=22,"OK",IF(F38<=22,"LESS")) -> OK | G40: =IF(G38>=22,"OK",IF(G38<=22,"LESS")) -> OK | H40: =IF(H38>=22,"OK",IF(H38<=22,"LESS")) -> OK | I40: =IF(I38>=22,"OK",IF(I38<=22,"LESS")) -> OK | ... Q40: =IF(Q38>=22,"OK",IF(Q38<=22,"LESS")) -> OK
A43: Done by | B43: AKASH
A45: Comment

Sheet 04
A1: Station: | B1: IGKV ,RAIPUR
A2: Date: | B2: =$A$9 -> 04/06/2023 01:00 | D2: Power Off | G2: Pw.Off | L2: Link Fail | N2: Link F | P2: Maintenance | R2: Maint.
A3: Report Type: | B3: Mean | D3: Calibration | G3: Calib. | L3: Data Fail | N3: Data F | P3: Invalid | R3: Invalid
A4: Time Base: | B4: 01 Hour | D4: Zero Referrence | G4: Z.Ref | L4: Warm Up | N4: Wm. Up
A7: Date & Time | B7: NO | C7: NO2 | D7: NOX | E7: SO2 | F7: O3 | G7: PM 10 | H7: PM 2.5 | I7: BENZ | J7: WS | K7: WD | L7: TEMP | M7: HUM | N7: SR | O7: RG | P7: CO | Q7: NH3
B8: ug/m3 | C8: ug/m3 | D8: ppb | E8: ug/m3 | F8: ug/m3 | G8: ug/m3 | H8: ug/m3 | I8: ug/m3 | J8: m/sec | K8: deg | L8: degreC | M8: % | N8: w/m2 | O8: mm | P8: mg/m3 | Q8: ug/m3
A9: 04/06/2023 01:00 | B9: 46.87 | C9: 67.6 | D9: 70.99 | E9: 40.63 | F9: 7.89 | G9: 233.53 | H9: 136.79 | I9: 15.13 | J9: 0.36 | K9: 326.17 | L9: 32.31 | M9: 35.78 | N9: 0 | O9: 0 | P9: 1.23 | Q9: 7.26
A10: 04/06/2023 02:00 | B10: 48.52 | C10: 66.96 | D10: 72.85 | E10: 34.86 | F10: 6.78 | G10: 132.92 | H10: 118.55 | I10: 10.69 | J10: 0.32 | K10: 75.29 | L10: 30.99 | M10: 37.34 | N10: 0 | O10: 0 | P10: 1.16 | Q10: 7.33
A11: 04/06/2023 03:00 | B11: 41.27 | C11: 61.74 | D11: 64.3 | E11: 15.88 | F11: 10.71 | G11: 105.55 | H11: 86.2 | I11: 10.49 | J11: 0.63 | K11: 54.18 | L11: 31.13 | M11: 36.89 | N11: 0 | O11: 0 | P11: 1.11 | Q11: 7.2
A12: 04/06/2023 04:00 | B12: 42.36 | C12: 63.79 | D12: 66.25 | E12: 20.63 | F12: 7.6 | G12: 98.49 | H12: 64.09 | I12: 9.69 | J12: 0.29 | K12: 188.16 | L12: 30.33 | M12: 44.64 | N12: 0 | O12: 0 | P12: 1.01 | Q12: 6.99
A13: 04/06/2023 05:00 | B13: 43.49 | C13: 64.11 | D13: 67.33 | E13: 13.06 | F13: 5.32 | G13: 79.4 | H13: 52.68 | I13: 9.74 | J13: 0.45 | K13: 253.35 | L13: 28.4 | M13: 48.95 | N13: 0 | O13: 0 | P13: 1.03 | Q13: 6.97
A14: 04/06/2023 06:00 | B14: 40.09 | C14: 63.25 | D14: 64.15 | E14: 7.18 | F14: 5.65 | G14: 79.4 | H14: 52.68 | I14: 9.63 | J14: 0.32 | K14: 244.84 | L14: 28.03 | M14: 52.24 | N14: 20.5 | O14: 0 | P14: 0.97 | Q14: 6.76
A15: 04/06/2023 07:00 | B15: 37.71 | C15: 60.38 | D15: 60.75 | E15: 8.83 | F15: 4.88 | G15: 59.55 | H15: 46.09 | I15: 9.9 | J15: 0.19 | K15: 289.83 | L15: 29.8 | M15: 53.82 | N15: 63.6 | O15: 0 | P15: 0.94 | Q15: 6.69
A16: 04/06/2023 08:00 | B16: 38 | C16: 62.93 | D16: 61.14 | E16: 22.35 | F16: 11.19 | G16: 86.59 | H16: 53.14 | I16: 10.83 | J16: 0.68 | K16: 319.44 | L16: 31.81 | M16: 40.1 | N16: 132 | O16: 0 | P16: 0.96 | Q16: 6.66
A17: 04/06/2023 09:00 | B17: 33.82 | C17: 62.39 | D17: 57.65 | E17: 27.82 | F17: 14.71 | G17: 90.12 | H17: 66.24 | I17: 9.67 | J17: 1.05 | K17: 312.19 | L17: 35.06 | M17: 32.45 | N17: 235.2 | O17: 0 | P17: 0.93 | Q17: 6.54
A18: 04/06/2023 10:00 | B18: 23.45 | C18: 61.84 | D18: 49.52 | E18: 33.98 | F18: 33.43 | G18: 101.05 | H18: 66.24 | I18: 9.28 | J18: 1.07 | K18: 347.3 | L18: 36.04 | M18: 30.64 | N18: 256.1 | O18: 0 | P18: 0.9 | Q18: 6.23
A19: 04/06/2023 11:00 | B19: 15.12 | C19: 64.68 | D19: 44.88 | E19: 54.44 | F19: 51.54 | G19: 105.21 | H19: 41.23 | I19: 8.47 | J19: 0.82 | K19: 130.55 | L19: 38.74 | M19: 29.35 | N19: 318.4 | O19: 0 | P19: 0.93 | Q19: 5.91
A20: 04/06/2023 12:00 | B20: 7.84 | C20: 58.84 | D20: 34.82 | E20: 61.17 | F20: 78.12 | G20: 105.21 | H20: 35.17 | I20: 7.86 | J20: 0.41 | K20: 106.83 | L20: 40.52 | M20: 24.59 | N20: 679.4 | O20: 0 | P20: 0.85 | Q20: 5.48
... A32: 04/06/2023 24:00 | B32: 5.23 | C32: 50.36 | D32: 29.29 | E32: 9.9 | F32: 20.65 | G32: 68.06 | H32: 39.2 | I32: 4.19 | J32: 0.51 | K32: 130.31 | L32: 31.52 | M32: 44.31 | N32: 0 | O32: 0 | P32: 0.53 | Q32: 4.79
A34: Min | B34: =MIN(B9:B32) -> 3.38 | C34: =MIN(C9:C32) -> 47.04 | D34: =MIN(D9:D32) -> 26.47 | E34: =MIN(E9:E32) -> 7.18 | F34: =MIN(F9:F32) -> 4.88 | G34: =MIN(G9:G32) -> 46.29 | H34: =MIN(H9:H32) -> 35.17 | I34: =MIN(I9:I32) -> 4.19 | ... Q34: =MIN(Q9:Q32) -> 4.69
A35: Max | B35: =MAX(B9:B32) -> 48.52 | C35: =MAX(C9:C32) -> 67.6 | D35: =MAX(D9:D32) -> 72.85 | E35: =MAX(E9:E32) -> 68.1 | F35: =MAX(F9:F32) -> 83.97 | G35: =MAX(G9:G32) -> 233.53 | H35: =MAX(H9:H32) -> 136.79 | I35: =MAX(I9:I32) -> 15.13 | ... Q35: =MAX(Q9:Q32) -> 7.33
A36: Avg | B36: =AVERAGE(B9:B32) -> 20.107083 | C36: =AVERAGE(C9:C32) -> 58.096667 | D36: =AVERAGE(D9:D32) -> 45.147083 | E36: =AVERAGE(E9:E32) -> 25.645 | F36: =AVERAGE(F9:F32) -> 31.565833 | G36: =AVERAGE(G9:G32) -> 96.30125 | H36: =AVERAGE(H9:H32) -> 62.550417 | I36: =AVERAGE(I9:I32) -> 7.8895833 | ... Q36: =AVERAGE(Q9:Q32) -> 5.8079167
A37: Stdev | B37: =STDEV(B9:B32) -> 17.568866 | C37: =STDEV(C9:C32) -> 6.0525307 | D37: =STDEV(D9:D32) -> 16.818053 | E37: =STDEV(E9:E32) -> 17.522829 | F37: =STDEV(F9:F32) -> 24.139059 | G37: =STDEV(G9:G32) -> 36.411281 | H37: =STDEV(H9:H32) -> 23.847495 | I37: =STDEV(I9:I32) -> 2.6977083 | ... Q37: =STDEV(Q9:Q32) -> 0.96755173
A38: Num | B38: =COUNT(B9:B32) -> 24 | C38: =COUNT(C9:C32) -> 24 | D38: =COUNT(D9:D32) -> 24 | E38: =COUNT(E9:E32) -> 24 | F38: =COUNT(F9:F32) -> 24 | G38: =COUNT(G9:G32) -> 24 | H38: =COUNT(H9:H32) -> 24 | I38: =COUNT(I9:I32) -> 24 | ... Q38: =COUNT(Q9:Q32) -> 24
A39: DCR | B39: =IF(B38>=22,">90%",IF(B38<=22,"<90%")) -> >90% | C39: =IF(C38>=22,">90%",IF(C38<=22,"<90%")) -> >90% | D39: =IF(D38>=22,">90%",IF(D38<=22,"<90%")) -> >90% | E39: =IF(E38>=22,">90%",IF(E38<=22,"<90%")) -> >90% | F39: =IF(F38>=22,">90%",IF(F38<=22,"<90%")) -> >90% | G39: =IF(G38>=22,">90%",IF(G38<=22,"<90%")) -> >90% | H39: =IF(H38>=22,">90%",IF(H38<=22,"<90%")) -> >90% | I39: =IF(I38>=22,">90%",IF(I38<=22,"<90%")) -> >90% | ... Q39: =IF(Q38>=22,">90%",IF(Q38<=22,"<90%")) -> >90%
A40: Status | B40: =IF(B38>=22,"OK",IF(B38<=22,"LESS")) -> OK | C40: =IF(C38>=22,"OK",IF(C38<=22,"LESS")) -> OK | D40: =IF(D38>=22,"OK",IF(D38<=22,"LESS")) -> OK | E40: =IF(E38>=22,"OK",IF(E38<=22,"LESS")) -> OK | F40: =IF(F38>=22,"OK",IF(F38<=22,"LESS")) -> OK | G40: =IF(G38>=22,"OK",IF(G38<=22,"LESS")) -> OK | H40: =IF(H38>=22,"OK",IF(H38<=22,"LESS")) -> OK | I40: =IF(I38>=22,"OK",IF(I38<=22,"LESS")) -> OK | ... Q40: =IF(Q38>=22,"OK",IF(Q38<=22,"LESS")) -> OK
A43: Done by | B43: AKASH
A45: Comment

Sheet 05
A1: Station: | B1: IGKV ,RAIPUR
A2: Date: | B2: =$A$9 -> 05/06/2023 01:00 | D2: Power Off | G2: Pw.Off | L2: Link Fail | N2: Link F | P2: Maintenance | R2: Maint.
A3: Report Type: | B3: Mean | D3: Calibration | G3: Calib. | L3: Data Fail | N3: Data F | P3: Invalid | R3: Invalid
A4: Time Base: | B4: 01 Hour | D4: Zero Referrence | G4: Z.Ref | L4: Warm Up | N4: Wm. Up
A7: Date & Time | B7: NO | C7: NO2 | D7: NOX | E7: SO2 | F7: O3 | G7: PM 10 | H7: PM 2.5 | I7: BENZ | J7: WS | K7: WD | L7: TEMP | M7: HUM | N7: SR | O7: RG | P7: CO | Q7: NH3
B8: ug/m3 | C8: ug/m3 | D8: ppb | E8: ug/m3 | F8: ug/m3 | G8: ug/m3 | H8: ug/m3 | I8: ug/m3 | J8: m/sec | K8: deg | L8: degreC | M8: % | N8: w/m2 | O8: mm | P8: mg/m3 | Q8: ug/m3
A9: 05/06/2023 01:00 | B9: 4.85 | C9: 51.07 | D9: 29.36 | E9: 8.34 | F9: 22.46 | G9: 49.28 | H9: 34.58 | I9: 4.21 | J9: 0.21 | K9: 153.5 | L9: 30.91 | M9: 48.34 | N9: 0 | O9: 0 | P9: 0.53 | Q9: 4.87
A10: 05/06/2023 02:00 | B10: 6.76 | C10: 54.11 | D10: 32.65 | E10: 8 | F10: 18.49 | G10: 46.7 | H10: 30.98 | I10: 4.06 | J10: 0.27 | K10: 164.33 | L10: 29.87 | M10: 49.52 | N10: 0 | O10: 0 | P10: 0.53 | Q10: 4.96
A11: 05/06/2023 03:00 | B11: 6.91 | C11: 52.34 | D11: 31.84 | E11: 5.68 | F11: 20.9 | G11: 32.77 | H11: 19.72 | I11: 4.22 | J11: 0.25 | K11: 167.07 | L11: 29.66 | M11: 49.08 | N11: 0 | O11: 0 | P11: 0.52 | Q11: 4.96
A12: 05/06/2023 04:00 | B12: 9.31 | C12: 53.08 | D12: 34.15 | E12: 5.47 | F12: 19.41 | G12: 30.09 | H12: 20.81 | I12: 4.08 | J12: 0.2 | K12: 231.77 | L12: 29.25 | M12: 52.72 | N12: 0 | O12: 0 | P12: 0.51 | Q12: 4.98
A13: 05/06/2023 05:00 | B13: 10.83 | C13: 58.92 | D13: 38.4 | E13: 5.04 | F13: 9.68 | G13: 30.78 | H13: 20.81 | I13: 4.05 | J13: 0.29 | K13: 172.99 | L13: 28.64 | M13: 55.83 | N13: 0 | O13: 0 | P13: 0.54 | Q13: 5.14
A14: 05/06/2023 06:00 | B14: 12.35 | C14: 61.57 | D14: 40.97 | E14: 5.07 | F14: 8.05 | G14: 36.11 | H14: 19.9 | I14: 4.39 | J14: 0.21 | K14: 219.47 | L14: 28.48 | M14: 57.78 | N14: 38.5 | O14: 0 | P14: 0.55 | Q14: 5.31
A15: 05/06/2023 07:00 | B15: 12.66 | C15: 55.7 | D15: 38.21 | E15: 5.14 | F15: 8.94 | G15: 36.11 | H15: 20.99 | I15: 4.49 | J15: 0.4 | K15: 282.1 | L15: 29.95 | M15: 51.39 | N15: 91.6 | O15: 0 | P15: 0.56 | Q15: 5.33
A16: 05/06/2023 08:00 | B16: 12.31 | C16: 57.17 | D16: 38.68 | E16: 6.31 | F16: 12.38 | G16: 38.78 | H16: 23 | I16: 4.76 | J16: 0.78 | K16: 290.7 | L16: 31.43 | M16: 47.15 | N16: 133.6 | O16: 0 | P16: 0.6 | Q16: 5.32
A17: 05/06/2023 09:00 | B17: 11.65 | C17: 59.22 | D17: 37.93 | E17: 7.34 | F17: 14.94 | G17: 46.12 | H17: 25.21 | I17: 5.18 | J17: 0.61 | K17: 307.23 | L17: 33.61 | M17: 44.78 | N17: 178.7 | O17: 0 | P17: 0.68 | Q17: 5.25
A18: 05/06/2023 10:00 | B18: 8.9 | C18: 56.41 | D18: 35.57 | E18: 29.63 | F18: 29.24 | G18: 58.16 | H18: 29.64 | I18: 6.07 | J18: 0.79 | K18: 330.82 | L18: 35.45 | M18: 38.86 | N18: 217.4 | O18: 0 | P18: 0.85 | Q18: 5.19
A19: 05/06/2023 11:00 | B19: 6.66 | C19: 56.16 | D19: 33.01 | E19: 34.01 | F19: 47.57 | G19: 83.33 | H19: 46.44 | I19: 6.91 | J19: 0.74 | K19: 323.36 | L19: 36.77 | M19: 37 | N19: 276.5 | O19: 0 | P19: 0.9 | Q19: 5.08
A20: 05/06/2023 12:00 | B20: 3.87 | C20: 53.2 | D20: 29.86 | E20: 37.13 | F20: 61.06 | G20: 97.07 | H20: 54.26 | I20: 6.73 | J20: 0.83 | K20: 334.05 | L20: 38.64 | M20: 32.42 | N20: 672.8 | O20: 0 | P20: 0.89 | Q20: 4.98
... A32: 05/06/2023 24:00 | B32: 9.51 | C32: 58.86 | D32: 37.33 | E32: 6.23 | F32: 15.62 | G32: 58.41 | H32: 26.43 | I32: 5.3 | J32: 0.16 | K32: 251.12 | L32: 28.27 | M32: 59.3 | N32: 0 | O32: 0 | P32: 0.65 | Q32: 5.26
A34: Min | B34: =MIN(B9:B32) -> 2.11 | C34: =MIN(C9:C32) -> 42.01 | D34: =MIN(D9:D32) -> 22.31 | E34: =MIN(E9:E32) -> 5.04 | F34: =MIN(F9:F32) -> 8.05 | G34: =MIN(G9:G32) -> 30.09 | H34: =MIN(H9:H32) -> 19.72 | I34: =MIN(I9:I32) -> 4.05 | ... Q34: =MIN(Q9:Q32) -> 4.73
A35: Max | B35: =MAX(B9:B32) -> 12.66 | C35: =MAX(C9:C32) -> 61.57 | D35: =MAX(D9:D32) -> 40.97 | E35: =MAX(E9:E32) -> 37.13 | F35: =MAX(F9:F32) -> 83.25 | G35: =MAX(G9:G32) -> 185.57 | H35: =MAX(H9:H32) -> 54.8 | I35: =MAX(I9:I32) -> 6.91 | ... Q35: =MAX(Q9:Q32) -> 5.33
A36: Avg | B36: =AVERAGE(B9:B32) -> 7.0308333 | C36: =AVERAGE(C9:C32) -> 54.27 | D36: =AVERAGE(D9:D32) -> 32.824583 | E36: =AVERAGE(E9:E32) -> 16.044167 | F36: =AVERAGE(F9:F32) -> 31.883333 | G36: =AVERAGE(G9:G32) -> 75.55625 | H36: =AVERAGE(H9:H32) -> 36.527917 | I36: =AVERAGE(I9:I32) -> 5.3645833 | ... Q36: =AVERAGE(Q9:Q32) -> 5.0345833
A37: Stdev | B37: =STDEV(B9:B32) -> 3.3968027 | C37: =STDEV(C9:C32) -> 4.9466862 | D37: =STDEV(D9:D32) -> 5.019236 | E37: =STDEV(E9:E32) -> 11.467238 | F37: =STDEV(F9:F32) -> 21.283831 | G37: =STDEV(G9:G32) -> 43.452539 | H37: =STDEV(H9:H32) -> 13.320748 | I37: =STDEV(I9:I32) -> 0.92337744 | ... Q37: =STDEV(Q9:Q32) -> 0.19133352
A38: Num | B38: =COUNT(B9:B32) -> 24 | C38: =COUNT(C9:C32) -> 24 | D38: =COUNT(D9:D32) -> 24 | E38: =COUNT(E9:E32) -> 24 | F38: =COUNT(F9:F32) -> 24 | G38: =COUNT(G9:G32) -> 24 | H38: =COUNT(H9:H32) -> 24 | I38: =COUNT(I9:I32) -> 24 | ... Q38: =COUNT(Q9:Q32) -> 24
A39: DCR | B39: =IF(B38>=22,">90%",IF(B38<=22,"<90%")) -> >90% | C39: =IF(C38>=22,">90%",IF(C38<=22,"<90%")) -> >90% | D39: =IF(D38>=22,">90%",IF(D38<=22,"<90%")) -> >90% | E39: =IF(E38>=22,">90%",IF(E38<=22,"<90%")) -> >90% | F39: =IF(F38>=22,">90%",IF(F38<=22,"<90%")) -> >90% | G39: =IF(G38>=22,">90%",IF(G38<=22,"<90%")) -> >90% | H39: =IF(H38>=22,">90%",IF(H38<=22,"<90%")) -> >90% | I39: =IF(I38>=22,">90%",IF(I38<=22,"<90%")) -> >90% | ... Q39: =IF(Q38>=22,">90%",IF(Q38<=22,"<90%")) -> >90%
A40: Status | B40: =IF(B38>=22,"OK",IF(B38<=22,"LESS")) -> OK | C40: =IF(C38>=22,"OK",IF(C38<=22,"LESS")) -> OK | D40: =IF(D38>=22,"OK",IF(D38<=22,"LESS")) -> OK | E40: =IF(E38>=22,"OK",IF(E38<=22,"LESS")) -> OK | F40: =IF(F38>=22,"OK",IF(F38<=22,"LESS")) -> OK | G40: =IF(G38>=22,"OK",IF(G38<=22,"LESS")) -> OK | H40: =IF(H38>=22,"OK",IF(H38<=22,"LESS")) -> OK | I40: =IF(I38>=22,"OK",IF(I38<=22,"LESS")) -> OK | ... Q40: =IF(Q38>=22,"OK",IF(Q38<=22,"LESS")) -> OK
A43: Done by | B43: AKASH
A45: Comment

Sheet 06
A1: Station: | B1: IGKV ,RAIPUR
A2: Date: | B2: =$A$9 -> 06/06/2023 01:00 | D2: Power Off | G2: Pw.Off | L2: Link Fail | N2: Link F | P2: Maintenance | R2: Maint.
A3: Report Type: | B3: Mean | D3: Calibration | G3: Calib. | L3: Data Fail | N3: Data F | P3: Invalid | R3: Invalid
A4: Time Base: | B4: 01 Hour | D4: Zero Referrence | G4: Z.Ref | L4: Warm Up | N4: Wm. Up
A7: Date & Time | B7: NO | C7: NO2 | D7: NOX | E7: SO2 | F7: O3 | G7: PM 10 | H7: PM 2.5 | I7: BENZ | J7: WS | K7: WD | L7: TEMP | M7: HUM | N7: SR | O7: RG | P7: CO | Q7: NH3
B8: ug/m3 | C8: ug/m3 | D8: ppb | E8: ug/m3 | F8: ug/m3 | G8: ug/m3 | H8: ug/m3 | I8: ug/m3 | J8: m/sec | K8: deg | L8: degreC | M8: % | N8: w/m2 | O8: mm | P8: mg/m3 | Q8: ug/m3
A9: 06/06/2023 01:00 | B9: 11.66 | C9: 63.47 | D9: 40.59 | E9: 6.14 | F9: 12.84 | G9: 51.53 | H9: 25.75 | I9: 5.32 | J9: 0.13 | K9: 221.53 | L9: 27.9 | M9: 60.57 | N9: 0 | O9: 0 | P9: 0.65 | Q9: 5.33
A10: 06/06/2023 02:00 | B10: 12.52 | C10: 60.21 | D10: 40.4 | E10: 6.07 | F10: 11.42 | G10: 51.53 | H10: 22.91 | I10: 5.47 | J10: 0.14 | K10: 243 | L10: 27.61 | M10: 63.29 | N10: 0 | O10: 0 | P10: 0.65 | Q10: 5.35
A11: 06/06/2023 03:00 | B11: 14.52 | C11: 62.81 | D11: 43.42 | E11: 6.4 | F11: 9.64 | G11: 44.15 | H11: 22.91 | I11: 5.52 | J11: 0.15 | K11: 238.73 | L11: 27.01 | M11: 65.34 | N11: 0 | O11: 0 | P11: 0.65 | Q11: 5.41
A12: 06/06/2023 04:00 | B12: 16.68 | C12: 63.91 | D12: 45.53 | E12: 6.79 | F12: 5.77 | G12: 36.83 | H12: 22.1 | I12: 5.62 | J12: 0.21 | K12: 224.27 | L12: 26.57 | M12: 68.04 | N12: 0 | O12: 0 | P12: 0.65 | Q12: 5.51
A13: 06/06/2023 05:00 | B13: 21.77 | C13: 64.16 | D13: 49.71 | E13: 6.02 | F13: 4.71 | G13: 45.49 | H13: 22.1 | I13: 5.6 | J13: 0.15 | K13: 246.51 | L13: 26.66 | M13: 68.3 | N13: 0 | O13: 0 | P13: 0.65 | Q13: 5.7
A14: 06/06/2023 06:00 | B14: 26.18 | C14: 69.75 | D14: 55.75 | E14: 6.16 | F14: 4.11 | G14: 59.01 | H14: 20.64 | I14: 5.67 | J14: 0.16 | K14: 130.13 | L14: 26.84 | M14: 68.39 | N14: 21.4 | O14: 0 | P14: 0.67 | Q14: 6.06
A15: 06/06/2023 07:00 | B15: 26.87 | C15: 66.46 | D15: 54.83 | E15: 6.19 | F15: 7.64 | G15: 72.42 | H15: 25.08 | I15: 6.41 | J15: 0.52 | K15: 53.09 | L15: 29.28 | M15: 64.58 | N15: 69.2 | O15: 0 | P15: 0.71 | Q15: 6.2
A16: 06/06/2023 08:00 | B16: 25.4 | C16: 63.9 | D16: 51.63 | E16: 6.22 | F16: 15.17 | G16: 75.29 | H16: 27.2 | I16: 6.45 | J16: 0.38 | K16: 136.35 | L16: 32.34 | M16: 53.77 | N16: 99.1 | O16: 0 | P16: 0.71 | Q16: 6.22
A17: 06/06/2023 09:00 | B17: 21.8 | C17: 63 | D17: 49.35 | E17: 6.09 | F17: 20.24 | G17: 75.29 | H17: 30.15 | I17: 6.41 | J17: 0.38 | K17: 269.45 | L17: 34.22 | M17: 45.22 | N17: 126.9 | O17: 0 | P17: 0.69 | Q17: 6
A18: 06/06/2023 10:00 | B18: 13.31 | C18: 55.51 | D18: 37.17 | E18: 6.86 | F18: 21.87 | G18: 52.25 | H18: 31.47 | I18: 6.06 | J18: 0.46 | K18: 295.64 | L18: 36.99 | M18: 39.28 | N18: 138.8 | O18: 0 | P18: 0.66 | Q18: 5.49
A19: 06/06/2023 11:00 | B19: 8.69 | C19: 52.37 | D19: 32.48 | E19: 10.38 | F19: 37.1 | G19: 39.95 | H19: 36.37 | I19: 6.27 | J19: 0.74 | K19: 332.83 | L19: 38.77 | M19: 30.65 | N19: 163.2 | O19: 0 | P19: 0.68 | Q19: 5.23
A20: 06/06/2023 12:00 | B20: 4.73 | C20: 48.91 | D20: 28.3 | E20: 12.2 | F20: 49.92 | G20: 40.88 | H20: 36.73 | I20: 6.26 | J20: 0.82 | K20: 351.84 | L20: 39.94 | M20: 25.53 | N20: 860.1 | O20: 0 | P20: 0.67 | Q20: 4.97
... A32: 06/06/2023 24:00 | B32: 58.3 | C32: 66.98 | D32: 81.2 | E32: 10.11 | F32: 11.09 | G32: 67.51 | H32: 33.9 | I32: 6.28 | J32: 0.21 | K32: 179.84 | L32: 31.22 | M32: 41 | N32: 0 | O32: 0 | P32: 0.85 | Q32: 5.95
A34: Min | B34: =MIN(B9:B32) -> 2.98 | C34: =MIN(C9:C32) -> 44.57 | D34: =MIN(D9:D32) -> 24.63 | E34: =MIN(E9:E32) -> 6.02 | F34: =MIN(F9:F32) -> 4.11 | G34: =MIN(G9:G32) -> 36.83 | H34: =MIN(H9:H32) -> 20.64 | I34: =MIN(I9:I32) -> 4.5 | ... Q34: =MIN(Q9:Q32) -> 4.83
A35: Max | B35: =MAX(B9:B32) -> 58.3 | C35: =MAX(C9:C32) -> 69.75 | D35: =MAX(D9:D32) -> 81.2 | E35: =MAX(E9:E32) -> 21.27 | F35: =MAX(F9:F32) -> 49.92 | G35: =MAX(G9:G32) -> 78.03 | H35: =MAX(H9:H32) -> 39.95 | I35: =MAX(I9:I32) -> 6.45 | ... Q35: =MAX(Q9:Q32) -> 6.22
A36: Avg | B36: =AVERAGE(B9:B32) -> 15.47875 | C36: =AVERAGE(C9:C32) -> 60.025417 | D36: =AVERAGE(D9:D32) -> 42.40375 | E36: =AVERAGE(E9:E32) -> 10.9225 | F36: =AVERAGE(F9:F32) -> 24.028333 | G36: =AVERAGE(G9:G32) -> 58.065833 | H36: =AVERAGE(H9:H32) -> 31.341667 | I36: =AVERAGE(I9:I32) -> 5.8108333 | ... Q36: =AVERAGE(Q9:Q32) -> 5.5304167
A37: Stdev | B37: =STDEV(B9:B32) -> 11.650797 | C37: =STDEV(C9:C32) -> 6.3892831 | D37: =STDEV(D9:D32) -> 11.667465 | E37: =STDEV(E9:E32) -> 4.9934272 | F37: =STDEV(F9:F32) -> 14.813914 | G37: =STDEV(G9:G32) -> 13.360332 | H37: =STDEV(H9:H32) -> 6.1577937 | I37: =STDEV(I9:I32) -> 0.51319898 | ... Q37: =STDEV(Q9:Q32) -> 0.36313226
A38: Num | B38: =COUNT(B9:B32) -> 24 | C38: =COUNT(C9:C32) -> 24 | D38: =COUNT(D9:D32) -> 24 | E38: =COUNT(E9:E32) -> 24 | F38: =COUNT(F9:F32) -> 24 | G38: =COUNT(G9:G32) -> 24 | H38: =COUNT(H9:H32) -> 24 | I38: =COUNT(I9:I32) -> 24 | ... Q38: =COUNT(Q9:Q32) -> 24
A39: DCR | B39: =IF(B38>=22,">90%",IF(B38<=22,"<90%")) -> >90% | C39: =IF(C38>=22,">90%",IF(C38<=22,"<90%")) -> >90% | D39: =IF(D38>=22,">90%",IF(D38<=22,"<90%")) -> >90% | E39: =IF(E38>=22,">90%",IF(E38<=22,"<90%")) -> >90% | F39: =IF(F38>=22,">90%",IF(F38<=22,"<90%")) -> >90% | G39: =IF(G38>=22,">90%",IF(G38<=22,"<90%")) -> >90% | H39: =IF(H38>=22,">90%",IF(H38<=22,"<90%")) -> >90% | I39: =IF(I38>=22,">90%",IF(I38<=22,"<90%")) -> >90% | ... Q39: =IF(Q38>=22,">90%",IF(Q38<=22,"<90%")) -> >90%
A40: Status | B40: =IF(B38>=22,"OK",IF(B38<=22,"LESS")) -> OK | C40: =IF(C38>=22,"OK",IF(C38<=22,"LESS")) -> OK | D40: =IF(D38>=22,"OK",IF(D38<=22,"LESS")) -> OK | E40: =IF(E38>=22,"OK",IF(E38<=22,"LESS")) -> OK | F40: =IF(F38>=22,"OK",IF(F38<=22,"LESS")) -> OK | G40: =IF(G38>=22,"OK",IF(G38<=22,"LESS")) -> OK | H40: =IF(H38>=22,"OK",IF(H38<=22,"LESS")) -> OK | I40: =IF(I38>=22,"OK",IF(I38<=22,"LESS")) -> OK | ... Q40: =IF(Q38>=22,"OK",IF(Q38<=22,"LESS")) -> OK
A43: Done by | B43: AKASH
A45: Comment

Sheet 07
A1: Station: | B1: IGKV ,RAIPUR
A2: Date: | B2: =$A$9 -> 07/06/2023 01:00 | D2: Power Off | G2: Pw.Off | L2: Link Fail | N2: Link F | P2: Maintenance | R2: Maint.
A3: Report Type: | B3: Mean | D3: Calibration | G3: Calib. | L3: Data Fail | N3: Data F | P3: Invalid | R3: Invalid
A4: Time Base: | B4: 01 Hour | D4: Zero Referrence | G4: Z.Ref | L4: Warm Up | N4: Wm. Up
A7: Date & Time | B7: NO | C7: NO2 | D7: NOX | E7: SO2 | F7: O3 | G7: PM 10 | H7: PM 2.5 | I7: BENZ | J7: WS | K7: WD | L7: TEMP | M7: HUM | N7: SR | O7: RG | P7: CO | Q7: NH3
B8: ug/m3 | C8: ug/m3 | D8: ppb | E8: ug/m3 | F8: ug/m3 | G8: ug/m3 | H8: ug/m3 | I8: ug/m3 | J8: m/sec | K8: deg | L8: degreC | M8: % | N8: w/m2 | O8: mm | P8: mg/m3 | Q8: ug/m3
A9: 07/06/2023 01:00 | B9: 34.56 | C9: 65.7 | D9: 59.79 | E9: 7.98 | F9: 5.4 | G9: 80.2 | H9: 40.84 | I9: 6.55 | J9: 0.31 | K9: 248.92 | L9: 30.12 | M9: 44.43 | N9: 0 | O9: 0 | P9: 0.79 | Q9: 6.29
A10: 07/06/2023 02:00 | B10: 47.3 | C10: 69.09 | D10: 70.21 | E10: 8.67 | F10: 3.99 | G10: 86.18 | H10: 40.84 | I10: 6.81 | J10: 0.29 | K10: 125.24 | L10: 30.25 | M10: 43.12 | N10: 0 | O10: 0 | P10: 0.85 | Q10: 6.67
A11: 07/06/2023 03:00 | B11: 48.82 | C11: 69.02 | D11: 74.17 | E11: 9.83 | F11: 4.06 | G11: 86.18 | H11: 37.26 | I11: 10.4 | J11: 0.36 | K11: 132.82 | L11: 30.19 | M11: 44.42 | N11: 0 | O11: 0 | P11: 0.91 | Q11: 6.94
A12: 07/06/2023 04:00 | B12: 52.39 | C12: 69.36 | D12: 74.87 | E12: 9.76 | F12: 3.95 | G12: 92.91 | H12: 35.98 | I12: 12.87 | J12: 0.21 | K12: 184.64 | L12: 29.77 | M12: 48.9 | N12: 0 | O12: 0 | P12: 0.92 | Q12: 7.1
A13: 07/06/2023 05:00 | B13: 60.17 | C13: 68.8 | D13: 83.15 | E13: 26.24 | F13: 3.82 | G13: 107.59 | H13: 39.41 | I13: 13.47 | J13: 0.55 | K13: 133.67 | L13: 29.43 | M13: 45.42 | N13: 0 | O13: 0 | P13: 1 | Q13: 7.46
A14: 07/06/2023 06:00 | B14: 61.97 | C14: 70.69 | D14: 83.9 | E14: 23.05 | F14: 3.82 | G14: 134.84 | H14: 49.69 | I14: 13.66 | J14: 0.29 | K14: 180.28 | L14: 29.1 | M14: 50.72 | N14: 21.9 | O14: 0 | P14: 1.13 | Q14: 7.76
A15: 07/06/2023 07:00 | B15: 57.97 | C15: 66.85 | D15: 79.01 | E15: 32.19 | F15: 5.75 | G15: 171.49 | H15: 57.02 | I15: 14.87 | J15: 0.42 | K15: 52.84 | L15: 30.82 | M15: 42.48 | N15: 65.2 | O15: 0 | P15: 1.26 | Q15: 7.81
A16: 07/06/2023 08:00 | B16: 53.03 | C16: 68.79 | D16: 74.63 | E16: 28.13 | F16: 13.07 | G16: 200.04 | H16: 74.14 | I16: 15.09 | J16: 1.36 | K16: 58.55 | L16: 34.08 | M16: 37.71 | N16: 98.3 | O16: 0 | P16: 1.23 | Q16: 7.8
A17: 07/06/2023 09:00 | B17: 44.42 | C17: 65.3 | D17: 68.7 | E17: 20.84 | F17: 26.17 | G17: 200.04 | H17: 74.14 | I17: 13.47 | J17: 1.2 | K17: 60.52 | L17: 36.52 | M17: 28.69 | N17: 171.1 | O17: 0 | P17: 1.04 | Q17: 7.53
A18: 07/06/2023 10:00 | B18: 30.44 | C18: 57.94 | D18: 53.19 | E18: 28.05 | F18: 40.1 | G18: 109.65 | H18: 67.44 | I18: 12.26 | J18: 0.92 | K18: 60.58 | L18: 38.66 | M18: 26.24 | N18: 162.5 | O18: 0 | P18: 1.01 | Q18: 6.87
A19: 07/06/2023 11:00 | B19: 19.82 | C19: 64.73 | D19: 44.12 | E19: 28.72 | F19: 50.81 | G19: 109.65 | H19: 60.82 | I19: 10.93 | J19: 0.78 | K19: 71.45 | L19: 40.85 | M19: 22.66 | N19: 190.9 | O19: 0 | P19: 0.94 | Q19: 6.32
A20: 07/06/2023 12:00 | B20: 11.63 | C20: 62.65 | D20: 41.01 | E20: 24.9 | F20: 53.48 | G20: 95.55 | H20: 60.46 | I20: 10.32 | J20: 0.99 | K20: 70.91 | L20: 42.16 | M20: 18.68 | N20: 773.8 | O20: 0 | P20: 0.86 | Q20: 5.9
... A32: 07/06/2023 24:00 | B32: 37.89 | C32: 67.82 | D32: 64.35 | E32: 18.99 | F32: 10.41 | G32: 103.55 | H32: 47.82 | I32: 6.45 | J32: 0.44 | K32: 312.45 | L32: 32.69 | M32: 37.68 | N32: 0 | O32: 0 | P32: 0.87 | Q32: 6.04
A34: Min | B34: =MIN(B9:B32) -> 5.31 | C34: =MIN(C9:C32) -> 52.88 | D34: =MIN(D9:D32) -> 30.84 | E34: =MIN(E9:E32) -> 7.98 | F34: =MIN(F9:F32) -> 3.82 | G34: =MIN(G9:G32) -> 49.85 | H34: =MIN(H9:H32) -> 35.98 | I34: =MIN(I9:I32) -> 5.75 | ... Q34: =MIN(Q9:Q32) -> 5.09
A35: Max | B35: =MAX(B9:B32) -> 61.97 | C35: =MAX(C9:C32) -> 70.69 | D35: =MAX(D9:D32) -> 83.9 | E35: =MAX(E9:E32) -> 74.99 | F35: =MAX(F9:F32) -> 61.77 | G35: =MAX(G9:G32) -> 200.04 | H35: =MAX(H9:H32) -> 74.14 | I35: =MAX(I9:I32) -> 15.09 | ... Q35: =MAX(Q9:Q32) -> 7.81
A36: Avg | B36: =AVERAGE(B9:B32) -> 27.915833 | C36: =AVERAGE(C9:C32) -> 63.234167 | D36: =AVERAGE(D9:D32) -> 53.469583 | E36: =AVERAGE(E9:E32) -> 28.435 | F36: =AVERAGE(F9:F32) -> 28.194167 | G36: =AVERAGE(G9:G32) -> 108.22 | H36: =AVERAGE(H9:H32) -> 50.226667 | I36: =AVERAGE(I9:I32) -> 9.2458333 | ... Q36: =AVERAGE(Q9:Q32) -> 6.2283333
A37: Stdev | B37: =STDEV(B9:B32) -> 20.494297 | C37: =STDEV(C9:C32) -> 5.17388 | D37: =STDEV(D9:D32) -> 18.396306 | E37: =STDEV(E9:E32) -> 17.396022 | F37: =STDEV(F9:F32) -> 21.842079 | G37: =STDEV(G9:G32) -> 36.419959 | H37: =STDEV(H9:H32) -> 10.61626 | I37: =STDEV(I9:I32) -> 3.2723996 | ... Q37: =STDEV(Q9:Q32) -> 0.9606595
A38: Num | B38: =COUNT(B9:B32) -> 24 | C38: =COUNT(C9:C32) -> 24 | D38: =COUNT(D9:D32) -> 24 | E38: =COUNT(E9:E32) -> 24 | F38: =COUNT(F9:F32) -> 24 | G38: =COUNT(G9:G32) -> 24 | H38: =COUNT(H9:H32) -> 24 | I38: =COUNT(I9:I32) -> 24 | ... Q38: =COUNT(Q9:Q32) -> 24
A39: DCR | B39: =IF(B38>=22,">90%",IF(B38<=22,"<90%")) -> >90% | C39: =IF(C38>=22,">90%",IF(C38<=22,"<90%")) -> >90% | D39: =IF(D38>=22,">90%",IF(D38<=22,"<90%")) -> >90% | E39: =IF(E38>=22,">90%",IF(E38<=22,"<90%")) -> >90% | F39: =IF(F38>=22,">90%",IF(F38<=22,"<90%")) -> >90% | G39: =IF(G38>=22,">90%",IF(G38<=22,"<90%")) -> >90% | H39: =IF(H38>=22,">90%",IF(H38<=22,"<90%")) -> >90% | I39: =IF(I38>=22,">90%",IF(I38<=22,"<90%")) -> >90% | ... Q39: =IF(Q38>=22,">90%",IF(Q38<=22,"<90%")) -> >90%
A40: Status | B40: =IF(B38>=22,"OK",IF(B38<=22,"LESS")) -> OK | C40: =IF(C38>=22,"OK",IF(C38<=22,"LESS")) -> OK | D40: =IF(D38>=22,"OK",IF(D38<=22,"LESS")) -> OK | E40: =IF(E38>=22,"OK",IF(E38<=22,"LESS")) -> OK | F40: =IF(F38>=22,"OK",IF(F38<=22,"LESS")) -> OK | G40: =IF(G38>=22,"OK",IF(G38<=22,"LESS")) -> OK | H40: =IF(H38>=22,"OK",IF(H38<=22,"LESS")) -> OK | I40: =IF(I38>=22,"OK",IF(I38<=22,"LESS")) -> OK | ... Q40: =IF(Q38>=22,"OK",IF(Q38<=22,"LESS")) -> OK
A43: Done by | B43: AKASH
A45: Comment

Sheet 08
A1: Station: | B1: IGKV ,RAIPUR
A2: Date: | B2: =$A$9 -> 08/06/2023 01:00 | D2: Power Off | G2: Pw.Off | L2: Link Fail | N2: Link F | P2: Maintenance | R2: Maint.
A3: Report Type: | B3: Mean | D3: Calibration | G3: Calib. | L3: Data Fail | N3: Data F | P3: Invalid | R3: Invalid
A4: Time Base: | B4: 01 Hour | D4: Zero Referrence | G4: Z.Ref | L4: Warm Up | N4: Wm. Up
A7: Date & Time | B7: NO | C7: NO2 | D7: NOX | E7: SO2 | F7: O3 | G7: PM 10 | H7: PM 2.5 | I7: BENZ | J7: WS | K7: WD | L7: TEMP | M7: HUM | N7: SR | O7: RG | P7: CO | Q7: NH3
B8: ug/m3 | C8: ug/m3 | D8: ppb | E8: ug/m3 | F8: ug/m3 | G8: ug/m3 | H8: ug/m3 | I8: ug/m3 | J8: m/sec | K8: deg | L8: degreC | M8: % | N8: w/m2 | O8: mm | P8: mg/m3 | Q8: ug/m3
A9: 08/06/2023 01:00 | B9: 18.02 | C9: 62.69 | D9: 46.16 | E9: 31.18 | F9: 15.79 | G9: 97.74 | H9: 47.82 | I9: 7.49 | J9: 0.27 | K9: 219.04 | L9: 31.9 | M9: 43 | N9: 0 | O9: 0 | P9: 0.84 | Q9: 6.05
A10: 08/06/2023 02:00 | B10: 19.63 | C10: 63.12 | D10: 47.68 | E10: 16.76 | F10: 9.75 | G10: 93.2 | H10: 41.08 | I10: 7.47 | J10: 0.21 | K10: 213.08 | L10: 30.56 | M10: 45.26 | N10: 0 | O10: 0 | P10: 0.85 | Q10: 6.04
A11: 08/06/2023 03:00 | B11: 19.6 | C11: 57.49 | D11: 44.64 | E11: 10.37 | F11: 10.25 | G11: 92.94 | H11: 39.65 | I11: 7.09 | J11: 0.2 | K11: 186.33 | L11: 29.88 | M11: 47.15 | N11: 0 | O11: 0 | P11: 0.78 | Q11: 5.99
A12: 08/06/2023 04:00 | B12: 22.49 | C12: 62.72 | D12: 49.76 | E12: 9.58 | F12: 9.58 | G12: 80.18 | H12: 36.61 | I12: 6.95 | J12: 0.27 | K12: 254.81 | L12: 29.06 | M12: 49.72 | N12: 0 | O12: 0 | P12: 0.79 | Q12: 6
A13: 08/06/2023 05:00 | B13: 22.4 | C13: 60.4 | D13: 48.47 | E13: 7.65 | F13: 7.17 | G13: 61.28 | H13: 32.91 | I13: 7.06 | J13: 0.2 | K13: 216.55 | L13: 28.33 | M13: 51.29 | N13: 0 | O13: 0 | P13: 0.77 | Q13: 6.02
A14: 08/06/2023 06:00 | B14: 24.34 | C14: 62.17 | D14: 50.18 | E14: 6.96 | F14: 5.6 | G14: 58.93 | H14: 30.24 | I14: 7.34 | J14: 0.2 | K14: 192.52 | L14: 27.98 | M14: 54.71 | N14: 20.8 | O14: 0 | P14: 0.78 | Q14: 6.06
A15: 08/06/2023 07:00 | B15: 26.3 | C15: 60.61 | D15: 51.05 | E15: 7.81 | F15: 7.74 | G15: 65.17 | H15: 29.69 | I15: 7.78 | J15: 0.27 | K15: 215.21 | L15: 31.05 | M15: 53 | N15: 68.9 | O15: 0 | P15: 0.82 | Q15: 6.14
A16: 08/06/2023 08:00 | B16: 24.62 | C16: 60.51 | D16: 50.31 | E16: 34.2 | F16: 11.84 | G16: 85.53 | H16: 31.74 | I16: 8.73 | J16: 0.95 | K16: 324.34 | L16: 33.78 | M16: 44.02 | N16: 106.5 | O16: 0 | P16: 0.87 | Q16: 6.17
A17: 08/06/2023 09:00 | B17: 23.51 | C17: 64.2 | D17: 51.35 | E17: 22.02 | F17: 20.41 | G17: 96.95 | H17: 39.13 | I17: 8.72 | J17: 0.98 | K17: 331.1 | L17: 36.25 | M17: 32.9 | N17: 130 | O17: 0 | P17: 0.83 | Q17: 6.15
A18: 08/06/2023 10:00 | B18: 16.61 | C18: 52.45 | D18: 39.67 | E18: 20.3 | F18: 33.44 | G18: 96.95 | H18: 40 | I18: 8.17 | J18: 0.81 | K18: 346.44 | L18: 38.43 | M18: 26.37 | N18: 159 | O18: 0 | P18: 0.78 | Q18: 5.81
A19: 08/06/2023 11:00 | B19: 10.92 | C19: 59.96 | D19: 36.95 | E19: 33.59 | F19: 39.77 | G19: 91.22 | H19: 40 | I19: 7.41 | J19: 0.79 | K19: 348.29 | L19: 40.32 | M19: 21.38 | N19: 184.9 | O19: 0 | P19: 0.72 | Q19: 5.48
A20: 08/06/2023 12:00 | B20: 7.58 | C20: 59.98 | D20: 36.37 | E20: 22.26 | F20: 50.38 | G20: 76.45 | H20: 41.45 | I20: 7.06 | J20: 1.32 | K20: 49.51 | L20: 41.12 | M20: 18.43 | N20: 744.4 | O20: 0 | P20: 0.7 | Q20: 5.54
... A32: 08/06/2023 24:00 | B32: 41.82 | C32: 65.77 | D32: 66.85 | E32: 8 | F32: 3.99 | G32: 105.93 | H32: 40.68 | I32: 11.21 | J32: 0.24 | K32: 190.43 | L32: 32.13 | M32: 43.65 | N32: 0 | O32: 0 | P32: 1.2 | Q32: 6.14
A34: Min | B34: =MIN(B9:B32) -> 4.23 | C34: =MIN(C9:C32) -> 44.84 | D34: =MIN(D9:D32) -> 28.79 | E34: =MIN(E9:E32) -> 6.96 | F34: =MIN(F9:F32) -> 3.99 | G34: =MIN(G9:G32) -> 58.14 | H34: =MIN(H9:H32) -> 29.69 | I34: =MIN(I9:I32) -> 5.01 | ... Q34: =MIN(Q9:Q32) -> 5.21
A35: Max | B35: =MAX(B9:B32) -> 45.3 | C35: =MAX(C9:C32) -> 68.79 | D35: =MAX(D9:D32) -> 69.48 | E35: =MAX(E9:E32) -> 34.2 | F35: =MAX(F9:F32) -> 55.52 | G35: =MAX(G9:G32) -> 105.93 | H35: =MAX(H9:H32) -> 47.82 | I35: =MAX(I9:I32) -> 12.03 | ... Q35: =MAX(Q9:Q32) -> 6.17
A36: Avg | B36: =AVERAGE(B9:B32) -> 16.595417 | C36: =AVERAGE(C9:C32) -> 61.141667 | D36: =AVERAGE(D9:D32) -> 44.009583 | E36: =AVERAGE(E9:E32) -> 17.600417 | F36: =AVERAGE(F9:F32) -> 27.539583 | G36: =AVERAGE(G9:G32) -> 81.588333 | H36: =AVERAGE(H9:H32) -> 37.320833 | I36: =AVERAGE(I9:I32) -> 7.5125 | ... Q36: =AVERAGE(Q9:Q32) -> 5.735
A37: Stdev | B37: =STDEV(B9:B32) -> 11.154168 | C37: =STDEV(C9:C32) -> 5.0382413 | D37: =STDEV(D9:D32) -> 10.044191 | E37: =STDEV(E9:E32) -> 8.1256002 | F37: =STDEV(F9:F32) -> 17.990509 | G37: =STDEV(G9:G32) -> 15.433888 | H37: =STDEV(H9:H32) -> 4.2005434 | I37: =STDEV(I9:I32) -> 1.6861643 | ... Q37: =STDEV(Q9:Q32) -> 0.31663997
A38: Num | B38: =COUNT(B9:B32) -> 24 | C38: =COUNT(C9:C32) -> 24 | D38: =COUNT(D9:D32) -> 24 | E38: =COUNT(E9:E32) -> 24 | F38: =COUNT(F9:F32) -> 24 | G38: =COUNT(G9:G32) -> 24 | H38: =COUNT(H9:H32) -> 24 | I38: =COUNT(I9:I32) -> 24 | ... Q38: =COUNT(Q9:Q32) -> 24
A39: DCR | B39: =IF(B38>=22,">90%",IF(B38<=22,"<90%")) -> >90% | C39: =IF(C38>=22,">90%",IF(C38<=22,"<90%")) -> >90% | D39: =IF(D38>=22,">90%",IF(D38<=22,"<90%")) -> >90% | E39: =IF(E38>=22,">90%",IF(E38<=22,"<90%")) -> >90% | F39: =IF(F38>=22,">90%",IF(F38<=22,"<90%")) -> >90% | G39: =IF(G38>=22,">90%",IF(G38<=22,"<90%")) -> >90% | H39: =IF(H38>=22,">90%",IF(H38<=22,"<90%")) -> >90% | I39: =IF(I38>=22,">90%",IF(I38<=22,"<90%")) -> >90% | ... Q39: =IF(Q38>=22,">90%",IF(Q38<=22,"<90%")) -> >90%
A40: Status | B40: =IF(B38>=22,"OK",IF(B38<=22,"LESS")) -> OK | C40: =IF(C38>=22,"OK",IF(C38<=22,"LESS")) -> OK | D40: =IF(D38>=22,"OK",IF(D38<=22,"LESS")) -> OK | E40: =IF(E38>=22,"OK",IF(E38<=22,"LESS")) -> OK | F40: =IF(F38>=22,"OK",IF(F38<=22,"LESS")) -> OK | G40: =IF(G38>=22,"OK",IF(G38<=22,"LESS")) -> OK | H40: =IF(H38>=22,"OK",IF(H38<=22,"LESS")) -> OK | I40: =IF(I38>=22,"OK",IF(I38<=22,"LESS")) -> OK | ... Q40: =IF(Q38>=22,"OK",IF(Q38<=22,"LESS")) -> OK
A43: Done by | B43: AKASH
A45: Comment

Sheet 09
A1: Station: | B1: IGKV ,RAIPUR
A2: Date: | B2: =$A$9 -> 09/06/2023 01:00 | D2: Power Off | G2: Pw.Off | L2: Link Fail | N2: Link F | P2: Maintenance | R2: Maint.
A3: Report Type: | B3: Mean | D3: Calibration | G3: Calib. | L3: Data Fail | N3: Data F | P3: Invalid | R3: Invalid
A4: Time Base: | B4: 01 Hour | D4: Zero Referrence | G4: Z.Ref | L4: Warm Up | N4: Wm. Up
A7: Date & Time | B7: NO | C7: NO2 | D7: NOX | E7: SO2 | F7: O3 | G7: PM 10 | H7: PM 2.5 | I7: BENZ | J7: WS | K7: WD | L7: TEMP | M7: HUM | N7: SR | O7: RG | P7: CO | Q7: NH3
B8: ug/m3 | C8: ug/m3 | D8: ppb | E8: ug/m3 | F8: ug/m3 | G8: ug/m3 | H8: ug/m3 | I8: ug/m3 | J8: m/sec | K8: deg | L8: degreC | M8: % | N8: w/m2 | O8: mm | P8: mg/m3 | Q8: ug/m3
A9: 09/06/2023 01:00 | B9: 38.19 | C9: 63.84 | D9: 62.93 | E9: 6.87 | F9: 3.95 | G9: 105.93 | H9: 40.68 | I9: 10.95 | J9: 0.25 | K9: 225.59 | L9: 30.75 | M9: 45.27 | N9: 0 | O9: 0 | P9: 1.1 | Q9: 6.35
A10: 09/06/2023 02:00 | B10: 30.76 | C10: 60.92 | D10: 55.28 | E10: 5.37 | F10: 3.99 | G10: 105.78 | H10: 39.83 | I10: 10.91 | J10: 0.19 | K10: 214.12 | L10: 29.91 | M10: 47.32 | N10: 0 | O10: 0 | P10: 1.15 | Q10: 6.42
A11: 09/06/2023 03:00 | B11: 30.21 | C11: 61.73 | D11: 55.34 | E11: 6.6 | F11: 3.85 | G11: 103.32 | H11: 38.55 | I11: 11.26 | J11: 0.19 | K11: 189.09 | L11: 29.3 | M11: 50.57 | N11: 0 | O11: 0 | P11: 1.18 | Q11: 6.47
A12: 09/06/2023 04:00 | B12: 31.77 | C12: 61.57 | D12: 56.4 | E12: 6.3 | F12: 3.94 | G12: 101.88 | H12: 36.05 | I12: 11.33 | J12: 0.2 | K12: 194.84 | L12: 28.38 | M12: 52.71 | N12: 0 | O12: 0 | P12: 1.16 | Q12: 6.49
A13: 09/06/2023 05:00 | B13: 40.22 | C13: 62.44 | D13: 63.34 | E13: 25.69 | F13: 4.23 | G13: 95.58 | H13: 36.05 | I13: 11.36 | J13: 0.39 | K13: 310.48 | L13: 29.43 | M13: 53.29 | N13: 0 | O13: 0 | P13: 1.16 | Q13: 6.6
A14: 09/06/2023 06:00 | B14: 42.72 | C14: 63.67 | D14: 66.4 | E14: 19.55 | F14: 5.59 | G14: 103.93 | H14: 39.19 | I14: 11.02 | J14: 0.46 | K14: 68.42 | L14: 29.7 | M14: 30.94 | N14: 30.9 | O14: 0 | P14: 1.11 | Q14: 6.71
A15: 09/06/2023 07:00 | B15: 45.24 | C15: 66.57 | D15: 70.02 | E15: 45.75 | F15: 9.82 | G15: 115.41 | H15: 43.97 | I15: 11.17 | J15: 0.33 | K15: 57.3 | L15: 32.13 | M15: 30.85 | N15: 99.6 | O15: 0 | P15: 1.14 | Q15: 6.93
A16: 09/06/2023 08:00 | B16: 37.87 | C16: 66.02 | D16: 63.81 | E16: 68.89 | F16: 14.14 | G16: 136.69 | H16: 52.63 | I16: 10.76 | J16: 0.39 | K16: 322.36 | L16: 35.42 | M16: 26.23 | N16: 133.2 | O16: 0 | P16: 1.13 | Q16: 6.93
A17: 09/06/2023 09:00 | B17: 31.97 | C17: 62.83 | D17: 56.27 | E17: 63.58 | F17: 22 | G17: 169.35 | H17: 64.59 | I17: 10.52 | J17: 1.11 | K17: 346.39 | L17: 37.02 | M17: 25.01 | N17: 145.6 | O17: 0 | P17: 1.03 | Q17: 6.86
A18: 09/06/2023 10:00 | B18: 21.88 | C18: 62.29 | D18: 47.3 | E18: 32.07 | F18: 37.47 | G18: 169.35 | H18: 64.59 | I18: 9.45 | J18: 0.79 | K18: 31.01 | L18: 39.9 | M18: 21.57 | N18: 151.8 | O18: 0 | P18: 0.91 | Q18: 6.48
A19: 09/06/2023 11:00 | B19: 16.51 | C19: 62.31 | D19: 44.41 | E19: 41.97 | F19: 42.08 | G19: 94.28 | H19: 49.93 | I19: 8.03 | J19: 0.63 | K19: 340.56 | L19: 41.49 | M19: 14.32 | N19: 179.4 | O19: 0 | P19: 0.86 | Q19: 6.1
A20: 09/06/2023 12:00 | B20: 9.9 | C20: 60.68 | D20: 37.16 | E20: 49.73 | F20: 48.74 | G20: 94.28 | H20: 47.09 | I20: 7.13 | J20: 1.14 | K20: 312.29 | L20: 42.37 | M20: 14.25 | N20: 747.6 | O20: 0 | P20: 0.76 | Q20: 5.76
... A32: 09/06/2023 24:00 | B32: 40.67 | C32: 66.55 | D32: 66.01 | E32: 9.55 | F32: 4.52 | G32: 68.98 | H32: 25.34 | I32: 9.32 | J32: 0.26 | K32: 328.47 | L32: 32.8 | M32: 43.52 | N32: 0 | O32: 0 | P32: 0.92 | Q32: 6.01
A34: Min | B34: =MIN(B9:B32) -> 5.75 | C34: =MIN(C9:C32) -> 40.71 | D34: =MIN(D9:D32) -> 24.71 | E34: =MIN(E9:E32) -> 5.37 | F34: =MIN(F9:F32) -> 3.85 | G34: =MIN(G9:G32) -> 47.85 | H34: =MIN(H9:H32) -> 25.34 | I34: =MIN(I9:I32) -> 4.05 | ... Q34: =MIN(Q9:Q32) -> 5.15
A35: Max | B35: =MAX(B9:B32) -> 45.24 | C35: =MAX(C9:C32) -> 66.57 | D35: =MAX(D9:D32) -> 70.02 | E35: =MAX(E9:E32) -> 68.89 | F35: =MAX(F9:F32) -> 50.51 | G35: =MAX(G9:G32) -> 169.35 | H35: =MAX(H9:H32) -> 64.59 | I35: =MAX(I9:I32) -> 11.36 | ... Q35: =MAX(Q9:Q32) -> 6.93
A36: Avg | B36: =AVERAGE(B9:B32) -> 22.249167 | C36: =AVERAGE(C9:C32) -> 59.379167 | D36: =AVERAGE(D9:D32) -> 47.471667 | E36: =AVERAGE(E9:E32) -> 20.4625 | F36: =AVERAGE(F9:F32) -> 23.714583 | G36: =AVERAGE(G9:G32) -> 91.31 | H36: =AVERAGE(H9:H32) -> 38.417083 | I36: =AVERAGE(I9:I32) -> 8.2466667 | ... Q36: =AVERAGE(Q9:Q32) -> 5.9475
A37: Stdev | B37: =STDEV(B9:B32) -> 14.21037 | C37: =STDEV(C9:C32) -> 6.6633775 | D37: =STDEV(D9:D32) -> 14.054576 | E37: =STDEV(E9:E32) -> 19.260079 | F37: =STDEV(F9:F32) -> 16.313867 | G37: =STDEV(G9:G32) -> 33.546577 | H37: =STDEV(H9:H32) -> 11.158278 | I37: =STDEV(I9:I32) -> 2.5237044 | ... Q37: =STDEV(Q9:Q32) -> 0.63963475
A38: Num | B38: =COUNT(B9:B32) -> 24 | C38: =COUNT(C9:C32) -> 24 | D38: =COUNT(D9:D32) -> 24 | E38: =COUNT(E9:E32) -> 24 | F38: =COUNT(F9:F32) -> 24 | G38: =COUNT(G9:G32) -> 24 | H38: =COUNT(H9:H32) -> 24 | I38: =COUNT(I9:I32) -> 24 | ... Q38: =COUNT(Q9:Q32) -> 24
A39: DCR | B39: =IF(B38>=22,">90%",IF(B38<=22,"<90%")) -> >90% | C39: =IF(C38>=22,">90%",IF(C38<=22,"<90%")) -> >90% | D39: =IF(D38>=22,">90%",IF(D38<=22,"<90%")) -> >90% | E39: =IF(E38>=22,">90%",IF(E38<=22,"<90%")) -> >90% | F39: =IF(F38>=22,">90%",IF(F38<=22,"<90%")) -> >90% | G39: =IF(G38>=22,">90%",IF(G38<=22,"<90%")) -> >90% | H39: =IF(H38>=22,">90%",IF(H38<=22,"<90%")) -> >90% | I39: =IF(I38>=22,">90%",IF(I38<=22,"<90%")) -> >90% | ... Q39: =IF(Q38>=22,">90%",IF(Q38<=22,"<90%")) -> >90%
A40: Status | B40: =IF(B38>=22,"OK",IF(B38<=22,"LESS")) -> OK | C40: =IF(C38>=22,"OK",IF(C38<=22,"LESS")) -> OK | D40: =IF(D38>=22,"OK",IF(D38<=22,"LESS")) -> OK | E40: =IF(E38>=22,"OK",IF(E38<=22,"LESS")) -> OK | F40: =IF(F38>=22,"OK",IF(F38<=22,"LESS")) -> OK | G40: =IF(G38>=22,"OK",IF(G38<=22,"LESS")) -> OK | H40: =IF(H38>=22,"OK",IF(H38<=22,"LESS")) -> OK | I40: =IF(I38>=22,"OK",IF(I38<=22,"LESS")) -> OK | ... Q40: =IF(Q38>=22,"OK",IF(Q38<=22,"LESS")) -> OK
A43: Done by | B43: AKASH
A45: Comment

Sheet 10
A1: Station: | B1: IGKV ,RAIPUR
A2: Date: | B2: =$A$9 -> 10/06/2023 01:00 | D2: Power Off | G2: Pw.Off | L2: Link Fail | N2: Link F | P2: Maintenance | R2: Maint.
A3: Report Type: | B3: Mean | D3: Calibration | G3: Calib. | L3: Data Fail | N3: Data F | P3: Invalid | R3: Invalid
A4: Time Base: | B4: 01 Hour | D4: Zero Referrence | G4: Z.Ref | L4: Warm Up | N4: Wm. Up
A7: Date & Time | B7: NO | C7: NO2 | D7: NOX | E7: SO2 | F7: O3 | G7: PM 10 | H7: PM 2.5 | I7: BENZ | J7: WS | K7: WD | L7: TEMP | M7: HUM | N7: SR | O7: RG | P7: CO | Q7: NH3
B8: ug/m3 | C8: ug/m3 | D8: ppb | E8: ug/m3 | F8: ug/m3 | G8: ug/m3 | H8: ug/m3 | I8: ug/m3 | J8: m/sec | K8: deg | L8: degreC | M8: % | N8: w/m2 | O8: mm | P8: mg/m3 | Q8: ug/m3
A9: 10/06/2023 01:00 | B9: 43.55 | C9: 61.99 | D9: 66.27 | E9: 17.81 | F9: 4.14 | G9: 85.65 | H9: 26.6 | I9: 9.43 | J9: 0.23 | K9: 222.12 | L9: 32.28 | M9: 45.5 | N9: 0 | O9: 0 | P9: 0.88 | Q9: 6.31
A10: 10/06/2023 02:00 | B10: 38.95 | C10: 61.73 | D10: 62.44 | E10: 22.81 | F10: 7.04 | G10: 85.65 | H10: 29.35 | I10: 9.62 | J10: 0.4 | K10: 248.98 | L10: 32.31 | M10: 39.61 | N10: 0 | O10: 0 | P10: 0.79 | Q10: 6.55
A11: 10/06/2023 03:00 | B11: 27.08 | C11: 59.61 | D11: 51.81 | E11: 24.48 | F11: 13.12 | G11: 85.06 | H11: 29.36 | I11: 7.96 | J11: 0.53 | K11: 274.9 | L11: 32.56 | M11: 40.42 | N11: 0 | O11: 0 | P11: 0.78 | Q11: 6.51
A12: 10/06/2023 04:00 | B12: 23.96 | C12: 57.3 | D12: 47.11 | E12: 38.91 | F12: 12.71 | G12: 67.89 | H12: 29.36 | I12: 6.97 | J12: 0.37 | K12: 286.06 | L12: 32.74 | M12: 35.23 | N12: 0 | O12: 0 | P12: 0.66 | Q12: 6.39
A13: 10/06/2023 05:00 | B13: 21.5 | C13: 53.75 | D13: 43.91 | E13: 36.8 | F13: 9.18 | G13: 61.09 | H13: 28.67 | I13: 6.6 | J13: 0.24 | K13: 184.21 | L13: 31.9 | M13: 46.16 | N13: 0 | O13: 0 | P13: 0.65 | Q13: 6.32
A14: 10/06/2023 06:00 | B14: 33.12 | C14: 58.85 | D14: 56.21 | E14: 21.14 | F14: 7.16 | G14: 58.46 | H14: 28.62 | I14: 6.58 | J14: 0.42 | K14: 259.49 | L14: 31.39 | M14: 45.25 | N14: 12.5 | O14: 0 | P14: 0.65 | Q14: 6.34
A15: 10/06/2023 07:00 | B15: 31.35 | C15: 57.26 | D15: 54.01 | E15: 13.87 | F15: 10.12 | G15: 63.73 | H15: 26.13 | I15: 6.89 | J15: 0.25 | K15: 199.73 | L15: 31.79 | M15: 47.3 | N15: 36.6 | O15: 0 | P15: 0.73 | Q15: 6.33
A16: 10/06/2023 08:00 | B16: 28.49 | C16: 58.56 | D16: 52.4 | E16: 15.6 | F16: 13.9 | G16: 70.73 | H16: 29.7 | I16: 7.97 | J16: 0.27 | K16: 228.01 | L16: 33.37 | M16: 52.08 | N16: 150.3 | O16: 0 | P16: 0.73 | Q16: 6.38
A17: 10/06/2023 09:00 | B17: 26.5 | C17: 58.24 | D17: 50.63 | E17: 13.62 | F17: 13.09 | G17: 70.73 | H17: 29.7 | I17: 8.11 | J17: 0.62 | K17: 268.32 | L17: 33.96 | M17: 44.34 | N17: 139 | O17: 0 | P17: 0.89 | Q17: 6.26
A18: 10/06/2023 10:00 | B18: 18.9 | C18: 53.81 | D18: 42.23 | E18: 20.57 | F18: 25.76 | G18: 83.34 | H18: 33.65 | I18: 12.45 | J18: 0.34 | K18: 253.29 | L18: 35.2 | M18: 43.15 | N18: 258.6 | O18: 0 | P18: 1 | Q18: 6.15
A19: 10/06/2023 11:00 | B19: 13.24 | C19: 56.89 | D19: 39.18 | E19: 13.39 | F19: 37.31 | G19: 85.96 | H19: 35.34 | I19: 11.46 | J19: 0.64 | K19: 274.22 | L19: 39.54 | M19: 32.17 | N19: 236.6 | O19: 0 | P19: 0.93 | Q19: 5.89
A20: 10/06/2023 12:00 | B20: 8 | C20: 58.35 | D20: 35.3 | E20: 9.78 | F20: 33.09 | G20: 85.96 | H20: 35.34 | I20: 10.09 | J20: 1.5 | K20: 295.67 | L20: 40.31 | M20: 24.49 | N20: 404 | O20: 0 | P20: 0.83 | Q20: 5.5
... A32: 10/06/2023 24:00 | B32: 8.55 | C32: 53.62 | D32: 33.83 | E32: 8 | F32: 23.53 | G32: 65.68 | H32: 26.55 | I32: 5.42 | J32: 0.94 | K32: 262.24 | L32: 32.95 | M32: 38.35 | N32: 0 | O32: 0 | P32: 0.64 | Q32: 5.22
A34: Min | B34: =MIN(B9:B32) -> 4.79 | C34: =MIN(C9:C32) -> 44.39 | D34: =MIN(D9:D32) -> 25.99 | E34: =MIN(E9:E32) -> 7.6 | F34: =MIN(F9:F32) -> 4.14 | G34: =MIN(G9:G32) -> 52.18 | H34: =MIN(H9:H32) -> 25.46 | I34: =MIN(I9:I32) -> 5.42 | ... Q34: =MIN(Q9:Q32) -> 4.95
A35: Max | B35: =MAX(B9:B32) -> 43.55 | C35: =MAX(C9:C32) -> 62.17 | D35: =MAX(D9:D32) -> 66.27 | E35: =MAX(E9:E32) -> 38.91 | F35: =MAX(F9:F32) -> 52.96 | G35: =MAX(G9:G32) -> 85.96 | H35: =MAX(H9:H32) -> 35.34 | I35: =MAX(I9:I32) -> 12.45 | ... Q35: =MAX(Q9:Q32) -> 6.55
A36: Avg | B36: =AVERAGE(B9:B32) -> 17.698333 | C36: =AVERAGE(C9:C32) -> 55.057917 | D36: =AVERAGE(D9:D32) -> 41.782917 | E36: =AVERAGE(E9:E32) -> 16.862917 | F36: =AVERAGE(F9:F32) -> 24.282917 | G36: =AVERAGE(G9:G32) -> 71.055 | H36: =AVERAGE(H9:H32) -> 30.159167 | I36: =AVERAGE(I9:I32) -> 7.8608333 | ... Q36: =AVERAGE(Q9:Q32) -> 5.70625
A37: Stdev | B37: =STDEV(B9:B32) -> 11.798865 | C37: =STDEV(C9:C32) -> 5.0542208 | D37: =STDEV(D9:D32) -> 11.611493 | E37: =STDEV(E9:E32) -> 8.8342025 | F37: =STDEV(F9:F32) -> 14.235075 | G37: =STDEV(G9:G32) -> 12.109452 | H37: =STDEV(H9:H32) -> 3.1665575 | I37: =STDEV(I9:I32) -> 1.8623546 | ... Q37: =STDEV(Q9:Q32) -> 0.5963134
A38: Num | B38: =COUNT(B9:B32) -> 24 | C38: =COUNT(C9:C32) -> 24 | D38: =COUNT(D9:D32) -> 24 | E38: =COUNT(E9:E32) -> 24 | F38: =COUNT(F9:F32) -> 24 | G38: =COUNT(G9:G32) -> 24 | H38: =COUNT(H9:H32) -> 24 | I38: =COUNT(I9:I32) -> 24 | ... Q38: =COUNT(Q9:Q32) -> 24
