Workbook

Sheet 01
A1: Station: | B1: IGKV ,RAIPUR
A2: Date: | B2: =$A$9 -> 45505.042 | D2: Power Off | G2: Pw.Off | L2: Link Fail | N2: Link F | P2: Maintenance | R2: Maint.
A3: Report Type: | B3: Mean | D3: Calibration | G3: Calib. | L3: Data Fail | N3: Data F | P3: Invalid | R3: Invalid
A4: Time Base: | B4: 01 Hour | D4: Zero Referrence | G4: Z.Ref | L4: Warm Up | N4: Wm. Up
A7: Date & Time | B7: NO | C7: NO2 | D7: NOX | E7: SO2 | F7: O3 | G7: PM 10 | H7: PM 2.5 | I7: BENZ | J7: WS | K7: WD | L7: TEMP | M7: HUM | N7: SR | O7: RG | P7: CO | Q7: NH3
B8: ug/m3 | C8: ug/m3 | D8: ppb | E8: ug/m3 | F8: ug/m3 | G8: ug/m3 | H8: ug/m3 | I8: ug/m3 | J8: m/sec | K8: deg | L8: degreC | M8: % | N8: w/m2 | O8: mm | P8: mg/m3 | Q8: ug/m3
A9: 45505.042 | B9: 9.23 | C9: 4.17 | D9: 14 | E9: 11.79 | F9: 4.44 | G9: 24.01 | H9: 10.42 | I9: 4.19 | J9: 0.79 | K9: 280.75 | L9: 25.28 | M9: 109.33 | N9: 2.9 | O9: 0 | P9: 0.4 | Q9: 4.68
A10: 45505.083 | B10: 9.2 | C10: 4.17 | D10: 14 | E10: 11.42 | F10: 4.24 | G10: 24.01 | H10: 10.42 | I10: 4.12 | J10: 0.8 | K10: 279.59 | L10: 24.8 | M10: 105.58 | N10: 3.5 | O10: 0.2 | P10: 0.38 | Q10: 4.66
A11: 45505.125 | B11: 9.21 | C11: 4.19 | D11: 14 | E11: 10.7 | F11: 4.52 | G11: 19.83 | H11: 10.09 | I11: 4 | J11: 0.44 | K11: 276.88 | L11: 24.77 | M11: 102.91 | N11: 2.5 | O11: 0 | P11: 0.36 | Q11: 4.68
A12: 45505.167 | B12: 9.18 | C12: 4.22 | D12: 14 | E12: 10.52 | F12: 4.55 | G12: 13.99 | H12: 7.43 | I12: 3.84 | J12: 0.24 | K12: 270.05 | L12: 24.95 | M12: 102.62 | N12: 2.5 | O12: 0 | P12: 0.33 | Q12: 4.67
A13: 45505.208 | B13: 9.15 | C13: 4.28 | D13: 14 | E13: 11.12 | F13: 4.9 | G13: 11.36 | H13: 5.93 | I13: 3.76 | J13: 0.26 | K13: 271.12 | L13: 25.12 | M13: 103.78 | N13: 2.5 | O13: 0 | P13: 0.28 | Q13: 4.68
A14: 45505.25 | B14: 9.15 | C14: 4.27 | D14: 14 | E14: 11.62 | F14: 4.22 | G14: 10.95 | H14: 4.95 | I14: 3.51 | J14: 0.36 | K14: 278.55 | L14: 25.22 | M14: 104.36 | N14: 13.1 | O14: 0.4 | P14: 0.26 | Q14: 4.68
A15: 45505.292 | B15: 9.18 | C15: 4.2 | D15: 14 | E15: 12.16 | F15: 4.65 | G15: 10.95 | H15: 4.34 | I15: 3.55 | J15: 0.64 | K15: 277.09 | L15: 25.52 | M15: 102.78 | N15: 44.8 | O15: 0.2 | P15: 0.25 | Q15: 4.67
A16: 45505.333 | B16: 9.2 | C16: 4.19 | D16: 14 | E16: 12.68 | F16: 3.75 | G16: 18.87 | H16: 3.39 | I16: 3.33 | J16: 0.81 | K16: 278.91 | L16: 25.77 | M16: 99.16 | N16: 95.5 | O16: 0 | P16: 0.25 | Q16: 4.67
A17: 45505.375 | B17: 9.2 | C17: 4.17 | D17: 14 | E17: 13.3 | F17: 4.13 | G17: 21.65 | H17: 3.31 | I17: 3.23 | J17: 0.95 | K17: 280.56 | L17: 25.99 | M17: 97.31 | N17: 137.9 | O17: 0 | P17: 0.28 | Q17: 4.67
A18: 45505.417 | B18: 9.18 | C18: 4.23 | D18: 14 | E18: 13.06 | F18: 6.15 | G18: 21.65 | H18: 4.84 | I18: 3.2 | J18: 0.98 | K18: 284.4 | L18: 26.16 | M18: 97.48 | N18: 109.6 | O18: 0 | P18: 0.29 | Q18: 4.67
A19: 45505.458 | B19: 9.17 | C19: 4.23 | D19: 14 | E19: 9.21 | F19: 5.41 | G19: 15.78 | H19: 9.59 | I19: 3.19 | J19: 1.03 | K19: 280.79 | L19: 26.63 | M19: 94.29 | N19: 140.7 | O19: 0 | P19: 0.27 | Q19: 4.67
A20: 45505.5 | B20: 9.18 | C20: 4.23 | D20: 14 | E20: 9.03 | F20: 5.53 | G20: 14.88 | H20: 9.59 | I20: 3.37 | J20: 0.95 | K20: 284.6 | L20: 26.71 | M20: 92.32 | N20: 132.3 | O20: 0 | P20: 0.28 | Q20: 4.68
... A32: 45506 | B32: 9.23 | C32: 4.26 | D32: 14 | E32: 9.43 | F32: 5.55 | G32: 26.12 | H32: 16.73 | I32: 3.7 | J32: 0.33 | K32: 275.68 | L32: 25.72 | M32: 96.57 | N32: 2.4 | O32: 0.2 | P32: 0.34 | Q32: 4.67
A34: Min | B34: =MIN(B9:B32) -> 9.14 | C34: =MIN(C9:C32) -> 4.1 | D34: =MIN(D9:D32) -> 14 | E34: =MIN(E9:E32) -> 8.58 | F34: =MIN(F9:F32) -> 3.75 | G34: =MIN(G9:G32) -> 10.95 | H34: =MIN(H9:H32) -> 3.31 | I34: =MIN(I9:I32) -> 3.19 | ... Q34: =MIN(Q9:Q32) -> 4.65
A35: Max | B35: =MAX(B9:B32) -> 9.25 | C35: =MAX(C9:C32) -> 4.28 | D35: =MAX(D9:D32) -> 14 | E35: =MAX(E9:E32) -> 13.3 | F35: =MAX(F9:F32) -> 6.15 | G35: =MAX(G9:G32) -> 33.67 | H35: =MAX(H9:H32) -> 16.73 | I35: =MAX(I9:I32) -> 4.25 | ... Q35: =MAX(Q9:Q32) -> 4.68
A36: Avg | B36: =AVERAGE(B9:B32) -> 9.1983333 | C36: =AVERAGE(C9:C32) -> 4.1966667 | D36: =AVERAGE(D9:D32) -> 14 | E36: =AVERAGE(E9:E32) -> 10.563333 | F36: =AVERAGE(F9:F32) -> 4.83125 | G36: =AVERAGE(G9:G32) -> 20.59625 | H36: =AVERAGE(H9:H32) -> 10.121667 | I36: =AVERAGE(I9:I32) -> 3.7095833 | ... Q36: =AVERAGE(Q9:Q32) -> 4.67
A37: Stdev | B37: =STDEV(B9:B32) -> 0.03239252 | C37: =STDEV(C9:C32) -> 0.05738252 | D37: =STDEV(D9:D32) -> 0 | E37: =STDEV(E9:E32) -> 1.3861698 | F37: =STDEV(F9:F32) -> 0.62980544 | G37: =STDEV(G9:G32) -> 6.1172172 | H37: =STDEV(H9:H32) -> 4.475743 | I37: =STDEV(I9:I32) -> 0.33233664 | ... Q37: =STDEV(Q9:Q32) -> 0.007801895
A38: Num | B38: =COUNT(B9:B32) -> 24 | C38: =COUNT(C9:C32) -> 24 | D38: =COUNT(D9:D32) -> 24 | E38: =COUNT(E9:E32) -> 24 | F38: =COUNT(F9:F32) -> 24 | G38: =COUNT(G9:G32) -> 24 | H38: =COUNT(H9:H32) -> 24 | I38: =COUNT(I9:I32) -> 24 | ... Q38: =COUNT(Q9:Q32) -> 24
A39: DCR | B39: =IF(B38>=22,">90%",IF(B38<=22,"<90%")) -> >90% | C39: =IF(C38>=22,">90%",IF(C38<=22,"<90%")) -> >90% | D39: =IF(D38>=22,">90%",IF(D38<=22,"<90%")) -> >90% | E39: =IF(E38>=22,">90%",IF(E38<=22,"<90%")) -> >90% | F39: =IF(F38>=22,">90%",IF(F38<=22,"<90%")) -> >90% | G39: =IF(G38>=22,">90%",IF(G38<=22,"<90%")) -> >90% | H39: =IF(H38>=22,">90%",IF(H38<=22,"<90%")) -> >90% | I39: =IF(I38>=22,">90%",IF(I38<=22,"<90%")) -> >90% | ... Q39: =IF(Q38>=22,">90%",IF(Q38<=22,"<90%")) -> >90%
A40: Status | B40: =IF(B38>=22,"OK",IF(B38<=22,"LESS")) -> OK | C40: =IF(C38>=22,"OK",IF(C38<=22,"LESS")) -> OK | D40: =IF(D38>=22,"OK",IF(D38<=22,"LESS")) -> OK | E40: =IF(E38>=22,"OK",IF(E38<=22,"LESS")) -> OK | F40: =IF(F38>=22,"OK",IF(F38<=22,"LESS")) -> OK | G40: =IF(G38>=22,"OK",IF(G38<=22,"LESS")) -> OK | H40: =IF(H38>=22,"OK",IF(H38<=22,"LESS")) -> OK | I40: =IF(I38>=22,"OK",IF(I38<=22,"LESS")) -> OK | ... Q40: =IF(Q38>=22,"OK",IF(Q38<=22,"LESS")) -> OK
A43: Done by | B43: AKASH
A45: Comment

Sheet 02
A1: Station: | B1: IGKV ,RAIPUR
A2: Date: | B2: =$A$9 -> 45506.042 | D2: Power Off | G2: Pw.Off | L2: Link Fail | N2: Link F | P2: Maintenance | R2: Maint.
A3: Report Type: | B3: Mean | D3: Calibration | G3: Calib. | L3: Data Fail | N3: Data F | P3: Invalid | R3: Invalid
A4: Time Base: | B4: 01 Hour | D4: Zero Referrence | G4: Z.Ref | L4: Warm Up | N4: Wm. Up
A7: Date & Time | B7: NO | C7: NO2 | D7: NOX | E7: SO2 | F7: O3 | G7: PM 10 | H7: PM 2.5 | I7: BENZ | J7: WS | K7: WD | L7: TEMP | M7: HUM | N7: SR | O7: RG | P7: CO | Q7: NH3
B8: ug/m3 | C8: ug/m3 | D8: ppb | E8: ug/m3 | F8: ug/m3 | G8: ug/m3 | H8: ug/m3 | I8: ug/m3 | J8: m/sec | K8: deg | L8: degreC | M8: % | N8: w/m2 | O8: mm | P8: mg/m3 | Q8: ug/m3
A9: 45506.042 | B9: 9.23 | C9: 4.2 | D9: 14 | E9: 10 | F9: 4.28 | G9: 29.64 | H9: 12.47 | I9: 3.47 | J9: 0.78 | K9: 282.84 | L9: 25.29 | M9: 101.61 | N9: 2.8 | O9: 5.8 | P9: 0.33 | Q9: 4.67
A10: 45506.083 | B10: 9.21 | C10: 4.21 | D10: 14 | E10: 10.46 | F10: 4.15 | G10: 30.23 | H10: 10.31 | I10: 3.39 | J10: 0.65 | K10: 278.72 | L10: 24.72 | M10: 101.78 | N10: 2.6 | O10: 0.2 | P10: 0.32 | Q10: 4.67
A11: 45506.125 | B11: 9.21 | C11: 4.16 | D11: 14 | E11: 9.01 | F11: 4.02 | G11: 30.23 | H11: 14.69 | I11: 3.36 | J11: 0.77 | K11: 279.88 | L11: 24.56 | M11: 102.58 | N11: 2.9 | O11: 0.2 | P11: 0.32 | Q11: 4.67
A12: 45506.167 | B12: 9.22 | C12: 4.15 | D12: 14 | E12: 9.71 | F12: 3.71 | G12: 23.14 | H12: 14.69 | I12: 3.22 | J12: 0.84 | K12: 278.99 | L12: 24.61 | M12: 102.51 | N12: 3 | O12: 0.2 | P12: 0.34 | Q12: 4.66
A13: 45506.208 | B13: 9.22 | C13: 4.25 | D13: 14 | E13: 9.7 | F13: 3.93 | G13: 16.91 | H13: 10.89 | I13: 3.18 | J13: 0.7 | K13: 281.24 | L13: 24.5 | M13: 102.72 | N13: 2.6 | O13: 0 | P13: 0.35 | Q13: 4.67
A14: 45506.25 | B14: 9.11 | C14: 4.32 | D14: 14 | E14: 8.2 | F14: 3.65 | G14: 12.49 | H14: 8.51 | I14: 3.27 | J14: 0.7 | K14: 280.35 | L14: 24.46 | M14: 101.37 | N14: 6.8 | O14: 0.2 | P14: 0.34 | Q14: 4.68
A15: 45506.292 | B15: 9.11 | C15: 4.31 | D15: 14 | E15: 7.41 | F15: 3.66 | G15: 12.04 | H15: 8.04 | I15: 3.3 | J15: 0.81 | K15: 281.79 | L15: 24.34 | M15: 101.77 | N15: 25.1 | O15: 0.6 | P15: 0.33 | Q15: 4.67
A16: 45506.333 | B16: 9.09 | C16: 4.35 | D16: 14 | E16: 6.7 | F16: 3.78 | G16: 10.77 | H16: 6.09 | I16: 3.37 | J16: 0.86 | K16: 280.34 | L16: 24.36 | M16: 101.8 | N16: 41.8 | O16: 0.4 | P16: 0.32 | Q16: 4.69
A17: 45506.375 | B17: 9.16 | C17: 4.34 | D17: 14 | E17: 6.51 | F17: 5.18 | G17: 10.77 | H17: 5.08 | I17: 3.36 | J17: 1.04 | K17: 281.63 | L17: 24.93 | M17: 101.52 | N17: 110.6 | O17: 0.2 | P17: 0.33 | Q17: 4.67
A18: 45506.417 | B18: 9.17 | C18: 4.24 | D18: 14 | E18: 7.45 | F18: 3.69 | G18: 14.33 | H18: 4.58 | I18: 3.27 | J18: 1.06 | K18: 282.42 | L18: 25.41 | M18: 98.09 | N18: 100.3 | O18: 0 | P18: 0.29 | Q18: 4.67
A19: 45506.458 | B19: 9.19 | C19: 4.23 | D19: 14 | E19: 9.84 | F19: 4.18 | G19: 14.33 | H19: 3.3 | I19: 3.18 | J19: 1.21 | K19: 284.65 | L19: 25.75 | M19: 93.66 | N19: 99.2 | O19: 0 | P19: 0.29 | Q19: 4.66
A20: 45506.5 | B20: 9.19 | C20: 4.2 | D20: 14 | E20: 10.79 | F20: 4.46 | G20: 10.97 | H20: 2.44 | I20: 3.08 | J20: 1.11 | K20: 282.85 | L20: 26.05 | M20: 92.04 | N20: 73.6 | O20: 0 | P20: 0.3 | Q20: 4.67
... A32: 45507 | B32: 9.19 | C32: 4.28 | D32: 14 | E32: 11.51 | F32: 4.02 | G32: 6.72 | H32: 4.84 | I32: 3.09 | J32: 0.99 | K32: 279.29 | L32: 25.04 | M32: 97.17 | N32: 2.5 | O32: 0 | P32: 0.28 | Q32: 4.67
A34: Min | B34: =MIN(B9:B32) -> 9.09 | C34: =MIN(C9:C32) -> 4.15 | D34: =MIN(D9:D32) -> 14 | E34: =MIN(E9:E32) -> 6.51 | F34: =MIN(F9:F32) -> 3.65 | G34: =MIN(G9:G32) -> 6.72 | H34: =MIN(H9:H32) -> 2.44 | I34: =MIN(I9:I32) -> 2.94 | ... Q34: =MIN(Q9:Q32) -> 4.66
A35: Max | B35: =MAX(B9:B32) -> 9.23 | C35: =MAX(C9:C32) -> 4.35 | D35: =MAX(D9:D32) -> 14 | E35: =MAX(E9:E32) -> 11.57 | F35: =MAX(F9:F32) -> 5.29 | G35: =MAX(G9:G32) -> 30.23 | H35: =MAX(H9:H32) -> 14.69 | I35: =MAX(I9:I32) -> 3.47 | ... Q35: =MAX(Q9:Q32) -> 4.69
A36: Avg | B36: =AVERAGE(B9:B32) -> 9.17875 | C36: =AVERAGE(C9:C32) -> 4.2370833 | D36: =AVERAGE(D9:D32) -> 14 | E36: =AVERAGE(E9:E32) -> 9.55125 | F36: =AVERAGE(F9:F32) -> 4.1929167 | G36: =AVERAGE(G9:G32) -> 15.429167 | H36: =AVERAGE(H9:H32) -> 6.88875 | I36: =AVERAGE(I9:I32) -> 3.1833333 | ... Q36: =AVERAGE(Q9:Q32) -> 4.6695833
A37: Stdev | B37: =STDEV(B9:B32) -> 0.037336601 | C37: =STDEV(C9:C32) -> 0.054651399 | D37: =STDEV(D9:D32) -> 0 | E37: =STDEV(E9:E32) -> 1.4387897 | F37: =STDEV(F9:F32) -> 0.41570766 | G37: =STDEV(G9:G32) -> 6.8621741 | H37: =STDEV(H9:H32) -> 3.5365794 | I37: =STDEV(I9:I32) -> 0.15516237 | ... Q37: =STDEV(Q9:Q32) -> 0.0085867272
A38: Num | B38: =COUNT(B9:B32) -> 24 | C38: =COUNT(C9:C32) -> 24 | D38: =COUNT(D9:D32) -> 24 | E38: =COUNT(E9:E32) -> 24 | F38: =COUNT(F9:F32) -> 24 | G38: =COUNT(G9:G32) -> 24 | H38: =COUNT(H9:H32) -> 24 | I38: =COUNT(I9:I32) -> 24 | ... Q38: =COUNT(Q9:Q32) -> 24
A39: DCR | B39: =IF(B38>=22,">90%",IF(B38<=22,"<90%")) -> >90% | C39: =IF(C38>=22,">90%",IF(C38<=22,"<90%")) -> >90% | D39: =IF(D38>=22,">90%",IF(D38<=22,"<90%")) -> >90% | E39: =IF(E38>=22,">90%",IF(E38<=22,"<90%")) -> >90% | F39: =IF(F38>=22,">90%",IF(F38<=22,"<90%")) -> >90% | G39: =IF(G38>=22,">90%",IF(G38<=22,"<90%")) -> >90% | H39: =IF(H38>=22,">90%",IF(H38<=22,"<90%")) -> >90% | I39: =IF(I38>=22,">90%",IF(I38<=22,"<90%")) -> >90% | ... Q39: =IF(Q38>=22,">90%",IF(Q38<=22,"<90%")) -> >90%
A40: Status | B40: =IF(B38>=22,"OK",IF(B38<=22,"LESS")) -> OK | C40: =IF(C38>=22,"OK",IF(C38<=22,"LESS")) -> OK | D40: =IF(D38>=22,"OK",IF(D38<=22,"LESS")) -> OK | E40: =IF(E38>=22,"OK",IF(E38<=22,"LESS")) -> OK | F40: =IF(F38>=22,"OK",IF(F38<=22,"LESS")) -> OK | G40: =IF(G38>=22,"OK",IF(G38<=22,"LESS")) -> OK | H40: =IF(H38>=22,"OK",IF(H38<=22,"LESS")) -> OK | I40: =IF(I38>=22,"OK",IF(I38<=22,"LESS")) -> OK | ... Q40: =IF(Q38>=22,"OK",IF(Q38<=22,"LESS")) -> OK
A43: Done by | B43: AKASH
A45: Comment

Sheet 03
A1: Station: | B1: IGKV ,RAIPUR
A2: Date: | B2: =$A$9 -> 45507.042 | D2: Power Off | G2: Pw.Off | L2: Link Fail | N2: Link F | P2: Maintenance | R2: Maint.
A3: Report Type: | B3: Mean | D3: Calibration | G3: Calib. | L3: Data Fail | N3: Data F | P3: Invalid | R3: Invalid
A4: Time Base: | B4: 01 Hour | D4: Zero Referrence | G4: Z.Ref | L4: Warm Up | N4: Wm. Up
A7: Date & Time | B7: NO | C7: NO2 | D7: NOX | E7: SO2 | F7: O3 | G7: PM 10 | H7: PM 2.5 | I7: BENZ | J7: WS | K7: WD | L7: TEMP | M7: HUM | N7: SR | O7: RG | P7: CO | Q7: NH3
B8: ug/m3 | C8: ug/m3 | D8: ppb | E8: ug/m3 | F8: ug/m3 | G8: ug/m3 | H8: ug/m3 | I8: ug/m3 | J8: m/sec | K8: deg | L8: degreC | M8: % | N8: w/m2 | O8: mm | P8: mg/m3 | Q8: ug/m3
A9: 45507.042 | B9: 9.41 | C9: 4.1 | D9: 14.13 | E9: 10.39 | F9: 3.95 | G9: 5.39 | H9: 4.04 | I9: 3.16 | J9: 0.96 | K9: 279.5 | L9: 25.09 | M9: 96.41 | N9: 2.3 | O9: 0 | P9: 0.28 | Q9: 4.66
A10: 45507.083 | B10: 9.41 | C10: 4.1 | D10: 14.13 | E10: 9.62 | F10: 3.8 | G10: 8.14 | H10: 4.36 | I10: 3.17 | J10: 1.02 | K10: 279.7 | L10: 25.11 | M10: 91.56 | N10: 2.5 | O10: 0 | P10: 0.27 | Q10: 4.67
A11: 45507.125 | B11: 9.4 | C11: 4.08 | D11: 14.12 | E11: 10.74 | F11: 3.72 | G11: 8.14 | H11: 4.93 | I11: 3.11 | J11: 0.86 | K11: 279.18 | L11: 24.65 | M11: 98.66 | N11: 3.6 | O11: 0.6 | P11: 0.26 | Q11: 4.67
A12: 45507.167 | B12: 9.4 | C12: 4.11 | D12: 14.13 | E12: 10.56 | F12: 3.57 | G12: 6.62 | H12: 7.95 | I12: 3.06 | J12: 0.82 | K12: 278.56 | L12: 24.05 | M12: 100.7 | N12: 2.5 | O12: 0.8 | P12: 0.24 | Q12: 4.67
A13: 45507.208 | B13: 9.42 | C13: 4.09 | D13: 14.13 | E13: 11.32 | F13: 4.08 | G13: 5.59 | H13: 9.55 | I13: 2.97 | J13: 1.01 | K13: 277.82 | L13: 23.96 | M13: 100.3 | N13: 2.8 | O13: 1 | P13: 0.2 | Q13: 4.67
A14: 45507.25 | B14: 9.41 | C14: 4.1 | D14: 14.13 | E14: 11.64 | F14: 4.18 | G14: 4.49 | H14: 9.55 | I14: 2.83 | J14: 1.1 | K14: 281.59 | L14: 23.4 | M14: 103.11 | N14: 4.5 | O14: 2 | P14: 0.2 | Q14: 4.69
A15: 45507.292 | B15: 9.43 | C15: 4.1 | D15: 14.15 | E15: 12.09 | F15: 3.78 | G15: 10.98 | H15: 7.32 | I15: 2.75 | J15: 0.99 | K15: 279.5 | L15: 23.36 | M15: 101.79 | N15: 7.9 | O15: 3 | P15: 0.2 | Q15: 4.67
A16: 45507.333 | B16: 9.43 | C16: 4.11 | D16: 14.15 | E16: 12.43 | F16: 3.72 | G16: 10.98 | H16: 5.94 | I16: 2.72 | J16: 0.85 | K16: 279.24 | L16: 23.47 | M16: 101.82 | N16: 8.5 | O16: 2.6 | P16: 0.2 | Q16: 4.66
A17: 45507.375 | B17: 9.41 | C17: 4.07 | D17: 14.13 | E17: 13.09 | F17: 3.59 | G17: 7.91 | H17: 5.1 | I17: 2.83 | J17: 0.68 | K17: 322.75 | L17: 23.48 | M17: 102.43 | N17: 9.6 | O17: 10.2 | P17: 0.27 | Q17: 4.67
A18: 45507.417 | B18: 9.3 | C18: 4.11 | D18: 14.04 | E18: 11.73 | F18: 3.61 | G18: 6.9 | H18: 5.1 | I18: 3.07 | J18: 0.98 | K18: 282.16 | L18: 23.69 | M18: 101.94 | N18: 69.1 | O18: 5.4 | P18: 0.27 | Q18: 4.66
A19: 45507.458 | B19: 9.31 | C19: 4.1 | D19: 14.05 | E19: 9.26 | F19: 3.77 | G19: 5.78 | H19: 3.89 | I19: 3.04 | J19: 0.91 | K19: 278.51 | L19: 23.96 | M19: 101.87 | N19: 97.3 | O19: 0.6 | P19: 0.26 | Q19: 4.67
A20: 45507.5 | B20: 9.32 | C20: 4.07 | D20: 14.05 | E20: 8.59 | F20: 3.94 | G20: 5.09 | H20: 3.59 | I20: 3.02 | J20: 0.93 | K20: 280.6 | L20: 24.11 | M20: 101.6 | N20: 84.1 | O20: 0.6 | P20: 0.26 | Q20: 4.67
... A32: 45508 | B32: 9.38 | C32: 4.08 | D32: 14.1 | E32: 8.67 | F32: 4.22 | G32: 11.72 | H32: 4.84 | I32: 2.91 | J32: 0.52 | K32: 272.83 | L32: 25.24 | M32: 98.9 | N32: 2.5 | O32: 0 | P32: 0.22 | Q32: 4.67
A34: Min | B34: =MIN(B9:B32) -> 9.3 | C34: =MIN(C9:C32) -> 4.07 | D34: =MIN(D9:D32) -> 14.04 | E34: =MIN(E9:E32) -> 7.51 | F34: =MIN(F9:F32) -> 3.57 | G34: =MIN(G9:G32) -> 3.73 | H34: =MIN(H9:H32) -> 3.59 | I34: =MIN(I9:I32) -> 2.69 | ... Q34: =MIN(Q9:Q32) -> 4.66
A35: Max | B35: =MAX(B9:B32) -> 9.43 | C35: =MAX(C9:C32) -> 4.11 | D35: =MAX(D9:D32) -> 14.15 | E35: =MAX(E9:E32) -> 13.09 | F35: =MAX(F9:F32) -> 5.04 | G35: =MAX(G9:G32) -> 13.59 | H35: =MAX(H9:H32) -> 9.55 | I35: =MAX(I9:I32) -> 3.17 | ... Q35: =MAX(Q9:Q32) -> 4.69
A36: Avg | B36: =AVERAGE(B9:B32) -> 9.38375 | C36: =AVERAGE(C9:C32) -> 4.0933333 | D36: =AVERAGE(D9:D32) -> 14.106667 | E36: =AVERAGE(E9:E32) -> 10.005833 | F36: =AVERAGE(F9:F32) -> 4.0625 | G36: =AVERAGE(G9:G32) -> 8.0895833 | H36: =AVERAGE(H9:H32) -> 5.5708333 | I36: =AVERAGE(I9:I32) -> 2.9208333 | ... Q36: =AVERAGE(Q9:Q32) -> 4.6695833
A37: Stdev | B37: =STDEV(B9:B32) -> 0.038313637 | C37: =STDEV(C9:C32) -> 0.011293194 | D37: =STDEV(D9:D32) -> 0.031714304 | E37: =STDEV(E9:E32) -> 1.6016511 | F37: =STDEV(F9:F32) -> 0.3955431 | G37: =STDEV(G9:G32) -> 2.8995914 | H37: =STDEV(H9:H32) -> 1.6108381 | I37: =STDEV(I9:I32) -> 0.14358505 | ... Q37: =STDEV(Q9:Q32) -> 0.0075060362
A38: Num | B38: =COUNT(B9:B32) -> 24 | C38: =COUNT(C9:C32) -> 24 | D38: =COUNT(D9:D32) -> 24 | E38: =COUNT(E9:E32) -> 24 | F38: =COUNT(F9:F32) -> 24 | G38: =COUNT(G9:G32) -> 24 | H38: =COUNT(H9:H32) -> 24 | I38: =COUNT(I9:I32) -> 24 | ... Q38: =COUNT(Q9:Q32) -> 24
A39: DCR | B39: =IF(B38>=22,">90%",IF(B38<=22,"<90%")) -> >90% | C39: =IF(C38>=22,">90%",IF(C38<=22,"<90%")) -> >90% | D39: =IF(D38>=22,">90%",IF(D38<=22,"<90%")) -> >90% | E39: =IF(E38>=22,">90%",IF(E38<=22,"<90%")) -> >90% | F39: =IF(F38>=22,">90%",IF(F38<=22,"<90%")) -> >90% | G39: =IF(G38>=22,">90%",IF(G38<=22,"<90%")) -> >90% | H39: =IF(H38>=22,">90%",IF(H38<=22,"<90%")) -> >90% | I39: =IF(I38>=22,">90%",IF(I38<=22,"<90%")) -> >90% | ... Q39: =IF(Q38>=22,">90%",IF(Q38<=22,"<90%")) -> >90%
A40: Status | B40: =IF(B38>=22,"OK",IF(B38<=22,"LESS")) -> OK | C40: =IF(C38>=22,"OK",IF(C38<=22,"LESS")) -> OK | D40: =IF(D38>=22,"OK",IF(D38<=22,"LESS")) -> OK | E40: =IF(E38>=22,"OK",IF(E38<=22,"LESS")) -> OK | F40: =IF(F38>=22,"OK",IF(F38<=22,"LESS")) -> OK | G40: =IF(G38>=22,"OK",IF(G38<=22,"LESS")) -> OK | H40: =IF(H38>=22,"OK",IF(H38<=22,"LESS")) -> OK | I40: =IF(I38>=22,"OK",IF(I38<=22,"LESS")) -> OK | ... Q40: =IF(Q38>=22,"OK",IF(Q38<=22,"LESS")) -> OK
A43: Done by | B43: AKASH
A45: Comment

Sheet 04
A1: Station: | B1: IGKV ,RAIPUR
A2: Date: | B2: =$A$9 -> 45508.042 | D2: Power Off | G2: Pw.Off | L2: Link Fail | N2: Link F | P2: Maintenance | R2: Maint.
A3: Report Type: | B3: Mean | D3: Calibration | G3: Calib. | L3: Data Fail | N3: Data F | P3: Invalid | R3: Invalid
A4: Time Base: | B4: 01 Hour | D4: Zero Referrence | G4: Z.Ref | L4: Warm Up | N4: Wm. Up
A7: Date & Time | B7: NO | C7: NO2 | D7: NOX | E7: SO2 | F7: O3 | G7: PM 10 | H7: PM 2.5 | I7: BENZ | J7: WS | K7: WD | L7: TEMP | M7: HUM | N7: SR | O7: RG | P7: CO | Q7: NH3
B8: ug/m3 | C8: ug/m3 | D8: ppb | E8: ug/m3 | F8: ug/m3 | G8: ug/m3 | H8: ug/m3 | I8: ug/m3 | J8: m/sec | K8: deg | L8: degreC | M8: % | N8: w/m2 | O8: mm | P8: mg/m3 | Q8: ug/m3
A9: 45508.042 | B9: 9.3 | C9: 4.08 | D9: 14.02 | E9: 9.02 | F9: 3.9 | G9: 11.72 | H9: 3.69 | I9: 2.84 | J9: 0.47 | K9: 270.21 | L9: 24.95 | M9: 99.2 | N9: 2 | O9: 0 | P9: 0.22 | Q9: 4.66
A10: 45508.083 | B10: 9.28 | C10: 4.1 | D10: 14.02 | E10: 9.73 | F10: 3.58 | G10: 14.05 | H10: 10.81 | I10: 2.8 | J10: 0.46 | K10: 267.19 | L10: 24.8 | M10: 97.85 | N10: 2.4 | O10: 0 | P10: 0.22 | Q10: 4.66
A11: 45508.125 | B11: 9.3 | C11: 4.1 | D11: 14.03 | E11: 9.3 | F11: 3.65 | G11: 14.05 | H11: 10.81 | I11: 2.73 | J11: 0.49 | K11: 271.43 | L11: 24.94 | M11: 97.6 | N11: 2.4 | O11: 0 | P11: 0.22 | Q11: 4.66
A12: 45508.167 | B12: 9.3 | C12: 4.07 | D12: 14.03 | E12: 9.23 | F12: 3.93 | G12: 10.78 | H12: 14.39 | I12: 2.74 | J12: 0.57 | K12: 271.25 | L12: 25.03 | M12: 95.31 | N12: 2.4 | O12: 0 | P12: 0.27 | Q12: 4.66
A13: 45508.208 | B13: 9.26 | C13: 4.13 | D13: 14 | E13: 8.15 | F13: 3.63 | G13: 8.46 | H13: 14.39 | I13: 2.81 | J13: 0.56 | K13: 273.8 | L13: 24.89 | M13: 100.5 | N13: 3 | O13: 0.8 | P13: 0.26 | Q13: 4.68
A14: 45508.25 | B14: 9.24 | C14: 4.12 | D14: 14 | E14: 7.69 | F14: 4.26 | G14: 6.16 | H14: 10.46 | I14: 2.9 | J14: 0.44 | K14: 270.96 | L14: 24.48 | M14: 100.45 | N14: 14.5 | O14: 0 | P14: 0.26 | Q14: 4.67
A15: 45508.292 | B15: 9.24 | C15: 4.12 | D15: 14 | E15: 7.22 | F15: 4.09 | G15: 14.14 | H15: 7.57 | I15: 2.89 | J15: 0.68 | K15: 274.82 | L15: 25.06 | M15: 99.2 | N15: 47.6 | O15: 0 | P15: 0.26 | Q15: 4.67
A16: 45508.333 | B16: 9.24 | C16: 4.12 | D16: 14 | E16: 7.14 | F16: 4.03 | G16: 14.14 | H16: 7.52 | I16: 2.92 | J16: 0.69 | K16: 272.54 | L16: 26.01 | M16: 95.87 | N16: 146.3 | O16: 0 | P16: 0.25 | Q16: 4.68
A17: 45508.375 | B17: 9.35 | C17: 4.09 | D17: 14.08 | E17: 7.77 | F17: 4.94 | G17: 10.73 | H17: 8.52 | I17: 2.93 | J17: 0.7 | K17: 272.72 | L17: 26.92 | M17: 90.29 | N17: 158.8 | O17: 0 | P17: 0.22 | Q17: 4.67
A18: 45508.417 | B18: 9.34 | C18: 4.08 | D18: 14.07 | E18: 8.07 | F18: 5.58 | G18: 10.19 | H18: 11.62 | I18: 2.82 | J18: 1.02 | K18: 277.24 | L18: 27.36 | M18: 87.17 | N18: 183.8 | O18: 0 | P18: 0.22 | Q18: 4.67
A19: 45508.458 | B19: 9.34 | C19: 4.08 | D19: 14.06 | E19: 10.82 | F19: 4.82 | G19: 7.78 | H19: 11.62 | I19: 2.77 | J19: 0.8 | K19: 274.09 | L19: 27.58 | M19: 83.79 | N19: 175.2 | O19: 0 | P19: 0.22 | Q19: 4.67
A20: 45508.5 | B20: 9.32 | C20: 4.08 | D20: 14.05 | E20: 11.24 | F20: 4.32 | G20: 7.8 | H20: 10.14 | I20: 2.69 | J20: 0.71 | K20: 274.19 | L20: 27.4 | M20: 95.28 | N20: 152.3 | O20: 0.6 | P20: 0.23 | Q20: 4.67
... A32: 45509 | B32: 9.27 | C32: 4.1 | D32: 14.01 | E32: 12.27 | F32: 5.15 | G32: 17.1 | H32: 10.55 | I32: 3.14 | J32: 0.62 | K32: 280.46 | L32: 25.57 | M32: 98.97 | N32: 3.3 | O32: 0 | P32: 0.34 | Q32: 4.67
A34: Min | B34: =MIN(B9:B32) -> 9.23 | C34: =MIN(C9:C32) -> 4.06 | D34: =MIN(D9:D32) -> 14 | E34: =MIN(E9:E32) -> 7.14 | F34: =MIN(F9:F32) -> 3.58 | G34: =MIN(G9:G32) -> 6.16 | H34: =MIN(H9:H32) -> 3.69 | I34: =MIN(I9:I32) -> 2.61 | ... Q34: =MIN(Q9:Q32) -> 4.66
A35: Max | B35: =MAX(B9:B32) -> 9.35 | C35: =MAX(C9:C32) -> 4.16 | D35: =MAX(D9:D32) -> 14.08 | E35: =MAX(E9:E32) -> 13.68 | F35: =MAX(F9:F32) -> 6.9 | G35: =MAX(G9:G32) -> 18.65 | H35: =MAX(H9:H32) -> 14.39 | I35: =MAX(I9:I32) -> 3.2 | ... Q35: =MAX(Q9:Q32) -> 4.69
A36: Avg | B36: =AVERAGE(B9:B32) -> 9.2845833 | C36: =AVERAGE(C9:C32) -> 4.10125 | D36: =AVERAGE(D9:D32) -> 14.022917 | E36: =AVERAGE(E9:E32) -> 10.05875 | F36: =AVERAGE(F9:F32) -> 4.6975 | G36: =AVERAGE(G9:G32) -> 13.479583 | H36: =AVERAGE(H9:H32) -> 9.52375 | I36: =AVERAGE(I9:I32) -> 2.8141667 | ... Q36: =AVERAGE(Q9:Q32) -> 4.6695833
A37: Stdev | B37: =STDEV(B9:B32) -> 0.036113248 | C37: =STDEV(C9:C32) -> 0.023831382 | D37: =STDEV(D9:D32) -> 0.024931064 | E37: =STDEV(E9:E32) -> 1.9478245 | F37: =STDEV(F9:F32) -> 0.91049079 | G37: =STDEV(G9:G32) -> 3.5398716 | H37: =STDEV(H9:H32) -> 2.9734664 | I37: =STDEV(I9:I32) -> 0.16215711 | ... Q37: =STDEV(Q9:Q32) -> 0.0075060362
A38: Num | B38: =COUNT(B9:B32) -> 24 | C38: =COUNT(C9:C32) -> 24 | D38: =COUNT(D9:D32) -> 24 | E38: =COUNT(E9:E32) -> 24 | F38: =COUNT(F9:F32) -> 24 | G38: =COUNT(G9:G32) -> 24 | H38: =COUNT(H9:H32) -> 24 | I38: =COUNT(I9:I32) -> 24 | ... Q38: =COUNT(Q9:Q32) -> 24
A39: DCR | B39: =IF(B38>=22,">90%",IF(B38<=22,"<90%")) -> >90% | C39: =IF(C38>=22,">90%",IF(C38<=22,"<90%")) -> >90% | D39: =IF(D38>=22,">90%",IF(D38<=22,"<90%")) -> >90% | E39: =IF(E38>=22,">90%",IF(E38<=22,"<90%")) -> >90% | F39: =IF(F38>=22,">90%",IF(F38<=22,"<90%")) -> >90% | G39: =IF(G38>=22,">90%",IF(G38<=22,"<90%")) -> >90% | H39: =IF(H38>=22,">90%",IF(H38<=22,"<90%")) -> >90% | I39: =IF(I38>=22,">90%",IF(I38<=22,"<90%")) -> >90% | ... Q39: =IF(Q38>=22,">90%",IF(Q38<=22,"<90%")) -> >90%
A40: Status | B40: =IF(B38>=22,"OK",IF(B38<=22,"LESS")) -> OK | C40: =IF(C38>=22,"OK",IF(C38<=22,"LESS")) -> OK | D40: =IF(D38>=22,"OK",IF(D38<=22,"LESS")) -> OK | E40: =IF(E38>=22,"OK",IF(E38<=22,"LESS")) -> OK | F40: =IF(F38>=22,"OK",IF(F38<=22,"LESS")) -> OK | G40: =IF(G38>=22,"OK",IF(G38<=22,"LESS")) -> OK | H40: =IF(H38>=22,"OK",IF(H38<=22,"LESS")) -> OK | I40: =IF(I38>=22,"OK",IF(I38<=22,"LESS")) -> OK | ... Q40: =IF(Q38>=22,"OK",IF(Q38<=22,"LESS")) -> OK
A43: Done by | B43: AKASH
A45: Comment

Sheet 05
A1: Station: | B1: IGKV ,RAIPUR
A2: Date: | B2: =$A$9 -> 45509.042 | D2: Power Off | G2: Pw.Off | L2: Link Fail | N2: Link F | P2: Maintenance | R2: Maint.
A3: Report Type: | B3: Mean | D3: Calibration | G3: Calib. | L3: Data Fail | N3: Data F | P3: Invalid | R3: Invalid
A4: Time Base: | B4: 01 Hour | D4: Zero Referrence | G4: Z.Ref | L4: Warm Up | N4: Wm. Up
A7: Date & Time | B7: NO | C7: NO2 | D7: NOX | E7: SO2 | F7: O3 | G7: PM 10 | H7: PM 2.5 | I7: BENZ | J7: WS | K7: WD | L7: TEMP | M7: HUM | N7: SR | O7: RG | P7: CO | Q7: NH3
B8: ug/m3 | C8: ug/m3 | D8: ppb | E8: ug/m3 | F8: ug/m3 | G8: ug/m3 | H8: ug/m3 | I8: ug/m3 | J8: m/sec | K8: deg | L8: degreC | M8: % | N8: w/m2 | O8: mm | P8: mg/m3 | Q8: ug/m3
A9: 45509.042 | B9: 9.34 | C9: 4.06 | D9: 14.05 | E9: 11.24 | F9: 4.78 | G9: 17.1 | H9: 10.55 | I9: 3.1 | J9: 0.39 | K9: 272.53 | L9: 25.25 | M9: 97.22 | N9: 3.4 | O9: 0 | P9: 0.32 | Q9: 4.68
A10: 45509.083 | B10: 9.31 | C10: 4.07 | D10: 14.03 | E10: 11.26 | F10: 4.27 | G10: 12.7 | H10: 8.88 | I10: 3.14 | J10: 0.36 | K10: 270.86 | L10: 24.93 | M10: 95.63 | N10: 3 | O10: 0 | P10: 0.31 | Q10: 4.68
A11: 45509.125 | B11: 9.31 | C11: 4.08 | D11: 14.05 | E11: 9.21 | F11: 4.27 | G11: 17.56 | H11: 9.5 | I11: 3.31 | J11: 0.16 | K11: 263.99 | L11: 24.63 | M11: 97.42 | N11: 2.4 | O11: 0 | P11: 0.31 | Q11: 4.66
A12: 45509.167 | B12: 9.3 | C12: 4.11 | D12: 14.06 | E12: 9.82 | F12: 3.92 | G12: 17.56 | H12: 11.5 | I12: 3.23 | J12: 0.09 | K12: 212.41 | L12: 24.57 | M12: 98.39 | N12: 2.2 | O12: 0 | P12: 0.26 | Q12: 4.67
A13: 45509.208 | B13: 9.32 | C13: 4.1 | D13: 14.06 | E13: 10.26 | F13: 3.6 | G13: 14.46 | H13: 11.5 | I13: 3.05 | J13: 0.13 | K13: 260.83 | L13: 24.63 | M13: 98.29 | N13: 2.1 | O13: 0 | P13: 0.25 | Q13: 4.67
A14: 45509.25 | B14: 9.32 | C14: 4.08 | D14: 14.06 | E14: 11.02 | F14: 3.57 | G14: 15.49 | H14: 8.42 | I14: 2.99 | J14: 0.3 | K14: 274.42 | L14: 24.66 | M14: 97.64 | N14: 15 | O14: 0 | P14: 0.25 | Q14: 4.67
A15: 45509.292 | B15: 9.33 | C15: 4.09 | D15: 14.05 | E15: 11.3 | F15: 3.59 | G15: 15.49 | H15: 6.54 | I15: 2.98 | J15: 0.32 | K15: 278.23 | L15: 25.51 | M15: 96.12 | N15: 64.1 | O15: 0 | P15: 0.26 | Q15: 4.66
A16: 45509.333 | B16: 9.31 | C16: 4.08 | D16: 14.04 | E16: 11.98 | F16: 3.8 | G16: 15.02 | H16: 5.17 | I16: 3.06 | J16: 0.8 | K16: 284.81 | L16: 26.95 | M16: 92.28 | N16: 112.3 | O16: 0 | P16: 0.31 | Q16: 4.67
A17: 45509.375 | B17: 9.3 | C17: 4.07 | D17: 14.03 | E17: 11.14 | F17: 4.6 | G17: 20.2 | H17: 5.37 | I17: 3.11 | J17: 1.06 | K17: 289.67 | L17: 28.1 | M17: 85.61 | N17: 175.1 | O17: 0 | P17: 0.31 | Q17: 4.66
A18: 45509.417 | B18: 9.3 | C18: 4.08 | D18: 14.04 | E18: 10.6 | F18: 4.77 | G18: 20.2 | H18: 11.39 | I18: 3.26 | J18: 0.85 | K18: 284.81 | L18: 28.92 | M18: 80.4 | N18: 319.2 | O18: 0 | P18: 0.33 | Q18: 4.66
A19: 45509.458 | B19: 9.32 | C19: 4.07 | D19: 14.04 | E19: 10.21 | F19: 4.77 | G19: 20.09 | H19: 13.11 | I19: 3.58 | J19: 0.86 | K19: 290.38 | L19: 29.72 | M19: 77.98 | N19: 492 | O19: 0 | P19: 0.35 | Q19: 4.67
A20: 45509.5 | B20: 9.31 | C20: 4.11 | D20: 14.05 | E20: 10.36 | F20: 6.02 | G20: 29.54 | H20: 13.11 | I20: 3.88 | J20: 1.09 | K20: 287.13 | L20: 30.18 | M20: 75.78 | N20: 446.6 | O20: 0 | P20: 0.39 | Q20: 4.67
... A32: 45510 | B32: 9.52 | C32: 4.07 | D32: 14.21 | E32: 10.73 | F32: 4.86 | G32: 34.7 | H32: 15.8 | I32: 6.24 | J32: 0.66 | K32: 282.61 | L32: 26.79 | M32: 89.8 | N32: 2.4 | O32: 0 | P32: 0.58 | Q32: 4.67
A34: Min | B34: =MIN(B9:B32) -> 9.3 | C34: =MIN(C9:C32) -> 4.06 | D34: =MIN(D9:D32) -> 14.03 | E34: =MIN(E9:E32) -> 8.63 | F34: =MIN(F9:F32) -> 3.57 | G34: =MIN(G9:G32) -> 12.7 | H34: =MIN(H9:H32) -> 5.17 | I34: =MIN(I9:I32) -> 2.98 | ... Q34: =MIN(Q9:Q32) -> 4.66
A35: Max | B35: =MAX(B9:B32) -> 9.53 | C35: =MAX(C9:C32) -> 4.12 | D35: =MAX(D9:D32) -> 14.22 | E35: =MAX(E9:E32) -> 12.23 | F35: =MAX(F9:F32) -> 11.2 | G35: =MAX(G9:G32) -> 41.45 | H35: =MAX(H9:H32) -> 20.37 | I35: =MAX(I9:I32) -> 6.24 | ... Q35: =MAX(Q9:Q32) -> 4.69
A36: Avg | B36: =AVERAGE(B9:B32) -> 9.36625 | C36: =AVERAGE(C9:C32) -> 4.0866667 | D36: =AVERAGE(D9:D32) -> 14.089583 | E36: =AVERAGE(E9:E32) -> 10.5275 | F36: =AVERAGE(F9:F32) -> 6.1516667 | G36: =AVERAGE(G9:G32) -> 26.116667 | H36: =AVERAGE(H9:H32) -> 12.26 | I36: =AVERAGE(I9:I32) -> 3.8841667 | ... Q36: =AVERAGE(Q9:Q32) -> 4.6725
A37: Stdev | B37: =STDEV(B9:B32) -> 0.079005366 | C37: =STDEV(C9:C32) -> 0.015510632 | D37: =STDEV(D9:D32) -> 0.064772456 | E37: =STDEV(E9:E32) -> 1.0613619 | F37: =STDEV(F9:F32) -> 2.4727026 | G37: =STDEV(G9:G32) -> 9.2692346 | H37: =STDEV(H9:H32) -> 3.8682082 | I37: =STDEV(I9:I32) -> 0.82249312 | ... Q37: =STDEV(Q9:Q32) -> 0.0084698955
A38: Num | B38: =COUNT(B9:B32) -> 24 | C38: =COUNT(C9:C32) -> 24 | D38: =COUNT(D9:D32) -> 24 | E38: =COUNT(E9:E32) -> 24 | F38: =COUNT(F9:F32) -> 24 | G38: =COUNT(G9:G32) -> 24 | H38: =COUNT(H9:H32) -> 24 | I38: =COUNT(I9:I32) -> 24 | ... Q38: =COUNT(Q9:Q32) -> 24
A39: DCR | B39: =IF(B38>=22,">90%",IF(B38<=22,"<90%")) -> >90% | C39: =IF(C38>=22,">90%",IF(C38<=22,"<90%")) -> >90% | D39: =IF(D38>=22,">90%",IF(D38<=22,"<90%")) -> >90% | E39: =IF(E38>=22,">90%",IF(E38<=22,"<90%")) -> >90% | F39: =IF(F38>=22,">90%",IF(F38<=22,"<90%")) -> >90% | G39: =IF(G38>=22,">90%",IF(G38<=22,"<90%")) -> >90% | H39: =IF(H38>=22,">90%",IF(H38<=22,"<90%")) -> >90% | I39: =IF(I38>=22,">90%",IF(I38<=22,"<90%")) -> >90% | ... Q39: =IF(Q38>=22,">90%",IF(Q38<=22,"<90%")) -> >90%
A40: Status | B40: =IF(B38>=22,"OK",IF(B38<=22,"LESS")) -> OK | C40: =IF(C38>=22,"OK",IF(C38<=22,"LESS")) -> OK | D40: =IF(D38>=22,"OK",IF(D38<=22,"LESS")) -> OK | E40: =IF(E38>=22,"OK",IF(E38<=22,"LESS")) -> OK | F40: =IF(F38>=22,"OK",IF(F38<=22,"LESS")) -> OK | G40: =IF(G38>=22,"OK",IF(G38<=22,"LESS")) -> OK | H40: =IF(H38>=22,"OK",IF(H38<=22,"LESS")) -> OK | I40: =IF(I38>=22,"OK",IF(I38<=22,"LESS")) -> OK | ... Q40: =IF(Q38>=22,"OK",IF(Q38<=22,"LESS")) -> OK
A43: Done by | B43: AKASH
A45: Comment

Sheet 06
A1: Station: | B1: IGKV ,RAIPUR
A2: Date: | B2: =$A$9 -> 45510.042 | D2: Power Off | G2: Pw.Off | L2: Link Fail | N2: Link F | P2: Maintenance | R2: Maint.
A3: Report Type: | B3: Mean | D3: Calibration | G3: Calib. | L3: Data Fail | N3: Data F | P3: Invalid | R3: Invalid
A4: Time Base: | B4: 01 Hour | D4: Zero Referrence | G4: Z.Ref | L4: Warm Up | N4: Wm. Up
A7: Date & Time | B7: NO | C7: NO2 | D7: NOX | E7: SO2 | F7: O3 | G7: PM 10 | H7: PM 2.5 | I7: BENZ | J7: WS | K7: WD | L7: TEMP | M7: HUM | N7: SR | O7: RG | P7: CO | Q7: NH3
B8: ug/m3 | C8: ug/m3 | D8: ppb | E8: ug/m3 | F8: ug/m3 | G8: ug/m3 | H8: ug/m3 | I8: ug/m3 | J8: m/sec | K8: deg | L8: degreC | M8: % | N8: w/m2 | O8: mm | P8: mg/m3 | Q8: ug/m3
A9: 45510.042 | B9: 9.16 | C9: 4.26 | D9: 14.01 | E9: 10.87 | F9: 4.67 | G9: 41.81 | H9: 13.12 | I9: 8.23 | J9: 0.64 | K9: 280.27 | L9: 26.77 | M9: 92.09 | N9: 2.4 | O9: 0 | P9: 0.6 | Q9: 4.67
A10: 45510.083 | B10: 9.16 | C10: 4.26 | D10: 14 | E10: 11.02 | F10: 4.86 | G10: 41.81 | H10: 15.85 | I10: 8.21 | J10: 0.53 | K10: 277.4 | L10: 26.58 | M10: 94.64 | N10: 2.3 | O10: 0 | P10: 0.56 | Q10: 4.69
A11: 45510.125 | B11: 9.14 | C11: 4.28 | D11: 14 | E11: 9.91 | F11: 5.3 | G11: 30.29 | H11: 17.07 | I11: 7.27 | J11: 0.48 | K11: 280.72 | L11: 26.49 | M11: 94.08 | N11: 2.3 | O11: 0 | P11: 0.54 | Q11: 4.69
A12: 45510.167 | B12: 9.1 | C12: 4.34 | D12: 14 | E12: 9.16 | F12: 6.65 | G12: 29.09 | H12: 17.07 | I12: 6.27 | J12: 0.5 | K12: 280.12 | L12: 26.17 | M12: 95.44 | N12: 2.3 | O12: 0 | P12: 0.52 | Q12: 4.67
A13: 45510.208 | B13: 9.11 | C13: 4.32 | D13: 14 | E13: 8.18 | F13: 5.96 | G13: 24.98 | H13: 12.78 | I13: 5.59 | J13: 0.44 | K13: 281.39 | L13: 25.84 | M13: 96.99 | N13: 2.1 | O13: 0 | P13: 0.48 | Q13: 4.68
A14: 45510.25 | B14: 9.12 | C14: 4.31 | D14: 14 | E14: 7.53 | F14: 5.57 | G14: 17.57 | H14: 9.81 | I14: 5.07 | J14: 0.23 | K14: 273.77 | L14: 25.66 | M14: 98.12 | N14: 17.3 | O14: 0 | P14: 0.45 | Q14: 4.67
A15: 45510.292 | B15: 9.11 | C15: 4.34 | D15: 14 | E15: 7.63 | F15: 5.12 | G15: 25.07 | H15: 9.32 | I15: 5.24 | J15: 0.53 | K15: 282.47 | L15: 26.27 | M15: 97.56 | N15: 51.6 | O15: 0 | P15: 0.48 | Q15: 4.67
A16: 45510.333 | B16: 9.13 | C16: 4.31 | D16: 14 | E16: 7.99 | F16: 5.38 | G16: 29.66 | H16: 10.21 | I16: 5.32 | J16: 0.57 | K16: 279.27 | L16: 27.26 | M16: 93.98 | N16: 104.9 | O16: 0 | P16: 0.45 | Q16: 4.68
A17: 45510.375 | B17: 9.1 | C17: 4.35 | D17: 14 | E17: 9.37 | F17: 5.42 | G17: 39.79 | H17: 16.89 | I17: 5.93 | J17: 0.64 | K17: 295.66 | L17: 28.21 | M17: 88.71 | N17: 157.6 | O17: 0 | P17: 0.5 | Q17: 4.66
A18: 45510.417 | B18: 9.09 | C18: 4.34 | D18: 14 | E18: 10.09 | F18: 4.95 | G18: 39.79 | H18: 16.89 | I18: 6.23 | J18: 0.85 | K18: 307.81 | L18: 28.81 | M18: 83.05 | N18: 175.1 | O18: 0 | P18: 0.52 | Q18: 4.66
A19: 45510.458 | B19: 9.12 | C19: 4.32 | D19: 14 | E19: 10.7 | F19: 6.08 | G19: 48.92 | H19: 13.4 | I19: 6.31 | J19: 1.19 | K19: 316.43 | L19: 29.98 | M19: 78.2 | N19: 479.1 | O19: 0 | P19: 0.53 | Q19: 4.68
A20: 45510.5 | B20: 9.09 | C20: 4.36 | D20: 14 | E20: 10.63 | F20: 5.54 | G20: 54.71 | H20: 18.08 | I20: 6.09 | J20: 0.86 | K20: 309.96 | L20: 31.06 | M20: 74.06 | N20: 501 | O20: 0 | P20: 0.52 | Q20: 4.67
A21: 45510.542 | B21: 10.79 | C21: 4.41 | D21: 15.34 | E21: 10.54 | F21: 21.44 | G21: 54.71 | H21: 18.39 | I21: 5.58 | J21: 0.96 | K21: 293.62 | L21: 31.47 | M21: 71.45 | N21: 650.3 | O21: 0 | P21: 0.53 | Q21: 4.67
A22: 45510.583 | B22: 11.75 | C22: 4.36 | D22: 16.07 | E22: Calib. | F22: Calib. | G22: Calib. | H22: Calib. | I22: 7.3 | J22: 0.55 | K22: 286.49 | L22: 31.36 | M22: 77.13 | N22: 237.3 | O22: 0 | P22: 0.48 | Q22: 4.66
A23: 45510.625 | B23: 8.99 | C23: 4.58 | D23: 14 | E23: 6.21 | F23: 23.75 | G23: Calib. | H23: Calib. | I23: 12.64 | J23: 0.56 | K23: 357.15 | L23: 30.9 | M23: 80.41 | N23: 173.3 | O23: 0 | P23: 0.39 | Q23: 4.66
A24: 45510.667 | B24: 8.97 | C24: 4.56 | D24: 14 | E24: 6.76 | F24: 9.07 | G24: 18.54 | H24: 2.15 | I24: 9.8 | J24: 1.26 | K24: 337.52 | L24: 25.99 | M24: 101.29 | N24: 16.8 | O24: 12.8 | P24: 0.35 | Q24: 4.66
A25: 45510.708 | B25: 9.04 | C25: 4.52 | D25: 14 | E25: 4.99 | F25: 4.74 | G25: 23.59 | H25: 6.84 | I25: 5.65 | J25: 0.91 | K25: 302.86 | L25: 25.36 | M25: 101.48 | N25: 9.9 | O25: 1.6 | P25: 0.36 | Q25: 4.66
A26: 45510.75 | B26: 9.09 | C26: 4.41 | D26: 14 | E26: 6.04 | F26: 2.53 | G26: 35.1 | H26: 6.7 | I26: 4.54 | J26: 0.56 | K26: 284.12 | L26: 24.59 | M26: 102.75 | N26: 4.1 | O26: 2.2 | P26: 0.38 | Q26: 4.67
A27: 45510.792 | B27: 9.02 | C27: 4.46 | D27: 14 | E27: 6.92 | F27: 2.42 | G27: 33.55 | H27: 9.89 | I27: 4.64 | J27: 0.72 | K27: 279.33 | L27: 24.6 | M27: 102.87 | N27: 3 | O27: 1 | P27: 0.39 | Q27: 4.69
A28: 45510.833 | B28: 9.07 | C28: 4.41 | D28: 14 | E28: 7.35 | F28: 2.46 | G28: 27.7 | H28: 9.34 | I28: 4.68 | J28: 0.44 | K28: 272.61 | L28: 24.38 | M28: 102.53 | N28: 3.2 | O28: 0.8 | P28: 0.38 | Q28: 4.68
A29: 45510.875 | B29: 9.1 | C29: 4.36 | D29: 14 | E29: 8.37 | F29: 2.32 | G29: 30.62 | H29: 8.8 | I29: 4.74 | J29: 0.26 | K29: 267.46 | L29: 24.44 | M29: 103.21 | N29: 2.2 | O29: 0.2 | P29: 0.38 | Q29: 4.67
A30: 45510.917 | B30: 9.09 | C30: 4.38 | D30: 14 | E30: 8.79 | F30: 2.63 | G30: 29.98 | H30: 8.38 | I30: 4.59 | J30: 0.36 | K30: 273.51 | L30: 24.55 | M30: 103.25 | N30: 2.5 | O30: 0.2 | P30: 0.36 | Q30: 4.68
A31: 45510.958 | B31: 9.05 | C31: 4.42 | D31: 14 | E31: 7.87 | F31: 3.7 | G31: 26.68 | H31: 6.71 | I31: 4.39 | J31: 0.38 | K31: 273.38 | L31: 24.74 | M31: 102.88 | N31: 2.4 | O31: 0.2 | P31: 0.34 | Q31: 4.68
A32: 45511 | B32: 9.07 | C32: 4.38 | D32: 14 | E32: 6.91 | F32: 4.76 | G32: 29.15 | H32: 5.08 | I32: 4.24 | J32: 0.37 | K32: 279.85 | L32: 24.82 | M32: 103.06 | N32: 2.5 | O32: 0.2 | P32: 0.3 | Q32: 4.67
A34: Min | B34: =MIN(B9:B32) -> 8.97 | C34: =MIN(C9:C32) -> 4.26 | D34: =MIN(D9:D32) -> 14 | E34: =MIN(E9:E32) -> 4.99 | F34: =MIN(F9:F32) -> 2.32 | G34: =MIN(G9:G32) -> 17.57 | H34: =MIN(H9:H32) -> 2.15 | I34: =MIN(I9:I32) -> 4.24 | ... Q34: =MIN(Q9:Q32) -> 4.66
A35: Max | B35: =MAX(B9:B32) -> 11.75 | C35: =MAX(C9:C32) -> 4.58 | D35: =MAX(D9:D32) -> 16.07 | E35: =MAX(E9:E32) -> 11.02 | F35: =MAX(F9:F32) -> 23.75 | G35: =MAX(G9:G32) -> 54.71 | H35: =MAX(H9:H32) -> 18.39 | I35: =MAX(I9:I32) -> 12.64 | ... Q35: =MAX(Q9:Q32) -> 4.69
A36: Avg | B36: =AVERAGE(B9:B32) -> 9.2691667 | C36: =AVERAGE(C9:C32) -> 4.3766667 | D36: =AVERAGE(D9:D32) -> 14.1425 | E36: =AVERAGE(E9:E32) -> 8.4273913 | F36: =AVERAGE(F9:F32) -> 6.3182609 | G36: =AVERAGE(G9:G32) -> 33.323182 | H36: =AVERAGE(H9:H32) -> 11.489545 | I36: =AVERAGE(I9:I32) -> 6.1895833 | ... Q36: =AVERAGE(Q9:Q32) -> 4.6725
A37: Stdev | B37: =STDEV(B9:B32) -> 0.63404099 | C37: =STDEV(C9:C32) -> 0.08473317 | D37: =STDEV(D9:D32) -> 0.49313769 | E37: =STDEV(E9:E32) -> 1.7404524 | F37: =STDEV(F9:F32) -> 5.3861689 | G37: =STDEV(G9:G32) -> 10.328663 | H37: =STDEV(H9:H32) -> 4.7188008 | I37: =STDEV(I9:I32) -> 1.9607307 | ... Q37: =STDEV(Q9:Q32) -> 0.0098907071
A38: Num | B38: =COUNT(B9:B32) -> 24 | C38: =COUNT(C9:C32) -> 24 | D38: =COUNT(D9:D32) -> 24 | E38: 24 | F38: 24 | G38: 24 | H38: 24 | I38: =COUNT(I9:I32) -> 24 | J38: =COUNT(J9:J32) -> 24 | K38: =COUNT(K9:K32) -> 24 | L38: =COUNT(L9:L32) -> 24 | M38: =COUNT(M9:M32) -> 24 | N38: =COUNT(N9:N32) -> 24 | O38: =COUNT(O9:O32) -> 24 | P38: =COUNT(P9:P32) -> 24 | Q38: =COUNT(Q9:Q32) -> 24
A39: DCR | B39: =IF(B38>=22,">90%",IF(B38<=22,"<90%")) -> >90% | C39: =IF(C38>=22,">90%",IF(C38<=22,"<90%")) -> >90% | D39: =IF(D38>=22,">90%",IF(D38<=22,"<90%")) -> >90% | E39: =IF(E38>=22,">90%",IF(E38<=22,"<90%")) -> >90% | F39: =IF(F38>=22,">90%",IF(F38<=22,"<90%")) -> >90% | G39: =IF(G38>=22,">90%",IF(G38<=22,"<90%")) -> >90% | H39: =IF(H38>=22,">90%",IF(H38<=22,"<90%")) -> >90% | I39: =IF(I38>=22,">90%",IF(I38<=22,"<90%")) -> >90% | ... Q39: =IF(Q38>=22,">90%",IF(Q38<=22,"<90%")) -> >90%
A40: Status | B40: =IF(B38>=22,"OK",IF(B38<=22,"LESS")) -> OK | C40: =IF(C38>=22,"OK",IF(C38<=22,"LESS")) -> OK | D40: =IF(D38>=22,"OK",IF(D38<=22,"LESS")) -> OK | E40: =IF(E38>=22,"OK",IF(E38<=22,"LESS")) -> OK | F40: =IF(F38>=22,"OK",IF(F38<=22,"LESS")) -> OK | G40: =IF(G38>=22,"OK",IF(G38<=22,"LESS")) -> OK | H40: =IF(H38>=22,"OK",IF(H38<=22,"LESS")) -> OK | I40: =IF(I38>=22,"OK",IF(I38<=22,"LESS")) -> OK | ... Q40: =IF(Q38>=22,"OK",IF(Q38<=22,"LESS")) -> OK
A43: Done by | B43: AKASH
A45: Comment

Sheet 07
A1: Station: | B1: IGKV ,RAIPUR
A2: Date: | B2: =$A$9 -> 45511.042 | D2: Power Off | G2: Pw.Off | L2: Link Fail | N2: Link F | P2: Maintenance | R2: Maint.
A3: Report Type: | B3: Mean | D3: Calibration | G3: Calib. | L3: Data Fail | N3: Data F | P3: Invalid | R3: Invalid
A4: Time Base: | B4: 01 Hour | D4: Zero Referrence | G4: Z.Ref | L4: Warm Up | N4: Wm. Up
A7: Date & Time | B7: NO | C7: NO2 | D7: NOX | E7: SO2 | F7: O3 | G7: PM 10 | H7: PM 2.5 | I7: BENZ | J7: WS | K7: WD | L7: TEMP | M7: HUM | N7: SR | O7: RG | P7: CO | Q7: NH3
B8: ug/m3 | C8: ug/m3 | D8: ppb | E8: ug/m3 | F8: ug/m3 | G8: ug/m3 | H8: ug/m3 | I8: ug/m3 | J8: m/sec | K8: deg | L8: degreC | M8: % | N8: w/m2 | O8: mm | P8: mg/m3 | Q8: ug/m3
A9: 45511.042 | B9: 9.32 | C9: 4.2 | D9: 14.07 | E9: 6.85 | F9: 5.27 | G9: 27.48 | H9: 9.26 | I9: 4.03 | J9: 0.68 | K9: 279.05 | L9: 24.87 | M9: 102.25 | N9: 2.8 | O9: 1.8 | P9: 0.28 | Q9: 4.67
A10: 45511.083 | B10: 9.32 | C10: 4.09 | D10: 14.05 | E10: 7.2 | F10: 4.12 | G10: 20.17 | H10: 8.98 | I10: 4.04 | J10: 0.8 | K10: 283.1 | L10: 24.31 | M10: 101.99 | N10: 2.8 | O10: 0 | P10: 0.28 | Q10: 4.67
A11: 45511.125 | B11: 9.31 | C11: 4.09 | D11: 14.05 | E11: 9.02 | F11: 4.2 | G11: 15.11 | H11: 11.27 | I11: 3.77 | J11: 0.56 | K11: 280.47 | L11: 24.22 | M11: 101.88 | N11: 2.6 | O11: 0 | P11: 0.29 | Q11: 4.67
A12: 45511.167 | B12: 9.32 | C12: 4.08 | D12: 14.06 | E12: 9.67 | F12: 2.65 | G12: 12.62 | H12: 10.59 | I12: 4.2 | J12: 0.61 | K12: 310.61 | L12: 24.32 | M12: 101.87 | N12: 3.1 | O12: 0 | P12: 0.33 | Q12: 4.67
A13: 45511.208 | B13: 9.35 | C13: 4.06 | D13: 14.06 | E13: 10.09 | F13: 2.32 | G13: 14.25 | H13: 8.14 | I13: 4.63 | J13: 0.9 | K13: 285.91 | L13: 24.02 | M13: 101.82 | N13: 3.2 | O13: 7 | P13: 0.33 | Q13: 4.67
A14: 45511.25 | B14: 10.45 | C14: 4.07 | D14: 14.51 | E14: 10.01 | F14: 2.22 | G14: 13.59 | H14: 6.31 | I14: 4.6 | J14: 0.16 | K14: 258.47 | L14: 23.99 | M14: 101.67 | N14: 10.7 | O14: 0.2 | P14: 0.48 | Q14: 4.67
A15: 45511.292 | B15: 9.33 | C15: 6 | D15: 14.31 | E15: 3.7 | F15: 6.12 | G15: 12.97 | H15: 5.44 | I15: 5.32 | J15: 0.44 | K15: 275.2 | L15: 24.09 | M15: 101.53 | N15: 26.3 | O15: 0 | P15: 0.51 | Q15: 4.87
A16: 45511.333 | B16: 8 | C16: 6 | D16: 14 | E16: Data F | F16: 6.83 | G16: 17.56 | H16: 6.68 | I16: 5.09 | J16: 0.38 | K16: 277.82 | L16: 24.6 | M16: 101.47 | N16: 62.4 | O16: 0 | P16: 0.46 | Q16: 4.6
A17: 45511.375 | B17: 8 | C17: 6 | D17: 14 | E17: Data F | F17: 6.24 | G17: 17.63 | H17: 6.39 | I17: 4.96 | J17: 0.36 | K17: 292.06 | L17: 25.07 | M17: 101.46 | N17: 74.1 | O17: 0.2 | P17: 0.47 | Q17: 4.59
A18: 45511.417 | B18: 8 | C18: 6 | D18: 14 | E18: Data F | F18: 6.3 | G18: 19.65 | H18: 7.13 | I18: 5.38 | J18: 0.43 | K18: 283.75 | L18: 25.53 | M18: 100.65 | N18: 101.5 | O18: 0.2 | P18: 0.52 | Q18: 4.59
A19: 45511.458 | B19: 8 | C19: 6 | D19: 14 | E19: 9.82 | F19: 7.13 | G19: 22.59 | H19: 8.76 | I19: 5.73 | J19: 0.61 | K19: 282.97 | L19: 26 | M19: 100.5 | N19: 99.2 | O19: 0 | P19: 0.55 | Q19: 4.58
A20: 45511.5 | B20: 8 | C20: 6 | D20: 14 | E20: 10.43 | F20: 6.6 | G20: 23.8 | H20: 14.1 | I20: 6.04 | J20: 0.52 | K20: 294.06 | L20: 26.47 | M20: 96.71 | N20: 96.5 | O20: 0 | P20: 0.6 | Q20: 4.57
A21: 45511.542 | B21: 8 | C21: 6 | D21: 14 | E21: 11.08 | F21: 6.28 | G21: 44.13 | H21: 18.02 | I21: 6.51 | J21: 0.42 | K21: 298.57 | L21: 26.58 | M21: 96.17 | N21: 94 | O21: 0.2 | P21: 0.63 | Q21: 4.58
A22: 45511.583 | B22: 8 | C22: 6 | D22: 14 | E22: 11.24 | F22: 6.39 | G22: 43.33 | H22: 17.47 | I22: 6.95 | J22: 0.41 | K22: 326.66 | L22: 27.04 | M22: 95.54 | N22: 94.7 | O22: 0 | P22: 0.69 | Q22: 4.56
A23: 45511.625 | B23: 8 | C23: 6 | D23: 14 | E23: 11.4 | F23: 6.55 | G23: 45.39 | H23: 24.65 | I23: 7.16 | J23: 0.14 | K23: 306.4 | L23: 27.12 | M23: 96.86 | N23: 55.1 | O23: 0.4 | P23: 0.6 | Q23: 4.57
A24: 45511.667 | B24: 8 | C24: 6 | D24: 14 | E24: 11.8 | F24: 6.92 | G24: 45 | H24: 22.71 | I24: 7.29 | J24: 0.17 | K24: 313.38 | L24: 26.96 | M24: 95.62 | N24: 70.3 | O24: 0.2 | P24: 0.63 | Q24: 4.56
A25: 45511.708 | B25: 8 | C25: 6 | D25: 14 | E25: 10.55 | F25: 7.35 | G25: 46.11 | H25: 18.92 | I25: 7.18 | J25: 0.24 | K25: 270.81 | L25: 26.78 | M25: 98.65 | N25: 28.1 | O25: 0.8 | P25: 0.62 | Q25: 4.58
A26: 45511.75 | B26: 8 | C26: 6 | D26: 14 | E26: 10.01 | F26: 7.89 | G26: 45.1 | H26: 24.08 | I26: 7.25 | J26: 0.42 | K26: 279.35 | L26: 26.22 | M26: 99.21 | N26: 12.8 | O26: 0.2 | P26: 0.65 | Q26: 4.57
A27: 45511.792 | B27: 8 | C27: 6 | D27: 14 | E27: 10.06 | F27: 7.84 | G27: 43.84 | H27: 22.58 | I27: 7.25 | J27: 0.83 | K27: 304.13 | L27: 26.09 | M27: 98.98 | N27: 4.5 | O27: 1.6 | P27: 0.61 | Q27: 4.58
A28: 45511.833 | B28: 8 | C28: 6 | D28: 14 | E28: 9.5 | F28: 6.19 | G28: 41.62 | H28: 18.47 | I28: 7.14 | J28: 0.87 | K28: 283.16 | L28: 24.6 | M28: 99.23 | N28: 2.5 | O28: 0 | P28: 0.57 | Q28: 4.58
A29: 45511.875 | B29: 8 | C29: 6 | D29: 14 | E29: 9.44 | F29: 5.84 | G29: 31.2 | H29: 17.49 | I29: 6.85 | J29: 0.63 | K29: 285.17 | L29: 24.56 | M29: 98.97 | N29: 2.4 | O29: 0 | P29: 0.54 | Q29: 4.57
A30: 45511.917 | B30: 8 | C30: 6 | D30: 14 | E30: 10 | F30: 5.58 | G30: 24.49 | H30: 13.34 | I30: 7.1 | J30: 0.51 | K30: 281.84 | L30: 24.77 | M30: 99.04 | N30: 2.6 | O30: 0 | P30: 0.59 | Q30: 4.58
... A32: 45512 | B32: 8 | C32: 6 | D32: 14 | E32: 11.1 | F32: 5.56 | G32: 21.45 | H32: 9.05 | I32: 6.41 | J32: 0.56 | K32: 282.87 | L32: 24.85 | M32: 98.63 | N32: 2.9 | O32: 0 | P32: 0.5 | Q32: 4.59
A34: Min | B34: =MIN(B9:B32) -> 8 | C34: =MIN(C9:C32) -> 4.06 | D34: =MIN(D9:D32) -> 14 | E34: =MIN(E9:E32) -> 3.7 | F34: =MIN(F9:F32) -> 2.22 | G34: =MIN(G9:G32) -> 12.62 | H34: =MIN(H9:H32) -> 5.44 | I34: =MIN(I9:I32) -> 3.77 | ... Q34: =MIN(Q9:Q32) -> 4.56
A35: Max | B35: =MAX(B9:B32) -> 10.45 | C35: =MAX(C9:C32) -> 6 | D35: =MAX(D9:D32) -> 14.51 | E35: =MAX(E9:E32) -> 11.8 | F35: =MAX(F9:F32) -> 7.89 | G35: =MAX(G9:G32) -> 46.11 | H35: =MAX(H9:H32) -> 24.65 | I35: =MAX(I9:I32) -> 7.29 | ... Q35: =MAX(Q9:Q32) -> 4.87
A36: Avg | B36: =AVERAGE(B9:B32) -> 8.4333333 | C36: =AVERAGE(C9:C32) -> 5.5245833 | D36: =AVERAGE(D9:D32) -> 14.04625 | E36: =AVERAGE(E9:E32) -> 9.6780952 | F36: =AVERAGE(F9:F32) -> 5.7558333 | G36: =AVERAGE(G9:G32) -> 27.995417 | H36: =AVERAGE(H9:H32) -> 13.369167 | I36: =AVERAGE(I9:I32) -> 5.9129167 | ... Q36: =AVERAGE(Q9:Q32) -> 4.6133333
A37: Stdev | B37: =STDEV(B9:B32) -> 0.72323348 | C37: =STDEV(C9:C32) -> 0.84149442 | D37: =STDEV(D9:D32) -> 0.11831471 | E37: =STDEV(E9:E32) -> 1.8252113 | F37: =STDEV(F9:F32) -> 1.5889754 | G37: =STDEV(G9:G32) -> 12.607514 | H37: =STDEV(H9:H32) -> 6.2308614 | I37: =STDEV(I9:I32) -> 1.2436289 | ... Q37: =STDEV(Q9:Q32) -> 0.068503676
A38: Num | B38: =COUNT(B9:B32) -> 24 | C38: =COUNT(C9:C32) -> 24 | D38: =COUNT(D9:D32) -> 24 | E38: 24 | F38: =COUNT(F9:F32) -> 24 | G38: =COUNT(G9:G32) -> 24 | H38: =COUNT(H9:H32) -> 24 | I38: =COUNT(I9:I32) -> 24 | J38: =COUNT(J9:J32) -> 24 | K38: =COUNT(K9:K32) -> 24 | L38: =COUNT(L9:L32) -> 24 | M38: =COUNT(M9:M32) -> 24 | ... Q38: =COUNT(Q9:Q32) -> 24
A39: DCR | B39: =IF(B38>=22,">90%",IF(B38<=22,"<90%")) -> >90% | C39: =IF(C38>=22,">90%",IF(C38<=22,"<90%")) -> >90% | D39: =IF(D38>=22,">90%",IF(D38<=22,"<90%")) -> >90% | E39: =IF(E38>=22,">90%",IF(E38<=22,"<90%")) -> >90% | F39: =IF(F38>=22,">90%",IF(F38<=22,"<90%")) -> >90% | G39: =IF(G38>=22,">90%",IF(G38<=22,"<90%")) -> >90% | H39: =IF(H38>=22,">90%",IF(H38<=22,"<90%")) -> >90% | I39: =IF(I38>=22,">90%",IF(I38<=22,"<90%")) -> >90% | ... Q39: =IF(Q38>=22,">90%",IF(Q38<=22,"<90%")) -> >90%
A40: Status | B40: =IF(B38>=22,"OK",IF(B38<=22,"LESS")) -> OK | C40: =IF(C38>=22,"OK",IF(C38<=22,"LESS")) -> OK | D40: =IF(D38>=22,"OK",IF(D38<=22,"LESS")) -> OK | E40: =IF(E38>=22,"OK",IF(E38<=22,"LESS")) -> OK | F40: =IF(F38>=22,"OK",IF(F38<=22,"LESS")) -> OK | G40: =IF(G38>=22,"OK",IF(G38<=22,"LESS")) -> OK | H40: =IF(H38>=22,"OK",IF(H38<=22,"LESS")) -> OK | I40: =IF(I38>=22,"OK",IF(I38<=22,"LESS")) -> OK | ... Q40: =IF(Q38>=22,"OK",IF(Q38<=22,"LESS")) -> OK
A43: Done by | B43: AKASH
A45: Comment

Sheet 08
A1: Station: | B1: IGKV ,RAIPUR
A2: Date: | B2: =$A$9 -> 45512.042 | D2: Power Off | G2: Pw.Off | L2: Link Fail | N2: Link F | P2: Maintenance | R2: Maint.
A3: Report Type: | B3: Mean | D3: Calibration | G3: Calib. | L3: Data Fail | N3: Data F | P3: Invalid | R3: Invalid
A4: Time Base: | B4: 01 Hour | D4: Zero Referrence | G4: Z.Ref | L4: Warm Up | N4: Wm. Up
A7: Date & Time | B7: NO | C7: NO2 | D7: NOX | E7: SO2 | F7: O3 | G7: PM 10 | H7: PM 2.5 | I7: BENZ | J7: WS | K7: WD | L7: TEMP | M7: HUM | N7: SR | O7: RG | P7: CO | Q7: NH3
B8: ug/m3 | C8: ug/m3 | D8: ppb | E8: ug/m3 | F8: ug/m3 | G8: ug/m3 | H8: ug/m3 | I8: ug/m3 | J8: m/sec | K8: deg | L8: degreC | M8: % | N8: w/m2 | O8: mm | P8: mg/m3 | Q8: ug/m3
A9: 45512.042 | B9: 9.27 | C9: 4.09 | D9: 14.01 | E9: 11.69 | F9: 5.29 | G9: 17.57 | H9: 8.42 | I9: 6.09 | J9: 0.66 | K9: 282.34 | L9: 24.68 | M9: 97.9 | N9: 2.8 | O9: 0 | P9: 0.47 | Q9: 4.56
A10: 45512.083 | B10: 9.3 | C10: 4.08 | D10: 14.03 | E10: 11.03 | F10: 5.99 | G10: 17.16 | H10: 6.44 | I10: 5.9 | J10: 0.72 | K10: 282.46 | L10: 24.51 | M10: 98.08 | N10: 2.5 | O10: 0 | P10: 0.46 | Q10: 4.6
A11: 45512.125 | B11: 9.27 | C11: 4.09 | D11: 14.01 | E11: 10.72 | F11: 5.78 | G11: 18.09 | H11: 5.41 | I11: 7.39 | J11: 0.76 | K11: 287.67 | L11: 24.47 | M11: 96.33 | N11: 2.5 | O11: 0.2 | P11: 0.56 | Q11: 4.58
A12: 45512.167 | B12: 9.24 | C12: 4.11 | D12: 14 | E12: 11.04 | F12: 5.39 | G12: 17.38 | H12: 12.41 | I12: 8.6 | J12: 0.64 | K12: 284.2 | L12: 24.39 | M12: 98.4 | N12: 2.5 | O12: 0.6 | P12: 0.65 | Q12: 4.59
A13: 45512.208 | B13: 9.27 | C13: 4.07 | D13: 14.01 | E13: 10.53 | F13: 5.58 | G13: 35.13 | H13: 17.53 | I13: 8.68 | J13: 0.57 | K13: 281.51 | L13: 24.21 | M13: 99.62 | N13: 2.4 | O13: 0 | P13: 0.63 | Q13: 4.58
A14: 45512.25 | B14: 9.28 | C14: 4.07 | D14: 14 | E14: 10.15 | F14: 5.86 | G14: 33.63 | H14: 16.35 | I14: 8.35 | J14: 0.47 | K14: 280.37 | L14: 24.37 | M14: 99.74 | N14: 10.3 | O14: 0 | P14: 0.59 | Q14: 4.58
A15: 45512.292 | B15: 9.26 | C15: 4.09 | D15: 14 | E15: 10.76 | F15: 5.38 | G15: 28.92 | H15: 12.53 | I15: 8.78 | J15: 0.55 | K15: 299.4 | L15: 24.89 | M15: 99.04 | N15: 38.4 | O15: 0 | P15: 0.64 | Q15: 4.57
A16: 45512.333 | B16: 9.26 | C16: 4.08 | D16: 14.01 | E16: 11.1 | F16: 5.47 | G16: 49.37 | H16: 11.75 | I16: 8.77 | J16: 0.69 | K16: 309.15 | L16: 24.94 | M16: 97.63 | N16: 37.7 | O16: 0.2 | P16: 0.62 | Q16: 4.58
A17: 45512.375 | B17: 9.27 | C17: 4.08 | D17: 14 | E17: 11.32 | F17: 5.29 | G17: 51.06 | H17: 16.46 | I17: 8.06 | J17: 1.06 | K17: 312.05 | L17: 24.25 | M17: 98.33 | N17: 61 | O17: 0.4 | P17: 0.59 | Q17: 4.58
A18: 45512.417 | B18: 9.26 | C18: 4.09 | D18: 14 | E18: 11.71 | F18: 5.35 | G18: 48.75 | H18: 15.52 | I18: 7.24 | J18: 0.85 | K18: 297.65 | L18: 24.36 | M18: 98.03 | N18: 105.8 | O18: 0.4 | P18: 0.54 | Q18: 4.58
A19: 45512.458 | B19: 9.28 | C19: 4.07 | D19: 14 | E19: 9.52 | F19: 6 | G19: 38.52 | H19: 16.43 | I19: 6.57 | J19: 0.71 | K19: 285.99 | L19: 25.23 | M19: 97.46 | N19: 151.3 | O19: 0.2 | P19: 0.53 | Q19: 4.58
A20: 45512.5 | B20: 9.29 | C20: 4.1 | D20: 14.03 | E20: 8.47 | F20: 6.96 | G20: 41.82 | H20: 15.65 | I20: 6.34 | J20: 0.67 | K20: 286.55 | L20: 25.86 | M20: 96.97 | N20: 161.3 | O20: 0.6 | P20: 0.51 | Q20: 4.59
... A32: 45513 | B32: 9.31 | C32: 4.09 | D32: 14.02 | E32: 9.31 | F32: 6.56 | G32: 26.14 | H32: 13.73 | I32: 5.72 | J32: 0.53 | K32: 284.86 | L32: 25.13 | M32: 95.5 | N32: 2.3 | O32: 0 | P32: 0.4 | Q32: 4.59
A34: Min | B34: =MIN(B9:B32) -> 9.24 | C34: =MIN(C9:C32) -> 4.07 | D34: =MIN(D9:D32) -> 14 | E34: =MIN(E9:E32) -> 7.18 | F34: =MIN(F9:F32) -> 5.29 | G34: =MIN(G9:G32) -> 17.16 | H34: =MIN(H9:H32) -> 5.41 | I34: =MIN(I9:I32) -> 5.44 | ... Q34: =MIN(Q9:Q32) -> 4.56
A35: Max | B35: =MAX(B9:B32) -> 9.31 | C35: =MAX(C9:C32) -> 4.12 | D35: =MAX(D9:D32) -> 14.04 | E35: =MAX(E9:E32) -> 11.71 | F35: =MAX(F9:F32) -> 10.7 | G35: =MAX(G9:G32) -> 51.06 | H35: =MAX(H9:H32) -> 19.49 | I35: =MAX(I9:I32) -> 8.78 | ... Q35: =MAX(Q9:Q32) -> 4.6
A36: Avg | B36: =AVERAGE(B9:B32) -> 9.2725 | C36: =AVERAGE(C9:C32) -> 4.09 | D36: =AVERAGE(D9:D32) -> 14.011667 | E36: =AVERAGE(E9:E32) -> 9.79125 | F36: =AVERAGE(F9:F32) -> 6.9933333 | G36: =AVERAGE(G9:G32) -> 34.453333 | H36: =AVERAGE(H9:H32) -> 15.18 | I36: =AVERAGE(I9:I32) -> 6.7633333 | ... Q36: =AVERAGE(Q9:Q32) -> 4.5808333
A37: Stdev | B37: =STDEV(B9:B32) -> 0.018474424 | C37: =STDEV(C9:C32) -> 0.012853692 | D37: =STDEV(D9:D32) -> 0.013405601 | E37: =STDEV(E9:E32) -> 1.4307958 | F37: =STDEV(F9:F32) -> 1.6792951 | G37: =STDEV(G9:G32) -> 10.072635 | H37: =STDEV(H9:H32) -> 3.9055846 | I37: =STDEV(I9:I32) -> 1.1494674 | ... Q37: =STDEV(Q9:Q32) -> 0.0092861124
A38: Num | B38: =COUNT(B9:B32) -> 24 | C38: =COUNT(C9:C32) -> 24 | D38: =COUNT(D9:D32) -> 24 | E38: =COUNT(E9:E32) -> 24 | F38: =COUNT(F9:F32) -> 24 | G38: =COUNT(G9:G32) -> 24 | H38: =COUNT(H9:H32) -> 24 | I38: =COUNT(I9:I32) -> 24 | ... Q38: =COUNT(Q9:Q32) -> 24
A39: DCR | B39: =IF(B38>=22,">90%",IF(B38<=22,"<90%")) -> >90% | C39: =IF(C38>=22,">90%",IF(C38<=22,"<90%")) -> >90% | D39: =IF(D38>=22,">90%",IF(D38<=22,"<90%")) -> >90% | E39: =IF(E38>=22,">90%",IF(E38<=22,"<90%")) -> >90% | F39: =IF(F38>=22,">90%",IF(F38<=22,"<90%")) -> >90% | G39: =IF(G38>=22,">90%",IF(G38<=22,"<90%")) -> >90% | H39: =IF(H38>=22,">90%",IF(H38<=22,"<90%")) -> >90% | I39: =IF(I38>=22,">90%",IF(I38<=22,"<90%")) -> >90% | ... Q39: =IF(Q38>=22,">90%",IF(Q38<=22,"<90%")) -> >90%
A40: Status | B40: =IF(B38>=22,"OK",IF(B38<=22,"LESS")) -> OK | C40: =IF(C38>=22,"OK",IF(C38<=22,"LESS")) -> OK | D40: =IF(D38>=22,"OK",IF(D38<=22,"LESS")) -> OK | E40: =IF(E38>=22,"OK",IF(E38<=22,"LESS")) -> OK | F40: =IF(F38>=22,"OK",IF(F38<=22,"LESS")) -> OK | G40: =IF(G38>=22,"OK",IF(G38<=22,"LESS")) -> OK | H40: =IF(H38>=22,"OK",IF(H38<=22,"LESS")) -> OK | I40: =IF(I38>=22,"OK",IF(I38<=22,"LESS")) -> OK | ... Q40: =IF(Q38>=22,"OK",IF(Q38<=22,"LESS")) -> OK
A43: Done by | B43: AKASH
A45: Comment

Sheet 09
A1: Station: | B1: IGKV ,RAIPUR
A2: Date: | B2: =$A$9 -> 45513.042 | D2: Power Off | G2: Pw.Off | L2: Link Fail | N2: Link F | P2: Maintenance | R2: Maint.
A3: Report Type: | B3: Mean | D3: Calibration | G3: Calib. | L3: Data Fail | N3: Data F | P3: Invalid | R3: Invalid
A4: Time Base: | B4: 01 Hour | D4: Zero Referrence | G4: Z.Ref | L4: Warm Up | N4: Wm. Up
A7: Date & Time | B7: NO | C7: NO2 | D7: NOX | E7: SO2 | F7: O3 | G7: PM 10 | H7: PM 2.5 | I7: BENZ | J7: WS | K7: WD | L7: TEMP | M7: HUM | N7: SR | O7: RG | P7: CO | Q7: NH3
B8: ug/m3 | C8: ug/m3 | D8: ppb | E8: ug/m3 | F8: ug/m3 | G8: ug/m3 | H8: ug/m3 | I8: ug/m3 | J8: m/sec | K8: deg | L8: degreC | M8: % | N8: w/m2 | O8: mm | P8: mg/m3 | Q8: ug/m3
A9: 45513.042 | B9: 9.22 | C9: 4.15 | D9: 14 | E9: 9.26 | F9: 6.38 | G9: 25.54 | H9: 12.06 | I9: 5.57 | J9: 0.5 | K9: 279.65 | L9: 24.84 | M9: 96.35 | N9: 2.1 | O9: 0 | P9: 0.4 | Q9: 4.57
A10: 45513.083 | B10: 9.24 | C10: 4.11 | D10: 14 | E10: 9.97 | F10: 5.88 | G10: 22.89 | H10: 11.51 | I10: 5.23 | J10: 0.54 | K10: 279.52 | L10: 24.71 | M10: 96.13 | N10: 2.2 | O10: 0 | P10: 0.37 | Q10: 4.63
A11: 45513.125 | B11: 9.24 | C11: 4.11 | D11: 14 | E11: 10.52 | F11: 5.59 | G11: 21.49 | H11: 11.18 | I11: 4.81 | J11: 0.52 | K11: 281.54 | L11: 24.71 | M11: 95.44 | N11: 2.4 | O11: 0 | P11: 0.36 | Q11: 4.64
A12: 45513.167 | B12: 9.23 | C12: 4.13 | D12: 14 | E12: 10.98 | F12: 5.67 | G12: 19.59 | H12: 8.98 | I12: 4.44 | J12: 0.66 | K12: 284.8 | L12: 24.66 | M12: 94.69 | N12: 2.3 | O12: 0 | P12: 0.35 | Q12: 4.57
A13: 45513.208 | B13: 9.23 | C13: 4.14 | D13: 14 | E13: 11.27 | F13: 5.62 | G13: 16.19 | H13: 6.86 | I13: 4.11 | J13: 0.81 | K13: 284 | L13: 24.71 | M13: 95.56 | N13: 2.5 | O13: 0.6 | P13: 0.33 | Q13: 4.58
A14: 45513.25 | B14: 9.24 | C14: 4.14 | D14: 14 | E14: 11.59 | F14: 5.39 | G14: 19.55 | H14: 5.94 | I14: 3.91 | J14: 0.84 | K14: 281.05 | L14: 23.84 | M14: 99.9 | N14: 4.6 | O14: 4.6 | P14: 0.33 | Q14: 4.64
A15: 45513.292 | B15: 9.2 | C15: 4.21 | D15: 14 | E15: 10.67 | F15: 5.49 | G15: 19.3 | H15: 5.52 | I15: 4.25 | J15: 0.7 | K15: 283.07 | L15: 23.54 | M15: 99.9 | N15: 23.1 | O15: 1.2 | P15: 0.33 | Q15: 4.62
A16: 45513.333 | B16: 9.19 | C16: 4.22 | D16: 14 | E16: 10.18 | F16: 5.44 | G16: 17.68 | H16: 5.49 | I16: 4.55 | J16: 0.77 | K16: 282.06 | L16: 23.64 | M16: 99.9 | N16: 56.7 | O16: 2.2 | P16: 0.32 | Q16: 4.58
A17: 45513.375 | B17: 9.19 | C17: 4.2 | D17: 14 | E17: 9.77 | F17: 5.68 | G17: 16.23 | H17: 9.21 | I17: 4.49 | J17: 0.59 | K17: 280.04 | L17: 24.69 | M17: 99.88 | N17: 120 | O17: 0 | P17: 0.31 | Q17: 4.6
A18: 45513.417 | B18: 9.19 | C18: 4.21 | D18: 14 | E18: 9.77 | F18: 5.43 | G18: 15.65 | H18: 14.42 | I18: 4.48 | J18: 0.67 | K18: 288.91 | L18: 25.59 | M18: 99.88 | N18: 156 | O18: 0 | P18: 0.31 | Q18: 4.59
A19: 45513.458 | B19: 9.19 | C19: 4.18 | D19: 14 | E19: 10.86 | F19: 5.78 | G19: 21.46 | H19: 14.09 | I19: 4.46 | J19: 0.81 | K19: 296.64 | L19: 26.6 | M19: 90.9 | N19: 244.3 | O19: 0 | P19: 0.37 | Q19: 4.78
A20: 45513.5 | B20: 9.21 | C20: 4.18 | D20: 14 | E20: 11.19 | F20: 5.51 | G20: 42.33 | H20: 18.02 | I20: 5.15 | J20: 0.73 | K20: 290.73 | L20: 26.38 | M20: 89.6 | N20: 127.3 | O20: 0 | P20: 0.45 | Q20: 4.79
... A32: 45514 | B32: 9.21 | C32: 4.17 | D32: 14 | E32: 11.81 | F32: 6.37 | G32: 71.41 | H32: 36.87 | I32: 6.64 | J32: 0.1 | K32: 217.54 | L32: 26.06 | M32: 96.74 | N32: 2.4 | O32: 0 | P32: 0.59 | Q32: 5.07
A34: Min | B34: =MIN(B9:B32) -> 9.19 | C34: =MIN(C9:C32) -> 4.11 | D34: =MIN(D9:D32) -> 14 | E34: =MIN(E9:E32) -> 9.26 | F34: =MIN(F9:F32) -> 5.39 | G34: =MIN(G9:G32) -> 15.65 | H34: =MIN(H9:H32) -> 5.49 | I34: =MIN(I9:I32) -> 3.91 | ... Q34: =MIN(Q9:Q32) -> 4.57
A35: Max | B35: =MAX(B9:B32) -> 9.24 | C35: =MAX(C9:C32) -> 4.22 | D35: =MAX(D9:D32) -> 14 | E35: =MAX(E9:E32) -> 12.38 | F35: =MAX(F9:F32) -> 12.08 | G35: =MAX(G9:G32) -> 72.74 | H35: =MAX(H9:H32) -> 37.25 | I35: =MAX(I9:I32) -> 6.64 | ... Q35: =MAX(Q9:Q32) -> 8.24
A36: Avg | B36: =AVERAGE(B9:B32) -> 9.2175 | C36: =AVERAGE(C9:C32) -> 4.1591667 | D36: =AVERAGE(D9:D32) -> 14 | E36: =AVERAGE(E9:E32) -> 10.737917 | F36: =AVERAGE(F9:F32) -> 6.90125 | G36: =AVERAGE(G9:G32) -> 44.11625 | H36: =AVERAGE(H9:H32) -> 20.04 | I36: =AVERAGE(I9:I32) -> 5.3320833 | ... Q36: =AVERAGE(Q9:Q32) -> 4.83375
A37: Stdev | B37: =STDEV(B9:B32) -> 0.016746187 | C37: =STDEV(C9:C32) -> 0.033089689 | D37: =STDEV(D9:D32) -> 0 | E37: =STDEV(E9:E32) -> 0.86369267 | F37: =STDEV(F9:F32) -> 1.9898991 | G37: =STDEV(G9:G32) -> 23.838645 | H37: =STDEV(H9:H32) -> 10.765802 | I37: =STDEV(I9:I32) -> 0.83417743 | ... Q37: =STDEV(Q9:Q32) -> 0.76350344
A38: Num | B38: =COUNT(B9:B32) -> 24 | C38: =COUNT(C9:C32) -> 24 | D38: =COUNT(D9:D32) -> 24 | E38: =COUNT(E9:E32) -> 24 | F38: =COUNT(F9:F32) -> 24 | G38: =COUNT(G9:G32) -> 24 | H38: =COUNT(H9:H32) -> 24 | I38: =COUNT(I9:I32) -> 24 | ... Q38: =COUNT(Q9:Q32) -> 24
A39: DCR | B39: =IF(B38>=22,">90%",IF(B38<=22,"<90%")) -> >90% | C39: =IF(C38>=22,">90%",IF(C38<=22,"<90%")) -> >90% | D39: =IF(D38>=22,">90%",IF(D38<=22,"<90%")) -> >90% | E39: =IF(E38>=22,">90%",IF(E38<=22,"<90%")) -> >90% | F39: =IF(F38>=22,">90%",IF(F38<=22,"<90%")) -> >90% | G39: =IF(G38>=22,">90%",IF(G38<=22,"<90%")) -> >90% | H39: =IF(H38>=22,">90%",IF(H38<=22,"<90%")) -> >90% | I39: =IF(I38>=22,">90%",IF(I38<=22,"<90%")) -> >90% | ... Q39: =IF(Q38>=22,">90%",IF(Q38<=22,"<90%")) -> >90%
A40: Status | B40: =IF(B38>=22,"OK",IF(B38<=22,"LESS")) -> OK | C40: =IF(C38>=22,"OK",IF(C38<=22,"LESS")) -> OK | D40: =IF(D38>=22,"OK",IF(D38<=22,"LESS")) -> OK | E40: =IF(E38>=22,"OK",IF(E38<=22,"LESS")) -> OK | F40: =IF(F38>=22,"OK",IF(F38<=22,"LESS")) -> OK | G40: =IF(G38>=22,"OK",IF(G38<=22,"LESS")) -> OK | H40: =IF(H38>=22,"OK",IF(H38<=22,"LESS")) -> OK | I40: =IF(I38>=22,"OK",IF(I38<=22,"LESS")) -> OK | ... Q40: =IF(Q38>=22,"OK",IF(Q38<=22,"LESS")) -> OK
A43: Done by | B43: AKASH
A45: Comment

Sheet 10
A1: Station: | B1: IGKV ,RAIPUR
A2: Date: | B2: =$A$9 -> 45514.042 | D2: Power Off | G2: Pw.Off | L2: Link Fail | N2: Link F | P2: Maintenance | R2: Maint.
A3: Report Type: | B3: Mean | D3: Calibration | G3: Calib. | L3: Data Fail | N3: Data F | P3: Invalid | R3: Invalid
A4: Time Base: | B4: 01 Hour | D4: Zero Referrence | G4: Z.Ref | L4: Warm Up | N4: Wm. Up
A7: Date & Time | B7: NO | C7: NO2 | D7: NOX | E7: SO2 | F7: O3 | G7: PM 10 | H7: PM 2.5 | I7: BENZ | J7: WS | K7: WD | L7: TEMP | M7: HUM | N7: SR | O7: RG | P7: CO | Q7: NH3
B8: ug/m3 | C8: ug/m3 | D8: ppb | E8: ug/m3 | F8: ug/m3 | G8: ug/m3 | H8: ug/m3 | I8: ug/m3 | J8: m/sec | K8: deg | L8: degreC | M8: % | N8: w/m2 | O8: mm | P8: mg/m3 | Q8: ug/m3
A9: 45514.042 | B9: 9.19 | C9: 4.21 | D9: 14 | E9: 11.96 | F9: 6.45 | G9: 71.44 | H9: 37.27 | I9: 6.91 | J9: 0.16 | K9: 206.06 | L9: 25.83 | M9: 97.09 | N9: 2.2 | O9: 0 | P9: 0.6 | Q9: 4.58
A10: 45514.083 | B10: 9.2 | C10: 4.17 | D10: 14 | E10: 10.5 | F10: 6.97 | G10: 71.55 | H10: 38.94 | I10: 6.82 | J10: 0.13 | K10: 195.52 | L10: 25.67 | M10: 98.12 | N10: 2.1 | O10: 0 | P10: 0.57 | Q10: 4.58
A11: 45514.125 | B11: 9.2 | C11: 4.17 | D11: 14 | E11: 10.49 | F11: 7.76 | G11: 70.47 | H11: 37.63 | I11: 6.36 | J11: 0.13 | K11: 205.54 | L11: 25.61 | M11: 98.44 | N11: 2.1 | O11: 0 | P11: 0.52 | Q11: 4.57
A12: 45514.167 | B12: 9.2 | C12: 4.17 | D12: 14 | E12: 10.34 | F12: 7.62 | G12: 64.05 | H12: 29.26 | I12: 5.85 | J12: 0.13 | K12: 186.81 | L12: 25.72 | M12: 98.79 | N12: 2.3 | O12: 0 | P12: 0.48 | Q12: 4.59
A13: 45514.208 | B13: 9.21 | C13: 4.16 | D13: 14 | E13: 10.76 | F13: 8.22 | G13: 54.1 | H13: 27.42 | I13: 5.7 | J13: 0.44 | K13: 283.39 | L13: 25.64 | M13: 98.95 | N13: 2.3 | O13: 0 | P13: 0.47 | Q13: 4.58
A14: 45514.25 | B14: 9.21 | C14: 4.16 | D14: 14 | E14: 10.79 | F14: 8.28 | G14: 50.23 | H14: 26.4 | I14: 5.75 | J14: 0.52 | K14: 285.9 | L14: 25.62 | M14: 95.81 | N14: 5.8 | O14: 0 | P14: 0.46 | Q14: 4.58
A15: 45514.292 | B15: 9.22 | C15: 4.19 | D15: 14 | E15: 11.56 | F15: 6.33 | G15: 49 | H15: 23.6 | I15: 5.42 | J15: 0.47 | K15: 279.39 | L15: 25.84 | M15: 95.59 | N15: 59.8 | O15: 0 | P15: 0.44 | Q15: 4.57
A16: 45514.333 | B16: 9.21 | C16: 4.19 | D16: 14 | E16: 12.19 | F16: 5.96 | G16: 44.94 | H16: 22.64 | I16: 5.31 | J16: 0.68 | K16: 285.32 | L16: 27.31 | M16: 92.54 | N16: 113.6 | O16: 0 | P16: 0.46 | Q16: 4.59
