Workbook

Sheet 01
A1: Station: | B1: BHATAGAON RAIPUR
A2: Date: | B2: =$A$9 -> 01/02/2025 01:00 | D2: Power Off | G2: Pw.Off | L2: Link Fail | N2: Link F | P2: Maintenance | R2: Maint.
A3: Report Type: | B3: Mean | D3: Calibration | G3: Calib. | L3: Data Fail | N3: Data F | P3: Invalid | R3: Invalid
A4: Time Base: | B4: 01 Hour | D4: Zero Referrence | G4: Z.Ref | L4: Warm Up | N4: Wm. Up
A7: Date & Time | B7: NO_BHATAGAON | C7: NO2__BHATAGAON | D7: NOX_BHATAGAON | E7: SO2__BHATAGAON | F7: O3__BHATAGAON | G7: PM10__BHATAGAON | H7: PM2_5__BHATAGAON | I7: BENZ__BHATAGAON | J7: WS__BHATAGAON | K7: WD__BHATAGAON | L7: TEMP__BHATAGAON | M7: HUM__BHATAGAON | N7: SR__BHATAGAON | O7: RG__BHATAGAON | P7: CO__BHATAGAON | Q7: NH3__BHATAGAON
B8: ug/m3 | C8: ug/m3 | D8: ppb | E8: ug/m3 | F8: ug/m3 | G8: mg/m3 | H8: ug/m3 | I8: ug/m3 | J8: m/sec | K8: deg | L8: degreC | M8: % | N8: w/m2 | O8: mm | P8: ug/m3 | Q8: ug/m3
A9: 01/02/2025 01:00 | B9: 79.79 | C9: 54.29 | D9: 90.97 | E9: 6.92 | F9: 2.13 | G9: 115.85 | H9: 33.82 | I9: Invalid | J9: 0.57 | K9: 299.02 | L9: 17.68 | M9: 99.85 | N9: 79 | O9: 0 | P9: 1.31 | Q9: 9.79
A10: 01/02/2025 02:00 | B10: 78.05 | C10: 51.45 | D10: 88.1 | E10: 6.89 | F10: 2.13 | G10: 108.73 | H10: 31.45 | I10: Invalid | J10: 0.62 | K10: 346.53 | L10: 16.99 | M10: 104.29 | N10: 78.8 | O10: 0 | P10: 1.31 | Q10: 9.8
A11: 01/02/2025 03:00 | B11: 73.31 | C11: 51.13 | D11: 83.54 | E11: 6.55 | F11: 2.13 | G11: 103.22 | H11: 32.18 | I11: Invalid | J11: 0.52 | K11: 329.61 | L11: 16.74 | M11: 105.21 | N11: 78.6 | O11: 0 | P11: 1.25 | Q11: 9.81
A12: 01/02/2025 04:00 | B12: 64.59 | C12: 50.31 | D12: 76.42 | E12: 6.62 | F12: 2.13 | G12: 97.76 | H12: 30.82 | I12: Invalid | J12: 0.57 | K12: 300.58 | L12: 16.77 | M12: 101.8 | N12: 78.8 | O12: 0 | P12: 1.14 | Q12: 9.77
A13: 01/02/2025 05:00 | B13: 57.24 | C13: 49.47 | D13: 70.37 | E13: 6.38 | F13: 2.13 | G13: 79.32 | H13: 30.56 | I13: Invalid | J13: 0.48 | K13: 305.62 | L13: 16.16 | M13: 104.2 | N13: 78.8 | O13: 0 | P13: 0.99 | Q13: 9.72
A14: 01/02/2025 06:00 | B14: 54.69 | C14: 48.28 | D14: 67.34 | E14: 6.48 | F14: 2.13 | G14: 71.53 | H14: 28.06 | I14: Invalid | J14: 0.35 | K14: 295.65 | L14: 15.69 | M14: 105.51 | N14: 78.9 | O14: 0 | P14: 0.97 | Q14: 9.7
A15: 01/02/2025 07:00 | B15: 54.48 | C15: 49.18 | D15: 67.91 | E15: 6.39 | F15: 2.13 | G15: 69.55 | H15: 26.99 | I15: Invalid | J15: 0.58 | K15: 357.07 | L15: 15.44 | M15: 105.57 | N15: 90.5 | O15: 0 | P15: 0.95 | Q15: 9.72
A16: 01/02/2025 08:00 | B16: 58.24 | C16: 50.82 | D16: 70.54 | E16: 6.44 | F16: 2.13 | G16: 70.98 | H16: 27.31 | I16: Invalid | J16: 0.72 | K16: 202.01 | L16: 17.83 | M16: 102.63 | N16: 209.7 | O16: 0 | P16: 0.95 | Q16: 9.73
A17: 01/02/2025 09:00 | B17: 55.19 | C17: 50.37 | D17: 68.92 | E17: 6.88 | F17: 2.13 | G17: 72.55 | H17: 29.14 | I17: Invalid | J17: 1.49 | K17: 171.21 | L17: 21.26 | M17: 88.4 | N17: 383.5 | O17: 0 | P17: 0.92 | Q17: 9.71
A18: 01/02/2025 10:00 | B18: 47.47 | C18: 53.43 | D18: 62.77 | E18: 6.85 | F18: 2.13 | G18: 67.39 | H18: 26.89 | I18: Invalid | J18: 1.62 | K18: 162.63 | L18: 23.91 | M18: 69.98 | N18: 488.3 | O18: 0 | P18: 0.86 | Q18: 9.69
A19: 01/02/2025 11:00 | B19: 36.39 | C19: 54.54 | D19: 55.5 | E19: 6.52 | F19: 2.13 | G19: 62.5 | H19: 24.71 | I19: Invalid | J19: 1.27 | K19: 164.39 | L19: 26.32 | M19: 63.29 | N19: 546.3 | O19: 0 | P19: 0.77 | Q19: 9.64
A20: 01/02/2025 12:00 | B20: 23.02 | C20: 56.66 | D20: 46.46 | E20: 6.3 | F20: 2.13 | G20: 53.56 | H20: 23.52 | I20: Invalid | J20: 0.77 | K20: 320.12 | L20: 30.85 | M20: 45.41 | N20: 592.5 | O20: 0 | P20: 0.68 | Q20: 9.6
... A32: 01/02/2025 24:00 | B32: 107.1 | C32: 59.04 | D32: 114.65 | E32: 8.19 | F32: 2.13 | G32: 189.26 | H32: 42.09 | I32: Invalid | J32: 0.67 | K32: 318.74 | L32: 18.75 | M32: 79.06 | N32: 78.8 | O32: 0 | P32: 1.89 | Q32: 9.91
A34: Min | B34: =MIN(B9:B32) -> 3.41 | C34: =MIN(C9:C32) -> 48.28 | D34: =MIN(D9:D32) -> 29.04 | E34: =MIN(E9:E32) -> 5.37 | F34: =MIN(F9:F32) -> 2.13 | G34: =MIN(G9:G32) -> 40.48 | H34: =MIN(H9:H32) -> 18.96 | I34: =MIN(I9:I32) -> 0 | ... Q34: =MIN(Q9:Q32) -> 9.22
A35: Max | B35: =MAX(B9:B32) -> 107.1 | C35: =MAX(C9:C32) -> 64.84 | D35: =MAX(D9:D32) -> 114.65 | E35: =MAX(E9:E32) -> 8.57 | F35: =MAX(F9:F32) -> 2.13 | G35: =MAX(G9:G32) -> 191.05 | H35: =MAX(H9:H32) -> 42.09 | I35: =MAX(I9:I32) -> 0 | ... Q35: =MAX(Q9:Q32) -> 9.91
A36: Avg | B36: =AVERAGE(B9:B32) -> 47.449583 | C36: =AVERAGE(C9:C32) -> 55.272083 | D36: =AVERAGE(D9:D32) -> 65.064583 | E36: =AVERAGE(E9:E32) -> 6.6633333 | F36: =AVERAGE(F9:F32) -> 2.13 | G36: =AVERAGE(G9:G32) -> 86.749167 | H36: =AVERAGE(H9:H32) -> 27.989167 | I36: =AVERAGE(I9:I32) -> #DIV/0! | ... Q36: =AVERAGE(Q9:Q32) -> 9.6295833
A37: Stdev | B37: =STDEV(B9:B32) -> 30.716822 | C37: =STDEV(C9:C32) -> 4.929032 | D37: =STDEV(D9:D32) -> 24.636778 | E37: =STDEV(E9:E32) -> 0.83763989 | F37: =STDEV(F9:F32) -> 4.5364061e-16 | G37: =STDEV(G9:G32) -> 46.381131 | H37: =STDEV(H9:H32) -> 6.2356171 | I37: =STDEV(I9:I32) -> #DIV/0! | ... Q37: =STDEV(Q9:Q32) -> 0.18581148
A38: Num | B38: =COUNT(B9:B32) -> 24 | C38: =COUNT(C9:C32) -> 24 | D38: =COUNT(D9:D32) -> 24 | E38: =COUNT(E9:E32) -> 24 | F38: =COUNT(F9:F32) -> 24 | G38: =COUNT(G9:G32) -> 24 | H38: =COUNT(H9:H32) -> 24 | I38: =COUNT(I9:I32) -> 0 | ... Q38: =COUNT(Q9:Q32) -> 24
A39: DCR | B39: =IF(B38>=22,">90%",IF(B38<=22,"<90%")) -> >90% | C39: =IF(C38>=22,">90%",IF(C38<=22,"<90%")) -> >90% | D39: =IF(D38>=22,">90%",IF(D38<=22,"<90%")) -> >90% | E39: =IF(E38>=22,">90%",IF(E38<=22,"<90%")) -> >90% | F39: =IF(F38>=22,">90%",IF(F38<=22,"<90%")) -> >90% | G39: =IF(G38>=22,">90%",IF(G38<=22,"<90%")) -> >90% | H39: =IF(H38>=22,">90%",IF(H38<=22,"<90%")) -> >90% | I39: =IF(I38>=22,">90%",IF(I38<=22,"<90%")) -> <90% | ... Q39: =IF(Q38>=22,">90%",IF(Q38<=22,"<90%")) -> >90%
A40: Status | B40: =IF(B38>=22,"OK",IF(B38<=22,"LESS")) -> OK | C40: =IF(C38>=22,"OK",IF(C38<=22,"LESS")) -> OK | D40: =IF(D38>=22,"OK",IF(D38<=22,"LESS")) -> OK | E40: =IF(E38>=22,"OK",IF(E38<=22,"LESS")) -> OK | F40: =IF(F38>=22,"OK",IF(F38<=22,"LESS")) -> OK | G40: =IF(G38>=22,"OK",IF(G38<=22,"LESS")) -> OK | H40: =IF(H38>=22,"OK",IF(H38<=22,"LESS")) -> OK | I40: =IF(I38>=22,"OK",IF(I38<=22,"LESS")) -> LESS | ... Q40: =IF(Q38>=22,"OK",IF(Q38<=22,"LESS")) -> OK
A43: Done by | B43: RAHUL
A45: Comment

Sheet 02
A1: Station: | B1: BHATAGAON RAIPUR
A2: Date: | B2: =$A$9 -> 02/02/2025 01:00 | D2: Power Off | G2: Pw.Off | L2: Link Fail | N2: Link F | P2: Maintenance | R2: Maint.
A3: Report Type: | B3: Mean | D3: Calibration | G3: Calib. | L3: Data Fail | N3: Data F | P3: Invalid | R3: Invalid
A4: Time Base: | B4: 01 Hour | D4: Zero Referrence | G4: Z.Ref | L4: Warm Up | N4: Wm. Up
A7: Date & Time | B7: NO_BHATAGAON | C7: NO2__BHATAGAON | D7: NOX_BHATAGAON | E7: SO2__BHATAGAON | F7: O3__BHATAGAON | G7: PM10__BHATAGAON | H7: PM2_5__BHATAGAON | I7: BENZ__BHATAGAON | J7: WS__BHATAGAON | K7: WD__BHATAGAON | L7: TEMP__BHATAGAON | M7: HUM__BHATAGAON | N7: SR__BHATAGAON | O7: RG__BHATAGAON | P7: CO__BHATAGAON | Q7: NH3__BHATAGAON
B8: ug/m3 | C8: ug/m3 | D8: ppb | E8: ug/m3 | F8: ug/m3 | G8: mg/m3 | H8: ug/m3 | I8: ug/m3 | J8: m/sec | K8: deg | L8: degreC | M8: % | N8: w/m2 | O8: mm | P8: ug/m3 | Q8: ug/m3
A9: 02/02/2025 01:00 | B9: 106.68 | C9: 56.85 | D9: 113.88 | E9: 7.34 | F9: 2.13 | G9: 144.42 | H9: 39.16 | I9: Invalid | J9: 0.66 | K9: 307.18 | L9: 17.76 | M9: 84.92 | N9: 78.7 | O9: 0 | P9: 1.76 | Q9: 9.97
A10: 02/02/2025 02:00 | B10: 102.47 | C10: 52.53 | D10: 108.24 | E10: 6.74 | F10: 2.13 | G10: 149.43 | H10: 41.03 | I10: Invalid | J10: 0.65 | K10: 304 | L10: 16.74 | M10: 87.97 | N10: 78.6 | O10: 0 | P10: 1.46 | Q10: 9.91
A11: 02/02/2025 03:00 | B11: 94.8 | C11: 50.07 | D11: 100.29 | E11: 6.42 | F11: 2.13 | G11: 113.58 | H11: 26.67 | I11: Invalid | J11: 0.67 | K11: 309.59 | L11: 17.37 | M11: 86.11 | N11: 78.8 | O11: 0 | P11: 1.49 | Q11: 9.91
A12: 02/02/2025 04:00 | B12: 78.52 | C12: 51.92 | D12: 87.88 | E12: 6.03 | F12: 2.13 | G12: 78.79 | H12: 16 | I12: Invalid | J12: 0.69 | K12: 315.45 | L12: 16.58 | M12: 84.3 | N12: 79 | O12: 0 | P12: 1.33 | Q12: 9.85
A13: 02/02/2025 05:00 | B13: 67.94 | C13: 51.61 | D13: 80.07 | E13: 5.94 | F13: 2.13 | G13: 78.98 | H13: 17.64 | I13: Invalid | J13: 0.59 | K13: 282.48 | L13: 16.28 | M13: 89.92 | N13: 78.7 | O13: 0 | P13: 1.18 | Q13: 9.8
A14: 02/02/2025 06:00 | B14: 62.18 | C14: 48.7 | D14: 73.86 | E14: 5.81 | F14: 2.13 | G14: 79.63 | H14: 24.29 | I14: Invalid | J14: 0.64 | K14: 306.49 | L14: 15.67 | M14: 94.47 | N14: 78.8 | O14: 0 | P14: 1.02 | Q14: 9.76
A15: 02/02/2025 07:00 | B15: 60.03 | C15: 52.96 | D15: 73.51 | E15: 5.88 | F15: 2.13 | G15: 91.39 | H15: 14.33 | I15: Invalid | J15: 0.58 | K15: 348.21 | L15: 15.51 | M15: 94.76 | N15: 90.1 | O15: 0 | P15: 0.98 | Q15: 9.71
A16: 02/02/2025 08:00 | B16: 72.95 | C16: 53 | D16: 84.81 | E16: 5.58 | F16: 2.13 | G16: 83.36 | H16: 8.74 | I16: Invalid | J16: 0.81 | K16: 219.77 | L16: 18.27 | M16: 94.6 | N16: 231.1 | O16: 0 | P16: 1.02 | Q16: 9.79
A17: 02/02/2025 09:00 | B17: 70.55 | C17: 53.55 | D17: 83.18 | E17: 6.11 | F17: 2.13 | G17: 87.88 | H17: 34.13 | I17: Invalid | J17: 1.24 | K17: 210.4 | L17: 22.07 | M17: 75.73 | N17: 401.2 | O17: 0 | P17: 0.98 | Q17: 9.82
A18: 02/02/2025 10:00 | B18: 60.17 | C18: 52.94 | D18: 73.12 | E18: 5.94 | F18: 2.13 | G18: 92.76 | H18: 69.9 | I18: Invalid | J18: 1.73 | K18: 172.73 | L18: 24.77 | M18: 62.91 | N18: 513.6 | O18: 0 | P18: 0.94 | Q18: 9.76
A19: 02/02/2025 11:00 | B19: 47.07 | C19: 60.35 | D19: 64.86 | E19: 6.47 | F19: 2.13 | G19: 90.21 | H19: 40.89 | I19: Invalid | J19: 1.14 | K19: 307.03 | L19: 29.21 | M19: 57.72 | N19: 545.8 | O19: 0 | P19: 0.89 | Q19: 9.71
A20: 02/02/2025 12:00 | B20: 29.71 | C20: 69.4 | D20: 56.02 | E20: 5.97 | F20: 2.13 | G20: 72.5 | H20: 72.97 | I20: Invalid | J20: 1.35 | K20: 314.66 | L20: 32.01 | M20: 35.49 | N20: 577.5 | O20: 0 | P20: 0.92 | Q20: 9.63
... A32: 02/02/2025 24:00 | B32: 60.58 | C32: 60.92 | D32: 77.9 | E32: 7.78 | F32: 2.13 | G32: 107.74 | H32: 34.21 | I32: Invalid | J32: 0.6 | K32: 340.66 | L32: 19.26 | M32: 76.53 | N32: 82.1 | O32: 0 | P32: 1.19 | Q32: 9.71
A34: Min | B34: =MIN(B9:B32) -> 3.35 | C34: =MIN(C9:C32) -> 48.7 | D34: =MIN(D9:D32) -> 31.63 | E34: =MIN(E9:E32) -> 5.39 | F34: =MIN(F9:F32) -> 2.13 | G34: =MIN(G9:G32) -> 43.16 | H34: =MIN(H9:H32) -> 8.74 | I34: =MIN(I9:I32) -> 0 | ... Q34: =MIN(Q9:Q32) -> 9.36
A35: Max | B35: =MAX(B9:B32) -> 106.68 | C35: =MAX(C9:C32) -> 71.75 | D35: =MAX(D9:D32) -> 113.88 | E35: =MAX(E9:E32) -> 7.78 | F35: =MAX(F9:F32) -> 2.31 | G35: =MAX(G9:G32) -> 149.43 | H35: =MAX(H9:H32) -> 75.33 | I35: =MAX(I9:I32) -> 0 | ... Q35: =MAX(Q9:Q32) -> 9.97
A36: Avg | B36: =AVERAGE(B9:B32) -> 45.36375 | C36: =AVERAGE(C9:C32) -> 58.097917 | D36: =AVERAGE(D9:D32) -> 64.803333 | E36: =AVERAGE(E9:E32) -> 6.4108333 | F36: =AVERAGE(F9:F32) -> 2.14125 | G36: =AVERAGE(G9:G32) -> 83.2275 | H36: =AVERAGE(H9:H32) -> 34.71625 | I36: =AVERAGE(I9:I32) -> #DIV/0! | ... Q36: =AVERAGE(Q9:Q32) -> 9.6575
A37: Stdev | B37: =STDEV(B9:B32) -> 32.94897 | C37: =STDEV(C9:C32) -> 6.0421512 | D37: =STDEV(D9:D32) -> 24.412821 | E37: =STDEV(E9:E32) -> 0.71213651 | F37: =STDEV(F9:F32) -> 0.040358448 | G37: =STDEV(G9:G32) -> 26.88776 | H37: =STDEV(H9:H32) -> 18.028822 | I37: =STDEV(I9:I32) -> #DIV/0! | ... Q37: =STDEV(Q9:Q32) -> 0.17627178
A38: Num | B38: =COUNT(B9:B32) -> 24 | C38: =COUNT(C9:C32) -> 24 | D38: =COUNT(D9:D32) -> 24 | E38: =COUNT(E9:E32) -> 24 | F38: =COUNT(F9:F32) -> 24 | G38: =COUNT(G9:G32) -> 24 | H38: =COUNT(H9:H32) -> 24 | I38: =COUNT(I9:I32) -> 0 | ... Q38: =COUNT(Q9:Q32) -> 24
A39: DCR | B39: =IF(B38>=22,">90%",IF(B38<=22,"<90%")) -> >90% | C39: =IF(C38>=22,">90%",IF(C38<=22,"<90%")) -> >90% | D39: =IF(D38>=22,">90%",IF(D38<=22,"<90%")) -> >90% | E39: =IF(E38>=22,">90%",IF(E38<=22,"<90%")) -> >90% | F39: =IF(F38>=22,">90%",IF(F38<=22,"<90%")) -> >90% | G39: =IF(G38>=22,">90%",IF(G38<=22,"<90%")) -> >90% | H39: =IF(H38>=22,">90%",IF(H38<=22,"<90%")) -> >90% | I39: =IF(I38>=22,">90%",IF(I38<=22,"<90%")) -> <90% | ... Q39: =IF(Q38>=22,">90%",IF(Q38<=22,"<90%")) -> >90%
A40: Status | B40: =IF(B38>=22,"OK",IF(B38<=22,"LESS")) -> OK | C40: =IF(C38>=22,"OK",IF(C38<=22,"LESS")) -> OK | D40: =IF(D38>=22,"OK",IF(D38<=22,"LESS")) -> OK | E40: =IF(E38>=22,"OK",IF(E38<=22,"LESS")) -> OK | F40: =IF(F38>=22,"OK",IF(F38<=22,"LESS")) -> OK | G40: =IF(G38>=22,"OK",IF(G38<=22,"LESS")) -> OK | H40: =IF(H38>=22,"OK",IF(H38<=22,"LESS")) -> OK | I40: =IF(I38>=22,"OK",IF(I38<=22,"LESS")) -> LESS | ... Q40: =IF(Q38>=22,"OK",IF(Q38<=22,"LESS")) -> OK
A43: Done by | B43: RAHUL
A45: Comment

Sheet 03
A1: Station: | B1: BHATAGAON RAIPUR
A2: Date: | B2: =$A$9 -> 03/02/2025 01:00 | D2: Power Off | G2: Pw.Off | L2: Link Fail | N2: Link F | P2: Maintenance | R2: Maint.
A3: Report Type: | B3: Mean | D3: Calibration | G3: Calib. | L3: Data Fail | N3: Data F | P3: Invalid | R3: Invalid
A4: Time Base: | B4: 01 Hour | D4: Zero Referrence | G4: Z.Ref | L4: Warm Up | N4: Wm. Up
A7: Date & Time | B7: NO_BHATAGAON | C7: NO2__BHATAGAON | D7: NOX_BHATAGAON | E7: SO2__BHATAGAON | F7: O3__BHATAGAON | G7: PM10__BHATAGAON | H7: PM2_5__BHATAGAON | I7: BENZ__BHATAGAON | J7: WS__BHATAGAON | K7: WD__BHATAGAON | L7: TEMP__BHATAGAON | M7: HUM__BHATAGAON | N7: SR__BHATAGAON | O7: RG__BHATAGAON | P7: CO__BHATAGAON | Q7: NH3__BHATAGAON
B8: ug/m3 | C8: ug/m3 | D8: ppb | E8: ug/m3 | F8: ug/m3 | G8: mg/m3 | H8: ug/m3 | I8: ug/m3 | J8: m/sec | K8: deg | L8: degreC | M8: % | N8: w/m2 | O8: mm | P8: ug/m3 | Q8: ug/m3
A9: 03/02/2025 01:00 | B9: 62.67 | C9: 60.41 | D9: 80.44 | E9: 6.45 | F9: 2.14 | G9: 104 | H9: 35.21 | I9: Invalid | J9: 0.98 | K9: 344.83 | L9: 19.04 | M9: 78.04 | N9: 80.6 | O9: 0 | P9: 1.21 | Q9: 9.76
A10: 03/02/2025 02:00 | B10: 57.64 | C10: 58.06 | D10: 75.18 | E10: 6.57 | F10: 2.13 | G10: 107.64 | H10: 37.38 | I10: Invalid | J10: 0.67 | K10: 355.33 | L10: 18.94 | M10: 73.54 | N10: 81.1 | O10: 0 | P10: 1.05 | Q10: 9.76
A11: 03/02/2025 03:00 | B11: 52.4 | C11: 52.73 | D11: 68.2 | E11: 6.46 | F11: 2.13 | G11: 117.52 | H11: 43.75 | I11: Invalid | J11: 0.94 | K11: 337.37 | L11: 18.16 | M11: 75.95 | N11: 81.2 | O11: 0 | P11: 1.07 | Q11: 9.72
A12: 03/02/2025 04:00 | B12: 47.4 | C12: 53.8 | D12: 63.96 | E12: 6.65 | F12: 2.13 | G12: 125.61 | H12: 48.57 | I12: Invalid | J12: 0.64 | K12: 244.07 | L12: 17.52 | M12: 87.83 | N12: 80.9 | O12: 0 | P12: 1.08 | Q12: 9.69
A13: 03/02/2025 05:00 | B13: 43 | C13: 50.73 | D13: 59.61 | E13: 5.98 | F13: 2.13 | G13: 114.36 | H13: 41.31 | I13: Invalid | J13: 0.73 | K13: 255.23 | L13: 16.5 | M13: 89.62 | N13: 80.9 | O13: 0 | P13: 1.02 | Q13: 9.68
A14: 03/02/2025 06:00 | B14: 41.87 | C14: 48.74 | D14: 56.94 | E14: 5.74 | F14: 2.13 | G14: 87.35 | H14: 22.01 | I14: Invalid | J14: 0.61 | K14: 311.83 | L14: 15.62 | M14: 93.23 | N14: 80.8 | O14: 0 | P14: 0.94 | Q14: 9.69
A15: 03/02/2025 07:00 | B15: 48.04 | C15: 48.35 | D15: 62.23 | E15: 6.04 | F15: 2.13 | G15: 85.45 | H15: 30.06 | I15: Invalid | J15: 0.63 | K15: 293.31 | L15: 15.46 | M15: 95.38 | N15: 90.7 | O15: 0 | P15: 0.92 | Q15: 9.65
A16: 03/02/2025 08:00 | B16: 51.43 | C16: 48.05 | D16: 64.98 | E16: 6.68 | F16: 2.13 | G16: 90.77 | H16: 31.73 | I16: Invalid | J16: 0.84 | K16: 233.18 | L16: 18.86 | M16: 93.15 | N16: 224 | O16: 0 | P16: 0.91 | Q16: 9.68
A17: 03/02/2025 09:00 | B17: 49.6 | C17: 52.25 | D17: 64.01 | E17: 7.11 | F17: 2.13 | G17: 97.04 | H17: 69.82 | I17: Invalid | J17: 0.98 | K17: 185.09 | L17: 23.17 | M17: 72.02 | N17: 397.1 | O17: 0 | P17: 0.94 | Q17: 9.69
A18: 03/02/2025 10:00 | B18: 45.38 | C18: 54.98 | D18: 63.74 | E18: 7.27 | F18: 2.13 | G18: 101.1 | H18: 69.82 | I18: Invalid | J18: 1.43 | K18: 115.44 | L18: 24.18 | M18: 53.52 | N18: 502 | O18: 0 | P18: 0.94 | Q18: 9.71
A19: 03/02/2025 11:00 | B19: 35.29 | C19: 58.34 | D19: 56.23 | E19: 6.88 | F19: 2.13 | G19: 94.39 | H19: 37.57 | I19: Invalid | J19: 1.29 | K19: 126.7 | L19: 27.15 | M19: 48.11 | N19: 556.3 | O19: 0 | P19: 0.88 | Q19: 9.65
A20: 03/02/2025 12:00 | B20: 25.52 | C20: 62.94 | D20: 49.69 | E20: 6.92 | F20: 2.13 | G20: 89.68 | H20: 56.69 | I20: Invalid | J20: 0.75 | K20: 336.06 | L20: 31.81 | M20: 38.22 | N20: 569.6 | O20: 0 | P20: 0.82 | Q20: 9.59
... A32: 03/02/2025 24:00 | B32: 131.62 | C32: 63.27 | D32: 135.87 | E32: 8.62 | F32: 2.13 | G32: 145.83 | H32: 42.82 | I32: Invalid | J32: 0.65 | K32: 326.67 | L32: 19.64 | M32: 86.39 | N32: 75.1 | O32: 0 | P32: 2.11 | Q32: 10.09
A34: Min | B34: =MIN(B9:B32) -> 4.09 | C34: =MIN(C9:C32) -> 48.05 | D34: =MIN(D9:D32) -> 34.43 | E34: =MIN(E9:E32) -> 5.74 | F34: =MIN(F9:F32) -> 2.13 | G34: =MIN(G9:G32) -> 67.01 | H34: =MIN(H9:H32) -> 22.01 | I34: =MIN(I9:I32) -> 0 | ... Q34: =MIN(Q9:Q32) -> 9.49
A35: Max | B35: =MAX(B9:B32) -> 131.62 | C35: =MAX(C9:C32) -> 69.91 | D35: =MAX(D9:D32) -> 135.87 | E35: =MAX(E9:E32) -> 8.87 | F35: =MAX(F9:F32) -> 2.45 | G35: =MAX(G9:G32) -> 185.53 | H35: =MAX(H9:H32) -> 69.82 | I35: =MAX(I9:I32) -> 0 | ... Q35: =MAX(Q9:Q32) -> 10.09
A36: Avg | B36: =AVERAGE(B9:B32) -> 43.532917 | C36: =AVERAGE(C9:C32) -> 60.451667 | D36: =AVERAGE(D9:D32) -> 64.579583 | E36: =AVERAGE(E9:E32) -> 6.9575 | F36: =AVERAGE(F9:F32) -> 2.165 | G36: =AVERAGE(G9:G32) -> 105.26375 | H36: =AVERAGE(H9:H32) -> 40.445833 | I36: =AVERAGE(I9:I32) -> #DIV/0! | ... Q36: =AVERAGE(Q9:Q32) -> 9.685
A37: Stdev | B37: =STDEV(B9:B32) -> 31.845055 | C37: =STDEV(C9:C32) -> 7.6128179 | D37: =STDEV(D9:D32) -> 25.286306 | E37: =STDEV(E9:E32) -> 0.86231866 | F37: =STDEV(F9:F32) -> 0.086023253 | G37: =STDEV(G9:G32) -> 31.110495 | H37: =STDEV(H9:H32) -> 12.602094 | I37: =STDEV(I9:I32) -> #DIV/0! | ... Q37: =STDEV(Q9:Q32) -> 0.14542292
A38: Num | B38: =COUNT(B9:B32) -> 24 | C38: =COUNT(C9:C32) -> 24 | D38: =COUNT(D9:D32) -> 24 | E38: =COUNT(E9:E32) -> 24 | F38: =COUNT(F9:F32) -> 24 | G38: =COUNT(G9:G32) -> 24 | H38: =COUNT(H9:H32) -> 24 | I38: =COUNT(I9:I32) -> 0 | ... Q38: =COUNT(Q9:Q32) -> 24
A39: DCR | B39: =IF(B38>=22,">90%",IF(B38<=22,"<90%")) -> >90% | C39: =IF(C38>=22,">90%",IF(C38<=22,"<90%")) -> >90% | D39: =IF(D38>=22,">90%",IF(D38<=22,"<90%")) -> >90% | E39: =IF(E38>=22,">90%",IF(E38<=22,"<90%")) -> >90% | F39: =IF(F38>=22,">90%",IF(F38<=22,"<90%")) -> >90% | G39: =IF(G38>=22,">90%",IF(G38<=22,"<90%")) -> >90% | H39: =IF(H38>=22,">90%",IF(H38<=22,"<90%")) -> >90% | I39: =IF(I38>=22,">90%",IF(I38<=22,"<90%")) -> <90% | ... Q39: =IF(Q38>=22,">90%",IF(Q38<=22,"<90%")) -> >90%
A40: Status | B40: =IF(B38>=22,"OK",IF(B38<=22,"LESS")) -> OK | C40: =IF(C38>=22,"OK",IF(C38<=22,"LESS")) -> OK | D40: =IF(D38>=22,"OK",IF(D38<=22,"LESS")) -> OK | E40: =IF(E38>=22,"OK",IF(E38<=22,"LESS")) -> OK | F40: =IF(F38>=22,"OK",IF(F38<=22,"LESS")) -> OK | G40: =IF(G38>=22,"OK",IF(G38<=22,"LESS")) -> OK | H40: =IF(H38>=22,"OK",IF(H38<=22,"LESS")) -> OK | I40: =IF(I38>=22,"OK",IF(I38<=22,"LESS")) -> LESS | ... Q40: =IF(Q38>=22,"OK",IF(Q38<=22,"LESS")) -> OK
A43: Done by | B43: RAHUL
A45: Comment

Sheet 04
A1: Station: | B1: BHATAGAON RAIPUR
A2: Date: | B2: =$A$9 -> 04/02/2025 01:00 | D2: Power Off | G2: Pw.Off | L2: Link Fail | N2: Link F | P2: Maintenance | R2: Maint.
A3: Report Type: | B3: Mean | D3: Calibration | G3: Calib. | L3: Data Fail | N3: Data F | P3: Invalid | R3: Invalid
A4: Time Base: | B4: 01 Hour | D4: Zero Referrence | G4: Z.Ref | L4: Warm Up | N4: Wm. Up
A7: Date & Time | B7: NO_BHATAGAON | C7: NO2__BHATAGAON | D7: NOX_BHATAGAON | E7: SO2__BHATAGAON | F7: O3__BHATAGAON | G7: PM10__BHATAGAON | H7: PM2_5__BHATAGAON | I7: BENZ__BHATAGAON | J7: WS__BHATAGAON | K7: WD__BHATAGAON | L7: TEMP__BHATAGAON | M7: HUM__BHATAGAON | N7: SR__BHATAGAON | O7: RG__BHATAGAON | P7: CO__BHATAGAON | Q7: NH3__BHATAGAON
B8: ug/m3 | C8: ug/m3 | D8: ppb | E8: ug/m3 | F8: ug/m3 | G8: mg/m3 | H8: ug/m3 | I8: ug/m3 | J8: m/sec | K8: deg | L8: degreC | M8: % | N8: w/m2 | O8: mm | P8: ug/m3 | Q8: ug/m3
A9: 04/02/2025 01:00 | B9: 139.7 | C9: 58.86 | D9: 141.32 | E9: 9.46 | F9: 2.13 | G9: 140.21 | H9: 38.56 | I9: Invalid | J9: 0.71 | K9: 342.38 | L9: 19.67 | M9: 89.34 | N9: 75.3 | O9: 0 | P9: 2.14 | Q9: 10.21
A10: 04/02/2025 02:00 | B10: 127.91 | C10: 58.64 | D10: 131.83 | E10: 9.12 | F10: 2.13 | G10: 147.18 | H10: 42.49 | I10: Invalid | J10: 0.78 | K10: 295.66 | L10: 18.97 | M10: 84.73 | N10: 75.4 | O10: 0 | P10: 1.96 | Q10: 10.22
A11: 04/02/2025 03:00 | B11: 114.82 | C11: 56.88 | D11: 120.42 | E11: 9.23 | F11: 2.13 | G11: 152.7 | H11: 48.39 | I11: Invalid | J11: 0.95 | K11: 330.81 | L11: 18.76 | M11: 92.4 | N11: 75.6 | O11: 0 | P11: 1.88 | Q11: 10.15
A12: 04/02/2025 04:00 | B12: 105.27 | C12: 51.95 | D12: 110.18 | E12: 8.8 | F12: 2.22 | G12: 129.65 | H12: 42.58 | I12: Invalid | J12: 0.56 | K12: 226.3 | L12: 17.98 | M12: 89.38 | N12: 75.1 | O12: 0 | P12: 1.78 | Q12: 10.08
A13: 04/02/2025 05:00 | B13: 96.57 | C13: 52.94 | D13: 103.05 | E13: 8.65 | F13: 2.13 | G13: 134.07 | H13: 44.65 | I13: Invalid | J13: 0.48 | K13: 354.53 | L13: 18.01 | M13: 77.99 | N13: 75 | O13: 0 | P13: 1.73 | Q13: 10.04
A14: 04/02/2025 06:00 | B14: 82.15 | C14: 53.51 | D14: 91.94 | E14: 8.09 | F14: 2.13 | G14: 119.84 | H14: 40.75 | I14: Invalid | J14: 0.36 | K14: 75.06 | L14: 17.94 | M14: 77.02 | N14: 75.2 | O14: 0 | P14: 1.56 | Q14: 9.99
A15: 04/02/2025 07:00 | B15: 67.2 | C15: 53.62 | D15: 80.53 | E15: 7.65 | F15: 2.13 | G15: 103.63 | H15: 48.17 | I15: Invalid | J15: 0.28 | K15: 357.6 | L15: 17.49 | M15: 78.72 | N15: 91.3 | O15: 0 | P15: 1.36 | Q15: 9.93
A16: 04/02/2025 08:00 | B16: 59.24 | C16: 50.83 | D16: 72.16 | E16: 7.32 | F16: 2.13 | G16: 85.48 | H16: 52.28 | I16: Invalid | J16: 1.45 | K16: 113.76 | L16: 19.86 | M16: 76.18 | N16: 237.6 | O16: 0 | P16: 1.25 | Q16: 9.82
A17: 04/02/2025 09:00 | B17: 49.83 | C17: 59.37 | D17: 66.51 | E17: 6.62 | F17: 2.13 | G17: 84.92 | H17: 60.66 | I17: Invalid | J17: 0.68 | K17: 101.41 | L17: 24.47 | M17: 60.01 | N17: 403.5 | O17: 0 | P17: 1.17 | Q17: 9.79
A18: 04/02/2025 10:00 | B18: 41.23 | C18: 62.29 | D18: 62.59 | E18: 6.31 | F18: 2.13 | G18: 97.06 | H18: 48.44 | I18: Invalid | J18: 1.32 | K18: 117.08 | L18: 26.4 | M18: 47.49 | N18: 498.1 | O18: 0 | P18: 1.11 | Q18: 9.76
A19: 04/02/2025 11:00 | B19: 27.52 | C19: 63.69 | D19: 53.97 | E19: 6.09 | F19: 2.13 | G19: 105.75 | H19: 49.79 | I19: Invalid | J19: 1.28 | K19: 120.1 | L19: 27.47 | M19: 46.34 | N19: 546.4 | O19: 0 | P19: 0.99 | Q19: 9.74
A20: 04/02/2025 12:00 | B20: 14.37 | C20: 61.52 | D20: 42 | E20: 6.02 | F20: 2.16 | G20: 78.65 | H20: 41.08 | I20: Invalid | J20: 1.29 | K20: 159.33 | L20: 29.63 | M20: 40.48 | N20: 564.6 | O20: 0 | P20: 0.8 | Q20: 9.64
... A32: 04/02/2025 24:00 | B32: 219.32 | C32: 59.94 | D32: 204.18 | E32: 11.45 | F32: 2.13 | G32: 256.09 | H32: 63.81 | I32: Invalid | J32: 0.65 | K32: 329.61 | L32: 19.47 | M32: 79.9 | N32: 79.2 | O32: 0 | P32: 3.27 | Q32: 10.59
A34: Min | B34: =MIN(B9:B32) -> 3.28 | C34: =MIN(C9:C32) -> 50.83 | D34: =MIN(D9:D32) -> 30.78 | E34: =MIN(E9:E32) -> 5.59 | F34: =MIN(F9:F32) -> 2.13 | G34: =MIN(G9:G32) -> 56.34 | H34: =MIN(H9:H32) -> 24.09 | I34: =MIN(I9:I32) -> 0 | ... Q34: =MIN(Q9:Q32) -> 9.56
A35: Max | B35: =MAX(B9:B32) -> 219.32 | C35: =MAX(C9:C32) -> 66.98 | D35: =MAX(D9:D32) -> 204.18 | E35: =MAX(E9:E32) -> 11.97 | F35: =MAX(F9:F32) -> 2.76 | G35: =MAX(G9:G32) -> 256.42 | H35: =MAX(H9:H32) -> 63.81 | I35: =MAX(I9:I32) -> 0 | ... Q35: =MAX(Q9:Q32) -> 10.59
A36: Avg | B36: =AVERAGE(B9:B32) -> 72.200833 | C36: =AVERAGE(C9:C32) -> 59.212917 | D36: =AVERAGE(D9:D32) -> 87.021667 | E36: =AVERAGE(E9:E32) -> 7.6241667 | F36: =AVERAGE(F9:F32) -> 2.19375 | G36: =AVERAGE(G9:G32) -> 122.635 | H36: =AVERAGE(H9:H32) -> 41.734583 | I36: =AVERAGE(I9:I32) -> #DIV/0! | ... Q36: =AVERAGE(Q9:Q32) -> 9.8775
A37: Stdev | B37: =STDEV(B9:B32) -> 64.571988 | C37: =STDEV(C9:C32) -> 4.2540206 | D37: =STDEV(D9:D32) -> 51.548648 | E37: =STDEV(E9:E32) -> 1.9028923 | F37: =STDEV(F9:F32) -> 0.17611292 | G37: =STDEV(G9:G32) -> 61.588227 | H37: =STDEV(H9:H32) -> 11.11774 | I37: =STDEV(I9:I32) -> #DIV/0! | ... Q37: =STDEV(Q9:Q32) -> 0.29638767
A38: Num | B38: =COUNT(B9:B32) -> 24 | C38: =COUNT(C9:C32) -> 24 | D38: =COUNT(D9:D32) -> 24 | E38: =COUNT(E9:E32) -> 24 | F38: =COUNT(F9:F32) -> 24 | G38: =COUNT(G9:G32) -> 24 | H38: =COUNT(H9:H32) -> 24 | I38: =COUNT(I9:I32) -> 0 | ... Q38: =COUNT(Q9:Q32) -> 24
A39: DCR | B39: =IF(B38>=22,">90%",IF(B38<=22,"<90%")) -> >90% | C39: =IF(C38>=22,">90%",IF(C38<=22,"<90%")) -> >90% | D39: =IF(D38>=22,">90%",IF(D38<=22,"<90%")) -> >90% | E39: =IF(E38>=22,">90%",IF(E38<=22,"<90%")) -> >90% | F39: =IF(F38>=22,">90%",IF(F38<=22,"<90%")) -> >90% | G39: =IF(G38>=22,">90%",IF(G38<=22,"<90%")) -> >90% | H39: =IF(H38>=22,">90%",IF(H38<=22,"<90%")) -> >90% | I39: =IF(I38>=22,">90%",IF(I38<=22,"<90%")) -> <90% | ... Q39: =IF(Q38>=22,">90%",IF(Q38<=22,"<90%")) -> >90%
A40: Status | B40: =IF(B38>=22,"OK",IF(B38<=22,"LESS")) -> OK | C40: =IF(C38>=22,"OK",IF(C38<=22,"LESS")) -> OK | D40: =IF(D38>=22,"OK",IF(D38<=22,"LESS")) -> OK | E40: =IF(E38>=22,"OK",IF(E38<=22,"LESS")) -> OK | F40: =IF(F38>=22,"OK",IF(F38<=22,"LESS")) -> OK | G40: =IF(G38>=22,"OK",IF(G38<=22,"LESS")) -> OK | H40: =IF(H38>=22,"OK",IF(H38<=22,"LESS")) -> OK | I40: =IF(I38>=22,"OK",IF(I38<=22,"LESS")) -> LESS | ... Q40: =IF(Q38>=22,"OK",IF(Q38<=22,"LESS")) -> OK
A43: Done by | B43: RAHUL
A45: Comment

Sheet 05
A1: Station: | B1: BHATAGAON RAIPUR
A2: Date: | B2: =$A$9 -> 05/02/2025 01:00 | D2: Power Off | G2: Pw.Off | L2: Link Fail | N2: Link F | P2: Maintenance | R2: Maint.
A3: Report Type: | B3: Mean | D3: Calibration | G3: Calib. | L3: Data Fail | N3: Data F | P3: Invalid | R3: Invalid
A4: Time Base: | B4: 01 Hour | D4: Zero Referrence | G4: Z.Ref | L4: Warm Up | N4: Wm. Up
A7: Date & Time | B7: NO_BHATAGAON | C7: NO2__BHATAGAON | D7: NOX_BHATAGAON | E7: SO2__BHATAGAON | F7: O3__BHATAGAON | G7: PM10__BHATAGAON | H7: PM2_5__BHATAGAON | I7: BENZ__BHATAGAON | J7: WS__BHATAGAON | K7: WD__BHATAGAON | L7: TEMP__BHATAGAON | M7: HUM__BHATAGAON | N7: SR__BHATAGAON | O7: RG__BHATAGAON | P7: CO__BHATAGAON | Q7: NH3__BHATAGAON
B8: ug/m3 | C8: ug/m3 | D8: ppb | E8: ug/m3 | F8: ug/m3 | G8: mg/m3 | H8: ug/m3 | I8: ug/m3 | J8: m/sec | K8: deg | L8: degreC | M8: % | N8: w/m2 | O8: mm | P8: ug/m3 | Q8: ug/m3
A9: 05/02/2025 01:00 | B9: 212.26 | C9: 55.24 | D9: 197.7 | E9: 10.9 | F9: 2.13 | G9: 159.6 | H9: 46.86 | I9: Invalid | J9: 0.62 | K9: 354.08 | L9: 19.31 | M9: 68.94 | N9: 79.1 | O9: 0 | P9: 2.25 | Q9: 10.6
A10: 05/02/2025 02:00 | B10: 187.34 | C10: 55.26 | D10: 177.73 | E10: 9.39 | F10: 2.13 | G10: 96.77 | H10: 28.49 | I10: Invalid | J10: 0.4 | K10: 332.49 | L10: 18.09 | M10: 75.79 | N10: 79.2 | O10: 0 | P10: 2.16 | Q10: 10.5
A11: 05/02/2025 03:00 | B11: 156.62 | C11: 53.05 | D11: 151.94 | E11: 8.58 | F11: 2.13 | G11: 92.18 | H11: 42.83 | I11: Invalid | J11: 0.62 | K11: 296.53 | L11: 17.37 | M11: 81.52 | N11: 79.2 | O11: 0 | P11: 1.92 | Q11: 10.4
A12: 05/02/2025 04:00 | B12: 130.47 | C12: 52.46 | D12: 130.66 | E12: 7.59 | F12: 2.13 | G12: 95.83 | H12: 45.48 | I12: Invalid | J12: 0.62 | K12: 333.25 | L12: 16.88 | M12: 83.7 | N12: 79.1 | O12: 0 | P12: 1.57 | Q12: 10.28
A13: 05/02/2025 05:00 | B13: 113.28 | C13: 49.33 | D13: 114.9 | E13: 7.56 | F13: 2.13 | G13: 74.5 | H13: 33.01 | I13: Invalid | J13: 0.74 | K13: 346.46 | L13: 16.67 | M13: 82.28 | N13: 79.1 | O13: 0 | P13: 1.23 | Q13: 10.11
A14: 05/02/2025 06:00 | B14: 102.26 | C14: 50.08 | D14: 105.91 | E14: 7.5 | F14: 2.13 | G14: 74.56 | H14: 26.19 | I14: Invalid | J14: 0.51 | K14: 336.12 | L14: 16.9 | M14: 85.21 | N14: 79.5 | O14: 0 | P14: 1.22 | Q14: 10.07
A15: 05/02/2025 07:00 | B15: 90.57 | C15: 50.75 | D15: 97.29 | E15: 7.18 | F15: 2.13 | G15: 77.86 | H15: 23.48 | I15: Invalid | J15: 0.51 | K15: 257.48 | L15: 16.62 | M15: 83.38 | N15: 95.3 | O15: 0 | P15: 1.1 | Q15: 9.99
A16: 05/02/2025 08:00 | B16: Calib. | C16: Calib. | D16: Calib. | E16: 7.44 | F16: 2.13 | G16: 94.3 | H16: 31.96 | I16: Invalid | J16: 0.95 | K16: 343.6 | L16: 20.67 | M16: 84.23 | N16: 234.5 | O16: 0 | P16: 1.24 | Q16: 10.03
A17: 05/02/2025 09:00 | B17: Calib. | C17: Calib. | D17: Calib. | E17: 7.22 | F17: 2.13 | G17: 182.84 | H17: 38.55 | I17: Invalid | J17: 1.21 | K17: 344.54 | L17: 27.58 | M17: 56.65 | N17: 380.8 | O17: 0 | P17: 1.54 | Q17: 10.01
A18: 05/02/2025 10:00 | B18: 83.61 | C18: 65.38 | D18: 96.11 | E18: 7.5 | F18: 2.13 | G18: 271.63 | H18: 52.03 | I18: Invalid | J18: 1.22 | K18: 351.89 | L18: 31.09 | M18: 37.59 | N18: 525.1 | O18: 0 | P18: 1.37 | Q18: 9.97
A19: 05/02/2025 11:00 | B19: 66.89 | C19: 91.68 | D19: 87.15 | E19: 17.11 | F19: 29.9 | G19: 155.89 | H19: 58.97 | I19: Invalid | J19: 0.98 | K19: 340.72 | L19: 32.3 | M19: 30.77 | N19: 575.9 | O19: 0 | P19: 1.26 | Q19: 10.06
A20: 05/02/2025 12:00 | B20: 2.42 | C20: 87.01 | D20: 46.03 | E20: 12.51 | F20: 15.26 | G20: Calib. | H20: Data F | I20: Invalid | J20: 0.75 | K20: 299.78 | L20: 32.46 | M20: 32.15 | N20: 583.7 | O20: 0 | P20: 0.62 | Q20: 9.73
A21: 05/02/2025 13:00 | B21: 2.01 | C21: 68.83 | D21: 36.15 | E21: Calib. | F21: 18.33 | G21: Calib. | H21: Data F | I21: Invalid | J21: 1.26 | K21: 214.01 | L21: 31.2 | M21: 32.3 | N21: 568.8 | O21: 0 | P21: 0.57 | Q21: 9.59
A22: 05/02/2025 14:00 | B22: 4.01 | C22: 59.04 | D22: 31.1 | E22: 7.86 | F22: 15.76 | G22: Calib. | H22: Data F | I22: Invalid | J22: 0.87 | K22: 295.15 | L22: 31.86 | M22: 31.32 | N22: 513 | O22: 0 | P22: 0.61 | Q22: 9.6
A23: 05/02/2025 15:00 | B23: 3.05 | C23: 53.89 | D23: 29.15 | E23: 7.67 | F23: 11.88 | G23: 8.39 | H23: 4.1 | I23: Invalid | J23: 0.64 | K23: 290.26 | L23: 31.16 | M23: 26.63 | N23: 471.9 | O23: 0 | P23: 0.51 | Q23: 9.59
A24: 05/02/2025 16:00 | B24: 3.07 | C24: 57.66 | D24: 31.04 | E24: 7.76 | F24: 7.44 | G24: 75.55 | H24: 36.92 | I24: Invalid | J24: 0.76 | K24: 308.23 | L24: 29.16 | M24: 28.29 | N24: 202.2 | O24: 0 | P24: 0.56 | Q24: 9.6
A25: 05/02/2025 17:00 | B25: 3.15 | C25: 70.09 | D25: 37.76 | E25: 8.9 | F25: 11.64 | G25: 63.7 | H25: 28.17 | I25: Invalid | J25: 0.69 | K25: 305.28 | L25: 28.82 | M25: 29.1 | N25: 134.3 | O25: 0 | P25: 0.59 | Q25: 9.6
A26: 05/02/2025 18:00 | B26: 5.63 | C26: 71.28 | D26: 40.34 | E26: 7.68 | F26: 4.01 | G26: 44.07 | H26: 20.57 | I26: Invalid | J26: 0.56 | K26: 286.3 | L26: 27.73 | M26: 32.87 | N26: 101.9 | O26: 0 | P26: 0.65 | Q26: 9.57
A27: 05/02/2025 19:00 | B27: 15.89 | C27: 70.18 | D27: 48.04 | E27: 7 | F27: 2.13 | G27: 59.12 | H27: 21 | I27: Invalid | J27: 0.58 | K27: 332.72 | L27: 25.12 | M27: 42.29 | N27: 79.3 | O27: 0 | P27: 1.19 | Q27: 9.6
A28: 05/02/2025 20:00 | B28: 27.47 | C28: 69.76 | D28: 56.92 | E28: 7.23 | F28: 2.13 | G28: 66.29 | H28: 23.26 | I28: Invalid | J28: 0.58 | K28: 308.35 | L28: 23.19 | M28: 45.32 | N28: 78.9 | O28: 0 | P28: 1.35 | Q28: 9.65
A29: 05/02/2025 21:00 | B29: 39.7 | C29: 65.72 | D29: 64.02 | E29: 7.26 | F29: 2.13 | G29: 75.51 | H29: 15.12 | I29: Invalid | J29: 0.55 | K29: 326.34 | L29: 22.18 | M29: 54.82 | N29: 78.9 | O29: 0 | P29: 1.42 | Q29: 9.7
A30: 05/02/2025 22:00 | B30: 59.73 | C30: 64.16 | D30: 80.04 | E30: 7.88 | F30: 2.17 | G30: 98.84 | H30: 21.36 | I30: Invalid | J30: 0.69 | K30: 314.35 | L30: 20.98 | M30: 61.6 | N30: 78.8 | O30: 0 | P30: 1.7 | Q30: 9.74
A31: 05/02/2025 23:00 | B31: 59.98 | C31: 64.31 | D31: 80.32 | E31: 7.9 | F31: 2.13 | G31: 116.49 | H31: 87 | I31: Invalid | J31: 0.68 | K31: 262.58 | L31: 21.01 | M31: 58.02 | N31: 78.9 | O31: 0 | P31: 1.15 | Q31: 9.83
A32: 05/02/2025 24:00 | B32: 52.26 | C32: 59.78 | D32: 71.76 | E32: 6.84 | F32: 2.13 | G32: 90.57 | H32: 12.09 | I32: Invalid | J32: 0.76 | K32: 323.95 | L32: 19.73 | M32: 65.69 | N32: 78.5 | O32: 0 | P32: 1.09 | Q32: 9.83
A34: Min | B34: =MIN(B9:B32) -> 2.01 | C34: =MIN(C9:C32) -> 49.33 | D34: =MIN(D9:D32) -> 29.15 | E34: =MIN(E9:E32) -> 6.84 | F34: =MIN(F9:F32) -> 2.13 | G34: =MIN(G9:G32) -> 8.39 | H34: =MIN(H9:H32) -> 4.1 | I34: =MIN(I9:I32) -> 0 | ... Q34: =MIN(Q9:Q32) -> 9.57
A35: Max | B35: =MAX(B9:B32) -> 212.26 | C35: =MAX(C9:C32) -> 91.68 | D35: =MAX(D9:D32) -> 197.7 | E35: =MAX(E9:E32) -> 17.11 | F35: =MAX(F9:F32) -> 29.9 | G35: =MAX(G9:G32) -> 271.63 | H35: =MAX(H9:H32) -> 87 | I35: =MAX(I9:I32) -> 0 | ... Q35: =MAX(Q9:Q32) -> 10.6
A36: Avg | B36: =AVERAGE(B9:B32) -> 64.621364 | C36: =AVERAGE(C9:C32) -> 62.951818 | D36: =AVERAGE(D9:D32) -> 82.366364 | E36: =AVERAGE(E9:E32) -> 8.4547826 | F36: =AVERAGE(F9:F32) -> 6.1808333 | G36: =AVERAGE(G9:G32) -> 98.785238 | H36: =AVERAGE(H9:H32) -> 33.211429 | I36: =AVERAGE(I9:I32) -> #DIV/0! | ... Q36: =AVERAGE(Q9:Q32) -> 9.9020833
A37: Stdev | B37: =STDEV(B9:B32) -> 63.753901 | C37: =STDEV(C9:C32) -> 11.205433 | D37: =STDEV(D9:D32) -> 48.406713 | E37: =STDEV(E9:E32) -> 2.2993949 | F37: =STDEV(F9:F32) -> 7.268752 | G37: =STDEV(G9:G32) -> 55.71302 | H37: =STDEV(H9:H32) -> 18.364426 | I37: =STDEV(I9:I32) -> #DIV/0! | ... Q37: =STDEV(Q9:Q32) -> 0.31017497
A38: Num | B38: =COUNT(B9:B32)+2 -> 24 | C38: =COUNT(C9:C32)+2 -> 24 | D38: =COUNT(D9:D32)+2 -> 24 | E38: =COUNT(E9:E32)+1 -> 24 | F38: =COUNT(F9:F32) -> 24 | G38: =COUNT(G9:G32)+3 -> 24 | H38: =COUNT(H9:H32)+3 -> 24 | I38: =COUNT(I9:I32) -> 0 | J38: =COUNT(J9:J32) -> 24 | K38: =COUNT(K9:K32) -> 24 | L38: =COUNT(L9:L32) -> 24 | M38: =COUNT(M9:M32) -> 24 | N38: =COUNT(N9:N32) -> 24 | O38: =COUNT(O9:O32) -> 24 | P38: =COUNT(P9:P32) -> 24 | Q38: =COUNT(Q9:Q32) -> 24
A39: DCR | B39: =IF(B38>=22,">90%",IF(B38<=22,"<90%")) -> >90% | C39: =IF(C38>=22,">90%",IF(C38<=22,"<90%")) -> >90% | D39: =IF(D38>=22,">90%",IF(D38<=22,"<90%")) -> >90% | E39: =IF(E38>=22,">90%",IF(E38<=22,"<90%")) -> >90% | F39: =IF(F38>=22,">90%",IF(F38<=22,"<90%")) -> >90% | G39: =IF(G38>=22,">90%",IF(G38<=22,"<90%")) -> >90% | H39: =IF(H38>=22,">90%",IF(H38<=22,"<90%")) -> >90% | I39: =IF(I38>=22,">90%",IF(I38<=22,"<90%")) -> <90% | ... Q39: =IF(Q38>=22,">90%",IF(Q38<=22,"<90%")) -> >90%
A40: Status | B40: =IF(B38>=22,"OK",IF(B38<=22,"LESS")) -> OK | C40: =IF(C38>=22,"OK",IF(C38<=22,"LESS")) -> OK | D40: =IF(D38>=22,"OK",IF(D38<=22,"LESS")) -> OK | E40: =IF(E38>=22,"OK",IF(E38<=22,"LESS")) -> OK | F40: =IF(F38>=22,"OK",IF(F38<=22,"LESS")) -> OK | G40: =IF(G38>=22,"OK",IF(G38<=22,"LESS")) -> OK | H40: =IF(H38>=22,"OK",IF(H38<=22,"LESS")) -> OK | I40: =IF(I38>=22,"OK",IF(I38<=22,"LESS")) -> LESS | ... Q40: =IF(Q38>=22,"OK",IF(Q38<=22,"LESS")) -> OK
A43: Done by | B43: RAHUL
A45: Comment

Sheet 06
A1: Station: | B1: BHATAGAON RAIPUR
A2: Date: | B2: =$A$9 -> 06/02/2025 01:00 | D2: Power Off | G2: Pw.Off | L2: Link Fail | N2: Link F | P2: Maintenance | R2: Maint.
A3: Report Type: | B3: Mean | D3: Calibration | G3: Calib. | L3: Data Fail | N3: Data F | P3: Invalid | R3: Invalid
A4: Time Base: | B4: 01 Hour | D4: Zero Referrence | G4: Z.Ref | L4: Warm Up | N4: Wm. Up
A7: Date & Time | B7: NO_BHATAGAON | C7: NO2__BHATAGAON | D7: NOX_BHATAGAON | E7: SO2__BHATAGAON | F7: O3__BHATAGAON | G7: PM10__BHATAGAON | H7: PM2_5__BHATAGAON | I7: BENZ__BHATAGAON | J7: WS__BHATAGAON | K7: WD__BHATAGAON | L7: TEMP__BHATAGAON | M7: HUM__BHATAGAON | N7: SR__BHATAGAON | O7: RG__BHATAGAON | P7: CO__BHATAGAON | Q7: NH3__BHATAGAON
B8: ug/m3 | C8: ug/m3 | D8: ppb | E8: ug/m3 | F8: ug/m3 | G8: mg/m3 | H8: ug/m3 | I8: ug/m3 | J8: m/sec | K8: deg | L8: degreC | M8: % | N8: w/m2 | O8: mm | P8: ug/m3 | Q8: ug/m3
A9: 06/02/2025 01:00 | B9: 49.32 | C9: 56.8 | D9: 67.85 | E9: 4.87 | F9: 2.13 | G9: 85.6 | H9: 20.76 | I9: Invalid | J9: 1.55 | K9: 354.84 | L9: 19.47 | M9: 62.99 | N9: 78.4 | O9: 0 | P9: 0.94 | Q9: 9.82
A10: 06/02/2025 02:00 | B10: 42.94 | C10: 55.04 | D10: 61.81 | E10: 5.27 | F10: 2.13 | G10: 75.79 | H10: 20.56 | I10: Invalid | J10: 1.09 | K10: 355.84 | L10: 19.48 | M10: 64.22 | N10: 78.4 | O10: 0 | P10: 0.8 | Q10: 9.75
A11: 06/02/2025 03:00 | B11: 35.34 | C11: 53.66 | D11: 53.76 | E11: 5 | F11: 2.13 | G11: 78.53 | H11: 39.3 | I11: Invalid | J11: 1.4 | K11: 355.59 | L11: 19.29 | M11: 65.7 | N11: 78.6 | O11: 0 | P11: 0.83 | Q11: 9.74
A12: 06/02/2025 04:00 | B12: 24.43 | C12: 55.56 | D12: 46.72 | E12: 5.17 | F12: 2.13 | G12: 63.47 | H12: 6.33 | I12: Invalid | J12: 1.82 | K12: 354.13 | L12: 18.81 | M12: 68.73 | N12: 78.8 | O12: 0 | P12: 0.73 | Q12: 9.71
A13: 06/02/2025 05:00 | B13: 14.93 | C13: 58.21 | D13: 40.34 | E13: 5.64 | F13: 2.13 | G13: 61.67 | H13: 26.74 | I13: Invalid | J13: 2.06 | K13: 356.35 | L13: 18.07 | M13: 69.35 | N13: 78.8 | O13: 0 | P13: 0.64 | Q13: 9.68
A14: 06/02/2025 06:00 | B14: 10.84 | C14: 58.38 | D14: 37.82 | E14: 5.62 | F14: 2.13 | G14: 66.35 | H14: 6.53 | I14: Invalid | J14: 1.68 | K14: 358.8 | L14: 17.73 | M14: 69.38 | N14: 78.5 | O14: 0 | P14: 0.57 | Q14: 9.61
A15: 06/02/2025 07:00 | B15: 7.5 | C15: 54.5 | D15: 33.11 | E15: 5.41 | F15: 2.13 | G15: 67.66 | H15: 36.39 | I15: Invalid | J15: 1.46 | K15: 354.3 | L15: 17.01 | M15: 72.87 | N15: 91.1 | O15: 0 | P15: 0.51 | Q15: 9.58
A16: 06/02/2025 08:00 | B16: 8.82 | C16: 54.16 | D16: 33.99 | E16: 5.58 | F16: 2.13 | G16: 60.42 | H16: 26.88 | I16: Invalid | J16: 1.43 | K16: 358.55 | L16: 18.56 | M16: 73.55 | N16: 212.8 | O16: 0 | P16: 0.56 | Q16: 9.61
A17: 06/02/2025 09:00 | B17: 9.15 | C17: 55 | D17: 34.7 | E17: 6.62 | F17: 2.13 | G17: 61.2 | H17: 28.78 | I17: Invalid | J17: 1.37 | K17: 357.45 | L17: 21.18 | M17: 63.11 | N17: 375.5 | O17: 0 | P17: 0.59 | Q17: 9.63
A18: 06/02/2025 10:00 | B18: 8.74 | C18: 56.46 | D18: 34.62 | E18: 6.87 | F18: 2.13 | G18: 59.3 | H18: 26.75 | I18: Invalid | J18: 1.28 | K18: 23.66 | L18: 23.6 | M18: 52.1 | N18: 489.7 | O18: 0 | P18: 0.59 | Q18: 9.6
A19: 06/02/2025 11:00 | B19: 7.82 | C19: 59.6 | D19: 35.77 | E19: 6.85 | F19: 2.13 | G19: 58.18 | H19: 21.94 | I19: Invalid | J19: 1.73 | K19: 349.45 | L19: 26.57 | M19: 42.18 | N19: 539.3 | O19: 0 | P19: 0.59 | Q19: 9.58
A20: 06/02/2025 12:00 | B20: 6.7 | C20: 58.97 | D20: 34.8 | E20: 7.2 | F20: 2.13 | G20: 61.84 | H20: 7.91 | I20: Invalid | J20: 1.24 | K20: 358.01 | L20: 27.6 | M20: 42.03 | N20: 542.2 | O20: 0 | P20: 0.6 | Q20: 9.6
... A32: 06/02/2025 24:00 | B32: 18.73 | C32: 62.7 | D32: 46.41 | E32: 5.02 | F32: 2.13 | G32: 74.18 | H32: 351.28 | I32: Invalid | J32: 0.65 | K32: 351.38 | L32: 17.85 | M32: 34.84 | N32: 78.2 | O32: 0 | P32: 0.91 | Q32: 9.66
A34: Min | B34: =MIN(B9:B32) -> 4.94 | C34: =MIN(C9:C32) -> 53.66 | D34: =MIN(D9:D32) -> 32.76 | E34: =MIN(E9:E32) -> 4.87 | F34: =MIN(F9:F32) -> 2.13 | G34: =MIN(G9:G32) -> 58.18 | H34: =MIN(H9:H32) -> 6.33 | I34: =MIN(I9:I32) -> 0 | ... Q34: =MIN(Q9:Q32) -> 9.56
A35: Max | B35: =MAX(B9:B32) -> 49.32 | C35: =MAX(C9:C32) -> 67.79 | D35: =MAX(D9:D32) -> 67.85 | E35: =MAX(E9:E32) -> 7.4 | F35: =MAX(F9:F32) -> 2.18 | G35: =MAX(G9:G32) -> 97.5 | H35: =MAX(H9:H32) -> 351.28 | I35: =MAX(I9:I32) -> 0 | ... Q35: =MAX(Q9:Q32) -> 9.82
A36: Avg | B36: =AVERAGE(B9:B32) -> 15.035417 | C36: =AVERAGE(C9:C32) -> 59.798333 | D36: =AVERAGE(D9:D32) -> 41.73125 | E36: =AVERAGE(E9:E32) -> 5.95 | F36: =AVERAGE(F9:F32) -> 2.1320833 | G36: =AVERAGE(G9:G32) -> 73.292083 | H36: =AVERAGE(H9:H32) -> 39.1725 | I36: =AVERAGE(I9:I32) -> #DIV/0! | ... Q36: =AVERAGE(Q9:Q32) -> 9.6370833
A37: Stdev | B37: =STDEV(B9:B32) -> 12.049718 | C37: =STDEV(C9:C32) -> 4.4321186 | D37: =STDEV(D9:D32) -> 9.3189588 | E37: =STDEV(E9:E32) -> 0.80396301 | F37: =STDEV(F9:F32) -> 0.010206207 | G37: =STDEV(G9:G32) -> 12.040529 | H37: =STDEV(H9:H32) -> 67.528139 | I37: =STDEV(I9:I32) -> #DIV/0! | ... Q37: =STDEV(Q9:Q32) -> 0.064570768
A38: Num | B38: =COUNT(B9:B32) -> 24 | C38: =COUNT(C9:C32) -> 24 | D38: =COUNT(D9:D32) -> 24 | E38: =COUNT(E9:E32) -> 24 | F38: =COUNT(F9:F32) -> 24 | G38: =COUNT(G9:G32) -> 24 | H38: =COUNT(H9:H32) -> 24 | I38: =COUNT(I9:I32) -> 0 | ... Q38: =COUNT(Q9:Q32) -> 24
A39: DCR | B39: =IF(B38>=22,">90%",IF(B38<=22,"<90%")) -> >90% | C39: =IF(C38>=22,">90%",IF(C38<=22,"<90%")) -> >90% | D39: =IF(D38>=22,">90%",IF(D38<=22,"<90%")) -> >90% | E39: =IF(E38>=22,">90%",IF(E38<=22,"<90%")) -> >90% | F39: =IF(F38>=22,">90%",IF(F38<=22,"<90%")) -> >90% | G39: =IF(G38>=22,">90%",IF(G38<=22,"<90%")) -> >90% | H39: =IF(H38>=22,">90%",IF(H38<=22,"<90%")) -> >90% | I39: =IF(I38>=22,">90%",IF(I38<=22,"<90%")) -> <90% | ... Q39: =IF(Q38>=22,">90%",IF(Q38<=22,"<90%")) -> >90%
A40: Status | B40: =IF(B38>=22,"OK",IF(B38<=22,"LESS")) -> OK | C40: =IF(C38>=22,"OK",IF(C38<=22,"LESS")) -> OK | D40: =IF(D38>=22,"OK",IF(D38<=22,"LESS")) -> OK | E40: =IF(E38>=22,"OK",IF(E38<=22,"LESS")) -> OK | F40: =IF(F38>=22,"OK",IF(F38<=22,"LESS")) -> OK | G40: =IF(G38>=22,"OK",IF(G38<=22,"LESS")) -> OK | H40: =IF(H38>=22,"OK",IF(H38<=22,"LESS")) -> OK | I40: =IF(I38>=22,"OK",IF(I38<=22,"LESS")) -> LESS | ... Q40: =IF(Q38>=22,"OK",IF(Q38<=22,"LESS")) -> OK
A43: Done by | B43: RAHUL
A45: Comment

Sheet 07
A1: Station: | B1: BHATAGAON RAIPUR
A2: Date: | B2: =$A$9 -> 07/02/2025 01:00 | D2: Power Off | G2: Pw.Off | L2: Link Fail | N2: Link F | P2: Maintenance | R2: Maint.
A3: Report Type: | B3: Mean | D3: Calibration | G3: Calib. | L3: Data Fail | N3: Data F | P3: Invalid | R3: Invalid
A4: Time Base: | B4: 01 Hour | D4: Zero Referrence | G4: Z.Ref | L4: Warm Up | N4: Wm. Up
A7: Date & Time | B7: NO_BHATAGAON | C7: NO2__BHATAGAON | D7: NOX_BHATAGAON | E7: SO2__BHATAGAON | F7: O3__BHATAGAON | G7: PM10__BHATAGAON | H7: PM2_5__BHATAGAON | I7: BENZ__BHATAGAON | J7: WS__BHATAGAON | K7: WD__BHATAGAON | L7: TEMP__BHATAGAON | M7: HUM__BHATAGAON | N7: SR__BHATAGAON | O7: RG__BHATAGAON | P7: CO__BHATAGAON | Q7: NH3__BHATAGAON
B8: ug/m3 | C8: ug/m3 | D8: ppb | E8: ug/m3 | F8: ug/m3 | G8: mg/m3 | H8: ug/m3 | I8: ug/m3 | J8: m/sec | K8: deg | L8: degreC | M8: % | N8: w/m2 | O8: mm | P8: ug/m3 | Q8: ug/m3
A9: 07/02/2025 01:00 | B9: 16.14 | C9: 58.74 | D9: 42.26 | E9: 4.68 | F9: 2.13 | G9: 60.57 | H9: Data F | I9: Invalid | J9: 0.83 | K9: 351.46 | L9: 16.91 | M9: 35.24 | N9: 78 | O9: 0 | P9: 0.82 | Q9: 9.67
A10: 07/02/2025 02:00 | B10: 12.9 | C10: 53.63 | D10: 36.99 | E10: 4.78 | F10: 2.13 | G10: 53.86 | H10: Data F | I10: Invalid | J10: 1.24 | K10: 359.64 | L10: 16.57 | M10: 35.47 | N10: 78.1 | O10: 0 | P10: 0.68 | Q10: 9.67
A11: 07/02/2025 03:00 | B11: 11.44 | C11: 49.94 | D11: 33.89 | E11: 4.72 | F11: 2.13 | G11: 45.73 | H11: Data F | I11: Invalid | J11: 0.77 | K11: 83.36 | L11: 16.11 | M11: 35.23 | N11: 78.3 | O11: 0 | P11: 0.6 | Q11: 9.6
A12: 07/02/2025 04:00 | B12: 10.49 | C12: 47.96 | D12: 32 | E12: 5.08 | F12: 2.13 | G12: 41.59 | H12: Data F | I12: Invalid | J12: 0.63 | K12: 353.04 | L12: 15.3 | M12: 36.26 | N12: 78.1 | O12: 0 | P12: 0.6 | Q12: 9.59
A13: 07/02/2025 05:00 | B13: 9.04 | C13: 47.24 | D13: 30.43 | E13: 5.13 | F13: 2.13 | G13: 55.64 | H13: Data F | I13: Invalid | J13: 0.57 | K13: 359.25 | L13: 14.93 | M13: 35.39 | N13: 78 | O13: 0 | P13: 0.55 | Q13: 9.53
A14: 07/02/2025 06:00 | B14: 11.28 | C14: 47.56 | D14: 31.95 | E14: 4.2 | F14: 2.13 | G14: 53.73 | H14: Data F | I14: Invalid | J14: 0.63 | K14: 352.58 | L14: 14.58 | M14: 38 | N14: 78.2 | O14: 0 | P14: 0.5 | Q14: 9.57
A15: 07/02/2025 07:00 | B15: 13.53 | C15: 47.14 | D15: 33.94 | E15: 4.73 | F15: 2.13 | G15: 55.76 | H15: Data F | I15: Invalid | J15: 0.44 | K15: 347.8 | L15: 14.07 | M15: 38.22 | N15: 93.2 | O15: 0 | P15: 0.46 | Q15: 9.61
A16: 07/02/2025 08:00 | B16: 15.47 | C16: 49.48 | D16: 36.88 | E16: 6.36 | F16: 2.13 | G16: 59.73 | H16: Data F | I16: Invalid | J16: 0.93 | K16: 352.42 | L16: 17.42 | M16: 37.24 | N16: 236.7 | O16: 0 | P16: 0.53 | Q16: 9.6
A17: 07/02/2025 09:00 | B17: 16.65 | C17: 52.4 | D17: 38.85 | E17: 6.44 | F17: 2.13 | G17: 55.49 | H17: Data F | I17: Invalid | J17: 1.94 | K17: 106.68 | L17: 18.72 | M17: 28.94 | N17: 415.1 | O17: 0 | P17: 0.54 | Q17: 9.68
A18: 07/02/2025 10:00 | B18: 16.48 | C18: 55.32 | D18: 40.75 | E18: 6.04 | F18: 2.13 | G18: 56.02 | H18: 13.84 | I18: Invalid | J18: 1.81 | K18: 358.08 | L18: 24.39 | M18: 26.22 | N18: 528.8 | O18: 0 | P18: 0.54 | Q18: 9.67
A19: 07/02/2025 11:00 | B19: 17.12 | C19: 67.06 | D19: 41.89 | E19: 8.54 | F19: 9.84 | G19: 57.7 | H19: 32.79 | I19: Invalid | J19: 1.8 | K19: 106.49 | L19: 22.74 | M19: 24.3 | N19: 571.4 | O19: 0 | P19: 0.55 | Q19: 9.73
A20: 07/02/2025 12:00 | B20: 7.89 | C20: 73.52 | D20: 43.36 | E20: 11.41 | F20: 3.04 | G20: 44.74 | H20: 1.97 | I20: Invalid | J20: 1.15 | K20: 350.14 | L20: 26.45 | M20: 21.23 | N20: 568.6 | O20: 0 | P20: 0.43 | Q20: 9.75
A21: 07/02/2025 13:00 | B21: 10.28 | C21: 77.33 | D21: 47.27 | E21: 9.58 | F21: 2.13 | G21: 47.06 | H21: 0.16 | I21: Invalid | J21: 1.29 | K21: 350.44 | L21: 28.34 | M21: 16.41 | N21: 554.1 | O21: 0 | P21: 0.44 | Q21: 9.88
A22: 07/02/2025 14:00 | B22: 12.91 | C22: 71.63 | D22: 45.86 | E22: 7.41 | F22: 2.13 | G22: 55.03 | H22: 2.61 | I22: Invalid | J22: 1.64 | K22: 350.73 | L22: 29.47 | M22: 15.74 | N22: 521.4 | O22: 0 | P22: 0.51 | Q22: 10.13
A23: 07/02/2025 15:00 | B23: 14.1 | C23: 70.77 | D23: 46.38 | E23: 6.79 | F23: 2.13 | G23: 48.28 | H23: 21.09 | I23: Invalid | J23: 1.51 | K23: 346.7 | L23: 27.42 | M23: 18.29 | N23: 347.4 | O23: 0 | P23: 0.64 | Q23: 10.18
A24: 07/02/2025 16:00 | B24: 15.44 | C24: 93.3 | D24: 56 | E24: 16.61 | F24: 2.61 | G24: 73.26 | H24: 2.95 | I24: Invalid | J24: 1.86 | K24: 353.75 | L24: 27.01 | M24: 23.4 | N24: 253.5 | O24: 0 | P24: 0.69 | Q24: 10.33
A25: 07/02/2025 17:00 | B25: 14.77 | C25: 129.42 | D25: 77.04 | E25: 75.61 | F25: 17.07 | G25: 71.5 | H25: 0.47 | I25: Invalid | J25: 1.44 | K25: 356.38 | L25: 24.88 | M25: 26.38 | N25: 148.7 | O25: 0 | P25: 0.97 | Q25: 10.45
A26: 07/02/2025 18:00 | B26: 40.69 | C26: 158.9 | D26: 114.27 | E26: 33.58 | F26: 11.86 | G26: 85.43 | H26: 31.47 | I26: Invalid | J26: 0.9 | K26: 357.76 | L26: 22.55 | M26: 31.25 | N26: 100.8 | O26: 0 | P26: 1.6 | Q26: 10.37
A27: 07/02/2025 19:00 | B27: 42.73 | C27: 132.49 | D27: 97.68 | E27: 14.37 | F27: 2.87 | G27: 81.62 | H27: Data F | I27: Invalid | J27: 0.76 | K27: 338.47 | L27: 20.7 | M27: 46.74 | N27: 77.8 | O27: 0 | P27: 1.86 | Q27: 10.39
A28: 07/02/2025 20:00 | B28: 65.14 | C28: 78.28 | D28: 79.79 | E28: 10.66 | F28: 2.57 | G28: 93.91 | H28: Data F | I28: Invalid | J28: 0.66 | K28: 333.58 | L28: 18.85 | M28: 49.85 | N28: 77.5 | O28: 0 | P28: 1.59 | Q28: 10.64
A29: 07/02/2025 21:00 | B29: 92.98 | C29: 55.75 | D29: 97.26 | E29: 10.95 | F29: 2.13 | G29: 122.45 | H29: Data F | I29: Invalid | J29: 0.61 | K29: 348.31 | L29: 18.53 | M29: 53.41 | N29: 77.5 | O29: 0 | P29: 1.91 | Q29: 11.09
A30: 07/02/2025 22:00 | B30: 124.28 | C30: 52.66 | D30: 121.19 | E30: 11.08 | F30: 2.13 | G30: 132.75 | H30: Data F | I30: Invalid | J30: 0.67 | K30: 351.74 | L30: 17.33 | M30: 59.27 | N30: 77.4 | O30: 0 | P30: 2.6 | Q30: 11.1
A31: 07/02/2025 23:00 | B31: 134.8 | C31: 49.07 | D31: 132.36 | E31: 11.17 | F31: 2.13 | G31: 153.36 | H31: Data F | I31: Invalid | J31: 0.68 | K31: 277.57 | L31: 17.15 | M31: 57.79 | N31: 77.5 | O31: 0 | P31: 2.87 | Q31: 11
A32: 07/02/2025 24:00 | B32: 150.86 | C32: 60.05 | D32: 148.66 | E32: 11.61 | F32: 2.18 | G32: 175.32 | H32: Data F | I32: Invalid | J32: 0.66 | K32: 340.84 | L32: 16.33 | M32: 66.72 | N32: 77.5 | O32: 0 | P32: 2.6 | Q32: 10.85
A34: Min | B34: =MIN(B9:B32) -> 7.89 | C34: =MIN(C9:C32) -> 47.14 | D34: =MIN(D9:D32) -> 30.43 | E34: =MIN(E9:E32) -> 4.2 | F34: =MIN(F9:F32) -> 2.13 | G34: =MIN(G9:G32) -> 41.59 | H34: =MIN(H9:H32) -> 0.16 | I34: =MIN(I9:I32) -> 0 | ... Q34: =MIN(Q9:Q32) -> 9.53
A35: Max | B35: =MAX(B9:B32) -> 150.86 | C35: =MAX(C9:C32) -> 158.9 | D35: =MAX(D9:D32) -> 148.66 | E35: =MAX(E9:E32) -> 75.61 | F35: =MAX(F9:F32) -> 17.07 | G35: =MAX(G9:G32) -> 175.32 | H35: =MAX(H9:H32) -> 32.79 | I35: =MAX(I9:I32) -> 0 | ... Q35: =MAX(Q9:Q32) -> 11.1
A36: Avg | B36: =AVERAGE(B9:B32) -> 36.55875 | C36: =AVERAGE(C9:C32) -> 69.985 | D36: =AVERAGE(D9:D32) -> 62.789583 | E36: =AVERAGE(E9:E32) -> 12.147083 | F36: =AVERAGE(F9:F32) -> 3.5883333 | G36: =AVERAGE(G9:G32) -> 74.18875 | H36: =AVERAGE(H9:H32) -> 11.927778 | I36: =AVERAGE(I9:I32) -> #DIV/0! | ... Q36: =AVERAGE(Q9:Q32) -> 10.086667
A37: Stdev | B37: =STDEV(B9:B32) -> 43.638506 | C37: =STDEV(C9:C32) -> 30.103171 | D37: =STDEV(D9:D32) -> 36.272121 | E37: =STDEV(E9:E32) -> 14.85434 | F37: =STDEV(F9:F32) -> 3.7768237 | G37: =STDEV(G9:G32) -> 36.241063 | H37: =STDEV(H9:H32) -> 13.421409 | I37: =STDEV(I9:I32) -> #DIV/0! | ... Q37: =STDEV(Q9:Q32) -> 0.53667792
A38: Num | B38: =COUNT(B9:B32) -> 24 | C38: =COUNT(C9:C32) -> 24 | D38: =COUNT(D9:D32) -> 24 | E38: =COUNT(E9:E32) -> 24 | F38: =COUNT(F9:F32) -> 24 | G38: =COUNT(G9:G32) -> 24 | H38: =COUNT(H9:H32)+15 -> 24 | I38: =COUNT(I9:I32) -> 0 | J38: =COUNT(J9:J32) -> 24 | K38: =COUNT(K9:K32) -> 24 | L38: =COUNT(L9:L32) -> 24 | M38: =COUNT(M9:M32) -> 24 | N38: =COUNT(N9:N32) -> 24 | O38: =COUNT(O9:O32) -> 24 | P38: =COUNT(P9:P32) -> 24 | Q38: =COUNT(Q9:Q32) -> 24
A39: DCR | B39: =IF(B38>=22,">90%",IF(B38<=22,"<90%")) -> >90% | C39: =IF(C38>=22,">90%",IF(C38<=22,"<90%")) -> >90% | D39: =IF(D38>=22,">90%",IF(D38<=22,"<90%")) -> >90% | E39: =IF(E38>=22,">90%",IF(E38<=22,"<90%")) -> >90% | F39: =IF(F38>=22,">90%",IF(F38<=22,"<90%")) -> >90% | G39: =IF(G38>=22,">90%",IF(G38<=22,"<90%")) -> >90% | H39: =IF(H38>=22,">90%",IF(H38<=22,"<90%")) -> >90% | I39: =IF(I38>=22,">90%",IF(I38<=22,"<90%")) -> <90% | ... Q39: =IF(Q38>=22,">90%",IF(Q38<=22,"<90%")) -> >90%
A40: Status | B40: =IF(B38>=22,"OK",IF(B38<=22,"LESS")) -> OK | C40: =IF(C38>=22,"OK",IF(C38<=22,"LESS")) -> OK | D40: =IF(D38>=22,"OK",IF(D38<=22,"LESS")) -> OK | E40: =IF(E38>=22,"OK",IF(E38<=22,"LESS")) -> OK | F40: =IF(F38>=22,"OK",IF(F38<=22,"LESS")) -> OK | G40: =IF(G38>=22,"OK",IF(G38<=22,"LESS")) -> OK | H40: =IF(H38>=22,"OK",IF(H38<=22,"LESS")) -> OK | I40: =IF(I38>=22,"OK",IF(I38<=22,"LESS")) -> LESS | ... Q40: =IF(Q38>=22,"OK",IF(Q38<=22,"LESS")) -> OK
A43: Done by | B43: RAHUL
A45: Comment

Sheet 08
A1: Station: | B1: BHATAGAON RAIPUR
A2: Date: | B2: =$A$9 -> 08/02/2025 01:00 | D2: Power Off | G2: Pw.Off | L2: Link Fail | N2: Link F | P2: Maintenance | R2: Maint.
A3: Report Type: | B3: Mean | D3: Calibration | G3: Calib. | L3: Data Fail | N3: Data F | P3: Invalid | R3: Invalid
A4: Time Base: | B4: 01 Hour | D4: Zero Referrence | G4: Z.Ref | L4: Warm Up | N4: Wm. Up
A7: Date & Time | B7: NO_BHATAGAON | C7: NO2__BHATAGAON | D7: NOX_BHATAGAON | E7: SO2__BHATAGAON | F7: O3__BHATAGAON | G7: PM10__BHATAGAON | H7: PM2_5__BHATAGAON | I7: BENZ__BHATAGAON | J7: WS__BHATAGAON | K7: WD__BHATAGAON | L7: TEMP__BHATAGAON | M7: HUM__BHATAGAON | N7: SR__BHATAGAON | O7: RG__BHATAGAON | P7: CO__BHATAGAON | Q7: NH3__BHATAGAON
B8: ug/m3 | C8: ug/m3 | D8: ppb | E8: ug/m3 | F8: ug/m3 | G8: mg/m3 | H8: ug/m3 | I8: ug/m3 | J8: m/sec | K8: deg | L8: degreC | M8: % | N8: w/m2 | O8: mm | P8: ug/m3 | Q8: ug/m3
A9: 08/02/2025 01:00 | B9: 151.95 | C9: 56.36 | D9: 149.7 | E9: 10.73 | F9: 2.13 | G9: 196.03 | H9: 55.82 | I9: Invalid | J9: 0.62 | K9: 326.62 | L9: 15.79 | M9: 63.7 | N9: 77.5 | O9: 0 | P9: 2.6 | Q9: 10.86
A10: 08/02/2025 02:00 | B10: 138.93 | C10: 57.76 | D10: 140.21 | E10: 9.73 | F10: 2.13 | G10: 172.45 | H10: 48.47 | I10: Invalid | J10: 0.68 | K10: 257.83 | L10: 15.47 | M10: 72.68 | N10: 77.4 | O10: 0 | P10: 2.22 | Q10: 10.75
A11: 08/02/2025 03:00 | B11: 125.82 | C11: 47.06 | D11: 124.11 | E11: 8.76 | F11: 2.13 | G11: 147.85 | H11: 46.7 | I11: Invalid | J11: 0.67 | K11: 333.63 | L11: 15.08 | M11: 80.91 | N11: 77.7 | O11: 0 | P11: 1.94 | Q11: 10.56
A12: 08/02/2025 04:00 | B12: 115.43 | C12: 56.13 | D12: 115.29 | E12: 7.84 | F12: 2.13 | G12: 142.31 | H12: 34.09 | I12: Invalid | J12: 1.24 | K12: 354.05 | L12: 15.01 | M12: 83.75 | N12: 77.4 | O12: 0 | P12: 1.77 | Q12: 10.39
A13: 08/02/2025 05:00 | B13: 97.58 | C13: 58.26 | D13: 107.32 | E13: 7.82 | F13: 2.13 | G13: 114.85 | H13: 51.97 | I13: Invalid | J13: 1.38 | K13: 358.81 | L13: 15.01 | M13: 54.43 | N13: 77.2 | O13: 0 | P13: 1.6 | Q13: 10.29
A14: 08/02/2025 06:00 | B14: 79.34 | C14: 52.31 | D14: 89.58 | E14: 6.27 | F14: 2.13 | G14: 70.65 | H14: 149.6 | I14: Invalid | J14: 1.2 | K14: 357.1 | L14: 14.84 | M14: 46.51 | N14: 77.6 | O14: 0 | P14: 1.27 | Q14: 10.19
A15: 08/02/2025 07:00 | B15: 66.44 | C15: 48.97 | D15: 77.49 | E15: 5.5 | F15: 2.13 | G15: 69.32 | H15: 19.99 | I15: Invalid | J15: 0.7 | K15: 345.41 | L15: 14.1 | M15: 45.6 | N15: 91.4 | O15: 0 | P15: 1.02 | Q15: 10.1
A16: 08/02/2025 08:00 | B16: 59.39 | C16: 47.23 | D16: 70.22 | E16: 5.54 | F16: 2.13 | G16: 44.67 | H16: 19.99 | I16: Invalid | J16: 0.65 | K16: 358.18 | L16: 16.57 | M16: 46.17 | N16: 237.5 | O16: 0 | P16: 1.03 | Q16: 9.98
A17: 08/02/2025 09:00 | B17: 55.32 | C17: 51.62 | D17: 68.92 | E17: 5.43 | F17: 2.13 | G17: 52.07 | H17: 19.99 | I17: Invalid | J17: 1.07 | K17: 103.01 | L17: 20.09 | M17: 34.34 | N17: 411.2 | O17: 0 | P17: 0.96 | Q17: 9.9
A18: 08/02/2025 10:00 | B18: 51.23 | C18: 51.17 | D18: 66.06 | E18: 5.35 | F18: 2.13 | G18: 65.58 | H18: 19.99 | I18: Invalid | J18: 1.76 | K18: 97.06 | L18: 22.12 | M18: 31.03 | N18: 544.2 | O18: 0 | P18: 0.87 | Q18: 9.89
A19: 08/02/2025 11:00 | B19: 42.33 | C19: 52.77 | D19: 60.14 | E19: 4.42 | F19: 2.13 | G19: 64.42 | H19: 19.99 | I19: Invalid | J19: 1.99 | K19: 357.55 | L19: 26.63 | M19: 26.95 | N19: 581.8 | O19: 0 | P19: 0.75 | Q19: 9.87
A20: 08/02/2025 12:00 | B20: 34.84 | C20: 51.3 | D20: 52.58 | E20: 4.54 | F20: 2.13 | G20: 47.97 | H20: 18.48 | I20: Invalid | J20: 0.7 | K20: 338.05 | L20: 26.71 | M20: 25.24 | N20: 581.3 | O20: 0 | P20: 0.66 | Q20: 9.79
... A32: 08/02/2025 24:00 | B32: 46.27 | C32: 59.97 | D32: 67.06 | E32: 7 | F32: 2.13 | G32: 87.74 | H32: 9.13 | I32: Invalid | J32: 0.63 | K32: 352.08 | L32: 16.86 | M32: 35.4 | N32: 78.1 | O32: 0 | P32: 1.46 | Q32: 9.78
A34: Min | B34: =MIN(B9:B32) -> 13.22 | C34: =MIN(C9:C32) -> 47.06 | D34: =MIN(D9:D32) -> 38.68 | E34: =MIN(E9:E32) -> 4.42 | F34: =MIN(F9:F32) -> 2.13 | G34: =MIN(G9:G32) -> 42.7 | H34: =MIN(H9:H32) -> 9.13 | I34: =MIN(I9:I32) -> 0 | ... Q34: =MIN(Q9:Q32) -> 9.61
A35: Max | B35: =MAX(B9:B32) -> 151.95 | C35: =MAX(C9:C32) -> 61.26 | D35: =MAX(D9:D32) -> 149.7 | E35: =MAX(E9:E32) -> 10.73 | F35: =MAX(F9:F32) -> 2.13 | G35: =MAX(G9:G32) -> 196.03 | H35: =MAX(H9:H32) -> 166.32 | I35: =MAX(I9:I32) -> 0 | ... Q35: =MAX(Q9:Q32) -> 10.86
A36: Avg | B36: =AVERAGE(B9:B32) -> 57.080833 | C36: =AVERAGE(C9:C32) -> 55.664167 | D36: =AVERAGE(D9:D32) -> 72.84125 | E36: =AVERAGE(E9:E32) -> 6.46 | F36: =AVERAGE(F9:F32) -> 2.13 | G36: =AVERAGE(G9:G32) -> 88.222917 | H36: =AVERAGE(H9:H32) -> 60.0775 | I36: =AVERAGE(I9:I32) -> #DIV/0! | ... Q36: =AVERAGE(Q9:Q32) -> 9.9566667
A37: Stdev | B37: =STDEV(B9:B32) -> 40.466053 | C37: =STDEV(C9:C32) -> 4.3043021 | D37: =STDEV(D9:D32) -> 31.775847 | E37: =STDEV(E9:E32) -> 1.6288326 | F37: =STDEV(F9:F32) -> 4.5364061e-16 | G37: =STDEV(G9:G32) -> 40.886086 | H37: =STDEV(H9:H32) -> 42.400944 | I37: =STDEV(I9:I32) -> #DIV/0! | ... Q37: =STDEV(Q9:Q32) -> 0.3640672
A38: Num | B38: =COUNT(B9:B32) -> 24 | C38: =COUNT(C9:C32) -> 24 | D38: =COUNT(D9:D32) -> 24 | E38: =COUNT(E9:E32) -> 24 | F38: =COUNT(F9:F32) -> 24 | G38: =COUNT(G9:G32) -> 24 | H38: =COUNT(H9:H32) -> 24 | I38: =COUNT(I9:I32) -> 0 | ... Q38: =COUNT(Q9:Q32) -> 24
A39: DCR | B39: =IF(B38>=22,">90%",IF(B38<=22,"<90%")) -> >90% | C39: =IF(C38>=22,">90%",IF(C38<=22,"<90%")) -> >90% | D39: =IF(D38>=22,">90%",IF(D38<=22,"<90%")) -> >90% | E39: =IF(E38>=22,">90%",IF(E38<=22,"<90%")) -> >90% | F39: =IF(F38>=22,">90%",IF(F38<=22,"<90%")) -> >90% | G39: =IF(G38>=22,">90%",IF(G38<=22,"<90%")) -> >90% | H39: =IF(H38>=22,">90%",IF(H38<=22,"<90%")) -> >90% | I39: =IF(I38>=22,">90%",IF(I38<=22,"<90%")) -> <90% | ... Q39: =IF(Q38>=22,">90%",IF(Q38<=22,"<90%")) -> >90%
A40: Status | B40: =IF(B38>=22,"OK",IF(B38<=22,"LESS")) -> OK | C40: =IF(C38>=22,"OK",IF(C38<=22,"LESS")) -> OK | D40: =IF(D38>=22,"OK",IF(D38<=22,"LESS")) -> OK | E40: =IF(E38>=22,"OK",IF(E38<=22,"LESS")) -> OK | F40: =IF(F38>=22,"OK",IF(F38<=22,"LESS")) -> OK | G40: =IF(G38>=22,"OK",IF(G38<=22,"LESS")) -> OK | H40: =IF(H38>=22,"OK",IF(H38<=22,"LESS")) -> OK | I40: =IF(I38>=22,"OK",IF(I38<=22,"LESS")) -> LESS | ... Q40: =IF(Q38>=22,"OK",IF(Q38<=22,"LESS")) -> OK
A43: Done by | B43: RAHUL
A45: Comment

Sheet 09
A1: Station: | B1: BHATAGAON RAIPUR
A2: Date: | B2: =$A$9 -> 09/02/2025 01:00 | D2: Power Off | G2: Pw.Off | L2: Link Fail | N2: Link F | P2: Maintenance | R2: Maint.
A3: Report Type: | B3: Mean | D3: Calibration | G3: Calib. | L3: Data Fail | N3: Data F | P3: Invalid | R3: Invalid
A4: Time Base: | B4: 01 Hour | D4: Zero Referrence | G4: Z.Ref | L4: Warm Up | N4: Wm. Up
A7: Date & Time | B7: NO_BHATAGAON | C7: NO2__BHATAGAON | D7: NOX_BHATAGAON | E7: SO2__BHATAGAON | F7: O3__BHATAGAON | G7: PM10__BHATAGAON | H7: PM2_5__BHATAGAON | I7: BENZ__BHATAGAON | J7: WS__BHATAGAON | K7: WD__BHATAGAON | L7: TEMP__BHATAGAON | M7: HUM__BHATAGAON | N7: SR__BHATAGAON | O7: RG__BHATAGAON | P7: CO__BHATAGAON | Q7: NH3__BHATAGAON
B8: ug/m3 | C8: ug/m3 | D8: ppb | E8: ug/m3 | F8: ug/m3 | G8: mg/m3 | H8: ug/m3 | I8: ug/m3 | J8: m/sec | K8: deg | L8: degreC | M8: % | N8: w/m2 | O8: mm | P8: ug/m3 | Q8: ug/m3
A9: 09/02/2025 01:00 | B9: 46.33 | C9: 54.51 | D9: 64.25 | E9: 6.61 | F9: 2.13 | G9: 71.84 | H9: 82.2 | I9: Invalid | J9: 0.6 | K9: 357.76 | L9: 16.57 | M9: 35.18 | N9: 77.9 | O9: 0 | P9: 1.2 | Q9: 9.79
A10: 09/02/2025 02:00 | B10: 41.33 | C10: 52.11 | D10: 58.99 | E10: 6.51 | F10: 2.35 | G10: 65.51 | H10: 12.94 | I10: Invalid | J10: 0.69 | K10: 349.19 | L10: 16.56 | M10: 33.78 | N10: 78.2 | O10: 0 | P10: 1 | Q10: 9.75
A11: 09/02/2025 03:00 | B11: 35.29 | C11: 51.88 | D11: 53.05 | E11: 6.26 | F11: 2.13 | G11: 58.33 | H11: 82.63 | I11: Invalid | J11: 0.57 | K11: 355.84 | L11: 15.51 | M11: 32.8 | N11: 78.4 | O11: 0 | P11: 0.97 | Q11: 9.72
A12: 09/02/2025 04:00 | B12: 31.61 | C12: 52.32 | D12: 51.22 | E12: 5.65 | F12: 2.13 | G12: 60.68 | H12: 36.98 | I12: Invalid | J12: 0.64 | K12: 344.44 | L12: 14.27 | M12: 39.15 | N12: 78.5 | O12: 0 | P12: 0.82 | Q12: 9.76
A13: 09/02/2025 05:00 | B13: 30.83 | C13: 52.22 | D13: 50.63 | E13: 5.49 | F13: 2.13 | G13: 60.03 | H13: 41.34 | I13: Invalid | J13: 0.71 | K13: 301.92 | L13: 12.88 | M13: 43.97 | N13: 78.3 | O13: 0 | P13: 0.71 | Q13: 9.72
A14: 09/02/2025 06:00 | B14: 34.29 | C14: 50.64 | D14: 52.01 | E14: 5.72 | F14: 2.13 | G14: 55.72 | H14: 34.34 | I14: Invalid | J14: 0.75 | K14: 277.27 | L14: 12.63 | M14: 72.47 | N14: 78.4 | O14: 0 | P14: 0.61 | Q14: 9.65
A15: 09/02/2025 07:00 | B15: 42.33 | C15: 48.93 | D15: 57.37 | E15: 6.42 | F15: 2.13 | G15: 69.24 | H15: 33.79 | I15: Invalid | J15: 0.69 | K15: 305.54 | L15: 10.74 | M15: 80.92 | N15: 90.9 | O15: 0 | P15: 0.66 | Q15: 9.65
A16: 09/02/2025 08:00 | B16: 64.11 | C16: 48.66 | D16: 75.46 | E16: 7.58 | F16: 2.13 | G16: 97.67 | H16: 30.74 | I16: Invalid | J16: 0.57 | K16: 296 | L16: 18.18 | M16: 80.78 | N16: 296.7 | O16: 0 | P16: 0.89 | Q16: 9.76
A17: 09/02/2025 09:00 | B17: 68.2 | C17: 52.15 | D17: 80.23 | E17: 7.46 | F17: 2.13 | G17: 115.9 | H17: 56.93 | I17: Invalid | J17: 1.69 | K17: 103.85 | L17: 20.98 | M17: 38.21 | N17: 508.2 | O17: 0 | P17: 0.93 | Q17: 9.88
A18: 09/02/2025 10:00 | B18: 60.75 | C18: 53.98 | D18: 73.87 | E18: 6.58 | F18: 2.13 | G18: 106.73 | H18: 63.98 | I18: Invalid | J18: 1.83 | K18: 114.6 | L18: 23.97 | M18: 26.6 | N18: 621.2 | O18: 0 | P18: 0.9 | Q18: 9.88
A19: 09/02/2025 11:00 | B19: 46.24 | C19: 58.12 | D19: 64.23 | E19: 6.14 | F19: 2.13 | G19: 82.55 | H19: 43.74 | I19: Invalid | J19: 1.21 | K19: 102.61 | L19: 26.31 | M19: 22.81 | N19: 636.9 | O19: 0 | P19: 0.84 | Q19: 9.77
A20: 09/02/2025 12:00 | B20: 33.17 | C20: 58.84 | D20: 55.73 | E20: 5.59 | F20: 2.13 | G20: 77.46 | H20: 39.05 | I20: Invalid | J20: 1.16 | K20: 357.31 | L20: 29.21 | M20: 15.95 | N20: 628.1 | O20: 0 | P20: 0.78 | Q20: 9.72
... A32: 09/02/2025 24:00 | B32: 188.76 | C32: 68.89 | D32: 184.87 | E32: 9.81 | F32: 2.13 | G32: 142.07 | H32: 79.71 | I32: Invalid | J32: 0.62 | K32: 297.14 | L32: 14.81 | M32: 53.68 | N32: 74.4 | O32: 0 | P32: 1.82 | Q32: 10.49
A34: Min | B34: =MIN(B9:B32) -> 5.11 | C34: =MIN(C9:C32) -> 48.66 | D34: =MIN(D9:D32) -> 28.29 | E34: =MIN(E9:E32) -> 4.45 | F34: =MIN(F9:F32) -> 2.13 | G34: =MIN(G9:G32) -> 37.12 | H34: =MIN(H9:H32) -> 12.94 | I34: =MIN(I9:I32) -> 0 | ... Q34: =MIN(Q9:Q32) -> 9.27
A35: Max | B35: =MAX(B9:B32) -> 188.76 | C35: =MAX(C9:C32) -> 69.71 | D35: =MAX(D9:D32) -> 184.87 | E35: =MAX(E9:E32) -> 9.81 | F35: =MAX(F9:F32) -> 2.35 | G35: =MAX(G9:G32) -> 160.47 | H35: =MAX(H9:H32) -> 95.21 | I35: =MAX(I9:I32) -> 0 | ... Q35: =MAX(Q9:Q32) -> 10.49
