Workbook

Sheet 01
A1: Station: | B1: BHATAGAON RAIPUR
A2: Date: | B2: =$A$9 -> 01/02/2025 00:15 | D2: Power Off | G2: Pw.Off | L2: Link Fail | N2: Link F | P2: Maintenance | R2: Maint.
A3: Report Type: | B3: Mean | D3: Calibration | G3: Calib. | L3: Data Fail | N3: Data F | P3: Invalid | R3: Invalid
A4: Time Base: | B4: 15 Min | D4: Zero Referrence | G4: Z.Ref | L4: Warm Up | N4: Wm. Up
A7: Date & Time | B7: NO_BHATAGAON | C7: NO2__BHATAGAON | D7: NOX_BHATAGAON | E7: SO2__BHATAGAON | F7: O3__BHATAGAON | G7: PM10__BHATAGAON | H7: PM2_5__BHATAGAON | I7: BENZ__BHATAGAON | J7: WS__BHATAGAON | K7: WD__BHATAGAON | L7: TEMP__BHATAGAON | M7: HUM__BHATAGAON | N7: SR__BHATAGAON | O7: RG__BHATAGAON | P7: CO__BHATAGAON | Q7: NH3__BHATAGAON
B8: ug/m3 | C8: ug/m3 | D8: ppb | E8: ug/m3 | F8: ug/m3 | G8: ug/m3 | H8: ug/m3 | I8: ug/m3 | J8: m/sec | K8: deg | L8: degreC | M8: % | N8: w/m2 | O8: mm | P8: mg/m3 | Q8: ug/m3
A9: 01/02/2025 00:15 | B9: 79.79 | C9: 54.29 | D9: 90.97 | E9: 6.37 | F9: 2.13 | G9: 115.85 | H9: 33.82 | I9: Invalid | J9: 0.57 | K9: 72.81 | L9: 17.68 | M9: 95.68 | N9: 78.8 | O9: 0 | P9: 1.31 | Q9: 9.79
A10: 01/02/2025 00:30 | B10: 78.84 | C10: 53.56 | D10: 89.83 | E10: 6.28 | F10: 2.13 | G10: 115.85 | H10: 33.82 | I10: Invalid | J10: 0.24 | K10: 52.38 | L10: 17.53 | M10: 96.59 | N10: 79 | O10: 0 | P10: 1.31 | Q10: 9.79
A11: 01/02/2025 00:45 | B11: 78 | C11: 52.58 | D11: 88.64 | E11: 6.92 | F11: 2.13 | G11: 115.85 | H11: 33.82 | I11: Invalid | J11: 0.55 | K11: 274.79 | L11: 17.37 | M11: 98.04 | N11: 78.8 | O11: 0 | P11: 1.28 | Q11: 9.79
A12: 01/02/2025 01:00 | B12: 77.39 | C12: 52.5 | D12: 88.11 | E12: 6.61 | F12: 2.13 | G12: 112.61 | H12: 32.47 | I12: Invalid | J12: 0.57 | K12: 299.02 | L12: 17.17 | M12: 99.85 | N12: 78.8 | O12: 0 | P12: 1.24 | Q12: 9.78
A13: 01/02/2025 01:15 | B13: 77.78 | C13: 50.37 | D13: 87.31 | E13: 6.78 | F13: 2.13 | G13: 108.73 | H13: 30.86 | I13: Invalid | J13: 0.62 | K13: 281.83 | L13: 16.99 | M13: 100.95 | N13: 78.6 | O13: 0 | P13: 1.29 | Q13: 9.78
A14: 01/02/2025 01:30 | B14: 78.05 | C14: 51.45 | D14: 88.1 | E14: 6.57 | F14: 2.13 | G14: 108.73 | H14: 30.86 | I14: Invalid | J14: 0.33 | K14: 267.98 | L14: 16.86 | M14: 102.16 | N14: 78.8 | O14: 0 | P14: 1.31 | Q14: 9.77
A15: 01/02/2025 01:45 | B15: 76.88 | C15: 49.53 | D15: 86.15 | E15: 6.89 | F15: 2.13 | G15: 108.73 | H15: 30.86 | I15: Invalid | J15: 0.31 | K15: 292.75 | L15: 16.77 | M15: 102.94 | N15: 78.7 | O15: 0 | P15: 1.28 | Q15: 9.79
A16: 01/02/2025 02:00 | B16: 75.1 | C16: 50.26 | D16: 85.11 | E16: 6.75 | F16: 2.13 | G16: 106.22 | H16: 31.45 | I16: Invalid | J16: 0.59 | K16: 346.53 | L16: 16.63 | M16: 104.29 | N16: 78.8 | O16: 0 | P16: 1.26 | Q16: 9.8
A17: 01/02/2025 02:15 | B17: 73.31 | C17: 50 | D17: 83.54 | E17: 6.55 | F17: 2.13 | G17: 103.22 | H17: 32.18 | I17: Invalid | J17: 0.35 | K17: 329.61 | L17: 16.49 | M17: 105.21 | N17: 78.5 | O17: 0 | P17: 1.25 | Q17: 9.81
A18: 01/02/2025 02:30 | B18: 71.17 | C18: 50.84 | D18: 82.26 | E18: 6.07 | F18: 2.13 | G18: 103.22 | H18: 32.18 | I18: Invalid | J18: 0.28 | K18: 258.47 | L18: 16.74 | M18: 104.17 | N18: 78.3 | O18: 0 | P18: 1.21 | Q18: 9.78
A19: 01/02/2025 02:45 | B19: 69.25 | C19: 48.38 | D19: 79.43 | E19: 6.19 | F19: 2.13 | G19: 103.22 | H19: 32.18 | I19: Invalid | J19: 0.22 | K19: 283.31 | L19: 16.64 | M19: 104.06 | N19: 78.6 | O19: 0 | P19: 1.19 | Q19: 9.78
A20: 01/02/2025 03:00 | B20: 67.01 | C20: 51.13 | D20: 79.07 | E20: 6.5 | F20: 2.13 | G20: 100.73 | H20: 31.58 | I20: Invalid | J20: 0.52 | K20: 277.27 | L20: 16.71 | M20: 101.99 | N20: 78.5 | O20: 0 | P20: 1.16 | Q20: 9.75
... A104: 01/02/2025 24:00 | B104: 107.1 | C104: 57.29 | D104: 114.45 | E104: 6.21 | F104: 2.13 | G104: 166.93 | H104: 40.04 | I104: Invalid | J104: 0.67 | K104: 302.77 | L104: 17.98 | M104: 79.06 | N104: 78.5 | O104: 0 | P104: 1.88 | Q104: 9.91
A106: Min | B106: =MIN(B9:B104) -> 3.25 | C106: =MIN(C9:C104) -> 46.27 | D106: =MIN(D9:D104) -> 26.36 | E106: =MIN(E9:E104) -> 5.03 | F106: =MIN(F9:F104) -> 2.13 | G106: =MIN(G9:G104) -> 39.61 | H106: =MIN(H9:H104) -> 17.98 | I106: =MIN(I9:I104) -> 0 | ... Q106: =MIN(Q9:Q104) -> 9.15
A107: Max | B107: =MAX(B9:B104) -> 107.1 | C107: =MAX(C9:C104) -> 64.84 | D107: =MAX(D9:D104) -> 114.65 | E107: =MAX(E9:E104) -> 8.57 | F107: =MAX(F9:F104) -> 2.13 | G107: =MAX(G9:G104) -> 191.05 | H107: =MAX(H9:H104) -> 42.09 | I107: =MAX(I9:I104) -> 0 | ... Q107: =MAX(Q9:Q104) -> 9.91
A108: Avg | B108: =AVERAGE(B9:B104) -> 44.4725 | C108: =AVERAGE(C9:C104) -> 54.015 | D108: =AVERAGE(D9:D104) -> 62.508333 | E108: =AVERAGE(E9:E104) -> 6.3905208 | F108: =AVERAGE(F9:F104) -> 2.13 | G108: =AVERAGE(G9:G104) -> 83.636354 | H108: =AVERAGE(H9:H104) -> 27.384792 | I108: =AVERAGE(I9:I104) -> #DIV/0! | ... Q108: =AVERAGE(Q9:Q104) -> 9.6017708
A109: Stdev | B109: =STDEV(B9:B104) -> 29.891747 | C109: =STDEV(C9:C104) -> 4.9786747 | D109: =STDEV(D9:D104) -> 24.053156 | E109: =STDEV(E9:E104) -> 0.80940052 | F109: =STDEV(F9:F104) -> 2.6785224e-15 | G109: =STDEV(G9:G104) -> 44.108563 | H109: =STDEV(H9:H104) -> 6.1186142 | I109: =STDEV(I9:I104) -> #DIV/0! | ... Q109: =STDEV(Q9:Q104) -> 0.19480081
A110: Num | B110: =COUNT(B9:B104) -> 96 | C110: =COUNT(C9:C104) -> 96 | D110: =COUNT(D9:D104) -> 96 | E110: =COUNT(E9:E104) -> 96 | F110: =COUNT(F9:F104) -> 96 | G110: =COUNT(G9:G104) -> 96 | H110: =COUNT(H9:H104) -> 96 | I110: =COUNT(I9:I104) -> 0 | ... Q110: =COUNT(Q9:Q104) -> 96
A111: DCR | B111: =IF(B110>=87,">90%",IF(B110<=87,"<90%")) -> >90% | C111: =IF(C110>=87,">90%",IF(C110<=87,"<90%")) -> >90% | D111: =IF(D110>=87,">90%",IF(D110<=87,"<90%")) -> >90% | E111: =IF(E110>=87,">90%",IF(E110<=87,"<90%")) -> >90% | F111: =IF(F110>=87,">90%",IF(F110<=87,"<90%")) -> >90% | G111: =IF(G110>=87,">90%",IF(G110<=87,"<90%")) -> >90% | H111: =IF(H110>=87,">90%",IF(H110<=87,"<90%")) -> >90% | I111: =IF(I110>=87,">90%",IF(I110<=87,"<90%")) -> <90% | ... Q111: =IF(Q110>=87,">90%",IF(Q110<=87,"<90%")) -> >90%
A112: Status | B112: =IF(B110>=87,"OK",IF(B110<=87,"LESS")) -> OK | C112: =IF(C110>=87,"OK",IF(C110<=87,"LESS")) -> OK | D112: =IF(D110>=87,"OK",IF(D110<=87,"LESS")) -> OK | E112: =IF(E110>=87,"OK",IF(E110<=87,"LESS")) -> OK | F112: =IF(F110>=87,"OK",IF(F110<=87,"LESS")) -> OK | G112: =IF(G110>=87,"OK",IF(G110<=87,"LESS")) -> OK | H112: =IF(H110>=87,"OK",IF(H110<=87,"LESS")) -> OK | I112: =IF(I110>=87,"OK",IF(I110<=87,"LESS")) -> LESS | ... Q112: =IF(Q110>=87,"OK",IF(Q110<=87,"LESS")) -> OK
A115: Done by | B115: RK
A117: Comment

Sheet 02
A1: Station: | B1: BHATAGAON RAIPUR
A2: Date: | B2: =$A$9 -> 02/02/2025 00:15 | D2: Power Off | G2: Pw.Off | L2: Link Fail | N2: Link F | P2: Maintenance | R2: Maint.
A3: Report Type: | B3: Mean | D3: Calibration | G3: Calib. | L3: Data Fail | N3: Data F | P3: Invalid | R3: Invalid
A4: Time Base: | B4: 15 Min | D4: Zero Referrence | G4: Z.Ref | L4: Warm Up | N4: Wm. Up
A7: Date & Time | B7: NO_BHATAGAON | C7: NO2__BHATAGAON | D7: NOX_BHATAGAON | E7: SO2__BHATAGAON | F7: O3__BHATAGAON | G7: PM10__BHATAGAON | H7: PM2_5__BHATAGAON | I7: BENZ__BHATAGAON | J7: WS__BHATAGAON | K7: WD__BHATAGAON | L7: TEMP__BHATAGAON | M7: HUM__BHATAGAON | N7: SR__BHATAGAON | O7: RG__BHATAGAON | P7: CO__BHATAGAON | Q7: NH3__BHATAGAON
B8: ug/m3 | C8: ug/m3 | D8: ppb | E8: ug/m3 | F8: ug/m3 | G8: ug/m3 | H8: ug/m3 | I8: ug/m3 | J8: m/sec | K8: deg | L8: degreC | M8: % | N8: w/m2 | O8: mm | P8: mg/m3 | Q8: ug/m3
A9: 02/02/2025 00:15 | B9: 106.68 | C9: 56.85 | D9: 113.88 | E9: 7.34 | F9: 2.13 | G9: 140.24 | H9: 37.59 | I9: Invalid | J9: 0.65 | K9: 307.18 | L9: 17.76 | M9: 82.39 | N9: 78.6 | O9: 0 | P9: 1.76 | Q9: 9.94
A10: 02/02/2025 00:30 | B10: 106.16 | C10: 51.32 | D10: 110.57 | E10: 6.71 | F10: 2.13 | G10: 140.24 | H10: 37.59 | I10: Invalid | J10: 0.64 | K10: 306.3 | L10: 17.52 | M10: 82.61 | N10: 78.7 | O10: 0 | P10: 1.7 | Q10: 9.97
A11: 02/02/2025 00:45 | B11: 104.97 | C11: 52.2 | D11: 110.07 | E11: 7.08 | F11: 2.13 | G11: 140.24 | H11: 37.59 | I11: Invalid | J11: 0.66 | K11: 299.6 | L11: 17.25 | M11: 83.38 | N11: 78.6 | O11: 0 | P11: 1.69 | Q11: 9.95
A12: 02/02/2025 01:00 | B12: 103.79 | C12: 52.34 | D12: 109.2 | E12: 6.88 | F12: 2.13 | G12: 144.42 | H12: 39.16 | I12: Invalid | J12: 0.26 | K12: 267.38 | L12: 16.97 | M12: 84.92 | N12: 78.7 | O12: 0 | P12: 1.7 | Q12: 9.91
A13: 02/02/2025 01:15 | B13: 102.47 | C13: 52.53 | D13: 108.24 | E13: 6.55 | F13: 2.13 | G13: 149.43 | H13: 41.03 | I13: Invalid | J13: 0.62 | K13: 279.85 | L13: 16.74 | M13: 87.51 | N13: 78.6 | O13: 0 | P13: 1.46 | Q13: 9.91
A14: 02/02/2025 01:30 | B14: 100.78 | C14: 52.13 | D14: 106.68 | E14: 6.54 | F14: 2.13 | G14: 149.43 | H14: 41.03 | I14: Invalid | J14: 0.59 | K14: 281.12 | L14: 16.71 | M14: 87.19 | N14: 78.3 | O14: 0 | P14: 1.41 | Q14: 9.9
A15: 02/02/2025 01:45 | B15: 98.87 | C15: 51.45 | D15: 104.79 | E15: 6.74 | F15: 2.13 | G15: 149.43 | H15: 41.03 | I15: Invalid | J15: 0.65 | K15: 304 | L15: 16.71 | M15: 87.78 | N15: 78.4 | O15: 0 | P15: 1.41 | Q15: 9.9
A16: 02/02/2025 02:00 | B16: 96.67 | C16: 51.61 | D16: 103.11 | E16: 6.48 | F16: 2.13 | G16: 133.1 | H16: 34.85 | I16: Invalid | J16: 0.63 | K16: 298.36 | L16: 16.52 | M16: 87.97 | N16: 78.6 | O16: 0 | P16: 1.32 | Q16: 9.89
A17: 02/02/2025 02:15 | B17: 94.8 | C17: 49.08 | D17: 100.29 | E17: 6.42 | F17: 2.13 | G17: 113.58 | H17: 26.67 | I17: Invalid | J17: 0.17 | K17: 290.94 | L17: 16.53 | M17: 86.11 | N17: 78.2 | O17: 0 | P17: 1.49 | Q17: 9.9
A18: 02/02/2025 02:30 | B18: 91.38 | C18: 49.44 | D18: 97.74 | E18: 6.16 | F18: 2.13 | G18: 113.58 | H18: 26.67 | I18: Invalid | J18: 0.56 | K18: 159.47 | L18: 17.21 | M18: 76.75 | N18: 77.3 | O18: 0 | P18: 1.48 | Q18: 9.91
A19: 02/02/2025 02:45 | B19: 86.8 | C19: 50.01 | D19: 94.36 | E19: 5.95 | F19: 2.13 | G19: 113.58 | H19: 26.67 | I19: Invalid | J19: 0.2 | K19: 283.8 | L19: 17.37 | M19: 74.15 | N19: 78.5 | O19: 0 | P19: 1.39 | Q19: 9.89
A20: 02/02/2025 03:00 | B20: 82.08 | C20: 50.07 | D20: 90.6 | E20: 5.26 | F20: 2.13 | G20: 97.66 | H20: 21.81 | I20: Invalid | J20: 0.67 | K20: 309.59 | L20: 16.95 | M20: 77.8 | N20: 78.8 | O20: 0 | P20: 1.37 | Q20: 9.89
... A64: 02/02/2025 14:00 | B64: 7.01 | C64: 64.59 | D64: 37.99 | E64: 5.39 | F64: 2.13 | G64: 54.79 | H64: 43.29 | I64: Invalid | J64: 0.51 | K64: 220.91 | L64: 29.97 | M64: 33.48 | N64: 517.6 | O64: 0 | P64: 0.68 | Q64: 9.51
A65: 02/02/2025 14:15 | B65: 6.09 | C65: 63.18 | D65: 36.52 | E65: 5.57 | F65: 2.13 | G65: 47.04 | H65: Data F | I65: Invalid | J65: 0.68 | K65: 283.65 | L65: 29.68 | M65: 33.49 | N65: 478.7 | O65: 0 | P65: 0.73 | Q65: 9.49
A66: 02/02/2025 14:30 | B66: 5.25 | C66: 61.95 | D66: 35.2 | E66: 5.51 | F66: 2.13 | G66: 47.04 | H66: Data F | I66: Invalid | J66: 0.78 | K66: 298.57 | L66: 29.9 | M66: 33.82 | N66: 359.9 | O66: 0 | P66: 0.66 | Q66: 9.49
A67: 02/02/2025 14:45 | B67: 4.78 | C67: 62.53 | D67: 35.13 | E67: 5.56 | F67: 2.13 | G67: 47.04 | H67: Data F | I67: Invalid | J67: 0.66 | K67: 244.23 | L67: 29.11 | M67: 32.47 | N67: 224.6 | O67: 0 | P67: 0.69 | Q67: 9.48
A68: 02/02/2025 15:00 | B68: 4.16 | C68: 62.17 | D68: 34.44 | E68: 5.51 | F68: 2.13 | G68: 44.36 | H68: 18.69 | I68: Invalid | J68: 0.58 | K68: 292.86 | L68: 29 | M68: 34.35 | N68: 216.7 | O68: 0 | P68: 0.64 | Q68: 9.45
A69: 02/02/2025 15:15 | B69: 3.81 | C69: 60.06 | D69: 33.05 | E69: 5.48 | F69: 2.13 | G69: 41.15 | H69: 41.02 | I69: Invalid | J69: 0.93 | K69: 299.87 | L69: 28.66 | M69: 35.47 | N69: 228.5 | O69: 0 | P69: 0.63 | Q69: 9.41
A70: 02/02/2025 15:30 | B70: 3.5 | C70: 59.94 | D70: 32.74 | E70: 5.32 | F70: 2.13 | G70: 41.15 | H70: 41.02 | I70: Invalid | J70: 0.76 | K70: 287.46 | L70: 28.64 | M70: 34.04 | N70: 186.2 | O70: 0 | P70: 0.63 | Q70: 9.39
A71: 02/02/2025 15:45 | B71: 3.3 | C71: 59.11 | D71: 32.16 | E71: 5.46 | F71: 2.16 | G71: 41.15 | H71: 41.02 | I71: Invalid | J71: 0.7 | K71: 279.26 | L71: 28.39 | M71: 33.87 | N71: 152.9 | O71: 0 | P71: 0.61 | Q71: 9.38
A72: 02/02/2025 16:00 | B72: 3.15 | C72: 57.95 | D72: 31.43 | E72: 5.67 | F72: 2.22 | G72: 43.16 | H72: 38.68 | I72: Invalid | J72: 0.77 | K72: 280.16 | L72: 28.16 | M72: 34.06 | N72: 136.9 | O72: 0 | P72: 0.6 | Q72: 9.36
A73: 02/02/2025 16:15 | B73: 3.05 | C73: 57.85 | D73: 31.3 | E73: 6.14 | F73: 2.22 | G73: 45.56 | H73: 35.88 | I73: Invalid | J73: 0.78 | K73: 277.34 | L73: 27.91 | M73: 33.79 | N73: 129.8 | O73: 0 | P73: 0.61 | Q73: 9.36
A74: 02/02/2025 16:30 | B74: 3.07 | C74: 57.28 | D74: 31.01 | E74: 6.4 | F74: 2.14 | G74: 45.56 | H74: 35.88 | I74: Invalid | J74: 0.51 | K74: 277.43 | L74: 27.72 | M74: 33.36 | N74: 123.4 | O74: 0 | P74: 0.62 | Q74: 9.34
A75: 02/02/2025 16:45 | B75: 3.23 | C75: 58.21 | D75: 31.63 | E75: 6.61 | F75: 2.13 | G75: 45.56 | H75: 35.88 | I75: Invalid | J75: 0.35 | K75: 272.35 | L75: 27.45 | M75: 33.65 | N75: 116.8 | O75: 0 | P75: 0.63 | Q75: 9.35
A76: 02/02/2025 17:00 | B76: 3.35 | C76: 56.91 | D76: 31.05 | E76: 6.33 | F76: 2.31 | G76: 47.34 | H76: 27.74 | I76: Invalid | J76: 0.26 | K76: 300.27 | L76: 27.12 | M76: 34.69 | N76: 111.1 | O76: 0 | P76: 0.67 | Q76: 9.35
A77: 02/02/2025 17:15 | B77: 3.58 | C77: 55.01 | D77: 30.23 | E77: 5.92 | F77: 2.13 | G77: 49.47 | H77: 18.01 | I77: Invalid | J77: 0.62 | K77: 309.99 | L77: 26.87 | M77: 36.64 | N77: 102.8 | O77: 0 | P77: 0.73 | Q77: 9.34
A78: 02/02/2025 17:30 | B78: 4.34 | C78: 55.64 | D78: 31.17 | E78: 5.92 | F78: 2.13 | G78: 49.47 | H78: 18.01 | I78: Invalid | J78: 0.88 | K78: 295.96 | L78: 26.45 | M78: 38.77 | N78: 95 | O78: 0 | P78: 0.66 | Q78: 9.35
A79: 02/02/2025 17:45 | B79: 4.99 | C79: 55.84 | D79: 31.8 | E79: 5.91 | F79: 2.13 | G79: 49.47 | H79: 18.01 | I79: Invalid | J79: 1.13 | K79: 309.52 | L79: 25.82 | M79: 40.21 | N79: 88.1 | O79: 0 | P79: 0.67 | Q79: 9.38
... A104: 02/02/2025 24:00 | B104: 60.58 | C104: 58.75 | D104: 77.9 | E104: 6.02 | F104: 2.13 | G104: 105.64 | H104: 34.21 | I104: Invalid | J104: 0.41 | K104: 340.66 | L104: 18.56 | M104: 76.53 | N104: 80.6 | O104: 0 | P104: 1.19 | Q104: 9.71
A106: Min | B106: =MIN(B9:B104) -> 3.05 | C106: =MIN(C9:C104) -> 46.74 | D106: =MIN(D9:D104) -> 30.23 | E106: =MIN(E9:E104) -> 5.2 | F106: =MIN(F9:F104) -> 2.13 | G106: =MIN(G9:G104) -> 41.15 | H106: =MIN(H9:H104) -> 5.51 | I106: =MIN(I9:I104) -> 0 | ... Q106: =MIN(Q9:Q104) -> 9.34
A107: Max | B107: =MAX(B9:B104) -> 106.68 | C107: =MAX(C9:C104) -> 71.75 | D107: =MAX(D9:D104) -> 113.88 | E107: =MAX(E9:E104) -> 7.78 | F107: =MAX(F9:F104) -> 2.31 | G107: =MAX(G9:G104) -> 149.43 | H107: =MAX(H9:H104) -> 75.33 | I107: =MAX(I9:I104) -> 0 | ... Q107: =MAX(Q9:Q104) -> 9.97
A108: Avg | B108: =AVERAGE(B9:B104) -> 42.412708 | C108: =AVERAGE(C9:C104) -> 56.769687 | D108: =AVERAGE(D9:D104) -> 62.295312 | E108: =AVERAGE(E9:E104) -> 6.1725 | F108: =AVERAGE(F9:F104) -> 2.1341667 | G108: =AVERAGE(G9:G104) -> 80.960104 | H108: =AVERAGE(H9:H104) -> 31.241183 | I108: =AVERAGE(I9:I104) -> #DIV/0! | ... Q108: =AVERAGE(Q9:Q104) -> 9.6358333
A109: Stdev | B109: =STDEV(B9:B104) -> 31.966574 | C109: =STDEV(C9:C104) -> 6.0183394 | D109: =STDEV(D9:D104) -> 23.507075 | E109: =STDEV(E9:E104) -> 0.67227814 | F109: =STDEV(F9:F104) -> 0.022462444 | G109: =STDEV(G9:G104) -> 26.222251 | H109: =STDEV(H9:H104) -> 17.544535 | I109: =STDEV(I9:I104) -> #DIV/0! | ... Q109: =STDEV(Q9:Q104) -> 0.17153589
A110: Num | B110: =COUNT(B9:B104) -> 96 | C110: =COUNT(C9:C104) -> 96 | D110: =COUNT(D9:D104) -> 96 | E110: =COUNT(E9:E104) -> 96 | F110: =COUNT(F9:F104) -> 96 | G110: =COUNT(G9:G104) -> 96 | H110: =COUNT(H9:H104)+3 -> 96 | I110: =COUNT(I9:I104) -> 0 | J110: =COUNT(J9:J104) -> 96 | K110: =COUNT(K9:K104) -> 96 | L110: =COUNT(L9:L104) -> 96 | M110: =COUNT(M9:M104) -> 96 | N110: =COUNT(N9:N104) -> 96 | O110: =COUNT(O9:O104) -> 96 | P110: =COUNT(P9:P104) -> 96 | Q110: =COUNT(Q9:Q104) -> 96
...

Sheet 03
A1: Station: | B1: BHATAGAON RAIPUR
A2: Date: | B2: =$A$9 -> 03/02/2025 00:15 | D2: Power Off | G2: Pw.Off | L2: Link Fail | N2: Link F | P2: Maintenance | R2: Maint.
A3: Report Type: | B3: Mean | D3: Calibration | G3: Calib. | L3: Data Fail | N3: Data F | P3: Invalid | R3: Invalid
A4: Time Base: | B4: 15 Min | D4: Zero Referrence | G4: Z.Ref | L4: Warm Up | N4: Wm. Up
A7: Date & Time | B7: NO_BHATAGAON | C7: NO2__BHATAGAON | D7: NOX_BHATAGAON | E7: SO2__BHATAGAON | F7: O3__BHATAGAON | G7: PM10__BHATAGAON | H7: PM2_5__BHATAGAON | I7: BENZ__BHATAGAON | J7: WS__BHATAGAON | K7: WD__BHATAGAON | L7: TEMP__BHATAGAON | M7: HUM__BHATAGAON | N7: SR__BHATAGAON | O7: RG__BHATAGAON | P7: CO__BHATAGAON | Q7: NH3__BHATAGAON
B8: ug/m3 | C8: ug/m3 | D8: ppb | E8: ug/m3 | F8: ug/m3 | G8: ug/m3 | H8: ug/m3 | I8: ug/m3 | J8: m/sec | K8: deg | L8: degreC | M8: % | N8: w/m2 | O8: mm | P8: mg/m3 | Q8: ug/m3
A9: 03/02/2025 00:15 | B9: 62.67 | C9: 60.41 | D9: 80.44 | E9: 6.45 | F9: 2.13 | G9: 103.12 | H9: 35.04 | I9: Invalid | J9: 0.62 | K9: 305.7 | L9: 18.52 | M9: 78.04 | N9: 80.3 | O9: 0 | P9: 1.21 | Q9: 9.7
A10: 03/02/2025 00:30 | B10: 62.67 | C10: 58.73 | D10: 79.56 | E10: 6.27 | F10: 2.13 | G10: 103.12 | H10: 35.04 | I10: Invalid | J10: 0.59 | K10: 344.83 | L10: 18.79 | M10: 72.78 | N10: 80.4 | O10: 0 | P10: 1.16 | Q10: 9.74
A11: 03/02/2025 00:45 | B11: 61.52 | C11: 59.09 | D11: 78.83 | E11: 5.94 | F11: 2.14 | G11: 103.12 | H11: 35.04 | I11: Invalid | J11: 0.98 | K11: 322.73 | L11: 18.88 | M11: 70.2 | N11: 79.6 | O11: 0 | P11: 1.16 | Q11: 9.76
A12: 03/02/2025 01:00 | B12: 59.65 | C12: 58.95 | D12: 77.26 | E12: 5.76 | F12: 2.13 | G12: 104 | H12: 35.21 | I12: Invalid | J12: 0.93 | K12: 335.34 | L12: 19.04 | M12: 71.01 | N12: 80.6 | O12: 0 | P12: 1.16 | Q12: 9.76
A13: 03/02/2025 01:15 | B13: 57.64 | C13: 58.06 | D13: 75.18 | E13: 6.57 | F13: 2.13 | G13: 105.04 | H13: 35.42 | I13: Invalid | J13: 0.37 | K13: 355.33 | L13: 18.94 | M13: 68.48 | N13: 81.1 | O13: 0 | P13: 1.05 | Q13: 9.76
A14: 03/02/2025 01:30 | B14: 55.84 | C14: 53.08 | D14: 71.13 | E14: 5.89 | F14: 2.13 | G14: 105.04 | H14: 35.42 | I14: Invalid | J14: 0.45 | K14: 309.08 | L14: 18.68 | M14: 69.92 | N14: 80.8 | O14: 0 | P14: 1.02 | Q14: 9.76
A15: 03/02/2025 01:45 | B15: 54.34 | C15: 52.82 | D15: 69.8 | E15: 5.88 | F15: 2.13 | G15: 105.04 | H15: 35.42 | I15: Invalid | J15: 0.67 | K15: 315.03 | L15: 18.28 | M15: 73.54 | N15: 80.8 | O15: 0 | P15: 1.05 | Q15: 9.75
A16: 03/02/2025 02:00 | B16: 53.48 | C16: 52.81 | D16: 69.1 | E16: 6.04 | F16: 2.13 | G16: 107.64 | H16: 37.38 | I16: Invalid | J16: 0.64 | K16: 314.56 | L16: 18.14 | M16: 72.29 | N16: 80.4 | O16: 0 | P16: 1.03 | Q16: 9.74
A17: 03/02/2025 02:15 | B17: 52.4 | C17: 52.73 | D17: 68.2 | E17: 6.02 | F17: 2.13 | G17: 110.75 | H17: 39.72 | I17: Invalid | J17: 0.62 | K17: 298.7 | L17: 18.16 | M17: 71.24 | N17: 80.8 | O17: 0 | P17: 0.99 | Q17: 9.72
A18: 03/02/2025 02:30 | B18: 51.06 | C18: 52.45 | D18: 66.97 | E18: 6.41 | F18: 2.13 | G18: 110.75 | H18: 39.72 | I18: Invalid | J18: 0.94 | K18: 337.37 | L18: 17.97 | M18: 74.48 | N18: 80.6 | O18: 0 | P18: 1.04 | Q18: 9.71
A19: 03/02/2025 02:45 | B19: 49.83 | C19: 51.97 | D19: 65.74 | E19: 6.32 | F19: 2.13 | G19: 110.75 | H19: 39.72 | I19: Invalid | J19: 0.59 | K19: 320.56 | L19: 17.71 | M19: 74.72 | N19: 81.2 | O19: 0 | P19: 1.07 | Q19: 9.69
A20: 03/02/2025 03:00 | B20: 48.61 | C20: 51.64 | D20: 64.58 | E20: 6.46 | F20: 2.13 | G20: 117.52 | H20: 43.75 | I20: Invalid | J20: 0.64 | K20: 267.24 | L20: 17.58 | M20: 75.95 | N20: 81 | O20: 0 | P20: 1.05 | Q20: 9.68
... A104: 03/02/2025 24:00 | B104: 131.62 | C104: 60.66 | D104: 135.87 | E104: 7.4 | F104: 2.13 | G104: 142.37 | H104: 40.88 | I104: Invalid | J104: 0.36 | K104: 88.08 | L104: 19.1 | M104: 84.39 | N104: 75 | O104: 0 | P104: 2.06 | Q104: 10.09
A106: Min | B106: =MIN(B9:B104) -> 3.43 | C106: =MIN(C9:C104) -> 45.93 | D106: =MIN(D9:D104) -> 33.29 | E106: =MIN(E9:E104) -> 5.45 | F106: =MIN(F9:F104) -> 2.13 | G106: =MIN(G9:G104) -> 63.3 | H106: =MIN(H9:H104) -> 3.29 | I106: =MIN(I9:I104) -> 0 | ... Q106: =MIN(Q9:Q104) -> 9.46
A107: Max | B107: =MAX(B9:B104) -> 131.62 | C107: =MAX(C9:C104) -> 69.91 | D107: =MAX(D9:D104) -> 135.87 | E107: =MAX(E9:E104) -> 8.87 | F107: =MAX(F9:F104) -> 2.45 | G107: =MAX(G9:G104) -> 185.53 | H107: =MAX(H9:H104) -> 72.82 | I107: =MAX(I9:I104) -> 0 | ... Q107: =MAX(Q9:Q104) -> 10.09
A108: Avg | B108: =AVERAGE(B9:B104) -> 40.322396 | C108: =AVERAGE(C9:C104) -> 59.2075 | D108: =AVERAGE(D9:D104) -> 61.892812 | E108: =AVERAGE(E9:E104) -> 6.6751042 | F108: =AVERAGE(F9:F104) -> 2.1436458 | G108: =AVERAGE(G9:G104) -> 102.3124 | H108: =AVERAGE(H9:H104) -> 36.736146 | I108: =AVERAGE(I9:I104) -> #DIV/0! | ... Q108: =AVERAGE(Q9:Q104) -> 9.6610417
A109: Stdev | B109: =STDEV(B9:B104) -> 29.88761 | C109: =STDEV(C9:C104) -> 7.5253244 | D109: =STDEV(D9:D104) -> 23.632593 | E109: =STDEV(E9:E104) -> 0.83953244 | F109: =STDEV(F9:F104) -> 0.048560755 | G109: =STDEV(G9:G104) -> 30.117447 | H109: =STDEV(H9:H104) -> 13.586743 | I109: =STDEV(I9:I104) -> #DIV/0! | ... Q109: =STDEV(Q9:Q104) -> 0.12904083
A110: Num | B110: =COUNT(B9:B104) -> 96 | C110: =COUNT(C9:C104) -> 96 | D110: =COUNT(D9:D104) -> 96 | E110: =COUNT(E9:E104) -> 96 | F110: =COUNT(F9:F104) -> 96 | G110: =COUNT(G9:G104) -> 96 | H110: =COUNT(H9:H104) -> 96 | I110: =COUNT(I9:I104) -> 0 | ... Q110: =COUNT(Q9:Q104) -> 96
A111: DCR | B111: =IF(B110>=87,">90%",IF(B110<=87,"<90%")) -> >90% | C111: =IF(C110>=87,">90%",IF(C110<=87,"<90%")) -> >90% | D111: =IF(D110>=87,">90%",IF(D110<=87,"<90%")) -> >90% | E111: =IF(E110>=87,">90%",IF(E110<=87,"<90%")) -> >90% | F111: =IF(F110>=87,">90%",IF(F110<=87,"<90%")) -> >90% | G111: =IF(G110>=87,">90%",IF(G110<=87,"<90%")) -> >90% | H111: =IF(H110>=87,">90%",IF(H110<=87,"<90%")) -> >90% | I111: =IF(I110>=87,">90%",IF(I110<=87,"<90%")) -> <90% | ... Q111: =IF(Q110>=87,">90%",IF(Q110<=87,"<90%")) -> >90%
A112: Status | B112: =IF(B110>=87,"OK",IF(B110<=87,"LESS")) -> OK | C112: =IF(C110>=87,"OK",IF(C110<=87,"LESS")) -> OK | D112: =IF(D110>=87,"OK",IF(D110<=87,"LESS")) -> OK | E112: =IF(E110>=87,"OK",IF(E110<=87,"LESS")) -> OK | F112: =IF(F110>=87,"OK",IF(F110<=87,"LESS")) -> OK | G112: =IF(G110>=87,"OK",IF(G110<=87,"LESS")) -> OK | H112: =IF(H110>=87,"OK",IF(H110<=87,"LESS")) -> OK | I112: =IF(I110>=87,"OK",IF(I110<=87,"LESS")) -> LESS | ... Q112: =IF(Q110>=87,"OK",IF(Q110<=87,"LESS")) -> OK
A115: Done by | B115: RK
A117: Comment

Sheet 04
A1: Station: | B1: BHATAGAON RAIPUR
A2: Date: | B2: =$A$9 -> 04/02/2025 00:15 | D2: Power Off | G2: Pw.Off | L2: Link Fail | N2: Link F | P2: Maintenance | R2: Maint.
A3: Report Type: | B3: Mean | D3: Calibration | G3: Calib. | L3: Data Fail | N3: Data F | P3: Invalid | R3: Invalid
A4: Time Base: | B4: 15 Min | D4: Zero Referrence | G4: Z.Ref | L4: Warm Up | N4: Wm. Up
A7: Date & Time | B7: NO_BHATAGAON | C7: NO2__BHATAGAON | D7: NOX_BHATAGAON | E7: SO2__BHATAGAON | F7: O3__BHATAGAON | G7: PM10__BHATAGAON | H7: PM2_5__BHATAGAON | I7: BENZ__BHATAGAON | J7: WS__BHATAGAON | K7: WD__BHATAGAON | L7: TEMP__BHATAGAON | M7: HUM__BHATAGAON | N7: SR__BHATAGAON | O7: RG__BHATAGAON | P7: CO__BHATAGAON | Q7: NH3__BHATAGAON
B8: ug/m3 | C8: ug/m3 | D8: ppb | E8: ug/m3 | F8: ug/m3 | G8: ug/m3 | H8: ug/m3 | I8: ug/m3 | J8: m/sec | K8: deg | L8: degreC | M8: % | N8: w/m2 | O8: mm | P8: mg/m3 | Q8: ug/m3
A9: 04/02/2025 00:15 | B9: 137.41 | C9: 58.86 | D9: 139.57 | E9: 9.44 | F9: 2.13 | G9: 138.24 | H9: 38.56 | I9: Invalid | J9: 0.71 | K9: 342.38 | L9: 18.93 | M9: 89.34 | N9: 75 | O9: 0 | P9: 2.03 | Q9: 10.11
A10: 04/02/2025 00:30 | B10: 139.7 | C10: 58.7 | D10: 141.32 | E10: 9.46 | F10: 2.13 | G10: 138.24 | H10: 38.56 | I10: Invalid | J10: 0.37 | K10: 51 | L10: 19.11 | M10: 84.84 | N10: 74.3 | O10: 0 | P10: 2.14 | Q10: 10.16
A11: 04/02/2025 00:45 | B11: 136.58 | C11: 58.61 | D11: 138.77 | E11: 9.32 | F11: 2.13 | G11: 138.24 | H11: 38.56 | I11: Invalid | J11: 0.43 | K11: 4.23 | L11: 19.67 | M11: 74.66 | N11: 74.8 | O11: 0 | P11: 2.08 | Q11: 10.21
A12: 04/02/2025 01:00 | B12: 132.3 | C12: 57.58 | D12: 134.8 | E12: 8.95 | F12: 2.13 | G12: 140.21 | H12: 38.1 | I12: Invalid | J12: 0.56 | K12: 269.37 | L12: 19.32 | M12: 77.63 | N12: 75.3 | O12: 0 | P12: 2.1 | Q12: 10.21
A13: 04/02/2025 01:15 | B13: 127.91 | C13: 58.64 | D13: 131.83 | E13: 8.68 | F13: 2.13 | G13: 142.57 | H13: 37.55 | I13: Invalid | J13: 0.61 | K13: 291.33 | L13: 18.97 | M13: 78.43 | N13: 75.4 | O13: 0 | P13: 1.87 | Q13: 10.21
A14: 04/02/2025 01:30 | B14: 123.98 | C14: 58.62 | D14: 128.67 | E14: 8.85 | F14: 2.13 | G14: 142.57 | H14: 37.55 | I14: Invalid | J14: 0.63 | K14: 295.66 | L14: 18.67 | M14: 80.91 | N14: 75.3 | O14: 0 | P14: 1.94 | Q14: 10.22
A15: 04/02/2025 01:45 | B15: 120.28 | C15: 55.48 | D15: 124.07 | E15: 8.99 | F15: 2.13 | G15: 142.57 | H15: 37.55 | I15: Invalid | J15: 0.18 | K15: 65.98 | L15: 18.43 | M15: 84.73 | N15: 75.3 | O15: 0 | P15: 1.95 | Q15: 10.21
A16: 04/02/2025 02:00 | B16: 117.2 | C16: 56.24 | D16: 121.99 | E16: 9.12 | F16: 2.13 | G16: 147.18 | H16: 42.49 | I16: Invalid | J16: 0.78 | K16: 153.13 | L16: 18.78 | M16: 82.67 | N16: 74.2 | O16: 0 | P16: 1.96 | Q16: 10.17
A17: 04/02/2025 02:15 | B17: 114.82 | C17: 56.88 | D17: 120.42 | E17: 9.23 | F17: 2.13 | G17: 152.7 | H17: 48.39 | I17: Invalid | J17: 0.25 | K17: 221.83 | L17: 18.76 | M17: 85.28 | N17: 75.2 | O17: 0 | P17: 1.88 | Q17: 10.15
A18: 04/02/2025 02:30 | B18: 112.53 | C18: 51.61 | D18: 115.83 | E18: 8.76 | F18: 2.13 | G18: 152.7 | H18: 48.39 | I18: Invalid | J18: 0.95 | K18: 330.81 | L18: 18.26 | M18: 89.8 | N18: 75.6 | O18: 0 | P18: 1.78 | Q18: 10.13
A19: 04/02/2025 02:45 | B19: 109.93 | C19: 51.64 | D19: 113.76 | E19: 8.83 | F19: 2.13 | G19: 152.7 | H19: 48.39 | I19: Invalid | J19: 0.61 | K19: 307.67 | L19: 17.8 | M19: 92.4 | N19: 75.2 | O19: 0 | P19: 1.74 | Q19: 10.11
A20: 04/02/2025 03:00 | B20: 107.6 | C20: 52.18 | D20: 112.17 | E20: 8.45 | F20: 2.13 | G20: 140.52 | H20: 44.99 | I20: Invalid | J20: 0.28 | K20: 305.47 | L20: 17.81 | M20: 89.13 | N20: 75 | O20: 0 | P20: 1.73 | Q20: 10.09
... A104: 04/02/2025 24:00 | B104: 216.27 | C104: 55.95 | D104: 201.29 | E104: 10.06 | F104: 2.13 | G104: 212.14 | H104: 56.09 | I104: Invalid | J104: 0.08 | K104: 230.4 | L104: 19.18 | M104: 74.2 | N104: 78.7 | O104: 0 | P104: 2.21 | Q104: 10.59
A106: Min | B106: =MIN(B9:B104) -> 2.99 | C106: =MIN(C9:C104) -> 47.6 | D106: =MIN(D9:D104) -> 29.18 | E106: =MIN(E9:E104) -> 4.87 | F106: =MIN(F9:F104) -> 2.13 | G106: =MIN(G9:G104) -> 53.02 | H106: =MIN(H9:H104) -> 16.64 | I106: =MIN(I9:I104) -> 0 | ... Q106: =MIN(Q9:Q104) -> 9.52
A107: Max | B107: =MAX(B9:B104) -> 219.32 | C107: =MAX(C9:C104) -> 66.98 | D107: =MAX(D9:D104) -> 204.18 | E107: =MAX(E9:E104) -> 11.97 | F107: =MAX(F9:F104) -> 2.76 | G107: =MAX(G9:G104) -> 256.42 | H107: =MAX(H9:H104) -> 63.81 | I107: =MAX(I9:I104) -> 0 | ... Q107: =MAX(Q9:Q104) -> 10.59
A108: Avg | B108: =AVERAGE(B9:B104) -> 66.656667 | C108: =AVERAGE(C9:C104) -> 57.73 | D108: =AVERAGE(D9:D104) -> 82.238542 | E108: =AVERAGE(E9:E104) -> 7.2648958 | F108: =AVERAGE(F9:F104) -> 2.1722917 | G108: =AVERAGE(G9:G104) -> 117.97427 | H108: =AVERAGE(H9:H104) -> 39.624792 | I108: =AVERAGE(I9:I104) -> #DIV/0! | ... Q108: =AVERAGE(Q9:Q104) -> 9.8470833
A109: Stdev | B109: =STDEV(B9:B104) -> 61.183421 | C109: =STDEV(C9:C104) -> 4.5378114 | D109: =STDEV(D9:D104) -> 48.817918 | E109: =STDEV(E9:E104) -> 1.8117691 | F109: =STDEV(F9:F104) -> 0.13676318 | G109: =STDEV(G9:G104) -> 58.958596 | H109: =STDEV(H9:H104) -> 11.340484 | I109: =STDEV(I9:I104) -> #DIV/0! | ... Q109: =STDEV(Q9:Q104) -> 0.27846919
A110: Num | B110: =COUNT(B9:B104) -> 96 | C110: =COUNT(C9:C104) -> 96 | D110: =COUNT(D9:D104) -> 96 | E110: =COUNT(E9:E104) -> 96 | F110: =COUNT(F9:F104) -> 96 | G110: =COUNT(G9:G104) -> 96 | H110: =COUNT(H9:H104) -> 96 | I110: =COUNT(I9:I104) -> 0 | ... Q110: =COUNT(Q9:Q104) -> 96
A111: DCR | B111: =IF(B110>=87,">90%",IF(B110<=87,"<90%")) -> >90% | C111: =IF(C110>=87,">90%",IF(C110<=87,"<90%")) -> >90% | D111: =IF(D110>=87,">90%",IF(D110<=87,"<90%")) -> >90% | E111: =IF(E110>=87,">90%",IF(E110<=87,"<90%")) -> >90% | F111: =IF(F110>=87,">90%",IF(F110<=87,"<90%")) -> >90% | G111: =IF(G110>=87,">90%",IF(G110<=87,"<90%")) -> >90% | H111: =IF(H110>=87,">90%",IF(H110<=87,"<90%")) -> >90% | I111: =IF(I110>=87,">90%",IF(I110<=87,"<90%")) -> <90% | ... Q111: =IF(Q110>=87,">90%",IF(Q110<=87,"<90%")) -> >90%
A112: Status | B112: =IF(B110>=87,"OK",IF(B110<=87,"LESS")) -> OK | C112: =IF(C110>=87,"OK",IF(C110<=87,"LESS")) -> OK | D112: =IF(D110>=87,"OK",IF(D110<=87,"LESS")) -> OK | E112: =IF(E110>=87,"OK",IF(E110<=87,"LESS")) -> OK | F112: =IF(F110>=87,"OK",IF(F110<=87,"LESS")) -> OK | G112: =IF(G110>=87,"OK",IF(G110<=87,"LESS")) -> OK | H112: =IF(H110>=87,"OK",IF(H110<=87,"LESS")) -> OK | I112: =IF(I110>=87,"OK",IF(I110<=87,"LESS")) -> LESS | ... Q112: =IF(Q110>=87,"OK",IF(Q110<=87,"LESS")) -> OK
A115: Done by | B115: RK
A117: Comment

Sheet 05
A1: Station: | B1: BHATAGAON RAIPUR
A2: Date: | B2: =$A$9 -> 05/02/2025 00:15 | D2: Power Off | G2: Pw.Off | L2: Link Fail | N2: Link F | P2: Maintenance | R2: Maint.
A3: Report Type: | B3: Mean | D3: Calibration | G3: Calib. | L3: Data Fail | N3: Data F | P3: Invalid | R3: Invalid
A4: Time Base: | B4: 15 Min | D4: Zero Referrence | G4: Z.Ref | L4: Warm Up | N4: Wm. Up
A7: Date & Time | B7: NO_BHATAGAON | C7: NO2__BHATAGAON | D7: NOX_BHATAGAON | E7: SO2__BHATAGAON | F7: O3__BHATAGAON | G7: PM10__BHATAGAON | H7: PM2_5__BHATAGAON | I7: BENZ__BHATAGAON | J7: WS__BHATAGAON | K7: WD__BHATAGAON | L7: TEMP__BHATAGAON | M7: HUM__BHATAGAON | N7: SR__BHATAGAON | O7: RG__BHATAGAON | P7: CO__BHATAGAON | Q7: NH3__BHATAGAON
B8: ug/m3 | C8: ug/m3 | D8: ppb | E8: ug/m3 | F8: ug/m3 | G8: ug/m3 | H8: ug/m3 | I8: ug/m3 | J8: m/sec | K8: deg | L8: degreC | M8: % | N8: w/m2 | O8: mm | P8: mg/m3 | Q8: ug/m3
A9: 05/02/2025 00:15 | B9: 212.26 | C9: 55.24 | D9: 197.7 | E9: 10.9 | F9: 2.13 | G9: 159.6 | H9: 46.86 | I9: Invalid | J9: 0.51 | K9: 305.21 | L9: 19.31 | M9: 67.28 | N9: 79 | O9: 0 | P9: 2.13 | Q9: 10.6
A10: 05/02/2025 00:30 | B10: 206.21 | C10: 53.8 | D10: 192.09 | E10: 10.4 | F10: 2.13 | G10: 159.6 | H10: 46.86 | I10: Invalid | J10: 0.55 | K10: 354.08 | L10: 19.09 | M10: 64.76 | N10: 79.1 | O10: 0 | P10: 2.18 | Q10: 10.59
A11: 05/02/2025 00:45 | B11: 199.64 | C11: 52.78 | D11: 186.29 | E11: 9.64 | F11: 2.13 | G11: 159.6 | H11: 46.86 | I11: Invalid | J11: 0.62 | K11: 263.42 | L11: 18.91 | M11: 65.55 | N11: 79 | O11: 0 | P11: 2.25 | Q11: 10.58
A12: 05/02/2025 01:00 | B12: 193.14 | C12: 52.9 | D12: 181.15 | E12: 9.57 | F12: 2.13 | G12: 130.98 | H12: 33.84 | I12: Invalid | J12: 0.34 | K12: 287.42 | L12: 18.46 | M12: 68.94 | N12: 79.1 | O12: 0 | P12: 2.2 | Q12: 10.56
A13: 05/02/2025 01:15 | B13: 187.34 | C13: 55.26 | D13: 177.73 | E13: 9.07 | F13: 2.13 | G13: 96.77 | H13: 18.27 | I13: Invalid | J13: 0.17 | K13: 332.49 | L13: 18.09 | M13: 73.14 | N13: 79.2 | O13: 0 | P13: 2.16 | Q13: 10.5
A14: 05/02/2025 01:30 | B14: 180.19 | C14: 53.6 | D14: 171.12 | E14: 9.39 | F14: 2.13 | G14: 96.77 | H14: 18.27 | I14: Invalid | J14: 0.18 | K14: 282.38 | L14: 17.85 | M14: 75.16 | N14: 79.1 | O14: 0 | P14: 2.06 | Q14: 10.48
A15: 05/02/2025 01:45 | B15: 171.97 | C15: 54.24 | D15: 164.87 | E15: 8.99 | F15: 2.13 | G15: 96.77 | H15: 18.27 | I15: Invalid | J15: 0.4 | K15: 310.97 | L15: 17.82 | M15: 74.22 | N15: 79.1 | O15: 0 | P15: 2.03 | Q15: 10.45
A16: 05/02/2025 02:00 | B16: 163.96 | C16: 52.94 | D16: 157.77 | E16: 8.61 | F16: 2.13 | G16: 93.29 | H16: 28.49 | I16: Invalid | J16: 0.14 | K16: 165.3 | L16: 17.54 | M16: 75.79 | N16: 79 | O16: 0 | P16: 1.98 | Q16: 10.44
A17: 05/02/2025 02:15 | B17: 156.62 | C17: 53.05 | D17: 151.94 | E17: 8.58 | F17: 2.13 | G17: 89.13 | H17: 40.71 | I17: Invalid | J17: 0.62 | K17: 280.66 | L17: 17.37 | M17: 78.41 | N17: 79.2 | O17: 0 | P17: 1.92 | Q17: 10.4
A18: 05/02/2025 02:30 | B18: 149.72 | C18: 52.16 | D18: 145.94 | E18: 8.01 | F18: 2.13 | G18: 89.13 | H18: 40.71 | I18: Invalid | J18: 0.46 | K18: 267.97 | L18: 17.2 | M18: 79.17 | N18: 79.1 | O18: 0 | P18: 1.82 | Q18: 10.37
A19: 05/02/2025 02:45 | B19: 143.1 | C19: 51.48 | D19: 140.28 | E19: 7.8 | F19: 2.13 | G19: 89.13 | H19: 40.71 | I19: Invalid | J19: 0.54 | K19: 286.16 | L19: 16.97 | M19: 80.55 | N19: 79.1 | O19: 0 | P19: 1.76 | Q19: 10.34
A20: 05/02/2025 03:00 | B20: 136.47 | C20: 52.56 | D20: 135.52 | E20: 7.7 | F20: 2.13 | G20: 92.18 | H20: 42.83 | I20: Invalid | J20: 0.55 | K20: 296.53 | L20: 16.88 | M20: 81.52 | N20: 79 | O20: 0 | P20: 1.69 | Q20: 10.32
... A50: 05/02/2025 10:30 | B50: 61.74 | C50: 68.77 | D50: 84.06 | E50: 6.29 | F50: 2.13 | G50: 155.89 | H50: 58.97 | I50: Invalid | J50: 0.87 | K50: 324.7 | L50: 32.3 | M50: 28.89 | N50: 558.1 | O50: 0 | P50: 1.26 | Q50: 9.89
A51: 05/02/2025 10:45 | B51: Calib. | C51: Calib. | D51: Calib. | E51: 11.86 | F51: 19.2 | G51: 155.89 | H51: 58.97 | I51: Invalid | J51: 0.55 | K51: 302.29 | L51: 31.9 | M51: 28.63 | N51: 575.9 | O51: 0 | P51: 0.9 | Q51: 10.06
A52: 05/02/2025 11:00 | B52: Calib. | C52: Calib. | D52: Calib. | E52: 17.11 | F52: 29.9 | G52: 155.89 | H52: 58.97 | I52: Invalid | J52: 0.4 | K52: 299.21 | L52: 31.79 | M52: 28.84 | N52: 574.6 | O52: 0 | P52: 0.6 | Q52: 9.96
A53: 05/02/2025 11:15 | B53: Calib. | C53: Calib. | D53: Calib. | E53: 12.51 | F53: 15.26 | G53: 155.89 | H53: 58.97 | I53: Invalid | J53: 0.14 | K53: 299.78 | L53: 32.03 | M53: 28.98 | N53: 583 | O53: 0 | P53: 0.62 | Q53: 9.73
A54: 05/02/2025 11:30 | B54: 2.42 | C54: 87.01 | D54: 46.03 | E54: 4.33 | F54: 10.58 | G54: 155.89 | H54: 58.97 | I54: Invalid | J54: 0.39 | K54: 189.68 | L54: 30.03 | M54: 32.15 | N54: 583.7 | O54: 0 | P54: 0.61 | Q54: 9.65
A55: 05/02/2025 11:45 | B55: 1.98 | C55: 77.9 | D55: 40.91 | E55: 3.35 | F55: 11.53 | G55: 155.89 | H55: 58.97 | I55: Invalid | J55: 0.33 | K55: 285.85 | L55: 31.04 | M55: 29.95 | N55: 576.8 | O55: 0 | P55: 0.57 | Q55: 9.6
A56: 05/02/2025 12:00 | B56: 1.98 | C56: 70.93 | D56: 37.27 | E56: 8.09 | F56: 11.55 | G56: 155.89 | H56: 58.97 | I56: Invalid | J56: 0.75 | K56: 292.11 | L56: 32.46 | M56: 27.96 | N56: 568 | O56: 0 | P56: 0.55 | Q56: 9.58
A57: 05/02/2025 12:15 | B57: 1.95 | C57: 68.83 | D57: 36.15 | E57: 40.05 | F57: 18.33 | G57: 155.89 | H57: 58.97 | I57: Invalid | J57: 0.44 | K57: 214.01 | L57: 30.96 | M57: 29.7 | N57: 557.7 | O57: 0 | P57: 0.55 | Q57: 9.59
A58: 05/02/2025 12:30 | B58: 1.78 | C58: 63.46 | D58: 33.2 | E58: 90.83 | F58: 17.35 | G58: 155.89 | H58: 58.97 | I58: Invalid | J58: 0.25 | K58: 196.37 | L58: 30.93 | M58: 30.1 | N58: 568.8 | O58: 0 | P58: 0.52 | Q58: 9.58
A59: 05/02/2025 12:45 | B59: 2.01 | C59: 64.53 | D59: 33.95 | E59: Calib. | F59: 14.08 | G59: 155.89 | H59: 58.97 | I59: Invalid | J59: 0.12 | K59: 168.76 | L59: 31.2 | M59: 29.66 | N59: 541 | O59: 0 | P59: 0.57 | Q59: 9.57
A60: 05/02/2025 13:00 | B60: 1.84 | C60: 64.07 | D60: 33.58 | E60: Calib. | F60: 16.01 | G60: 155.89 | H60: 58.97 | I60: Invalid | J60: 1.26 | K60: 155.9 | L60: 29.48 | M60: 32.3 | N60: 547.7 | O60: 0 | P60: 0.55 | Q60: 9.57
A61: 05/02/2025 13:15 | B61: 2.03 | C61: 59.04 | D61: 31.1 | E61: Calib. | F61: 15.76 | G61: 155.89 | H61: 58.97 | I61: Invalid | J61: 0.41 | K61: 173.73 | L61: 30.1 | M61: 31.32 | N61: 508.1 | O61: 0 | P61: 0.61 | Q61: 9.56
A62: 05/02/2025 13:30 | B62: 4.01 | C62: 53.23 | D62: 29.65 | E62: Calib. | F62: 7.98 | G62: 155.89 | H62: 58.97 | I62: Invalid | J62: 0.5 | K62: 216.99 | L62: 30.05 | M62: 30.2 | N62: 513 | O62: 0 | P62: 0.59 | Q62: 9.56
A63: 05/02/2025 13:45 | B63: 3.41 | C63: 51.47 | D63: 28.25 | E63: 3.65 | F63: 9.09 | G63: 155.89 | H63: 58.97 | I63: Invalid | J63: 0.84 | K63: 288.36 | L63: 31.11 | M63: 27.26 | N63: 434.1 | O63: 0 | P63: 0.59 | Q63: 9.58
A64: 05/02/2025 14:00 | B64: 2.36 | C64: 52.82 | D64: 28.11 | E64: 7.86 | F64: 13.3 | G64: Calib. | H64: Calib. | I64: Invalid | J64: 0.87 | K64: 295.15 | L64: 31.86 | M64: 27.07 | N64: 504 | O64: 0 | P64: 0.52 | Q64: 9.6
A65: 05/02/2025 14:15 | B65: 2.05 | C65: 53.89 | D65: 28.42 | E65: 7.67 | F65: 11.88 | G65: Calib. | H65: Calib. | I65: Invalid | J65: 0.39 | K65: 290.26 | L65: 31.16 | M65: 24.98 | N65: 471.9 | O65: 0 | P65: 0.51 | Q65: 9.57
A66: 05/02/2025 14:30 | B66: 2.27 | C66: 53.37 | D66: 28.33 | E66: 6.11 | F66: 6.39 | G66: Calib. | H66: Calib. | I66: Invalid | J66: 0.09 | K66: 212.27 | L66: 30.64 | M66: 26.25 | N66: 408.4 | O66: 0 | P66: 0.46 | Q66: 9.57
A67: 05/02/2025 14:45 | B67: 2.65 | C67: 53.06 | D67: 28.47 | E67: 5.97 | F67: 3.78 | G67: Calib. | H67: Calib. | I67: Invalid | J67: 0.41 | K67: 227.25 | L67: 30.42 | M67: 26.63 | N67: 228.6 | O67: 0 | P67: 0.48 | Q67: 9.58
A68: 05/02/2025 15:00 | B68: 3.05 | C68: 53.75 | D68: 29.15 | E68: 5.89 | F68: 2.98 | G68: 8.39 | H68: 4.1 | I68: Invalid | J68: 0.64 | K68: 265.36 | L68: 30.59 | M68: 25.33 | N68: 317.4 | O68: 0 | P68: 0.5 | Q68: 9.59
A69: 05/02/2025 15:15 | B69: 3.07 | C69: 53.45 | D69: 29.02 | E69: 5.96 | F69: 3.42 | G69: 75.55 | H69: 36.92 | I69: Invalid | J69: 0.59 | K69: 246.43 | L69: 28.81 | M69: 28 | N69: 202.2 | O69: 0 | P69: 0.46 | Q69: 9.6
A70: 05/02/2025 15:30 | B70: 2.92 | C70: 53.46 | D70: 28.9 | E70: 5.47 | F70: 4.06 | G70: 75.55 | H70: 36.92 | I70: Invalid | J70: 0.76 | K70: 280.42 | L70: 29.16 | M70: 27.68 | N70: 173.5 | O70: 0 | P70: 0.47 | Q70: 9.59
A71: 05/02/2025 15:45 | B71: 2.68 | C71: 54.69 | D71: 29.35 | E71: 5.91 | F71: 7.44 | G71: 75.55 | H71: 36.92 | I71: Invalid | J71: 0.55 | K71: 265.81 | L71: 28.42 | M71: 28.07 | N71: 160.9 | O71: 0 | P71: 0.49 | Q71: 9.58
...

Sheet 06
A1: Station: | B1: BHATAGAON RAIPUR
A2: Date: | B2: =$A$9 -> 06/02/2025 00:15 | D2: Power Off | G2: Pw.Off | L2: Link Fail | N2: Link F | P2: Maintenance | R2: Maint.
A3: Report Type: | B3: Mean | D3: Calibration | G3: Calib. | L3: Data Fail | N3: Data F | P3: Invalid | R3: Invalid
A4: Time Base: | B4: 15 Min | D4: Zero Referrence | G4: Z.Ref | L4: Warm Up | N4: Wm. Up
A7: Date & Time | B7: NO_BHATAGAON | C7: NO2__BHATAGAON | D7: NOX_BHATAGAON | E7: SO2__BHATAGAON | F7: O3__BHATAGAON | G7: PM10__BHATAGAON | H7: PM2_5__BHATAGAON | I7: BENZ__BHATAGAON | J7: WS__BHATAGAON | K7: WD__BHATAGAON | L7: TEMP__BHATAGAON | M7: HUM__BHATAGAON | N7: SR__BHATAGAON | O7: RG__BHATAGAON | P7: CO__BHATAGAON | Q7: NH3__BHATAGAON
B8: ug/m3 | C8: ug/m3 | D8: ppb | E8: ug/m3 | F8: ug/m3 | G8: ug/m3 | H8: ug/m3 | I8: ug/m3 | J8: m/sec | K8: deg | L8: degreC | M8: % | N8: w/m2 | O8: mm | P8: mg/m3 | Q8: ug/m3
A9: 06/02/2025 00:15 | B9: 49.32 | C9: 56.8 | D9: 67.85 | E9: 4.87 | F9: 2.13 | G9: 85.6 | H9: 20.76 | I9: Invalid | J9: 0.59 | K9: 291.97 | L9: 19.09 | M9: 61.81 | N9: 77.9 | O9: 0 | P9: 0.94 | Q9: 9.82
A10: 06/02/2025 00:30 | B10: 48.34 | C10: 54.58 | D10: 65.9 | E10: 4.42 | F10: 2.13 | G10: 85.6 | H10: 20.76 | I10: Invalid | J10: 1.42 | K10: 341.69 | L10: 19.19 | M10: 62.06 | N10: 77.2 | O10: 0 | P10: 0.92 | Q10: 9.81
A11: 06/02/2025 00:45 | B11: 46.6 | C11: 55.1 | D11: 64.78 | E11: 4.55 | F11: 2.13 | G11: 85.6 | H11: 20.76 | I11: Invalid | J11: 1.55 | K11: 351.95 | L11: 19.47 | M11: 61.42 | N11: 77.8 | O11: 0 | P11: 0.91 | Q11: 9.79
A12: 06/02/2025 01:00 | B12: 44.51 | C12: 55.25 | D12: 63.19 | E12: 4.56 | F12: 2.13 | G12: 84.59 | H12: 20.5 | I12: Invalid | J12: 1.07 | K12: 354.84 | L12: 19.39 | M12: 62.99 | N12: 78.4 | O12: 0 | P12: 0.89 | Q12: 9.78
A13: 06/02/2025 01:15 | B13: 42.94 | C13: 55.04 | D13: 61.81 | E13: 4.91 | F13: 2.13 | G13: 75.49 | H13: 18.48 | I13: Invalid | J13: 0.69 | K13: 355.84 | L13: 19.42 | M13: 63.68 | N13: 78.3 | O13: 0 | P13: 0.78 | Q13: 9.75
A14: 06/02/2025 01:30 | B14: 41.29 | C14: 54.74 | D14: 60.33 | E14: 5.27 | F14: 2.13 | G14: 75.49 | H14: 18.48 | I14: Invalid | J14: 1.09 | K14: 352.75 | L14: 19.48 | M14: 63.61 | N14: 78.1 | O14: 0 | P14: 0.8 | Q14: 9.74
A15: 06/02/2025 01:45 | B15: 39.33 | C15: 54.31 | D15: 58.54 | E15: 4.71 | F15: 2.13 | G15: 75.49 | H15: 18.48 | I15: Invalid | J15: 0.77 | K15: 345.98 | L15: 19.39 | M15: 64.07 | N15: 78.4 | O15: 0 | P15: 0.79 | Q15: 9.74
A16: 06/02/2025 02:00 | B16: 37.32 | C16: 53.49 | D16: 56.49 | E16: 4.86 | F16: 2.13 | G16: 75.79 | H16: 20.56 | I16: Invalid | J16: 0.88 | K16: 349.81 | L16: 19.31 | M16: 64.22 | N16: 78.2 | O16: 0 | P16: 0.75 | Q16: 9.73
A17: 06/02/2025 02:15 | B17: 35.34 | C17: 51.28 | D17: 53.76 | E17: 4.67 | F17: 2.13 | G17: 78.53 | H17: 39.3 | I17: Invalid | J17: 0.98 | K17: 352.4 | L17: 19.29 | M17: 64.26 | N17: 78.3 | O17: 0 | P17: 0.83 | Q17: 9.74
A18: 06/02/2025 02:30 | B18: 32.89 | C18: 52.55 | D18: 52.45 | E18: 4.84 | F18: 2.13 | G18: 78.53 | H18: 39.3 | I18: Invalid | J18: 1.07 | K18: 352.46 | L18: 19.2 | M18: 64.9 | N18: 78.5 | O18: 0 | P18: 0.79 | Q18: 9.73
A19: 06/02/2025 02:45 | B19: 30.1 | C19: 52.94 | D19: 50.42 | E19: 5 | F19: 2.13 | G19: 78.53 | H19: 39.3 | I19: Invalid | J19: 1.25 | K19: 351.21 | L19: 19.04 | M19: 65.7 | N19: 78.6 | O19: 0 | P19: 0.78 | Q19: 9.72
A20: 06/02/2025 03:00 | B20: 27.3 | C20: 53.66 | D20: 48.55 | E20: 4.51 | F20: 2.13 | G20: 76.85 | H20: 35.78 | I20: Invalid | J20: 1.4 | K20: 355.59 | L20: 18.94 | M20: 65.4 | N20: 78.6 | O20: 0 | P20: 0.73 | Q20: 9.71
... A100: 06/02/2025 23:00 | B100: 19.02 | C100: 62.12 | D100: 46.33 | E100: 4.6 | F100: 2.13 | G100: 85.37 | H100: 35.65 | I100: Invalid | J100: 0.97 | K100: 350.7 | L100: 17.97 | M100: 37.21 | N100: 78.1 | O100: 0 | P100: 0.93 | Q100: 9.62
A101: 06/02/2025 23:15 | B101: 18.73 | C101: 62.7 | D101: 46.41 | E101: 4.98 | F101: 2.13 | G101: 74.18 | H101: Data F | I101: Invalid | J101: 0.65 | K101: 348.1 | L101: 17.85 | M101: 34.84 | N101: 78 | O101: 0 | P101: 0.91 | Q101: 9.61
A102: 06/02/2025 23:30 | B102: 18 | C102: 61.7 | D102: 45.3 | E102: 5.02 | F102: 2.13 | G102: 74.18 | H102: Data F | I102: Invalid | J102: 0.41 | K102: 9.75 | L102: 17.67 | M102: 34.25 | N102: 78.2 | O102: 0 | P102: 0.88 | Q102: 9.63
A103: 06/02/2025 23:45 | B103: 17.13 | C103: 60.38 | D103: 43.9 | E103: 4.2 | F103: 2.13 | G103: 74.18 | H103: Data F | I103: Invalid | J103: 0.3 | K103: 15.31 | L103: 17.39 | M103: 34.72 | N103: 78.2 | O103: 0 | P103: 0.87 | Q103: 9.66
A104: 06/02/2025 24:00 | B104: 16.42 | C104: 59.5 | D104: 42.88 | E104: 3.73 | F104: 2.13 | G104: 72.67 | H104: Data F | I104: Invalid | J104: 0.49 | K104: 351.38 | L104: 17.1 | M104: 34.64 | N104: 78.1 | O104: 0 | P104: 0.84 | Q104: 9.66
A106: Min | B106: =MIN(B9:B104) -> 4.58 | C106: =MIN(C9:C104) -> 51.28 | D106: =MIN(D9:D104) -> 30.69 | E106: =MIN(E9:E104) -> 3.73 | F106: =MIN(F9:F104) -> 2.13 | G106: =MIN(G9:G104) -> 57.75 | H106: =MIN(H9:H104) -> 3.21 | I106: =MIN(I9:I104) -> 0 | ... Q106: =MIN(Q9:Q104) -> 9.55
A107: Max | B107: =MAX(B9:B104) -> 49.32 | C107: =MAX(C9:C104) -> 67.79 | D107: =MAX(D9:D104) -> 67.85 | E107: =MAX(E9:E104) -> 7.4 | F107: =MAX(F9:F104) -> 2.18 | G107: =MAX(G9:G104) -> 97.5 | H107: =MAX(H9:H104) -> 57.1 | I107: =MAX(I9:I104) -> 0 | ... Q107: =MAX(Q9:Q104) -> 9.82
A108: Avg | B108: =AVERAGE(B9:B104) -> 13.989688 | C108: =AVERAGE(C9:C104) -> 58.749687 | D108: =AVERAGE(D9:D104) -> 40.536875 | E108: =AVERAGE(E9:E104) -> 5.6291667 | F108: =AVERAGE(F9:F104) -> 2.1305208 | G108: =AVERAGE(G9:G104) -> 73.023333 | H108: =AVERAGE(H9:H104) -> 23.810978 | I108: =AVERAGE(I9:I104) -> #DIV/0! | ... Q108: =AVERAGE(Q9:Q104) -> 9.6227083
A109: Stdev | B109: =STDEV(B9:B104) -> 11.13083 | C109: =STDEV(C9:C104) -> 4.5262259 | D109: =STDEV(D9:D104) -> 8.7597897 | E109: =STDEV(E9:E104) -> 0.8124371 | F109: =STDEV(F9:F104) -> 0.0051031036 | G109: =STDEV(G9:G104) -> 11.820178 | H109: =STDEV(H9:H104) -> 12.660208 | I109: =STDEV(I9:I104) -> #DIV/0! | ... Q109: =STDEV(Q9:Q104) -> 0.063120256
A110: Num | B110: =COUNT(B9:B104) -> 96 | C110: =COUNT(C9:C104) -> 96 | D110: =COUNT(D9:D104) -> 96 | E110: =COUNT(E9:E104) -> 96 | F110: =COUNT(F9:F104) -> 96 | G110: =COUNT(G9:G104) -> 96 | H110: =COUNT(H9:H104)+4 -> 96 | I110: =COUNT(I9:I104) -> 0 | J110: =COUNT(J9:J104) -> 96 | K110: =COUNT(K9:K104) -> 96 | L110: =COUNT(L9:L104) -> 96 | M110: =COUNT(M9:M104) -> 96 | N110: =COUNT(N9:N104) -> 96 | O110: =COUNT(O9:O104) -> 96 | P110: =COUNT(P9:P104) -> 96 | Q110: =COUNT(Q9:Q104) -> 96
A111: DCR | B111: =IF(B110>=87,">90%",IF(B110<=87,"<90%")) -> >90% | C111: =IF(C110>=87,">90%",IF(C110<=87,"<90%")) -> >90% | D111: =IF(D110>=87,">90%",IF(D110<=87,"<90%")) -> >90% | E111: =IF(E110>=87,">90%",IF(E110<=87,"<90%")) -> >90% | F111: =IF(F110>=87,">90%",IF(F110<=87,"<90%")) -> >90% | G111: =IF(G110>=87,">90%",IF(G110<=87,"<90%")) -> >90% | H111: =IF(H110>=87,">90%",IF(H110<=87,"<90%")) -> >90% | I111: =IF(I110>=87,">90%",IF(I110<=87,"<90%")) -> <90% | ... Q111: =IF(Q110>=87,">90%",IF(Q110<=87,"<90%")) -> >90%
A112: Status | B112: =IF(B110>=87,"OK",IF(B110<=87,"LESS")) -> OK | C112: =IF(C110>=87,"OK",IF(C110<=87,"LESS")) -> OK | D112: =IF(D110>=87,"OK",IF(D110<=87,"LESS")) -> OK | E112: =IF(E110>=87,"OK",IF(E110<=87,"LESS")) -> OK | F112: =IF(F110>=87,"OK",IF(F110<=87,"LESS")) -> OK | G112: =IF(G110>=87,"OK",IF(G110<=87,"LESS")) -> OK | H112: =IF(H110>=87,"OK",IF(H110<=87,"LESS")) -> OK | I112: =IF(I110>=87,"OK",IF(I110<=87,"LESS")) -> LESS | ... Q112: =IF(Q110>=87,"OK",IF(Q110<=87,"LESS")) -> OK
A115: Done by | B115: RK
A117: Comment

Sheet 07
A1: Station: | B1: BHATAGAON RAIPUR
A2: Date: | B2: =$A$9 -> 07/02/2025 00:15 | D2: Power Off | G2: Pw.Off | L2: Link Fail | N2: Link F | P2: Maintenance | R2: Maint.
A3: Report Type: | B3: Mean | D3: Calibration | G3: Calib. | L3: Data Fail | N3: Data F | P3: Invalid | R3: Invalid
A4: Time Base: | B4: 15 Min | D4: Zero Referrence | G4: Z.Ref | L4: Warm Up | N4: Wm. Up
A7: Date & Time | B7: NO_BHATAGAON | C7: NO2__BHATAGAON | D7: NOX_BHATAGAON | E7: SO2__BHATAGAON | F7: O3__BHATAGAON | G7: PM10__BHATAGAON | H7: PM2_5__BHATAGAON | I7: BENZ__BHATAGAON | J7: WS__BHATAGAON | K7: WD__BHATAGAON | L7: TEMP__BHATAGAON | M7: HUM__BHATAGAON | N7: SR__BHATAGAON | O7: RG__BHATAGAON | P7: CO__BHATAGAON | Q7: NH3__BHATAGAON
B8: ug/m3 | C8: ug/m3 | D8: ppb | E8: ug/m3 | F8: ug/m3 | G8: ug/m3 | H8: ug/m3 | I8: ug/m3 | J8: m/sec | K8: deg | L8: degreC | M8: % | N8: w/m2 | O8: mm | P8: mg/m3 | Q8: ug/m3
A9: 07/02/2025 00:15 | B9: 16.14 | C9: 58.74 | D9: 42.26 | E9: 4.43 | F9: 2.13 | G9: 60.57 | H9: Data F | I9: Invalid | J9: 0.54 | K9: 350.53 | L9: 16.9 | M9: 35.24 | N9: 78 | O9: 0 | P9: 0.82 | Q9: 9.65
A10: 07/02/2025 00:30 | B10: 15.61 | C10: 57.83 | D10: 41.35 | E10: 4.68 | F10: 2.13 | G10: 60.57 | H10: Data F | I10: Invalid | J10: 0.56 | K10: 2.78 | L10: 16.91 | M10: 34.44 | N10: 77.6 | O10: 0 | P10: 0.8 | Q10: 9.65
A11: 07/02/2025 00:45 | B11: 14.72 | C11: 56.64 | D11: 40.02 | E11: 4.27 | F11: 2.13 | G11: 60.57 | H11: Data F | I11: Invalid | J11: 0.71 | K11: 346.42 | L11: 16.8 | M11: 34.02 | N11: 77.6 | O11: 0 | P11: 0.78 | Q11: 9.65
A12: 07/02/2025 01:00 | B12: 13.73 | C12: 55.69 | D12: 38.73 | E12: 4.28 | F12: 2.13 | G12: 59.82 | H12: Data F | I12: Invalid | J12: 0.83 | K12: 351.46 | L12: 16.77 | M12: 33.05 | N12: 77.9 | O12: 0 | P12: 0.74 | Q12: 9.67
A13: 07/02/2025 01:15 | B13: 12.9 | C13: 53.63 | D13: 36.99 | E13: 4.78 | F13: 2.13 | G13: 53.86 | H13: Data F | I13: Invalid | J13: 0.54 | K13: 359.64 | L13: 16.57 | M13: 33.39 | N13: 77.9 | O13: 0 | P13: 0.68 | Q13: 9.66
A14: 07/02/2025 01:30 | B14: 12.37 | C14: 50.89 | D14: 35.13 | E14: 4.52 | F14: 2.13 | G14: 53.86 | H14: Data F | I14: Invalid | J14: 0.44 | K14: 1.18 | L14: 16.39 | M14: 34.26 | N14: 78.1 | O14: 0 | P14: 0.66 | Q14: 9.67
A15: 07/02/2025 01:45 | B15: 12.27 | C15: 50.65 | D15: 34.92 | E15: 4.19 | F15: 2.13 | G15: 53.86 | H15: Data F | I15: Invalid | J15: 0.7 | K15: 345.7 | L15: 16.09 | M15: 35.47 | N15: 78 | O15: 0 | P15: 0.64 | Q15: 9.64
A16: 07/02/2025 02:00 | B16: 11.94 | C16: 50.04 | D16: 34.34 | E16: 4.67 | F16: 2.13 | G16: 53.04 | H16: Data F | I16: Invalid | J16: 1.24 | K16: 356.3 | L16: 16.16 | M16: 34.04 | N16: 77.6 | O16: 0 | P16: 0.61 | Q16: 9.61
A17: 07/02/2025 02:15 | B17: 11.44 | C17: 49.94 | D17: 33.89 | E17: 4.69 | F17: 2.13 | G17: 45.73 | H17: Data F | I17: Invalid | J17: 0.77 | K17: 5.01 | L17: 16.11 | M17: 34.21 | N17: 78.1 | O17: 0 | P17: 0.6 | Q17: 9.6
A18: 07/02/2025 02:30 | B18: 11.12 | C18: 49.17 | D18: 33.22 | E18: 4.72 | F18: 2.13 | G18: 45.73 | H18: Data F | I18: Invalid | J18: 0.34 | K18: 24.69 | L18: 15.83 | M18: 34.62 | N18: 78.3 | O18: 0 | P18: 0.59 | Q18: 9.6
A19: 07/02/2025 02:45 | B19: 10.93 | C19: 48.66 | D19: 32.81 | E19: 4.4 | F19: 2.13 | G19: 45.73 | H19: Data F | I19: Invalid | J19: 0.52 | K19: 83.36 | L19: 15.62 | M19: 35.23 | N19: 77.9 | O19: 0 | P19: 0.58 | Q19: 9.58
A20: 07/02/2025 03:00 | B20: 10.72 | C20: 47.37 | D20: 31.97 | E20: 4.44 | F20: 2.13 | G20: 45.16 | H20: Data F | I20: Invalid | J20: 0.36 | K20: 31.4 | L20: 15.55 | M20: 35.15 | N20: 78.2 | O20: 0 | P20: 0.58 | Q20: 9.57
... A44: 07/02/2025 09:00 | B44: 15.54 | C44: 52.4 | D44: 38.46 | E44: 6.39 | F44: 2.13 | G44: 55.49 | H44: Data F | I44: Invalid | J44: 1.94 | K44: 106.68 | L44: 18.28 | M44: 28 | N44: 415.1 | O44: 0 | P44: 0.53 | Q44: 9.66
A45: 07/02/2025 09:15 | B45: 15.22 | C45: 53.03 | D45: 38.53 | E45: 6.03 | F45: 2.13 | G45: 55.84 | H45: 11.73 | I45: Invalid | J45: 0.7 | K45: 61.25 | L45: 19.68 | M45: 26.22 | N45: 443.1 | O45: 0 | P45: 0.53 | Q45: 9.67
A46: 07/02/2025 09:30 | B46: 15.36 | C46: 54.03 | D46: 39.16 | E46: 6.01 | F46: 2.13 | G46: 55.84 | H46: 11.73 | I46: Invalid | J46: 1.81 | K46: 352.87 | L46: 23.19 | M46: 20.51 | N46: 477.4 | O46: 0 | P46: 0.53 | Q46: 9.66
A47: 07/02/2025 09:45 | B47: 15.68 | C47: 54 | D47: 39.41 | E47: 6.04 | F47: 2.13 | G47: 55.84 | H47: 11.73 | I47: Invalid | J47: 1.38 | K47: 358.08 | L47: 24.39 | M47: 19.9 | N47: 507.1 | O47: 0 | P47: 0.54 | Q47: 9.67
A48: 07/02/2025 10:00 | B48: 16.48 | C48: 55.32 | D48: 40.75 | E48: 5.96 | F48: 2.13 | G48: 56.02 | H48: 13.84 | I48: Invalid | J48: 0.9 | K48: 63.6 | L48: 24.11 | M48: 21.9 | N48: 528.8 | O48: 0 | P48: 0.54 | Q48: 9.64
A49: 07/02/2025 10:15 | B49: 17.12 | C49: 55.93 | D49: 41.57 | E49: 6.04 | F49: 2.13 | G49: 57.7 | H49: 32.79 | I49: Invalid | J49: 0.96 | K49: 29.44 | L49: 22.74 | M49: 22.07 | N49: 544.2 | O49: 0 | P49: 0.55 | Q49: 9.67
A50: 07/02/2025 10:30 | B50: 16.89 | C50: 56.89 | D50: 41.89 | E50: 6.28 | F50: 2.17 | G50: 57.7 | H50: 32.79 | I50: Invalid | J50: 1.77 | K50: 106.49 | L50: 21.29 | M50: 23.91 | N50: 561.1 | O50: 0 | P50: 0.54 | Q50: 9.67
A51: 07/02/2025 10:45 | B51: 9.68 | C51: 63.88 | D51: 39.76 | E51: 8.54 | F51: 9.84 | G51: 57.7 | H51: 32.79 | I51: Invalid | J51: 1.8 | K51: 104.63 | L51: 20.65 | M51: 24.3 | N51: 571.4 | O51: 0 | P51: 0.42 | Q51: 9.73
A52: 07/02/2025 11:00 | B52: 5.17 | C52: 67.06 | D52: 37.81 | E52: 7.31 | F52: 3.9 | G52: 56.24 | H52: 31.8 | I52: Invalid | J52: 1.37 | K52: 99.22 | L52: 21.9 | M52: 23.49 | N52: 563.6 | O52: 0 | P52: 0.42 | Q52: 9.68
A53: 07/02/2025 11:15 | B53: 5.37 | C53: 66.25 | D53: 37.54 | E53: 7.17 | F53: 2.14 | G53: 44.59 | H53: Data F | I53: Invalid | J53: 0.58 | K53: 54.74 | L53: 23.54 | M53: 21.23 | N53: 558.8 | O53: 0 | P53: 0.43 | Q53: 9.67
A54: 07/02/2025 11:30 | B54: 6 | C54: 66.16 | D54: 38 | E54: 7.62 | F54: 2.13 | G54: 44.59 | H54: Data F | I54: Invalid | J54: 0.98 | K54: 96.14 | L54: 23.74 | M54: 20.3 | N54: 565.3 | O54: 0 | P54: 0.43 | Q54: 9.68
A55: 07/02/2025 11:45 | B55: 6.49 | C55: 66.61 | D55: 38.63 | E55: 8.74 | F55: 3.04 | G55: 44.59 | H55: Data F | I55: Invalid | J55: 0.82 | K55: 84.13 | L55: 23.61 | M55: 19.26 | N55: 568.6 | O55: 0 | P55: 0.42 | Q55: 9.69
A56: 07/02/2025 12:00 | B56: 7.89 | C56: 73.52 | D56: 43.36 | E56: 11.41 | F56: 2.98 | G56: 44.74 | H56: Data F | I56: Invalid | J56: 1.15 | K56: 350.14 | L56: 26.45 | M56: 15.67 | N56: 562.7 | O56: 0 | P56: 0.42 | Q56: 9.75
A57: 07/02/2025 12:15 | B57: 9.13 | C57: 77.04 | D57: 46.2 | E57: 9.58 | F57: 2.13 | G57: 46.06 | H57: Data F | I57: Invalid | J57: 1.18 | K57: 349.21 | L57: 27.85 | M57: 14.66 | N57: 553.6 | O57: 0 | P57: 0.44 | Q57: 9.8
A58: 07/02/2025 12:30 | B58: 10.28 | C58: 77.33 | D58: 47.27 | E58: 9.08 | F58: 2.13 | G58: 46.06 | H58: Data F | I58: Invalid | J58: 1.11 | K58: 100.05 | L58: 25.69 | M58: 15.56 | N58: 554.1 | O58: 0 | P58: 0.44 | Q58: 9.83
A59: 07/02/2025 12:45 | B59: 8.61 | C59: 75.51 | D59: 44.98 | E59: 9.08 | F59: 2.13 | G59: 46.06 | H59: Data F | I59: Invalid | J59: 0.56 | K59: 69.41 | L59: 24.66 | M59: 16.41 | N59: 543.6 | O59: 0 | P59: 0.41 | Q59: 9.86
A60: 07/02/2025 13:00 | B60: 8.28 | C60: 73.63 | D60: 43.73 | E60: 7.07 | F60: 2.13 | G60: 47.06 | H60: Data F | I60: Invalid | J60: 1.29 | K60: 350.44 | L60: 28.34 | M60: 13.74 | N60: 529.4 | O60: 0 | P60: 0.42 | Q60: 9.88
A61: 07/02/2025 13:15 | B61: 9.73 | C61: 71.63 | D61: 43.85 | E61: 7.01 | F61: 2.13 | G61: 55.03 | H61: Data F | I61: Invalid | J61: 1.08 | K61: 330.79 | L61: 28.22 | M61: 14.59 | N61: 521.4 | O61: 0 | P61: 0.44 | Q61: 9.94
A62: 07/02/2025 13:30 | B62: 10.61 | C62: 70.06 | D62: 43.73 | E62: 6.65 | F62: 2.13 | G62: 55.03 | H62: Data F | I62: Invalid | J62: 1.64 | K62: 339.57 | L62: 29.47 | M62: 14.13 | N62: 510.7 | O62: 0 | P62: 0.46 | Q62: 9.99
A63: 07/02/2025 13:45 | B63: 11.39 | C63: 70.56 | D63: 44.62 | E63: 7.41 | F63: 2.13 | G63: 55.03 | H63: Data F | I63: Invalid | J63: 0.83 | K63: 335.5 | L63: 29.41 | M63: 14.46 | N63: 406.9 | O63: 0 | P63: 0.49 | Q63: 10.09
A64: 07/02/2025 14:00 | B64: 12.91 | C64: 70.59 | D64: 45.86 | E64: 6.26 | F64: 2.13 | G64: 53.93 | H64: Data F | I64: Invalid | J64: 0.77 | K64: 350.73 | L64: 28.81 | M64: 15.74 | N64: 430.4 | O64: 0 | P64: 0.51 | Q64: 10.13
A65: 07/02/2025 14:15 | B65: 13.44 | C65: 70.77 | D65: 46.38 | E65: 6.4 | F65: 2.13 | G65: 45.16 | H65: 21.09 | I65: Invalid | J65: 0.85 | K65: 1.17 | L65: 27.06 | M65: 17.21 | N65: 347.4 | O65: 0 | P65: 0.52 | Q65: 10.16
...

Sheet 08
A1: Station: | B1: BHATAGAON RAIPUR
A2: Date: | B2: =$A$9 -> 08/02/2025 00:15 | D2: Power Off | G2: Pw.Off | L2: Link Fail | N2: Link F | P2: Maintenance | R2: Maint.
A3: Report Type: | B3: Mean | D3: Calibration | G3: Calib. | L3: Data Fail | N3: Data F | P3: Invalid | R3: Invalid
A4: Time Base: | B4: 15 Min | D4: Zero Referrence | G4: Z.Ref | L4: Warm Up | N4: Wm. Up
A7: Date & Time | B7: NO_BHATAGAON | C7: NO2__BHATAGAON | D7: NOX_BHATAGAON | E7: SO2__BHATAGAON | F7: O3__BHATAGAON | G7: PM10__BHATAGAON | H7: PM2_5__BHATAGAON | I7: BENZ__BHATAGAON | J7: WS__BHATAGAON | K7: WD__BHATAGAON | L7: TEMP__BHATAGAON | M7: HUM__BHATAGAON | N7: SR__BHATAGAON | O7: RG__BHATAGAON | P7: CO__BHATAGAON | Q7: NH3__BHATAGAON
B8: ug/m3 | C8: ug/m3 | D8: ppb | E8: ug/m3 | F8: ug/m3 | G8: ug/m3 | H8: ug/m3 | I8: ug/m3 | J8: m/sec | K8: deg | L8: degreC | M8: % | N8: w/m2 | O8: mm | P8: mg/m3 | Q8: ug/m3
A9: 08/02/2025 00:15 | B9: 151.95 | C9: 55.93 | D9: 149.7 | E9: 10.73 | F9: 2.13 | G9: 196.03 | H9: Maint. | I9: Invalid | J9: 0.62 | K9: 326.62 | L9: 15.73 | M9: 63.7 | N9: 77.5 | O9: 0 | P9: 2.6 | Q9: 10.82
A10: 08/02/2025 00:30 | B10: 150.16 | C10: 55.36 | D10: 147.97 | E10: 10.1 | F10: 2.13 | G10: 196.03 | H10: Maint. | I10: Invalid | J10: 0.51 | K10: 281 | L10: 15.72 | M10: 57.28 | N10: 77.2 | O10: 0 | P10: 2.57 | Q10: 10.86
A11: 08/02/2025 00:45 | B11: 145.2 | C11: 56.36 | D11: 144.51 | E11: 9.87 | F11: 2.13 | G11: 196.03 | H11: Maint. | I11: Invalid | J11: 0.57 | K11: 240.36 | L11: 15.79 | M11: 58.52 | N11: 77.4 | O11: 0 | P11: 2.53 | Q11: 10.83
A12: 08/02/2025 01:00 | B12: 142.04 | C12: 53.04 | D12: 140.24 | E12: 9.55 | F12: 2.13 | G12: 193.41 | H12: Maint. | I12: Invalid | J12: 0.4 | K12: 305.22 | L12: 15.65 | M12: 59.43 | N12: 77.5 | O12: 0 | P12: 2.49 | Q12: 10.81
A13: 08/02/2025 01:15 | B13: 138.93 | C13: 57.76 | D13: 140.21 | E13: 9.73 | F13: 2.13 | G13: 172.45 | H13: 48.47 | I13: Invalid | J13: 0.49 | K13: 257.71 | L13: 15.42 | M13: 60.68 | N13: 77.4 | O13: 0 | P13: 2.19 | Q13: 10.75
A14: 08/02/2025 01:30 | B14: 135.6 | C14: 52.63 | D14: 134.87 | E14: 9.37 | F14: 2.13 | G14: 172.45 | H14: 48.47 | I14: Invalid | J14: 0.49 | K14: 257.83 | L14: 15.47 | M14: 60.49 | N14: 77.2 | O14: 0 | P14: 2.22 | Q14: 10.73
A15: 08/02/2025 01:45 | B15: 130.94 | C15: 54.72 | D15: 132.22 | E15: 9.24 | F15: 2.13 | G15: 172.45 | H15: 48.47 | I15: Invalid | J15: 0.62 | K15: 207.14 | L15: 15.39 | M15: 68.85 | N15: 77 | O15: 0 | P15: 2.17 | Q15: 10.7
A16: 08/02/2025 02:00 | B16: 128.01 | C16: 48.3 | D16: 126.51 | E16: 9.23 | F16: 2.13 | G16: 169.99 | H16: 48.29 | I16: Invalid | J16: 0.68 | K16: 208.25 | L16: 15.11 | M16: 72.68 | N16: 77.2 | O16: 0 | P16: 1.91 | Q16: 10.64
A17: 08/02/2025 02:15 | B17: 125.82 | C17: 47.06 | D17: 124.11 | E17: 8.76 | F17: 2.13 | G17: 147.85 | H17: 46.7 | I17: Invalid | J17: 0.67 | K17: 232.94 | L17: 15.08 | M17: 73.72 | N17: 77.4 | O17: 0 | P17: 1.94 | Q17: 10.56
A18: 08/02/2025 02:30 | B18: 123.49 | C18: 46.55 | D18: 121.98 | E18: 8.43 | F18: 2.13 | G18: 147.85 | H18: 46.7 | I18: Invalid | J18: 0.47 | K18: 333.63 | L18: 14.8 | M18: 75.02 | N18: 77.7 | O18: 0 | P18: 1.87 | Q18: 10.5
A19: 08/02/2025 02:45 | B19: 120.9 | C19: 46.48 | D19: 119.86 | E19: 8.03 | F19: 2.13 | G19: 147.85 | H19: 46.7 | I19: Invalid | J19: 0.56 | K19: 330.14 | L19: 14.33 | M19: 78.8 | N19: 77.4 | O19: 0 | P19: 1.81 | Q19: 10.47
A20: 08/02/2025 03:00 | B20: 118.17 | C20: 46.01 | D20: 117.43 | E20: 8.23 | F20: 2.13 | G20: 147.3 | H20: 45.36 | I20: Invalid | J20: 0.65 | K20: 300.7 | L20: 13.96 | M20: 80.91 | N20: 77.4 | O20: 0 | P20: 1.84 | Q20: 10.43
A21: 08/02/2025 03:15 | B21: 115.43 | C21: 46.13 | D21: 115.29 | E21: 7.84 | F21: 2.13 | G21: 142.31 | H21: 33.31 | I21: Invalid | J21: 0.56 | K21: 336.49 | L21: 13.79 | M21: 83.75 | N21: 77.4 | O21: 0 | P21: 1.77 | Q21: 10.39
A22: 08/02/2025 03:30 | B22: 112.28 | C22: 46.04 | D22: 112.72 | E22: 7.81 | F22: 2.13 | G22: 142.31 | H22: 33.31 | I22: Invalid | J22: 1.24 | K22: 354.05 | L22: 13.93 | M22: 70.8 | N22: 75.7 | O22: 0 | P22: 1.55 | Q22: 10.35
A23: 08/02/2025 03:45 | B23: 107.48 | C23: 46.72 | D23: 109.22 | E23: 7.54 | F23: 2.13 | G23: 142.31 | H23: 33.31 | I23: Invalid | J23: 0.48 | K23: 19.45 | L23: 15.01 | M23: 55.1 | N23: 76.8 | O23: 0 | P23: 1.71 | Q23: 10.34
A24: 08/02/2025 04:00 | B24: 102.14 | C24: 56.13 | D24: 109.86 | E24: 7.55 | F24: 2.13 | G24: 139.57 | H24: 34.09 | I24: Invalid | J24: 0.56 | K24: 27.84 | L24: 14.81 | M24: 56.08 | N24: 77.4 | O24: 0 | P24: 1.67 | Q24: 10.31
... A28: 08/02/2025 05:00 | B28: 83.59 | C28: 48.76 | D28: 91.13 | E28: 6.63 | F28: 2.13 | G28: 110.43 | H28: 51.97 | I28: Invalid | J28: 1.38 | K28: 358.81 | L28: 14.89 | M28: 44.51 | N28: 77.2 | O28: 0 | P28: 1.36 | Q28: 10.23
A29: 08/02/2025 05:15 | B29: 79.34 | C29: 52.31 | D29: 89.58 | E29: 6.27 | F29: 2.13 | G29: 70.65 | H29: Maint. | I29: Invalid | J29: 1.2 | K29: 357.1 | L29: 14.84 | M29: 45.05 | N29: 77.4 | O29: 0 | P29: 1.27 | Q29: 10.18
A30: 08/02/2025 05:30 | B30: 75.5 | C30: 51.49 | D30: 86.07 | E30: 6.03 | F30: 2.13 | G30: 70.65 | H30: Maint. | I30: Invalid | J30: 1.1 | K30: 353.75 | L30: 14.56 | M30: 46.51 | N30: 77.4 | O30: 0 | P30: 1.22 | Q30: 10.19
A31: 08/02/2025 05:45 | B31: 72.24 | C31: 50.06 | D31: 82.7 | E31: 6.25 | F31: 2.13 | G31: 70.65 | H31: Maint. | I31: Invalid | J31: 0.38 | K31: 21.62 | L31: 14.37 | M31: 45.64 | N31: 77.6 | O31: 0 | P31: 1.15 | Q31: 10.16
A32: 08/02/2025 06:00 | B32: 69.17 | C32: 50.05 | D32: 80.24 | E32: 5.71 | F32: 2.13 | G32: 70.51 | H32: Maint. | I32: Invalid | J32: 0.46 | K32: 48.67 | L32: 14.13 | M32: 46.42 | N32: 77.4 | O32: 0 | P32: 1.11 | Q32: 10.13
A33: 08/02/2025 06:15 | B33: 66.44 | C33: 48.97 | D33: 77.49 | E33: 5.44 | F33: 2.13 | G33: 69.32 | H33: Maint. | I33: Invalid | J33: 0.55 | K33: 6.69 | L33: 14.1 | M33: 45.45 | N33: 77.3 | O33: 0 | P33: 1.02 | Q33: 10.1
A34: 08/02/2025 06:30 | B34: 64.25 | C34: 43.74 | D34: 73 | E34: 5.5 | F34: 2.13 | G34: 69.32 | H34: Maint. | I34: Invalid | J34: 0.27 | K34: 42.95 | L34: 14.02 | M34: 44.78 | N34: 78 | O34: 0 | P34: 1.01 | Q34: 10.09
A35: 08/02/2025 06:45 | B35: 61.97 | C35: 43.77 | D35: 71.19 | E35: 5.36 | F35: 2.13 | G35: 69.32 | H35: Maint. | I35: Invalid | J35: 0.39 | K35: 23.95 | L35: 13.99 | M35: 45.6 | N35: 81.3 | O35: 0 | P35: 0.96 | Q35: 10.04
A36: 08/02/2025 07:00 | B36: 60.32 | C36: 44.13 | D36: 70.05 | E36: 4.88 | F36: 2.13 | G36: 66.79 | H36: Maint. | I36: Invalid | J36: 0.7 | K36: 345.41 | L36: 14 | M36: 45.43 | N36: 91.4 | O36: 0 | P36: 0.91 | Q36: 10.01
A37: 08/02/2025 07:15 | B37: 59.39 | C37: 45.81 | D37: 70.18 | E37: 5.34 | F37: 2.13 | G37: 44.02 | H37: Maint. | I37: Invalid | J37: 0.57 | K37: 358.18 | L37: 14.22 | M37: 46.17 | N37: 105.9 | O37: 0 | P37: 1.03 | Q37: 9.98
