Workbook

Sheet 01
A1: Station: | B1: BHATAGAON RAIPPUR
A2: Date: | B2: =$A$9 -> 01-06-2022 00:15 | D2: Power Off | G2: Pw.Off | L2: Link Fail | N2: Link F | P2: Maintenance | R2: Maint.
A3: Report Type: | B3: Mean | D3: Calibration | G3: Calib. | L3: Data Fail | N3: Data F | P3: Invalid | R3: Invalid
A4: Time Base: | B4: 15 Min | D4: Zero Referrence | G4: Z.Ref | L4: Warm Up | N4: Wm. Up
A7: Date & Time | B7: NO_BHATAGAON | C7: NO2__BHATAGAON | D7: NOX_BHATAGAON | E7: SO2__BHATAGAON | F7: O3__BHATAGAON | G7: PM10__BHATAGAON | H7: PM2.5__BHATAGAON | I7: BENZ__BHATAGAON | J7: WS__BHATAGAON | K7: WD__BHATAGAON | L7: TEMP__BHATAGAON | M7: HUM__BHATAGAON | N7: SR__BHATAGAON | O7: RG__BHATAGAON | P7: CO__BHATAGAON | Q7: NH3__BHATAGAON
B8: ug/m3 | C8: ug/m3 | D8: ug/m3 | E8: ug/m3 | F8: ug/m3 | G8: ug/m3 | H8: ug/m3 | I8: ug/m3 | J8: m/sec | K8: deg | L8: degreC | M8: % | N8: w/m2 | O8: mm | P8: mg/m3 | Q8: ug/m3
A9: 01-06-2022 00:15 | B9: 29.72 | C9: 30.78 | D9: 60.5 | E9: 7.38 | F9: 7.57 | G9: 159.06 | H9: Invalid | I9: 3.57 | J9: 1.85 | K9: 184.43 | L9: 39.25 | M9: 47.41 | N9: 392.4 | O9: 0 | P9: 1.08 | Q9: 60.94
A10: 01-06-2022 00:30 | B10: 26.71 | C10: 30.57 | D10: 57.28 | E10: 7.65 | F10: 10.23 | G10: 145.67 | H10: Invalid | I10: 3.02 | J10: 1.59 | K10: 209.51 | L10: 38.67 | M10: 48.05 | N10: 252.2 | O10: 0 | P10: 1.03 | Q10: 61.14
A11: 01-06-2022 00:45 | B11: 23.57 | C11: 32.26 | D11: 55.83 | E11: 7.53 | F11: 3.59 | G11: 140.26 | H11: Invalid | I11: 2.54 | J11: 0.77 | K11: 253.23 | L11: 38.19 | M11: 45.96 | N11: 378.7 | O11: 0 | P11: 1.54 | Q11: 68.92
A12: 01-06-2022 01:00 | B12: 19.18 | C12: 33.56 | D12: 52.74 | E12: 7.64 | F12: 1.27 | G12: 140.26 | H12: Invalid | I12: 2.89 | J12: 1.37 | K12: 246.29 | L12: 38.22 | M12: 46.08 | N12: 381.3 | O12: 0 | P12: 1.45 | Q12: 81.35
A13: 01-06-2022 01:15 | B13: 14.63 | C13: 33.79 | D13: 48.43 | E13: 7.65 | F13: 1.16 | G13: 108.04 | H13: Invalid | I13: 0.04 | J13: 0.79 | K13: 262.48 | L13: 38.09 | M13: 47.34 | N13: 386.2 | O13: 0 | P13: 1.46 | Q13: 83.44
A14: 01-06-2022 01:30 | B14: 10.76 | C14: 33.63 | D14: 44.39 | E14: 7.24 | F14: 1.29 | G14: 109.14 | H14: Invalid | I14: 1.83 | J14: 0.76 | K14: 306.48 | L14: 38.14 | M14: 47.94 | N14: 404.2 | O14: 0 | P14: 1.36 | Q14: 81.39
A15: 01-06-2022 01:45 | B15: 7.81 | C15: 32.8 | D15: 40.61 | E15: 7.1 | F15: 1.21 | G15: 113.6 | H15: Invalid | I15: 4.45 | J15: 1.26 | K15: 246.09 | L15: 38.12 | M15: 47.55 | N15: 343.9 | O15: 0 | P15: 1.4 | Q15: 78.83
A16: 01-06-2022 02:00 | B16: 5.52 | C16: 31.56 | D16: 37.08 | E16: 7.41 | F16: 1.27 | G16: 113.6 | H16: Invalid | I16: 3.73 | J16: 1.58 | K16: 259.86 | L16: 37.77 | M16: 48.39 | N16: 360.9 | O16: 0 | P16: 1.3 | Q16: 76.66
A17: 01-06-2022 02:15 | B17: 3.94 | C17: 30.37 | D17: 34.3 | E17: 7.45 | F17: 1.46 | G17: 113.6 | H17: Invalid | I17: 4.45 | J17: 1.54 | K17: 263.64 | L17: 37.07 | M17: 51.06 | N17: 429.5 | O17: 0 | P17: 1.29 | Q17: 73.88
A18: 01-06-2022 02:30 | B18: 3.01 | C18: 29.04 | D18: 32.05 | E18: 7.15 | F18: 1.47 | G18: 106.85 | H18: Invalid | I18: 3.93 | J18: 1.71 | K18: 200.34 | L18: 36.44 | M18: 53.31 | N18: 472.3 | O18: 0 | P18: 1.25 | Q18: 72.06
A19: 01-06-2022 02:45 | B19: 2.51 | C19: 28.29 | D19: 30.79 | E19: 7.42 | F19: 1.09 | G19: 100.69 | H19: Invalid | I19: 3.96 | J19: 1.85 | K19: 199.65 | L19: 36.7 | M19: 52.45 | N19: 548.3 | O19: 0 | P19: 1.24 | Q19: 69.01
A20: 01-06-2022 03:00 | B20: 2.18 | C20: 27.63 | D20: 29.81 | E20: 3.38 | F20: 1.44 | G20: 100.69 | H20: Invalid | I20: 3.6 | J20: 1.77 | K20: 245.59 | L20: 37.34 | M20: 53.36 | N20: 430.7 | O20: 0 | P20: 1.23 | Q20: 69.98
... A45: 01-06-2022 09:15 | B45: 1.63 | C45: 34.49 | D45: 36.11 | E45: 5.14 | F45: 3.76 | G45: 116.59 | H45: Invalid | I45: 6.51 | J45: 1.79 | K45: 320.55 | L45: 46.27 | M45: 34.2 | N45: 895.5 | O45: 0 | P45: 1.57 | Q45: 39.31
A46: 01-06-2022 09:30 | B46: 1.53 | C46: 33.27 | D46: 34.8 | E46: 4.95 | F46: 6.92 | G46: 119.72 | H46: Invalid | I46: 6.89 | J46: 1.92 | K46: 235.59 | L46: 46.81 | M46: 32.44 | N46: Invalid | O46: 0 | P46: 1.6 | Q46: 43.55
A47: 01-06-2022 09:45 | B47: 1.14 | C47: 34.37 | D47: 35.52 | E47: 5.01 | F47: 4.38 | G47: 122.58 | H47: Invalid | I47: 7.21 | J47: 0.25 | K47: 343.58 | L47: 47.35 | M47: 32.42 | N47: Invalid | O47: 0 | P47: 1.63 | Q47: 45.47
A48: 01-06-2022 10:00 | B48: 1.09 | C48: 35.99 | D48: 37.09 | E48: 4.98 | F48: 4.14 | G48: 122.58 | H48: Invalid | I48: 7.96 | J48: 2.23 | K48: 316.59 | L48: 50.75 | M48: 31.23 | N48: Invalid | O48: 0 | P48: 1.72 | Q48: 57.6
A49: 01-06-2022 10:15 | B49: 1.17 | C49: 37.35 | D49: 38.52 | E49: 5.33 | F49: 4.49 | G49: 122.58 | H49: Invalid | I49: 8.43 | J49: 2.39 | K49: 309.63 | L49: 50.26 | M49: 29.22 | N49: Invalid | O49: 0 | P49: 1.82 | Q49: 61.89
A50: 01-06-2022 10:30 | B50: 1.2 | C50: 37.92 | D50: 39.12 | E50: 5.37 | F50: 3.89 | G50: 124.66 | H50: Invalid | I50: 9.36 | J50: 2.6 | K50: 315.19 | L50: 52.13 | M50: 26.08 | N50: Invalid | O50: 0 | P50: 1.78 | Q50: 59.84
A51: 01-06-2022 10:45 | B51: 1.11 | C51: 38.52 | D51: 39.63 | E51: 5.05 | F51: 4.85 | G51: 128.59 | H51: Invalid | I51: 11.69 | J51: 2.84 | K51: 310.9 | L51: 51 | M51: 27.02 | N51: 1067 | O51: 0 | P51: 1.72 | Q51: 56.36
A52: 01-06-2022 11:00 | B52: 1.02 | C52: 38.33 | D52: 39.36 | E52: 3.11 | F52: 5.22 | G52: 128.59 | H52: Invalid | I52: 9.47 | J52: 3.5 | K52: 334.1 | L52: 52.48 | M52: 24.82 | N52: Invalid | O52: 0 | P52: 1.71 | Q52: 56.68
A53: 01-06-2022 11:15 | B53: 1.68 | C53: 40.85 | D53: 42.53 | E53: 5.88 | F53: 7.06 | G53: 128.59 | H53: Invalid | I53: 8.82 | J53: 3.71 | K53: 345.68 | L53: 53.33 | M53: 22.7 | N53: Invalid | O53: 0 | P53: 1.65 | Q53: 56.29
A54: 01-06-2022 11:30 | B54: 1.58 | C54: 44.13 | D54: 45.71 | E54: 6.07 | F54: 4.84 | G54: 126.16 | H54: Invalid | I54: 6.8 | J54: 2.57 | K54: 35.8 | L54: 50.84 | M54: 21.16 | N54: Invalid | O54: 0 | P54: 1.51 | Q54: 59.91
A55: 01-06-2022 11:45 | B55: 0.95 | C55: 43.34 | D55: 44.28 | E55: 6.06 | F55: 8.77 | G55: 123.88 | H55: Invalid | I55: 6.42 | J55: 2.87 | K55: 25.53 | L55: 51.38 | M55: 21.38 | N55: Invalid | O55: 0 | P55: 1.49 | Q55: 61.52
A56: 01-06-2022 12:00 | B56: 0.82 | C56: 45.44 | D56: 46.26 | E56: 5.52 | F56: 11.75 | G56: 123.88 | H56: Z.Ref | I56: 4.51 | J56: 4.61 | K56: 4.48 | L56: 53.48 | M56: 19.06 | N56: Invalid | O56: 0 | P56: 1.5 | Q56: 64.72
A57: 01-06-2022 12:15 | B57: 1.07 | C57: 54.19 | D57: 55.27 | E57: 4.82 | F57: 9.38 | G57: 123.88 | H57: Z.Ref | I57: 3.57 | J57: 3.55 | K57: 19.2 | L57: 54.9 | M57: 18.64 | N57: 808 | O57: 0 | P57: 1.57 | Q57: 72.11
A58: 01-06-2022 12:30 | B58: 1.1 | C58: 52.78 | D58: 53.88 | E58: 4.63 | F58: 14.02 | G58: Z.Ref | H58: Z.Ref | I58: 3.86 | J58: 2.6 | K58: 8.66 | L58: 55.66 | M58: 18.45 | N58: 653.5 | O58: 0 | P58: 1.48 | Q58: 62.64
A59: 01-06-2022 12:45 | B59: 0.97 | C59: 58.31 | D59: 59.28 | E59: 4.9 | F59: 13.24 | G59: Z.Ref | H59: Z.Ref | I59: 4.4 | J59: 2.03 | K59: 37.6 | L59: 51.34 | M59: 17.71 | N59: 699.3 | O59: 0 | P59: 1.43 | Q59: 101.85
A60: 01-06-2022 13:00 | B60: 0.7 | C60: 57.81 | D60: 58.52 | E60: 4.69 | F60: 16.53 | G60: Z.Ref | H60: Z.Ref | I60: 3.83 | J60: 1.13 | K60: 89.57 | L60: 50.15 | M60: 17.07 | N60: 827.5 | O60: 0 | P60: 1.28 | Q60: 109.72
A61: 01-06-2022 13:15 | B61: 0.49 | C61: 56.3 | D61: 56.79 | E61: 4.6 | F61: 16.6 | G61: Invalid | H61: Invalid | I61: 3.42 | J61: 0.79 | K61: 50.64 | L61: 54.61 | M61: 16.03 | N61: 584.8 | O61: 0 | P61: 1.22 | Q61: 106.54
A62: 01-06-2022 13:30 | B62: 0.25 | C62: 52.49 | D62: 52.74 | E62: 4.1 | F62: 21.29 | G62: 44.11 | H62: 39.12 | I62: 2.67 | J62: 1.81 | K62: 38.95 | L62: 52.15 | M62: 16.41 | N62: 895.4 | O62: 0 | P62: 1.18 | Q62: 107.87
A63: 01-06-2022 13:45 | B63: 0.09 | C63: 50.28 | D63: 50.37 | E63: 3.6 | F63: 15.86 | G63: Calib. | H63: Calib. | I63: 2.56 | J63: 2.57 | K63: 5.17 | L63: 53.96 | M63: 14.23 | N63: 521.6 | O63: 0 | P63: 1.26 | Q63: 115.61
A64: 01-06-2022 14:00 | B64: 0.41 | C64: 50.67 | D64: 51.07 | E64: 3.93 | F64: 7.7 | G64: Calib. | H64: Calib. | I64: 2.65 | J64: 2.16 | K64: 1.91 | L64: 56.23 | M64: 15.03 | N64: 719 | O64: 0 | P64: 1.23 | Q64: 126.38
A65: 01-06-2022 14:15 | B65: 1.19 | C65: 48.94 | D65: 50.12 | E65: 4.86 | F65: 5.19 | G65: Calib. | H65: Calib. | I65: 3.05 | J65: 3.13 | K65: 349.63 | L65: 56.05 | M65: 14.23 | N65: 587.3 | O65: 0 | P65: 1.33 | Q65: 120.11
A66: 01-06-2022 14:30 | B66: 1.67 | C66: 47.8 | D66: 49.47 | E66: 4.88 | F66: 4.63 | G66: 205.11 | H66: 45.63 | I66: 3.27 | J66: 2.6 | K66: 345.8 | L66: 52.73 | M66: 13.81 | N66: 552.4 | O66: 0 | P66: 1.37 | Q66: 110.86
...

Sheet 02
A1: Station: | B1: BHATAGAON RAIPUR
A2: Date: | B2: =$A$9 -> 02-06-2022 00:15 | D2: Power Off | G2: Pw.Off | L2: Link Fail | N2: Link F | P2: Maintenance | R2: Maint.
A3: Report Type: | B3: Mean | D3: Calibration | G3: Calib. | L3: Data Fail | N3: Data F | P3: Invalid | R3: Invalid
A4: Time Base: | B4: 15 Min | D4: Zero Referrence | G4: Z.Ref | L4: Warm Up | N4: Wm. Up
A7: Date & Time | B7: NO_BHATAGAON | C7: NO2__BHATAGAON | D7: NOX_BHATAGAON | E7: SO2__BHATAGAON | F7: O3__BHATAGAON | G7: PM10__BHATAGAON | H7: PM2_5__BHATAGAON | I7: BENZ__BHATAGAON | J7: WS__BHATAGAON | K7: WD__BHATAGAON | L7: TEMP__BHATAGAON | M7: HUM__BHATAGAON | N7: SR__BHATAGAON | O7: RG__BHATAGAON | P7: CO__BHATAGAON | Q7: NH3__BHATAGAON
B8: ug/m3 | C8: ug/m3 | D8: ug/m3 | E8: ug/m3 | F8: ug/m3 | G8: ug/m3 | H8: ug/m3 | I8: ug/m3 | J8: m/sec | K8: deg | L8: degreC | M8: % | N8: w/m2 | O8: mm | P8: mg/m3 | Q8: ug/m3
A9: 02-06-2022 00:15 | B9: 185.95 | C9: 61.34 | D9: 247.29 | E9: 8.85 | F9: Z.Ref | G9: 334.35 | H9: 72.65 | I9: 18.34 | J9: 1.07 | K9: 71.48 | L9: 40.17 | M9: 46.7 | N9: 112.5 | O9: 0 | P9: 4.13 | Q9: 177.61
A10: 02-06-2022 00:30 | B10: 182.24 | C10: 59.79 | D10: 242.03 | E10: 8.6 | F10: Z.Ref | G10: 323.12 | H10: 68.33 | I10: 17.92 | J10: 1.47 | K10: 15.22 | L10: 42.16 | M10: 46.6 | N10: 112.9 | O10: 0 | P10: 3.82 | Q10: 174.4
A11: 02-06-2022 00:45 | B11: 176.77 | C11: 58.06 | D11: 234.83 | E11: 8.44 | F11: Z.Ref | G11: 323.12 | H11: 67.1 | I11: 17.1 | J11: 0.89 | K11: 346.86 | L11: 41.52 | M11: 54.71 | N11: 113.7 | O11: 0 | P11: 3.88 | Q11: 172.91
A12: 02-06-2022 01:00 | B12: 172.14 | C12: 55.85 | D12: 227.99 | E12: 8.53 | F12: Z.Ref | G12: 323.12 | H12: 67.1 | I12: 14.56 | J12: 0.83 | K12: 72.79 | L12: 40.34 | M12: 49.95 | N12: 113.7 | O12: 0 | P12: 3.55 | Q12: 170.82
A13: 02-06-2022 01:15 | B13: 166.72 | C13: 53.93 | D13: 220.65 | E13: 8.44 | F13: 0.08 | G13: 323.12 | H13: 67.1 | I13: 16.26 | J13: 0.55 | K13: 232.77 | L13: 40.37 | M13: 42.69 | N13: 113.1 | O13: 0 | P13: 3.44 | Q13: 166.73
A14: 02-06-2022 01:30 | B14: 158.83 | C14: 51.25 | D14: 210.07 | E14: 8.34 | F14: 0.01 | G14: 297.56 | H14: 65.71 | I14: 14.43 | J14: 0.32 | K14: 168.26 | L14: 42.13 | M14: 41.97 | N14: 114.1 | O14: 0 | P14: 2.41 | Q14: 158.75
A15: 02-06-2022 01:45 | B15: 152.38 | C15: 49.85 | D15: 202.24 | E15: 8.61 | F15: Z.Ref | G15: 293.99 | H15: 65.23 | I15: 15.72 | J15: 0.62 | K15: 150.87 | L15: 40.34 | M15: 46.51 | N15: 113 | O15: 0 | P15: 2.33 | Q15: 143.39
A16: 02-06-2022 02:00 | B16: 146.25 | C16: 49.38 | D16: 195.63 | E16: 8.44 | F16: 0.01 | G16: 293.99 | H16: 65.23 | I16: 12.5 | J16: 0.43 | K16: 133.58 | L16: 37.82 | M16: 41.63 | N16: 115.7 | O16: 0 | P16: 1.98 | Q16: 143.97
A17: 02-06-2022 02:15 | B17: 138.89 | C17: 48.41 | D17: 187.3 | E17: 8.77 | F17: Z.Ref | G17: 293.99 | H17: 65.23 | I17: 12.8 | J17: 1.4 | K17: 262.33 | L17: 38.47 | M17: 43.55 | N17: 118.2 | O17: 0 | P17: 1.92 | Q17: 143.57
A18: 02-06-2022 02:30 | B18: 132.11 | C18: 47.43 | D18: 179.54 | E18: 9.11 | F18: 0.11 | G18: 249.65 | H18: 63.68 | I18: 11.89 | J18: 2.04 | K18: 180.19 | L18: 40.42 | M18: 40.24 | N18: 116.4 | O18: 0 | P18: 2.15 | Q18: 143.78
A19: 02-06-2022 02:45 | B19: 123.07 | C19: 45.71 | D19: 168.78 | E19: 8.78 | F19: 0.57 | G19: 248.96 | H19: 63.11 | I19: 11.94 | J19: 1.1 | K19: 181.86 | L19: 41.9 | M19: 41.15 | N19: 118.7 | O19: 0 | P19: 2.04 | Q19: 138.81
A20: 02-06-2022 03:00 | B20: 113.49 | C20: 44.3 | D20: 157.79 | E20: 4.73 | F20: 0.2 | G20: 248.96 | H20: 63.11 | I20: 11.66 | J20: 1.2 | K20: 179.57 | L20: 40.23 | M20: 44.67 | N20: 119.3 | O20: 0 | P20: 1.76 | Q20: 134.99
A21: 02-06-2022 03:15 | B21: 104.36 | C21: 43.2 | D21: 147.56 | E21: 8.47 | F21: 0.54 | G21: 248.96 | H21: 63.11 | I21: 10.04 | J21: 1.01 | K21: 58.09 | L21: 40.33 | M21: 45.96 | N21: 119.4 | O21: 0 | P21: 2.33 | Q21: 131.63
A22: 02-06-2022 03:30 | B22: 93.99 | C22: 41.48 | D22: 135.47 | E22: 8.51 | F22: 0.15 | G22: 203.51 | H22: 58.67 | I22: 7.09 | J22: 0.29 | K22: 313.42 | L22: 39.59 | M22: 46.35 | N22: 119.7 | O22: 0 | P22: 2.34 | Q22: 131.46
A23: 02-06-2022 03:45 | B23: 82.23 | C23: 40.51 | D23: 122.74 | E23: 8.13 | F23: Z.Ref | G23: 202.81 | H23: 57.14 | I23: 10.75 | J23: 1.33 | K23: 331.03 | L23: 37.69 | M23: 51.98 | N23: 120.7 | O23: 0 | P23: 2.33 | Q23: 127.2
A24: 02-06-2022 04:00 | B24: 72.13 | C24: 39.43 | D24: 111.55 | E24: 7.67 | F24: Z.Ref | G24: 202.81 | H24: 57.14 | I24: 9.03 | J24: 1.65 | K24: 321.27 | L24: 37.18 | M24: 54.83 | N24: 120.5 | O24: 0 | P24: 2.27 | Q24: 122.49
A25: 02-06-2022 04:15 | B25: 63.94 | C25: 38.28 | D25: 102.21 | E25: 7.79 | F25: Z.Ref | G25: 202.81 | H25: 57.14 | I25: 9.37 | J25: 0.7 | K25: 22.08 | L25: 38.15 | M25: 53.43 | N25: 122 | O25: 0 | P25: 2.19 | Q25: 117.94
A26: 02-06-2022 04:30 | B26: 58.91 | C26: 38.22 | D26: 97.13 | E26: 7.67 | F26: Z.Ref | G26: 164.24 | H26: 49.09 | I26: 9.48 | J26: 0.46 | K26: 233.25 | L26: 39.12 | M26: 50.48 | N26: 122.5 | O26: 0 | P26: 2.13 | Q26: 112.89
A27: 02-06-2022 04:45 | B27: 57.45 | C27: 39.56 | D27: 97.01 | E27: 7.39 | F27: Z.Ref | G27: 163.65 | H27: 46.16 | I27: 8.76 | J27: 1.41 | K27: 13.28 | L27: 39.26 | M27: 52.88 | N27: 122.6 | O27: 0 | P27: 2.1 | Q27: 112.87
A28: 02-06-2022 05:00 | B28: 55 | C28: 39.75 | D28: 94.75 | E28: 7.18 | F28: 0.06 | G28: 163.65 | H28: 46.16 | I28: 8.35 | J28: 0.87 | K28: 297.81 | L28: 38.78 | M28: 52 | N28: 122.8 | O28: 0 | P28: 2.02 | Q28: 112.37
A29: 02-06-2022 05:15 | B29: 49.64 | C29: 39.91 | D29: 89.54 | E29: 7.24 | F29: Maint. | G29: 163.65 | H29: 46.16 | I29: 8.62 | J29: 1.34 | K29: 283.07 | L29: 38.84 | M29: 51.82 | N29: 124.5 | O29: 0 | P29: 1.87 | Q29: 109.98
A30: 02-06-2022 05:30 | B30: 45.15 | C30: 39.41 | D30: 84.56 | E30: 7 | F30: Maint. | G30: 164.32 | H30: 47.13 | I30: 8.27 | J30: 0.68 | K30: 277.53 | L30: 38.98 | M30: 53.07 | N30: 130.4 | O30: 0 | P30: 1.89 | Q30: 102.45
A31: 02-06-2022 05:45 | B31: 43.35 | C31: 40.88 | D31: 84.23 | E31: 7 | F31: Maint. | G31: 164.33 | H31: 47.49 | I31: 7.04 | J31: 0.62 | K31: 265.23 | L31: 38.78 | M31: 54.77 | N31: 148.9 | O31: 0 | P31: 1.89 | Q31: 102.37
A32: 02-06-2022 06:00 | B32: 40.54 | C32: 39.72 | D32: 80.26 | E32: 7.1 | F32: 0.12 | G32: 164.33 | H32: 47.49 | I32: 7.23 | J32: 1.54 | K32: 282.91 | L32: 38.21 | M32: 53.06 | N32: 186.4 | O32: 0 | P32: 1.74 | Q32: 98.68
A33: 02-06-2022 06:15 | B33: 38.39 | C33: 39.1 | D33: 77.48 | E33: 7.15 | F33: 0.15 | G33: 164.33 | H33: 47.49 | I33: 7.54 | J33: 0.96 | K33: 297.53 | L33: 40.83 | M33: 52.44 | N33: 216.3 | O33: 0 | P33: 1.72 | Q33: 88.32
A34: 02-06-2022 06:30 | B34: 36.63 | C34: 40.9 | D34: 77.54 | E34: 7.38 | F34: 0.01 | G34: 162.54 | H34: 48.79 | I34: 7.23 | J34: 0.91 | K34: 346.15 | L34: 41.84 | M34: 51.01 | N34: 260.1 | O34: 0 | P34: 1.82 | Q34: 94.64
A35: 02-06-2022 06:45 | B35: 35.26 | C35: 41.08 | D35: 76.35 | E35: 7.97 | F35: 0.04 | G35: 162.51 | H35: 49.26 | I35: 7.73 | J35: 0.87 | K35: 353.19 | L35: 42.52 | M35: 49.6 | N35: 307.6 | O35: 0 | P35: 1.81 | Q35: 95.52
A36: 02-06-2022 07:00 | B36: 33.29 | C36: 41.9 | D36: 75.19 | E36: 4.1 | F36: 0.05 | G36: 162.51 | H36: 49.26 | I36: 8.35 | J36: 0.94 | K36: 329.68 | L36: 41.42 | M36: 48.55 | N36: 367.2 | O36: 0 | P36: 1.89 | Q36: 94.96
A37: 02-06-2022 07:15 | B37: 30.41 | C37: 41.46 | D37: 71.87 | E37: 7.84 | F37: 0.3 | G37: 162.51 | H37: 49.26 | I37: 8.75 | J37: 1.09 | K37: 350.46 | L37: 42.37 | M37: 47.26 | N37: 424.9 | O37: 0 | P37: 1.92 | Q37: 92.55
A38: 02-06-2022 07:30 | B38: 27.22 | C38: 43.92 | D38: 71.14 | E38: 7.73 | F38: 0.14 | G38: 145.1 | H38: 45.76 | I38: 9.31 | J38: 1.17 | K38: 317.85 | L38: 42.88 | M38: 45.47 | N38: 470.7 | O38: 0 | P38: 1.86 | Q38: 94.73
A39: 02-06-2022 07:45 | B39: 23.69 | C39: 42.27 | D39: 65.96 | E39: 7.85 | F39: 0.38 | G39: 144.69 | H39: 44.55 | I39: 9.19 | J39: 0.95 | K39: 21.61 | L39: 43.05 | M39: 44.01 | N39: 525.3 | O39: 0 | P39: 1.9 | Q39: 94.14
A40: 02-06-2022 08:00 | B40: 19.54 | C40: 42.07 | D40: 61.62 | E40: 7.83 | F40: 0.25 | G40: 144.69 | H40: 44.55 | I40: 9.18 | J40: 0.66 | K40: 8.54 | L40: 44.97 | M40: 41.73 | N40: 588.2 | O40: 0 | P40: 1.93 | Q40: 88.76
A41: 02-06-2022 08:15 | B41: 15.37 | C41: 45.66 | D41: 61.04 | E41: 7.64 | F41: 0.13 | G41: 144.69 | H41: 44.55 | I41: 9.72 | J41: 1.08 | K41: 302.14 | L41: 47.39 | M41: 39.72 | N41: 666.7 | O41: 0 | P41: 1.97 | Q41: 90.23
A42: 02-06-2022 08:30 | B42: 11.88 | C42: 47.21 | D42: 59.09 | E42: 7.27 | F42: 0.22 | G42: 143.87 | H42: 45.73 | I42: 10.04 | J42: 2.21 | K42: 314.99 | L42: 48.98 | M42: 36.63 | N42: 727.3 | O42: 0 | P42: 2.07 | Q42: 89.07
...

Sheet 03
A1: Station: | B1: BHATAGAON RAIPUR
A2: Date: | B2: =$A$9 -> 03-06-2022 00:15 | D2: Power Off | G2: Pw.Off | L2: Link Fail | N2: Link F | P2: Maintenance | R2: Maint.
A3: Report Type: | B3: Mean | D3: Calibration | G3: Calib. | L3: Data Fail | N3: Data F | P3: Invalid | R3: Invalid
A4: Time Base: | B4: 15 Min | D4: Zero Referrence | G4: Z.Ref | L4: Warm Up | N4: Wm. Up
A7: Date & Time | B7: NO_BHATAGAON | C7: NO2__BHATAGAON | D7: NOX_BHATAGAON | E7: SO2__BHATAGAON | F7: O3__BHATAGAON | G7: PM10__BHATAGAON | H7: PM2_5__BHATAGAON | I7: BENZ__BHATAGAON | J7: WS__BHATAGAON | K7: WD__BHATAGAON | L7: TEMP__BHATAGAON | M7: HUM__BHATAGAON | N7: SR__BHATAGAON | O7: RG__BHATAGAON | P7: CO__BHATAGAON | Q7: NH3__BHATAGAON
B8: ug/m3 | C8: ug/m3 | D8: ug/m3 | E8: ug/m3 | F8: ug/m3 | G8: ug/m3 | H8: ug/m3 | I8: ug/m3 | J8: m/sec | K8: deg | L8: degreC | M8: % | N8: w/m2 | O8: mm | P8: mg/m3 | Q8: ug/m3
A9: 03-06-2022 00:15 | B9: 125.05 | C9: 63.3 | D9: 188.35 | E9: 7 | F9: Z.Ref | G9: 304.17 | H9: 69.93 | I9: 13.47 | J9: 1.26 | K9: 50.14 | L9: 44.52 | M9: 33.86 | N9: 81.6 | O9: 0 | P9: 2.25 | Q9: 117.32
A10: 03-06-2022 00:30 | B10: 116.04 | C10: 60.22 | D10: 176.26 | E10: 7.41 | F10: 0.01 | G10: 242.98 | H10: 62.25 | I10: 9.55 | J10: 0.74 | K10: 339.39 | L10: 44.72 | M10: 34.24 | N10: 81.9 | O10: 0 | P10: 2.14 | Q10: 118.21
A11: 03-06-2022 00:45 | B11: 107.4 | C11: 57.59 | D11: 164.98 | E11: 7.12 | F11: 0.03 | G11: 236.49 | H11: 59.62 | I11: 10.04 | J11: 1.51 | K11: 236.85 | L11: 48.83 | M11: 34.77 | N11: 82 | O11: 0 | P11: 2.16 | Q11: 114.62
A12: 03-06-2022 01:00 | B12: 98.85 | C12: 55.05 | D12: 153.9 | E12: 7.45 | F12: 0.52 | G12: 236.49 | H12: 59.62 | I12: 9.76 | J12: 1.51 | K12: 239.36 | L12: 46.78 | M12: 30.77 | N12: 82.5 | O12: 0 | P12: 1.86 | Q12: 110.82
A13: 03-06-2022 01:15 | B13: 90.09 | C13: 52.11 | D13: 142.2 | E13: 7.38 | F13: 0.66 | G13: 236.49 | H13: 59.62 | I13: 9.75 | J13: 0.65 | K13: 42 | L13: 43.42 | M13: 33.9 | N13: 83.9 | O13: 0 | P13: 1.94 | Q13: 107.51
A14: 03-06-2022 01:30 | B14: 82.94 | C14: 50.08 | D14: 133.01 | E14: 7.58 | F14: 0.09 | G14: 189.85 | H14: 56.65 | I14: 8.35 | J14: 1.4 | K14: 274.73 | L14: 41.57 | M14: 37.97 | N14: 84 | O14: 0 | P14: 2.37 | Q14: 107.04
A15: 03-06-2022 01:45 | B15: 74.96 | C15: 47.1 | D15: 122.06 | E15: 7.36 | F15: 0.02 | G15: 188.71 | H15: 55.64 | I15: 8.7 | J15: 0.61 | K15: 347.58 | L15: 43.3 | M15: 40.6 | N15: 92.5 | O15: 0 | P15: 2.67 | Q15: 110.29
A16: 03-06-2022 02:00 | B16: 65.82 | C16: 44.71 | D16: 110.53 | E16: 7.06 | F16: Z.Ref | G16: 188.71 | H16: 55.64 | I16: 9.38 | J16: 0.38 | K16: 291.25 | L16: 43.35 | M16: 42.75 | N16: 100.1 | O16: 0 | P16: 2.59 | Q16: 105.97
A17: 03-06-2022 02:15 | B17: 57.65 | C17: 42.61 | D17: 100.27 | E17: 7.11 | F17: Z.Ref | G17: 188.71 | H17: 55.64 | I17: 10.57 | J17: 0.94 | K17: 160.98 | L17: 42.99 | M17: 41.29 | N17: 95.9 | O17: 0 | P17: 2.45 | Q17: 101.2
A18: 03-06-2022 02:30 | B18: 50.72 | C18: 40.94 | D18: 91.67 | E18: 6.8 | F18: Z.Ref | G18: 184.73 | H18: 55.59 | I18: 10.99 | J18: 1.42 | K18: 203.39 | L18: 40.18 | M18: 38.76 | N18: 97.2 | O18: 0 | P18: 2.4 | Q18: 96.66
A19: 03-06-2022 02:45 | B19: 45.2 | C19: 40.46 | D19: 85.66 | E19: 6.76 | F19: Z.Ref | G19: 184.67 | H19: 55.58 | I19: 10.78 | J19: 1.73 | K19: 295.94 | L19: 38.87 | M19: 44.25 | N19: 102.7 | O19: 0 | P19: 2.36 | Q19: 92.36
A20: 03-06-2022 03:00 | B20: 40.54 | C20: 39.47 | D20: 80.01 | E20: 2.58 | F20: Z.Ref | G20: 184.67 | H20: 55.58 | I20: 11.28 | J20: 1.23 | K20: 258.51 | L20: 37.88 | M20: 45.31 | N20: 111.9 | O20: 0 | P20: 2.37 | Q20: 91.1
A21: 03-06-2022 03:15 | B21: 36.53 | C21: 38.51 | D21: 75.03 | E21: 6.01 | F21: Z.Ref | G21: 184.67 | H21: 55.58 | I21: 11.34 | J21: 0.86 | K21: 6.56 | L21: 37.56 | M21: 44.52 | N21: 112 | O21: 0 | P21: 2.34 | Q21: 88.51
A22: 03-06-2022 03:30 | B22: 32.96 | C22: 37.5 | D22: 70.46 | E22: 6.01 | F22: Z.Ref | G22: 176.89 | H22: 55.71 | I22: 12.05 | J22: 1.58 | K22: 66.61 | L22: 38.68 | M22: 39.78 | N22: 108.6 | O22: 0 | P22: 2.24 | Q22: 86.42
A23: 03-06-2022 03:45 | B23: 29.57 | C23: 37.29 | D23: 66.86 | E23: 5.82 | F23: Z.Ref | G23: 176.65 | H23: 55.75 | I23: 12.37 | J23: 1.13 | K23: 109.49 | L23: 38.86 | M23: 39.48 | N23: 108 | O23: 0 | P23: 2.23 | Q23: 84.73
A24: 03-06-2022 04:00 | B24: 27.71 | C24: 36.57 | D24: 64.28 | E24: 6 | F24: Z.Ref | G24: 176.65 | H24: 55.75 | I24: 13.12 | J24: 1.87 | K24: 204.7 | L24: 38.57 | M24: 43.97 | N24: 107.4 | O24: 0 | P24: 2.19 | Q24: 83.91
A25: 03-06-2022 04:15 | B25: 27.89 | C25: 33.8 | D25: 61.69 | E25: 6.03 | F25: Z.Ref | G25: 176.65 | H25: 55.75 | I25: 12.68 | J25: 1.42 | K25: 301.43 | L25: 38.77 | M25: 47.6 | N25: 110.7 | O25: 0 | P25: 2.18 | Q25: 72.55
A26: 03-06-2022 04:30 | B26: 29.3 | C26: 35.2 | D26: 64.5 | E26: 6.21 | F26: Z.Ref | G26: 220.3 | H26: 53.35 | I26: 13 | J26: 0.64 | K26: 259.17 | L26: 37.73 | M26: 50.65 | N26: 104.5 | O26: 0 | P26: 2.34 | Q26: 65.45
A27: 03-06-2022 04:45 | B27: 31.68 | C27: 35.96 | D27: 67.64 | E27: 6.54 | F27: 0.14 | G27: 223.6 | H27: 52.53 | I27: 12.7 | J27: 1.63 | K27: 280.08 | L27: 37.85 | M27: 50.89 | N27: 92 | O27: 0 | P27: 2.23 | Q27: 70.16
A28: 03-06-2022 05:00 | B28: 33.64 | C28: 36.59 | D28: 70.23 | E28: 6.75 | F28: Z.Ref | G28: 223.6 | H28: 52.53 | I28: 13.09 | J28: 1.78 | K28: 337.71 | L28: 37.53 | M28: 52 | N28: 88.1 | O28: 0 | P28: 2.24 | Q28: 73.52
A29: 03-06-2022 05:15 | B29: 34.49 | C29: 36.72 | D29: 71.21 | E29: 7.02 | F29: Z.Ref | G29: 223.6 | H29: 52.53 | I29: 12.91 | J29: 1.11 | K29: 58.42 | L29: 38.83 | M29: 41.58 | N29: 89.7 | O29: 0 | P29: 2.48 | Q29: 75.96
A30: 03-06-2022 05:30 | B30: 34.6 | C30: 36.9 | D30: 71.5 | E30: 7.27 | F30: Z.Ref | G30: 266.8 | H30: 56.45 | I30: 12.3 | J30: 0.44 | K30: 11.9 | L30: 38.29 | M30: 45.43 | N30: 96.8 | O30: 0 | P30: 2.76 | Q30: 78.02
A31: 03-06-2022 05:45 | B31: 35.24 | C31: 36.46 | D31: 71.7 | E31: 7.7 | F31: 0.12 | G31: 272.12 | H31: 57.87 | I31: 11.16 | J31: 0.85 | K31: 24.77 | L31: 41.23 | M31: 41.82 | N31: 109.5 | O31: 0 | P31: 3.01 | Q31: 78.86
A32: 03-06-2022 06:00 | B32: 36.47 | C32: 35.43 | D32: 71.9 | E32: 7.91 | F32: 0.21 | G32: 272.12 | H32: 57.87 | I32: 11.48 | J32: 1.74 | K32: 2.03 | L32: 40.3 | M32: 42.65 | N32: 127.1 | O32: 0 | P32: 2.65 | Q32: 81.36
A33: 03-06-2022 06:15 | B33: 36.89 | C33: 35.75 | D33: 72.64 | E33: 7.84 | F33: 0.04 | G33: 272.12 | H33: 57.87 | I33: 13.57 | J33: 1.35 | K33: 344.92 | L33: 41.3 | M33: 40.89 | N33: 156.5 | O33: 0 | P33: 2.64 | Q33: 86.38
A34: 03-06-2022 06:30 | B34: 37.59 | C34: 38.11 | D34: 75.7 | E34: 7.64 | F34: 0.31 | G34: 418.77 | H34: 74.83 | I34: 13.97 | J34: 1.48 | K34: 21.34 | L34: 42.32 | M34: 39.19 | N34: 192.1 | O34: 0 | P34: 2.89 | Q34: 87.98
A35: 03-06-2022 06:45 | B35: 40.11 | C35: 40.97 | D35: 81.08 | E35: 7.7 | F35: 0.28 | G35: 421.02 | H35: 80.99 | I35: 14.17 | J35: 1.72 | K35: 137.24 | L35: 43.62 | M35: 36.9 | N35: 233.7 | O35: 0 | P35: 2.84 | Q35: 89.11
A36: 03-06-2022 07:00 | B36: 39.2 | C36: 43.67 | D36: 82.87 | E36: 3.6 | F36: 0.31 | G36: 421.02 | H36: 80.99 | I36: 14.71 | J36: 0.96 | K36: 171.37 | L36: 45.53 | M36: 34.96 | N36: 290.9 | O36: 0 | P36: 2.8 | Q36: 89.69
A37: 03-06-2022 07:15 | B37: 36.83 | C37: 47.04 | D37: 83.87 | E37: 7.22 | F37: 0.43 | G37: 421.02 | H37: 80.99 | I37: 14.36 | J37: 2.04 | K37: 72.27 | L37: 48.36 | M37: 33.58 | N37: 346.3 | O37: 0 | P37: 2.74 | Q37: 88.16
A38: 03-06-2022 07:30 | B38: 33.1 | C38: 49.64 | D38: 82.74 | E38: 7.03 | F38: 0.48 | G38: 371.49 | H38: 86.47 | I38: 14.57 | J38: 1.67 | K38: 173.27 | L38: 48.4 | M38: 32.38 | N38: 406.7 | O38: 0 | P38: 2.59 | Q38: 86.23
A39: 03-06-2022 07:45 | B39: 27.4 | C39: 52.83 | D39: 80.23 | E39: 7.02 | F39: 0.57 | G39: 370.31 | H39: 88.35 | I39: 14.41 | J39: 0.15 | K39: 267.66 | L39: 50.42 | M39: 33.88 | N39: 448.2 | O39: 0 | P39: 2.61 | Q39: 81.66
A40: 03-06-2022 08:00 | B40: 21.32 | C40: 57.13 | D40: 78.45 | E40: 7.16 | F40: 0.8 | G40: 370.31 | H40: 88.35 | I40: 13.63 | J40: 2.53 | K40: 334.53 | L40: 47.66 | M40: 33.17 | N40: 511.2 | O40: 0 | P40: 2.73 | Q40: 84.12
A41: 03-06-2022 08:15 | B41: 16.19 | C41: 61.49 | D41: 77.68 | E41: 6.98 | F41: 0.89 | G41: 370.31 | H41: 88.35 | I41: 14.12 | J41: 3.28 | K41: 333.99 | L41: 48 | M41: 31.62 | N41: 558.8 | O41: 0 | P41: 2.75 | Q41: 82.77
A42: 03-06-2022 08:30 | B42: 11.84 | C42: 64.18 | D42: 76.02 | E42: 7.64 | F42: 1.42 | G42: 340.47 | H42: 91 | I42: 14.8 | J42: 2.85 | K42: 330.59 | L42: 50.21 | M42: 29.12 | N42: 604.1 | O42: 0 | P42: 2.89 | Q42: 81.77
...

Sheet 04
A1: Station: | B1: BHATAGAON RAIPUR
A2: Date: | B2: =$A$9 -> 04-06-2022 00:15 | D2: Power Off | G2: Pw.Off | L2: Link Fail | N2: Link F | P2: Maintenance | R2: Maint.
A3: Report Type: | B3: Mean | D3: Calibration | G3: Calib. | L3: Data Fail | N3: Data F | P3: Invalid | R3: Invalid
A4: Time Base: | B4: 15 Min | D4: Zero Referrence | G4: Z.Ref | L4: Warm Up | N4: Wm. Up
A7: Date & Time | B7: NO_BHATAGAON | C7: NO2__BHATAGAON | D7: NOX_BHATAGAON | E7: SO2__BHATAGAON | F7: O3__BHATAGAON | G7: PM10__BHATAGAON | H7: PM2_5__BHATAGAON | I7: BENZ__BHATAGAON | J7: WS__BHATAGAON | K7: WD__BHATAGAON | L7: TEMP__BHATAGAON | M7: HUM__BHATAGAON | N7: SR__BHATAGAON | O7: RG__BHATAGAON | P7: CO__BHATAGAON | Q7: NH3__BHATAGAON
B8: ug/m3 | C8: ug/m3 | D8: ug/m3 | E8: ug/m3 | F8: ug/m3 | G8: ug/m3 | H8: ug/m3 | I8: ug/m3 | J8: m/sec | K8: deg | L8: degreC | M8: % | N8: w/m2 | O8: mm | P8: mg/m3 | Q8: ug/m3
A9: 04-06-2022 00:15 | B9: 67.1 | C9: 72.87 | D9: 139.97 | E9: 7.16 | F9: Data F | G9: 272.26 | H9: 72.87 | I9: 12.75 | J9: 1.03 | K9: 323.82 | L9: 46.45 | M9: 40.02 | N9: 80.7 | O9: 0 | P9: 3.24 | Q9: 108.2
A10: 04-06-2022 00:30 | B10: 62.03 | C10: 70.48 | D10: 132.51 | E10: 6.83 | F10: Data F | G10: 237.33 | H10: 68.27 | I10: 14.16 | J10: 1.92 | K10: 342.31 | L10: 46.74 | M10: 43.07 | N10: 100.8 | O10: 0 | P10: 3.1 | Q10: 104.04
A11: 04-06-2022 00:45 | B11: 56.74 | C11: 68.28 | D11: 125.02 | E11: 6.88 | F11: Data F | G11: 236.8 | H11: 66.69 | I11: 12.42 | J11: 1.26 | K11: 199.68 | L11: 46.99 | M11: 33.76 | N11: 106.3 | O11: 0 | P11: 2.78 | Q11: 100.24
A12: 04-06-2022 01:00 | B12: 48.25 | C12: 65.73 | D12: 113.98 | E12: 6.56 | F12: Data F | G12: 236.8 | H12: 66.69 | I12: 11.35 | J12: 1.37 | K12: 274.62 | L12: 46.77 | M12: 28.11 | N12: 103.8 | O12: 0 | P12: 2.46 | Q12: 95.67
A13: 04-06-2022 01:15 | B13: 38.26 | C13: 63.29 | D13: 101.55 | E13: 6.46 | F13: 0.42 | G13: 236.8 | H13: 66.69 | I13: 8.76 | J13: 0.96 | K13: 183.8 | L13: 45.22 | M13: 30.02 | N13: 105 | O13: 0 | P13: 2.42 | Q13: 89.32
A14: 04-06-2022 01:30 | B14: 29.63 | C14: 60.39 | D14: 90.02 | E14: 6.17 | F14: 0.52 | G14: 166.43 | H14: 59.12 | I14: 6.64 | J14: 1.44 | K14: 199.09 | L14: 44.98 | M14: 31.86 | N14: 103.3 | O14: 0 | P14: 2.37 | Q14: 85.23
A15: 04-06-2022 01:45 | B15: 23.03 | C15: 57.99 | D15: 81.02 | E15: 5.83 | F15: 0.34 | G15: 153.02 | H15: 56.37 | I15: 6.63 | J15: 1.56 | K15: 316.46 | L15: 43.65 | M15: 35.53 | N15: 104.4 | O15: 0 | P15: 2.29 | Q15: 81.44
A16: 04-06-2022 02:00 | B16: 17.89 | C16: 55.21 | D16: 73.1 | E16: 6.43 | F16: 0.39 | G16: 153.02 | H16: 56.37 | I16: 6.08 | J16: 1.35 | K16: 309.21 | L16: 42.44 | M16: 39.39 | N16: 104.3 | O16: 0 | P16: 2.28 | Q16: 77.92
A17: 04-06-2022 02:15 | B17: 13.82 | C17: 51.49 | D17: 65.3 | E17: 6 | F17: 0.88 | G17: 153.02 | H17: 56.37 | I17: 6.57 | J17: 1.43 | K17: 192.42 | L17: 42.53 | M17: 37.3 | N17: 103.3 | O17: 0 | P17: 1.92 | Q17: 75.2
A18: 04-06-2022 02:30 | B18: 11.61 | C18: 48.44 | D18: 60.05 | E18: 6.22 | F18: 0.83 | G18: 157.27 | H18: 55.16 | I18: 7.05 | J18: 0.9 | K18: 177.88 | L18: 42.28 | M18: 42.74 | N18: 104.6 | O18: 0 | P18: 1.89 | Q18: 64.8
A19: 04-06-2022 02:45 | B19: 10.92 | C19: 47.94 | D19: 58.86 | E19: 6.14 | F19: 1.02 | G19: 157.34 | H19: 54.72 | I19: 5.57 | J19: 1.59 | K19: 197.06 | L19: 42.8 | M19: 37.07 | N19: 103.6 | O19: 0 | P19: 1.63 | Q19: 58.75
A20: 04-06-2022 03:00 | B20: 10.15 | C20: 47.43 | D20: 57.58 | E20: 2.8 | F20: 1.08 | G20: 157.34 | H20: 54.72 | I20: 5.91 | J20: 1.36 | K20: 233.4 | L20: 41.8 | M20: 44.43 | N20: 105.1 | O20: 0 | P20: 1.75 | Q20: 62.06
A21: 04-06-2022 03:15 | B21: 9.97 | C21: 46.08 | D21: 56.05 | E21: 6.39 | F21: 0.71 | G21: 157.34 | H21: 54.72 | I21: 5.45 | J21: 0.56 | K21: 269.33 | L21: 40.93 | M21: 43.84 | N21: 102.4 | O21: 0 | P21: 1.73 | Q21: 64.79
A22: 04-06-2022 03:30 | B22: 10.25 | C22: 46.08 | D22: 56.33 | E22: 6.83 | F22: 0.48 | G22: 160.83 | H22: 50.97 | I22: 5.98 | J22: 1.36 | K22: 171.69 | L22: 41.04 | M22: 41.53 | N22: 88.3 | O22: 0 | P22: 1.66 | Q22: 66.08
A23: 04-06-2022 03:45 | B23: 10.03 | C23: 45.18 | D23: 55.21 | E23: 6.79 | F23: 1.48 | G23: 160.88 | H23: 49.6 | I23: 6 | J23: 1.16 | K23: 214.21 | L23: 42.41 | M23: 38.3 | N23: 87 | O23: 0 | P23: 1.61 | Q23: 67.04
A24: 04-06-2022 04:00 | B24: 9.35 | C24: 44.39 | D24: 53.74 | E24: 7.19 | F24: 1.78 | G24: 160.88 | H24: 49.6 | I24: 5.61 | J24: 2.2 | K24: 179.99 | L24: 42.79 | M24: 37.84 | N24: 88.1 | O24: 0 | P24: 1.66 | Q24: 66.57
... A57: 04-06-2022 12:15 | B57: 1.63 | C57: 52.29 | D57: 53.93 | E57: 3.19 | F57: 8.25 | G57: 140.38 | H57: 38.33 | I57: 4.65 | J57: 0.9 | K57: 348.55 | L57: 54.34 | M57: 14.81 | N57: 1012.8 | O57: 0 | P57: 1.51 | Q57: 101.77
A58: 04-06-2022 12:30 | B58: 4.2 | C58: 50.18 | D58: 54.39 | E58: 3.81 | F58: 6.22 | G58: Calib. | H58: Calib. | I58: 3.77 | J58: 3.74 | K58: 343.08 | L58: 51.9 | M58: 14.94 | N58: 954 | O58: 0 | P58: 1.53 | Q58: 112.56
A59: 04-06-2022 12:45 | B59: 2.95 | C59: 52.08 | D59: 55.03 | E59: 3.44 | F59: 6.69 | G59: Calib. | H59: Calib. | I59: 3.15 | J59: 2.02 | K59: 341 | L59: 53.31 | M59: 14.35 | N59: 935.7 | O59: 0 | P59: 1.44 | Q59: 130.36
A60: 04-06-2022 13:00 | B60: 2.35 | C60: 51.84 | D60: 54.19 | E60: 3.28 | F60: 8.22 | G60: Calib. | H60: Calib. | I60: 1.13 | J60: 4.37 | K60: 332.07 | L60: 55.2 | M60: 14.25 | N60: 1109.6 | O60: 0 | P60: 1.51 | Q60: 175.02
A61: 04-06-2022 13:15 | B61: 2.66 | C61: 46.67 | D61: 49.33 | E61: 3.1 | F61: 5.67 | G61: Calib. | H61: Calib. | I61: 0.01 | J61: 3.79 | K61: 345.02 | L61: 50.87 | M61: 13.56 | N61: 1026.7 | O61: 0 | P61: 1.54 | Q61: 181.56
A62: 04-06-2022 13:30 | B62: 2.72 | C62: 50.23 | D62: 52.95 | E62: 3.4 | F62: 8.93 | G62: Calib. | H62: Calib. | I62: Maint. | J62: 4.75 | K62: 338.9 | L62: 52.07 | M62: 13.58 | N62: 847.7 | O62: 0 | P62: 1.52 | Q62: 188.16
A63: 04-06-2022 13:45 | B63: 2.08 | C63: 50.4 | D63: 52.47 | E63: 4.52 | F63: 5.73 | G63: Calib. | H63: Calib. | I63: Maint. | J63: 4.69 | K63: 357.39 | L63: 51.19 | M63: 13.22 | N63: 816.9 | O63: 0 | P63: 1.53 | Q63: 168.5
A64: 04-06-2022 14:00 | B64: 2.69 | C64: 49.01 | D64: 51.7 | E64: 3.01 | F64: 4.39 | G64: Calib. | H64: Calib. | I64: 0.22 | J64: 4.25 | K64: 353.02 | L64: 48.9 | M64: 13.74 | N64: 857 | O64: 0 | P64: 1.54 | Q64: 156.47
A65: 04-06-2022 14:15 | B65: 3.44 | C65: 47.06 | D65: 50.49 | E65: 3.68 | F65: 7.74 | G65: 37.84 | H65: 8.68 | I65: 0.22 | J65: 4.22 | K65: 345.84 | L65: 51.87 | M65: 12.99 | N65: 723.7 | O65: 0 | P65: 1.54 | Q65: 182.04
A66: 04-06-2022 14:30 | B66: 1.93 | C66: 49.06 | D66: 50.99 | E66: 3.33 | F66: 8.31 | G66: 129.75 | H66: 33.96 | I66: Z.Ref | J66: 3.82 | K66: 344.83 | L66: 51.69 | M66: 13.92 | N66: 685.2 | O66: 0 | P66: 1.49 | Q66: 179.1
A67: 04-06-2022 14:45 | B67: 1.65 | C67: 48.48 | D67: 50.12 | E67: 3.46 | F67: 4.9 | G67: 129.75 | H67: 33.96 | I67: Z.Ref | J67: 3.73 | K67: 327.06 | L67: 49.3 | M67: 14.68 | N67: 390.5 | O67: 0 | P67: 1.5 | Q67: 161.93
A68: 04-06-2022 15:00 | B68: 2 | C68: 46.59 | D68: 48.59 | E68: 2.47 | F68: 4.2 | G68: 129.75 | H68: 33.96 | I68: Z.Ref | J68: 2.83 | K68: 317.52 | L68: 49.91 | M68: 15.64 | N68: 396.9 | O68: 0 | P68: 1.51 | Q68: 150.88
A69: 04-06-2022 15:15 | B69: 2.68 | C69: 46.12 | D69: 48.8 | E69: 4.16 | F69: 4.15 | G69: 126.71 | H69: 33.74 | I69: Z.Ref | J69: 4.08 | K69: 332.39 | L69: 47.67 | M69: 15.97 | N69: 737.1 | O69: 0 | P69: 1.53 | Q69: 143.86
A70: 04-06-2022 15:30 | B70: 2.65 | C70: 45.05 | D70: 47.71 | E70: 4.64 | F70: 4.48 | G70: 120.5 | H70: 33.06 | I70: Z.Ref | J70: 4.33 | K70: 338.54 | L70: 51.37 | M70: 14.77 | N70: 847.1 | O70: 0 | P70: 1.52 | Q70: 136.88
A71: 04-06-2022 15:45 | B71: 2.53 | C71: 43.61 | D71: 46.14 | E71: 4.72 | F71: 4.01 | G71: 120.5 | H71: 33.06 | I71: Z.Ref | J71: 4.2 | K71: 334.38 | L71: 50.26 | M71: 14.22 | N71: 702.3 | O71: 0 | P71: 1.51 | Q71: 110.84
A72: 04-06-2022 16:00 | B72: 2.71 | C72: 43.13 | D72: 45.84 | E72: 4.5 | F72: 4.05 | G72: 120.5 | H72: 33.06 | I72: Z.Ref | J72: 3.89 | K72: 317.26 | L72: 49.73 | M72: 14.93 | N72: 546.3 | O72: 0 | P72: 1.51 | Q72: 106.56
A73: 04-06-2022 16:15 | B73: 2.63 | C73: 42.58 | D73: 45.2 | E73: 4.8 | F73: 3.87 | G73: 119.6 | H73: 32.37 | I73: Z.Ref | J73: 3.17 | K73: 325.74 | L73: 49.96 | M73: 15.25 | N73: 296.9 | O73: 0 | P73: 1.51 | Q73: 108.07
A74: 04-06-2022 16:30 | B74: 2.71 | C74: 42.24 | D74: 44.95 | E74: 5.36 | F74: 3.69 | G74: 117.74 | H74: 30.37 | I74: Z.Ref | J74: 3.99 | K74: 348.95 | L74: 49.8 | M74: 15.48 | N74: 262.8 | O74: 0 | P74: 1.51 | Q74: 108.87
...

Sheet 05
A1: Station: | B1: BHATAGAON RAIPUR
A2: Date: | B2: =$A$9 -> 04-06-2022 00:60 | D2: Power Off | G2: Pw.Off | L2: Link Fail | N2: Link F | P2: Maintenance | R2: Maint.
A3: Report Type: | B3: Mean | D3: Calibration | G3: Calib. | L3: Data Fail | N3: Data F | P3: Invalid | R3: Invalid
A4: Time Base: | B4: 15 Min | D4: Zero Referrence | G4: Z.Ref | L4: Warm Up | N4: Wm. Up
A7: Date & Time | B7: NO_BHATAGAON | C7: NO2__BHATAGAON | D7: NOX_BHATAGAON | E7: SO2__BHATAGAON | F7: O3__BHATAGAON | G7: PM10__BHATAGAON | H7: PM2_5__BHATAGAON | I7: BENZ__BHATAGAON | J7: WS__BHATAGAON | K7: WD__BHATAGAON | L7: TEMP__BHATAGAON | M7: HUM__BHATAGAON | N7: SR__BHATAGAON | O7: RG__BHATAGAON | P7: CO__BHATAGAON | Q7: NH3__BHATAGAON
B8: ug/m3 | C8: ug/m3 | D8: ug/m3 | E8: ug/m3 | F8: ug/m3 | G8: ug/m3 | H8: ug/m3 | I8: ug/m3 | J8: m/sec | K8: deg | L8: degreC | M8: % | N8: w/m2 | O8: mm | P8: mg/m3 | Q8: ug/m3
A9: 04-06-2022 00:60 | B9: 1.6536294 | C9: 51.142921 | D9: 52.797715 | E9: 5.281125 | F9: 4.1867171 | G9: 110.03062 | H9: 27.728419 | I9: 5.5841469 | J9: 2.1911864 | K9: 312.04418 | L9: 45.529998 | M9: 16.294007 | N9: 392.0159 | O9: 0 | P9: 1.9850526 | Q9: 121.88967
A10: 05-06-2022 00:30 | B10: 2.34 | C10: 43.02 | D10: 45.35 | E10: 6.73 | F10: 2.31 | G10: 139.67 | H10: 39.13 | I10: 7.46 | J10: 2.1 | K10: 355.43 | L10: 38.46 | M10: 28.39 | N10: 160.9 | O10: 0 | P10: 2.03 | Q10: 85.52
A11: 05-06-2022 00:45 | B11: 1.89 | C11: 41.65 | D11: 43.54 | E11: 6.81 | F11: 1.82 | G11: 139.67 | H11: 39.13 | I11: 7.14 | J11: 2 | K11: 346.87 | L11: 37.94 | M11: 28.74 | N11: 166.3 | O11: 0 | P11: 2.07 | Q11: 71.06
A12: 05-06-2022 01:00 | B12: 1.94 | C12: 41.03 | D12: 42.97 | E12: 6.5 | F12: 1.46 | G12: 139.67 | H12: 39.13 | I12: 7.33 | J12: 1.56 | K12: 2.04 | L12: 38.74 | M12: 28.43 | N12: 164.2 | O12: 0 | P12: 2.09 | Q12: 75.28
A13: 05-06-2022 01:15 | B13: 2.07 | C13: 40.4 | D13: 42.48 | E13: 6.97 | F13: 1.26 | G13: 140.68 | H13: 38.9 | I13: 8.15 | J13: 1.17 | K13: 333.18 | L13: 38.89 | M13: 29.05 | N13: 170.7 | O13: 0 | P13: 2.12 | Q13: 80.17
A14: 05-06-2022 01:30 | B14: 2.21 | C14: 40.07 | D14: 42.28 | E14: 7.19 | F14: 1.05 | G14: 146.25 | H14: 38.16 | I14: 9.77 | J14: 1.28 | K14: 343.8 | L14: 37.83 | M14: 29.42 | N14: 172.7 | O14: 0 | P14: 2.16 | Q14: 80.56
A15: 05-06-2022 01:45 | B15: 2.26 | C15: 39.5 | D15: 41.76 | E15: 6.97 | F15: 1.05 | G15: 146.25 | H15: 38.16 | I15: 12.67 | J15: 0.33 | K15: 237.65 | L15: 41.4 | M15: 29 | N15: 170.6 | O15: 0 | P15: 2.2 | Q15: 81.24
A16: 05-06-2022 02:00 | B16: 2.19 | C16: 38.43 | D16: 40.61 | E16: 7.22 | F16: 1.19 | G16: 146.25 | H16: 38.16 | I16: 12.7 | J16: 1.08 | K16: 234.83 | L16: 43.11 | M16: 28.02 | N16: 161.5 | O16: 0 | P16: 2.17 | Q16: 81.13
A17: 05-06-2022 02:15 | B17: 1.92 | C17: 36.53 | D17: 38.45 | E17: 7.38 | F17: 1.34 | G17: 141.42 | H17: 38.68 | I17: 13.23 | J17: 2.06 | K17: 201.11 | L17: 41.9 | M17: 28.28 | N17: 161.2 | O17: 0 | P17: 2.12 | Q17: 80.88
A18: 05-06-2022 02:30 | B18: 1.7 | C18: 34.55 | D18: 36.25 | E18: 7.25 | F18: 1.56 | G18: 130.38 | H18: 40.29 | I18: 12.79 | J18: 3.2 | K18: 165.5 | L18: 39.95 | M18: 29.98 | N18: 166.5 | O18: 0 | P18: 2.06 | Q18: 83.57
A19: 05-06-2022 02:45 | B19: 1.46 | C19: 32.74 | D19: 34.2 | E19: 7.45 | F19: 1.31 | G19: 130.38 | H19: 40.29 | I19: 11.89 | J19: 2.24 | K19: 207.39 | L19: 38.03 | M19: 30.23 | N19: 162.2 | O19: 0 | P19: 1.99 | Q19: 85.83
A20: 05-06-2022 03:00 | B20: 1.28 | C20: 30.87 | D20: 32.15 | E20: 3.13 | F20: 1.47 | G20: 130.38 | H20: 40.29 | I20: 11.66 | J20: 3.94 | K20: 160.92 | L20: 39.25 | M20: 31.37 | N20: 164.1 | O20: 0 | P20: 1.93 | Q20: 84.16
... A62: 05-06-2022 13:30 | B62: 0.53 | C62: 39.47 | D62: 40 | E62: 7.2 | F62: 6.23 | G62: 150.26 | H62: 41.3 | I62: 0.3 | J62: 2.49 | K62: 14.2 | L62: 52.66 | M62: 16.52 | N62: 954 | O62: 0 | P62: 1.9 | Q62: 73.41
A63: 05-06-2022 13:45 | B63: 0.65 | C63: 38.4 | D63: 39.05 | E63: 8.33 | F63: 6.19 | G63: 150.26 | H63: 41.3 | I63: Z.Ref | J63: 3.33 | K63: 337.7 | L63: 52.96 | M63: 17.37 | N63: 948.4 | O63: 0 | P63: 1.85 | Q63: 73.42
A64: 05-06-2022 14:00 | B64: 0.65 | C64: 38.22 | D64: 38.87 | E64: 6.51 | F64: 6 | G64: 150.26 | H64: 41.3 | I64: 1.04 | J64: 2.57 | K64: 337.55 | L64: 61.64 | M64: 16.55 | N64: 900.5 | O64: 0 | P64: 1.84 | Q64: 65.36
A65: 05-06-2022 14:15 | B65: 0.74 | C65: 39.7 | D65: 40.45 | E65: 6.71 | F65: 5.66 | G65: 148.61 | H65: 40.47 | I65: 0.01 | J65: 3.12 | K65: 313.96 | L65: 62.21 | M65: 17.16 | N65: 915.9 | O65: 0 | P65: 1.82 | Q65: 61.58
A66: 05-06-2022 14:30 | B66: 0.6 | C66: 39.34 | D66: 39.94 | E66: 6.91 | F66: 6.06 | G66: 144.92 | H66: 37.93 | I66: 0.21 | J66: 2.5 | K66: 340.34 | L66: 60 | M66: 16.59 | N66: 468.2 | O66: 0 | P66: 1.79 | Q66: 62.23
A67: 05-06-2022 14:45 | B67: 0.54 | C67: 38.26 | D67: 38.8 | E67: 7.21 | F67: 5.85 | G67: 144.92 | H67: 37.93 | I67: Z.Ref | J67: 3.11 | K67: 332.94 | L67: 61.12 | M67: 17.31 | N67: 331 | O67: 0 | P67: 1.74 | Q67: 63.3
A68: 05-06-2022 15:00 | B68: 0.7 | C68: 37.64 | D68: 38.34 | E68: 3.67 | F68: 5.6 | G68: 144.92 | H68: 37.93 | I68: 0.77 | J68: 3.03 | K68: 330.99 | L68: 60.93 | M68: 15.85 | N68: 401.5 | O68: 0 | P68: 1.73 | Q68: 64.27
A69: 05-06-2022 15:15 | B69: 0.96 | C69: 38.28 | D69: 39.24 | E69: 6.4 | F69: 4.7 | G69: 139.48 | H69: 36.86 | I69: 0.01 | J69: 2.38 | K69: 330.31 | L69: 61.15 | M69: 15.19 | N69: 437.1 | O69: 0 | P69: 1.73 | Q69: 65.24
A70: 05-06-2022 15:30 | B70: 1.1 | C70: 39.09 | D70: 40.19 | E70: 6.66 | F70: 4.89 | G70: 127.83 | H70: 33.56 | I70: Z.Ref | J70: 3.23 | K70: 316.81 | L70: 60.3 | M70: 16.74 | N70: 316.7 | O70: 0 | P70: 1.74 | Q70: 65.72
A71: 05-06-2022 15:45 | B71: 1.28 | C71: 40.01 | D71: 41.29 | E71: 6.58 | F71: 4.74 | G71: 127.83 | H71: 33.56 | I71: Z.Ref | J71: 2.2 | K71: 321.93 | L71: 59.42 | M71: 16.77 | N71: 352.5 | O71: 0 | P71: 1.74 | Q71: 68.77
A72: 05-06-2022 16:00 | B72: 1.81 | C72: 41.45 | D72: 43.26 | E72: 6.79 | F72: 4.51 | G72: 127.83 | H72: 33.56 | I72: 2.78 | J72: 2.04 | K72: 322.08 | L72: 58.99 | M72: 18.88 | N72: 218.7 | O72: 0 | P72: 1.76 | Q72: 71.87
A73: 05-06-2022 16:15 | B73: 2.18 | C73: 43.63 | D73: 45.82 | E73: 6.95 | F73: 4.19 | G73: 127.27 | H73: 32.98 | I73: 1.42 | J73: 2.71 | K73: 337.12 | L73: 58.4 | M73: 18.03 | N73: 206 | O73: 0 | P73: 1.79 | Q73: 71.17
A74: 05-06-2022 16:30 | B74: 2.41 | C74: 45.04 | D74: 47.45 | E74: 7.05 | F74: 4.18 | G74: 126.08 | H74: 31.18 | I74: 0.02 | J74: 2.32 | K74: 332.77 | L74: 58.43 | M74: 18.24 | N74: 199.2 | O74: 0 | P74: 1.82 | Q74: 70.87
A75: 05-06-2022 16:45 | B75: 3.17 | C75: 47.77 | D75: 50.94 | E75: 6.93 | F75: 3.54 | G75: 126.08 | H75: 31.18 | I75: Z.Ref | J75: 2.18 | K75: 337.65 | L75: 58.95 | M75: 19.02 | N75: 187.2 | O75: 0 | P75: 1.88 | Q75: 72.44
A76: 05-06-2022 17:00 | B76: 4.11 | C76: 51.35 | D76: 55.46 | E76: 6.77 | F76: 2.82 | G76: 126.08 | H76: 31.18 | I76: Z.Ref | J76: 1.93 | K76: 359.56 | L76: 58.63 | M76: 19.01 | N76: 196.9 | O76: 0 | P76: 1.97 | Q76: 73.18
A77: 05-06-2022 17:15 | B77: 5.88 | C77: 55.84 | D77: 61.72 | E77: 6.9 | F77: 2.65 | G77: 124.93 | H77: 31.33 | I77: Z.Ref | J77: 1.86 | K77: 352.61 | L77: 59.01 | M77: 23.71 | N77: 224 | O77: 0 | P77: 2.09 | Q77: 74.63
A78: 05-06-2022 17:30 | B78: 7.16 | C78: 59.59 | D78: 66.75 | E78: 7.2 | F78: 2.18 | G78: 122.57 | H78: 31.78 | I78: Z.Ref | J78: 1.44 | K78: 344.14 | L78: 56.32 | M78: 31.55 | N78: 263.5 | O78: 0 | P78: 2.22 | Q78: 73.79
A79: 05-06-2022 17:45 | B79: 9.03 | C79: 62.15 | D79: 71.18 | E79: 6.97 | F79: 1.33 | G79: 122.57 | H79: 31.78 | I79: Z.Ref | J79: 1.56 | K79: 343.98 | L79: 54.93 | M79: 35.2 | N79: 254.1 | O79: 0 | P79: 2.34 | Q79: 76.6
A80: 05-06-2022 18:00 | B80: 15.62 | C80: 65.72 | D80: 81.34 | E80: 6.97 | F80: 0.77 | G80: 122.57 | H80: 31.78 | I80: 0.54 | J80: 1.28 | K80: 318.1 | L80: 53.98 | M80: 38.44 | N80: 244 | O80: 0 | P80: 2.48 | Q80: 82.17
A81: 05-06-2022 18:15 | B81: 24.17 | C81: 68.1 | D81: 92.27 | E81: 7.58 | F81: 1.13 | G81: 133.84 | H81: 33.13 | I81: 6.25 | J81: 1.67 | K81: 349.46 | L81: 53.21 | M81: 39.88 | N81: 236.7 | O81: 0 | P81: 2.77 | Q81: 87.49
A82: 05-06-2022 18:30 | B82: 30.54 | C82: 68.14 | D82: 98.68 | E82: 7.01 | F82: 0.88 | G82: 157.98 | H82: 37.29 | I82: 8.57 | J82: 1.83 | K82: 59.09 | L82: 53.18 | M82: 39.96 | N82: 232.9 | O82: 0 | P82: 3.1 | Q82: 75.89
A83: 05-06-2022 18:45 | B83: 30.54 | C83: 68.14 | D83: 98.68 | E83: 7.01 | F83: 0.88 | G83: 157.98 | H83: 37.29 | I83: 8.57 | J83: 1.83 | K83: 59.09 | L83: 53.18 | M83: 39.96 | N83: 232.9 | O83: 0 | P83: 3.1 | Q83: 75.89
...

Sheet 06
A1: Station: | B1: BHATAGAON RAIPUR
A2: Date: | B2: =$A$9 -> 06-06-2022 00:15 | D2: Power Off | G2: Pw.Off | L2: Link Fail | N2: Link F | P2: Maintenance | R2: Maint.
A3: Report Type: | B3: Mean | D3: Calibration | G3: Calib. | L3: Data Fail | N3: Data F | P3: Invalid | R3: Invalid
A4: Time Base: | B4: 15 Min | D4: Zero Referrence | G4: Z.Ref | L4: Warm Up | N4: Wm. Up
A7: Date & Time | B7: NO_BHATAGAON | C7: NO2__BHATAGAON | D7: NOX_BHATAGAON | E7: SO2__BHATAGAON | F7: O3__BHATAGAON | G7: PM10__BHATAGAON | H7: PM2_5__BHATAGAON | I7: BENZ__BHATAGAON | J7: WS__BHATAGAON | K7: WD__BHATAGAON | L7: TEMP__BHATAGAON | M7: HUM__BHATAGAON | N7: SR__BHATAGAON | O7: RG__BHATAGAON | P7: CO__BHATAGAON | Q7: NH3__BHATAGAON
B8: ug/m3 | C8: ug/m3 | D8: ug/m3 | E8: ug/m3 | F8: ug/m3 | G8: ug/m3 | H8: ug/m3 | I8: ug/m3 | J8: m/sec | K8: deg | L8: degreC | M8: % | N8: w/m2 | O8: mm | P8: mg/m3 | Q8: ug/m3
A9: 06-06-2022 00:15 | B9: 2.51 | C9: 40.8 | D9: 43.3 | E9: 7 | F9: 0.66 | G9: 172.28 | H9: 49.13 | I9: 9.84 | J9: 1.8 | K9: 192.07 | L9: 40.36 | M9: 38.32 | N9: 203.3 | O9: 0 | P9: 2.29 | Q9: 66.85
A10: 06-06-2022 00:30 | B10: 2.17 | C10: 38.71 | D10: 40.88 | E10: 6.95 | F10: 0.57 | G10: 153.66 | H10: 47.12 | I10: 9.6 | J10: 1.89 | K10: 144.96 | L10: 39.71 | M10: 37.59 | N10: 216 | O10: 0 | P10: 2.25 | Q10: 66.83
A11: 06-06-2022 00:45 | B11: 1.83 | C11: 36.16 | D11: 37.99 | E11: 7.27 | F11: 1.03 | G11: 153.66 | H11: 47.12 | I11: 9.35 | J11: 2.96 | K11: 130.07 | L11: 38.15 | M11: 38.17 | N11: 164.6 | O11: 0 | P11: 2.18 | Q11: 73.64
A12: 06-06-2022 01:00 | B12: 1.35 | C12: 33.52 | D12: 34.88 | E12: 7.27 | F12: 1.3 | G12: 153.66 | H12: 47.12 | I12: 9.06 | J12: 2.08 | K12: 94.9 | L12: 37.07 | M12: 37.35 | N12: 174.9 | O12: 0 | P12: 2.11 | Q12: 76.05
A13: 06-06-2022 01:15 | B13: 1.12 | C13: 31.78 | D13: 32.89 | E13: 7.34 | F13: 1.45 | G13: 150.52 | H13: 46.42 | I13: 8.7 | J13: 2.06 | K13: 125.94 | L13: 38.45 | M13: 36.46 | N13: 216.7 | O13: 0 | P13: 2.04 | Q13: 73.95
A14: 06-06-2022 01:30 | B14: 0.98 | C14: 30.65 | D14: 31.63 | E14: 7.28 | F14: 1.42 | G14: 136.38 | H14: 44.27 | I14: 8.39 | J14: 2.27 | K14: 139.64 | L14: 38.05 | M14: 35.16 | N14: 194.1 | O14: 0 | P14: 1.99 | Q14: 71.42
A15: 06-06-2022 01:45 | B15: 0.87 | C15: 29.5 | D15: 30.37 | E15: 7.06 | F15: 1.5 | G15: 136.38 | H15: 44.27 | I15: 8.02 | J15: 2.16 | K15: 158.3 | L15: 36.95 | M15: 34.67 | N15: 183.7 | O15: 0 | P15: 1.94 | Q15: 70.04
A16: 06-06-2022 02:00 | B16: 0.79 | C16: 28.47 | D16: 29.27 | E16: 6.91 | F16: 1.57 | G16: 136.38 | H16: 44.27 | I16: 7.6 | J16: 1.07 | K16: 104.93 | L16: 36.96 | M16: 35.41 | N16: 181.9 | O16: 0 | P16: 1.88 | Q16: 68.55
A17: 06-06-2022 02:15 | B17: 0.8 | C17: 27.51 | D17: 28.32 | E17: 6.88 | F17: 1.52 | G17: 130.58 | H17: 42.14 | I17: 7.39 | J17: 1.29 | K17: 176.17 | L17: 33.93 | M17: 36.14 | N17: 193.5 | O17: 0 | P17: 1.84 | Q17: 67.06
A18: 06-06-2022 02:30 | B18: 0.8 | C18: 26.71 | D18: 27.51 | E18: 7.12 | F18: 1.41 | G18: 118.15 | H18: 35.56 | I18: 6.97 | J18: 2.32 | K18: 169.53 | L18: 33.93 | M18: 36.81 | N18: 149.4 | O18: 0 | P18: 1.8 | Q18: 66.9
A19: 06-06-2022 02:45 | B19: 0.81 | C19: 26.1 | D19: 26.91 | E19: 7.12 | F19: 1.67 | G19: 118.15 | H19: 35.56 | I19: 6.78 | J19: 3.03 | K19: 168.24 | L19: 34.06 | M19: 37.2 | N19: 170.6 | O19: 0 | P19: 1.77 | Q19: 66.65
A20: 06-06-2022 03:00 | B20: 0.79 | C20: 25.56 | D20: 26.35 | E20: 3.36 | F20: 1.69 | G20: 118.15 | H20: 35.56 | I20: 6.47 | J20: 2.05 | K20: 164.75 | L20: 34.07 | M20: 38.28 | N20: 173.2 | O20: 0 | P20: 1.74 | Q20: 65.78
... A63: 06-06-2022 13:45 | B63: 0.27 | C63: 32.53 | D63: 32.8 | E63: 6.86 | F63: 6.09 | G63: 122.8 | H63: 47.56 | I63: 0.01 | J63: 2.36 | K63: 99.38 | L63: 47.38 | M63: 23.25 | N63: 867.8 | O63: 0 | P63: 1.96 | Q63: 62.74
A64: 06-06-2022 14:00 | B64: 0.29 | C64: 31.02 | D64: 31.31 | E64: 6.75 | F64: 6.53 | G64: 122.8 | H64: 47.56 | I64: Maint. | J64: 1.93 | K64: 117.52 | L64: 47.24 | M64: 22.46 | N64: 906.2 | O64: 0 | P64: 1.95 | Q64: 67.34
A65: 06-06-2022 14:15 | B65: 0.27 | C65: 30.27 | D65: 30.54 | E65: 6.99 | F65: 7.1 | G65: 123.66 | H65: 48.36 | I65: 0.07 | J65: 2.46 | K65: 83.34 | L65: 44.92 | M65: 22.83 | N65: 780.3 | O65: 0 | P65: 1.94 | Q65: 69.71
A66: 06-06-2022 14:30 | B66: 0.35 | C66: 30.45 | D66: 30.81 | E66: 7.31 | F66: 7.44 | G66: 125.49 | H66: 50.82 | I66: Z.Ref | J66: 1.74 | K66: 37.37 | L66: 50.32 | M66: 22.01 | N66: 791.6 | O66: 0 | P66: 1.94 | Q66: 67.52
A67: 06-06-2022 14:45 | B67: 0.44 | C67: 32.45 | D67: 32.9 | E67: 7.17 | F67: 7.31 | G67: 125.49 | H67: 50.82 | I67: Z.Ref | J67: 0.82 | K67: 146.49 | L67: 49.89 | M67: 20.94 | N67: 757.4 | O67: 0 | P67: 1.94 | Q67: 68.45
A68: 06-06-2022 15:00 | B68: 0.38 | C68: 32.4 | D68: 32.78 | E68: 2.93 | F68: 7.8 | G68: 125.49 | H68: 50.82 | I68: Z.Ref | J68: 1.54 | K68: 183.22 | L68: 49.41 | M68: 20.52 | N68: 592.4 | O68: 0 | P68: 1.9 | Q68: 66.93
A69: 06-06-2022 15:15 | B69: 0.22 | C69: 31.18 | D69: 31.4 | E69: 5.42 | F69: 8.39 | G69: 123.6 | H69: 49.63 | I69: Z.Ref | J69: 1.77 | K69: 168.05 | L69: 44.26 | M69: 20.58 | N69: 547.1 | O69: 0 | P69: 1.85 | Q69: 65.1
A70: 06-06-2022 15:30 | B70: 0.15 | C70: 29.68 | D70: 29.83 | E70: 5.96 | F70: 8.61 | G70: 119.56 | H70: 45.97 | I70: Z.Ref | J70: 1.51 | K70: 168.97 | L70: 43.86 | M70: 20.28 | N70: 539.7 | O70: 0 | P70: 1.81 | Q70: 63.09
A71: 06-06-2022 15:45 | B71: 0.14 | C71: 28.24 | D71: 28.38 | E71: 6.12 | F71: 8.59 | G71: 119.56 | H71: 45.97 | I71: Z.Ref | J71: 0.8 | K71: 230.46 | L71: 44.71 | M71: 19.23 | N71: 516.2 | O71: 0 | P71: 1.79 | Q71: 62.1
A72: 06-06-2022 16:00 | B72: 0.31 | C72: 28.72 | D72: 29.03 | E72: 5.92 | F72: 8.45 | G72: 119.56 | H72: 45.97 | I72: 0.08 | J72: 2.04 | K72: 329.1 | L72: 44.86 | M72: 19.71 | N72: 467 | O72: 0 | P72: 1.78 | Q72: 61.63
A73: 06-06-2022 16:15 | B73: 0.5 | C73: 31.78 | D73: 32.28 | E73: 5.93 | F73: 7.73 | G73: 118.92 | H73: 46.48 | I73: Maint. | J73: 1.99 | K73: 351.23 | L73: 45.24 | M73: 18.75 | N73: 385.7 | O73: 0 | P73: 1.81 | Q73: 61.64
A74: 06-06-2022 16:30 | B74: 0.53 | C74: 32.48 | D74: 33 | E74: 5.68 | F74: 7.25 | G74: 117.57 | H74: 48.04 | I74: Maint. | J74: 1.22 | K74: 176.39 | L74: 44.12 | M74: 18.61 | N74: 356 | O74: 0 | P74: 1.82 | Q74: 66.3
A75: 06-06-2022 16:45 | B75: 0.41 | C75: 28.94 | D75: 29.35 | E75: 5.21 | F75: 10.71 | G75: 117.57 | H75: 48.04 | I75: 0.04 | J75: 0.6 | K75: 227.57 | L75: 43.88 | M75: 19.86 | N75: 221 | O75: 0 | P75: 1.78 | Q75: 58.31
A76: 06-06-2022 17:00 | B76: 0.17 | C76: 26.71 | D76: 26.88 | E76: 4.49 | F76: 10.95 | G76: 117.57 | H76: 48.04 | I76: 0.06 | J76: 2.2 | K76: 189.16 | L76: 43.28 | M76: 21.86 | N76: 199 | O76: 0 | P76: 1.76 | Q76: 56.31
A77: 06-06-2022 17:15 | B77: 0.21 | C77: 24.57 | D77: 24.78 | E77: 4.5 | F77: 7.06 | G77: 116.66 | H77: 46.49 | I77: Z.Ref | J77: 3.31 | K77: 185.69 | L77: 42.31 | M77: 25.4 | N77: 131.5 | O77: 0 | P77: 1.72 | Q77: 77.7
A78: 06-06-2022 17:30 | B78: 0.24 | C78: 22.79 | D78: 23.04 | E78: 4.19 | F78: 6.34 | G78: 114.72 | H78: 41.71 | I78: Z.Ref | J78: 3.06 | K78: 187.35 | L78: 41.3 | M78: 27.64 | N78: 97.1 | O78: 0 | P78: 1.7 | Q78: 91.8
A79: 06-06-2022 17:45 | B79: 0.18 | C79: 24.41 | D79: 24.59 | E79: 4.21 | F79: 14.67 | G79: 114.72 | H79: 41.71 | I79: Z.Ref | J79: 2.71 | K79: 197.48 | L79: 40.88 | M79: 28.76 | N79: 91.8 | O79: 0 | P79: 1.65 | Q79: 119.56
A80: 06-06-2022 18:00 | B80: 0.05 | C80: 23.95 | D80: 24 | E80: 3.26 | F80: 15.33 | G80: 114.72 | H80: 41.71 | I80: Z.Ref | J80: 2.36 | K80: 203.11 | L80: 40.63 | M80: 28.65 | N80: 79.4 | O80: 0 | P80: 1.62 | Q80: 100.74
A81: 06-06-2022 18:15 | B81: 0.03 | C81: 25.16 | D81: 25.18 | E81: 2.87 | F81: 12.78 | G81: 116.52 | H81: 42.61 | I81: 0.09 | J81: 1.91 | K81: 222.15 | L81: 40.11 | M81: 30.41 | N81: 54.8 | O81: 0 | P81: 1.62 | Q81: 111.4
A82: 06-06-2022 18:30 | B82: 0.09 | C82: 26.73 | D82: 26.82 | E82: 3.28 | F82: 7.98 | G82: 120.39 | H82: 45.24 | I82: 1.09 | J82: 1.71 | K82: 213.59 | L82: 39.55 | M82: 31.57 | N82: 35 | O82: 0 | P82: 1.62 | Q82: 112.96
A83: 06-06-2022 18:45 | B83: 0.19 | C83: 26.55 | D83: 26.75 | E83: 3.21 | F83: 5.11 | G83: 120.39 | H83: 45.24 | I83: 3.75 | J83: 1.97 | K83: 208.31 | L83: 39.49 | M83: 31.3 | N83: 19.8 | O83: 0 | P83: 1.63 | Q83: 90.42
A84: 06-06-2022 19:00 | B84: 0.34 | C84: 26.6 | D84: 26.94 | E84: 2.23 | F84: 4.33 | G84: 120.39 | H84: 45.24 | I84: 4 | J84: 1.93 | K84: 197.97 | L84: 39.08 | M84: 32.98 | N84: 10.9 | O84: 0 | P84: 1.64 | Q84: 83.5
...

Sheet 07
A1: Station: | B1: BHATAGAON RAIPUR
A2: Date: | B2: =$A$9 -> 07-06-2022 00:15 | D2: Power Off | G2: Pw.Off | L2: Link Fail | N2: Link F | P2: Maintenance | R2: Maint.
A3: Report Type: | B3: Mean | D3: Calibration | G3: Calib. | L3: Data Fail | N3: Data F | P3: Invalid | R3: Invalid
A4: Time Base: | B4: 15 Min | D4: Zero Referrence | G4: Z.Ref | L4: Warm Up | N4: Wm. Up
A7: Date & Time | B7: NO_BHATAGAON | C7: NO2__BHATAGAON | D7: NOX_BHATAGAON | E7: SO2__BHATAGAON | F7: O3__BHATAGAON | G7: PM10__BHATAGAON | H7: PM2_5__BHATAGAON | I7: BENZ__BHATAGAON | J7: WS__BHATAGAON | K7: WD__BHATAGAON | L7: TEMP__BHATAGAON | M7: HUM__BHATAGAON | N7: SR__BHATAGAON | O7: RG__BHATAGAON | P7: CO__BHATAGAON | Q7: NH3__BHATAGAON
B8: ug/m3 | C8: ug/m3 | D8: ug/m3 | E8: ug/m3 | F8: ug/m3 | G8: ug/m3 | H8: ug/m3 | I8: ug/m3 | J8: m/sec | K8: deg | L8: degreC | M8: % | N8: w/m2 | O8: mm | P8: mg/m3 | Q8: ug/m3
A9: 07-06-2022 00:15 | B9: 0.67 | C9: 24.09 | D9: 24.76 | E9: 6.63 | F9: 1.7 | G9: 103.98 | H9: 41.51 | I9: 4.84 | J9: 1.63 | K9: 200.72 | L9: 41.77 | M9: 47.74 | N9: 49.2 | O9: 0 | P9: 1.65 | Q9: 74.63
A10: 07-06-2022 00:30 | B10: 0.7 | C10: 24.81 | D10: 25.51 | E10: 6.73 | F10: 1.95 | G10: 92.07 | H10: 37.21 | I10: 4.77 | J10: 2.18 | K10: 175.77 | L10: 45.63 | M10: 49.33 | N10: 48.9 | O10: 0 | P10: 1.63 | Q10: 76.92
A11: 07-06-2022 00:45 | B11: 0.68 | C11: 23.9 | D11: 24.57 | E11: 6.86 | F11: 1.98 | G11: 92.07 | H11: 37.21 | I11: 4.7 | J11: 1.47 | K11: 208.91 | L11: 43.92 | M11: 50.52 | N11: 49.4 | O11: 0 | P11: 1.63 | Q11: 77.49
A12: 07-06-2022 01:00 | B12: 0.65 | C12: 23.33 | D12: 23.98 | E12: 6.9 | F12: 2.06 | G12: 92.07 | H12: 37.21 | I12: 4.59 | J12: 1.47 | K12: 209.73 | L12: 39.86 | M12: 51.47 | N12: 53.9 | O12: 0 | P12: 1.62 | Q12: 76.03
A13: 07-06-2022 01:15 | B13: 0.65 | C13: 23.29 | D13: 23.94 | E13: 6.63 | F13: 1.89 | G13: 90.59 | H13: 35.83 | I13: 4.68 | J13: 1.72 | K13: 215.21 | L13: 41.04 | M13: 52.29 | N13: 70.6 | O13: 0 | P13: 1.61 | Q13: 77.37
A14: 07-06-2022 01:30 | B14: 0.7 | C14: 20.04 | D14: 20.74 | E14: 7.08 | F14: 2.14 | G14: 83.93 | H14: 31.56 | I14: 4.64 | J14: 1.34 | K14: 180.72 | L14: 35.05 | M14: 53.68 | N14: 90.9 | O14: 0 | P14: 1.61 | Q14: 78.56
A15: 07-06-2022 01:45 | B15: 0.8 | C15: 16.88 | D15: 17.68 | E15: 6.86 | F15: 1.66 | G15: 83.93 | H15: 31.56 | I15: 4.66 | J15: 1.16 | K15: 218.62 | L15: 38.75 | M15: 54.14 | N15: 81.9 | O15: 0 | P15: 1.61 | Q15: 54.99
A16: 07-06-2022 02:00 | B16: 0.92 | C16: 17.01 | D16: 17.92 | E16: 7 | F16: 1.31 | G16: 83.93 | H16: 31.56 | I16: 4.56 | J16: 1.64 | K16: 217.68 | L16: 39.91 | M16: 54.82 | N16: 83.1 | O16: 0 | P16: 1.6 | Q16: 51.79
A17: 07-06-2022 02:15 | B17: 1.02 | C17: 17.73 | D17: 18.75 | E17: 7.04 | F17: 1.19 | G17: 81.15 | H17: 31.77 | I17: 4.58 | J17: 2.04 | K17: 179.38 | L17: 41.09 | M17: 55.01 | N17: 110.2 | O17: 0 | P17: 1.6 | Q17: 53.32
A18: 07-06-2022 02:30 | B18: 1.1 | C18: 18.54 | D18: 19.64 | E18: 7.47 | F18: 1.12 | G18: 75.21 | H18: 32.43 | I18: 4.65 | J18: 2.61 | K18: 160.9 | L18: 39.01 | M18: 55.44 | N18: 124.3 | O18: 0 | P18: 1.59 | Q18: 56.83
A19: 07-06-2022 02:45 | B19: 1.15 | C19: 18.27 | D19: 19.42 | E19: 7.58 | F19: 1.05 | G19: 75.21 | H19: 32.43 | I19: 4.66 | J19: 2.04 | K19: 168.29 | L19: 38.19 | M19: 55.39 | N19: 114.9 | O19: 0 | P19: 1.6 | Q19: 58.13
A20: 07-06-2022 03:00 | B20: 1.23 | C20: 18.23 | D20: 19.46 | E20: 3.36 | F20: 1.03 | G20: 75.21 | H20: 32.43 | I20: 4.7 | J20: 2.13 | K20: 176.5 | L20: 38.39 | M20: 55.28 | N20: 101 | O20: 0 | P20: 1.59 | Q20: 57.62
... A60: 07-06-2022 13:00 | B60: 1.06 | C60: 43.56 | D60: 44.62 | E60: 6 | F60: 5.64 | G60: 122.99 | H60: 45.02 | I60: 0.89 | J60: 1.95 | K60: 350.31 | L60: 54.97 | M60: 16.1 | N60: 1084.5 | O60: 0 | P60: 2.05 | Q60: 73.03
A61: 07-06-2022 13:15 | B61: 1.11 | C61: 44.33 | D61: 45.45 | E61: 6.06 | F61: 5.76 | G61: 122.83 | H61: 43.84 | I61: Z.Ref | J61: 2.23 | K61: 340.09 | L61: 52.15 | M61: 15.84 | N61: 990.7 | O61: 0 | P61: 2.05 | Q61: 73.22
A62: 07-06-2022 13:30 | B62: 1.05 | C62: 44.66 | D62: 45.71 | E62: 5.76 | F62: 5.98 | G62: 121.82 | H62: 40.16 | I62: Z.Ref | J62: 2.23 | K62: 322.88 | L62: 51.35 | M62: 15 | N62: 987.1 | O62: 0 | P62: 2.02 | Q62: 74.6
A63: 07-06-2022 13:45 | B63: 0.99 | C63: 43.83 | D63: 44.83 | E63: 5.21 | F63: 6.09 | G63: 121.82 | H63: 40.16 | I63: Z.Ref | J63: 2.43 | K63: 25.27 | L63: 52.28 | M63: 13.62 | N63: 779.9 | O63: 0 | P63: 1.98 | Q63: 77
A64: 07-06-2022 14:00 | B64: 1.16 | C64: 42.96 | D64: 44.12 | E64: 5.6 | F64: 5.35 | G64: 121.82 | H64: 40.16 | I64: Z.Ref | J64: 2.17 | K64: 344.23 | L64: 49.91 | M64: 14.84 | N64: 985.6 | O64: 0 | P64: 1.93 | Q64: 77.88
A65: 07-06-2022 14:15 | B65: 1.31 | C65: 43.18 | D65: 44.49 | E65: 5.77 | F65: 8.47 | G65: 123.18 | H65: 38.39 | I65: Z.Ref | J65: 3.01 | K65: 3.2 | L65: 51.55 | M65: 13.45 | N65: 901.5 | O65: 0 | P65: 1.92 | Q65: 78.55
A66: 07-06-2022 14:30 | B66: 1.15 | C66: 43.46 | D66: 44.61 | E66: 5.65 | F66: 6.53 | G66: 126.1 | H66: 32.92 | I66: Z.Ref | J66: 2.52 | K66: 326.95 | L66: 50.12 | M66: 14.22 | N66: 403.6 | O66: 0 | P66: 1.88 | Q66: 77.74
A67: 07-06-2022 14:45 | B67: 1.7 | C67: 43.83 | D67: 45.53 | E67: 5.61 | F67: 5.3 | G67: 126.1 | H67: 32.92 | I67: Z.Ref | J67: 2.6 | K67: 343.82 | L67: 51.01 | M67: 15.87 | N67: 330.7 | O67: 0 | P67: 1.91 | Q67: 94.9
A68: 07-06-2022 15:00 | B68: 3.17 | C68: 48.69 | D68: 51.86 | E68: 2.2 | F68: 4.89 | G68: 126.1 | H68: 32.92 | I68: Z.Ref | J68: 1.56 | K68: 333.75 | L68: 47.6 | M68: 15.36 | N68: 736.1 | O68: 0 | P68: 1.98 | Q68: 77.27
A69: 07-06-2022 15:15 | B69: 2.53 | C69: 56.13 | D69: 58.66 | E69: 4.72 | F69: 6.24 | G69: 123.27 | H69: 33.85 | I69: 0.06 | J69: 0.77 | K69: 21.1 | L69: 52.35 | M69: 14.42 | N69: 878.7 | O69: 0 | P69: 1.87 | Q69: 93.44
A70: 07-06-2022 15:30 | B70: 1.59 | C70: 55.01 | D70: 56.6 | E70: 3.98 | F70: 6.67 | G70: 117.19 | H70: 36.75 | I70: 0.9 | J70: 3.09 | K70: 344.89 | L70: 53.1 | M70: 12.86 | N70: 757.3 | O70: 0 | P70: 1.81 | Q70: 102.88
A71: 07-06-2022 15:45 | B71: 1.78 | C71: 50.88 | D71: 52.66 | E71: 4.01 | F71: 3.73 | G71: 117.19 | H71: 36.75 | I71: 4.02 | J71: 2.73 | K71: 325.96 | L71: 57.93 | M71: 12.89 | N71: 687.5 | O71: 0 | P71: 1.8 | Q71: 110.5
A72: 07-06-2022 16:00 | B72: 2.41 | C72: 46.8 | D72: 49.21 | E72: 4.59 | F72: 2.56 | G72: 117.19 | H72: 36.75 | I72: 4.61 | J72: 2.19 | K72: 321.95 | L72: 59.59 | M72: 12.54 | N72: 612.3 | O72: 0 | P72: 1.79 | Q72: 116.9
A73: 07-06-2022 16:15 | B73: 2.58 | C73: 44 | D73: 46.58 | E73: 4.94 | F73: 2.51 | G73: 112.91 | H73: 34.69 | I73: 4.35 | J73: 3 | K73: 342.28 | L73: 55.18 | M73: 13.48 | N73: 491.3 | O73: 0 | P73: 1.75 | Q73: 123.85
A74: 07-06-2022 16:30 | B74: 2.65 | C74: 43.46 | D74: 46.11 | E74: 4.61 | F74: 3.09 | G74: 103.75 | H74: 28.33 | I74: 4.51 | J74: 2.15 | K74: 52.93 | L74: 48.51 | M74: 13.75 | N74: 454.1 | O74: 0 | P74: 1.75 | Q74: 132.21
A75: 07-06-2022 16:45 | B75: 2.32 | C75: 42.67 | D75: 44.99 | E75: 5.09 | F75: 2.86 | G75: 103.75 | H75: 28.33 | I75: 4.4 | J75: 1.65 | K75: 316.43 | L75: 47.99 | M75: 15.5 | N75: 373.6 | O75: 0 | P75: 1.72 | Q75: 137.47
A76: 07-06-2022 17:00 | B76: 2.77 | C76: 41.93 | D76: 44.69 | E76: 5.11 | F76: 2.59 | G76: 103.75 | H76: 28.33 | I76: 4.3 | J76: 2.18 | K76: 332.68 | L76: 46.42 | M76: 14.28 | N76: 352.1 | O76: 0 | P76: 1.74 | Q76: 130.65
A77: 07-06-2022 17:15 | B77: 4.21 | C77: 42.18 | D77: 46.39 | E77: 4.95 | F77: 2.1 | G77: 105.2 | H77: 28.55 | I77: 4.83 | J77: 2.22 | K77: 337.47 | L77: 52.9 | M77: 15.57 | N77: 333.3 | O77: 0 | P77: 1.84 | Q77: 131.48
A78: 07-06-2022 17:30 | B78: 5.87 | C78: 43.02 | D78: 48.9 | E78: 5.18 | F78: 1.96 | G78: 108.31 | H78: 29.2 | I78: 4.94 | J78: 2.64 | K78: 318.77 | L78: 52.61 | M78: 17.2 | N78: 200.1 | O78: 0 | P78: 1.86 | Q78: 133.38
A79: 07-06-2022 17:45 | B79: 7.57 | C79: 44.44 | D79: 52.02 | E79: 5.11 | F79: 2.27 | G79: 108.31 | H79: 29.2 | I79: 5.18 | J79: 2.58 | K79: 314.18 | L79: 48.05 | M79: 25.8 | N79: 211.1 | O79: 0 | P79: 1.94 | Q79: 134.3
A80: 07-06-2022 18:00 | B80: 9.45 | C80: 47.66 | D80: 57.11 | E80: 5.07 | F80: 1.76 | G80: 108.31 | H80: 29.2 | I80: 5.29 | J80: 2.2 | K80: 328.78 | L80: 44.02 | M80: 26.68 | N80: 204.1 | O80: 0 | P80: 2.02 | Q80: 132.24
... A104: 07-06-2022 24:00 | B104: 170.03 | C104: 57.57 | D104: 227.6 | E104: 7.97 | F104: 0.41 | G104: 339.32 | H104: 78.42 | I104: 23.34 | J104: 0.31 | K104: 241.43 | L104: 51.38 | M104: 37.07 | N104: 275.7 | O104: 0 | P104: 4.88 | Q104: 146.91
...

Sheet 08
A1: Station: | B1: BHATAGAON RAIPUR
A2: Date: | B2: =$A$9 -> 08-06-2022 00:15 | D2: Power Off | G2: Pw.Off | L2: Link Fail | N2: Link F | P2: Maintenance | R2: Maint.
A3: Report Type: | B3: Mean | D3: Calibration | G3: Calib. | L3: Data Fail | N3: Data F | P3: Invalid | R3: Invalid
A4: Time Base: | B4: 15 Min | D4: Zero Referrence | G4: Z.Ref | L4: Warm Up | N4: Wm. Up
A7: Date & Time | B7: NO_BHATAGAON | C7: NO2__BHATAGAON | D7: NOX_BHATAGAON | E7: SO2__BHATAGAON | F7: O3__BHATAGAON | G7: PM10__BHATAGAON | H7: PM2_5__BHATAGAON | I7: BENZ__BHATAGAON | J7: WS__BHATAGAON | K7: WD__BHATAGAON | L7: TEMP__BHATAGAON | M7: HUM__BHATAGAON | N7: SR__BHATAGAON | O7: RG__BHATAGAON | P7: CO__BHATAGAON | Q7: NH3__BHATAGAON
