Workbook

Sheet 01
A1: Station: | B1: BHATAGAON RAIPPUR
A2: Date: | B2: =$A$9 -> 01-02-2024 00:15 | D2: Power Off | G2: Pw.Off | L2: Link Fail | N2: Link F | P2: Maintenance | R2: Maint.
A3: Report Type: | B3: Mean | D3: Calibration | G3: Calib. | L3: Data Fail | N3: Data F | P3: Invalid | R3: Invalid
A4: Time Base: | B4: 15 Min | D4: Zero Referrence | G4: Z.Ref | L4: Warm Up | N4: Wm. Up
A7: Date & Time | B7: NO_BHATAGAON | C7: NO2__BHATAGAON | D7: NOX_BHATAGAON | E7: SO2__BHATAGAON | F7: O3__BHATAGAON | G7: PM10__BHATAGAON | H7: PM2_5__BHATAGAON | I7: BENZ__BHATAGAON | J7: WS__BHATAGAON | K7: WD__BHATAGAON | L7: TEMP__BHATAGAON | M7: HUM__BHATAGAON | N7: SR__BHATAGAON | O7: RG__BHATAGAON | P7: CO__BHATAGAON | Q7: NH3__BHATAGAON
B8: ug/m3 | C8: ug/m3 | D8: ppb | E8: ug/m3 | F8: ug/m3 | G8: ug/m3 | H8: ug/m3 | I8: ug/m3 | J8: m/sec | K8: deg | L8: degreC | M8: % | N8: w/m2 | O8: mm | P8: mg/m3 | Q8: ug/m3
A9: 01-02-2024 00:15 | B9: 16.07 | C9: 61.42 | D9: 47.43 | E9: 0.26 | F9: 3.15 | G9: 88.12 | H9: 37.77 | I9: 1.55 | J9: 0.09 | K9: 289.86 | L9: 17.56 | M9: 82.79 | N9: 59.3 | O9: 0 | P9: 1.04 | Q9: 7.93
A10: 01-02-2024 00:30 | B10: 18.71 | C10: 60.7 | D10: 49.15 | E10: 0.27 | F10: 3.16 | G10: 90.56 | H10: 39.22 | I10: 1.53 | J10: 0.08 | K10: 305.32 | L10: 17.68 | M10: 82.68 | N10: 59 | O10: 0 | P10: 1.06 | Q10: 8.07
A11: 01-02-2024 00:45 | B11: 20.8 | C11: 57.48 | D11: 49.05 | E11: 0.24 | F11: 2.91 | G11: 101.84 | H11: 44.16 | I11: 1.51 | J11: 0.17 | K11: 183.77 | L11: 17.86 | M11: 79.28 | N11: 58.7 | O11: 0 | P11: 1.05 | Q11: 8.19
A12: 01-02-2024 01:00 | B12: 20.33 | C12: 58.5 | D12: 49.23 | E12: 0.3 | F12: 2.97 | G12: 101.84 | H12: 44.16 | I12: 1.56 | J12: 0.51 | K12: 182.44 | L12: 18.24 | M12: 75.43 | N12: 58.1 | O12: 0 | P12: 1.03 | Q12: 8.18
A13: 01-02-2024 01:15 | B13: 18.13 | C13: 59.97 | D13: 48.28 | E13: 0.27 | F13: 3.26 | G13: 101.84 | H13: 44.16 | I13: 1.55 | J13: 0.62 | K13: 160.46 | L13: 18.18 | M13: 76.34 | N13: 58.6 | O13: 0 | P13: 0.96 | Q13: 8.14
A14: 01-02-2024 01:30 | B14: 16.23 | C14: 59.57 | D14: 46.54 | E14: 0.28 | F14: 3.01 | G14: 99.55 | H14: 43.18 | I14: 1.5 | J14: 0.68 | K14: 164.05 | L14: 18.19 | M14: 75.2 | N14: 58.5 | O14: 0 | P14: 0.95 | Q14: 8
A15: 01-02-2024 01:45 | B15: 14.57 | C15: 59.51 | D15: 45.17 | E15: 0.24 | F15: 3.17 | G15: 88.97 | H15: 39.86 | I15: 1.47 | J15: 0.13 | K15: 169.13 | L15: 18.04 | M15: 76.4 | N15: 59 | O15: 0 | P15: 0.92 | Q15: 7.91
A16: 01-02-2024 02:00 | B16: 13.07 | C16: 58.93 | D16: 43.65 | E16: 0.28 | F16: 3.22 | G16: 88.97 | H16: 39.86 | I16: 1.47 | J16: 0.06 | K16: 275.33 | L16: 17.76 | M16: 78.51 | N16: 59 | O16: 0 | P16: 0.9 | Q16: 7.75
A17: 01-02-2024 02:15 | B17: 11.71 | C17: 58.38 | D17: 42.25 | E17: 0.25 | F17: 3.26 | G17: 88.97 | H17: 39.86 | I17: 1.52 | J17: 0.34 | K17: 183.33 | L17: 17.83 | M17: 77.31 | N17: 58.3 | O17: 0 | P17: 0.86 | Q17: 7.61
A18: 01-02-2024 02:30 | B18: 10.46 | C18: 57.3 | D18: 40.66 | E18: 0.28 | F18: 3.18 | G18: 86.37 | H18: 39.51 | I18: 1.44 | J18: 0.17 | K18: 89.71 | L18: 17.83 | M18: 77.07 | N18: 58.7 | O18: 0 | P18: 0.84 | Q18: 7.45
A19: 01-02-2024 02:45 | B19: 9.47 | C19: 56.76 | D19: 39.56 | E19: 0.23 | F19: 3.02 | G19: 74.36 | H19: 38.31 | I19: 1.5 | J19: 0.03 | K19: 181.31 | L19: 17.75 | M19: 77.6 | N19: 58.6 | O19: 0 | P19: 0.81 | Q19: 7.33
A20: 01-02-2024 03:00 | B20: 8.69 | C20: 55.98 | D20: 38.51 | E20: 0.25 | F20: 3.07 | G20: 74.36 | H20: 38.31 | I20: 1.55 | J20: 0.12 | K20: 306.2 | L20: 17.48 | M20: 81.5 | N20: 59 | O20: 0 | P20: 0.79 | Q20: 7.25
... A24: 01-02-2024 04:00 | B24: 8.03 | C24: 53.27 | D24: 36.49 | E24: 0.08 | F24: 3.08 | G24: 68.28 | H24: 35.11 | I24: 1.56 | J24: 0.67 | K24: 328.27 | L24: 16.63 | M24: 88.18 | N24: 57.8 | O24: 0 | P24: 0.72 | Q24: 7.08
A25: 01-02-2024 04:15 | B25: 8.07 | C25: 53.6 | D25: 36.7 | E25: 0.1 | F25: 3.07 | G25: 68.28 | H25: 35.11 | I25: 1.53 | J25: 0.3 | K25: 329.68 | L25: 16.54 | M25: 89.18 | N25: 58.9 | O25: 0 | P25: 0.73 | Q25: Data F
A26: 01-02-2024 04:30 | B26: 9.52 | C26: 54.5 | D26: 38.36 | E26: 0.19 | F26: 3.05 | G26: 69.53 | H26: 35.32 | I26: 1.5 | J26: 0.09 | K26: 275.5 | L26: 16.26 | M26: 91.77 | N26: 59 | O26: 0 | P26: 0.76 | Q26: Data F
A27: 01-02-2024 04:45 | B27: 9.52 | C27: 54.5 | D27: 38.36 | E27: 0.19 | F27: 3.05 | G27: 69.53 | H27: 35.32 | I27: 1.5 | J27: 0.09 | K27: 275.5 | L27: 16.26 | M27: 91.77 | N27: 59 | O27: 0 | P27: 0.76 | Q27: Data F
A28: 01-02-2024 05:00 | B28: 9.52 | C28: 54.5 | D28: 38.36 | E28: 0.19 | F28: 3.05 | G28: 69.53 | H28: 35.32 | I28: 1.5 | J28: 0.09 | K28: 275.5 | L28: 16.26 | M28: 91.77 | N28: 59 | O28: 0 | P28: 0.76 | Q28: Data F
A29: 01-02-2024 05:15 | B29: 14.32 | C29: 53.41 | D29: 41.6 | E29: 0.16 | F29: 3.17 | G29: 87.91 | H29: 38.04 | I29: 1.46 | J29: 0.24 | K29: 315.84 | L29: 15.85 | M29: 93.76 | N29: 58.8 | O29: 0 | P29: 0.82 | Q29: 7.5
A30: 01-02-2024 05:30 | B30: 16.8 | C30: 53.55 | D30: 43.67 | E30: 0.18 | F30: 3.23 | G30: 94.16 | H30: 40.35 | I30: 1.51 | J30: 0.2 | K30: 322.75 | L30: 15.53 | M30: 96.08 | N30: 58.8 | O30: 0 | P30: 0.86 | Q30: 7.75
A31: 01-02-2024 05:45 | B31: 19.13 | C31: 53.57 | D31: 45.55 | E31: 0.11 | F31: 3.08 | G31: 123.09 | H31: 48.34 | I31: 1.52 | J31: 0.12 | K31: 76.57 | L31: 15.58 | M31: 95.94 | N31: 58.9 | O31: 0 | P31: 0.88 | Q31: 7.86
A32: 01-02-2024 06:00 | B32: 21.33 | C32: 53.41 | D32: 47.22 | E32: 0.25 | F32: 3.18 | G32: 123.09 | H32: 48.34 | I32: 1.49 | J32: 0.08 | K32: 305.07 | L32: 15.56 | M32: 96.58 | N32: 59 | O32: 0 | P32: 0.9 | Q32: 8.07
A33: 01-02-2024 06:15 | B33: 24.03 | C33: 53.15 | D33: 49.25 | E33: 0.16 | F33: 3.11 | G33: 123.09 | H33: 48.34 | I33: 1.51 | J33: 0.05 | K33: 136.95 | L33: 15.42 | M33: 98.29 | N33: 59 | O33: 0 | P33: 0.94 | Q33: 8.25
A34: 01-02-2024 06:30 | B34: 27.98 | C34: 53.22 | D34: 52.45 | E34: 0.19 | F34: 3.11 | G34: 127.54 | H34: 52.05 | I34: 1.43 | J34: 0.02 | K34: 248.72 | L34: 15.48 | M34: 98.51 | N34: 59.7 | O34: 0 | P34: 0.97 | Q34: 8.46
A35: 01-02-2024 06:45 | B35: 31.8 | C35: 53.32 | D35: 55.57 | E35: 0.24 | F35: 3.22 | G35: 148.13 | H35: 64.67 | I35: 1.51 | J35: 0.01 | K35: 213.63 | L35: 15.51 | M35: 98.56 | N35: 64.7 | O35: 0 | P35: 1 | Q35: 8.72
A36: 01-02-2024 07:00 | B36: 36.15 | C36: 53.13 | D36: 58.96 | E36: 0.25 | F36: 3.15 | G36: 148.13 | H36: 64.67 | I36: 1.4 | J36: 0.02 | K36: 100.93 | L36: 15.65 | M36: 98.14 | N36: 78.3 | O36: 0 | P36: 1.04 | Q36: 8.99
A37: 01-02-2024 07:15 | B37: 40.54 | C37: 53.19 | D37: 62.51 | E37: 0.26 | F37: 2.71 | G37: 148.13 | H37: 64.67 | I37: 1.43 | J37: 0.01 | K37: 251.99 | L37: 16 | M37: 95.81 | N37: 96.9 | O37: 0 | P37: 1.05 | Q37: 9.29
A38: 01-02-2024 07:30 | B38: 43.97 | C38: 53.29 | D38: 65.32 | E38: 0.26 | F38: 3.03 | G38: 153.74 | H38: 65.96 | I38: 1.54 | J38: 0.31 | K38: 126.71 | L38: 16.76 | M38: 92.12 | N38: 133.3 | O38: 0 | P38: 1.12 | Q38: 9.61
A39: 01-02-2024 07:45 | B39: 46.42 | C39: 51.87 | D39: 66.5 | E39: 0.29 | F39: 3.18 | G39: 179.71 | H39: 72.53 | I39: 1.54 | J39: 0.75 | K39: 106.88 | L39: 17.48 | M39: 84.86 | N39: 146.1 | O39: 0 | P39: 1.14 | Q39: 9.83
A40: 01-02-2024 08:00 | B40: 45.84 | C40: 52.05 | D40: 66.13 | E40: 0.15 | F40: 3.17 | G40: 179.71 | H40: 72.53 | I40: 1.41 | J40: 0.55 | K40: 92.89 | L40: 18.06 | M40: 82.61 | N40: 197.5 | O40: 0 | P40: 1.16 | Q40: 9.88
... A104: 01-02-2024 24:00 | B104: 94.7 | C104: 57.48 | D104: 108.31 | E104: 0.13 | F104: 3.06 | G104: 131.77 | H104: 51.49 | I104: 1.51 | J104: 0.13 | K104: 314.53 | L104: 18 | M104: 89.82 | N104: 58.1 | O104: 0 | P104: 1.96 | Q104: 13.68
A106: Min | B106: =MIN(B9:B104) -> 1.94 | C106: =MIN(C9:C104) -> 51.87 | D106: =MIN(D9:D104) -> 33.68 | E106: =MIN(E9:E104) -> 0.05 | F106: =MIN(F9:F104) -> 2.71 | G106: =MIN(G9:G104) -> 35.77 | H106: =MIN(H9:H104) -> 23.9 | I106: =MIN(I9:I104) -> 1.4 | ... Q106: =MIN(Q9:Q104) -> 6.81
A107: Max | B107: =MAX(B9:B104) -> 99.17 | C107: =MAX(C9:C104) -> 74.7 | D107: =MAX(D9:D104) -> 113.3 | E107: =MAX(E9:E104) -> 0.56 | F107: =MAX(F9:F104) -> 6.35 | G107: =MAX(G9:G104) -> 183.19 | H107: =MAX(H9:H104) -> 75.44 | I107: =MAX(I9:I104) -> 1.61 | ... Q107: =MAX(Q9:Q104) -> 13.92
A108: Avg | B108: =AVERAGE(B9:B104) -> 26.838333 | C108: =AVERAGE(C9:C104) -> 60.375312 | D108: =AVERAGE(D9:D104) -> 55.488438 | E108: =AVERAGE(E9:E104) -> 0.25354167 | F108: =AVERAGE(F9:F104) -> 3.4771875 | G108: =AVERAGE(G9:G104) -> 107.16604 | H108: =AVERAGE(H9:H104) -> 45.368125 | I108: =AVERAGE(I9:I104) -> 1.5020833 | ... Q108: =AVERAGE(Q9:Q104) -> 8.7976087
A109: Stdev | B109: =STDEV(B9:B104) -> 27.33243 | C109: =STDEV(C9:C104) -> 6.1454375 | D109: =STDEV(D9:D104) -> 21.42523 | E109: =STDEV(E9:E104) -> 0.10737028 | F109: =STDEV(F9:F104) -> 0.83062146 | G109: =STDEV(G9:G104) -> 43.266994 | H109: =STDEV(H9:H104) -> 13.852487 | I109: =STDEV(I9:I104) -> 0.043284048 | ... Q109: =STDEV(Q9:Q104) -> 1.907079
...

Sheet 02
A1: Station: | B1: BHATAGAON RAIPUR
A2: Date: | B2: =$A$9 -> 02-02-2024 00:15 | D2: Power Off | G2: Pw.Off | L2: Link Fail | N2: Link F | P2: Maintenance | R2: Maint.
A3: Report Type: | B3: Mean | D3: Calibration | G3: Calib. | L3: Data Fail | N3: Data F | P3: Invalid | R3: Invalid
A4: Time Base: | B4: 15 Min | D4: Zero Referrence | G4: Z.Ref | L4: Warm Up | N4: Wm. Up
A7: Date & Time | B7: NO_BHATAGAON | C7: NO2__BHATAGAON | D7: NOX_BHATAGAON | E7: SO2__BHATAGAON | F7: O3__BHATAGAON | G7: PM10__BHATAGAON | H7: PM2_5__BHATAGAON | I7: BENZ__BHATAGAON | J7: WS__BHATAGAON | K7: WD__BHATAGAON | L7: TEMP__BHATAGAON | M7: HUM__BHATAGAON | N7: SR__BHATAGAON | O7: RG__BHATAGAON | P7: CO__BHATAGAON | Q7: NH3__BHATAGAON
B8: ug/m3 | C8: ug/m3 | D8: ppb | E8: ug/m3 | F8: ug/m3 | G8: ug/m3 | H8: ug/m3 | I8: ug/m3 | J8: m/sec | K8: deg | L8: degreC | M8: % | N8: w/m2 | O8: mm | P8: mg/m3 | Q8: ug/m3
A9: 02-02-2024 00:15 | B9: 93.28 | C9: 57.43 | D9: 107.15 | E9: 0.25 | F9: 3.2 | G9: 131.77 | H9: 51.49 | I9: 1.5 | J9: 0.08 | K9: 281.71 | L9: 17.72 | M9: 91.51 | N9: 58.2 | O9: 0 | P9: 1.91 | Q9: 13.59
A10: 02-02-2024 00:30 | B10: 90.79 | C10: 56.21 | D10: 104.48 | E10: 0.32 | F10: 3.07 | G10: 129.46 | H10: 50.21 | I10: 1.5 | J10: 0.03 | K10: 181.85 | L10: 17.58 | M10: 92.33 | N10: 58.1 | O10: 0 | P10: 1.85 | Q10: 13.41
A11: 02-02-2024 00:45 | B11: 87.62 | C11: 55.54 | D11: 101.56 | E11: 0.28 | F11: 3.08 | G11: 118.79 | H11: 45.89 | I11: 1.52 | J11: 0.11 | K11: 282.58 | L11: 17.56 | M11: 93.69 | N11: 58.1 | O11: 0 | P11: 1.78 | Q11: 13.25
A12: 02-02-2024 01:00 | B12: 84.8 | C12: 55.32 | D12: 99.18 | E12: 0.27 | F12: 3.1 | G12: 118.79 | H12: 45.89 | I12: 1.39 | J12: 0.06 | K12: 351.82 | L12: 17.55 | M12: 95.79 | N12: 58.2 | O12: 0 | P12: 1.71 | Q12: 13.05
A13: 02-02-2024 01:15 | B13: 82.15 | C13: 52.77 | D13: 95.65 | E13: 0.23 | F13: 3.21 | G13: 118.79 | H13: 45.89 | I13: 1.55 | J13: 0.04 | K13: 262.19 | L13: 17.49 | M13: 94.78 | N13: 58.3 | O13: 0 | P13: 1.52 | Q13: 12.78
A14: 02-02-2024 01:30 | B14: 79.39 | C14: 53.52 | D14: 93.85 | E14: 0.22 | F14: 3.04 | G14: 112.82 | H14: 45.02 | I14: 1.48 | J14: 0.13 | K14: 280.38 | L14: 17.43 | M14: 94.87 | N14: 58.2 | O14: 0 | P14: 1.54 | Q14: 12.6
A15: 02-02-2024 01:45 | B15: 76.86 | C15: 54.85 | D15: 92.55 | E15: 0.29 | F15: 3.09 | G15: 85.22 | H15: 42.07 | I15: 1.57 | J15: 0.05 | K15: 350.64 | L15: 17.37 | M15: 95.58 | N15: 58.3 | O15: 0 | P15: 1.49 | Q15: 12.52
A16: 02-02-2024 02:00 | B16: 74.65 | C16: 55.13 | D16: 90.93 | E16: 0.26 | F16: 3.04 | G16: 85.22 | H16: 42.07 | I16: 1.53 | J16: 0.09 | K16: 248.23 | L16: 17.45 | M16: 92.9 | N16: 58 | O16: 0 | P16: 1.42 | Q16: 12.43
A17: 02-02-2024 02:15 | B17: 72.05 | C17: 55.25 | D17: 88.92 | E17: 0.31 | F17: 3.26 | G17: 85.22 | H17: 42.07 | I17: 1.43 | J17: 0.07 | K17: 255.22 | L17: 17.49 | M17: 91.5 | N17: 58.2 | O17: 0 | P17: 1.39 | Q17: 12.4
A18: 02-02-2024 02:30 | B18: 69.64 | C18: 55.12 | D18: 86.91 | E18: 0.27 | F18: 2.99 | G18: 82.74 | H18: 40.45 | I18: 1.44 | J18: 0.05 | K18: 48.42 | L18: 17.42 | M18: 90.76 | N18: 58.1 | O18: 0 | P18: 1.33 | Q18: 12.27
A19: 02-02-2024 02:45 | B19: 67.33 | C19: 54.89 | D19: 84.93 | E19: 0.25 | F19: 3.25 | G19: 71.27 | H19: 34.95 | I19: 1.43 | J19: 0.02 | K19: 10.4 | L19: 17.56 | M19: 88.08 | N19: 58.3 | O19: 0 | P19: 1.29 | Q19: 12.07
A20: 02-02-2024 03:00 | B20: 64.96 | C20: 54.84 | D20: 83 | E20: 0.23 | F20: 3.09 | G20: 71.27 | H20: 34.95 | I20: 1.52 | J20: 0.01 | K20: 248.28 | L20: 17.27 | M20: 92.57 | N20: 58.4 | O20: 0 | P20: 1.26 | Q20: 11.94
... A104: 02-02-2024 24:00 | B104: 34.36 | C104: 56.14 | D104: 59.18 | E104: 0.22 | F104: 3.1 | G104: 67.64 | H104: 30.18 | I104: 1.48 | J104: 0.07 | K104: 271.38 | L104: 18.19 | M104: 89.66 | N104: 61.9 | O104: 0 | P104: 1.02 | Q104: 9.74
A106: Min | B106: =MIN(B9:B104) -> 2.2 | C106: =MIN(C9:C104) -> 49.35 | D106: =MIN(D9:D104) -> 36.34 | E106: =MIN(E9:E104) -> 0.06 | F106: =MIN(F9:F104) -> 2.78 | G106: =MIN(G9:G104) -> 67.64 | H106: =MIN(H9:H104) -> 30.12 | I106: =MIN(I9:I104) -> 1.39 | ... Q106: =MIN(Q9:Q104) -> 7.59
A107: Max | B107: =MAX(B9:B104) -> 93.28 | C107: =MAX(C9:C104) -> 75.76 | D107: =MAX(D9:D104) -> 107.15 | E107: =MAX(E9:E104) -> 0.41 | F107: =MAX(F9:F104) -> 4.98 | G107: =MAX(G9:G104) -> 143.62 | H107: =MAX(H9:H104) -> 51.49 | I107: =MAX(I9:I104) -> 1.62 | ... Q107: =MAX(Q9:Q104) -> 13.59
A108: Avg | B108: =AVERAGE(B9:B104) -> 33.729062 | C108: =AVERAGE(C9:C104) -> 58.412083 | D108: =AVERAGE(D9:D104) -> 59.930729 | E108: =AVERAGE(E9:E104) -> 0.23052083 | F108: =AVERAGE(F9:F104) -> 3.4144792 | G108: =AVERAGE(G9:G104) -> 89.625833 | H108: =AVERAGE(H9:H104) -> 37.761458 | I108: =AVERAGE(I9:I104) -> 1.5013542 | ... Q108: =AVERAGE(Q9:Q104) -> 9.6309375
A109: Stdev | B109: =STDEV(B9:B104) -> 24.932802 | C109: =STDEV(C9:C104) -> 6.8322708 | D109: =STDEV(D9:D104) -> 18.003682 | E109: =STDEV(E9:E104) -> 0.069439406 | F109: =STDEV(F9:F104) -> 0.51017617 | G109: =STDEV(G9:G104) -> 21.589023 | H109: =STDEV(H9:H104) -> 5.3251147 | I109: =STDEV(I9:I104) -> 0.041488611 | ... Q109: =STDEV(Q9:Q104) -> 1.6202171
A110: Num | B110: =COUNT(B9:B104) -> 96 | C110: =COUNT(C9:C104) -> 96 | D110: =COUNT(D9:D104) -> 96 | E110: =COUNT(E9:E104) -> 96 | F110: =COUNT(F9:F104) -> 96 | G110: =COUNT(G9:G104) -> 96 | H110: =COUNT(H9:H104) -> 96 | I110: =COUNT(I9:I104) -> 96 | ... Q110: =COUNT(Q9:Q104) -> 96
A111: DCR | B111: =IF(B110>=87,">90%",IF(B110<=87,"<90%")) -> >90% | C111: =IF(C110>=87,">90%",IF(C110<=87,"<90%")) -> >90% | D111: =IF(D110>=87,">90%",IF(D110<=87,"<90%")) -> >90% | E111: =IF(E110>=87,">90%",IF(E110<=87,"<90%")) -> >90% | F111: =IF(F110>=87,">90%",IF(F110<=87,"<90%")) -> >90% | G111: =IF(G110>=87,">90%",IF(G110<=87,"<90%")) -> >90% | H111: =IF(H110>=87,">90%",IF(H110<=87,"<90%")) -> >90% | I111: =IF(I110>=87,">90%",IF(I110<=87,"<90%")) -> >90% | ... Q111: =IF(Q110>=87,">90%",IF(Q110<=87,"<90%")) -> >90%
A112: Status | B112: =IF(B110>=87,"OK",IF(B110<=87,"LESS")) -> OK | C112: =IF(C110>=87,"OK",IF(C110<=87,"LESS")) -> OK | D112: =IF(D110>=87,"OK",IF(D110<=87,"LESS")) -> OK | E112: =IF(E110>=87,"OK",IF(E110<=87,"LESS")) -> OK | F112: =IF(F110>=87,"OK",IF(F110<=87,"LESS")) -> OK | G112: =IF(G110>=87,"OK",IF(G110<=87,"LESS")) -> OK | H112: =IF(H110>=87,"OK",IF(H110<=87,"LESS")) -> OK | I112: =IF(I110>=87,"OK",IF(I110<=87,"LESS")) -> OK | ... Q112: =IF(Q110>=87,"OK",IF(Q110<=87,"LESS")) -> OK
A115: Done by | B115: RK
A117: Comment

Sheet 03
A1: Station: | B1: BHATAGAON RAIPUR
A2: Date: | B2: =$A$9 -> 03-02-2024 00:15 | D2: Power Off | G2: Pw.Off | L2: Link Fail | N2: Link F | P2: Maintenance | R2: Maint.
A3: Report Type: | B3: Mean | D3: Calibration | G3: Calib. | L3: Data Fail | N3: Data F | P3: Invalid | R3: Invalid
A4: Time Base: | B4: 15 Min | D4: Zero Referrence | G4: Z.Ref | L4: Warm Up | N4: Wm. Up
A7: Date & Time | B7: NO_BHATAGAON | C7: NO2__BHATAGAON | D7: NOX_BHATAGAON | E7: SO2__BHATAGAON | F7: O3__BHATAGAON | G7: PM10__BHATAGAON | H7: PM2_5__BHATAGAON | I7: BENZ__BHATAGAON | J7: WS__BHATAGAON | K7: WD__BHATAGAON | L7: TEMP__BHATAGAON | M7: HUM__BHATAGAON | N7: SR__BHATAGAON | O7: RG__BHATAGAON | P7: CO__BHATAGAON | Q7: NH3__BHATAGAON
B8: ug/m3 | C8: ug/m3 | D8: ppb | E8: ug/m3 | F8: ug/m3 | G8: ug/m3 | H8: ug/m3 | I8: ug/m3 | J8: m/sec | K8: deg | L8: degreC | M8: % | N8: w/m2 | O8: mm | P8: mg/m3 | Q8: ug/m3
A9: 03-02-2024 00:15 | B9: 34.12 | C9: 55.44 | D9: 58.6 | E9: 0.37 | F9: 3.11 | G9: 67.64 | H9: 30.18 | I9: 1.51 | J9: 0.12 | K9: 15.1 | L9: 17.74 | M9: 93.25 | N9: 62.2 | O9: 0 | P9: 1.02 | Q9: 9.7
A10: 03-02-2024 00:30 | B10: 34.24 | C10: 55.38 | D10: 58.67 | E10: 0.37 | F10: 3.13 | G10: 70.26 | H10: 31.11 | I10: 1.52 | J10: 0.05 | K10: 312.56 | L10: 17.46 | M10: 95.17 | N10: 62.1 | O10: 0 | P10: 1.02 | Q10: 9.73
A11: 03-02-2024 00:45 | B11: 34.28 | C11: 54.91 | D11: 58.45 | E11: 0.37 | F11: 3.18 | G11: 82.37 | H11: 34.27 | I11: 1.53 | J11: 0.04 | K11: 21.55 | L11: 17.42 | M11: 95.83 | N11: 61.9 | O11: 0 | P11: 1.01 | Q11: 9.69
A12: 03-02-2024 01:00 | B12: 35.17 | C12: 54.52 | D12: 58.94 | E12: 0.38 | F12: 3.16 | G12: 82.37 | H12: 34.27 | I12: 1.53 | J12: 0.08 | K12: 306.65 | L12: 17.04 | M12: 98.07 | N12: 62 | O12: 0 | P12: 1.03 | Q12: 9.66
A13: 03-02-2024 01:15 | B13: 36.9 | C13: 54.25 | D13: 60.18 | E13: 0.38 | F13: 3.13 | G13: 82.37 | H13: 34.27 | I13: 1.51 | J13: 0.03 | K13: 111.91 | L13: 16.74 | M13: 99.27 | N13: 61.8 | O13: 0 | P13: 1 | Q13: 9.77
A14: 03-02-2024 01:30 | B14: 38.08 | C14: 48.51 | D14: 57.96 | E14: 0.38 | F14: 3.25 | G14: 85.19 | H14: 36.1 | I14: 1.53 | J14: 0.05 | K14: 279.09 | L14: 16.64 | M14: 98.9 | N14: 62 | O14: 0 | P14: 1.03 | Q14: 9.64
A15: 03-02-2024 01:45 | B15: 38.19 | C15: 50.55 | D15: 59.17 | E15: 0.42 | F15: 3.11 | G15: 98.2 | H15: 42.31 | I15: 1.53 | J15: 0.15 | K15: 358.69 | L15: 16.71 | M15: 86.91 | N15: 61.2 | O15: 0 | P15: 1.02 | Q15: 9.65
A16: 03-02-2024 02:00 | B16: 36.3 | C16: 52.28 | D16: 58.61 | E16: 0.36 | F16: 3.18 | G16: 98.2 | H16: 42.31 | I16: 1.45 | J16: 0.3 | K16: 341.48 | L16: 17.61 | M16: 63.12 | N16: 60.5 | O16: 0 | P16: 1.01 | Q16: 9.65
A17: 03-02-2024 02:15 | B17: 33.06 | C17: 53.95 | D17: 56.93 | E17: 0.33 | F17: 3.25 | G17: 98.2 | H17: 42.31 | I17: 1.52 | J17: 0.45 | K17: 343.1 | L17: 17.78 | M17: 61.99 | N17: 61.5 | O17: 0 | P17: 0.97 | Q17: 9.52
A18: 03-02-2024 02:30 | B18: 30.46 | C18: 55.69 | D18: 55.81 | E18: 0.36 | F18: 2.93 | G18: 95.67 | H18: 42.09 | I18: 1.47 | J18: 0.58 | K18: 347.21 | L18: 17.57 | M18: 63.28 | N18: 61.8 | O18: 0 | P18: 0.94 | Q18: 9.34
A19: 03-02-2024 02:45 | B19: 28.4 | C19: 56.27 | D19: 54.47 | E19: 0.29 | F19: 3.13 | G19: 83.98 | H19: 41.33 | I19: 1.51 | J19: 0.25 | K19: 349.11 | L19: 17.22 | M19: 65.03 | N19: 62.5 | O19: 0 | P19: 0.91 | Q19: 9.16
A20: 03-02-2024 03:00 | B20: 26.35 | C20: 55.88 | D20: 52.62 | E20: 0.32 | F20: 3.31 | G20: 83.98 | H20: 41.33 | I20: 1.45 | J20: 0.18 | K20: 40.91 | L20: 16.92 | M20: 65.58 | N20: 62.3 | O20: 0 | P20: 0.89 | Q20: 8.96
... A53: 03-02-2024 11:15 | B53: 8.35 | C53: 73.7 | D53: 48.01 | E53: 0.3 | F53: 4.29 | G53: 79.98 | H53: 29.29 | I53: 1.51 | J53: 0.14 | K53: 54.95 | L53: 26.89 | M53: 27.38 | N53: 789.6 | O53: 0 | P53: 0.67 | Q53: 7.88
A54: 03-02-2024 11:30 | B54: Calib. | C54: Calib. | D54: Calib. | E54: 0.27 | F54: 4.6 | G54: 79.98 | H54: 29.29 | I54: 1.47 | J54: 0.9 | K54: 113.27 | L54: 26.18 | M54: 25 | N54: 832.1 | O54: 0 | P54: 0.65 | Q54: 7.65
A55: 03-02-2024 11:45 | B55: Calib. | C55: Calib. | D55: Calib. | E55: 0.27 | F55: 5.19 | G55: 17.77 | H55: 6.51 | I55: 1.49 | J55: 0.5 | K55: 350.22 | L55: 28.42 | M55: 23.17 | N55: 837.1 | O55: 0 | P55: Calib. | Q55: 7.32
A56: 03-02-2024 12:00 | B56: 4.21 | C56: 68.29 | D56: 41.7 | E56: 0.29 | F56: 6.08 | G56: Calib. | H56: Calib. | I56: 1.5 | J56: 0.47 | K56: 339.2 | L56: 29.33 | M56: 22.57 | N56: 839.2 | O56: 0 | P56: Calib. | Q56: 7.13
A57: 03-02-2024 12:15 | B57: 4.8 | C57: 69.82 | D57: 43.03 | E57: 0.37 | F57: 6.07 | G57: Calib. | H57: Calib. | I57: 1.51 | J57: 0.61 | K57: 3.15 | L57: 29.52 | M57: 22.91 | N57: 837.6 | O57: 0 | P57: Calib. | Q57: 6.93
A58: 03-02-2024 12:30 | B58: 4.92 | C58: 72.25 | D58: 44.47 | E58: 0.37 | F58: 5.43 | G58: Calib. | H58: Calib. | I58: 1.6 | J58: 0.14 | K58: 322.63 | L58: 30.17 | M58: 22.03 | N58: 844.2 | O58: 0 | P58: Calib. | Q58: 7.01
A59: 03-02-2024 12:45 | B59: 4.11 | C59: 71.84 | D59: 43.59 | E59: 0.33 | F59: 4.67 | G59: 30.38 | H59: 29.99 | I59: 1.51 | J59: 0.21 | K59: 136.43 | L59: 28.14 | M59: 23.45 | N59: 846.9 | O59: 0 | P59: 0.56 | Q59: 7.08
A60: 03-02-2024 13:00 | B60: 3.8 | C60: 69.1 | D60: 41.83 | E60: 0.33 | F60: 4.2 | G60: 38.51 | H60: 38.01 | I60: 1.43 | J60: 0.59 | K60: 121.78 | L60: 27.32 | M60: 23.87 | N60: 816.4 | O60: 0 | P60: 0.53 | Q60: 7.14
A61: 03-02-2024 13:15 | B61: 3.92 | C61: 66.13 | D61: 40.28 | E61: 0.23 | F61: 3.95 | G61: 38.51 | H61: 38.01 | I61: 1.48 | J61: 0.59 | K61: 103.8 | L61: 26.22 | M61: 25.77 | N61: 794.6 | O61: 0 | P61: 0.49 | Q61: 7.17
A62: 03-02-2024 13:30 | B62: 3.65 | C62: 63.24 | D62: 38.47 | E62: 0.33 | F62: 4.2 | G62: 38.51 | H62: 38.01 | I62: 1.47 | J62: 0.13 | K62: 324 | L62: 28.34 | M62: 23.4 | N62: 743.4 | O62: 0 | P62: 0.49 | Q62: 7.19
A63: 03-02-2024 13:45 | B63: 3.68 | C63: 61.99 | D63: 37.81 | E63: 0.37 | F63: 4.01 | G63: 46.18 | H63: 38.87 | I63: 1.52 | J63: 0.51 | K63: 315.45 | L63: 30 | M63: 22.51 | N63: 693.6 | O63: 0 | P63: 0.49 | Q63: 7.23
A64: 03-02-2024 14:00 | B64: 4.13 | C64: 61.34 | D64: 37.81 | E64: 0.27 | F64: 3.93 | G64: 48.24 | H64: 38.87 | I64: 1.57 | J64: 0.2 | K64: 349.79 | L64: 29.42 | M64: 22.42 | N64: 626.1 | O64: 0 | P64: 0.49 | Q64: 7.26
A65: 03-02-2024 14:15 | B65: 4.29 | C65: 61.16 | D65: 37.84 | E65: 0.31 | F65: 3.8 | G65: 48.24 | H65: 38.87 | I65: 1.53 | J65: 0.13 | K65: 12.78 | L65: 28.22 | M65: 23.63 | N65: 596.3 | O65: 0 | P65: 0.48 | Q65: 7.3
A66: 03-02-2024 14:30 | B66: 4.44 | C66: 61.65 | D66: 38.23 | E66: 0.42 | F66: 3.91 | G66: 48.24 | H66: 38.87 | I66: 1.45 | J66: 0.62 | K66: 342.08 | L66: 27.92 | M66: 25.34 | N66: 551.5 | O66: 0 | P66: 0.49 | Q66: 7.35
A67: 03-02-2024 14:45 | B67: 4.53 | C67: 63.5 | D67: 39.32 | E67: 0.28 | F67: 4.07 | G67: 54.71 | H67: 37.89 | I67: 1.49 | J67: 0.9 | K67: 323.28 | L67: 28.95 | M67: 24.3 | N67: 346.9 | O67: 0 | P67: 0.49 | Q67: 7.38
A68: 03-02-2024 15:00 | B68: 5.7 | C68: 63.15 | D68: 40.07 | E68: 0.31 | F68: 3.87 | G68: 56.44 | H68: 37.89 | I68: 1.52 | J68: 1.11 | K68: 330.45 | L68: 29.2 | M68: 23.01 | N68: 317.9 | O68: 0 | P68: 0.49 | Q68: 7.49
A69: 03-02-2024 15:15 | B69: 10.54 | C69: 57.11 | D69: 40.61 | E69: Calib. | F69: 3.99 | G69: 56.44 | H69: 37.89 | I69: 1.37 | J69: 0.49 | K69: 315.54 | L69: 28.6 | M69: 23.09 | N69: 288.4 | O69: 0 | P69: 0.48 | Q69: 7.64
A70: 03-02-2024 15:30 | B70: 9.03 | C70: 57.4 | D70: 39.56 | E70: Calib. | F70: 5.19 | G70: 56.44 | H70: 37.89 | I70: 1.49 | J70: 0.47 | K70: 322.97 | L70: 27.53 | M70: 23.18 | N70: 168.6 | O70: 0 | P70: 0.45 | Q70: 7.6
A71: 03-02-2024 15:45 | B71: 7.62 | C71: 57.7 | D71: 38.6 | E71: Calib. | F71: 4.56 | G71: 54.94 | H71: 30.6 | I71: 1.55 | J71: 0.82 | K71: 319.94 | L71: 26.58 | M71: 25.08 | N71: 139.2 | O71: 0 | P71: 0.44 | Q71: 7.48
A72: 03-02-2024 16:00 | B72: 7.22 | C72: 57.25 | D72: 38.03 | E72: Calib. | F72: 4.07 | G72: 54.54 | H72: 30.6 | I72: 1.45 | J72: 0.7 | K72: 322.74 | L72: 26.04 | M72: 25.79 | N72: 128.6 | O72: 0 | P72: 0.43 | Q72: 7.43
A73: 03-02-2024 16:15 | B73: 6.91 | C73: 57.54 | D73: 37.94 | E73: 0.04 | F73: 4.29 | G73: 54.54 | H73: 30.6 | I73: 1.45 | J73: 1.05 | K73: 336.11 | L73: 25.7 | M73: 26.88 | N73: 117.9 | O73: 0 | P73: 0.44 | Q73: 7.41
A74: 03-02-2024 16:30 | B74: 6.77 | C74: 59.02 | D74: 38.65 | E74: 0.13 | F74: 3.95 | G74: 54.54 | H74: 30.6 | I74: 1.51 | J74: 0.71 | K74: 323.23 | L74: 25.29 | M74: 27.06 | N74: 110 | O74: 0 | P74: 0.44 | Q74: 7.37
...

Sheet 04
A1: Station: | B1: BHATAGAON RAIPUR
A2: Date: | B2: =$A$9 -> 04-02-2024 00:15 | D2: Power Off | G2: Pw.Off | L2: Link Fail | N2: Link F | P2: Maintenance | R2: Maint.
A3: Report Type: | B3: Mean | D3: Calibration | G3: Calib. | L3: Data Fail | N3: Data F | P3: Invalid | R3: Invalid
A4: Time Base: | B4: 15 Min | D4: Zero Referrence | G4: Z.Ref | L4: Warm Up | N4: Wm. Up
A7: Date & Time | B7: NO_BHATAGAON | C7: NO2__BHATAGAON | D7: NOX_BHATAGAON | E7: SO2__BHATAGAON | F7: O3__BHATAGAON | G7: PM10__BHATAGAON | H7: PM2_5__BHATAGAON | I7: BENZ__BHATAGAON | J7: WS__BHATAGAON | K7: WD__BHATAGAON | L7: TEMP__BHATAGAON | M7: HUM__BHATAGAON | N7: SR__BHATAGAON | O7: RG__BHATAGAON | P7: CO__BHATAGAON | Q7: NH3__BHATAGAON
B8: ug/m3 | C8: ug/m3 | D8: ppb | E8: ug/m3 | F8: ug/m3 | G8: ug/m3 | H8: ug/m3 | I8: ug/m3 | J8: m/sec | K8: deg | L8: degreC | M8: % | N8: w/m2 | O8: mm | P8: mg/m3 | Q8: ug/m3
A9: 04-02-2024 00:15 | B9: 226.53 | C9: 65.76 | D9: 218.6 | E9: 0.41 | F9: 2.81 | G9: 203.44 | H9: 56.54 | I9: 1.53 | J9: 0.1 | K9: 285.76 | L9: 15.61 | M9: 77.22 | N9: 60.1 | O9: 0 | P9: 2.82 | Q9: 23.08
A10: 04-02-2024 00:30 | B10: 220.17 | C10: 64.36 | D10: 212.73 | E10: 0.42 | F10: 2.93 | G10: 203.44 | H10: 56.54 | I10: 1.41 | J10: 0.09 | K10: 316.83 | L10: 15.31 | M10: 80.27 | N10: 60 | O10: 0 | P10: 2.74 | Q10: 22.67
A11: 04-02-2024 00:45 | B11: 214.74 | C11: 63.2 | D11: 207.73 | E11: 0.43 | F11: 3.07 | G11: 159.78 | H11: 52.7 | I11: 1.53 | J11: 0.12 | K11: 333.94 | L11: 15.17 | M11: 81.17 | N11: 59.6 | O11: 0 | P11: 2.68 | Q11: 22.16
A12: 04-02-2024 01:00 | B12: 206.71 | C12: 62.11 | D12: 200.69 | E12: 0.43 | F12: 3.01 | G12: 148.86 | H12: 52.7 | I12: 1.49 | J12: 0.02 | K12: 184.58 | L12: 15.29 | M12: 75.19 | N12: 59.6 | O12: 0 | P12: 2.59 | Q12: 21.74
A13: 04-02-2024 01:15 | B13: 196.7 | C13: 61.91 | D13: 192.55 | E13: 0.37 | F13: 3 | G13: 148.86 | H13: 52.7 | I13: 1.48 | J13: 0.09 | K13: 247.7 | L13: 15.59 | M13: 74.76 | N13: 59.5 | O13: 0 | P13: 2.18 | Q13: 21.12
A14: 04-02-2024 01:30 | B14: 188.61 | C14: 60.8 | D14: 185.45 | E14: 0.34 | F14: 2.99 | G14: 148.86 | H14: 52.7 | I14: 1.58 | J14: 0.1 | K14: 227.65 | L14: 15.6 | M14: 76.92 | N14: 59.9 | O14: 0 | P14: 2.23 | Q14: 20.45
A15: 04-02-2024 01:45 | B15: 182.16 | C15: 59.87 | D15: 179.76 | E15: 0.29 | F15: 3 | G15: 127.46 | H15: 52.52 | I15: 1.57 | J15: 0.05 | K15: 71.44 | L15: 15.2 | M15: 79.14 | N15: 60.1 | O15: 0 | P15: 2.2 | Q15: 19.93
A16: 04-02-2024 02:00 | B16: 177.23 | C16: 59.61 | D16: 175.67 | E16: 0.33 | F16: 3.07 | G16: 121.73 | H16: 52.52 | I16: 1.48 | J16: 0.08 | K16: 201.31 | L16: 14.8 | M16: 83.42 | N16: 60 | O16: 0 | P16: 2.18 | Q16: 19.43
A17: 04-02-2024 02:15 | B17: 172.62 | C17: 59.68 | D17: 172.01 | E17: 0.36 | F17: 2.98 | G17: 121.73 | H17: 52.52 | I17: 1.48 | J17: 0.1 | K17: 277.92 | L17: 14.56 | M17: 86.29 | N17: 59.8 | O17: 0 | P17: 2.16 | Q17: 19.16
A18: 04-02-2024 02:30 | B18: 169.15 | C18: 59.44 | D18: 169.1 | E18: 0.36 | F18: 2.97 | G18: 121.73 | H18: 52.52 | I18: 1.55 | J18: 0.11 | K18: 296.95 | L18: 14.49 | M18: 87.86 | N18: 59.2 | O18: 0 | P18: 2.15 | Q18: 18.94
A19: 04-02-2024 02:45 | B19: 166.12 | C19: 59.17 | D19: 166.51 | E19: 0.35 | F19: 3.11 | G19: 170.06 | H19: 59.48 | I19: 1.51 | J19: 0.14 | K19: 289.53 | L19: 14.21 | M19: 91.86 | N19: 59.4 | O19: 0 | P19: 2.15 | Q19: 18.78
A20: 04-02-2024 03:00 | B20: 163.74 | C20: 59.16 | D20: 164.6 | E20: 0.3 | F20: 2.9 | G20: 183 | H20: 59.48 | I20: 1.44 | J20: 0.16 | K20: 294.07 | L20: 14.27 | M20: 90.2 | N20: 59.2 | O20: 0 | P20: 2.13 | Q20: 18.6
... A27: 04-02-2024 04:45 | B27: 148.21 | C27: 57.43 | D27: 151.19 | E27: 0.49 | F27: 3.36 | G27: 164.13 | H27: 58.05 | I27: 1.53 | J27: 0.13 | K27: 242.28 | L27: 14.34 | M27: 81.44 | N27: 59.7 | O27: 0 | P27: 1.93 | Q27: 17.75
A28: 04-02-2024 05:00 | B28: 143.05 | C28: 57.51 | D28: 147.1 | E28: 0.49 | F28: 2.98 | G28: 163.56 | H28: 58.05 | I28: 1.56 | J28: 0.13 | K28: 265.71 | L28: 14.15 | M28: 80.98 | N28: 59.6 | O28: 0 | P28: 1.87 | Q28: Data F
A29: 04-02-2024 05:15 | B29: 138.71 | C29: 57.27 | D29: 143.48 | E29: 0.49 | F29: 2.91 | G29: 163.56 | H29: 58.05 | I29: 1.5 | J29: 0.18 | K29: 299.67 | L29: 13.78 | M29: 86.63 | N29: 59.6 | O29: 0 | P29: 1.81 | Q29: Data F
A30: 04-02-2024 05:30 | B30: 135.06 | C30: 55.89 | D30: 139.8 | E30: 0.43 | F30: 3.06 | G30: 163.56 | H30: 58.05 | I30: 1.63 | J30: 0.07 | K30: 267.96 | L30: 13.48 | M30: 90.71 | N30: 59.7 | O30: 0 | P30: 1.75 | Q30: Data F
A31: 04-02-2024 05:45 | B31: 132.76 | C31: 55.73 | D31: 137.86 | E31: 0.41 | F31: 3.02 | G31: 135.45 | H31: 49.36 | I31: 1.48 | J31: 0.1 | K31: 252.64 | L31: 13.4 | M31: 92.74 | N31: 59.4 | O31: 0 | P31: 1.69 | Q31: Data F
A32: 04-02-2024 06:00 | B32: 132.76 | C32: 55.73 | D32: 137.86 | E32: 0.41 | F32: 3.02 | G32: 135.45 | H32: 49.36 | I32: 1.48 | J32: 0.1 | K32: 252.64 | L32: 13.4 | M32: 92.74 | N32: 59.4 | O32: 0 | P32: 1.69 | Q32: Data F
A33: 04-02-2024 06:15 | B33: 133.84 | C33: 54.99 | D33: 138.32 | E33: 0.4 | F33: 2.95 | G33: 123.73 | H33: 49.36 | I33: 1.42 | J33: 0.08 | K33: 294.83 | L33: 13.49 | M33: 94.14 | N33: 59.6 | O33: 0 | P33: 1.61 | Q33: 16.09
A34: 04-02-2024 06:30 | B34: 137.85 | C34: 54.63 | D34: 141.34 | E34: 0.38 | F34: 3 | G34: 123.73 | H34: 49.36 | I34: 1.46 | J34: 0.12 | K34: 272.11 | L34: 13.31 | M34: 96.51 | N34: 61 | O34: 0 | P34: 1.57 | Q34: 16.18
A35: 04-02-2024 06:45 | B35: 142.39 | C35: 55.31 | D35: 145.35 | E35: 0.43 | F35: 2.86 | G35: 131.53 | H35: 51.65 | I35: 1.57 | J35: 0.1 | K35: 285.05 | L35: 13.78 | M35: 94.82 | N35: 68.1 | O35: 0 | P35: 1.54 | Q35: 16.42
A36: 04-02-2024 07:00 | B36: 148.04 | C36: 55.44 | D36: 149.96 | E36: 0.46 | F36: 3.2 | G36: 133.62 | H36: 51.65 | I36: 1.47 | J36: 0.11 | K36: 270.34 | L36: 13.82 | M36: 93.33 | N36: 82 | O36: 0 | P36: 1.52 | Q36: 16.75
A37: 04-02-2024 07:15 | B37: 153.28 | C37: 55.68 | D37: 154.3 | E37: 0.42 | F37: 3.14 | G37: 133.62 | H37: 51.65 | I37: 1.49 | J37: 0.08 | K37: 288.35 | L37: 14.15 | M37: 92.87 | N37: 98.5 | O37: 0 | P37: 1.53 | Q37: 17.09
A38: 04-02-2024 07:30 | B38: 157.55 | C38: 56.36 | D38: 158.09 | E38: 0.44 | F38: 3.21 | G38: 133.62 | H38: 51.65 | I38: 1.47 | J38: 0.05 | K38: 218.01 | L38: 14.82 | M38: 89.23 | N38: 117.4 | O38: 0 | P38: 1.61 | Q38: 17.48
A39: 04-02-2024 07:45 | B39: 156.38 | C39: 56.88 | D39: 157.44 | E39: 0.4 | F39: 3.06 | G39: 137.88 | H39: 51.61 | I39: 1.46 | J39: 0.08 | K39: 95.17 | L39: 16.37 | M39: 81.09 | N39: 210.7 | O39: 0 | P39: 1.59 | Q39: 17.58
A40: 04-02-2024 08:00 | B40: 153.87 | C40: 56.55 | D40: 155.25 | E40: 0.3 | F40: 2.98 | G40: 139.02 | H40: 51.61 | I40: 1.5 | J40: 0.11 | K40: 13.65 | L40: 19.22 | M40: 67.79 | N40: 276.3 | O40: 0 | P40: 1.57 | Q40: 17.59
A41: 04-02-2024 08:15 | B41: 150.44 | C41: 57.97 | D41: 153.28 | E41: 0.48 | F41: 3.24 | G41: 139.02 | H41: 51.61 | I41: 1.48 | J41: 0.21 | K41: 336.51 | L41: 21.8 | M41: 57.89 | N41: 331.1 | O41: 0 | P41: 1.57 | Q41: 17.41
A42: 04-02-2024 08:30 | B42: 145.92 | C42: 60.28 | D42: 150.93 | E42: 0.53 | F42: 3.08 | G42: 139.02 | H42: 51.61 | I42: 1.51 | J42: 0.17 | K42: 351.6 | L42: 22.63 | M42: 55.65 | N42: 381.1 | O42: 0 | P42: 1.57 | Q42: 17.2
A43: 04-02-2024 08:45 | B43: 139.12 | C43: 62.35 | D43: 146.63 | E43: 0.55 | F43: 3.17 | G43: 147.93 | H43: 50.99 | I43: 1.6 | J43: 0.39 | K43: 149.93 | L43: 22.08 | M43: 57.27 | N43: 440.2 | O43: 0 | P43: 1.56 | Q43: 16.92
A44: 04-02-2024 09:00 | B44: 131.45 | C44: 63.98 | D44: 141.37 | E44: 0.42 | F44: 3.35 | G44: 150.31 | H44: 50.99 | I44: 1.51 | J44: 0.81 | K44: 146.6 | L44: 21.81 | M44: 56.96 | N44: 488.7 | O44: 0 | P44: 1.52 | Q44: 16.58
... A64: 04-02-2024 14:00 | B64: 9.87 | C64: 74.91 | D64: 49.9 | E64: 0.08 | F64: 3.63 | G64: 35.2 | H64: 27.6 | I64: 1.52 | J64: 0.38 | K64: 100.77 | L64: 28.7 | M64: 20.94 | N64: 687.6 | O64: 0 | P64: 0.74 | Q64: 7.94
A65: 04-02-2024 14:15 | B65: 7.67 | C65: 73.56 | D65: 47.39 | E65: Data F | F65: 3.72 | G65: 35.2 | H65: 27.6 | I65: 1.47 | J65: 0.2 | K65: 355.87 | L65: 29.91 | M65: 20.74 | N65: 672.9 | O65: 0 | P65: 0.72 | Q65: 7.47
A66: 04-02-2024 14:30 | B66: 5.91 | C66: 72.26 | D66: 45.27 | E66: 0.04 | F66: 4.19 | G66: 35.2 | H66: 27.6 | I66: 1.46 | J66: 0.13 | K66: 126.13 | L66: 27.9 | M66: 22.22 | N66: 636.8 | O66: 0 | P66: 0.69 | Q66: 6.9
A67: 04-02-2024 14:45 | B67: 4.25 | C67: 69.84 | D67: 42.6 | E67: 0.02 | F67: 4.19 | G67: 34.82 | H67: 23.93 | I67: 1.51 | J67: 0.16 | K67: 342.11 | L67: 28.78 | M67: 21.7 | N67: 389.1 | O67: 0 | P67: 0.66 | Q67: 6.09
...

Sheet 05
A1: Station: | B1: BHATAGAON RAIPUR
A2: Date: | B2: =$A$9 -> 05-02-2024 00:15 | D2: Power Off | G2: Pw.Off | L2: Link Fail | N2: Link F | P2: Maintenance | R2: Maint.
A3: Report Type: | B3: Mean | D3: Calibration | G3: Calib. | L3: Data Fail | N3: Data F | P3: Invalid | R3: Invalid
A4: Time Base: | B4: 15 Min | D4: Zero Referrence | G4: Z.Ref | L4: Warm Up | N4: Wm. Up
A7: Date & Time | B7: NO_BHATAGAON | C7: NO2__BHATAGAON | D7: NOX_BHATAGAON | E7: SO2__BHATAGAON | F7: O3__BHATAGAON | G7: PM10__BHATAGAON | H7: PM2_5__BHATAGAON | I7: BENZ__BHATAGAON | J7: WS__BHATAGAON | K7: WD__BHATAGAON | L7: TEMP__BHATAGAON | M7: HUM__BHATAGAON | N7: SR__BHATAGAON | O7: RG__BHATAGAON | P7: CO__BHATAGAON | Q7: NH3__BHATAGAON
B8: ug/m3 | C8: ug/m3 | D8: ppb | E8: ug/m3 | F8: ug/m3 | G8: ug/m3 | H8: ug/m3 | I8: ug/m3 | J8: m/sec | K8: deg | L8: degreC | M8: % | N8: w/m2 | O8: mm | P8: mg/m3 | Q8: ug/m3
A9: 05-02-2024 00:15 | B9: 101.36 | C9: 70.68 | D9: 120.94 | E9: 0.2 | F9: 3.26 | G9: 81.97 | H9: 35.51 | I9: 1.49 | J9: 0.14 | K9: 308.56 | L9: 16.85 | M9: 67.05 | N9: 64.4 | O9: 0 | P9: 1.5 | Q9: 15.71
A10: 05-02-2024 00:30 | B10: 98.15 | C10: 69.85 | D10: 117.9 | E10: 0.24 | F10: 3.18 | G10: 81.97 | H10: 35.51 | I10: 1.52 | J10: 0.15 | K10: 228.57 | L10: 17.63 | M10: 58.85 | N10: 63.4 | O10: 0 | P10: 1.44 | Q10: 15.43
A11: 05-02-2024 00:45 | B11: 93.48 | C11: 68.8 | D11: 113.58 | E11: 0.2 | F11: 2.83 | G11: 89.21 | H11: 31.96 | I11: 1.43 | J11: 0.21 | K11: 171.88 | L11: 18.12 | M11: 58.65 | N11: 63.7 | O11: 0 | P11: 1.41 | Q11: 15.08
A12: 05-02-2024 01:00 | B12: 88.24 | C12: 67.97 | D12: 108.92 | E12: 0.21 | F12: 3.02 | G12: 91.14 | H12: 31.96 | I12: 1.48 | J12: 0.38 | K12: 154.85 | L12: 17.92 | M12: 65.59 | N12: 63.8 | O12: 0 | P12: 1.34 | Q12: 14.72
A13: 05-02-2024 01:15 | B13: 83.3 | C13: 66.8 | D13: 104.31 | E13: 0.22 | F13: 3.06 | G13: 91.14 | H13: 31.96 | I13: 1.52 | J13: 0.09 | K13: 144.01 | L13: 17.68 | M13: 68.44 | N13: 64.5 | O13: 0 | P13: 1.21 | Q13: 14.39
A14: 05-02-2024 01:30 | B14: 78.42 | C14: 65.63 | D14: 99.75 | E14: 0.23 | F14: 3.17 | G14: 91.14 | H14: 31.96 | I14: 1.54 | J14: 0.1 | K14: 332.91 | L14: 17.48 | M14: 70.33 | N14: 64.8 | O14: 0 | P14: 1.22 | Q14: 13.93
A15: 05-02-2024 01:45 | B15: 74.23 | C15: 64.72 | D15: 95.89 | E15: 0.23 | F15: 3.14 | G15: 63.4 | H15: 30.76 | I15: 1.51 | J15: 0.1 | K15: 284.35 | L15: 16.88 | M15: 75.07 | N15: 64.9 | O15: 0 | P15: 1.16 | Q15: 13.56
A16: 05-02-2024 02:00 | B16: 70.13 | C16: 64.04 | D16: 92.22 | E16: 0.17 | F16: 3.19 | G16: 55.97 | H16: 30.76 | I16: 1.46 | J16: 0.12 | K16: 299.3 | L16: 16.3 | M16: 80.53 | N16: 65 | O16: 0 | P16: 1.13 | Q16: 13.23
A17: 05-02-2024 02:15 | B17: 66.18 | C17: 62.25 | D17: 88.08 | E17: 0.19 | F17: 3.09 | G17: 55.97 | H17: 30.76 | I17: 1.45 | J17: 0.01 | K17: 138.16 | L17: 16.55 | M17: 77.02 | N17: 64.3 | O17: 0 | P17: 1.08 | Q17: 12.88
A18: 05-02-2024 02:30 | B18: 61.82 | C18: 61.35 | D18: 84.08 | E18: 0.15 | F18: 3.17 | G18: 55.97 | H18: 30.76 | I18: 1.44 | J18: 0.06 | K18: 279.65 | L18: 16.31 | M18: 77.24 | N18: 64.7 | O18: 0 | P18: 1.04 | Q18: 12.51
A19: 05-02-2024 02:45 | B19: 57.8 | C19: 60.78 | D19: 80.54 | E19: 0.12 | F19: 3.06 | G19: 48.54 | H19: 25.08 | I19: 1.58 | J19: 0.14 | K19: 186.83 | L19: 16.11 | M19: 77.31 | N19: 64.4 | O19: 0 | P19: 1 | Q19: 12.11
A20: 05-02-2024 03:00 | B20: 53.96 | C20: 59.66 | D20: 76.84 | E20: 0.14 | F20: 3.16 | G20: 46.55 | H20: 25.08 | I20: 1.48 | J20: 0.09 | K20: 282.95 | L20: 15.94 | M20: 79.34 | N20: 65 | O20: 0 | P20: 0.95 | Q20: 11.68
... A104: 05-02-2024 24:00 | B104: 24.25 | C104: 59.58 | D104: 52.97 | E104: 0.23 | F104: 2.89 | G104: 71.19 | H104: 28.73 | I104: 1.4 | J104: 0.11 | K104: 308.02 | L104: 20.03 | M104: 80.79 | N104: 64.7 | O104: 0 | P104: 0.98 | Q104: 8.45
A106: Min | B106: =MIN(B9:B104) -> 1.33 | C106: =MIN(C9:C104) -> 45.16 | D106: =MIN(D9:D104) -> 29.49 | E106: =MIN(E9:E104) -> 0.07 | F106: =MIN(F9:F104) -> 2.73 | G106: =MIN(G9:G104) -> 32.12 | H106: =MIN(H9:H104) -> 15.24 | I106: =MIN(I9:I104) -> 1.39 | ... Q106: =MIN(Q9:Q104) -> 5.21
A107: Max | B107: =MAX(B9:B104) -> 101.36 | C107: =MAX(C9:C104) -> 73.07 | D107: =MAX(D9:D104) -> 120.94 | E107: =MAX(E9:E104) -> 0.46 | F107: =MAX(F9:F104) -> 16.96 | G107: =MAX(G9:G104) -> 91.14 | H107: =MAX(H9:H104) -> 35.51 | I107: =MAX(I9:I104) -> 1.58 | ... Q107: =MAX(Q9:Q104) -> 15.71
A108: Avg | B108: =AVERAGE(B9:B104) -> 28.566979 | C108: =AVERAGE(C9:C104) -> 60.996875 | D108: =AVERAGE(D9:D104) -> 57.217396 | E108: =AVERAGE(E9:E104) -> 0.2128125 | F108: =AVERAGE(F9:F104) -> 4.3139583 | G108: =AVERAGE(G9:G104) -> 60.048958 | H108: =AVERAGE(H9:H104) -> 23.427083 | I108: =AVERAGE(I9:I104) -> 1.4961458 | ... Q108: =AVERAGE(Q9:Q104) -> 8.7235417
A109: Stdev | B109: =STDEV(B9:B104) -> 26.681607 | C109: =STDEV(C9:C104) -> 5.5420728 | D109: =STDEV(D9:D104) -> 22.526552 | E109: =STDEV(E9:E104) -> 0.092117809 | F109: =STDEV(F9:F104) -> 2.3319594 | G109: =STDEV(G9:G104) -> 15.057474 | H109: =STDEV(H9:H104) -> 4.3728338 | I109: =STDEV(I9:I104) -> 0.037483183 | ... Q109: =STDEV(Q9:Q104) -> 2.7426814
A110: Num | B110: =COUNT(B9:B104) -> 96 | C110: =COUNT(C9:C104) -> 96 | D110: =COUNT(D9:D104) -> 96 | E110: =COUNT(E9:E104) -> 96 | F110: =COUNT(F9:F104) -> 96 | G110: =COUNT(G9:G104) -> 96 | H110: =COUNT(H9:H104) -> 96 | I110: =COUNT(I9:I104) -> 96 | ... Q110: =COUNT(Q9:Q104) -> 96
A111: DCR | B111: =IF(B110>=87,">90%",IF(B110<=87,"<90%")) -> >90% | C111: =IF(C110>=87,">90%",IF(C110<=87,"<90%")) -> >90% | D111: =IF(D110>=87,">90%",IF(D110<=87,"<90%")) -> >90% | E111: =IF(E110>=87,">90%",IF(E110<=87,"<90%")) -> >90% | F111: =IF(F110>=87,">90%",IF(F110<=87,"<90%")) -> >90% | G111: =IF(G110>=87,">90%",IF(G110<=87,"<90%")) -> >90% | H111: =IF(H110>=87,">90%",IF(H110<=87,"<90%")) -> >90% | I111: =IF(I110>=87,">90%",IF(I110<=87,"<90%")) -> >90% | ... Q111: =IF(Q110>=87,">90%",IF(Q110<=87,"<90%")) -> >90%
A112: Status | B112: =IF(B110>=87,"OK",IF(B110<=87,"LESS")) -> OK | C112: =IF(C110>=87,"OK",IF(C110<=87,"LESS")) -> OK | D112: =IF(D110>=87,"OK",IF(D110<=87,"LESS")) -> OK | E112: =IF(E110>=87,"OK",IF(E110<=87,"LESS")) -> OK | F112: =IF(F110>=87,"OK",IF(F110<=87,"LESS")) -> OK | G112: =IF(G110>=87,"OK",IF(G110<=87,"LESS")) -> OK | H112: =IF(H110>=87,"OK",IF(H110<=87,"LESS")) -> OK | I112: =IF(I110>=87,"OK",IF(I110<=87,"LESS")) -> OK | ... Q112: =IF(Q110>=87,"OK",IF(Q110<=87,"LESS")) -> OK
A115: Done by | B115: RK
A117: Comment

Sheet 06
A1: Station: | B1: BHATAGAON RAIPUR
A2: Date: | B2: =$A$9 -> 06-02-2024 00:15 | D2: Power Off | G2: Pw.Off | L2: Link Fail | N2: Link F | P2: Maintenance | R2: Maint.
A3: Report Type: | B3: Mean | D3: Calibration | G3: Calib. | L3: Data Fail | N3: Data F | P3: Invalid | R3: Invalid
A4: Time Base: | B4: 15 Min | D4: Zero Referrence | G4: Z.Ref | L4: Warm Up | N4: Wm. Up
A7: Date & Time | B7: NO_BHATAGAON | C7: NO2__BHATAGAON | D7: NOX_BHATAGAON | E7: SO2__BHATAGAON | F7: O3__BHATAGAON | G7: PM10__BHATAGAON | H7: PM2_5__BHATAGAON | I7: BENZ__BHATAGAON | J7: WS__BHATAGAON | K7: WD__BHATAGAON | L7: TEMP__BHATAGAON | M7: HUM__BHATAGAON | N7: SR__BHATAGAON | O7: RG__BHATAGAON | P7: CO__BHATAGAON | Q7: NH3__BHATAGAON
B8: ug/m3 | C8: ug/m3 | D8: ppb | E8: ug/m3 | F8: ug/m3 | G8: ug/m3 | H8: ug/m3 | I8: ug/m3 | J8: m/sec | K8: deg | L8: degreC | M8: % | N8: w/m2 | O8: mm | P8: mg/m3 | Q8: ug/m3
A9: 06-02-2024 00:15 | B9: 23.43 | C9: 59.58 | D9: 52.32 | E9: 0.33 | F9: 3.04 | G9: 71.19 | H9: 28.73 | I9: 1.48 | J9: 0.28 | K9: 153.1 | L9: 20.06 | M9: 79.53 | N9: 64.1 | O9: 0 | P9: 0.96 | Q9: 8.39
A10: 06-02-2024 00:30 | B10: 21.74 | C10: 58.84 | D10: 50.55 | E10: 0.35 | F10: 3.11 | G10: 71.19 | H10: 28.73 | I10: 1.53 | J10: 0.09 | K10: 160.17 | L10: 20.28 | M10: 77.83 | N10: 64.5 | O10: 0 | P10: 0.91 | Q10: 8.34
A11: 06-02-2024 00:45 | B11: 19.99 | C11: 57.92 | D11: 48.64 | E11: 0.32 | F11: 3.05 | G11: 65.4 | H11: 25.71 | I11: 1.45 | J11: 0.05 | K11: 229.32 | L11: 20.06 | M11: 79.61 | N11: 64.6 | O11: 0 | P11: 0.88 | Q11: 8.25
A12: 06-02-2024 01:00 | B12: 18.43 | C12: 57.44 | D12: 47.13 | E12: 0.33 | F12: 3.07 | G12: 63.85 | H12: 25.71 | I12: 1.54 | J12: 0.15 | K12: 316.67 | L12: 19.9 | M12: 80.78 | N12: 64.6 | O12: 0 | P12: 0.85 | Q12: 8.07
A13: 06-02-2024 01:15 | B13: 17.14 | C13: 56.87 | D13: 45.78 | E13: 0.32 | F13: 2.99 | G13: 63.85 | H13: 25.71 | I13: 1.55 | J13: 0.08 | K13: 292.77 | L13: 19.77 | M13: 81.02 | N13: 64.6 | O13: 0 | P13: 0.8 | Q13: 7.94
A14: 06-02-2024 01:30 | B14: 15.78 | C14: 55.99 | D14: 44.2 | E14: 0.37 | F14: 3.08 | G14: 63.85 | H14: 25.71 | I14: 1.47 | J14: 0.01 | K14: 272.69 | L14: 19.62 | M14: 82 | N14: 64.5 | O14: 0 | P14: 0.79 | Q14: 7.77
A15: 06-02-2024 01:45 | B15: 14.44 | C15: 55.37 | D15: 42.79 | E15: 0.3 | F15: 3.28 | G15: 54.61 | H15: 23.7 | I15: 1.52 | J15: 0.05 | K15: 225.56 | L15: 19.58 | M15: 81.72 | N15: 64.3 | O15: 0 | P15: 0.77 | Q15: 7.7
A16: 06-02-2024 02:00 | B16: 13.18 | C16: 54.77 | D16: 41.44 | E16: 0.28 | F16: 3.23 | G16: 52.13 | H16: 23.7 | I16: 1.46 | J16: 0.05 | K16: 201.38 | L16: 19.51 | M16: 81.41 | N16: 64.4 | O16: 0 | P16: 0.74 | Q16: 7.62
A17: 06-02-2024 02:15 | B17: 12.04 | C17: 53.96 | D17: 40.08 | E17: 0.32 | F17: 3.19 | G17: 52.13 | H17: 23.7 | I17: 1.53 | J17: 0.06 | K17: 190.05 | L17: 19.2 | M17: 82.94 | N17: 64.6 | O17: 0 | P17: 0.71 | Q17: 7.48
A18: 06-02-2024 02:30 | B18: 10.99 | C18: 53.17 | D18: 38.8 | E18: 0.26 | F18: 3.11 | G18: 52.13 | H18: 23.7 | I18: 1.57 | J18: 0.06 | K18: 230.58 | L18: 18.93 | M18: 85.14 | N18: 64.7 | O18: 0 | P18: 0.69 | Q18: 7.33
A19: 06-02-2024 02:45 | B19: 10.32 | C19: 52.88 | D19: 38.11 | E19: 0.31 | F19: 3.17 | G19: 53.78 | H19: 22.14 | I19: 1.52 | J19: 0.16 | K19: 167.95 | L19: 18.72 | M19: 86.55 | N19: 64.5 | O19: 0 | P19: 0.66 | Q19: 7.29
A20: 06-02-2024 03:00 | B20: 10.29 | C20: 54.41 | D20: 38.93 | E20: 0.31 | F20: 3.57 | G20: 54.22 | H20: 22.14 | I20: 1.37 | J20: 0.15 | K20: 159.98 | L20: 18.66 | M20: 86.7 | N20: 64.4 | O20: 0 | P20: 0.64 | Q20: 7.3
... A104: 06-02-2024 24:00 | B104: 43.12 | C104: 60.23 | D104: 68.47 | E104: 0.2 | F104: 3.13 | G104: 90.61 | H104: 33.86 | I104: 1.51 | J104: 0.66 | K104: 338.33 | L104: 20.06 | M104: 70.51 | N104: 62.9 | O104: 0 | P104: 1.34 | Q104: 9.94
A106: Min | B106: =MIN(B9:B104) -> 1.3 | C106: =MIN(C9:C104) -> 37.26 | D106: =MIN(D9:D104) -> 22.55 | E106: =MIN(E9:E104) -> 0.02 | F106: =MIN(F9:F104) -> 2.17 | G106: =MIN(G9:G104) -> 46.58 | H106: =MIN(H9:H104) -> 20.9 | I106: =MIN(I9:I104) -> 1.34 | ... Q106: =MIN(Q9:Q104) -> 5.21
A107: Max | B107: =MAX(B9:B104) -> 66.93 | C107: =MAX(C9:C104) -> 70.05 | D107: =MAX(D9:D104) -> 87.76 | E107: =MAX(E9:E104) -> 0.37 | F107: =MAX(F9:F104) -> 19.31 | G107: =MAX(G9:G104) -> 120.03 | H107: =MAX(H9:H104) -> 38.75 | I107: =MAX(I9:I104) -> 1.6 | ... Q107: =MAX(Q9:Q104) -> 11.39
A108: Avg | B108: =AVERAGE(B9:B104) -> 21.325313 | C108: =AVERAGE(C9:C104) -> 55.505521 | D108: =AVERAGE(D9:D104) -> 48.379792 | E108: =AVERAGE(E9:E104) -> 0.18125 | F108: =AVERAGE(F9:F104) -> 4.9126042 | G108: =AVERAGE(G9:G104) -> 70.839271 | H108: =AVERAGE(H9:H104) -> 27.187396 | I108: =AVERAGE(I9:I104) -> 1.4979167 | ... Q108: =AVERAGE(Q9:Q104) -> 7.9132292
A109: Stdev | B109: =STDEV(B9:B104) -> 20.606998 | C109: =STDEV(C9:C104) -> 5.7255714 | D109: =STDEV(D9:D104) -> 18.257419 | E109: =STDEV(E9:E104) -> 0.078381657 | F109: =STDEV(F9:F104) -> 3.2529194 | G109: =STDEV(G9:G104) -> 21.344647 | H109: =STDEV(H9:H104) -> 5.3632124 | I109: =STDEV(I9:I104) -> 0.044412342 | ... Q109: =STDEV(Q9:Q104) -> 1.7989257
A110: Num | B110: =COUNT(B9:B104) -> 96 | C110: =COUNT(C9:C104) -> 96 | D110: =COUNT(D9:D104) -> 96 | E110: =COUNT(E9:E104) -> 96 | F110: =COUNT(F9:F104) -> 96 | G110: =COUNT(G9:G104) -> 96 | H110: =COUNT(H9:H104) -> 96 | I110: =COUNT(I9:I104) -> 96 | ... Q110: =COUNT(Q9:Q104) -> 96
A111: DCR | B111: =IF(B110>=87,">90%",IF(B110<=87,"<90%")) -> >90% | C111: =IF(C110>=87,">90%",IF(C110<=87,"<90%")) -> >90% | D111: =IF(D110>=87,">90%",IF(D110<=87,"<90%")) -> >90% | E111: =IF(E110>=87,">90%",IF(E110<=87,"<90%")) -> >90% | F111: =IF(F110>=87,">90%",IF(F110<=87,"<90%")) -> >90% | G111: =IF(G110>=87,">90%",IF(G110<=87,"<90%")) -> >90% | H111: =IF(H110>=87,">90%",IF(H110<=87,"<90%")) -> >90% | I111: =IF(I110>=87,">90%",IF(I110<=87,"<90%")) -> >90% | ... Q111: =IF(Q110>=87,">90%",IF(Q110<=87,"<90%")) -> >90%
A112: Status | B112: =IF(B110>=87,"OK",IF(B110<=87,"LESS")) -> OK | C112: =IF(C110>=87,"OK",IF(C110<=87,"LESS")) -> OK | D112: =IF(D110>=87,"OK",IF(D110<=87,"LESS")) -> OK | E112: =IF(E110>=87,"OK",IF(E110<=87,"LESS")) -> OK | F112: =IF(F110>=87,"OK",IF(F110<=87,"LESS")) -> OK | G112: =IF(G110>=87,"OK",IF(G110<=87,"LESS")) -> OK | H112: =IF(H110>=87,"OK",IF(H110<=87,"LESS")) -> OK | I112: =IF(I110>=87,"OK",IF(I110<=87,"LESS")) -> OK | ... Q112: =IF(Q110>=87,"OK",IF(Q110<=87,"LESS")) -> OK
A115: Done by | B115: RK
A117: Comment

Sheet 07
A1: Station: | B1: BHATAGAON RAIPUR
A2: Date: | B2: =$A$9 -> 07-02-2024 00:15 | D2: Power Off | G2: Pw.Off | L2: Link Fail | N2: Link F | P2: Maintenance | R2: Maint.
A3: Report Type: | B3: Mean | D3: Calibration | G3: Calib. | L3: Data Fail | N3: Data F | P3: Invalid | R3: Invalid
A4: Time Base: | B4: 15 Min | D4: Zero Referrence | G4: Z.Ref | L4: Warm Up | N4: Wm. Up
A7: Date & Time | B7: NO_BHATAGAON | C7: NO2__BHATAGAON | D7: NOX_BHATAGAON | E7: SO2__BHATAGAON | F7: O3__BHATAGAON | G7: PM10__BHATAGAON | H7: PM2_5__BHATAGAON | I7: BENZ__BHATAGAON | J7: WS__BHATAGAON | K7: WD__BHATAGAON | L7: TEMP__BHATAGAON | M7: HUM__BHATAGAON | N7: SR__BHATAGAON | O7: RG__BHATAGAON | P7: CO__BHATAGAON | Q7: NH3__BHATAGAON
B8: ug/m3 | C8: ug/m3 | D8: ppb | E8: ug/m3 | F8: ug/m3 | G8: ug/m3 | H8: ug/m3 | I8: ug/m3 | J8: m/sec | K8: deg | L8: degreC | M8: % | N8: w/m2 | O8: mm | P8: mg/m3 | Q8: ug/m3
A9: 07-02-2024 00:15 | B9: 40.33 | C9: 60.45 | D9: 66.35 | E9: 0.34 | F9: 3.36 | G9: 90.61 | H9: 33.86 | I9: 1.51 | J9: 0.9 | K9: 346.52 | L9: 19.81 | M9: 72.26 | N9: 62.9 | O9: 0 | P9: 1.27 | Q9: 9.8
A10: 07-02-2024 00:30 | B10: 37.6 | C10: 60.52 | D10: 64.2 | E10: 0.34 | F10: 3.27 | G10: 90.61 | H10: 33.86 | I10: 1.49 | J10: 0.84 | K10: 345.06 | L10: 19.58 | M10: 73.69 | N10: 62.8 | O10: 0 | P10: 1.21 | Q10: 9.62
A11: 07-02-2024 00:45 | B11: 34.58 | C11: 60.14 | D11: 61.56 | E11: 0.37 | F11: 3.27 | G11: 74.18 | H11: 25.93 | I11: 1.51 | J11: 0.93 | K11: 341.58 | L11: 19.46 | M11: 74.46 | N11: 62.7 | O11: 0 | P11: 1.12 | Q11: 9.48
A12: 07-02-2024 01:00 | B12: 31.55 | C12: 59.94 | D12: 59.03 | E12: 0.36 | F12: 3.08 | G12: 69.79 | H12: 25.93 | I12: 1.53 | J12: 1.06 | K12: 346.06 | L12: 19.24 | M12: 75.93 | N12: 62.9 | O12: 0 | P12: 1.07 | Q12: 9.28
A13: 07-02-2024 01:15 | B13: 28.67 | C13: 59.78 | D13: 56.63 | E13: 0.3 | F13: 3.15 | G13: 69.79 | H13: 25.93 | I13: 1.49 | J13: 0.82 | K13: 348.92 | L13: 19.02 | M13: 77.66 | N13: 63 | O13: 0 | P13: 0.94 | Q13: 9.11
A14: 07-02-2024 01:30 | B14: 26.22 | C14: 59.36 | D14: 54.43 | E14: 0.27 | F14: 3.38 | G14: 69.79 | H14: 25.93 | I14: 1.5 | J14: 0.87 | K14: 346.49 | L14: 18.87 | M14: 78.55 | N14: 62.9 | O14: 0 | P14: 0.92 | Q14: 8.9
A15: 07-02-2024 01:45 | B15: 24.13 | C15: 59.08 | D15: 52.6 | E15: 0.26 | F15: 3.33 | G15: 56.59 | H15: 24.43 | I15: 1.53 | J15: 0.59 | K15: 351.38 | L15: 18.7 | M15: 79.47 | N15: 62.8 | O15: 0 | P15: 0.87 | Q15: 8.76
A16: 07-02-2024 02:00 | B16: 22.34 | C16: 58.49 | D16: 50.84 | E16: 0.26 | F16: 3.2 | G16: 53.06 | H16: 24.43 | I16: 1.53 | J16: 0.2 | K16: 333.16 | L16: 18.53 | M16: 80.57 | N16: 63.1 | O16: 0 | P16: 0.83 | Q16: 8.58
A17: 07-02-2024 02:15 | B17: 21.14 | C17: 57.84 | D17: 49.52 | E17: 0.27 | F17: 3.25 | G17: 53.06 | H17: 24.43 | I17: 1.58 | J17: 0.29 | K17: 82.39 | L17: 18.39 | M17: 81.27 | N17: 62.7 | O17: 0 | P17: 0.81 | Q17: 8.43
A18: 07-02-2024 02:30 | B18: 20.03 | C18: 56.87 | D18: 48.09 | E18: 0.28 | F18: 3.21 | G18: 53.06 | H18: 24.43 | I18: 1.49 | J18: 0.22 | K18: 56 | L18: 18.36 | M18: 81.58 | N18: 62.8 | O18: 0 | P18: 0.78 | Q18: 8.34
A19: 07-02-2024 02:45 | B19: 19 | C19: 56.3 | D19: 46.95 | E19: 0.28 | F19: 3.12 | G19: 49.48 | H19: 23.72 | I19: 1.55 | J19: 0.25 | K19: 2.21 | L19: 18.37 | M19: 81.88 | N19: 63 | O19: 0 | P19: 0.75 | Q19: 8.24
A20: 07-02-2024 03:00 | B20: 17.92 | C20: 52.36 | D20: 43.92 | E20: 0.28 | F20: 3.19 | G20: 48.53 | H20: 23.72 | I20: 1.49 | J20: 0.29 | K20: 79.11 | L20: 18.2 | M20: 82.66 | N20: 63 | O20: 0 | P20: 0.72 | Q20: 8.02
... A104: 07-02-2024 24:00 | B104: 41.33 | C104: 60.06 | D104: 66.94 | E104: 0.09 | F104: 3.24 | G104: 99.19 | H104: 38.99 | I104: 1.61 | J104: 1.4 | K104: 347.31 | L104: 19.25 | M104: 48.02 | N104: 66.5 | O104: 0 | P104: 1.26 | Q104: 10.31
A106: Min | B106: =MIN(B9:B104) -> 2.46 | C106: =MIN(C9:C104) -> 48.81 | D106: =MIN(D9:D104) -> 33.02 | E106: =MIN(E9:E104) -> 0.02 | F106: =MIN(F9:F104) -> 2.75 | G106: =MIN(G9:G104) -> 48.53 | H106: =MIN(H9:H104) -> 23.01 | I106: =MIN(I9:I104) -> 1.42 | ... Q106: =MIN(Q9:Q104) -> 6.87
A107: Max | B107: =MAX(B9:B104) -> 54.95 | C107: =MAX(C9:C104) -> 68.13 | D107: =MAX(D9:D104) -> 80.75 | E107: =MAX(E9:E104) -> 0.37 | F107: =MAX(F9:F104) -> 4.56 | G107: =MAX(G9:G104) -> 122.6 | H107: =MAX(H9:H104) -> 41.18 | I107: =MAX(I9:I104) -> 1.61 | ... Q107: =MAX(Q9:Q104) -> 11.25
A108: Avg | B108: =AVERAGE(B9:B104) -> 19.878854 | C108: =AVERAGE(C9:C104) -> 57.633958 | D108: =AVERAGE(D9:D104) -> 48.393542 | E108: =AVERAGE(E9:E104) -> 0.21020833 | F108: =AVERAGE(F9:F104) -> 3.3598958 | G108: =AVERAGE(G9:G104) -> 70.677188 | H108: =AVERAGE(H9:H104) -> 28.179687 | I108: =AVERAGE(I9:I104) -> 1.5045833 | ... Q108: =AVERAGE(Q9:Q104) -> 8.1985417
A109: Stdev | B109: =STDEV(B9:B104) -> 13.812411 | C109: =STDEV(C9:C104) -> 5.7592935 | D109: =STDEV(D9:D104) -> 12.120892 | E109: =STDEV(E9:E104) -> 0.074466229 | F109: =STDEV(F9:F104) -> 0.41569091 | G109: =STDEV(G9:G104) -> 20.71887 | H109: =STDEV(H9:H104) -> 5.2713447 | I109: =STDEV(I9:I104) -> 0.035211143 | ... Q109: =STDEV(Q9:Q104) -> 1.1015826
A110: Num | B110: =COUNT(B9:B104) -> 96 | C110: =COUNT(C9:C104) -> 96 | D110: =COUNT(D9:D104) -> 96 | E110: =COUNT(E9:E104) -> 96 | F110: =COUNT(F9:F104) -> 96 | G110: =COUNT(G9:G104) -> 96 | H110: =COUNT(H9:H104) -> 96 | I110: =COUNT(I9:I104) -> 96 | ... Q110: =COUNT(Q9:Q104) -> 96
A111: DCR | B111: =IF(B110>=87,">90%",IF(B110<=87,"<90%")) -> >90% | C111: =IF(C110>=87,">90%",IF(C110<=87,"<90%")) -> >90% | D111: =IF(D110>=87,">90%",IF(D110<=87,"<90%")) -> >90% | E111: =IF(E110>=87,">90%",IF(E110<=87,"<90%")) -> >90% | F111: =IF(F110>=87,">90%",IF(F110<=87,"<90%")) -> >90% | G111: =IF(G110>=87,">90%",IF(G110<=87,"<90%")) -> >90% | H111: =IF(H110>=87,">90%",IF(H110<=87,"<90%")) -> >90% | I111: =IF(I110>=87,">90%",IF(I110<=87,"<90%")) -> >90% | ... Q111: =IF(Q110>=87,">90%",IF(Q110<=87,"<90%")) -> >90%
A112: Status | B112: =IF(B110>=87,"OK",IF(B110<=87,"LESS")) -> OK | C112: =IF(C110>=87,"OK",IF(C110<=87,"LESS")) -> OK | D112: =IF(D110>=87,"OK",IF(D110<=87,"LESS")) -> OK | E112: =IF(E110>=87,"OK",IF(E110<=87,"LESS")) -> OK | F112: =IF(F110>=87,"OK",IF(F110<=87,"LESS")) -> OK | G112: =IF(G110>=87,"OK",IF(G110<=87,"LESS")) -> OK | H112: =IF(H110>=87,"OK",IF(H110<=87,"LESS")) -> OK | I112: =IF(I110>=87,"OK",IF(I110<=87,"LESS")) -> OK | ... Q112: =IF(Q110>=87,"OK",IF(Q110<=87,"LESS")) -> OK
A115: Done by | B115: RK
A117: Comment

Sheet 08
A1: Station: | B1: BHATAGAON RAIPUR
A2: Date: | B2: =$A$9 -> 08-02-2024 00:15 | D2: Power Off | G2: Pw.Off | L2: Link Fail | N2: Link F | P2: Maintenance | R2: Maint.
A3: Report Type: | B3: Mean | D3: Calibration | G3: Calib. | L3: Data Fail | N3: Data F | P3: Invalid | R3: Invalid
A4: Time Base: | B4: 15 Min | D4: Zero Referrence | G4: Z.Ref | L4: Warm Up | N4: Wm. Up
A7: Date & Time | B7: NO_BHATAGAON | C7: NO2__BHATAGAON | D7: NOX_BHATAGAON | E7: SO2__BHATAGAON | F7: O3__BHATAGAON | G7: PM10__BHATAGAON | H7: PM2_5__BHATAGAON | I7: BENZ__BHATAGAON | J7: WS__BHATAGAON | K7: WD__BHATAGAON | L7: TEMP__BHATAGAON | M7: HUM__BHATAGAON | N7: SR__BHATAGAON | O7: RG__BHATAGAON | P7: CO__BHATAGAON | Q7: NH3__BHATAGAON
B8: ug/m3 | C8: ug/m3 | D8: ppb | E8: ug/m3 | F8: ug/m3 | G8: ug/m3 | H8: ug/m3 | I8: ug/m3 | J8: m/sec | K8: deg | L8: degreC | M8: % | N8: w/m2 | O8: mm | P8: mg/m3 | Q8: ug/m3
A9: 08-02-2024 00:15 | B9: 36.47 | C9: 61.28 | D9: 63.71 | E9: 0.18 | F9: 3.09 | G9: 99.19 | H9: 38.99 | I9: 1.44 | J9: 0.9 | K9: 356.83 | L9: 19.05 | M9: 45.66 | N9: 66.7 | O9: 0 | P9: 1.16 | Q9: 9.85
A10: 08-02-2024 00:30 | B10: 32.08 | C10: 60.21 | D10: 59.6 | E10: 0.2 | F10: 3.23 | G10: 99.19 | H10: 38.99 | I10: 1.51 | J10: 0.91 | K10: 347.97 | L10: 18.86 | M10: 43.46 | N10: 66.6 | O10: 0 | P10: 1.07 | Q10: 9.37
A11: 08-02-2024 00:45 | B11: 28.36 | C11: 60.45 | D11: 56.75 | E11: 0.12 | F11: 3.24 | G11: 68.14 | H11: 28.98 | I11: 1.56 | J11: 0.83 | K11: 344.81 | L11: 18.65 | M11: 43.62 | N11: 66.7 | O11: 0 | P11: 1 | Q11: 8.96
A12: 08-02-2024 01:00 | B12: 25.16 | C12: 59.65 | D12: 53.74 | E12: 0.1 | F12: 3.36 | G12: 59.83 | H12: 28.98 | I12: 1.58 | J12: 0.67 | K12: 344.86 | L12: 18.38 | M12: 45 | N12: 66.8 | O12: 0 | P12: 0.93 | Q12: 8.62
A13: 08-02-2024 01:15 | B13: 22.58 | C13: 58.95 | D13: 51.29 | E13: 0.16 | F13: 3.34 | G13: 59.83 | H13: 28.98 | I13: 1.46 | J13: 0.81 | K13: 343.84 | L13: 18.22 | M13: 45.05 | N13: 66.5 | O13: 0 | P13: 0.85 | Q13: 8.31
A14: 08-02-2024 01:30 | B14: 20.49 | C14: 58.31 | D14: 49.26 | E14: 0.09 | F14: 3.4 | G14: 59.83 | H14: 28.98 | I14: 1.5 | J14: 0.66 | K14: 346.95 | L14: 18.16 | M14: 43.65 | N14: 66.5 | O14: 0 | P14: 0.82 | Q14: 8.04
A15: 08-02-2024 01:45 | B15: 18.55 | C15: 58.68 | D15: 47.9 | E15: 0.13 | F15: 3.28 | G15: 54.83 | H15: 17.1 | I15: 1.58 | J15: 0.96 | K15: 350.82 | L15: 17.95 | M15: 43.73 | N15: 66.6 | O15: 0 | P15: 0.77 | Q15: 7.82
A16: 08-02-2024 02:00 | B16: 16.74 | C16: 58.06 | D16: 46.11 | E16: 0.15 | F16: 3.18 | G16: 53.49 | H16: 17.1 | I16: 1.48 | J16: 0.92 | K16: 347.79 | L16: 17.79 | M16: 44.67 | N16: 66.7 | O16: 0 | P16: 0.73 | Q16: 7.6
A17: 08-02-2024 02:15 | B17: 15.5 | C17: 58.11 | D17: 45.15 | E17: 0.09 | F17: 3.2 | G17: 53.49 | H17: 17.1 | I17: 1.56 | J17: 0.62 | K17: 347.19 | L17: 17.58 | M17: 45.99 | N17: 66.8 | O17: 0 | P17: 0.69 | Q17: 7.43
A18: 08-02-2024 02:30 | B18: 14.62 | C18: 57.62 | D18: 44.17 | E18: 0.15 | F18: 3.4 | G18: 53.49 | H18: 17.1 | I18: 1.54 | J18: 0.75 | K18: 347.25 | L18: 17.48 | M18: 46.4 | N18: 66.7 | O18: 0 | P18: 0.65 | Q18: 7.25
A19: 08-02-2024 02:45 | B19: 13.87 | C19: 57.78 | D19: 43.66 | E19: 0.1 | F19: 3.3 | G19: 43.42 | H19: 9.23 | I19: 1.47 | J19: 0.46 | K19: 345.18 | L19: 17.31 | M19: 47.55 | N19: 67.1 | O19: 0 | P19: 0.62 | Q19: 7.19
A20: 08-02-2024 03:00 | B20: 13.27 | C20: 57.21 | D20: 42.86 | E20: 0.1 | F20: 3.37 | G20: 40.73 | H20: 9.23 | I20: 1.49 | J20: 0.6 | K20: 349.61 | L20: 17.09 | M20: 47.7 | N20: 66.8 | O20: 0 | P20: 0.59 | Q20: 7.11
... A104: 08-02-2024 24:00 | B104: 91.79 | C104: 65.27 | D104: 110.27 | E104: 0.34 | F104: 2.89 | G104: 105.78 | H104: 35.33 | I104: 1.54 | J104: 1.11 | K104: 334.78 | L104: 15.97 | M104: 57.31 | N104: 56.2 | O104: 0 | P104: 1.83 | Q104: 13.57
A106: Min | B106: =MIN(B9:B104) -> 3.79 | C106: =MIN(C9:C104) -> 54.99 | D106: =MIN(D9:D104) -> 37.81 | E106: =MIN(E9:E104) -> 0 | F106: =MIN(F9:F104) -> 2.89 | G106: =MIN(G9:G104) -> 27.05 | H106: =MIN(H9:H104) -> 6.64 | I106: =MIN(I9:I104) -> 1.4 | ... Q106: =MIN(Q9:Q104) -> 5.12
A107: Max | B107: =MAX(B9:B104) -> 115.83 | C107: =MAX(C9:C104) -> 71.78 | D107: =MAX(D9:D104) -> 130.14 | E107: =MAX(E9:E104) -> 0.85 | F107: =MAX(F9:F104) -> 6.85 | G107: =MAX(G9:G104) -> 132.93 | H107: =MAX(H9:H104) -> 38.99 | I107: =MAX(I9:I104) -> 1.62 | ... Q107: =MAX(Q9:Q104) -> 15.86
A108: Avg | B108: =AVERAGE(B9:B104) -> 25.303646 | C108: =AVERAGE(C9:C104) -> 62.618437 | D108: =AVERAGE(D9:D104) -> 55.495417 | E108: =AVERAGE(E9:E104) -> 0.2490625 | F108: =AVERAGE(F9:F104) -> 3.6355208 | G108: =AVERAGE(G9:G104) -> 65.859271 | H108: =AVERAGE(H9:H104) -> 20.967083 | I108: =AVERAGE(I9:I104) -> 1.5051042 | ... Q108: =AVERAGE(Q9:Q104) -> 8.8941667
A109: Stdev | B109: =STDEV(B9:B104) -> 31.706481 | C109: =STDEV(C9:C104) -> 4.5367499 | D109: =STDEV(D9:D104) -> 26.296591 | E109: =STDEV(E9:E104) -> 0.15532701 | F109: =STDEV(F9:F104) -> 0.71384927 | G109: =STDEV(G9:G104) -> 28.408524 | H109: =STDEV(H9:H104) -> 8.4105458 | I109: =STDEV(I9:I104) -> 0.04928958 | ... Q109: =STDEV(Q9:Q104) -> 2.8803423
A110: Num | B110: =COUNT(B9:B104) -> 96 | C110: =COUNT(C9:C104) -> 96 | D110: =COUNT(D9:D104) -> 96 | E110: =COUNT(E9:E104) -> 96 | F110: =COUNT(F9:F104) -> 96 | G110: =COUNT(G9:G104) -> 96 | H110: =COUNT(H9:H104) -> 96 | I110: =COUNT(I9:I104) -> 96 | ... Q110: =COUNT(Q9:Q104) -> 96
A111: DCR | B111: =IF(B110>=87,">90%",IF(B110<=87,"<90%")) -> >90% | C111: =IF(C110>=87,">90%",IF(C110<=87,"<90%")) -> >90% | D111: =IF(D110>=87,">90%",IF(D110<=87,"<90%")) -> >90% | E111: =IF(E110>=87,">90%",IF(E110<=87,"<90%")) -> >90% | F111: =IF(F110>=87,">90%",IF(F110<=87,"<90%")) -> >90% | G111: =IF(G110>=87,">90%",IF(G110<=87,"<90%")) -> >90% | H111: =IF(H110>=87,">90%",IF(H110<=87,"<90%")) -> >90% | I111: =IF(I110>=87,">90%",IF(I110<=87,"<90%")) -> >90% | ... Q111: =IF(Q110>=87,">90%",IF(Q110<=87,"<90%")) -> >90%
A112: Status | B112: =IF(B110>=87,"OK",IF(B110<=87,"LESS")) -> OK | C112: =IF(C110>=87,"OK",IF(C110<=87,"LESS")) -> OK | D112: =IF(D110>=87,"OK",IF(D110<=87,"LESS")) -> OK | E112: =IF(E110>=87,"OK",IF(E110<=87,"LESS")) -> OK | F112: =IF(F110>=87,"OK",IF(F110<=87,"LESS")) -> OK | G112: =IF(G110>=87,"OK",IF(G110<=87,"LESS")) -> OK | H112: =IF(H110>=87,"OK",IF(H110<=87,"LESS")) -> OK | I112: =IF(I110>=87,"OK",IF(I110<=87,"LESS")) -> OK | ... Q112: =IF(Q110>=87,"OK",IF(Q110<=87,"LESS")) -> OK
A115: Done by | B115: RK
A117: Comment

Sheet 09
A1: Station: | B1: BHATAGAON RAIPUR
A2: Date: | B2: =$A$9 -> 09-02-2024 00:15 | D2: Power Off | G2: Pw.Off | L2: Link Fail | N2: Link F | P2: Maintenance | R2: Maint.
A3: Report Type: | B3: Mean | D3: Calibration | G3: Calib. | L3: Data Fail | N3: Data F | P3: Invalid | R3: Invalid
A4: Time Base: | B4: 15 Min | D4: Zero Referrence | G4: Z.Ref | L4: Warm Up | N4: Wm. Up
A7: Date & Time | B7: NO_BHATAGAON | C7: NO2__BHATAGAON | D7: NOX_BHATAGAON | E7: SO2__BHATAGAON | F7: O3__BHATAGAON | G7: PM10__BHATAGAON | H7: PM2_5__BHATAGAON | I7: BENZ__BHATAGAON | J7: WS__BHATAGAON | K7: WD__BHATAGAON | L7: TEMP__BHATAGAON | M7: HUM__BHATAGAON | N7: SR__BHATAGAON | O7: RG__BHATAGAON | P7: CO__BHATAGAON | Q7: NH3__BHATAGAON
B8: ug/m3 | C8: ug/m3 | D8: ppb | E8: ug/m3 | F8: ug/m3 | G8: ug/m3 | H8: ug/m3 | I8: ug/m3 | J8: m/sec | K8: deg | L8: degreC | M8: % | N8: w/m2 | O8: mm | P8: mg/m3 | Q8: ug/m3
A9: 09-02-2024 00:15 | B9: 83.63 | C9: 64.84 | D9: 103.5 | E9: 0.45 | F9: 3.03 | G9: 105.78 | H9: 35.33 | I9: 1.55 | J9: 0.42 | K9: 324.24 | L9: 15.7 | M9: 60.81 | N9: 57 | O9: 0 | P9: 1.73 | Q9: 13
A10: 09-02-2024 00:30 | B10: 77.82 | C10: 64.13 | D10: 98.44 | E10: 0.44 | F10: 3.09 | G10: 105.78 | H10: 35.33 | I10: 1.51 | J10: 0.74 | K10: 353.2 | L10: 15.47 | M10: 61.14 | N10: 56.3 | O10: 0 | P10: 1.66 | Q10: 12.48
A11: 09-02-2024 00:45 | B11: 72.8 | C11: 63.75 | D11: 94.21 | E11: 0.41 | F11: 3.2 | G11: 89.37 | H11: 32.09 | I11: 1.5 | J11: 0.87 | K11: 352.33 | L11: 15.7 | M11: 57.58 | N11: 55.9 | O11: 0 | P11: 1.59 | Q11: 12.08
A12: 09-02-2024 01:00 | B12: 68.11 | C12: 63.61 | D12: 90.37 | E12: 0.38 | F12: 3.02 | G12: 84.97 | H12: 32.09 | I12: 1.54 | J12: 0.84 | K12: 349.41 | L12: 16 | M12: 49.02 | N12: 56.1 | O12: 0 | P12: 1.51 | Q12: 11.74
A13: 09-02-2024 01:15 | B13: 63.18 | C13: 63.32 | D13: 86.26 | E13: 0.35 | F13: 3.09 | G13: 84.97 | H13: 32.09 | I13: 1.56 | J13: 0.83 | K13: 351.97 | L13: 15.79 | M13: 54.28 | N13: 56.6 | O13: 0 | P13: 1.26 | Q13: 11.4
A14: 09-02-2024 01:30 | B14: 58.66 | C14: 62.68 | D14: 82.27 | E14: 0.36 | F14: 3.16 | G14: 84.97 | H14: 32.09 | I14: 1.52 | J14: 0.72 | K14: 351.09 | L14: 15.46 | M14: 57.32 | N14: 56.7 | O14: 0 | P14: 1.25 | Q14: 11.08
A15: 09-02-2024 01:45 | B15: 55.13 | C15: 61.91 | D15: 79.02 | E15: 0.39 | F15: 3.35 | G15: 77.37 | H15: 28.9 | I15: 1.44 | J15: 0.98 | K15: 351.36 | L15: 15.18 | M15: 59.18 | N15: 56.3 | O15: 0 | P15: 1.2 | Q15: 10.78
