Workbook

Sheet 01
A1: Station: | B1: BHATAGAON RAIPUR
A2: Date: | B2: =$A$9 -> 01/05/2025 00:15 | D2: Power Off | G2: Pw.Off | L2: Link Fail | N2: Link F | P2: Maintenance | R2: Maint.
A3: Report Type: | B3: Mean | D3: Calibration | G3: Calib. | L3: Data Fail | N3: Data F | P3: Invalid | R3: Invalid
A4: Time Base: | B4: 15 Min | D4: Zero Referrence | G4: Z.Ref | L4: Warm Up | N4: Wm. Up
A7: Date & Time | B7: NO_BHATAGAON | C7: NO2__BHATAGAON | D7: NOX_BHATAGAON | E7: SO2__BHATAGAON | F7: O3__BHATAGAON | G7: PM10__BHATAGAON | H7: PM2_5__BHATAGAON | I7: BENZ__BHATAGAON | J7: WS__BHATAGAON | K7: WD__BHATAGAON | L7: TEMP__BHATAGAON | M7: HUM__BHATAGAON | N7: SR__BHATAGAON | O7: RG__BHATAGAON | P7: CO__BHATAGAON | Q7: NH3__BHATAGAON
B8: ug/m3 | C8: ug/m3 | D8: ppb | E8: ug/m3 | F8: ug/m3 | G8: ug/m3 | H8: ug/m3 | I8: ug/m3 | J8: m/sec | K8: deg | L8: degreC | M8: % | N8: w/m2 | O8: mm | P8: mg/m3 | Q8: ug/m3
A9: 01/05/2025 00:15 | B9: 5.2 | C9: 25.89 | D9: 41.56 | E9: 3.01 | F9: 7.26 | G9: 21.51 | H9: 8.27 | I9: 4.13 | J9: 3.2 | K9: 91.32 | L9: 29.24 | M9: 62.55 | N9: 138.2 | O9: 0 | P9: 0.37 | Q9: 9.52
A10: 01/05/2025 00:30 | B10: 4.84 | C10: 22.95 | D10: 36.5 | E10: 2.84 | F10: 8.38 | G10: 21.51 | H10: 8.27 | I10: 3.83 | J10: 2.33 | K10: 93.51 | L10: 29.1 | M10: 62.79 | N10: 194.6 | O10: 0 | P10: 0.35 | Q10: 9.52
A11: 01/05/2025 00:45 | B11: 4.5 | C11: 23.62 | D11: 38.31 | E11: 2.72 | F11: 8.71 | G11: 21.51 | H11: 8.27 | I11: 3.9 | J11: 1.52 | K11: 121.37 | L11: 29.07 | M11: 61.82 | N11: 180.7 | O11: 0 | P11: 0.35 | Q11: 9.49
A12: 01/05/2025 01:00 | B12: 3.99 | C12: 21.92 | D12: 35.83 | E12: 2.42 | F12: 8.67 | G12: 21.81 | H12: 6.64 | I12: 4.02 | J12: 1.61 | K12: 155.12 | L12: 28.97 | M12: 61.74 | N12: 190.5 | O12: 0 | P12: 0.34 | Q12: 9.47
A13: 01/05/2025 01:15 | B13: 3.77 | C13: 22.69 | D13: 37.65 | E13: 2.58 | F13: 7.75 | G13: 21.9 | H13: 6.17 | I13: 4.02 | J13: 1.52 | K13: 151.35 | L13: 28.79 | M13: 62.53 | N13: 172 | O13: 0 | P13: 0.32 | Q13: 9.47
A14: 01/05/2025 01:30 | B14: 3.54 | C14: 21.11 | D14: 34.97 | E14: 2.46 | F14: 8.6 | G14: 21.9 | H14: 6.17 | I14: 4.05 | J14: 0.28 | K14: 127.02 | L14: 28.68 | M14: 62.97 | N14: 165.9 | O14: 0 | P14: 0.33 | Q14: 9.45
A15: 01/05/2025 01:45 | B15: 3.59 | C15: 22.25 | D15: 37.07 | E15: 2.49 | F15: 7.04 | G15: 21.9 | H15: 6.17 | I15: 4.11 | J15: 2 | K15: 181.42 | L15: 28.64 | M15: 63.03 | N15: 125.9 | O15: 0 | P15: 0.33 | Q15: 9.45
A16: 01/05/2025 02:00 | B16: 3.26 | C16: 20.08 | D16: 33.43 | E16: 2.36 | F16: 9.34 | G16: 15.99 | H16: 7.98 | I16: 4.07 | J16: 1.29 | K16: 200.23 | L16: 28.5 | M16: 63.94 | N16: 139.9 | O16: 0 | P16: 0.29 | Q16: 9.43
A17: 01/05/2025 02:15 | B17: 3.45 | C17: 21.98 | D17: 36.78 | E17: 2.66 | F17: 8.56 | G17: 14.31 | H17: 8.5 | I17: 3.85 | J17: 1.99 | K17: 265.65 | L17: 28.16 | M17: 67.21 | N17: 147.6 | O17: 0 | P17: 0.32 | Q17: 9.41
A18: 01/05/2025 02:30 | B18: 6.86 | C18: 27.22 | D18: 41.57 | E18: 2.58 | F18: 10.31 | G18: 14.31 | H18: 8.5 | I18: 3.96 | J18: 2.1 | K18: 271.75 | L18: 27.61 | M18: 74.35 | N18: 127.6 | O18: 0 | P18: 0.35 | Q18: 9.42
A19: 01/05/2025 02:45 | B19: 5.67 | C19: 25.15 | D19: 39.44 | E19: 2.39 | F19: 11.33 | G19: 14.31 | H19: 8.5 | I19: 4.11 | J19: 2 | K19: 274.68 | L19: 27.23 | M19: 76.37 | N19: 146.9 | O19: 0 | P19: 0.29 | Q19: 9.4
A20: 01/05/2025 03:00 | B20: 3.49 | C20: 19.94 | D20: 32.82 | E20: 2.22 | F20: 13.36 | G20: 17.96 | H20: 6.69 | I20: 3.9 | J20: 1.08 | K20: 38.47 | L20: 27.04 | M20: 75.56 | N20: 143.2 | O20: 0 | P20: 0.26 | Q20: 9.39
... A83: 01/05/2025 18:45 | B83: 3.12 | C83: 25.64 | D83: 44.28 | E83: 3.17 | F83: 6.92 | G83: 32.14 | H83: 12.49 | I83: 4.2 | J83: 2.4 | K83: 83.05 | L83: 14.64 | M83: 81.62 | N83: 45 | O83: 0 | P83: 0.32 | Q83: 9.46
A84: 01/05/2025 19:00 | B84: Pw.Off | C84: Pw.Off | D84: Pw.Off | E84: Pw.Off | F84: Pw.Off | G84: Pw.Off | H84: Pw.Off | I84: Pw.Off | J84: Pw.Off | K84: Pw.Off | L84: Pw.Off | M84: Pw.Off | N84: Pw.Off | O84: Pw.Off | P84: Pw.Off | Q84: Pw.Off
A85: 01/05/2025 19:15 | B85: Pw.Off | C85: Pw.Off | D85: Pw.Off | E85: Pw.Off | F85: Pw.Off | G85: Pw.Off | H85: Pw.Off | I85: Pw.Off | J85: Pw.Off | K85: Pw.Off | L85: Pw.Off | M85: Pw.Off | N85: Pw.Off | O85: Pw.Off | P85: Pw.Off | Q85: Pw.Off
A86: 01/05/2025 19:30 | B86: Pw.Off | C86: Pw.Off | D86: Pw.Off | E86: Pw.Off | F86: Pw.Off | G86: Pw.Off | H86: Pw.Off | I86: Pw.Off | J86: Pw.Off | K86: Pw.Off | L86: Pw.Off | M86: Pw.Off | N86: Pw.Off | O86: Pw.Off | P86: Pw.Off | Q86: Pw.Off
A87: 01/05/2025 19:45 | B87: Pw.Off | C87: Pw.Off | D87: Pw.Off | E87: Pw.Off | F87: Pw.Off | G87: Pw.Off | H87: Pw.Off | I87: Pw.Off | J87: Pw.Off | K87: Pw.Off | L87: Pw.Off | M87: Pw.Off | N87: Pw.Off | O87: Pw.Off | P87: Pw.Off | Q87: Pw.Off
A88: 01/05/2025 20:00 | B88: Pw.Off | C88: Pw.Off | D88: Pw.Off | E88: Pw.Off | F88: Pw.Off | G88: Pw.Off | H88: Pw.Off | I88: Pw.Off | J88: Pw.Off | K88: Pw.Off | L88: Pw.Off | M88: Pw.Off | N88: Pw.Off | O88: Pw.Off | P88: Pw.Off | Q88: Pw.Off
A89: 01/05/2025 20:15 | B89: Pw.Off | C89: Pw.Off | D89: Pw.Off | E89: Pw.Off | F89: Pw.Off | G89: Pw.Off | H89: Pw.Off | I89: Pw.Off | J89: Pw.Off | K89: Pw.Off | L89: Pw.Off | M89: Pw.Off | N89: Pw.Off | O89: Pw.Off | P89: Pw.Off | Q89: Pw.Off
A90: 01/05/2025 20:30 | B90: Pw.Off | C90: Pw.Off | D90: Pw.Off | E90: Pw.Off | F90: Pw.Off | G90: Pw.Off | H90: Pw.Off | I90: Pw.Off | J90: Pw.Off | K90: Pw.Off | L90: Pw.Off | M90: Pw.Off | N90: Pw.Off | O90: Pw.Off | P90: Pw.Off | Q90: Pw.Off
A91: 01/05/2025 20:45 | B91: Pw.Off | C91: Pw.Off | D91: Pw.Off | E91: Pw.Off | F91: Pw.Off | G91: Pw.Off | H91: Pw.Off | I91: Pw.Off | J91: Pw.Off | K91: Pw.Off | L91: Pw.Off | M91: Pw.Off | N91: Pw.Off | O91: Pw.Off | P91: Pw.Off | Q91: Pw.Off
A92: 01/05/2025 21:00 | B92: Pw.Off | C92: Pw.Off | D92: Pw.Off | E92: Pw.Off | F92: Pw.Off | G92: Pw.Off | H92: Pw.Off | I92: Pw.Off | J92: Pw.Off | K92: Pw.Off | L92: Pw.Off | M92: Pw.Off | N92: Pw.Off | O92: Pw.Off | P92: Pw.Off | Q92: Pw.Off
A93: 01/05/2025 21:15 | B93: Pw.Off | C93: Pw.Off | D93: Pw.Off | E93: Pw.Off | F93: Pw.Off | G93: Pw.Off | H93: Pw.Off | I93: Pw.Off | J93: Pw.Off | K93: Pw.Off | L93: Pw.Off | M93: Pw.Off | N93: Pw.Off | O93: Pw.Off | P93: Pw.Off | Q93: Pw.Off
A94: 01/05/2025 21:30 | B94: Pw.Off | C94: Pw.Off | D94: Pw.Off | E94: Pw.Off | F94: Pw.Off | G94: Pw.Off | H94: Pw.Off | I94: Pw.Off | J94: Pw.Off | K94: Pw.Off | L94: Pw.Off | M94: Pw.Off | N94: Pw.Off | O94: Pw.Off | P94: Pw.Off | Q94: Pw.Off
A95: 01/05/2025 21:45 | B95: Pw.Off | C95: Pw.Off | D95: Pw.Off | E95: Pw.Off | F95: Pw.Off | G95: Pw.Off | H95: Pw.Off | I95: Pw.Off | J95: Pw.Off | K95: Pw.Off | L95: Pw.Off | M95: Pw.Off | N95: Pw.Off | O95: Pw.Off | P95: Pw.Off | Q95: Pw.Off
... A99: 01/05/2025 22:45 | B99: Pw.Off | C99: Pw.Off | D99: Pw.Off | E99: Pw.Off | F99: Pw.Off | G99: Pw.Off | H99: Pw.Off | I99: Pw.Off | J99: Pw.Off | K99: Pw.Off | L99: Pw.Off | M99: Pw.Off | N99: Pw.Off | O99: Pw.Off | P99: Pw.Off | Q99: Pw.Off
A100: 01/05/2025 23:00 | B100: Wm. Up | C100: Wm. Up | D100: Wm. Up | E100: Wm. Up | F100: 6.29 | G100: 0.2 | H100: 9.76 | I100: 3.95 | J100: 1.36 | K100: 152.87 | L100: 24.47 | M100: 91.26 | N100: 45.1 | O100: 0 | P100: 0.13 | Q100: Wm. Up
A101: 01/05/2025 23:15 | B101: Wm. Up | C101: Wm. Up | D101: Wm. Up | E101: 2.18 | F101: 8.53 | G101: 0 | H101: 8.74 | I101: 3.99 | J101: 1.14 | K101: 233.56 | L101: 0.94 | M101: 92.7 | N101: 45.3 | O101: 0 | P101: 0.07 | Q101: Wm. Up
A102: 01/05/2025 23:30 | B102: Wm. Up | C102: Wm. Up | D102: Wm. Up | E102: Wm. Up | F102: 56.07 | G102: 0.04 | H102: 8.74 | I102: 4.19 | J102: 0.95 | K102: 232.19 | L102: 24.1 | M102: 94 | N102: 45.3 | O102: 0 | P102: 0.18 | Q102: Wm. Up
A103: 01/05/2025 23:45 | B103: 3.23 | C103: 15.23 | D103: 24.2 | E103: 1.88 | F103: 5.55 | G103: 0.04 | H103: 8.74 | I103: 3.9 | J103: 0.77 | K103: 224.93 | L103: 23.99 | M103: 94.43 | N103: 45.2 | O103: 0 | P103: 0.21 | Q103: 8.24
A104: 01/05/2025 24:00 | B104: 4.53 | C104: 23.55 | D104: 38.11 | E104: 1.2 | F104: 6.19 | G104: 18.04 | H104: 6.7 | I104: 4 | J104: 1.09 | K104: 229.45 | L104: 23.98 | M104: 94.45 | N104: 45.1 | O104: 0 | P104: 0.18 | Q104: 9.65
A106: Min | B106: =MIN(B9:B104) -> 1.95 | C106: =MIN(C9:C104) -> 15.23 | D106: =MIN(D9:D104) -> 24.2 | E106: =MIN(E9:E104) -> 1.2 | F106: =MIN(F9:F104) -> 5.55 | G106: =MIN(G9:G104) -> 0 | H106: =MIN(H9:H104) -> 4.41 | I106: =MIN(I9:I104) -> 3.82 | ... Q106: =MIN(Q9:Q104) -> 8.24
A107: Max | B107: =MAX(B9:B104) -> 22.55 | C107: =MAX(C9:C104) -> 41.35 | D107: =MAX(D9:D104) -> 59.84 | E107: =MAX(E9:E104) -> 4.6 | F107: =MAX(F9:F104) -> 56.07 | G107: =MAX(G9:G104) -> 535.11 | H107: =MAX(H9:H104) -> 12.73 | I107: =MAX(I9:I104) -> 4.24 | ... Q107: =MAX(Q9:Q104) -> 9.65
A108: Avg | B108: =AVERAGE(B9:B104) -> 6.0125974 | C108: =AVERAGE(C9:C104) -> 25.007403 | D108: =AVERAGE(D9:D104) -> 38.635844 | E108: =AVERAGE(E9:E104) -> 3.0810256 | F108: =AVERAGE(F9:F104) -> 12.4245 | G108: =AVERAGE(G9:G104) -> 47.978875 | H108: =AVERAGE(H9:H104) -> 7.566875 | I108: =AVERAGE(I9:I104) -> 4.008375 | ... Q108: =AVERAGE(Q9:Q104) -> 9.4266234
...

Sheet 02
A1: Station: | B1: BHATAGAON RAIPUR
A2: Date: | B2: =$A$9 -> 02/05/2025 00:15 | D2: Power Off | G2: Pw.Off | L2: Link Fail | N2: Link F | P2: Maintenance | R2: Maint.
A3: Report Type: | B3: Mean | D3: Calibration | G3: Calib. | L3: Data Fail | N3: Data F | P3: Invalid | R3: Invalid
A4: Time Base: | B4: 15 Min | D4: Zero Referrence | G4: Z.Ref | L4: Warm Up | N4: Wm. Up
A7: Date & Time | B7: NO_BHATAGAON | C7: NO2__BHATAGAON | D7: NOX_BHATAGAON | E7: SO2__BHATAGAON | F7: O3__BHATAGAON | G7: PM10__BHATAGAON | H7: PM2_5__BHATAGAON | I7: BENZ__BHATAGAON | J7: WS__BHATAGAON | K7: WD__BHATAGAON | L7: TEMP__BHATAGAON | M7: HUM__BHATAGAON | N7: SR__BHATAGAON | O7: RG__BHATAGAON | P7: CO__BHATAGAON | Q7: NH3__BHATAGAON
B8: ug/m3 | C8: ug/m3 | D8: ppb | E8: ug/m3 | F8: ug/m3 | G8: ug/m3 | H8: ug/m3 | I8: ug/m3 | J8: m/sec | K8: deg | L8: degreC | M8: % | N8: w/m2 | O8: mm | P8: mg/m3 | Q8: ug/m3
A9: 02/05/2025 00:15 | B9: 4.61 | C9: 24.37 | D9: 39.56 | E9: Data F | F9: 5.59 | G9: 22.92 | H9: 6.12 | I9: 4.01 | J9: 0.74 | K9: 274.83 | L9: 23.78 | M9: 96.32 | N9: 45.2 | O9: 0 | P9: 0.15 | Q9: 9.67
A10: 02/05/2025 00:30 | B10: 4.83 | C10: 23.98 | D10: 38.48 | E10: Data F | F10: 5.38 | G10: 22.92 | H10: 6.12 | I10: 3.99 | J10: 0.61 | K10: 250.1 | L10: 23.58 | M10: 98.42 | N10: 45.4 | O10: 0 | P10: 0.15 | Q10: 9.63
A11: 02/05/2025 00:45 | B11: 5.3 | C11: 23.47 | D11: 36.8 | E11: Data F | F11: 5.71 | G11: 22.92 | H11: 6.12 | I11: 3.98 | J11: 0.18 | K11: 291.84 | L11: 23.57 | M11: 98.14 | N11: 45.1 | O11: 0 | P11: 0.15 | Q11: 9.64
A12: 02/05/2025 01:00 | B12: 5.58 | C12: 24.28 | D12: 37.92 | E12: Data F | F12: 5.21 | G12: 29.24 | H12: 4.93 | I12: 4.01 | J12: 0.42 | K12: 325.21 | L12: 23.55 | M12: 98.35 | N12: 45.1 | O12: 0 | P12: 0.13 | Q12: 9.63
A13: 02/05/2025 01:15 | B13: 6.09 | C13: 22.88 | D13: 34.45 | E13: Data F | F13: 6.03 | G13: 31.05 | H13: 4.59 | I13: 4.06 | J13: 0.8 | K13: 49.93 | L13: 23.6 | M13: 97.5 | N13: 45.1 | O13: 0 | P13: 0.3 | Q13: 9.64
A14: 02/05/2025 01:30 | B14: 6.55 | C14: 25.07 | D14: 37.93 | E14: Data F | F14: 5.04 | G14: 31.05 | H14: 4.59 | I14: 3.85 | J14: 0.71 | K14: 23.51 | L14: 23.88 | M14: 96.47 | N14: 44.9 | O14: 0 | P14: 0.31 | Q14: 9.62
A15: 02/05/2025 01:45 | B15: 6.84 | C15: 23.9 | D15: 35.25 | E15: Data F | F15: 5.46 | G15: 31.05 | H15: 4.59 | I15: 4.13 | J15: 0.29 | K15: 63.47 | L15: 24.19 | M15: 95.52 | N15: 45 | O15: 0 | P15: 0.33 | Q15: 9.62
A16: 02/05/2025 02:00 | B16: 7.1 | C16: 25.8 | D16: 38.5 | E16: Data F | F16: 5.8 | G16: 21.14 | H16: 6.41 | I16: 4.04 | J16: 0.47 | K16: 96.26 | L16: 24.14 | M16: 95.95 | N16: 44.9 | O16: 0 | P16: 0.31 | Q16: 9.62
A17: 02/05/2025 02:15 | B17: 7.07 | C17: 25.28 | D17: 37.54 | E17: Data F | F17: 6.21 | G17: 18.31 | H17: 6.93 | I17: 3.96 | J17: 1.91 | K17: 98.16 | L17: 24.12 | M17: 96.07 | N17: 45.1 | O17: 0 | P17: 0.31 | Q17: 9.67
A18: 02/05/2025 02:30 | B18: 7.17 | C18: 23.99 | D18: 34.92 | E18: Data F | F18: 5.76 | G18: 18.31 | H18: 6.93 | I18: 3.89 | J18: 1.61 | K18: 96.86 | L18: 23.91 | M18: 97.23 | N18: 45.6 | O18: 0 | P18: 0.3 | Q18: 9.66
A19: 02/05/2025 02:45 | B19: 7.18 | C19: 23.13 | D19: 33.25 | E19: Data F | F19: 5.87 | G19: 18.31 | H19: 6.93 | I19: 3.98 | J19: 1.17 | K19: 109.42 | L19: 23.84 | M19: 97.03 | N19: 45.4 | O19: 0 | P19: 0.3 | Q19: 9.64
A20: 02/05/2025 03:00 | B20: 6.7 | C20: 22.49 | D20: 32.77 | E20: Data F | F20: 6.18 | G20: 14.53 | H20: 5.66 | I20: 4.04 | J20: 0.7 | K20: 95.83 | L20: 23.8 | M20: 97.19 | N20: 45.6 | O20: 0 | P20: 0.29 | Q20: 9.62
... A39: 02/05/2025 07:45 | B39: 11.06 | C39: 26.96 | D39: 34.62 | E39: Data F | F39: 6.12 | G39: 12.9 | H39: 6.99 | I39: 4.14 | J39: 1.32 | K39: 95.9 | L39: 27.3 | M39: 80.15 | N39: 396.9 | O39: 0 | P39: 0.28 | Q39: 9.64
A40: 02/05/2025 08:00 | B40: 11.69 | C40: 29.73 | D40: 38.96 | E40: 1.95 | F40: 6.91 | G40: 11.66 | H40: 5.71 | I40: 4.08 | J40: 0.46 | K40: 79.51 | L40: 28.45 | M40: 77.19 | N40: 440.7 | O40: 0 | P40: 0.3 | Q40: 9.65
A41: 02/05/2025 08:15 | B41: 11.91 | C41: 29.39 | D41: 37.97 | E41: 2.27 | F41: 6.89 | G41: 11.3 | H41: 5.34 | I41: 3.89 | J41: 0.32 | K41: 23.37 | L41: 29.58 | M41: 71.54 | N41: 510.1 | O41: 0 | P41: 0.3 | Q41: 9.64
A42: 02/05/2025 08:30 | B42: 12.69 | C42: 29.02 | D42: 36.07 | E42: 1.91 | F42: 6.29 | G42: 11.3 | H42: 5.34 | I42: 3.92 | J42: 0.65 | K42: 331.89 | L42: 30.69 | M42: 68.59 | N42: 557.6 | O42: 0 | P42: 0.31 | Q42: 9.63
A43: 02/05/2025 08:45 | B43: 13.04 | C43: 31.29 | D43: 39.87 | E43: 2.64 | F43: 6.3 | G43: 11.3 | H43: 5.34 | I43: 3.99 | J43: 0.69 | K43: 347.84 | L43: 32.11 | M43: 63.02 | N43: 611.9 | O43: 0 | P43: 0.32 | Q43: 9.65
A44: 02/05/2025 09:00 | B44: 13.13 | C44: 31.99 | D44: 41.08 | E44: 2.25 | F44: 6.79 | G44: 10.55 | H44: 5.61 | I44: 3.9 | J44: 0.58 | K44: 328.77 | L44: 32.93 | M44: 59.94 | N44: 665.2 | O44: 0 | P44: 0.35 | Q44: 9.64
A45: 02/05/2025 09:15 | B45: 11.66 | C45: 29.35 | D45: 38.27 | E45: 2.17 | F45: 7.03 | G45: 10.33 | H45: 5.69 | I45: 4 | J45: 0.41 | K45: 272.33 | L45: 32.84 | M45: 61.7 | N45: 761.4 | O45: 0 | P45: 0.35 | Q45: 9.65
A46: 02/05/2025 09:30 | B46: 12.57 | C46: 31.88 | D46: 41.72 | E46: 2.18 | F46: 6.39 | G46: 10.33 | H46: 5.69 | I46: 4.1 | J46: 1.28 | K46: 279.29 | L46: 34.96 | M46: 53.33 | N46: 770 | O46: 0 | P46: 0.38 | Q46: 9.63
A47: 02/05/2025 09:45 | B47: 12.51 | C47: 34.46 | D47: 46.75 | E47: 2.4 | F47: 6.8 | G47: 10.33 | H47: 5.69 | I47: 4.16 | J47: 0.5 | K47: 341.29 | L47: 35.11 | M47: 52.81 | N47: 782.4 | O47: 0 | P47: 0.42 | Q47: 9.65
A48: 02/05/2025 10:00 | B48: 11.4 | C48: 32.92 | D48: 45.52 | E48: 2.37 | F48: 7.75 | G48: 28.91 | H48: 7.8 | I48: 4 | J48: 1.09 | K48: 272.65 | L48: 35.26 | M48: 51.45 | N48: 812.6 | O48: 0 | P48: 0.43 | Q48: 9.63
A49: 02/05/2025 10:15 | B49: 10.17 | C49: 31.01 | D49: 43.75 | E49: 2.03 | F49: 6.27 | G49: 34.21 | H49: 8.4 | I49: 4 | J49: 0.64 | K49: 257.31 | L49: 35.74 | M49: 48.08 | N49: 859.2 | O49: 0 | P49: 0.45 | Q49: 9.63
A50: 02/05/2025 10:30 | B50: 7.88 | C50: 29.99 | D50: 45.31 | E50: 2 | F50: 8.43 | G50: 34.21 | H50: 8.4 | I50: 3.99 | J50: 0.76 | K50: 250.64 | L50: 35.27 | M50: 47.99 | N50: 887 | O50: 0 | P50: 0.45 | Q50: 9.64
A51: 02/05/2025 10:45 | B51: 1.39 | C51: 25.12 | D51: 45.95 | E51: 2.35 | F51: 14.32 | G51: 34.21 | H51: 8.4 | I51: 4.12 | J51: 1.2 | K51: 276.51 | L51: 36.7 | M51: 44.26 | N51: 913.4 | O51: 0 | P51: 0.49 | Q51: 9.67
A52: 02/05/2025 11:00 | B52: -0.09 | C52: 4.04 | D52: 7.87 | E52: 2.89 | F52: 20.44 | G52: 34.21 | H52: 8.4 | I52: 4.2 | J52: 0.53 | K52: 118.33 | L52: 35.51 | M52: 47.07 | N52: 919.3 | O52: 0 | P52: 0.53 | Q52: 9.6
A53: 02/05/2025 11:15 | B53: 0.01 | C53: 4.58 | D53: 8.75 | E53: 3.88 | F53: 17.25 | G53: Calib. | H53: Calib. | I53: 3.97 | J53: 0.34 | K53: 204.07 | L53: 35.48 | M53: 46.72 | N53: 916.2 | O53: 0 | P53: 0.54 | Q53: 9.56
A54: 02/05/2025 11:30 | B54: 2.96 | C54: 55.94 | D54: 60.55 | E54: 3.66 | F54: 19.33 | G54: Calib. | H54: Calib. | I54: 4.16 | J54: 0.37 | K54: 103.96 | L54: 36.24 | M54: 45.45 | N54: 884.3 | O54: 0 | P54: 0.61 | Q54: 9.55
A55: 02/05/2025 11:45 | B55: 2.52 | C55: 32.26 | D55: 57.89 | E55: 35.89 | F55: 23.03 | G55: Calib. | H55: Calib. | I55: 4.09 | J55: 0.19 | K55: 30.01 | L55: 35.43 | M55: 47.79 | N55: 883.4 | O55: 0 | P55: 0.66 | Q55: 9.55
A56: 02/05/2025 12:00 | B56: 5.06 | C56: 42.95 | D56: 74.43 | E56: Calib. | F56: 20.85 | G56: Calib. | H56: Calib. | I56: 4.13 | J56: 0.65 | K56: 312.4 | L56: 36.85 | M56: 45.19 | N56: 844.2 | O56: 0 | P56: 0.86 | Q56: 9.55
A57: 02/05/2025 12:15 | B57: 6.21 | C57: 41.47 | D57: 69.84 | E57: Calib. | F57: 15.65 | G57: 89.87 | H57: 27.85 | I57: 3.85 | J57: 1.4 | K57: 288.09 | L57: 38.16 | M57: 40.86 | N57: 858.6 | O57: 0 | P57: 0.82 | Q57: 9.54
A58: 02/05/2025 12:30 | B58: 3.24 | C58: 41.64 | D58: 74.72 | E58: Calib. | F58: 20.15 | G58: 89.87 | H58: 27.85 | I58: 4.08 | J58: 0.82 | K58: 112.35 | L58: 37.73 | M58: 40.48 | N58: 848.6 | O58: 0 | P58: 0.82 | Q58: 9.53
A59: 02/05/2025 12:45 | B59: 1.33 | C59: 34.83 | D59: 64.62 | E59: Calib. | F59: 22.07 | G59: 89.87 | H59: 27.85 | I59: 3.86 | J59: 1.42 | K59: 111.17 | L59: 35.53 | M59: 46.13 | N59: 831.6 | O59: 0 | P59: 0.8 | Q59: 9.54
A60: 02/05/2025 13:00 | B60: 3.28 | C60: 41.01 | D60: 73.46 | E60: Calib. | F60: 19.13 | G60: 89.87 | H60: 27.85 | I60: 4.11 | J60: 0.24 | K60: 274.1 | L60: 36.68 | M60: 42.85 | N60: 802.4 | O60: 0 | P60: 0.83 | Q60: 9.49
...

Sheet 03
A1: Station: | B1: BHATAGAON RAIPUR
A2: Date: | B2: =$A$9 -> 03/05/2025 00:15 | D2: Power Off | G2: Pw.Off | L2: Link Fail | N2: Link F | P2: Maintenance | R2: Maint.
A3: Report Type: | B3: Mean | D3: Calibration | G3: Calib. | L3: Data Fail | N3: Data F | P3: Invalid | R3: Invalid
A4: Time Base: | B4: 15 Min | D4: Zero Referrence | G4: Z.Ref | L4: Warm Up | N4: Wm. Up
A7: Date & Time | B7: NO_BHATAGAON | C7: NO2__BHATAGAON | D7: NOX_BHATAGAON | E7: SO2__BHATAGAON | F7: O3__BHATAGAON | G7: PM10__BHATAGAON | H7: PM2_5__BHATAGAON | I7: BENZ__BHATAGAON | J7: WS__BHATAGAON | K7: WD__BHATAGAON | L7: TEMP__BHATAGAON | M7: HUM__BHATAGAON | N7: SR__BHATAGAON | O7: RG__BHATAGAON | P7: CO__BHATAGAON | Q7: NH3__BHATAGAON
B8: ug/m3 | C8: ug/m3 | D8: ppb | E8: ug/m3 | F8: ug/m3 | G8: ug/m3 | H8: ug/m3 | I8: ug/m3 | J8: m/sec | K8: deg | L8: degreC | M8: % | N8: w/m2 | O8: mm | P8: mg/m3 | Q8: ug/m3
A9: 03/05/2025 00:15 | B9: 9.43 | C9: 32.83 | D9: 45.3 | E9: 3.05 | F9: 15.96 | G9: 23.18 | H9: 11.45 | I9: 3.99 | J9: 0.43 | K9: 213.52 | L9: 31.41 | M9: 50.08 | N9: 57.7 | O9: 0 | P9: 0.46 | Q9: 9.64
A10: 03/05/2025 00:30 | B10: 8.52 | C10: 30.41 | D10: 42.07 | E10: 3.31 | F10: 16.06 | G10: 23.18 | H10: 11.45 | I10: 4.16 | J10: 0.31 | K10: 210.18 | L10: 31.26 | M10: 51.83 | N10: 58.1 | O10: 0 | P10: 0.44 | Q10: 9.67
A11: 03/05/2025 00:45 | B11: 10.88 | C11: 36.47 | D11: 50.04 | E11: 3.19 | F11: 11.61 | G11: 23.18 | H11: 11.45 | I11: 4.11 | J11: 0.26 | K11: 198.33 | L11: 30.76 | M11: 55.37 | N11: 58.3 | O11: 0 | P11: 0.47 | Q11: 9.66
A12: 03/05/2025 01:00 | B12: 9.5 | C12: 30.87 | D12: 41.45 | E12: 3.01 | F12: 15.77 | G12: 23.18 | H12: 11.45 | I12: 3.97 | J12: 0.43 | K12: 165.86 | L12: 30.72 | M12: 55.39 | N12: 57.7 | O12: 0 | P12: 0.43 | Q12: 9.65
A13: 03/05/2025 01:15 | B13: 8.95 | C13: 27.46 | D13: 35.77 | E13: 2.81 | F13: 14.29 | G13: 30.6 | H13: 12.09 | I13: 4.04 | J13: 0.33 | K13: 185.7 | L13: 30.61 | M13: 57.01 | N13: 58 | O13: 0 | P13: 0.46 | Q13: 9.63
A14: 03/05/2025 01:30 | B14: 8.81 | C14: 26.83 | D14: 34.79 | E14: 2.68 | F14: 14.31 | G14: 30.6 | H14: 12.09 | I14: 4.1 | J14: 0.28 | K14: 184.6 | L14: 30.31 | M14: 59.64 | N14: 58.2 | O14: 0 | P14: 0.44 | Q14: 9.63
A15: 03/05/2025 01:45 | B15: 8.62 | C15: 26.46 | D15: 34.36 | E15: 2.88 | F15: 12.85 | G15: 30.6 | H15: 12.09 | I15: 3.92 | J15: 0.29 | K15: 196.43 | L15: 30.08 | M15: 61.37 | N15: 58.1 | O15: 0 | P15: 0.43 | Q15: 9.64
A16: 03/05/2025 02:00 | B16: 8.81 | C16: 28.54 | D16: 38.05 | E16: 2.82 | F16: 11.25 | G16: 30.6 | H16: 12.09 | I16: 3.89 | J16: 0.22 | K16: 243.26 | L16: 29.75 | M16: 64.23 | N16: 58.3 | O16: 0 | P16: 0.42 | Q16: 9.66
A17: 03/05/2025 02:15 | B17: 12.02 | C17: 30.69 | D17: 37.24 | E17: 2.8 | F17: 8.27 | G17: 32.13 | H17: 11.19 | I17: 4.02 | J17: 0.26 | K17: 252.36 | L17: 29.47 | M17: 65.09 | N17: 58.4 | O17: 0 | P17: 0.52 | Q17: 9.65
A18: 03/05/2025 02:30 | B18: 11.15 | C18: 29.52 | D18: 36.33 | E18: 2.66 | F18: 9.3 | G18: 32.13 | H18: 11.18 | I18: 3.95 | J18: 0.27 | K18: 261.04 | L18: 29.23 | M18: 66.85 | N18: 58.5 | O18: 0 | P18: 0.47 | Q18: 9.62
A19: 03/05/2025 02:45 | B19: 11.37 | C19: 28.73 | D19: 34.48 | E19: 2.77 | F19: 10.06 | G19: 32.13 | H19: 11.18 | I19: 4.06 | J19: 0.28 | K19: 255.49 | L19: 29.1 | M19: 68.55 | N19: 58.4 | O19: 0 | P19: 0.46 | Q19: 9.62
A20: 03/05/2025 03:00 | B20: 11.92 | C20: 28.67 | D20: 33.52 | E20: 2.47 | F20: 7.9 | G20: 32.13 | H20: 11.18 | I20: 3.98 | J20: 0.22 | K20: 256.98 | L20: 28.96 | M20: 70.51 | N20: 58.4 | O20: 0 | P20: 0.5 | Q20: 9.65
... A104: 03/05/2025 24:00 | B104: 20.04 | C104: 31.41 | D104: 26.3 | E104: 3.11 | F104: 5.5 | G104: 47.97 | H104: 9.71 | I104: 4.03 | J104: 0.48 | K104: 188.37 | L104: 24.28 | M104: 98.04 | N104: 69.8 | O104: 0 | P104: 0.59 | Q104: 9.68
A106: Min | B106: =MIN(B9:B104) -> 6.53 | C106: =MIN(C9:C104) -> 19.43 | D106: =MIN(D9:D104) -> 21.59 | E106: =MIN(E9:E104) -> 1.38 | F106: =MIN(F9:F104) -> 4.88 | G106: =MIN(G9:G104) -> 16.43 | H106: =MIN(H9:H104) -> 4.75 | I106: =MIN(I9:I104) -> 3.67 | ... Q106: =MIN(Q9:Q104) -> 0
A107: Max | B107: =MAX(B9:B104) -> 24.45 | C107: =MAX(C9:C104) -> 39.16 | D107: =MAX(D9:D104) -> 50.04 | E107: =MAX(E9:E104) -> 4.49 | F107: =MAX(F9:F104) -> 26.67 | G107: =MAX(G9:G104) -> 47.97 | H107: =MAX(H9:H104) -> 17.67 | I107: =MAX(I9:I104) -> 4.3 | ... Q107: =MAX(Q9:Q104) -> 9.71
A108: Avg | B108: =AVERAGE(B9:B104) -> 12.320104 | C108: =AVERAGE(C9:C104) -> 27.696042 | D108: =AVERAGE(D9:D104) -> 31.048542 | E108: =AVERAGE(E9:E104) -> 2.5525 | F108: =AVERAGE(F9:F104) -> 9.1635417 | G108: =AVERAGE(G9:G104) -> 29.95125 | H108: =AVERAGE(H9:H104) -> 11.170312 | I108: =AVERAGE(I9:I104) -> 3.9991667 | ... Q108: =AVERAGE(Q9:Q104) -> 9.5077083
A109: Stdev | B109: =STDEV(B9:B104) -> 4.5431692 | C109: =STDEV(C9:C104) -> 4.8896254 | D109: =STDEV(D9:D104) -> 6.2130742 | E109: =STDEV(E9:E104) -> 0.61807 | F109: =STDEV(F9:F104) -> 4.5831931 | G109: =STDEV(G9:G104) -> 8.7479085 | H109: =STDEV(H9:H104) -> 3.2559408 | I109: =STDEV(I9:I104) -> 0.1009603 | ... Q109: =STDEV(Q9:Q104) -> 0.98283101
A110: Num | B110: =COUNT(B9:B104) -> 96 | C110: =COUNT(C9:C104) -> 96 | D110: =COUNT(D9:D104) -> 96 | E110: =COUNT(E9:E104) -> 96 | F110: =COUNT(F9:F104) -> 96 | G110: =COUNT(G9:G104) -> 96 | H110: =COUNT(H9:H104) -> 96 | I110: =COUNT(I9:I104) -> 96 | ... Q110: =COUNT(Q9:Q104) -> 96
A111: DCR | B111: =IF(B110>=87,">90%",IF(B110<=87,"<90%")) -> >90% | C111: =IF(C110>=87,">90%",IF(C110<=87,"<90%")) -> >90% | D111: =IF(D110>=87,">90%",IF(D110<=87,"<90%")) -> >90% | E111: =IF(E110>=87,">90%",IF(E110<=87,"<90%")) -> >90% | F111: =IF(F110>=87,">90%",IF(F110<=87,"<90%")) -> >90% | G111: =IF(G110>=87,">90%",IF(G110<=87,"<90%")) -> >90% | H111: =IF(H110>=87,">90%",IF(H110<=87,"<90%")) -> >90% | I111: =IF(I110>=87,">90%",IF(I110<=87,"<90%")) -> >90% | ... Q111: =IF(Q110>=87,">90%",IF(Q110<=87,"<90%")) -> >90%
A112: Status | B112: =IF(B110>=87,"OK",IF(B110<=87,"LESS")) -> OK | C112: =IF(C110>=87,"OK",IF(C110<=87,"LESS")) -> OK | D112: =IF(D110>=87,"OK",IF(D110<=87,"LESS")) -> OK | E112: =IF(E110>=87,"OK",IF(E110<=87,"LESS")) -> OK | F112: =IF(F110>=87,"OK",IF(F110<=87,"LESS")) -> OK | G112: =IF(G110>=87,"OK",IF(G110<=87,"LESS")) -> OK | H112: =IF(H110>=87,"OK",IF(H110<=87,"LESS")) -> OK | I112: =IF(I110>=87,"OK",IF(I110<=87,"LESS")) -> OK | ... Q112: =IF(Q110>=87,"OK",IF(Q110<=87,"LESS")) -> OK
A115: Done by | B115: RK
A117: Comment

Sheet 04
A1: Station: | B1: BHATAGAON RAIPUR
A2: Date: | B2: =$A$9 -> 04/05/2025 00:15 | D2: Power Off | G2: Pw.Off | L2: Link Fail | N2: Link F | P2: Maintenance | R2: Maint.
A3: Report Type: | B3: Mean | D3: Calibration | G3: Calib. | L3: Data Fail | N3: Data F | P3: Invalid | R3: Invalid
A4: Time Base: | B4: 15 Min | D4: Zero Referrence | G4: Z.Ref | L4: Warm Up | N4: Wm. Up
A7: Date & Time | B7: NO_BHATAGAON | C7: NO2__BHATAGAON | D7: NOX_BHATAGAON | E7: SO2__BHATAGAON | F7: O3__BHATAGAON | G7: PM10__BHATAGAON | H7: PM2_5__BHATAGAON | I7: BENZ__BHATAGAON | J7: WS__BHATAGAON | K7: WD__BHATAGAON | L7: TEMP__BHATAGAON | M7: HUM__BHATAGAON | N7: SR__BHATAGAON | O7: RG__BHATAGAON | P7: CO__BHATAGAON | Q7: NH3__BHATAGAON
B8: ug/m3 | C8: ug/m3 | D8: ppb | E8: ug/m3 | F8: ug/m3 | G8: ug/m3 | H8: ug/m3 | I8: ug/m3 | J8: m/sec | K8: deg | L8: degreC | M8: % | N8: w/m2 | O8: mm | P8: mg/m3 | Q8: ug/m3
A9: 04/05/2025 00:15 | B9: 22.06 | C9: 31.66 | D9: 23.68 | E9: 3.42 | F9: 5.62 | G9: 59.94 | H9: 6.8 | I9: 4.25 | J9: 0.78 | K9: 157.8 | L9: 24.23 | M9: 99.89 | N9: 69.9 | O9: 0 | P9: 0.63 | Q9: 9.69
A10: 04/05/2025 00:30 | B10: 24.03 | C10: 31.82 | D10: 20.98 | E10: 3.3 | F10: 6.01 | G10: 59.94 | H10: 6.8 | I10: 3.97 | J10: 1.29 | K10: 152.14 | L10: 24 | M10: 100.77 | N10: 70.1 | O10: 0 | P10: 0.65 | Q10: 9.66
A11: 04/05/2025 00:45 | B11: 24.56 | C11: 34.92 | D11: 26.08 | E11: 3.31 | F11: 5.27 | G11: 59.94 | H11: 6.8 | I11: 4.01 | J11: 1.02 | K11: 159.93 | L11: 23.86 | M11: 101.35 | N11: 70 | O11: 0 | P11: 0.64 | Q11: 9.66
A12: 04/05/2025 01:00 | B12: 24.42 | C12: 33.99 | D12: 24.53 | E12: 3.63 | F12: 5.15 | G12: 59.94 | H12: 6.8 | I12: 3.95 | J12: 1.53 | K12: 157.78 | L12: 23.83 | M12: 101.01 | N12: 70 | O12: 0 | P12: 0.65 | Q12: 9.68
A13: 04/05/2025 01:15 | B13: 24.22 | C13: 33.5 | D13: 23.9 | E13: 3.37 | F13: 5.84 | G13: 63.14 | H13: 17.22 | I13: 4.15 | J13: 1.6 | K13: 155.25 | L13: 23.82 | M13: 101.01 | N13: 70.2 | O13: 0 | P13: 0.63 | Q13: 9.7
A14: 04/05/2025 01:30 | B14: 23.8 | C14: 33.6 | D14: 24.73 | E14: 3.64 | F14: 5.54 | G14: 63.14 | H14: 17.22 | I14: 3.98 | J14: 1.52 | K14: 157.42 | L14: 23.77 | M14: 101.61 | N14: 70.4 | O14: 0 | P14: 0.64 | Q14: 9.69
A15: 04/05/2025 01:45 | B15: 23.15 | C15: 31.96 | D15: 22.58 | E15: 3.56 | F15: 5.63 | G15: 63.14 | H15: 17.22 | I15: 4.04 | J15: 1.28 | K15: 161.45 | L15: 23.72 | M15: 101.44 | N15: 70.4 | O15: 0 | P15: 0.63 | Q15: 9.7
A16: 04/05/2025 02:00 | B16: 22.6 | C16: 31.87 | D16: 23.26 | E16: 3.47 | F16: 5.93 | G16: 63.14 | H16: 17.22 | I16: 3.86 | J16: 0.9 | K16: 169.09 | L16: 23.72 | M16: 100.89 | N16: 70.6 | O16: 0 | P16: 0.6 | Q16: 9.71
A17: 04/05/2025 02:15 | B17: 22.23 | C17: 31.42 | D17: 22.98 | E17: 3.68 | F17: 5.29 | G17: 51.83 | H17: 13.61 | I17: 3.96 | J17: 0.97 | K17: 169.52 | L17: 23.55 | M17: 100.34 | N17: 70.7 | O17: 0 | P17: 0.58 | Q17: 9.71
A18: 04/05/2025 02:30 | B18: 21.71 | C18: 29.62 | D18: 20.31 | E18: 3.1 | F18: 5.54 | G18: 51.7 | H18: 13.57 | I18: 4.09 | J18: 0.78 | K18: 206.3 | L18: 23.41 | M18: 99.95 | N18: 70.9 | O18: 0 | P18: 0.58 | Q18: 9.71
A19: 04/05/2025 02:45 | B19: 21.21 | C19: 32.01 | D19: 25.67 | E19: 3.28 | F19: 5.29 | G19: 51.7 | H19: 13.57 | I19: 4.05 | J19: 0.86 | K19: 192.83 | L19: 23.36 | M19: 100.09 | N19: 70.8 | O19: 0 | P19: 0.55 | Q19: 9.71
A20: 04/05/2025 03:00 | B20: 20.23 | C20: 29.29 | D20: 21.96 | E20: 2.81 | F20: 5.86 | G20: 51.7 | H20: 13.57 | I20: 3.96 | J20: 0.9 | K20: 179.48 | L20: 23.34 | M20: 99.39 | N20: 70.9 | O20: 0 | P20: 0.53 | Q20: 9.74
... A104: 04/05/2025 24:00 | B104: 12.59 | C104: 30.24 | D104: 35.5 | E104: 2.38 | F104: 6.27 | G104: 47.76 | H104: 15.8 | I104: 4.02 | J104: 1.9 | K104: 258.15 | L104: 29.85 | M104: 52.57 | N104: 148.2 | O104: 0 | P104: 0.6 | Q104: 9.61
A106: Min | B106: =MIN(B9:B104) -> 7.35 | C106: =MIN(C9:C104) -> 21.17 | D106: =MIN(D9:D104) -> 17.64 | E106: =MIN(E9:E104) -> 1.5 | F106: =MIN(F9:F104) -> 4.89 | G106: =MIN(G9:G104) -> 21.92 | H106: =MIN(H9:H104) -> 4.55 | I106: =MIN(I9:I104) -> 3.8 | ... Q106: =MIN(Q9:Q104) -> 9.47
A107: Max | B107: =MAX(B9:B104) -> 37.46 | C107: =MAX(C9:C104) -> 82.05 | D107: =MAX(D9:D104) -> 113.64 | E107: =MAX(E9:E104) -> 4.71 | F107: =MAX(F9:F104) -> 24.1 | G107: =MAX(G9:G104) -> 63.14 | H107: =MAX(H9:H104) -> 19.17 | I107: =MAX(I9:I104) -> 4.25 | ... Q107: =MAX(Q9:Q104) -> 9.74
A108: Avg | B108: =AVERAGE(B9:B104) -> 15.749062 | C108: =AVERAGE(C9:C104) -> 33.787396 | D108: =AVERAGE(D9:D104) -> 37.445625 | E108: =AVERAGE(E9:E104) -> 2.9416667 | F108: =AVERAGE(F9:F104) -> 9.7248958 | G108: =AVERAGE(G9:G104) -> 35.413958 | H108: =AVERAGE(H9:H104) -> 11.008958 | I108: =AVERAGE(I9:I104) -> 4.0173958 | ... Q108: =AVERAGE(Q9:Q104) -> 9.6085417
A109: Stdev | B109: =STDEV(B9:B104) -> 5.4925115 | C109: =STDEV(C9:C104) -> 11.724231 | D109: =STDEV(D9:D104) -> 21.698367 | E109: =STDEV(E9:E104) -> 0.59265267 | F109: =STDEV(F9:F104) -> 5.4956038 | G109: =STDEV(G9:G104) -> 12.245491 | H109: =STDEV(H9:H104) -> 3.8493071 | I109: =STDEV(I9:I104) -> 0.088093787 | ... Q109: =STDEV(Q9:Q104) -> 0.075560769
A110: Num | B110: =COUNT(B9:B104) -> 96 | C110: =COUNT(C9:C104) -> 96 | D110: =COUNT(D9:D104) -> 96 | E110: =COUNT(E9:E104) -> 96 | F110: =COUNT(F9:F104) -> 96 | G110: =COUNT(G9:G104) -> 96 | H110: =COUNT(H9:H104) -> 96 | I110: =COUNT(I9:I104) -> 96 | ... Q110: =COUNT(Q9:Q104) -> 96
A111: DCR | B111: =IF(B110>=87,">90%",IF(B110<=87,"<90%")) -> >90% | C111: =IF(C110>=87,">90%",IF(C110<=87,"<90%")) -> >90% | D111: =IF(D110>=87,">90%",IF(D110<=87,"<90%")) -> >90% | E111: =IF(E110>=87,">90%",IF(E110<=87,"<90%")) -> >90% | F111: =IF(F110>=87,">90%",IF(F110<=87,"<90%")) -> >90% | G111: =IF(G110>=87,">90%",IF(G110<=87,"<90%")) -> >90% | H111: =IF(H110>=87,">90%",IF(H110<=87,"<90%")) -> >90% | I111: =IF(I110>=87,">90%",IF(I110<=87,"<90%")) -> >90% | ... Q111: =IF(Q110>=87,">90%",IF(Q110<=87,"<90%")) -> >90%
A112: Status | B112: =IF(B110>=87,"OK",IF(B110<=87,"LESS")) -> OK | C112: =IF(C110>=87,"OK",IF(C110<=87,"LESS")) -> OK | D112: =IF(D110>=87,"OK",IF(D110<=87,"LESS")) -> OK | E112: =IF(E110>=87,"OK",IF(E110<=87,"LESS")) -> OK | F112: =IF(F110>=87,"OK",IF(F110<=87,"LESS")) -> OK | G112: =IF(G110>=87,"OK",IF(G110<=87,"LESS")) -> OK | H112: =IF(H110>=87,"OK",IF(H110<=87,"LESS")) -> OK | I112: =IF(I110>=87,"OK",IF(I110<=87,"LESS")) -> OK | ... Q112: =IF(Q110>=87,"OK",IF(Q110<=87,"LESS")) -> OK
A115: Done by | B115: RK
A117: Comment

Sheet 05
A1: Station: | B1: BHATAGAON RAIPUR
A2: Date: | B2: =$A$9 -> 05/05/2025 00:15 | D2: Power Off | G2: Pw.Off | L2: Link Fail | N2: Link F | P2: Maintenance | R2: Maint.
A3: Report Type: | B3: Mean | D3: Calibration | G3: Calib. | L3: Data Fail | N3: Data F | P3: Invalid | R3: Invalid
A4: Time Base: | B4: 15 Min | D4: Zero Referrence | G4: Z.Ref | L4: Warm Up | N4: Wm. Up
A7: Date & Time | B7: NO_BHATAGAON | C7: NO2__BHATAGAON | D7: NOX_BHATAGAON | E7: SO2__BHATAGAON | F7: O3__BHATAGAON | G7: PM10__BHATAGAON | H7: PM2_5__BHATAGAON | I7: BENZ__BHATAGAON | J7: WS__BHATAGAON | K7: WD__BHATAGAON | L7: TEMP__BHATAGAON | M7: HUM__BHATAGAON | N7: SR__BHATAGAON | O7: RG__BHATAGAON | P7: CO__BHATAGAON | Q7: NH3__BHATAGAON
B8: ug/m3 | C8: ug/m3 | D8: ppb | E8: ug/m3 | F8: ug/m3 | G8: ug/m3 | H8: ug/m3 | I8: ug/m3 | J8: m/sec | K8: deg | L8: degreC | M8: % | N8: w/m2 | O8: mm | P8: mg/m3 | Q8: ug/m3
A9: 05/05/2025 00:15 | B9: 10.42 | C9: 28.23 | D9: 34.99 | E9: 2.76 | F9: 6.15 | G9: 47.23 | H9: 15.55 | I9: 3.87 | J9: 1.52 | K9: 256.83 | L9: 29.63 | M9: 55.47 | N9: 134.4 | O9: 0 | P9: 0.55 | Q9: 9.61
A10: 05/05/2025 00:30 | B10: 9.49 | C10: 27.18 | D10: 34.39 | E10: 2.9 | F10: 5.98 | G10: 47.23 | H10: 15.55 | I10: 4.14 | J10: 1.38 | K10: 260.96 | L10: 29.08 | M10: 54.25 | N10: 136.3 | O10: 0 | P10: 0.53 | Q10: 9.6
A11: 05/05/2025 00:45 | B11: 9.05 | C11: 26.04 | D11: 32.91 | E11: 2.68 | F11: 6.96 | G11: 47.23 | H11: 15.55 | I11: 3.85 | J11: 0.47 | K11: 289.24 | L11: 29.15 | M11: 51.84 | N11: 155.3 | O11: 0 | P11: 0.5 | Q11: 9.58
A12: 05/05/2025 01:00 | B12: 8.78 | C12: 25.49 | D12: 32.25 | E12: 3.05 | F12: 10.7 | G12: 47.23 | H12: 15.55 | I12: 3.94 | J12: 0.44 | K12: 355.55 | L12: 29.45 | M12: 47.01 | N12: 152.6 | O12: 0 | P12: 0.41 | Q12: 9.58
A13: 05/05/2025 01:15 | B13: 9.31 | C13: 26.1 | D13: 32.61 | E13: 3.42 | F13: 13.18 | G13: 35.05 | H13: 10.17 | I13: 4.15 | J13: 0.1 | K13: 124.64 | L13: 30.06 | M13: 44.64 | N13: 161.3 | O13: 0 | P13: 0.4 | Q13: 9.58
A14: 05/05/2025 01:30 | B14: 8.7 | C14: 24.72 | D14: 30.9 | E14: 2.96 | F14: 14.79 | G14: 35.05 | H14: 10.11 | I14: 3.88 | J14: 0.6 | K14: 121.02 | L14: 29.79 | M14: 44.04 | N14: 156.9 | O14: 0 | P14: 0.36 | Q14: 9.56
A15: 05/05/2025 01:45 | B15: 8.93 | C15: 24.09 | D15: 29.34 | E15: 3.13 | F15: 9.24 | G15: 35.05 | H15: 10.11 | I15: 3.87 | J15: 0.77 | K15: 140.25 | L15: 29.63 | M15: 45.67 | N15: 164.6 | O15: 0 | P15: 0.42 | Q15: 9.56
A16: 05/05/2025 02:00 | B16: 9.6 | C16: 24.56 | D16: 29.23 | E16: 3 | F16: 9.14 | G16: 35.05 | H16: 10.11 | I16: 3.91 | J16: 0.79 | K16: 116.27 | L16: 29.53 | M16: 46.63 | N16: 175 | O16: 0 | P16: 0.41 | Q16: 9.56
A17: 05/05/2025 02:15 | B17: 9.22 | C17: 24.69 | D17: 30.04 | E17: 3.27 | F17: 10.54 | G17: 38.1 | H17: 13.67 | I17: 3.94 | J17: 0.17 | K17: 201.65 | L17: 29.34 | M17: 50.17 | N17: 177.4 | O17: 0 | P17: 0.34 | Q17: 9.56
A18: 05/05/2025 02:30 | B18: 9.37 | C18: 26.76 | D18: 33.78 | E18: 2.99 | F18: 9.68 | G18: 38.1 | H18: 13.71 | I18: 4.13 | J18: 0.64 | K18: 140.99 | L18: 28.83 | M18: 51.15 | N18: 180.3 | O18: 0 | P18: 0.36 | Q18: 9.57
A19: 05/05/2025 02:45 | B19: 10.06 | C19: 24.73 | D19: 28.85 | E19: 2.68 | F19: 8.35 | G19: 38.1 | H19: 13.71 | I19: 4.04 | J19: 0.52 | K19: 169.98 | L19: 28.54 | M19: 53.76 | N19: 157.2 | O19: 0 | P19: 0.38 | Q19: 9.57
A20: 05/05/2025 03:00 | B20: 11.14 | C20: 25.96 | D20: 29.55 | E20: 3.15 | F20: 6.46 | G20: 38.1 | H20: 13.71 | I20: 3.95 | J20: 0.31 | K20: 345.68 | L20: 28.11 | M20: 58.17 | N20: 126.7 | O20: 0 | P20: 0.42 | Q20: 9.58
... A104: 05/05/2025 24:00 | B104: 31.9 | C104: 46.35 | D104: 36.7 | E104: 4.61 | F104: 6.55 | G104: 81.48 | H104: 23.92 | I104: 3.99 | J104: 1.99 | K104: 105.27 | L104: 28.35 | M104: 68.32 | N104: 49.9 | O104: 0 | P104: 0.87 | Q104: 9.63
A106: Min | B106: =MIN(B9:B104) -> 6.6 | C106: =MIN(C9:C104) -> 22.27 | D106: =MIN(D9:D104) -> 26.32 | E106: =MIN(E9:E104) -> 2.01 | F106: =MIN(F9:F104) -> 5.07 | G106: =MIN(G9:G104) -> 12.07 | H106: =MIN(H9:H104) -> 6.92 | I106: =MIN(I9:I104) -> 3.73 | ... Q106: =MIN(Q9:Q104) -> 9.43
A107: Max | B107: =MAX(B9:B104) -> 241.02 | C107: =MAX(C9:C104) -> 264.98 | D107: =MAX(D9:D104) -> 134.19 | E107: =MAX(E9:E104) -> 8.87 | F107: =MAX(F9:F104) -> 25.05 | G107: =MAX(G9:G104) -> 93.56 | H107: =MAX(H9:H104) -> 26.93 | I107: =MAX(I9:I104) -> 4.2 | ... Q107: =MAX(Q9:Q104) -> 9.82
A108: Avg | B108: =AVERAGE(B9:B104) -> 31.508646 | C108: =AVERAGE(C9:C104) -> 51.930417 | D108: =AVERAGE(D9:D104) -> 47.981875 | E108: =AVERAGE(E9:E104) -> 4.5554167 | F108: =AVERAGE(F9:F104) -> 10.957188 | G108: =AVERAGE(G9:G104) -> 42.334479 | H108: =AVERAGE(H9:H104) -> 13.647083 | I108: =AVERAGE(I9:I104) -> 4.0005208 | ... Q108: =AVERAGE(Q9:Q104) -> 9.5702083
A109: Stdev | B109: =STDEV(B9:B104) -> 47.007834 | C109: =STDEV(C9:C104) -> 51.764316 | D109: =STDEV(D9:D104) -> 30.112563 | E109: =STDEV(E9:E104) -> 1.817857 | F109: =STDEV(F9:F104) -> 5.854434 | G109: =STDEV(G9:G104) -> 22.495441 | H109: =STDEV(H9:H104) -> 5.8497581 | I109: =STDEV(I9:I104) -> 0.082364655 | ... Q109: =STDEV(Q9:Q104) -> 0.086863222
A110: Num | B110: =COUNT(B9:B104) -> 96 | C110: =COUNT(C9:C104) -> 96 | D110: =COUNT(D9:D104) -> 96 | E110: =COUNT(E9:E104) -> 96 | F110: =COUNT(F9:F104) -> 96 | G110: =COUNT(G9:G104) -> 96 | H110: =COUNT(H9:H104) -> 96 | I110: =COUNT(I9:I104) -> 96 | ... Q110: =COUNT(Q9:Q104) -> 96
A111: DCR | B111: =IF(B110>=87,">90%",IF(B110<=87,"<90%")) -> >90% | C111: =IF(C110>=87,">90%",IF(C110<=87,"<90%")) -> >90% | D111: =IF(D110>=87,">90%",IF(D110<=87,"<90%")) -> >90% | E111: =IF(E110>=87,">90%",IF(E110<=87,"<90%")) -> >90% | F111: =IF(F110>=87,">90%",IF(F110<=87,"<90%")) -> >90% | G111: =IF(G110>=87,">90%",IF(G110<=87,"<90%")) -> >90% | H111: =IF(H110>=87,">90%",IF(H110<=87,"<90%")) -> >90% | I111: =IF(I110>=87,">90%",IF(I110<=87,"<90%")) -> >90% | ... Q111: =IF(Q110>=87,">90%",IF(Q110<=87,"<90%")) -> >90%
A112: Status | B112: =IF(B110>=87,"OK",IF(B110<=87,"LESS")) -> OK | C112: =IF(C110>=87,"OK",IF(C110<=87,"LESS")) -> OK | D112: =IF(D110>=87,"OK",IF(D110<=87,"LESS")) -> OK | E112: =IF(E110>=87,"OK",IF(E110<=87,"LESS")) -> OK | F112: =IF(F110>=87,"OK",IF(F110<=87,"LESS")) -> OK | G112: =IF(G110>=87,"OK",IF(G110<=87,"LESS")) -> OK | H112: =IF(H110>=87,"OK",IF(H110<=87,"LESS")) -> OK | I112: =IF(I110>=87,"OK",IF(I110<=87,"LESS")) -> OK | ... Q112: =IF(Q110>=87,"OK",IF(Q110<=87,"LESS")) -> OK
A115: Done by | B115: RK
A117: Comment

Sheet 06
A1: Station: | B1: BHATAGAON RAIPUR
A2: Date: | B2: =$A$9 -> 06/05/2025 00:15 | D2: Power Off | G2: Pw.Off | L2: Link Fail | N2: Link F | P2: Maintenance | R2: Maint.
A3: Report Type: | B3: Mean | D3: Calibration | G3: Calib. | L3: Data Fail | N3: Data F | P3: Invalid | R3: Invalid
A4: Time Base: | B4: 15 Min | D4: Zero Referrence | G4: Z.Ref | L4: Warm Up | N4: Wm. Up
A7: Date & Time | B7: NO_BHATAGAON | C7: NO2__BHATAGAON | D7: NOX_BHATAGAON | E7: SO2__BHATAGAON | F7: O3__BHATAGAON | G7: PM10__BHATAGAON | H7: PM2_5__BHATAGAON | I7: BENZ__BHATAGAON | J7: WS__BHATAGAON | K7: WD__BHATAGAON | L7: TEMP__BHATAGAON | M7: HUM__BHATAGAON | N7: SR__BHATAGAON | O7: RG__BHATAGAON | P7: CO__BHATAGAON | Q7: NH3__BHATAGAON
B8: ug/m3 | C8: ug/m3 | D8: ppb | E8: ug/m3 | F8: ug/m3 | G8: ug/m3 | H8: ug/m3 | I8: ug/m3 | J8: m/sec | K8: deg | L8: degreC | M8: % | N8: w/m2 | O8: mm | P8: mg/m3 | Q8: ug/m3
A9: 06/05/2025 00:15 | B9: 31.44 | C9: 45.92 | D9: 36.58 | E9: 4.71 | F9: 7.27 | G9: 57.07 | H9: 17.58 | I9: 3.95 | J9: 1.69 | K9: 100.39 | L9: 28.3 | M9: 67.35 | N9: 50 | O9: 0 | P9: 0.84 | Q9: 9.59
A10: 06/05/2025 00:30 | B10: 29.05 | C10: 43.74 | D10: 36.07 | E10: 5.14 | F10: 6.65 | G10: 57.07 | H10: 17.58 | I10: 4.13 | J10: 1.87 | K10: 103.13 | L10: 28.28 | M10: 69.12 | N10: 50.2 | O10: 0 | P10: 0.83 | Q10: 9.61
A11: 06/05/2025 00:45 | B11: 26.96 | C11: 41.92 | D11: 35.81 | E11: 5.08 | F11: 7.17 | G11: 57.07 | H11: 17.58 | I11: 3.9 | J11: 0.8 | K11: 103.32 | L11: 27.91 | M11: 75.47 | N11: 50.4 | O11: 0 | P11: 0.79 | Q11: 9.63
A12: 06/05/2025 01:00 | B12: 29 | C12: 41.83 | D12: 32.5 | E12: 5.15 | F12: 6.21 | G12: 57.07 | H12: 17.58 | I12: 3.89 | J12: 0.97 | K12: 100.74 | L12: 27.77 | M12: 74.46 | N12: 50.3 | O12: 0 | P12: 0.8 | Q12: 9.64
A13: 06/05/2025 01:15 | B13: 23.59 | C13: 38.39 | D13: 34.2 | E13: 5.34 | F13: 7.77 | G13: 52.39 | H13: 18.99 | I13: 4.06 | J13: 0.25 | K13: 289.68 | L13: 27.67 | M13: 75.13 | N13: 50.5 | O13: 0 | P13: 0.67 | Q13: 9.62
A14: 06/05/2025 01:30 | B14: 23.27 | C14: 37.4 | D14: 32.82 | E14: 5.17 | F14: 7.79 | G14: 52.39 | H14: 18.99 | I14: 3.95 | J14: 0.43 | K14: 261.06 | L14: 27.42 | M14: 79.27 | N14: 50.4 | O14: 0 | P14: 0.69 | Q14: 9.64
A15: 06/05/2025 01:45 | B15: 20.95 | C15: 35.63 | D15: 32.99 | E15: 5.09 | F15: 7.61 | G15: 52.39 | H15: 18.99 | I15: 4 | J15: 0.34 | K15: 274.08 | L15: 27.34 | M15: 79.77 | N15: 50.1 | O15: 0 | P15: 0.66 | Q15: 9.66
A16: 06/05/2025 02:00 | B16: 19.5 | C16: 35.38 | D16: 34.74 | E16: 4.91 | F16: 8.99 | G16: 52.39 | H16: 18.99 | I16: 4.03 | J16: 0.34 | K16: 271.48 | L16: 27.58 | M16: 76.73 | N16: 49.9 | O16: 0 | P16: 0.58 | Q16: 9.67
A17: 06/05/2025 02:15 | B17: 21.16 | C17: 35.89 | D17: 33.16 | E17: 4.71 | F17: 7.18 | G17: 37.66 | H17: 16.16 | I17: 4 | J17: 0.59 | K17: 240.12 | L17: 27.7 | M17: 72.09 | N17: 49.5 | O17: 0 | P17: 0.62 | Q17: 9.64
A18: 06/05/2025 02:30 | B18: 17.8 | C18: 32.68 | D18: 32.19 | E18: 4.91 | F18: 7.05 | G18: 37.66 | H18: 16.13 | I18: 3.94 | J18: 0.47 | K18: 180.11 | L18: 28.33 | M18: 67.13 | N18: 50 | O18: 0 | P18: 0.57 | Q18: 9.65
A19: 06/05/2025 02:45 | B19: 14.62 | C19: 31.43 | D19: 34.67 | E19: 4.76 | F19: 7.64 | G19: 37.66 | H19: 16.13 | I19: 3.88 | J19: 0.56 | K19: 204.86 | L19: 28.16 | M19: 72.28 | N19: 50.5 | O19: 0 | P19: 0.47 | Q19: 9.65
A20: 06/05/2025 03:00 | B20: 19 | C20: 33.72 | D20: 32.34 | E20: 4.65 | F20: 5.77 | G20: 37.66 | H20: 16.13 | I20: 3.91 | J20: 0.87 | K20: 237.66 | L20: 27.71 | M20: 76.33 | N20: 50.6 | O20: 0 | P20: 0.59 | Q20: 9.64
... A56: 06/05/2025 12:00 | B56: 9.59 | C56: 27.58 | D56: 35.01 | E56: 4.94 | F56: 10.61 | G56: 36.58 | H56: 4.03 | I56: 4.1 | J56: 0.58 | K56: 219.06 | L56: 38.18 | M56: 29.13 | N56: 1080.6 | O56: 0 | P56: 0.42 | Q56: 9.58
A57: 06/05/2025 12:15 | B57: 9.35 | C57: 28.27 | D57: 36.7 | E57: 5.05 | F57: 8.83 | G57: 33.61 | H57: Data F | I57: 4.17 | J57: 0.76 | K57: 254.64 | L57: 39.46 | M57: 28.77 | N57: 1049.8 | O57: 0 | P57: 0.47 | Q57: 9.56
A58: 06/05/2025 12:30 | B58: 10.23 | C58: 29.02 | D58: 36.79 | E58: 5.14 | F58: 12.98 | G58: 33.61 | H58: Data F | I58: 4 | J58: 0.81 | K58: 265.74 | L58: 39.96 | M58: 28.28 | N58: 1061.5 | O58: 0 | P58: 0.44 | Q58: 9.53
A59: 06/05/2025 12:45 | B59: 9.29 | C59: 27.45 | D59: 35.23 | E59: 5.12 | F59: 10.16 | G59: 33.61 | H59: Data F | I59: 3.77 | J59: 0.93 | K59: 263.15 | L59: 41.24 | M59: 26.62 | N59: 1050.3 | O59: 0 | P59: 0.46 | Q59: 9.56
A60: 06/05/2025 13:00 | B60: 8.12 | C60: 23.57 | D60: 29.6 | E60: 5.87 | F60: 14.12 | G60: 33.61 | H60: Data F | I60: 3.92 | J60: 0.34 | K60: 206.43 | L60: 39.82 | M60: 27.42 | N60: 1023.1 | O60: 0 | P60: 0.41 | Q60: 9.57
A61: 06/05/2025 13:15 | B61: 9.57 | C61: 28.96 | D61: 37.7 | E61: 6.73 | F61: 14.5 | G61: 32.55 | H61: Data F | I61: 4 | J61: 0.73 | K61: 270.86 | L61: 41.13 | M61: 26.27 | N61: 970.8 | O61: 0 | P61: 0.52 | Q61: 9.56
A62: 06/05/2025 13:30 | B62: 9.51 | C62: 28.93 | D62: 37.73 | E62: 10.43 | F62: 17.61 | G62: 32.55 | H62: Data F | I62: 3.99 | J62: 0.61 | K62: 231.76 | L62: 40.13 | M62: 26.36 | N62: 942.5 | O62: 0 | P62: 0.58 | Q62: 9.55
A63: 06/05/2025 13:45 | B63: 8.37 | C63: 26.99 | D63: 35.75 | E63: 7.76 | F63: 18.9 | G63: 32.55 | H63: Data F | I63: 4.06 | J63: 0.57 | K63: 189.11 | L63: 38.6 | M63: 27.48 | N63: 600.1 | O63: 0 | P63: 0.55 | Q63: 9.56
A64: 06/05/2025 14:00 | B64: 8.29 | C64: 28.49 | D64: 38.76 | E64: 9.01 | F64: 19.16 | G64: 32.55 | H64: Data F | I64: 4.02 | J64: 0.68 | K64: 253.92 | L64: 39.39 | M64: 27.16 | N64: 539.9 | O64: 0 | P64: 0.56 | Q64: 9.55
A65: 06/05/2025 14:15 | B65: 8.21 | C65: 28.59 | D65: 39.07 | E65: 8.5 | F65: 16.94 | G65: 32.15 | H65: Data F | I65: 3.93 | J65: 0.92 | K65: 255.39 | L65: 40.25 | M65: 26.41 | N65: 566.7 | O65: 0 | P65: 0.59 | Q65: 9.55
A66: 06/05/2025 14:30 | B66: 8.17 | C66: 27.65 | D66: 37.33 | E66: 9.93 | F66: 18.69 | G66: 32.15 | H66: Data F | I66: 3.99 | J66: 0.64 | K66: 241.87 | L66: 40.04 | M66: 26.07 | N66: 469.1 | O66: 0 | P66: 0.57 | Q66: 9.53
A67: 06/05/2025 14:45 | B67: 7.8 | C67: 25.59 | D67: 33.96 | E67: 14.12 | F67: 25.12 | G67: 32.15 | H67: Data F | I67: 4.04 | J67: 0.44 | K67: 224.15 | L67: 39.63 | M67: 25.64 | N67: 315.7 | O67: 0 | P67: 0.55 | Q67: 9.51
A68: 06/05/2025 15:00 | B68: 9.32 | C68: 28.2 | D68: 36.61 | E68: 9.67 | F68: 16.58 | G68: 32.15 | H68: Data F | I68: 3.95 | J68: 0.81 | K68: 262.06 | L68: 40.52 | M68: 23.62 | N68: 316.8 | O68: 0 | P68: 0.56 | Q68: 9.52
A69: 06/05/2025 15:15 | B69: 7.9 | C69: 25.53 | D69: 33.68 | E69: 8.6 | F69: 14.99 | G69: 36.44 | H69: 13.95 | I69: 4.02 | J69: 0.73 | K69: 255.75 | L69: 40.1 | M69: 23.89 | N69: 425.6 | O69: 0 | P69: 0.54 | Q69: 9.52
A70: 06/05/2025 15:30 | B70: 9.2 | C70: 29.15 | D70: 38.61 | E70: 8.56 | F70: 14.5 | G70: 36.44 | H70: 13.95 | I70: 3.96 | J70: 0.68 | K70: 255.67 | L70: 40.13 | M70: 23.61 | N70: 388.2 | O70: 0 | P70: 0.56 | Q70: 9.51
A71: 06/05/2025 15:45 | B71: 9.09 | C71: 29.35 | D71: 39.18 | E71: 7.29 | F71: 15.43 | G71: 36.44 | H71: 13.95 | I71: 3.95 | J71: 0.73 | K71: 261.51 | L71: 39.85 | M71: 24.09 | N71: 427.9 | O71: 0 | P71: 0.57 | Q71: 9.53
A72: 06/05/2025 16:00 | B72: 8.4 | C72: 29.41 | D72: 40.34 | E72: 9.84 | F72: 19.91 | G72: 36.44 | H72: 13.95 | I72: 4.08 | J72: 0.57 | K72: 255.57 | L72: 39.97 | M72: 24.14 | N72: 426.7 | O72: 0 | P72: 0.54 | Q72: 9.53
A73: 06/05/2025 16:15 | B73: 9.58 | C73: 28.78 | D73: 37.33 | E73: 9.55 | F73: 17.32 | G73: 36.73 | H73: 14.16 | I73: 3.96 | J73: 0.8 | K73: 267.41 | L73: 39.38 | M73: 25.05 | N73: 338 | O73: 0 | P73: 0.54 | Q73: 9.54
A74: 06/05/2025 16:30 | B74: 9.16 | C74: 30.13 | D74: 40.55 | E74: 6.01 | F74: 13.48 | G74: 36.73 | H74: 14.16 | I74: 3.92 | J74: 0.8 | K74: 249.84 | L74: 39.15 | M74: 24.79 | N74: 261 | O74: 0 | P74: 0.55 | Q74: 9.54
A75: 06/05/2025 16:45 | B75: 9.22 | C75: 31.77 | D75: 43.59 | E75: 9.58 | F75: 22.35 | G75: 36.73 | H75: 14.16 | I75: 4.06 | J75: 0.49 | K75: 256.01 | L75: 38.72 | M75: 24.82 | N75: 155.7 | O75: 0 | P75: 0.49 | Q75: 9.52
A76: 06/05/2025 17:00 | B76: 12.16 | C76: 36.64 | D76: 48.4 | E76: 14.77 | F76: 23.88 | G76: 36.73 | H76: 14.16 | I76: 3.95 | J76: 0.64 | K76: 271.87 | L76: 38.8 | M76: 25.83 | N76: 137.6 | O76: 0 | P76: 0.6 | Q76: 9.51
A77: 06/05/2025 17:15 | B77: 8.93 | C77: 34.91 | D77: 50.06 | E77: 20.18 | F77: 23.55 | G77: 38.87 | H77: 14.47 | I77: 4.01 | J77: 0.53 | K77: 239.07 | L77: 38.47 | M77: 25.22 | N77: 125.9 | O77: 0 | P77: 0.61 | Q77: 9.52
...

Sheet 07
A1: Station: | B1: BHATAGAON RAIPUR
A2: Date: | B2: =$A$9 -> 07/05/2025 00:15 | D2: Power Off | G2: Pw.Off | L2: Link Fail | N2: Link F | P2: Maintenance | R2: Maint.
A3: Report Type: | B3: Mean | D3: Calibration | G3: Calib. | L3: Data Fail | N3: Data F | P3: Invalid | R3: Invalid
A4: Time Base: | B4: 15 Min | D4: Zero Referrence | G4: Z.Ref | L4: Warm Up | N4: Wm. Up
A7: Date & Time | B7: NO_BHATAGAON | C7: NO2__BHATAGAON | D7: NOX_BHATAGAON | E7: SO2__BHATAGAON | F7: O3__BHATAGAON | G7: PM10__BHATAGAON | H7: PM2_5__BHATAGAON | I7: BENZ__BHATAGAON | J7: WS__BHATAGAON | K7: WD__BHATAGAON | L7: TEMP__BHATAGAON | M7: HUM__BHATAGAON | N7: SR__BHATAGAON | O7: RG__BHATAGAON | P7: CO__BHATAGAON | Q7: NH3__BHATAGAON
B8: ug/m3 | C8: ug/m3 | D8: ppb | E8: ug/m3 | F8: ug/m3 | G8: ug/m3 | H8: ug/m3 | I8: ug/m3 | J8: m/sec | K8: deg | L8: degreC | M8: % | N8: w/m2 | O8: mm | P8: mg/m3 | Q8: ug/m3
A9: 07/05/2025 00:15 | B9: 16.86 | C9: 35.2 | D9: 38.45 | E9: 4.84 | F9: 12.36 | G9: 48.27 | H9: 9.4 | I9: 3.94 | J9: 0.22 | K9: 277.75 | L9: 30.08 | M9: 51.87 | N9: 60.8 | O9: 0 | P9: 0.43 | Q9: 9.65
A10: 07/05/2025 00:30 | B10: 14.46 | C10: 29.62 | D10: 31.45 | E10: 4.46 | F10: 13.65 | G10: 48.27 | H10: 9.4 | I10: 4 | J10: 0.19 | K10: 214.63 | L10: 29.95 | M10: 52.68 | N10: 60.6 | O10: 0 | P10: 0.38 | Q10: 9.65
A11: 07/05/2025 00:45 | B11: 22.02 | C11: 35.75 | D11: 31.58 | E11: 4.61 | F11: 11.02 | G11: 48.27 | H11: 9.4 | I11: 4.06 | J11: 0.27 | K11: 236.9 | L11: 29.91 | M11: 54.64 | N11: 60.7 | O11: 0 | P11: 0.5 | Q11: 9.64
A12: 07/05/2025 01:00 | B12: 20.2 | C12: 35.11 | D12: 33.13 | E12: 4.46 | F12: 10.51 | G12: 48.27 | H12: 9.4 | I12: 3.97 | J12: 0.34 | K12: 188.01 | L12: 29.99 | M12: 54.92 | N12: 60.3 | O12: 0 | P12: 0.43 | Q12: 9.63
A13: 07/05/2025 01:15 | B13: 14.49 | C13: 33.31 | D13: 38.46 | E13: 4.33 | F13: 10.54 | G13: 42.26 | H13: 14.33 | I13: 4.26 | J13: 0.35 | K13: 173.9 | L13: 29.76 | M13: 56.08 | N13: 60.5 | O13: 0 | P13: 0.34 | Q13: 9.62
A14: 07/05/2025 01:30 | B14: 26.46 | C14: 40.57 | D14: 33.98 | E14: 4.33 | F14: 9.08 | G14: 42.26 | H14: 14.33 | I14: 3.91 | J14: 0.22 | K14: 218.87 | L14: 29.61 | M14: 57.91 | N14: 60.7 | O14: 0 | P14: 0.52 | Q14: 9.64
A15: 07/05/2025 01:45 | B15: 18.45 | C15: 40.26 | D15: 45.68 | E15: 4.37 | F15: 8.67 | G15: 42.26 | H15: 14.33 | I15: 3.95 | J15: 0.13 | K15: 238.23 | L15: 29.13 | M15: 61.83 | N15: 61.2 | O15: 0 | P15: 0.33 | Q15: 9.61
A16: 07/05/2025 02:00 | B16: 25.46 | C16: 46.66 | D16: 47.18 | E16: 4.19 | F16: 7.84 | G16: 42.26 | H16: 14.33 | I16: 4.09 | J16: 0.24 | K16: 246.31 | L16: 28.78 | M16: 65.49 | N16: 61.1 | O16: 0 | P16: 0.35 | Q16: 9.65
A17: 07/05/2025 02:15 | B17: 15.07 | C17: 33.22 | D17: 37.4 | E17: 4.42 | F17: 9.81 | G17: 38.76 | H17: 13.31 | I17: 3.96 | J17: 0.22 | K17: 178.5 | L17: 28.99 | M17: 61.63 | N17: 60.3 | O17: 0 | P17: 0.29 | Q17: 9.65
A18: 07/05/2025 02:30 | B18: 14.75 | C18: 31.38 | D18: 34.37 | E18: 4.12 | F18: 10.61 | G18: 38.76 | H18: 13.31 | I18: 4.06 | J18: 0.1 | K18: 218.79 | L18: 29.31 | M18: 58.97 | N18: 60.7 | O18: 0 | P18: 0.29 | Q18: 9.65
A19: 07/05/2025 02:45 | B19: 19.2 | C19: 36.95 | D19: 38.21 | E19: 4.15 | F19: 9.1 | G19: 38.76 | H19: 13.31 | I19: 3.98 | J19: 0.23 | K19: 261.11 | L19: 28.97 | M19: 63.63 | N19: 61.1 | O19: 0 | P19: 0.31 | Q19: 9.64
A20: 07/05/2025 03:00 | B20: 20 | C20: 38.87 | D20: 40.65 | E20: 4.3 | F20: 8.18 | G20: 38.76 | H20: 13.31 | I20: 4.03 | J20: 0.19 | K20: 292.19 | L20: 28.41 | M20: 68.84 | N20: 61.3 | O20: 0 | P20: 0.33 | Q20: 9.63
... A104: 07/05/2025 24:00 | B104: 12.68 | C104: 27.99 | D104: 31.07 | E104: 6.3 | F104: 13.88 | G104: 43.02 | H104: 12.05 | I104: 3.98 | J104: 0.93 | K104: 150.53 | L104: 32.26 | M104: 43.03 | N104: 28 | O104: 0 | P104: 0.37 | Q104: 9.55
A106: Min | B106: =MIN(B9:B104) -> 6.55 | C106: =MIN(C9:C104) -> 20.29 | D106: =MIN(D9:D104) -> 24.28 | E106: =MIN(E9:E104) -> 3.62 | F106: =MIN(F9:F104) -> 6.08 | G106: =MIN(G9:G104) -> 22.77 | H106: =MIN(H9:H104) -> 2.95 | I106: =MIN(I9:I104) -> 3.67 | ... Q106: =MIN(Q9:Q104) -> 9.44
A107: Max | B107: =MAX(B9:B104) -> 84.57 | C107: =MAX(C9:C104) -> 117.38 | D107: =MAX(D9:D104) -> 95.71 | E107: =MAX(E9:E104) -> 9.67 | F107: =MAX(F9:F104) -> 24.44 | G107: =MAX(G9:G104) -> 48.27 | H107: =MAX(H9:H104) -> 19.09 | I107: =MAX(I9:I104) -> 4.26 | ... Q107: =MAX(Q9:Q104) -> 9.67
A108: Avg | B108: =AVERAGE(B9:B104) -> 15.127812 | C108: =AVERAGE(C9:C104) -> 35.808021 | D108: =AVERAGE(D9:D104) -> 42.265417 | E108: =AVERAGE(E9:E104) -> 5.84625 | F108: =AVERAGE(F9:F104) -> 12.238125 | G108: =AVERAGE(G9:G104) -> 34.990625 | H108: =AVERAGE(H9:H104) -> 9.2720833 | I108: =AVERAGE(I9:I104) -> 3.9988542 | ... Q108: =AVERAGE(Q9:Q104) -> 9.555625
A109: Stdev | B109: =STDEV(B9:B104) -> 10.249821 | C109: =STDEV(C9:C104) -> 13.993667 | D109: =STDEV(D9:D104) -> 15.699762 | E109: =STDEV(E9:E104) -> 1.2525462 | F109: =STDEV(F9:F104) -> 4.8552434 | G109: =STDEV(G9:G104) -> 5.9348835 | H109: =STDEV(H9:H104) -> 4.2363944 | I109: =STDEV(I9:I104) -> 0.099428576 | ... Q109: =STDEV(Q9:Q104) -> 0.063508184
A110: Num | B110: =COUNT(B9:B104) -> 96 | C110: =COUNT(C9:C104) -> 96 | D110: =COUNT(D9:D104) -> 96 | E110: =COUNT(E9:E104) -> 96 | F110: =COUNT(F9:F104) -> 96 | G110: =COUNT(G9:G104) -> 96 | H110: =COUNT(H9:H104) -> 96 | I110: =COUNT(I9:I104) -> 96 | ... Q110: =COUNT(Q9:Q104) -> 96
A111: DCR | B111: =IF(B110>=87,">90%",IF(B110<=87,"<90%")) -> >90% | C111: =IF(C110>=87,">90%",IF(C110<=87,"<90%")) -> >90% | D111: =IF(D110>=87,">90%",IF(D110<=87,"<90%")) -> >90% | E111: =IF(E110>=87,">90%",IF(E110<=87,"<90%")) -> >90% | F111: =IF(F110>=87,">90%",IF(F110<=87,"<90%")) -> >90% | G111: =IF(G110>=87,">90%",IF(G110<=87,"<90%")) -> >90% | H111: =IF(H110>=87,">90%",IF(H110<=87,"<90%")) -> >90% | I111: =IF(I110>=87,">90%",IF(I110<=87,"<90%")) -> >90% | ... Q111: =IF(Q110>=87,">90%",IF(Q110<=87,"<90%")) -> >90%
A112: Status | B112: =IF(B110>=87,"OK",IF(B110<=87,"LESS")) -> OK | C112: =IF(C110>=87,"OK",IF(C110<=87,"LESS")) -> OK | D112: =IF(D110>=87,"OK",IF(D110<=87,"LESS")) -> OK | E112: =IF(E110>=87,"OK",IF(E110<=87,"LESS")) -> OK | F112: =IF(F110>=87,"OK",IF(F110<=87,"LESS")) -> OK | G112: =IF(G110>=87,"OK",IF(G110<=87,"LESS")) -> OK | H112: =IF(H110>=87,"OK",IF(H110<=87,"LESS")) -> OK | I112: =IF(I110>=87,"OK",IF(I110<=87,"LESS")) -> OK | ... Q112: =IF(Q110>=87,"OK",IF(Q110<=87,"LESS")) -> OK
A115: Done by | B115: RK
A117: Comment

Sheet 08
A1: Station: | B1: BHATAGAON RAIPUR
A2: Date: | B2: =$A$9 -> 08/05/2025 00:15 | D2: Power Off | G2: Pw.Off | L2: Link Fail | N2: Link F | P2: Maintenance | R2: Maint.
A3: Report Type: | B3: Mean | D3: Calibration | G3: Calib. | L3: Data Fail | N3: Data F | P3: Invalid | R3: Invalid
A4: Time Base: | B4: 15 Min | D4: Zero Referrence | G4: Z.Ref | L4: Warm Up | N4: Wm. Up
A7: Date & Time | B7: NO_BHATAGAON | C7: NO2__BHATAGAON | D7: NOX_BHATAGAON | E7: SO2__BHATAGAON | F7: O3__BHATAGAON | G7: PM10__BHATAGAON | H7: PM2_5__BHATAGAON | I7: BENZ__BHATAGAON | J7: WS__BHATAGAON | K7: WD__BHATAGAON | L7: TEMP__BHATAGAON | M7: HUM__BHATAGAON | N7: SR__BHATAGAON | O7: RG__BHATAGAON | P7: CO__BHATAGAON | Q7: NH3__BHATAGAON
B8: ug/m3 | C8: ug/m3 | D8: ppb | E8: ug/m3 | F8: ug/m3 | G8: ug/m3 | H8: ug/m3 | I8: ug/m3 | J8: m/sec | K8: deg | L8: degreC | M8: % | N8: w/m2 | O8: mm | P8: mg/m3 | Q8: ug/m3
A9: 08/05/2025 00:15 | B9: 13.74 | C9: 30 | D9: 33.29 | E9: 6.6 | F9: 9.17 | G9: 39.67 | H9: 12.53 | I9: 4.07 | J9: 1.03 | K9: 158.16 | L9: 32.17 | M9: 42.77 | N9: 28.1 | O9: 0 | P9: 0.48 | Q9: 9.55
A10: 08/05/2025 00:30 | B10: 13.46 | C10: 29.93 | D10: 33.56 | E10: 6.72 | F10: 9.73 | G10: 39.67 | H10: 12.53 | I10: 4 | J10: 1.21 | K10: 157.01 | L10: 31.91 | M10: 44.08 | N10: 28.4 | O10: 0 | P10: 0.43 | Q10: 9.56
A11: 08/05/2025 00:45 | B11: 11.49 | C11: 26.9 | D11: 30.81 | E11: 6.33 | F11: 11.93 | G11: 39.67 | H11: 12.53 | I11: 3.98 | J11: 0.89 | K11: 166.29 | L11: 31.59 | M11: 46.15 | N11: 28.5 | O11: 0 | P11: 0.38 | Q11: 9.55
A12: 08/05/2025 01:00 | B12: 11.34 | C12: 25.62 | D12: 28.58 | E12: 6.7 | F12: 13.55 | G12: 39.67 | H12: 12.53 | I12: 3.94 | J12: 1.01 | K12: 158.86 | L12: 31.3 | M12: 47.19 | N12: 28.3 | O12: 0 | P12: 0.33 | Q12: 9.55
A13: 08/05/2025 01:15 | B13: 11.36 | C13: 25.72 | D13: 28.75 | E13: 6.29 | F13: 11.49 | G13: 37.59 | H13: 10.59 | I13: 4.1 | J13: 0.83 | K13: 158.03 | L13: 30.94 | M13: 48.02 | N13: 28.5 | O13: 0 | P13: 0.23 | Q13: 9.55
A14: 08/05/2025 01:30 | B14: 10.76 | C14: 25.56 | D14: 29.37 | E14: 6.66 | F14: 10.76 | G14: 37.59 | H14: 10.59 | I14: 4.07 | J14: 0.98 | K14: 156.16 | L14: 30.61 | M14: 49.55 | N14: 28.3 | O14: 0 | P14: 0.28 | Q14: 9.55
A15: 08/05/2025 01:45 | B15: 11.24 | C15: 26.68 | D15: 30.76 | E15: 6.96 | F15: 10.57 | G15: 37.59 | H15: 10.59 | I15: 4 | J15: 0.38 | K15: 202.32 | L15: 30.42 | M15: 50.47 | N15: 28.7 | O15: 0 | P15: 0.27 | Q15: 9.56
A16: 08/05/2025 02:00 | B16: 8.68 | C16: 22.74 | D16: 27.15 | E16: 7.1 | F16: 13.56 | G16: 37.59 | H16: 10.59 | I16: 3.98 | J16: 0.34 | K16: 226.08 | L16: 30.29 | M16: 51.89 | N16: 28.6 | O16: 0 | P16: 0.21 | Q16: 9.56
A17: 08/05/2025 02:15 | B17: 8.33 | C17: 22.08 | D17: 26.43 | E17: 6.95 | F17: 14.75 | G17: 32.06 | H17: 11.32 | I17: 4.1 | J17: 0.31 | K17: 227.47 | L17: 30.13 | M17: 52.71 | N17: 28.5 | O17: 0 | P17: 0.17 | Q17: 9.55
A18: 08/05/2025 02:30 | B18: 9.33 | C18: 23.66 | D18: 27.9 | E18: 6.7 | F18: 12.05 | G18: 32.06 | H18: 11.32 | I18: 4.04 | J18: 0.37 | K18: 213 | L18: 29.83 | M18: 53.68 | N18: 28.3 | O18: 0 | P18: 0.23 | Q18: 9.55
A19: 08/05/2025 02:45 | B19: 9.64 | C19: 25.88 | D19: 31.69 | E19: 6.7 | F19: 11.28 | G19: 32.06 | H19: 11.32 | I19: 4.08 | J19: 0.44 | K19: 182.18 | L19: 29.61 | M19: 54.31 | N19: 28.4 | O19: 0 | P19: 0.22 | Q19: 9.55
A20: 08/05/2025 03:00 | B20: 8.52 | C20: 21.62 | D20: 25.25 | E20: 6.61 | F20: 12.01 | G20: 32.06 | H20: 11.32 | I20: 3.94 | J20: 0.34 | K20: 239.99 | L20: 29.47 | M20: 56.03 | N20: 28.7 | O20: 0 | P20: 0.21 | Q20: 9.56
... A59: 08/05/2025 12:45 | B59: 7.87 | C59: 25.92 | D59: 34.48 | E59: 6.81 | F59: 19.43 | G59: 45.94 | H59: 16.09 | I59: 4.11 | J59: 0.4 | K59: 244.83 | L59: 42.05 | M59: 28.64 | N59: 894.9 | O59: 0 | P59: 0.35 | Q59: 9.55
A60: 08/05/2025 13:00 | B60: 3.55 | C60: 4.71 | D60: 2.58 | E60: 7.85 | F60: 16.77 | G60: Calib. | H60: Calib. | I60: 3.95 | J60: 1.08 | K60: 160.74 | L60: 40.23 | M60: 30.59 | N60: 860.6 | O60: 0 | P60: 0.29 | Q60: 9.56
A61: 08/05/2025 13:15 | B61: 2.81 | C61: 23.63 | D61: 39.47 | E61: 4.65 | F61: 16.72 | G61: Calib. | H61: Calib. | I61: 3.89 | J61: 0.77 | K61: 200.17 | L61: 39.49 | M61: 30.25 | N61: 836.8 | O61: 0 | P61: 0.28 | Q61: 9.56
A62: 08/05/2025 13:30 | B62: Calib. | C62: Calib. | D62: Calib. | E62: 5.71 | F62: 23.33 | G62: Calib. | H62: Calib. | I62: 3.98 | J62: 0.71 | K62: 130.41 | L62: 39.07 | M62: 30.89 | N62: 811.8 | O62: 0 | P62: 0.25 | Q62: 9.53
A63: 08/05/2025 13:45 | B63: Calib. | C63: Calib. | D63: Calib. | E63: 7.85 | F63: 24.19 | G63: Calib. | H63: Calib. | I63: 4.07 | J63: 0.27 | K63: 270.01 | L63: 39.78 | M63: 30.51 | N63: 561.5 | O63: 0 | P63: 0.31 | Q63: 9.5
A64: 08/05/2025 14:00 | B64: 0.59 | C64: 20.76 | D64: 38.84 | E64: 4 | F64: 16.48 | G64: 4.38 | H64: 0.78 | I64: 4.2 | J64: 0.75 | K64: 260.82 | L64: 42 | M64: 27.29 | N64: 490.5 | O64: 0 | P64: 0.31 | Q64: 9.51
A65: 08/05/2025 14:15 | B65: 0.44 | C65: 17.94 | D65: 33.65 | E65: 3.21 | F65: 18.81 | G65: 49.64 | H65: 11.74 | I65: 4.16 | J65: 0.36 | K65: 222.65 | L65: 40.6 | M65: 28.48 | N65: 405.5 | O65: 0 | P65: 0.32 | Q65: 9.52
A66: 08/05/2025 14:30 | B66: 1.45 | C66: 21 | D66: 37.97 | E66: Calib. | F66: 20.64 | G66: 49.64 | H66: 11.74 | I66: 3.98 | J66: 0.27 | K66: 227.37 | L66: 40.28 | M66: 29.01 | N66: 389.6 | O66: 0 | P66: 0.34 | Q66: 9.53
A67: 08/05/2025 14:45 | B67: 0.8 | C67: 18.82 | D67: 34.79 | E67: Calib. | F67: 16.99 | G67: 49.64 | H67: 11.74 | I67: 3.88 | J67: 0.51 | K67: 229.02 | L67: 39.99 | M67: 28.91 | N67: 297.3 | O67: 0 | P67: 0.3 | Q67: 9.54
A68: 08/05/2025 15:00 | B68: 0.77 | C68: 22.58 | D68: 42.03 | E68: Calib. | F68: 19.34 | G68: 48.94 | H68: 11.66 | I68: 4.11 | J68: 0.5 | K68: 252.81 | L68: 40.05 | M68: 29.36 | N68: 280.1 | O68: 0 | P68: 0.33 | Q68: 9.52
A69: 08/05/2025 15:15 | B69: 1.22 | C69: 23.63 | D69: 43.35 | E69: Calib. | F69: 17.03 | G69: 41.7 | H69: 10.56 | I69: 4.1 | J69: 0.89 | K69: 160.83 | L69: 40.15 | M69: 30.6 | N69: 338.5 | O69: 0 | P69: 0.33 | Q69: 9.52
A70: 08/05/2025 15:30 | B70: 1.68 | C70: 21.56 | D70: 38.68 | E70: 2.1 | F70: 11.69 | G70: 41.7 | H70: 10.56 | I70: 4 | J70: 2.71 | K70: 155.11 | L70: 36.09 | M70: 41.12 | N70: 301.8 | O70: 0 | P70: 0.32 | Q70: 9.5
A71: 08/05/2025 15:45 | B71: 3.85 | C71: 22.65 | D71: 37.43 | E71: 0.02 | F71: 3.32 | G71: 41.7 | H71: 10.56 | I71: 3.83 | J71: 1.82 | K71: 160.2 | L71: 35.03 | M71: 44.53 | N71: 197.7 | O71: 0 | P71: 4.48 | Q71: 9.49
A72: 08/05/2025 16:00 | B72: 3.9 | C72: 21.23 | D72: 34.65 | E72: 3.33 | F72: 123.54 | G72: 41.66 | H72: 10.64 | I72: 3.85 | J72: 1.37 | K72: 157.34 | L72: 34.58 | M72: 46.76 | N72: 239.8 | O72: 0 | P72: 0.23 | Q72: 9.47
A73: 08/05/2025 16:15 | B73: 4.02 | C73: 20.94 | D73: 33.92 | E73: 5.64 | F73: 115.69 | G73: 41.18 | H73: 11.76 | I73: 4.02 | J73: 1.38 | K73: 159.69 | L73: 34.71 | M73: 40.5 | N73: 304.8 | O73: 0 | P73: 0.23 | Q73: 9.45
A74: 08/05/2025 16:30 | B74: 4.31 | C74: 21.44 | D74: 34.41 | E74: 5.79 | F74: 112.95 | G74: 41.18 | H74: 11.76 | I74: 4.12 | J74: 1.43 | K74: 151.61 | L74: 34.5 | M74: 37.65 | N74: 201.3 | O74: 0 | P74: 0.21 | Q74: 9.44
A75: 08/05/2025 16:45 | B75: 4.1 | C75: 20.24 | D75: 32.44 | E75: 5.64 | F75: 111.91 | G75: 41.18 | H75: 11.76 | I75: 4.01 | J75: 1.58 | K75: 165.41 | L75: 33.73 | M75: 41.74 | N75: 185.6 | O75: 0 | P75: 0.21 | Q75: 9.43
A76: 08/05/2025 17:00 | B76: 3.97 | C76: 19.32 | D76: 30.89 | E76: 5.75 | F76: 4.5 | G76: 41.33 | H76: 11.73 | I76: 3.96 | J76: 1.66 | K76: 153.14 | L76: 33.23 | M76: 43.76 | N76: 158.6 | O76: 0 | P76: 0.2 | Q76: 9.43
A77: 08/05/2025 17:15 | B77: 4.06 | C77: 19.15 | D77: 30.42 | E77: 5.43 | F77: 3.62 | G77: 43.18 | H77: 11.26 | I77: 4.06 | J77: 1.38 | K77: 167.1 | L77: 32.68 | M77: 45.52 | N77: 126.2 | O77: 0 | P77: 0.2 | Q77: 9.42
A78: 08/05/2025 17:30 | B78: 4.24 | C78: 21.35 | D78: 34.35 | E78: 5.79 | F78: 1.79 | G78: 43.18 | H78: 11.26 | I78: 4 | J78: 2.42 | K78: 158.81 | L78: 32.75 | M78: 46.11 | N78: 136.3 | O78: 0 | P78: 0.2 | Q78: 9.46
A79: 08/05/2025 17:45 | B79: 4.72 | C79: 21.77 | D79: 34.42 | E79: 5.78 | F79: 1.95 | G79: 43.18 | H79: 11.26 | I79: 3.93 | J79: 2.02 | K79: 147.06 | L79: 32.59 | M79: 46.52 | N79: 116.7 | O79: 0 | P79: 0.2 | Q79: 9.48
A80: 08/05/2025 18:00 | B80: 5.16 | C80: 21.2 | D80: 32.67 | E80: 5.67 | F80: 1.85 | G80: 43.26 | H80: 11.11 | I80: 4.15 | J80: 1.7 | K80: 156.51 | L80: 32.67 | M80: 45.81 | N80: 87 | O80: 0 | P80: 0.2 | Q80: 9.47
...

Sheet 09
A1: Station: | B1: BHATAGAON RAIPUR
A2: Date: | B2: =$A$9 -> 09/05/2025 00:15 | D2: Power Off | G2: Pw.Off | L2: Link Fail | N2: Link F | P2: Maintenance | R2: Maint.
A3: Report Type: | B3: Mean | D3: Calibration | G3: Calib. | L3: Data Fail | N3: Data F | P3: Invalid | R3: Invalid
