Workbook

Sheet 01
A1: Station: | B1: IGKV RAIPUR
A2: Date: | B2: =$A$9 -> 01/11/2025 00:15 | C2: Power Off | G2: Pw.Off | J2: Link Fail | L2: Link F | N2: Maintenance | P2: Maint.
A3: Report Type: | B3: Mean | C3: Calibration | G3: Calib. | J3: Data Fail | L3: Data F | N3: Invalid | P3: Invalid
A4: Time Base: | B4: 15 Min | C4: Zero Referrence | G4: Z.Ref | J4: Warm Up | L4: Wm. Up
A7: Date & Time | B7: NO | C7: NO2 | D7: NOX | E7: SO2 | F7: O3 | G7: PM 10 | H7: PM 2.5 | I7: BENZ | J7: WS | K7: WD | L7: TEMP | M7: HUM | N7: SR | O7: RG | P7: CO | Q7: NH3
B8: ug/m3 | C8: ug/m3 | D8: ppb | E8: ug/m3 | F8: ug/m3 | G8: ug/m3 | H8: ug/m3 | I8: ug/m3 | J8: m/sec | K8: deg | L8: degreC | M8: % | N8: w/m2 | O8: mm | P8: mg/m3 | Q8: ug/m3
A9: 01/11/2025 00:15 | B9: 5.08 | C9: 5.17 | D9: 6.77 | E9: 6.63 | F9: 2 | G9: 20.09 | H9: 9.14 | I9: 4.26 | J9: 0.08 | K9: 228.57 | L9: 20.6 | M9: 33.73 | N9: 2.2 | O9: 0 | P9: 0.25 | Q9: 9.32
A10: 01/11/2025 00:30 | B10: 5.07 | C10: 5.2 | D10: 6.79 | E10: 6.57 | F10: 2 | G10: 20.09 | H10: 9.14 | I10: 4.22 | J10: 0.06 | K10: 215.14 | L10: 19.3 | M10: 30.58 | N10: 2.2 | O10: 0 | P10: 0.25 | Q10: 9.32
A11: 01/11/2025 00:45 | B11: 5.13 | C11: 5.25 | D11: 6.86 | E11: 6.65 | F11: 2 | G11: 17.92 | H11: 10.01 | I11: 4.18 | J11: 0.09 | K11: 154.74 | L11: 15.54 | M11: 21.16 | N11: 2.4 | O11: 0 | P11: 0.25 | Q11: 9.32
A12: 01/11/2025 01:00 | B12: 5.13 | C12: 5.26 | D12: 6.86 | E12: 6.64 | F12: 2 | G12: 17.13 | H12: 10.02 | I12: 4.14 | J12: 0.06 | K12: 158.12 | L12: 14.94 | M12: 19.68 | N12: 2.3 | O12: 0 | P12: 0.25 | Q12: 9.32
A13: 01/11/2025 01:15 | B13: 5.13 | C13: 5.22 | D13: 6.84 | E13: 6.49 | F13: 2 | G13: 17.13 | H13: 10.02 | I13: 4.18 | J13: 0.1 | K13: 179.14 | L13: 16.91 | M13: 24.62 | N13: 2.2 | O13: 0 | P13: 0.25 | Q13: 9.32
A14: 01/11/2025 01:30 | B14: 5.13 | C14: 5.17 | D14: 6.82 | E14: 6.67 | F14: 2 | G14: 17.13 | H14: 10.02 | I14: 4.18 | J14: 0.08 | K14: 154.17 | L14: 15.77 | M14: 21.76 | N14: 2.3 | O14: 0 | P14: 0.25 | Q14: 9.32
A15: 01/11/2025 01:45 | B15: 5.17 | C15: 5.13 | D15: 6.83 | E15: 6.59 | F15: 2 | G15: 19.42 | H15: 10.91 | I15: 4.12 | J15: 0.18 | K15: 244.97 | L15: 21.59 | M15: 36.25 | N15: 2.2 | O15: 0 | P15: 0.25 | Q15: 9.32
A16: 01/11/2025 02:00 | B16: 5.21 | C16: 5.1 | D16: 6.84 | E16: 6.53 | F16: 2 | G16: 20.3 | H16: 10.96 | I16: 4.13 | J16: 0.21 | K16: 248.23 | L16: 21.88 | M16: 36.95 | N16: 2.4 | O16: 0 | P16: 0.25 | Q16: 9.32
A17: 01/11/2025 02:15 | B17: 5.23 | C17: 5.1 | D17: 6.86 | E17: 4.43 | F17: 2 | G17: 20.3 | H17: 10.96 | I17: 4.06 | J17: 0.18 | K17: 263.34 | L17: 23.22 | M17: 40.29 | N17: 2.4 | O17: 0 | P17: 0.26 | Q17: 9.32
A18: 01/11/2025 02:30 | B18: 5.17 | C18: 5.12 | D18: 6.82 | E18: 5.4 | F18: 2 | G18: 20.3 | H18: 10.96 | I18: 4.1 | J18: 0.21 | K18: 247.83 | L18: 22.08 | M18: 37.45 | N18: 2.2 | O18: 0 | P18: 0.24 | Q18: 9.32
A19: 01/11/2025 02:45 | B19: 5.11 | C19: 5.07 | D19: 6.74 | E19: 5.56 | F19: 2 | G19: 19.01 | H19: 7.96 | I19: 4.05 | J19: 0.3 | K19: 253.47 | L19: 22.69 | M19: 38.92 | N19: 2.2 | O19: 0 | P19: 0.24 | Q19: 9.32
A20: 01/11/2025 03:00 | B20: 5.05 | C20: 5.1 | D20: 6.71 | E20: 5.42 | F20: 2 | G20: 18.51 | H20: 7.87 | I20: 4.02 | J20: 0.29 | K20: 252.38 | L20: 22.6 | M20: 38.72 | N20: 2.2 | O20: 0 | P20: 0.24 | Q20: 9.32
... A104: 01/11/2025 24:00 | B104: 14.51 | C104: 7.7 | D104: 15.66 | E104: 6.95 | F104: 2 | G104: 94.95 | H104: 42.31 | I104: 6.4 | J104: 0.08 | K104: 199.47 | L104: 19.22 | M104: 30.31 | N104: 2.2 | O104: 0 | P104: 0.61 | Q104: 9.32
A106: Min | B106: =MIN(B9:B104) -> 1.55 | C106: =MIN(C9:C104) -> 4.87 | D106: =MIN(D9:D104) -> 4.78 | E106: =MIN(E9:E104) -> 3.3 | F106: =MIN(F9:F104) -> 2 | G106: =MIN(G9:G104) -> 11.87 | H106: =MIN(H9:H104) -> 6.22 | I106: =MIN(I9:I104) -> 3.48 | ... Q106: =MIN(Q9:Q104) -> 9.32
A107: Max | B107: =MAX(B9:B104) -> 17.77 | C107: =MAX(C9:C104) -> 18.28 | D107: =MAX(D9:D104) -> 20.72 | E107: =MAX(E9:E104) -> 10.73 | F107: =MAX(F9:F104) -> 35.25 | G107: =MAX(G9:G104) -> 98.91 | H107: =MAX(H9:H104) -> 47.31 | I107: =MAX(I9:I104) -> 11.69 | ... Q107: =MAX(Q9:Q104) -> 9.38
A108: Avg | B108: =AVERAGE(B9:B104) -> 7.0338542 | C108: =AVERAGE(C9:C104) -> 8.5667708 | D108: =AVERAGE(D9:D104) -> 10.116042 | E108: =AVERAGE(E9:E104) -> 5.9528125 | F108: =AVERAGE(F9:F104) -> 4.0635417 | G108: =AVERAGE(G9:G104) -> 41.791875 | H108: =AVERAGE(H9:H104) -> 15.398437 | I108: =AVERAGE(I9:I104) -> 5.216875 | ... Q108: =AVERAGE(Q9:Q104) -> 9.3207292
A109: Stdev | B109: =STDEV(B9:B104) -> 3.7007454 | C109: =STDEV(C9:C104) -> 3.5969576 | D109: =STDEV(D9:D104) -> 3.5834701 | E109: =STDEV(E9:E104) -> 1.4968885 | F109: =STDEV(F9:F104) -> 5.5524966 | G109: =STDEV(G9:G104) -> 25.793825 | H109: =STDEV(H9:H104) -> 9.9267671 | I109: =STDEV(I9:I104) -> 1.5466339 | ... Q109: =STDEV(Q9:Q104) -> 0.0061975872
A110: Num | B110: =COUNT(B9:B104) -> 96 | C110: =COUNT(C9:C104) -> 96 | D110: =COUNT(D9:D104) -> 96 | E110: =COUNT(E9:E104) -> 96 | F110: =COUNT(F9:F104) -> 96 | G110: =COUNT(G9:G104) -> 96 | H110: =COUNT(H9:H104) -> 96 | I110: =COUNT(I9:I104) -> 96 | ... Q110: =COUNT(Q9:Q104) -> 96
A111: DCR | B111: =IF(B110>=87,">90%",IF(B110<=87,"<90%")) -> >90% | C111: =IF(C110>=87,">90%",IF(C110<=87,"<90%")) -> >90% | D111: =IF(D110>=87,">90%",IF(D110<=87,"<90%")) -> >90% | E111: =IF(E110>=87,">90%",IF(E110<=87,"<90%")) -> >90% | F111: =IF(F110>=87,">90%",IF(F110<=87,"<90%")) -> >90% | G111: =IF(G110>=87,">90%",IF(G110<=87,"<90%")) -> >90% | H111: =IF(H110>=87,">90%",IF(H110<=87,"<90%")) -> >90% | I111: =IF(I110>=87,">90%",IF(I110<=87,"<90%")) -> >90% | ... Q111: =IF(Q110>=87,">90%",IF(Q110<=87,"<90%")) -> >90%
A112: Status | B112: =IF(B110>=87,"OK",IF(B110<=87,"LESS")) -> OK | C112: =IF(C110>=87,"OK",IF(C110<=87,"LESS")) -> OK | D112: =IF(D110>=87,"OK",IF(D110<=87,"LESS")) -> OK | E112: =IF(E110>=87,"OK",IF(E110<=87,"LESS")) -> OK | F112: =IF(F110>=87,"OK",IF(F110<=87,"LESS")) -> OK | G112: =IF(G110>=87,"OK",IF(G110<=87,"LESS")) -> OK | H112: =IF(H110>=87,"OK",IF(H110<=87,"LESS")) -> OK | I112: =IF(I110>=87,"OK",IF(I110<=87,"LESS")) -> OK | ... Q112: =IF(Q110>=87,"OK",IF(Q110<=87,"LESS")) -> OK
A115: Done by | B115: AKASH
A117: Comment

Sheet 02
A1: Station: | B1: IGKV RAIPUR
A2: Date: | B2: =$A$9 -> 02/11/2025 00:15 | C2: Power Off | G2: Pw.Off | J2: Link Fail | L2: Link F | N2: Maintenance | P2: Maint.
A3: Report Type: | B3: Mean | C3: Calibration | G3: Calib. | J3: Data Fail | L3: Data F | N3: Invalid | P3: Invalid
A4: Time Base: | B4: 15 Min | C4: Zero Referrence | G4: Z.Ref | J4: Warm Up | L4: Wm. Up
A7: Date & Time | B7: NO | C7: NO2 | D7: NOX | E7: SO2 | F7: O3 | G7: PM 10 | H7: PM 2.5 | I7: BENZ | J7: WS | K7: WD | L7: TEMP | M7: HUM | N7: SR | O7: RG | P7: CO | Q7: NH3
B8: ug/m3 | C8: ug/m3 | D8: ppb | E8: ug/m3 | F8: ug/m3 | G8: ug/m3 | H8: ug/m3 | I8: ug/m3 | J8: m/sec | K8: deg | L8: degreC | M8: % | N8: w/m2 | O8: mm | P8: mg/m3 | Q8: ug/m3
A9: 02/11/2025 00:15 | B9: 14.76 | C9: 7.47 | D9: 15.73 | E9: 6.51 | F9: 2 | G9: 94.95 | H9: 42.31 | I9: 6.36 | J9: 0.1 | K9: 174.95 | L9: 16.26 | M9: 22.91 | N9: 2.1 | O9: 0 | P9: 0.62 | Q9: 9.32
A10: 02/11/2025 00:30 | B10: 15.01 | C10: 7.23 | D10: 15.81 | E10: 6.4 | F10: 2 | G10: 94.95 | H10: 42.31 | I10: 6.36 | J10: 0.13 | K10: 170.12 | L10: 17.44 | M10: 25.89 | N10: 2.1 | O10: 0 | P10: 0.61 | Q10: 9.32
A11: 02/11/2025 00:45 | B11: 15.12 | C11: 7.15 | D11: 15.86 | E11: 6.31 | F11: 2 | G11: 89.28 | H11: 43.02 | I11: 6.46 | J11: 0.1 | K11: 165.55 | L11: 15.98 | M11: 22.24 | N11: 2.2 | O11: 0 | P11: 0.62 | Q11: 9.32
A12: 02/11/2025 01:00 | B12: 15.36 | C12: 7.08 | D12: 16.02 | E12: 6.45 | F12: 2 | G12: 87.22 | H12: 43.03 | I12: 6.54 | J12: 0.1 | K12: 169.46 | L12: 16.98 | M12: 24.71 | N12: 2.1 | O12: 0 | P12: 0.62 | Q12: 9.32
A13: 02/11/2025 01:15 | B13: 15.5 | C13: 7.16 | D13: 16.18 | E13: 6.16 | F13: 2 | G13: 87.22 | H13: 43.03 | I13: 6.59 | J13: 0.13 | K13: 147.09 | L13: 14.41 | M13: 18.33 | N13: 2.1 | O13: 0 | P13: 0.63 | Q13: 9.32
A14: 02/11/2025 01:30 | B14: 15.64 | C14: 7.26 | D14: 16.34 | E14: 6.46 | F14: 2 | G14: 87.22 | H14: 43.03 | I14: 6.68 | J14: 0.1 | K14: 155.13 | L14: 14.83 | M14: 19.39 | N14: 2.1 | O14: 0 | P14: 0.62 | Q14: 9.32
A15: 02/11/2025 01:45 | B15: 15.98 | C15: 7.39 | D15: 16.68 | E15: 6.55 | F15: 2 | G15: 86.24 | H15: 41.55 | I15: 6.72 | J15: 0.04 | K15: 327.6 | L15: 22.28 | M15: 37.82 | N15: 2.1 | O15: 0 | P15: 0.62 | Q15: 9.32
A16: 02/11/2025 02:00 | B16: 16.61 | C16: 7.4 | D16: 17.18 | E16: 6.4 | F16: 2 | G16: 85.86 | H16: 41.48 | I16: 6.76 | J16: 0.08 | K16: 121.87 | L16: 12.67 | M16: 13.85 | N16: 2.1 | O16: 0 | P16: 0.64 | Q16: 9.32
A17: 02/11/2025 02:15 | B17: 17.49 | C17: 7.55 | D17: 17.97 | E17: 5.47 | F17: 2 | G17: 85.86 | H17: 41.48 | I17: 6.79 | J17: 0.13 | K17: 164.8 | L17: 15.83 | M17: 21.89 | N17: 2.1 | O17: 0 | P17: 0.64 | Q17: 9.32
A18: 02/11/2025 02:30 | B18: 18.28 | C18: 7.76 | D18: 18.72 | E18: 6.49 | F18: 2 | G18: 85.86 | H18: 41.48 | I18: 6.84 | J18: 0.12 | K18: 215.15 | L18: 18.91 | M18: 29.59 | N18: 2.1 | O18: 0 | P18: 0.64 | Q18: 9.32
A19: 02/11/2025 02:45 | B19: 18.98 | C19: 7.94 | D19: 19.37 | E19: 5.5 | F19: 2 | G19: 98.51 | H19: 45.83 | I19: 6.96 | J19: 0.1 | K19: 192.86 | L19: 17.73 | M19: 26.61 | N19: 2.1 | O19: 0 | P19: 0.64 | Q19: 9.32
A20: 02/11/2025 03:00 | B20: 19.72 | C20: 8.06 | D20: 20.03 | E20: 6.62 | F20: 2 | G20: 103.38 | H20: 45.96 | I20: 7.07 | J20: 0.1 | K20: 150.81 | L20: 15.2 | M20: 20.29 | N20: 2.1 | O20: 0 | P20: 0.65 | Q20: 9.32
... A104: 02/11/2025 24:00 | B104: 9.12 | C104: 6.64 | D104: 10.78 | E104: 6.38 | F104: 2 | G104: 63.53 | H104: 21.25 | I104: 7.66 | J104: 0.18 | K104: 148.15 | L104: 14.35 | M104: 18.16 | N104: 2.1 | O104: 0 | P104: 0.65 | Q104: 9.32
A106: Min | B106: =MIN(B9:B104) -> 5.36 | C106: =MIN(C9:C104) -> 6.27 | D106: =MIN(D9:D104) -> 9.43 | E106: =MIN(E9:E104) -> 4.29 | F106: =MIN(F9:F104) -> 2 | G106: =MIN(G9:G104) -> 50.33 | H106: =MIN(H9:H104) -> 16.09 | I106: =MIN(I9:I104) -> 6.12 | ... Q106: =MIN(Q9:Q104) -> 9.32
A107: Max | B107: =MAX(B9:B104) -> 21.15 | C107: =MAX(C9:C104) -> 14.6 | D107: =MAX(D9:D104) -> 21.2 | E107: =MAX(E9:E104) -> 14.01 | F107: =MAX(F9:F104) -> 5.35 | G107: =MAX(G9:G104) -> 108.61 | H107: =MAX(H9:H104) -> 50.42 | I107: =MAX(I9:I104) -> 8.54 | ... Q107: =MAX(Q9:Q104) -> 9.32
A108: Avg | B108: =AVERAGE(B9:B104) -> 12.643021 | C108: =AVERAGE(C9:C104) -> 8.5791667 | D108: =AVERAGE(D9:D104) -> 14.620938 | E108: =AVERAGE(E9:E104) -> 7.3913542 | F108: =AVERAGE(F9:F104) -> 2.2475 | G108: =AVERAGE(G9:G104) -> 73.824375 | H108: =AVERAGE(H9:H104) -> 30.664896 | I108: =AVERAGE(I9:I104) -> 7.1996875 | ... Q108: =AVERAGE(Q9:Q104) -> 9.32
A109: Stdev | B109: =STDEV(B9:B104) -> 5.2991924 | C109: =STDEV(C9:C104) -> 1.8659879 | D109: =STDEV(D9:D104) -> 3.9846445 | E109: =STDEV(E9:E104) -> 1.7906286 | F109: =STDEV(F9:F104) -> 0.75636527 | G109: =STDEV(G9:G104) -> 14.639539 | H109: =STDEV(H9:H104) -> 10.112073 | I109: =STDEV(I9:I104) -> 0.6281459 | ... Q109: =STDEV(Q9:Q104) -> 1.7856816e-14
A110: Num | B110: =COUNT(B9:B104) -> 96 | C110: =COUNT(C9:C104) -> 96 | D110: =COUNT(D9:D104) -> 96 | E110: =COUNT(E9:E104) -> 96 | F110: =COUNT(F9:F104) -> 96 | G110: =COUNT(G9:G104) -> 96 | H110: =COUNT(H9:H104) -> 96 | I110: =COUNT(I9:I104) -> 96 | ... Q110: =COUNT(Q9:Q104) -> 96
A111: DCR | B111: =IF(B110>=87,">90%",IF(B110<=87,"<90%")) -> >90% | C111: =IF(C110>=87,">90%",IF(C110<=87,"<90%")) -> >90% | D111: =IF(D110>=87,">90%",IF(D110<=87,"<90%")) -> >90% | E111: =IF(E110>=87,">90%",IF(E110<=87,"<90%")) -> >90% | F111: =IF(F110>=87,">90%",IF(F110<=87,"<90%")) -> >90% | G111: =IF(G110>=87,">90%",IF(G110<=87,"<90%")) -> >90% | H111: =IF(H110>=87,">90%",IF(H110<=87,"<90%")) -> >90% | I111: =IF(I110>=87,">90%",IF(I110<=87,"<90%")) -> >90% | ... Q111: =IF(Q110>=87,">90%",IF(Q110<=87,"<90%")) -> >90%
A112: Status | B112: =IF(B110>=87,"OK",IF(B110<=87,"LESS")) -> OK | C112: =IF(C110>=87,"OK",IF(C110<=87,"LESS")) -> OK | D112: =IF(D110>=87,"OK",IF(D110<=87,"LESS")) -> OK | E112: =IF(E110>=87,"OK",IF(E110<=87,"LESS")) -> OK | F112: =IF(F110>=87,"OK",IF(F110<=87,"LESS")) -> OK | G112: =IF(G110>=87,"OK",IF(G110<=87,"LESS")) -> OK | H112: =IF(H110>=87,"OK",IF(H110<=87,"LESS")) -> OK | I112: =IF(I110>=87,"OK",IF(I110<=87,"LESS")) -> OK | ... Q112: =IF(Q110>=87,"OK",IF(Q110<=87,"LESS")) -> OK
A115: Done by | B115: AKASH
A117: Comment

Sheet 03
A1: Station: | B1: IGKV RAIPUR
A2: Date: | B2: =$A$9 -> 03/11/2025 00:15 | C2: Power Off | G2: Pw.Off | J2: Link Fail | L2: Link F | N2: Maintenance | P2: Maint.
A3: Report Type: | B3: Mean | C3: Calibration | G3: Calib. | J3: Data Fail | L3: Data F | N3: Invalid | P3: Invalid
A4: Time Base: | B4: 15 Min | C4: Zero Referrence | G4: Z.Ref | J4: Warm Up | L4: Wm. Up
A7: Date & Time | B7: NO | C7: NO2 | D7: NOX | E7: SO2 | F7: O3 | G7: PM 10 | H7: PM 2.5 | I7: BENZ | J7: WS | K7: WD | L7: TEMP | M7: HUM | N7: SR | O7: RG | P7: CO | Q7: NH3
B8: ug/m3 | C8: ug/m3 | D8: ppb | E8: ug/m3 | F8: ug/m3 | G8: ug/m3 | H8: ug/m3 | I8: ug/m3 | J8: m/sec | K8: deg | L8: degreC | M8: % | N8: w/m2 | O8: mm | P8: mg/m3 | Q8: ug/m3
A9: 03/11/2025 00:15 | B9: 8.58 | C9: 6.62 | D9: 10.34 | E9: 6.09 | F9: 2 | G9: 63.53 | H9: 21.25 | I9: 7.74 | J9: 0.13 | K9: 138.94 | L9: 13.26 | M9: 15.4 | N9: 2.1 | O9: 0 | P9: 0.64 | Q9: 9.32
A10: 03/11/2025 00:30 | B10: 8.13 | C10: 6.97 | D10: 10.16 | E10: 5.88 | F10: 2 | G10: 63.53 | H10: 21.25 | I10: 7.84 | J10: 0.16 | K10: 151.07 | L10: 14.94 | M10: 19.58 | N10: 2.2 | O10: 0 | P10: 0.63 | Q10: 9.32
A11: 03/11/2025 00:45 | B11: 8.02 | C11: 6.94 | D11: 10.06 | E11: 6.4 | F11: 2 | G11: 65.49 | H11: 21.41 | I11: 7.96 | J11: 0.16 | K11: 151.73 | L11: 14.68 | M11: 18.8 | N11: 2.2 | O11: 0 | P11: 0.63 | Q11: 9.32
A12: 03/11/2025 01:00 | B12: 8.17 | C12: 6.86 | D12: 10.13 | E12: 6.43 | F12: 2 | G12: 66.2 | H12: 21.42 | I12: 7.98 | J12: 0.07 | K12: 227.37 | L12: 20.57 | M12: 33.42 | N12: 2.2 | O12: 0 | P12: 0.64 | Q12: 9.32
A13: 03/11/2025 01:15 | B13: 9.17 | C13: 7.3 | D13: 11.17 | E13: 5.9 | F13: 2 | G13: 66.2 | H13: 21.42 | I13: 8.01 | J13: 0.11 | K13: 187.67 | L13: 17.03 | M13: 24.64 | N13: 2.1 | O13: 0 | P13: 0.65 | Q13: 9.32
A14: 03/11/2025 01:30 | B14: 9.81 | C14: 7.42 | D14: 11.74 | E14: 6.1 | F14: 2 | G14: 66.2 | H14: 21.42 | I14: 8.1 | J14: 0.08 | K14: 190.39 | L14: 17.99 | M14: 27.11 | N14: 2.2 | O14: 0 | P14: 0.65 | Q14: 9.32
A15: 03/11/2025 01:45 | B15: 10.17 | C15: 7.56 | D15: 12.1 | E15: 6.06 | F15: 2 | G15: 63.22 | H15: 25.35 | I15: 8.25 | J15: 0.14 | K15: 183.14 | L15: 17.51 | M15: 25.85 | N15: 2.1 | O15: 0 | P15: 0.66 | Q15: 9.32
A16: 03/11/2025 02:00 | B16: 10.12 | C16: 7.38 | D16: 11.97 | E16: 6.35 | F16: 2 | G16: 62.13 | H16: 26.3 | I16: 8.35 | J16: 0.17 | K16: 150.43 | L16: 14.67 | M16: 18.72 | N16: 2.1 | O16: 0 | P16: 0.65 | Q16: 9.32
A17: 03/11/2025 02:15 | B17: 9.95 | C17: 7.15 | D17: 11.71 | E17: 6.13 | F17: 2 | G17: 62.13 | H17: 26.3 | I17: 8.33 | J17: 0.12 | K17: 141.29 | L17: 14.29 | M17: 17.83 | N17: 2.3 | O17: 0 | P17: 0.66 | Q17: 9.32
A18: 03/11/2025 02:30 | B18: 9.76 | C18: 6.89 | D18: 11.43 | E18: 7.28 | F18: 2 | G18: 62.13 | H18: 26.3 | I18: 8.33 | J18: 0.08 | K18: 178.7 | L18: 15.67 | M18: 21.33 | N18: 2.2 | O18: 0 | P18: 0.65 | Q18: 9.32
A19: 03/11/2025 02:45 | B19: 9.48 | C19: 6.84 | D19: 11.18 | E19: 7.11 | F19: 2 | G19: 60.64 | H19: 21.55 | I19: 8.36 | J19: 0.12 | K19: 143.54 | L19: 14.26 | M19: 17.76 | N19: 2.1 | O19: 0 | P19: 0.65 | Q19: 9.32
A20: 03/11/2025 03:00 | B20: 9.8 | C20: 6.8 | D20: 11.41 | E20: 7.08 | F20: 2 | G20: 60.07 | H20: 21.4 | I20: 8.38 | J20: 0.15 | K20: 146.44 | L20: 14.42 | M20: 18.17 | N20: 2.1 | O20: 0 | P20: 0.66 | Q20: 9.32
... A104: 03/11/2025 24:00 | B104: 10.36 | C104: 10.33 | D104: 13.7 | E104: 8.03 | F104: 2 | G104: 72.73 | H104: 26.69 | I104: 8.89 | J104: 0.1 | K104: 290.39 | L104: 19.49 | M104: 30.76 | N104: 1.9 | O104: 0 | P104: 0.76 | Q104: 9.32
A106: Min | B106: =MIN(B9:B104) -> 2.88 | C106: =MIN(C9:C104) -> 6.62 | D106: =MIN(D9:D104) -> 7.13 | E106: =MIN(E9:E104) -> 5.49 | F106: =MIN(F9:F104) -> 2 | G106: =MIN(G9:G104) -> 55.73 | H106: =MIN(H9:H104) -> 20.54 | I106: =MIN(I9:I104) -> 5.65 | ... Q106: =MIN(Q9:Q104) -> 9.27
A107: Max | B107: =MAX(B9:B104) -> 19.63 | C107: =MAX(C9:C104) -> 12.03 | D107: =MAX(D9:D104) -> 20.2 | E107: =MAX(E9:E104) -> 9.3 | F107: =MAX(F9:F104) -> 8.18 | G107: =MAX(G9:G104) -> 89.04 | H107: =MAX(H9:H104) -> 31.56 | I107: =MAX(I9:I104) -> 8.89 | ... Q107: =MAX(Q9:Q104) -> 17.73
A108: Avg | B108: =AVERAGE(B9:B104) -> 9.5786458 | C108: =AVERAGE(C9:C104) -> 8.665 | D108: =AVERAGE(D9:D104) -> 12.208854 | E108: =AVERAGE(E9:E104) -> 7.4814583 | F108: =AVERAGE(F9:F104) -> 2.5711458 | G108: =AVERAGE(G9:G104) -> 66.044687 | H108: =AVERAGE(H9:H104) -> 24.594167 | I108: =AVERAGE(I9:I104) -> 7.5571875 | ... Q108: =AVERAGE(Q9:Q104) -> 9.4334375
A109: Stdev | B109: =STDEV(B9:B104) -> 5.6788217 | C109: =STDEV(C9:C104) -> 1.3658073 | D109: =STDEV(D9:D104) -> 4.5270541 | E109: =STDEV(E9:E104) -> 0.81204871 | F109: =STDEV(F9:F104) -> 1.2689447 | G109: =STDEV(G9:G104) -> 8.0353852 | H109: =STDEV(H9:H104) -> 2.9454485 | I109: =STDEV(I9:I104) -> 1.0322196 | ... Q109: =STDEV(Q9:Q104) -> 0.87712668
A110: Num | B110: =COUNT(B9:B104) -> 96 | C110: =COUNT(C9:C104) -> 96 | D110: =COUNT(D9:D104) -> 96 | E110: =COUNT(E9:E104) -> 96 | F110: =COUNT(F9:F104) -> 96 | G110: =COUNT(G9:G104) -> 96 | H110: =COUNT(H9:H104) -> 96 | I110: =COUNT(I9:I104) -> 96 | ... Q110: =COUNT(Q9:Q104) -> 96
A111: DCR | B111: =IF(B110>=87,">90%",IF(B110<=87,"<90%")) -> >90% | C111: =IF(C110>=87,">90%",IF(C110<=87,"<90%")) -> >90% | D111: =IF(D110>=87,">90%",IF(D110<=87,"<90%")) -> >90% | E111: =IF(E110>=87,">90%",IF(E110<=87,"<90%")) -> >90% | F111: =IF(F110>=87,">90%",IF(F110<=87,"<90%")) -> >90% | G111: =IF(G110>=87,">90%",IF(G110<=87,"<90%")) -> >90% | H111: =IF(H110>=87,">90%",IF(H110<=87,"<90%")) -> >90% | I111: =IF(I110>=87,">90%",IF(I110<=87,"<90%")) -> >90% | ... Q111: =IF(Q110>=87,">90%",IF(Q110<=87,"<90%")) -> >90%
A112: Status | B112: =IF(B110>=87,"OK",IF(B110<=87,"LESS")) -> OK | C112: =IF(C110>=87,"OK",IF(C110<=87,"LESS")) -> OK | D112: =IF(D110>=87,"OK",IF(D110<=87,"LESS")) -> OK | E112: =IF(E110>=87,"OK",IF(E110<=87,"LESS")) -> OK | F112: =IF(F110>=87,"OK",IF(F110<=87,"LESS")) -> OK | G112: =IF(G110>=87,"OK",IF(G110<=87,"LESS")) -> OK | H112: =IF(H110>=87,"OK",IF(H110<=87,"LESS")) -> OK | I112: =IF(I110>=87,"OK",IF(I110<=87,"LESS")) -> OK | ... Q112: =IF(Q110>=87,"OK",IF(Q110<=87,"LESS")) -> OK
A115: Done by | B115: AKASH
A117: Comment

Sheet 04
A1: Station: | B1: IGKV RAIPUR
A2: Date: | B2: =$A$9 -> 04/11/2025 00:15 | C2: Power Off | G2: Pw.Off | J2: Link Fail | L2: Link F | N2: Maintenance | P2: Maint.
A3: Report Type: | B3: Mean | C3: Calibration | G3: Calib. | J3: Data Fail | L3: Data F | N3: Invalid | P3: Invalid
A4: Time Base: | B4: 15 Min | C4: Zero Referrence | G4: Z.Ref | J4: Warm Up | L4: Wm. Up
A7: Date & Time | B7: NO | C7: NO2 | D7: NOX | E7: SO2 | F7: O3 | G7: PM 10 | H7: PM 2.5 | I7: BENZ | J7: WS | K7: WD | L7: TEMP | M7: HUM | N7: SR | O7: RG | P7: CO | Q7: NH3
B8: ug/m3 | C8: ug/m3 | D8: ppb | E8: ug/m3 | F8: ug/m3 | G8: ug/m3 | H8: ug/m3 | I8: ug/m3 | J8: m/sec | K8: deg | L8: degreC | M8: % | N8: w/m2 | O8: mm | P8: mg/m3 | Q8: ug/m3
A9: 04/11/2025 00:15 | B9: 10.11 | C9: 10.75 | D9: 13.73 | E9: 7.81 | F9: 2 | G9: 72.73 | H9: 26.69 | I9: 9.43 | J9: 0.1 | K9: 56.72 | L9: 12.68 | M9: 13.65 | N9: 2.1 | O9: 0 | P9: 0.75 | Q9: 9.32
A10: 04/11/2025 00:30 | B10: 9.17 | C10: 8.61 | D10: 11.86 | E10: 7.33 | F10: 2 | G10: 72.73 | H10: 26.69 | I10: 9.84 | J10: 0.26 | K10: 27.66 | L10: 12.49 | M10: 13 | N10: 2.2 | O10: 0 | P10: 0.73 | Q10: 9.32
A11: 04/11/2025 00:45 | B11: 9.13 | C11: 7.93 | D11: 11.47 | E11: 7.53 | F11: 2 | G11: 76.04 | H11: 32.5 | I11: 9.74 | J11: 0.23 | K11: 25.34 | L11: 12.08 | M11: 12.06 | N11: 2.5 | O11: 0 | P11: 0.75 | Q11: 9.32
A12: 04/11/2025 01:00 | B12: 9.26 | C12: 7.61 | D12: 11.41 | E12: 7.25 | F12: 2 | G12: 77.24 | H12: 32.58 | I12: 9.48 | J12: 0.22 | K12: 11.82 | L12: 14.9 | M12: 19.06 | N12: 2.4 | O12: 0 | P12: 0.78 | Q12: 9.32
A13: 04/11/2025 01:15 | B13: 9.54 | C13: 7.5 | D13: 11.57 | E13: 7.36 | F13: 2 | G13: 77.24 | H13: 32.58 | I13: 9.41 | J13: 0.28 | K13: 25.59 | L13: 7.23 | M13: -0.2 | N13: 2.4 | O13: 0 | P13: 0.78 | Q13: 9.32
A14: 04/11/2025 01:30 | B14: 9.93 | C14: 7.38 | D14: 11.82 | E14: 7.47 | F14: 2 | G14: 77.24 | H14: 32.58 | I14: 9.43 | J14: 0.21 | K14: 26.84 | L14: 9.72 | M14: 6.14 | N14: 2.3 | O14: 0 | P14: 0.78 | Q14: 9.32
A15: 04/11/2025 01:45 | B15: 10.45 | C15: 7.42 | D15: 12.25 | E15: 7.49 | F15: 2 | G15: 85.53 | H15: 32.57 | I15: 9.39 | J15: 0.13 | K15: 27.73 | L15: 8.29 | M15: 2.58 | N15: 2.2 | O15: 0 | P15: 0.78 | Q15: 9.32
A16: 04/11/2025 02:00 | B16: 11.09 | C16: 7.42 | D16: 12.77 | E16: 7.5 | F16: 2 | G16: 88.72 | H16: 32.57 | I16: 9.37 | J16: 0.15 | K16: 14.05 | L16: 13.56 | M16: 15.82 | N16: 2.1 | O16: 0 | P16: 0.78 | Q16: 9.32
A17: 04/11/2025 02:15 | B17: 11.57 | C17: 7.49 | D17: 13.19 | E17: 6.44 | F17: 2 | G17: 88.72 | H17: 32.57 | I17: 9.37 | J17: 0.21 | K17: 25.43 | L17: 11.5 | M17: 10.59 | N17: 2.1 | O17: 0 | P17: 0.79 | Q17: 9.32
A18: 04/11/2025 02:30 | B18: 11.98 | C18: 7.53 | D18: 13.54 | E18: 7.81 | F18: 2 | G18: 88.72 | H18: 32.57 | I18: 9.38 | J18: 0.24 | K18: 38.62 | L18: 8.53 | M18: 3.23 | N18: 2.2 | O18: 0 | P18: 0.79 | Q18: 9.32
A19: 04/11/2025 02:45 | B19: 12.35 | C19: 7.53 | D19: 13.84 | E19: 7.69 | F19: 2 | G19: 101.26 | H19: 31.14 | I19: 9.4 | J19: 0.19 | K19: 46.84 | L19: 11.41 | M19: 10.44 | N19: 2.1 | O19: 0 | P19: 0.79 | Q19: 9.32
A20: 04/11/2025 03:00 | B20: 12.85 | C20: 7.53 | D20: 14.24 | E20: 7.51 | F20: 2 | G20: 105.81 | H20: 31.09 | I20: 9.38 | J20: 0.2 | K20: 40.9 | L20: 7.91 | M20: 1.68 | N20: 2.1 | O20: 0 | P20: 0.79 | Q20: 9.32
... A104: 04/11/2025 24:00 | B104: 11.8 | C104: 7.96 | D104: 13.62 | E104: 6.53 | F104: 2 | G104: 96.92 | H104: 29.99 | I104: 9.22 | J104: 0.1 | K104: 181.12 | L104: 17.04 | M104: 24.89 | N104: 2.1 | O104: 0 | P104: 0.7 | Q104: 32.49
A106: Min | B106: =MIN(B9:B104) -> 3.41 | C106: =MIN(C9:C104) -> 7.38 | D106: =MIN(D9:D104) -> 8.31 | E106: =MIN(E9:E104) -> 5.51 | F106: =MIN(F9:F104) -> 2 | G106: =MIN(G9:G104) -> 59.82 | H106: =MIN(H9:H104) -> 21.02 | I106: =MIN(I9:I104) -> 5.87 | ... Q106: =MIN(Q9:Q104) -> 9.32
A107: Max | B107: =MAX(B9:B104) -> 15.22 | C107: =MAX(C9:C104) -> 14.56 | D107: =MAX(D9:D104) -> 16.6 | E107: =MAX(E9:E104) -> 13.91 | F107: =MAX(F9:F104) -> 9.29 | G107: =MAX(G9:G104) -> 108.27 | H107: =MAX(H9:H104) -> 34.01 | I107: =MAX(I9:I104) -> 9.84 | ... Q107: =MAX(Q9:Q104) -> 32.49
A108: Avg | B108: =AVERAGE(B9:B104) -> 9.1133333 | C108: =AVERAGE(C9:C104) -> 9.0895833 | D108: =AVERAGE(D9:D104) -> 12.0575 | E108: =AVERAGE(E9:E104) -> 7.8457292 | F108: =AVERAGE(F9:F104) -> 2.3182292 | G108: =AVERAGE(G9:G104) -> 83.881042 | H108: =AVERAGE(H9:H104) -> 28.561875 | I108: =AVERAGE(I9:I104) -> 8.0591667 | ... Q108: =AVERAGE(Q9:Q104) -> 9.7610417
A109: Stdev | B109: =STDEV(B9:B104) -> 3.8303724 | C109: =STDEV(C9:C104) -> 1.7266694 | D109: =STDEV(D9:D104) -> 2.6598678 | E109: =STDEV(E9:E104) -> 1.7204453 | F109: =STDEV(F9:F104) -> 1.1610431 | G109: =STDEV(G9:G104) -> 14.579962 | H109: =STDEV(H9:H104) -> 3.5655496 | I109: =STDEV(I9:I104) -> 1.0665129 | ... Q109: =STDEV(Q9:Q104) -> 2.722702
A110: Num | B110: =COUNT(B9:B104) -> 96 | C110: =COUNT(C9:C104) -> 96 | D110: =COUNT(D9:D104) -> 96 | E110: =COUNT(E9:E104) -> 96 | F110: =COUNT(F9:F104) -> 96 | G110: =COUNT(G9:G104) -> 96 | H110: =COUNT(H9:H104) -> 96 | I110: =COUNT(I9:I104) -> 96 | ... Q110: =COUNT(Q9:Q104) -> 96
A111: DCR | B111: =IF(B110>=87,">90%",IF(B110<=87,"<90%")) -> >90% | C111: =IF(C110>=87,">90%",IF(C110<=87,"<90%")) -> >90% | D111: =IF(D110>=87,">90%",IF(D110<=87,"<90%")) -> >90% | E111: =IF(E110>=87,">90%",IF(E110<=87,"<90%")) -> >90% | F111: =IF(F110>=87,">90%",IF(F110<=87,"<90%")) -> >90% | G111: =IF(G110>=87,">90%",IF(G110<=87,"<90%")) -> >90% | H111: =IF(H110>=87,">90%",IF(H110<=87,"<90%")) -> >90% | I111: =IF(I110>=87,">90%",IF(I110<=87,"<90%")) -> >90% | ... Q111: =IF(Q110>=87,">90%",IF(Q110<=87,"<90%")) -> >90%
A112: Status | B112: =IF(B110>=87,"OK",IF(B110<=87,"LESS")) -> OK | C112: =IF(C110>=87,"OK",IF(C110<=87,"LESS")) -> OK | D112: =IF(D110>=87,"OK",IF(D110<=87,"LESS")) -> OK | E112: =IF(E110>=87,"OK",IF(E110<=87,"LESS")) -> OK | F112: =IF(F110>=87,"OK",IF(F110<=87,"LESS")) -> OK | G112: =IF(G110>=87,"OK",IF(G110<=87,"LESS")) -> OK | H112: =IF(H110>=87,"OK",IF(H110<=87,"LESS")) -> OK | I112: =IF(I110>=87,"OK",IF(I110<=87,"LESS")) -> OK | ... Q112: =IF(Q110>=87,"OK",IF(Q110<=87,"LESS")) -> OK
A115: Done by | B115: AKASH
A117: Comment

Sheet 05
A1: Station: | B1: IGKV RAIPUR
A2: Date: | B2: =$A$9 -> 05/11/2025 00:15 | C2: Power Off | G2: Pw.Off | J2: Link Fail | L2: Link F | N2: Maintenance | P2: Maint.
A3: Report Type: | B3: Mean | C3: Calibration | G3: Calib. | J3: Data Fail | L3: Data F | N3: Invalid | P3: Invalid
A4: Time Base: | B4: 15 Min | C4: Zero Referrence | G4: Z.Ref | J4: Warm Up | L4: Wm. Up
A7: Date & Time | B7: NO | C7: NO2 | D7: NOX | E7: SO2 | F7: O3 | G7: PM 10 | H7: PM 2.5 | I7: BENZ | J7: WS | K7: WD | L7: TEMP | M7: HUM | N7: SR | O7: RG | P7: CO | Q7: NH3
B8: ug/m3 | C8: ug/m3 | D8: ppb | E8: ug/m3 | F8: ug/m3 | G8: ug/m3 | H8: ug/m3 | I8: ug/m3 | J8: m/sec | K8: deg | L8: degreC | M8: % | N8: w/m2 | O8: mm | P8: mg/m3 | Q8: ug/m3
A9: 05/11/2025 00:15 | B9: 12.66 | C9: 8 | D9: 14.33 | E9: 6.61 | F9: 2 | G9: 96.92 | H9: 29.99 | I9: 9.24 | J9: 0.14 | K9: 207.69 | L9: 19.15 | M9: 30.2 | N9: 2 | O9: 0 | P9: 0.7 | Q9: 11.01
A10: 05/11/2025 00:30 | B10: 12.76 | C10: 8.05 | D10: 14.43 | E10: 6.77 | F10: 2 | G10: 96.92 | H10: 29.99 | I10: 9.31 | J10: 0.13 | K10: 208.24 | L10: 18.76 | M10: 29.24 | N10: 2.3 | O10: 0 | P10: 0.71 | Q10: 9.42
A11: 05/11/2025 00:45 | B11: 12.9 | C11: 8.02 | D11: 14.53 | E11: 6.29 | F11: 2 | G11: 91.44 | H11: 26.62 | I11: 9.36 | J11: 0.08 | K11: 211.59 | L11: 19.47 | M11: 31.03 | N11: 2.1 | O11: 0 | P11: 0.71 | Q11: 9.32
A12: 05/11/2025 01:00 | B12: 13.03 | C12: 7.91 | D12: 14.58 | E12: 6.73 | F12: 2 | G12: 89.44 | H12: 26.47 | I12: 9.38 | J12: 0.09 | K12: 145.15 | L12: 14.57 | M12: 18.75 | N12: 2.1 | O12: 0 | P12: 0.7 | Q12: 9.32
A13: 05/11/2025 01:15 | B13: 13.25 | C13: 7.82 | D13: 14.71 | E13: 6.4 | F13: 2 | G13: 89.44 | H13: 26.47 | I13: 9.4 | J13: 0.1 | K13: 185.77 | L13: 17.73 | M13: 26.65 | N13: 2.1 | O13: 0 | P13: 0.68 | Q13: 14.49
A14: 05/11/2025 01:30 | B14: 14.26 | C14: 8.1 | D14: 15.67 | E14: 6.65 | F14: 2 | G14: 89.44 | H14: 26.47 | I14: 9.47 | J14: 0.13 | K14: 161.78 | L14: 15.89 | M14: 21.98 | N14: 2.1 | O14: 0 | P14: 0.66 | Q14: 14.08
A15: 05/11/2025 01:45 | B15: 15.81 | C15: 8.65 | D15: 17.2 | E15: 6.92 | F15: 2 | G15: 92.52 | H15: 28.83 | I15: 9.52 | J15: 0.18 | K15: 152.6 | L15: 15.05 | M15: 19.76 | N15: 2 | O15: 0 | P15: 0.67 | Q15: 10.48
A16: 05/11/2025 02:00 | B16: 17.11 | C16: 8.96 | D16: 18.41 | E16: 6.8 | F16: 2 | G16: 93.71 | H16: 28.95 | I16: 9.52 | J16: 0.11 | K16: 208.17 | L16: 19.26 | M16: 30.19 | N16: 2.1 | O16: 0 | P16: 0.67 | Q16: 10.01
A17: 05/11/2025 02:15 | B17: 17.31 | C17: 8.9 | D17: 18.53 | E17: 5.25 | F17: 2 | G17: 93.71 | H17: 28.95 | I17: 9.58 | J17: 0.13 | K17: 225.15 | L17: 19.73 | M17: 31.41 | N17: 2.1 | O17: 0 | P17: 0.67 | Q17: 10.29
A18: 05/11/2025 02:30 | B18: 17.04 | C18: 8.78 | D18: 18.25 | E18: 6.41 | F18: 2 | G18: 93.71 | H18: 28.95 | I18: 9.64 | J18: 0.17 | K18: 165.65 | L18: 15.91 | M18: 21.97 | N18: 2.1 | O18: 0 | P18: 0.67 | Q18: 9.49
A19: 05/11/2025 02:45 | B19: 16.64 | C19: 8.62 | D19: 17.85 | E19: 6.2 | F19: 2 | G19: 84.31 | H19: 28.87 | I19: 9.66 | J19: 0.09 | K19: 171.43 | L19: 16.77 | M19: 24.05 | N19: 2.1 | O19: 0 | P19: 0.67 | Q19: 9.32
A20: 05/11/2025 03:00 | B20: 16.25 | C20: 8.43 | D20: 17.43 | E20: 6.24 | F20: 2 | G20: 80.69 | H20: 28.87 | I20: 9.67 | J20: 0.18 | K20: 124.93 | L20: 12.74 | M20: 13.97 | N20: 2 | O20: 0 | P20: 0.67 | Q20: 9.46
... A104: 05/11/2025 24:00 | B104: 8.74 | C104: 10.28 | D104: 12.38 | E104: 7.1 | F104: 2 | G104: 73.32 | H104: 29.87 | I104: 7.29 | J104: 0.13 | K104: 198.77 | L104: 19.14 | M104: 29.95 | N104: 2.1 | O104: 0 | P104: 0.67 | Q104: 9.32
A106: Min | B106: =MIN(B9:B104) -> 1.65 | C106: =MIN(C9:C104) -> 6.74 | D106: =MIN(D9:D104) -> 5.97 | E106: =MIN(E9:E104) -> 3.99 | F106: =MIN(F9:F104) -> 1.45 | G106: =MIN(G9:G104) -> 0 | H106: =MIN(H9:H104) -> 0 | I106: =MIN(I9:I104) -> 3.59 | ... Q106: =MIN(Q9:Q104) -> 9.32
A107: Max | B107: =MAX(B9:B104) -> 21.7 | C107: =MAX(C9:C104) -> 21.57 | D107: =MAX(D9:D104) -> 22.18 | E107: =MAX(E9:E104) -> 16.9 | F107: =MAX(F9:F104) -> 259.23 | G107: =MAX(G9:G104) -> 100.83 | H107: =MAX(H9:H104) -> 46.42 | I107: =MAX(I9:I104) -> 12.12 | ... Q107: =MAX(Q9:Q104) -> 14.49
A108: Avg | B108: =AVERAGE(B9:B104) -> 9.2715625 | C108: =AVERAGE(C9:C104) -> 10.269896 | D108: =AVERAGE(D9:D104) -> 12.801354 | E108: =AVERAGE(E9:E104) -> 7.0827083 | F108: =AVERAGE(F9:F104) -> 11.035521 | G108: =AVERAGE(G9:G104) -> 71.388958 | H108: =AVERAGE(H9:H104) -> 29.821667 | I108: =AVERAGE(I9:I104) -> 8.4905208 | ... Q108: =AVERAGE(Q9:Q104) -> 9.5391667
A109: Stdev | B109: =STDEV(B9:B104) -> 7.0521058 | C109: =STDEV(C9:C104) -> 3.057774 | D109: =STDEV(D9:D104) -> 5.1531427 | E109: =STDEV(E9:E104) -> 2.5024954 | F109: =STDEV(F9:F104) -> 29.301746 | G109: =STDEV(G9:G104) -> 22.164177 | H109: =STDEV(H9:H104) -> 8.0660311 | I109: =STDEV(I9:I104) -> 2.3907666 | ... Q109: =STDEV(Q9:Q104) -> 0.7936414
A110: Num | B110: =COUNT(B9:B104) -> 96 | C110: =COUNT(C9:C104) -> 96 | D110: =COUNT(D9:D104) -> 96 | E110: =COUNT(E9:E104) -> 96 | F110: =COUNT(F9:F104) -> 96 | G110: =COUNT(G9:G104) -> 96 | H110: =COUNT(H9:H104) -> 96 | I110: =COUNT(I9:I104) -> 96 | ... Q110: =COUNT(Q9:Q104) -> 96
A111: DCR | B111: =IF(B110>=87,">90%",IF(B110<=87,"<90%")) -> >90% | C111: =IF(C110>=87,">90%",IF(C110<=87,"<90%")) -> >90% | D111: =IF(D110>=87,">90%",IF(D110<=87,"<90%")) -> >90% | E111: =IF(E110>=87,">90%",IF(E110<=87,"<90%")) -> >90% | F111: =IF(F110>=87,">90%",IF(F110<=87,"<90%")) -> >90% | G111: =IF(G110>=87,">90%",IF(G110<=87,"<90%")) -> >90% | H111: =IF(H110>=87,">90%",IF(H110<=87,"<90%")) -> >90% | I111: =IF(I110>=87,">90%",IF(I110<=87,"<90%")) -> >90% | ... Q111: =IF(Q110>=87,">90%",IF(Q110<=87,"<90%")) -> >90%
A112: Status | B112: =IF(B110>=87,"OK",IF(B110<=87,"LESS")) -> OK | C112: =IF(C110>=87,"OK",IF(C110<=87,"LESS")) -> OK | D112: =IF(D110>=87,"OK",IF(D110<=87,"LESS")) -> OK | E112: =IF(E110>=87,"OK",IF(E110<=87,"LESS")) -> OK | F112: =IF(F110>=87,"OK",IF(F110<=87,"LESS")) -> OK | G112: =IF(G110>=87,"OK",IF(G110<=87,"LESS")) -> OK | H112: =IF(H110>=87,"OK",IF(H110<=87,"LESS")) -> OK | I112: =IF(I110>=87,"OK",IF(I110<=87,"LESS")) -> OK | ... Q112: =IF(Q110>=87,"OK",IF(Q110<=87,"LESS")) -> OK
A115: Done by | B115: AKASH
A117: Comment

Sheet 06
A1: Station: | B1: IGKV RAIPUR
A2: Date: | B2: =$A$9 -> 06/11/2025 00:15 | C2: Power Off | G2: Pw.Off | J2: Link Fail | L2: Link F | N2: Maintenance | P2: Maint.
A3: Report Type: | B3: Mean | C3: Calibration | G3: Calib. | J3: Data Fail | L3: Data F | N3: Invalid | P3: Invalid
A4: Time Base: | B4: 15 Min | C4: Zero Referrence | G4: Z.Ref | J4: Warm Up | L4: Wm. Up
A7: Date & Time | B7: NO | C7: NO2 | D7: NOX | E7: SO2 | F7: O3 | G7: PM 10 | H7: PM 2.5 | I7: BENZ | J7: WS | K7: WD | L7: TEMP | M7: HUM | N7: SR | O7: RG | P7: CO | Q7: NH3
B8: ug/m3 | C8: ug/m3 | D8: ppb | E8: ug/m3 | F8: ug/m3 | G8: ug/m3 | H8: ug/m3 | I8: ug/m3 | J8: m/sec | K8: deg | L8: degreC | M8: % | N8: w/m2 | O8: mm | P8: mg/m3 | Q8: ug/m3
A9: 06/11/2025 00:15 | B9: 8.98 | C9: 10.82 | D9: 12.85 | E9: 7 | F9: 2 | G9: 73.32 | H9: 29.87 | I9: 7.29 | J9: 0.15 | K9: 181.89 | L9: 17.3 | M9: 25.39 | N9: 2.1 | O9: 0 | P9: 0.67 | Q9: 9.92
A10: 06/11/2025 00:30 | B10: 8.45 | C10: 9.57 | D10: 11.77 | E10: 6.86 | F10: 2 | G10: 74.6 | H10: 30.76 | I10: 7.31 | J10: 0.18 | K10: 172.29 | L10: 16.4 | M10: 23.16 | N10: 2.1 | O10: 0 | P10: 0.66 | Q10: 11.87
A11: 06/11/2025 00:45 | B11: 8.26 | C11: 8.84 | D11: 11.24 | E11: 6.31 | F11: 2 | G11: 76.2 | H11: 31.36 | I11: 7.3 | J11: 0.29 | K11: 168.46 | L11: 16.44 | M11: 23.21 | N11: 2.3 | O11: 0 | P11: 0.66 | Q11: 10.91
A12: 06/11/2025 01:00 | B12: 8.16 | C12: 8.37 | D12: 10.91 | E12: 6.15 | F12: 2 | G12: 76.2 | H12: 31.36 | I12: 7.29 | J12: 0.19 | K12: 171.87 | L12: 16.95 | M12: 24.45 | N12: 2.5 | O12: 0 | P12: 0.67 | Q12: 9.41
A13: 06/11/2025 01:15 | B13: 8.03 | C13: 8 | D13: 10.62 | E13: 6.1 | F13: 2 | G13: 76.2 | H13: 31.36 | I13: 7.29 | J13: 0.07 | K13: 181.32 | L13: 19.03 | M13: 29.5 | N13: 2.4 | O13: 0 | P13: 0.67 | Q13: 9.32
A14: 06/11/2025 01:30 | B14: 7.85 | C14: 7.75 | D14: 10.34 | E14: 6 | F14: 2 | G14: 74.65 | H14: 30.4 | I14: 7.27 | J14: 0.14 | K14: 152.77 | L14: 15.11 | M14: 19.94 | N14: 2.2 | O14: 0 | P14: 0.66 | Q14: 9.32
A15: 06/11/2025 01:45 | B15: 7.82 | C15: 7.51 | D15: 10.2 | E15: 4.74 | F15: 2 | G15: 72.72 | H15: 28.8 | I15: 7.25 | J15: 0.13 | K15: 177.89 | L15: 17.13 | M15: 24.91 | N15: 2.1 | O15: 0 | P15: 0.66 | Q15: 9.32
A16: 06/11/2025 02:00 | B16: 7.98 | C16: 7.32 | D16: 10.23 | E16: 5.97 | F16: 2 | G16: 72.72 | H16: 28.8 | I16: 7.24 | J16: 0.07 | K16: 206.82 | L16: 18.86 | M16: 29.42 | N16: 2.1 | O16: 0 | P16: 0.67 | Q16: 9.32
A17: 06/11/2025 02:15 | B17: 8.2 | C17: 7.1 | D17: 10.28 | E17: 5.12 | F17: 2 | G17: 72.72 | H17: 28.8 | I17: 7.29 | J17: 0.09 | K17: 156.5 | L17: 15.71 | M17: 21.5 | N17: 2.1 | O17: 0 | P17: 0.66 | Q17: 9.32
A18: 06/11/2025 02:30 | B18: 8.38 | C18: 6.96 | D18: 10.36 | E18: 6.03 | F18: 2 | G18: 67.68 | H18: 24.36 | I18: 7.33 | J18: 0.09 | K18: 178.09 | L18: 16.99 | M18: 24.74 | N18: 2.1 | O18: 0 | P18: 0.66 | Q18: 9.32
A19: 06/11/2025 02:45 | B19: 8.55 | C19: 6.92 | D19: 10.47 | E19: 6.1 | F19: 2 | G19: 61.38 | H19: 21.29 | I19: 7.44 | J19: 0.07 | K19: 103.77 | L19: 12.4 | M19: 13.22 | N19: 2.1 | O19: 0 | P19: 0.66 | Q19: 9.32
A20: 06/11/2025 03:00 | B20: 8.95 | C20: 6.8 | D20: 10.73 | E20: 5.85 | F20: 2 | G20: 61.38 | H20: 21.29 | I20: 7.61 | J20: 0.11 | K20: 167 | L20: 16.16 | M20: 22.7 | N20: 2 | O20: 0 | P20: 0.67 | Q20: 9.32
... A104: 06/11/2025 24:00 | B104: 9.27 | C104: 8.38 | D104: 11.81 | E104: 5.97 | F104: 2 | G104: 105.67 | H104: 38.72 | I104: 9.36 | J104: 0.19 | K104: 180.96 | L104: 17.06 | M104: 24.97 | N104: 2.5 | O104: 0 | P104: 0.78 | Q104: 9.32
A106: Min | B106: =MIN(B9:B104) -> 2.91 | C106: =MIN(C9:C104) -> 6.8 | D106: =MIN(D9:D104) -> 6.6 | E106: =MIN(E9:E104) -> 4.04 | F106: =MIN(F9:F104) -> 2 | G106: =MIN(G9:G104) -> 52.18 | H106: =MIN(H9:H104) -> 18.61 | I106: =MIN(I9:I104) -> 6.12 | ... Q106: =MIN(Q9:Q104) -> 9.32
A107: Max | B107: =MAX(B9:B104) -> 17.11 | C107: =MAX(C9:C104) -> 15.01 | D107: =MAX(D9:D104) -> 18.66 | E107: =MAX(E9:E104) -> 11.12 | F107: =MAX(F9:F104) -> 7.47 | G107: =MAX(G9:G104) -> 107.72 | H107: =MAX(H9:H104) -> 38.72 | I107: =MAX(I9:I104) -> 10.26 | ... Q107: =MAX(Q9:Q104) -> 11.87
A108: Avg | B108: =AVERAGE(B9:B104) -> 8.0605208 | C108: =AVERAGE(C9:C104) -> 9.2042708 | D108: =AVERAGE(D9:D104) -> 11.273125 | E108: =AVERAGE(E9:E104) -> 6.7445833 | F108: =AVERAGE(F9:F104) -> 2.4255208 | G108: =AVERAGE(G9:G104) -> 77.881771 | H108: =AVERAGE(H9:H104) -> 27.897917 | I108: =AVERAGE(I9:I104) -> 8.07125 | ... Q108: =AVERAGE(Q9:Q104) -> 9.3719792
A109: Stdev | B109: =STDEV(B9:B104) -> 4.4799613 | C109: =STDEV(C9:C104) -> 1.8202919 | D109: =STDEV(D9:D104) -> 3.5517318 | E109: =STDEV(E9:E104) -> 1.1299082 | F109: =STDEV(F9:F104) -> 0.98382804 | G109: =STDEV(G9:G104) -> 18.313839 | H109: =STDEV(H9:H104) -> 4.2838175 | I109: =STDEV(I9:I104) -> 1.0447757 | ... Q109: =STDEV(Q9:Q104) -> 0.31060084
A110: Num | B110: =COUNT(B9:B104) -> 96 | C110: =COUNT(C9:C104) -> 96 | D110: =COUNT(D9:D104) -> 96 | E110: =COUNT(E9:E104) -> 96 | F110: =COUNT(F9:F104) -> 96 | G110: =COUNT(G9:G104) -> 96 | H110: =COUNT(H9:H104) -> 96 | I110: =COUNT(I9:I104) -> 96 | ... Q110: =COUNT(Q9:Q104) -> 96
A111: DCR | B111: =IF(B110>=87,">90%",IF(B110<=87,"<90%")) -> >90% | C111: =IF(C110>=87,">90%",IF(C110<=87,"<90%")) -> >90% | D111: =IF(D110>=87,">90%",IF(D110<=87,"<90%")) -> >90% | E111: =IF(E110>=87,">90%",IF(E110<=87,"<90%")) -> >90% | F111: =IF(F110>=87,">90%",IF(F110<=87,"<90%")) -> >90% | G111: =IF(G110>=87,">90%",IF(G110<=87,"<90%")) -> >90% | H111: =IF(H110>=87,">90%",IF(H110<=87,"<90%")) -> >90% | I111: =IF(I110>=87,">90%",IF(I110<=87,"<90%")) -> >90% | ... Q111: =IF(Q110>=87,">90%",IF(Q110<=87,"<90%")) -> >90%
A112: Status | B112: =IF(B110>=87,"OK",IF(B110<=87,"LESS")) -> OK | C112: =IF(C110>=87,"OK",IF(C110<=87,"LESS")) -> OK | D112: =IF(D110>=87,"OK",IF(D110<=87,"LESS")) -> OK | E112: =IF(E110>=87,"OK",IF(E110<=87,"LESS")) -> OK | F112: =IF(F110>=87,"OK",IF(F110<=87,"LESS")) -> OK | G112: =IF(G110>=87,"OK",IF(G110<=87,"LESS")) -> OK | H112: =IF(H110>=87,"OK",IF(H110<=87,"LESS")) -> OK | I112: =IF(I110>=87,"OK",IF(I110<=87,"LESS")) -> OK | ... Q112: =IF(Q110>=87,"OK",IF(Q110<=87,"LESS")) -> OK
A115: Done by | B115: AKASH
A117: Comment

Sheet 07
A1: Station: | B1: IGKV RAIPUR
A2: Date: | B2: =$A$9 -> 07/11/2025 00:15 | C2: Power Off | G2: Pw.Off | J2: Link Fail | L2: Link F | N2: Maintenance | P2: Maint.
A3: Report Type: | B3: Mean | C3: Calibration | G3: Calib. | J3: Data Fail | L3: Data F | N3: Invalid | P3: Invalid
A4: Time Base: | B4: 15 Min | C4: Zero Referrence | G4: Z.Ref | J4: Warm Up | L4: Wm. Up
A7: Date & Time | B7: NO | C7: NO2 | D7: NOX | E7: SO2 | F7: O3 | G7: PM 10 | H7: PM 2.5 | I7: BENZ | J7: WS | K7: WD | L7: TEMP | M7: HUM | N7: SR | O7: RG | P7: CO | Q7: NH3
B8: ug/m3 | C8: ug/m3 | D8: ppb | E8: ug/m3 | F8: ug/m3 | G8: ug/m3 | H8: ug/m3 | I8: ug/m3 | J8: m/sec | K8: deg | L8: degreC | M8: % | N8: w/m2 | O8: mm | P8: mg/m3 | Q8: ug/m3
A9: 07/11/2025 00:15 | B9: 9.25 | C9: 8.41 | D9: 11.81 | E9: 5.72 | F9: 2 | G9: 105.67 | H9: 38.72 | I9: 9.41 | J9: 0.14 | K9: 180.19 | L9: 17.16 | M9: 25.25 | N9: 2.3 | O9: 0 | P9: 0.79 | Q9: 9.32
A10: 07/11/2025 00:30 | B10: 9.41 | C10: 8.18 | D10: 11.82 | E10: 5.89 | F10: 2 | G10: 104.32 | H10: 35.51 | I10: 9.44 | J10: 0.11 | K10: 176.87 | L10: 16.63 | M10: 23.92 | N10: 2.1 | O10: 0 | P10: 0.78 | Q10: 9.32
A11: 07/11/2025 00:45 | B11: 9.6 | C11: 7.95 | D11: 11.85 | E11: 5.78 | F11: 2 | G11: 102.63 | H11: 33.33 | I11: 9.48 | J11: 0.08 | K11: 173.6 | L11: 17.35 | M11: 25.74 | N11: 2 | O11: 0 | P11: 0.78 | Q11: 9.32
A12: 07/11/2025 01:00 | B12: 9.89 | C12: 7.87 | D12: 12.05 | E12: 6.18 | F12: 2 | G12: 102.63 | H12: 33.33 | I12: 9.51 | J12: 0.08 | K12: 186.05 | L12: 17.33 | M12: 25.69 | N12: 2.1 | O12: 0 | P12: 0.79 | Q12: 9.32
A13: 07/11/2025 01:15 | B13: 10.93 | C13: 8.07 | D13: 12.98 | E13: 5.89 | F13: 2 | G13: 102.63 | H13: 33.33 | I13: 9.59 | J13: 0.19 | K13: 178.88 | L13: 17.39 | M13: 25.83 | N13: 2 | O13: 0 | P13: 0.81 | Q13: 9.32
A14: 07/11/2025 01:30 | B14: 11.76 | C14: 8.19 | D14: 13.7 | E14: 6.02 | F14: 2 | G14: 103.7 | H14: 37.12 | I14: 9.68 | J14: 0.18 | K14: 173.64 | L14: 16.93 | M14: 24.67 | N14: 2.3 | O14: 0 | P14: 0.81 | Q14: 9.32
A15: 07/11/2025 01:45 | B15: 12.07 | C15: 8.1 | D15: 13.91 | E15: 6.32 | F15: 2 | G15: 105.05 | H15: 43.52 | I15: 9.77 | J15: 0.12 | K15: 180.17 | L15: 16.31 | M15: 23.05 | N15: 2.1 | O15: 0 | P15: 0.81 | Q15: 9.32
A16: 07/11/2025 02:00 | B16: 12.28 | C16: 8.03 | D16: 14.05 | E16: 6.4 | F16: 2 | G16: 105.05 | H16: 43.52 | I16: 9.79 | J16: 0.13 | K16: 172.79 | L16: 17.21 | M16: 25.38 | N16: 2.1 | O16: 0 | P16: 0.81 | Q16: 9.32
A17: 07/11/2025 02:15 | B17: 12.71 | C17: 8.03 | D17: 14.39 | E17: 5.87 | F17: 2 | G17: 105.05 | H17: 43.52 | I17: 9.77 | J17: 0.14 | K17: 161.77 | L17: 15.8 | M17: 21.83 | N17: 2.1 | O17: 0 | P17: 0.82 | Q17: 9.32
A18: 07/11/2025 02:30 | B18: 13.23 | C18: 8.01 | D18: 14.79 | E18: 7.19 | F18: 2 | G18: 102.78 | H18: 42.71 | I18: 9.82 | J18: 0.09 | K18: 125.32 | L18: 12.6 | M18: 13.77 | N18: 1.9 | O18: 0 | P18: 0.81 | Q18: 9.32
A19: 07/11/2025 02:45 | B19: 13.95 | C19: 8.23 | D19: 15.49 | E19: 7.17 | F19: 2 | G19: 99.94 | H19: 42.16 | I19: 9.84 | J19: 0.1 | K19: 118.9 | L19: 11.46 | M19: 10.72 | N19: 2 | O19: 0 | P19: 0.81 | Q19: 9.32
A20: 07/11/2025 03:00 | B20: 14.36 | C20: 8.44 | D20: 15.93 | E20: 7.37 | F20: 2 | G20: 99.94 | H20: 42.16 | I20: 9.79 | J20: 0.09 | K20: 122.53 | L20: 13.32 | M20: 15.4 | N20: 2.2 | O20: 0 | P20: 0.8 | Q20: 9.32
... A104: 07/11/2025 24:00 | B104: 13.83 | C104: 9.78 | D104: 16.21 | E104: 6.12 | F104: 2 | G104: 86.91 | H104: 34.3 | I104: 9.4 | J104: 0.19 | K104: 166.63 | L104: 16.15 | M104: 22.66 | N104: 2.1 | O104: 0 | P104: 0.68 | Q104: 9.32
A106: Min | B106: =MIN(B9:B104) -> 2.13 | C106: =MIN(C9:C104) -> 7.87 | D106: =MIN(D9:D104) -> 7.87 | E106: =MIN(E9:E104) -> 3.83 | F106: =MIN(F9:F104) -> 1.22 | G106: =MIN(G9:G104) -> 51.83 | H106: =MIN(H9:H104) -> 18.54 | I106: =MIN(I9:I104) -> 3.2 | ... Q106: =MIN(Q9:Q104) -> 9.32
A107: Max | B107: =MAX(B9:B104) -> 16.33 | C107: =MAX(C9:C104) -> 27.03 | D107: =MAX(D9:D104) -> 17.99 | E107: =MAX(E9:E104) -> 20.49 | F107: =MAX(F9:F104) -> 67.12 | G107: =MAX(G9:G104) -> 118.93 | H107: =MAX(H9:H104) -> 43.52 | I107: =MAX(I9:I104) -> 10.66 | ... Q107: =MAX(Q9:Q104) -> 15.17
A108: Avg | B108: =AVERAGE(B9:B104) -> 10.011667 | C108: =AVERAGE(C9:C104) -> 11.190833 | D108: =AVERAGE(D9:D104) -> 13.874896 | E108: =AVERAGE(E9:E104) -> 6.9552083 | F108: =AVERAGE(F9:F104) -> 4.77625 | G108: =AVERAGE(G9:G104) -> 89.573958 | H108: =AVERAGE(H9:H104) -> 30.083021 | I108: =AVERAGE(I9:I104) -> 8.145 | ... Q108: =AVERAGE(Q9:Q104) -> 9.4114583
A109: Stdev | B109: =STDEV(B9:B104) -> 4.7338291 | C109: =STDEV(C9:C104) -> 4.3101649 | D109: =STDEV(D9:D104) -> 2.8636072 | E109: =STDEV(E9:E104) -> 2.7006179 | F109: =STDEV(F9:F104) -> 11.218597 | G109: =STDEV(G9:G104) -> 22.951437 | H109: =STDEV(H9:H104) -> 7.3683033 | I109: =STDEV(I9:I104) -> 2.120146 | ... Q109: =STDEV(Q9:Q104) -> 0.64838257
A110: Num | B110: =COUNT(B9:B104) -> 96 | C110: =COUNT(C9:C104) -> 96 | D110: =COUNT(D9:D104) -> 96 | E110: =COUNT(E9:E104) -> 96 | F110: =COUNT(F9:F104) -> 96 | G110: =COUNT(G9:G104) -> 96 | H110: =COUNT(H9:H104) -> 96 | I110: =COUNT(I9:I104) -> 96 | ... Q110: =COUNT(Q9:Q104) -> 96
A111: DCR | B111: =IF(B110>=87,">90%",IF(B110<=87,"<90%")) -> >90% | C111: =IF(C110>=87,">90%",IF(C110<=87,"<90%")) -> >90% | D111: =IF(D110>=87,">90%",IF(D110<=87,"<90%")) -> >90% | E111: =IF(E110>=87,">90%",IF(E110<=87,"<90%")) -> >90% | F111: =IF(F110>=87,">90%",IF(F110<=87,"<90%")) -> >90% | G111: =IF(G110>=87,">90%",IF(G110<=87,"<90%")) -> >90% | H111: =IF(H110>=87,">90%",IF(H110<=87,"<90%")) -> >90% | I111: =IF(I110>=87,">90%",IF(I110<=87,"<90%")) -> >90% | ... Q111: =IF(Q110>=87,">90%",IF(Q110<=87,"<90%")) -> >90%
A112: Status | B112: =IF(B110>=87,"OK",IF(B110<=87,"LESS")) -> OK | C112: =IF(C110>=87,"OK",IF(C110<=87,"LESS")) -> OK | D112: =IF(D110>=87,"OK",IF(D110<=87,"LESS")) -> OK | E112: =IF(E110>=87,"OK",IF(E110<=87,"LESS")) -> OK | F112: =IF(F110>=87,"OK",IF(F110<=87,"LESS")) -> OK | G112: =IF(G110>=87,"OK",IF(G110<=87,"LESS")) -> OK | H112: =IF(H110>=87,"OK",IF(H110<=87,"LESS")) -> OK | I112: =IF(I110>=87,"OK",IF(I110<=87,"LESS")) -> OK | ... Q112: =IF(Q110>=87,"OK",IF(Q110<=87,"LESS")) -> OK
A115: Done by | B115: AKASH
A117: Comment

Sheet 08
A1: Station: | B1: IGKV RAIPUR
A2: Date: | B2: =$A$9 -> 08/11/2025 00:15 | C2: Power Off | G2: Pw.Off | J2: Link Fail | L2: Link F | N2: Maintenance | P2: Maint.
A3: Report Type: | B3: Mean | C3: Calibration | G3: Calib. | J3: Data Fail | L3: Data F | N3: Invalid | P3: Invalid
A4: Time Base: | B4: 15 Min | C4: Zero Referrence | G4: Z.Ref | J4: Warm Up | L4: Wm. Up
A7: Date & Time | B7: NO | C7: NO2 | D7: NOX | E7: SO2 | F7: O3 | G7: PM 10 | H7: PM 2.5 | I7: BENZ | J7: WS | K7: WD | L7: TEMP | M7: HUM | N7: SR | O7: RG | P7: CO | Q7: NH3
B8: ug/m3 | C8: ug/m3 | D8: ppb | E8: ug/m3 | F8: ug/m3 | G8: ug/m3 | H8: ug/m3 | I8: ug/m3 | J8: m/sec | K8: deg | L8: degreC | M8: % | N8: w/m2 | O8: mm | P8: mg/m3 | Q8: ug/m3
A9: 08/11/2025 00:15 | B9: 14.01 | C9: 9.77 | D9: 16.34 | E9: 6.33 | F9: 2 | G9: 86.91 | H9: 34.3 | I9: 9.52 | J9: 0.13 | K9: 167.38 | L9: 16.17 | M9: 22.74 | N9: 2 | O9: 0 | P9: 0.69 | Q9: 9.32
A10: 08/11/2025 00:30 | B10: 14.4 | C10: 9.77 | D10: 16.65 | E10: 6.13 | F10: 2 | G10: 87.97 | H10: 33.03 | I10: 9.6 | J10: 0.15 | K10: 148.64 | L10: 14.33 | M10: 18.12 | N10: 1.9 | O10: 0 | P10: 0.7 | Q10: 9.32
A11: 08/11/2025 00:45 | B11: 14.99 | C11: 9.84 | D11: 17.16 | E11: 6.12 | F11: 2 | G11: 89.29 | H11: 32.17 | I11: 9.71 | J11: 0.12 | K11: 91.72 | L11: 10.69 | M11: 8.87 | N11: 2 | O11: 0 | P11: 0.72 | Q11: 9.32
A12: 08/11/2025 01:00 | B12: 15.73 | C12: 9.87 | D12: 17.77 | E12: 6.41 | F12: 2 | G12: 89.29 | H12: 32.17 | I12: 9.82 | J12: 0.1 | K12: 18.99 | L12: 11.35 | M12: 10.32 | N12: 1.8 | O12: 0 | P12: 0.74 | Q12: 13.89
A13: 08/11/2025 01:15 | B13: 16.38 | C13: 9.98 | D13: 18.35 | E13: 6.16 | F13: 2 | G13: 89.29 | H13: 32.17 | I13: 9.9 | J13: 0.21 | K13: 42.18 | L13: 6.25 | M13: -2.45 | N13: 2.1 | O13: 0 | P13: 0.76 | Q13: 11.71
A14: 08/11/2025 01:30 | B14: 16.6 | C14: 10 | D14: 18.54 | E14: 6.35 | F14: 2 | G14: 99.33 | H14: 34.1 | I14: 9.95 | J14: 0.19 | K14: 40.06 | L14: 7.57 | M14: 0.82 | N14: 2.1 | O14: 0 | P14: 0.77 | Q14: 9.68
A15: 08/11/2025 01:45 | B15: 16.65 | C15: 9.97 | D15: 18.56 | E15: 6.09 | F15: 2 | G15: 111.88 | H15: 37.36 | I15: 10 | J15: 0.33 | K15: 35.51 | L15: 6.56 | M15: -1.84 | N15: 2.1 | O15: 0 | P15: 0.77 | Q15: 9.32
A16: 08/11/2025 02:00 | B16: 16.39 | C16: 9.79 | D16: 18.26 | E16: 6.2 | F16: 2 | G16: 111.88 | H16: 37.36 | I16: 10.01 | J16: 0.58 | K16: 43.58 | L16: 8.23 | M16: 2.47 | N16: 2.1 | O16: 0 | P16: 0.78 | Q16: 9.32
A17: 08/11/2025 02:15 | B17: 15.92 | C17: 9.86 | D17: 17.92 | E17: 4.66 | F17: 2 | G17: 111.88 | H17: 37.36 | I17: 10 | J17: 0.6 | K17: 43.77 | L17: 6.31 | M17: -1.64 | N17: 2.1 | O17: 0 | P17: 0.78 | Q17: 9.45
A18: 08/11/2025 02:30 | B18: 15.35 | C18: 9.91 | D18: 17.49 | E18: 5.68 | F18: 2 | G18: 111.33 | H18: 35.77 | I18: 9.93 | J18: 0.33 | K18: 37.82 | L18: 10 | M18: 6.87 | N18: 2.1 | O18: 0 | P18: 0.77 | Q18: 9.59
A19: 08/11/2025 02:45 | B19: 14.86 | C19: 10.05 | D19: 17.17 | E19: 5.88 | F19: 2 | G19: 110.65 | H19: 34.68 | I19: 9.79 | J19: 0.29 | K19: 41.15 | L19: 6.48 | M19: -1.94 | N19: 2.1 | O19: 0 | P19: 0.76 | Q19: 9.53
A20: 08/11/2025 03:00 | B20: 14.58 | C20: 10.13 | D20: 16.98 | E20: 5.96 | F20: 2 | G20: 110.65 | H20: 34.68 | I20: 9.63 | J20: 0.47 | K20: 35.67 | L20: 8.34 | M20: 2 | N20: 1.9 | O20: 0 | P20: 0.76 | Q20: 9.65
... A104: 08/11/2025 24:00 | B104: 13.2 | C104: 11.87 | D104: 16.78 | E104: 5.36 | F104: 2 | G104: 129.54 | H104: 49.83 | I104: 11.03 | J104: 0.26 | K104: 32.48 | L104: 8.8 | M104: 3.9 | N104: 2.1 | O104: 0 | P104: 0.81 | Q104: 9.32
A106: Min | B106: =MIN(B9:B104) -> 1.65 | C106: =MIN(C9:C104) -> 9.77 | D106: =MIN(D9:D104) -> 8.56 | E106: =MIN(E9:E104) -> 3.5 | F106: =MIN(F9:F104) -> 2 | G106: =MIN(G9:G104) -> 58.35 | H106: =MIN(H9:H104) -> 25.46 | I106: =MIN(I9:I104) -> 3.74 | ... Q106: =MIN(Q9:Q104) -> 9.32
A107: Max | B107: =MAX(B9:B104) -> 16.65 | C107: =MAX(C9:C104) -> 20.76 | D107: =MAX(D9:D104) -> 18.56 | E107: =MAX(E9:E104) -> 13.32 | F107: =MAX(F9:F104) -> 44.07 | G107: =MAX(G9:G104) -> 129.54 | H107: =MAX(H9:H104) -> 49.83 | I107: =MAX(I9:I104) -> 11.03 | ... Q107: =MAX(Q9:Q104) -> 13.89
A108: Avg | B108: =AVERAGE(B9:B104) -> 8.2648958 | C108: =AVERAGE(C9:C104) -> 12.508542 | D108: =AVERAGE(D9:D104) -> 13.162813 | E108: =AVERAGE(E9:E104) -> 6.4672917 | F108: =AVERAGE(F9:F104) -> 5.9203125 | G108: =AVERAGE(G9:G104) -> 82.515938 | H108: =AVERAGE(H9:H104) -> 32.784583 | I108: =AVERAGE(I9:I104) -> 7.5757292 | ... Q108: =AVERAGE(Q9:Q104) -> 9.443125
A109: Stdev | B109: =STDEV(B9:B104) -> 5.1968168 | C109: =STDEV(C9:C104) -> 2.697693 | D109: =STDEV(D9:D104) -> 3.1021156 | E109: =STDEV(E9:E104) -> 1.9569022 | F109: =STDEV(F9:F104) -> 8.499017 | G109: =STDEV(G9:G104) -> 15.714995 | H109: =STDEV(H9:H104) -> 4.3426957 | I109: =STDEV(I9:I104) -> 1.8948805 | ... Q109: =STDEV(Q9:Q104) -> 0.53529788
A110: Num | B110: =COUNT(B9:B104) -> 96 | C110: =COUNT(C9:C104) -> 96 | D110: =COUNT(D9:D104) -> 96 | E110: =COUNT(E9:E104) -> 96 | F110: =COUNT(F9:F104) -> 96 | G110: =COUNT(G9:G104) -> 96 | H110: =COUNT(H9:H104) -> 96 | I110: =COUNT(I9:I104) -> 96 | ... Q110: =COUNT(Q9:Q104) -> 96
A111: DCR | B111: =IF(B110>=87,">90%",IF(B110<=87,"<90%")) -> >90% | C111: =IF(C110>=87,">90%",IF(C110<=87,"<90%")) -> >90% | D111: =IF(D110>=87,">90%",IF(D110<=87,"<90%")) -> >90% | E111: =IF(E110>=87,">90%",IF(E110<=87,"<90%")) -> >90% | F111: =IF(F110>=87,">90%",IF(F110<=87,"<90%")) -> >90% | G111: =IF(G110>=87,">90%",IF(G110<=87,"<90%")) -> >90% | H111: =IF(H110>=87,">90%",IF(H110<=87,"<90%")) -> >90% | I111: =IF(I110>=87,">90%",IF(I110<=87,"<90%")) -> >90% | ... Q111: =IF(Q110>=87,">90%",IF(Q110<=87,"<90%")) -> >90%
A112: Status | B112: =IF(B110>=87,"OK",IF(B110<=87,"LESS")) -> OK | C112: =IF(C110>=87,"OK",IF(C110<=87,"LESS")) -> OK | D112: =IF(D110>=87,"OK",IF(D110<=87,"LESS")) -> OK | E112: =IF(E110>=87,"OK",IF(E110<=87,"LESS")) -> OK | F112: =IF(F110>=87,"OK",IF(F110<=87,"LESS")) -> OK | G112: =IF(G110>=87,"OK",IF(G110<=87,"LESS")) -> OK | H112: =IF(H110>=87,"OK",IF(H110<=87,"LESS")) -> OK | I112: =IF(I110>=87,"OK",IF(I110<=87,"LESS")) -> OK | ... Q112: =IF(Q110>=87,"OK",IF(Q110<=87,"LESS")) -> OK
A115: Done by | B115: AKASH
A117: Comment

Sheet 09
A1: Station: | B1: IGKV RAIPUR
A2: Date: | B2: =$A$9 -> 09/11/2025 00:15 | C2: Power Off | G2: Pw.Off | J2: Link Fail | L2: Link F | N2: Maintenance | P2: Maint.
A3: Report Type: | B3: Mean | C3: Calibration | G3: Calib. | J3: Data Fail | L3: Data F | N3: Invalid | P3: Invalid
A4: Time Base: | B4: 15 Min | C4: Zero Referrence | G4: Z.Ref | J4: Warm Up | L4: Wm. Up
A7: Date & Time | B7: NO | C7: NO2 | D7: NOX | E7: SO2 | F7: O3 | G7: PM 10 | H7: PM 2.5 | I7: BENZ | J7: WS | K7: WD | L7: TEMP | M7: HUM | N7: SR | O7: RG | P7: CO | Q7: NH3
B8: ug/m3 | C8: ug/m3 | D8: ppb | E8: ug/m3 | F8: ug/m3 | G8: ug/m3 | H8: ug/m3 | I8: ug/m3 | J8: m/sec | K8: deg | L8: degreC | M8: % | N8: w/m2 | O8: mm | P8: mg/m3 | Q8: ug/m3
A9: 09/11/2025 00:15 | B9: 13.55 | C9: 11.66 | D9: 16.95 | E9: 5.27 | F9: 2 | G9: 129.54 | H9: 49.83 | I9: 11.12 | J9: 0.16 | K9: 23.36 | L9: 11.85 | M9: 11.47 | N9: 2 | O9: 0 | P9: 0.81 | Q9: 9.32
A10: 09/11/2025 00:30 | B10: 13.7 | C10: 12.05 | D10: 17.29 | E10: 5.33 | F10: 2 | G10: 131.59 | H10: 49.41 | I10: 11.17 | J10: 0.08 | K10: 61.38 | L10: 7.83 | M10: 1.63 | N10: 2.1 | O10: 0 | P10: 0.82 | Q10: 9.32
A11: 09/11/2025 00:45 | B11: 14.14 | C11: 12.22 | D11: 17.73 | E11: 5.47 | F11: 2 | G11: 134.05 | H11: 49.14 | I11: 11.18 | J11: 0.12 | K11: 65.35 | L11: 10.73 | M11: 8.95 | N11: 2 | O11: 0 | P11: 0.82 | Q11: 9.32
A12: 09/11/2025 01:00 | B12: 14.46 | C12: 12.28 | D12: 18.01 | E12: 5.54 | F12: 2 | G12: 134.05 | H12: 49.14 | I12: 11.13 | J12: 0.16 | K12: 45.54 | L12: 10.27 | M12: 7.65 | N12: 2 | O12: 0 | P12: 0.81 | Q12: 9.32
A13: 09/11/2025 01:15 | B13: 14.61 | C13: 12.31 | D13: 18.15 | E13: 5.26 | F13: 2 | G13: 134.05 | H13: 49.14 | I13: 11.06 | J13: 0.15 | K13: 31.69 | L13: 12.04 | M13: 11.96 | N13: 2.1 | O13: 0 | P13: 0.81 | Q13: 9.32
A14: 09/11/2025 01:30 | B14: 14.56 | C14: 12.09 | D14: 17.99 | E14: 5.3 | F14: 2 | G14: 129.29 | H14: 48.76 | I14: 11.05 | J14: 0.26 | K14: 44.93 | L14: 7.83 | M14: 0.82 | N14: 2.1 | O14: 0 | P14: 0.8 | Q14: 9.32
A15: 09/11/2025 01:45 | B15: 14.46 | C15: 12.11 | D15: 17.93 | E15: 5.44 | F15: 2 | G15: 123.33 | H15: 48.11 | I15: 10.95 | J15: 0.17 | K15: 44.5 | L15: 9.15 | M15: 4.86 | N15: 2 | O15: 0 | P15: 0.79 | Q15: 9.32
A16: 09/11/2025 02:00 | B16: 14.31 | C16: 12.18 | D16: 17.84 | E16: 5.27 | F16: 2 | G16: 123.33 | H16: 48.11 | I16: 10.8 | J16: 0.12 | K16: 56.97 | L16: 7.67 | M16: 1.23 | N16: 2.1 | O16: 0 | P16: 0.79 | Q16: 9.32
A17: 09/11/2025 02:15 | B17: 14.17 | C17: 12.21 | D17: 17.74 | E17: 4.91 | F17: 2 | G17: 123.33 | H17: 48.11 | I17: 10.7 | J17: 0.22 | K17: 55 | L17: 8.34 | M17: 2.9 | N17: 2 | O17: 0 | P17: 0.78 | Q17: 9.32
A18: 09/11/2025 02:30 | B18: 14.04 | C18: 12.29 | D18: 17.68 | E18: 6.26 | F18: 2 | G18: 122.28 | H18: 47.96 | I18: 10.62 | J18: 0.19 | K18: 59.2 | L18: 9.27 | M18: 5.26 | N18: 2.1 | O18: 0 | P18: 0.78 | Q18: 9.32
A19: 09/11/2025 02:45 | B19: 14.11 | C19: 12.27 | D19: 17.73 | E19: 6.28 | F19: 2 | G19: 120.96 | H19: 47.87 | I19: 10.53 | J19: 0.18 | K19: 56.81 | L19: 9.59 | M19: 6.04 | N19: 2.1 | O19: 0 | P19: 0.8 | Q19: 9.32
A20: 09/11/2025 03:00 | B20: 14.37 | C20: 12.35 | D20: 17.98 | E20: 6.42 | F20: 2 | G20: 120.96 | H20: 47.87 | I20: 10.5 | J20: 0.28 | K20: 45.84 | L20: 7.48 | M20: 0.65 | N20: 2.1 | O20: 0 | P20: 0.84 | Q20: 9.32
... A104: 09/11/2025 24:00 | B104: 7.11 | C104: 9.75 | D104: 10.8 | E104: 6.4 | F104: 2 | G104: 79.5 | H104: 39.22 | I104: 10.92 | J104: 0.09 | K104: 185.34 | L104: 16.43 | M104: 23.16 | N104: 1.9 | O104: 0 | P104: 0.8 | Q104: 9.32
A106: Min | B106: =MIN(B9:B104) -> 1.63 | C106: =MIN(C9:C104) -> 9.75 | D106: =MIN(D9:D104) -> 6.79 | E106: =MIN(E9:E104) -> 4.65 | F106: =MIN(F9:F104) -> 2 | G106: =MIN(G9:G104) -> 79.5 | H106: =MIN(H9:H104) -> 39.22 | I106: =MIN(I9:I104) -> 8.92 | ... Q106: =MIN(Q9:Q104) -> 9.32
A107: Max | B107: =MAX(B9:B104) -> 17.95 | C107: =MAX(C9:C104) -> 14.11 | D107: =MAX(D9:D104) -> 21.16 | E107: =MAX(E9:E104) -> 10.98 | F107: =MAX(F9:F104) -> 8.35 | G107: =MAX(G9:G104) -> 199.67 | H107: =MAX(H9:H104) -> 81.16 | I107: =MAX(I9:I104) -> 13.56 | ... Q107: =MAX(Q9:Q104) -> 9.32
A108: Avg | B108: =AVERAGE(B9:B104) -> 8.7169792 | C108: =AVERAGE(C9:C104) -> 12.156667 | D108: =AVERAGE(D9:D104) -> 13.341979 | E108: =AVERAGE(E9:E104) -> 6.5542708 | F108: =AVERAGE(F9:F104) -> 2.2247917 | G108: =AVERAGE(G9:G104) -> 121.03833 | H108: =AVERAGE(H9:H104) -> 55.696458 | I108: =AVERAGE(I9:I104) -> 10.991458 | ... Q108: =AVERAGE(Q9:Q104) -> 9.32
A109: Stdev | B109: =STDEV(B9:B104) -> 5.5746007 | C109: =STDEV(C9:C104) -> 1.0148328 | D109: =STDEV(D9:D104) -> 4.6367856 | E109: =STDEV(E9:E104) -> 1.3249657 | F109: =STDEV(F9:F104) -> 0.83798503 | G109: =STDEV(G9:G104) -> 37.921957 | H109: =STDEV(H9:H104) -> 11.908918 | I109: =STDEV(I9:I104) -> 1.227739 | ... Q109: =STDEV(Q9:Q104) -> 1.7856816e-14
A110: Num | B110: =COUNT(B9:B104) -> 96 | C110: =COUNT(C9:C104) -> 96 | D110: =COUNT(D9:D104) -> 96 | E110: =COUNT(E9:E104) -> 96 | F110: =COUNT(F9:F104) -> 96 | G110: =COUNT(G9:G104) -> 96 | H110: =COUNT(H9:H104) -> 96 | I110: =COUNT(I9:I104) -> 96 | ... Q110: =COUNT(Q9:Q104) -> 96
A111: DCR | B111: =IF(B110>=87,">90%",IF(B110<=87,"<90%")) -> >90% | C111: =IF(C110>=87,">90%",IF(C110<=87,"<90%")) -> >90% | D111: =IF(D110>=87,">90%",IF(D110<=87,"<90%")) -> >90% | E111: =IF(E110>=87,">90%",IF(E110<=87,"<90%")) -> >90% | F111: =IF(F110>=87,">90%",IF(F110<=87,"<90%")) -> >90% | G111: =IF(G110>=87,">90%",IF(G110<=87,"<90%")) -> >90% | H111: =IF(H110>=87,">90%",IF(H110<=87,"<90%")) -> >90% | I111: =IF(I110>=87,">90%",IF(I110<=87,"<90%")) -> >90% | ... Q111: =IF(Q110>=87,">90%",IF(Q110<=87,"<90%")) -> >90%
A112: Status | B112: =IF(B110>=87,"OK",IF(B110<=87,"LESS")) -> OK | C112: =IF(C110>=87,"OK",IF(C110<=87,"LESS")) -> OK | D112: =IF(D110>=87,"OK",IF(D110<=87,"LESS")) -> OK | E112: =IF(E110>=87,"OK",IF(E110<=87,"LESS")) -> OK | F112: =IF(F110>=87,"OK",IF(F110<=87,"LESS")) -> OK | G112: =IF(G110>=87,"OK",IF(G110<=87,"LESS")) -> OK | H112: =IF(H110>=87,"OK",IF(H110<=87,"LESS")) -> OK | I112: =IF(I110>=87,"OK",IF(I110<=87,"LESS")) -> OK | ... Q112: =IF(Q110>=87,"OK",IF(Q110<=87,"LESS")) -> OK
A115: Done by | B115: AKASH
A117: Comment

Sheet 10
A1: Station: | B1: IGKV RAIPUR
A2: Date: | B2: =$A$9 -> 10/11/2025 00:15 | C2: Power Off | G2: Pw.Off | J2: Link Fail | L2: Link F | N2: Maintenance | P2: Maint.
A3: Report Type: | B3: Mean | C3: Calibration | G3: Calib. | J3: Data Fail | L3: Data F | N3: Invalid | P3: Invalid
A4: Time Base: | B4: 15 Min | C4: Zero Referrence | G4: Z.Ref | J4: Warm Up | L4: Wm. Up
A7: Date & Time | B7: NO | C7: NO2 | D7: NOX | E7: SO2 | F7: O3 | G7: PM 10 | H7: PM 2.5 | I7: BENZ | J7: WS | K7: WD | L7: TEMP | M7: HUM | N7: SR | O7: RG | P7: CO | Q7: NH3
B8: ug/m3 | C8: ug/m3 | D8: ppb | E8: ug/m3 | F8: ug/m3 | G8: ug/m3 | H8: ug/m3 | I8: ug/m3 | J8: m/sec | K8: deg | L8: degreC | M8: % | N8: w/m2 | O8: mm | P8: mg/m3 | Q8: ug/m3
A9: 10/11/2025 00:15 | B9: 7.13 | C9: 9.33 | D9: 10.6 | E9: 6.52 | F9: 2 | G9: 79.5 | H9: 39.22 | I9: 10.86 | J9: 0.09 | K9: 183.91 | L9: 16.73 | M9: 23.98 | N9: 1.9 | O9: 0 | P9: 0.8 | Q9: 9.32
A10: 10/11/2025 00:30 | B10: 6.96 | C10: 9.52 | D10: 10.56 | E10: 6.12 | F10: 2 | G10: 73.27 | H10: 39.15 | I10: 10.81 | J10: 0.08 | K10: 192.81 | L10: 18.12 | M10: 27.37 | N10: 2 | O10: 0 | P10: 0.8 | Q10: 9.32
A11: 10/11/2025 00:45 | B11: 6.88 | C11: 9.47 | D11: 10.46 | E11: 4.42 | F11: 2 | G11: 65.83 | H11: 39.1 | I11: 10.74 | J11: 0.14 | K11: 191.13 | L11: 17.06 | M11: 24.7 | N11: 2 | O11: 0 | P11: 0.79 | Q11: 9.32
A12: 10/11/2025 01:00 | B12: 6.83 | C12: 9.49 | D12: 10.44 | E12: 6.37 | F12: 2 | G12: 65.83 | H12: 39.1 | I12: 10.72 | J12: 0.06 | K12: 53.55 | L12: 12.5 | M12: 13.22 | N12: 1.7 | O12: 0 | P12: 0.79 | Q12: 9.32
A13: 10/11/2025 01:15 | B13: 7.25 | C13: 9.82 | D13: 10.95 | E13: 6.25 | F13: 2 | G13: 65.83 | H13: 39.1 | I13: 10.69 | J13: 0.11 | K13: 181.82 | L13: 17.02 | M13: 24.87 | N13: 1.7 | O13: 0 | P13: 0.79 | Q13: 9.32
A14: 10/11/2025 01:30 | B14: 7.91 | C14: 10.14 | D14: 11.64 | E14: 6.36 | F14: 2 | G14: 66.96 | H14: 39.05 | I14: 10.66 | J14: 0.16 | K14: 178.15 | L14: 16.73 | M14: 23.9 | N14: 1.8 | O14: 0 | P14: 0.8 | Q14: 9.32
A15: 10/11/2025 01:45 | B15: 8.4 | C15: 10.5 | D15: 12.22 | E15: 6.75 | F15: 2 | G15: 68.37 | H15: 38.95 | I15: 10.71 | J15: 0.16 | K15: 190.02 | L15: 17.91 | M15: 26.76 | N15: 1.9 | O15: 0 | P15: 0.8 | Q15: 9.32
A16: 10/11/2025 02:00 | B16: 8.68 | C16: 10.75 | D16: 12.57 | E16: 6.25 | F16: 2 | G16: 68.37 | H16: 38.95 | I16: 10.79 | J16: 0.12 | K16: 209.87 | L16: 19.84 | M16: 31.63 | N16: 2 | O16: 0 | P16: 0.8 | Q16: 9.32
A17: 10/11/2025 02:15 | B17: 8.74 | C17: 10.7 | D17: 12.6 | E17: 5.46 | F17: 2 | G17: 68.37 | H17: 38.95 | I17: 10.83 | J17: 0.06 | K17: 203.71 | L17: 19.34 | M17: 30.39 | N17: 1.9 | O17: 0 | P17: 0.81 | Q17: 9.32
A18: 10/11/2025 02:30 | B18: 8.78 | C18: 10.58 | D18: 12.57 | E18: 6.44 | F18: 2 | G18: 67.67 | H18: 37.99 | I18: 10.86 | J18: 0.11 | K18: 136.11 | L18: 13.73 | M18: 16.43 | N18: 1.8 | O18: 0 | P18: 0.81 | Q18: 9.32
A19: 10/11/2025 02:45 | B19: 9.19 | C19: 10.64 | D19: 12.93 | E19: 6.5 | F19: 2 | G19: 66.79 | H19: 37.34 | I19: 10.96 | J19: 0.1 | K19: 184.77 | L19: 16.85 | M19: 24.21 | N19: 1.7 | O19: 0 | P19: 0.81 | Q19: 9.32
A20: 10/11/2025 03:00 | B20: 10.36 | C20: 10.82 | D20: 13.96 | E20: 6.85 | F20: 2 | G20: 66.79 | H20: 37.34 | I20: 11.07 | J20: 0.09 | K20: 165.23 | L20: 16.65 | M20: 23.72 | N20: 1.9 | O20: 0 | P20: 0.83 | Q20: 9.32
... A104: 10/11/2025 24:00 | B104: 10.4 | C104: 12.29 | D104: 14.76 | E104: 6.56 | F104: 2 | G104: 86.4 | H104: 41.39 | I104: 10.71 | J104: 0.06 | K104: 177.3 | L104: 16.13 | M104: 22.55 | N104: 1.9 | O104: 0 | P104: 0.79 | Q104: 9.32
A106: Min | B106: =MIN(B9:B104) -> 1.81 | C106: =MIN(C9:C104) -> 9.33 | D106: =MIN(D9:D104) -> 7.88 | E106: =MIN(E9:E104) -> 3.77 | F106: =MIN(F9:F104) -> 2 | G106: =MIN(G9:G104) -> 54.52 | H106: =MIN(H9:H104) -> 37.34 | I106: =MIN(I9:I104) -> 6.07 | ... Q106: =MIN(Q9:Q104) -> 9.32
A107: Max | B107: =MAX(B9:B104) -> 23.34 | C107: =MAX(C9:C104) -> 29.18 | D107: =MAX(D9:D104) -> 26.08 | E107: =MAX(E9:E104) -> 25.29 | F107: =MAX(F9:F104) -> 32.98 | G107: =MAX(G9:G104) -> 140.47 | H107: =MAX(H9:H104) -> 67.44 | I107: =MAX(I9:I104) -> 14.99 | ... Q107: =MAX(Q9:Q104) -> 9.32
A108: Avg | B108: =AVERAGE(B9:B104) -> 9.6123958 | C108: =AVERAGE(C9:C104) -> 14.852083 | D108: =AVERAGE(D9:D104) -> 15.467813 | E108: =AVERAGE(E9:E104) -> 7.243125 | F108: =AVERAGE(F9:F104) -> 3.6552083 | G108: =AVERAGE(G9:G104) -> 85.358958 | H108: =AVERAGE(H9:H104) -> 46.513333 | I108: =AVERAGE(I9:I104) -> 10.826875 | ... Q108: =AVERAGE(Q9:Q104) -> 9.32
