Workbook

Sheet 01
A1: Station: | B1: Bhatagaon, RAIPUR
A2: Date: | B2: =$A$9 -> 01-11-2022 00:15 | D2: Power Off | G2: Pw.Off | L2: Link Fail | N2: Link F | P2: Maintenance | R2: Maint.
A3: Report Type: | B3: Mean | D3: Calibration | G3: Calib. | L3: Data Fail | N3: Data F | P3: Invalid | R3: Invalid
A4: Time Base: | B4: 15 Min | D4: Zero Referrence | G4: Z.Ref | L4: Warm Up | N4: Wm. Up
A7: Date & Time | B7: NO_BHATAGAON | C7: NO2__BHATAGAON | D7: NOX_BHATAGAON | E7: SO2__BHATAGAON | F7: O3__BHATAGAON | G7: PM10__BHATAGAON | H7: PM2_5__BHATAGAON | I7: BENZ__BHATAGAON | J7: WS__BHATAGAON | K7: WD__BHATAGAON | L7: TEMP__BHATAGAON | M7: HUM__BHATAGAON | N7: SR__BHATAGAON | O7: RG__BHATAGAON | P7: CO__BHATAGAON | Q7: NH3__BHATAGAON
B8: ug/m3 | C8: ug/m3 | D8: ug/m3 | E8: ug/m3 | F8: ug/m3 | G8: ug/m3 | H8: ug/m3 | I8: ug/m3 | J8: m/sec | K8: deg | L8: degreC | M8: % | N8: w/m2 | O8: mm | P8: mg/m3 | Q8: ug/m3
A9: 01-11-2022 00:15 | B9: 0.65 | C9: 72.75 | D9: 40.67 | E9: 47.47 | F9: 64.41 | G9: 186.07 | H9: 64.44 | I9: 0.24 | J9: 0.4 | K9: 56.52 | L9: Maint. | M9: Maint. | N9: 4.4 | O9: 0 | P9: 0.79 | Q9: 59.91
A10: 01-11-2022 00:30 | B10: 0.85 | C10: 67.7 | D10: 38.04 | E10: 44.64 | F10: 53.45 | G10: 184.79 | H10: 67.77 | I10: 0.21 | J10: 0.18 | K10: 41.71 | L10: Maint. | M10: Maint. | N10: 4.9 | O10: 0 | P10: 0.8 | Q10: 49.91
A11: 01-11-2022 00:45 | B11: 6.67 | C11: 97 | D11: 58.88 | E11: 41.34 | F11: 50.53 | G11: 184.79 | H11: 68.91 | I11: 0.21 | J11: 0.24 | K11: 70.67 | L11: Maint. | M11: Maint. | N11: 4.5 | O11: 0 | P11: 0.9 | Q11: 51.26
A12: 01-11-2022 01:00 | B12: 0.38 | C12: 63.22 | D12: 35.19 | E12: 52.14 | F12: 65.66 | G12: 184.79 | H12: 68.91 | I12: 0.21 | J12: 0.26 | K12: 69.97 | L12: Maint. | M12: Maint. | N12: 4.5 | O12: 0 | P12: 0.68 | Q12: 53.25
A13: 01-11-2022 01:15 | B13: 0.16 | C13: 49.03 | D13: 27.19 | E13: 61.76 | F13: 73.04 | G13: 184.79 | H13: 68.91 | I13: 0.21 | J13: 0.28 | K13: 72.72 | L13: Maint. | M13: Maint. | N13: 4.5 | O13: 0 | P13: 0.57 | Q13: 49.06
A14: 01-11-2022 01:30 | B14: 0.65 | C14: 56.95 | D14: 31.95 | E14: 62.44 | F14: 66.96 | G14: 161.08 | H14: 71.91 | I14: 0.17 | J14: 0.23 | K14: 44.9 | L14: Maint. | M14: Maint. | N14: 4.6 | O14: 0 | P14: 0.59 | Q14: 45.26
A15: 01-11-2022 01:45 | B15: 1.08 | C15: 63.47 | D15: 35.89 | E15: 52.36 | F15: 54.94 | G15: 161.08 | H15: 72.93 | I15: 0.14 | J15: 0.25 | K15: 16.47 | L15: Maint. | M15: Maint. | N15: 4.8 | O15: 0 | P15: 0.58 | Q15: 47.6
A16: 01-11-2022 02:00 | B16: 0.3 | C16: 47.06 | D16: 26.21 | E16: 44.16 | F16: 63.76 | G16: 161.08 | H16: 72.93 | I16: 0.13 | J16: 0.41 | K16: 35.69 | L16: Maint. | M16: Maint. | N16: 4.3 | O16: 0 | P16: 0.56 | Q16: 49
A17: 01-11-2022 02:15 | B17: 0.85 | C17: 55.34 | D17: 31.22 | E17: 42.43 | F17: 56.26 | G17: 161.08 | H17: 72.93 | I17: 0.13 | J17: 0.6 | K17: 32.62 | L17: Maint. | M17: Maint. | N17: 4.3 | O17: 0 | P17: 0.63 | Q17: 48.01
A18: 01-11-2022 02:30 | B18: 0.94 | C18: 63.81 | D18: 35.97 | E18: 49.76 | F18: 41.67 | G18: 149.18 | H18: 70.59 | I18: 0.13 | J18: 0.67 | K18: 34.73 | L18: Maint. | M18: Maint. | N18: 4.6 | O18: 0 | P18: 0.79 | Q18: 49.21
A19: 01-11-2022 02:45 | B19: 0.61 | C19: 68.06 | D19: 38.05 | E19: 73.85 | F19: 33.16 | G19: 149.18 | H19: 69.78 | I19: 0.12 | J19: 0.25 | K19: 33.64 | L19: Maint. | M19: Maint. | N19: 4.8 | O19: 0 | P19: 0.87 | Q19: 51.57
A20: 01-11-2022 03:00 | B20: 0.91 | C20: 103.01 | D20: 57.58 | E20: 136.99 | F20: 18.57 | G20: 149.18 | H20: 69.78 | I20: 0.12 | J20: 0.46 | K20: 22.13 | L20: Maint. | M20: Maint. | N20: 4.5 | O20: 0 | P20: 1.37 | Q20: 59.81
... A104: 01-11-2022 24:00 | B104: 52.69 | C104: 192.62 | D104: 148.55 | E104: 15.55 | F104: 2.88 | G104: 364.59 | H104: 102.49 | I104: 0.95 | J104: 0.05 | K104: 308.59 | L104: Maint. | M104: Maint. | N104: 4.6 | O104: 0 | P104: 2.37 | Q104: 182.38
A106: Min | B106: =MIN(B9:B104) -> 0.16 | C106: =MIN(C9:C104) -> 38.79 | D106: =MIN(D9:D104) -> 22.61 | E106: =MIN(E9:E104) -> 15.55 | F106: =MIN(F9:F104) -> 2.88 | G106: =MIN(G9:G104) -> 108.87 | H106: =MIN(H9:H104) -> 52.41 | I106: =MIN(I9:I104) -> 0.07 | ... Q106: =MIN(Q9:Q104) -> 27.15
A107: Max | B107: =MAX(B9:B104) -> 177.14 | C107: =MAX(C9:C104) -> 396.01 | D107: =MAX(D9:D104) -> 360.6 | E107: =MAX(E9:E104) -> 144.94 | F107: =MAX(F9:F104) -> 128.46 | G107: =MAX(G9:G104) -> 364.59 | H107: =MAX(H9:H104) -> 103.21 | I107: =MAX(I9:I104) -> 1.85 | ... Q107: =MAX(Q9:Q104) -> 272.25
A108: Avg | B108: =AVERAGE(B9:B104) -> 26.571875 | C108: =AVERAGE(C9:C104) -> 135.09115 | D108: =AVERAGE(D9:D104) -> 95.860625 | E108: =AVERAGE(E9:E104) -> 57.691354 | F108: =AVERAGE(F9:F104) -> 50.876875 | G108: =AVERAGE(G9:G104) -> 183.16917 | H108: =AVERAGE(H9:H104) -> 73.481979 | I108: =AVERAGE(I9:I104) -> 0.4059375 | ... Q108: =AVERAGE(Q9:Q104) -> 91.972812
A109: Stdev | B109: =STDEV(B9:B104) -> 39.526765 | C109: =STDEV(C9:C104) -> 93.734299 | D109: =STDEV(D9:D104) -> 80.951806 | E109: =STDEV(E9:E104) -> 27.262204 | F109: =STDEV(F9:F104) -> 39.336387 | G109: =STDEV(G9:G104) -> 66.664922 | H109: =STDEV(H9:H104) -> 15.290665 | I109: =STDEV(I9:I104) -> 0.49139239 | ... Q109: =STDEV(Q9:Q104) -> 62.439094
A110: Num | B110: =COUNT(B9:B104) -> 96 | C110: =COUNT(C9:C104) -> 96 | D110: =COUNT(D9:D104) -> 96 | E110: =COUNT(E9:E104) -> 96 | F110: =COUNT(F9:F104) -> 96 | G110: =COUNT(G9:G104) -> 96 | H110: =COUNT(H9:H104) -> 96 | I110: =COUNT(I9:I104) -> 96 | ... K110: =COUNT(K9:K104) -> 96 | L110: =COUNT(L9:L104)+96 -> 96 | M110: =COUNT(M9:M104)+96 -> 96 | N110: =COUNT(N9:N104) -> 96 | O110: =COUNT(O9:O104) -> 96 | P110: =COUNT(P9:P104) -> 96 | Q110: =COUNT(Q9:Q104) -> 96
A111: DCR | B111: =IF(B110>=87,">90%",IF(B110<=87,"<90%")) -> >90% | C111: =IF(C110>=87,">90%",IF(C110<=87,"<90%")) -> >90% | D111: =IF(D110>=87,">90%",IF(D110<=87,"<90%")) -> >90% | E111: =IF(E110>=87,">90%",IF(E110<=87,"<90%")) -> >90% | F111: =IF(F110>=87,">90%",IF(F110<=87,"<90%")) -> >90% | G111: =IF(G110>=87,">90%",IF(G110<=87,"<90%")) -> >90% | H111: =IF(H110>=87,">90%",IF(H110<=87,"<90%")) -> >90% | I111: =IF(I110>=87,">90%",IF(I110<=87,"<90%")) -> >90% | ... Q111: =IF(Q110>=87,">90%",IF(Q110<=87,"<90%")) -> >90%
A112: Status | B112: =IF(B110>=87,"OK",IF(B110<=87,"LESS")) -> OK | C112: =IF(C110>=87,"OK",IF(C110<=87,"LESS")) -> OK | D112: =IF(D110>=87,"OK",IF(D110<=87,"LESS")) -> OK | E112: =IF(E110>=87,"OK",IF(E110<=87,"LESS")) -> OK | F112: =IF(F110>=87,"OK",IF(F110<=87,"LESS")) -> OK | G112: =IF(G110>=87,"OK",IF(G110<=87,"LESS")) -> OK | H112: =IF(H110>=87,"OK",IF(H110<=87,"LESS")) -> OK | I112: =IF(I110>=87,"OK",IF(I110<=87,"LESS")) -> OK | ... Q112: =IF(Q110>=87,"OK",IF(Q110<=87,"LESS")) -> OK
A115: Done by | B115: RK
A117: Comment | B117: T&H SENSOR CONNECTOR ISSUE

Sheet 02
A1: Station: | B1: Bhatagaon, RAIPUR
A2: Date: | B2: =$A$9 -> 02-11-2022 00:15 | D2: Power Off | G2: Pw.Off | L2: Link Fail | N2: Link F | P2: Maintenance | R2: Maint.
A3: Report Type: | B3: Mean | D3: Calibration | G3: Calib. | L3: Data Fail | N3: Data F | P3: Invalid | R3: Invalid
A4: Time Base: | B4: 15 Min | D4: Zero Referrence | G4: Z.Ref | L4: Warm Up | N4: Wm. Up
A7: Date & Time | B7: NO_BHATAGAON | C7: NO2__BHATAGAON | D7: NOX_BHATAGAON | E7: SO2__BHATAGAON | F7: O3__BHATAGAON | G7: PM10__BHATAGAON | H7: PM2_5__BHATAGAON | I7: BENZ__BHATAGAON | J7: WS__BHATAGAON | K7: WD__BHATAGAON | L7: TEMP__BHATAGAON | M7: HUM__BHATAGAON | N7: SR__BHATAGAON | O7: RG__BHATAGAON | P7: CO__BHATAGAON | Q7: NH3__BHATAGAON
B8: ug/m3 | C8: ug/m3 | D8: ug/m3 | E8: ug/m3 | F8: ug/m3 | G8: ug/m3 | H8: ug/m3 | I8: ug/m3 | J8: m/sec | K8: deg | L8: degreC | M8: % | N8: w/m2 | O8: mm | P8: mg/m3 | Q8: ug/m3
A9: 02-11-2022 00:15 | B9: 52.92 | C9: 188.81 | D9: 146.63 | E9: 17.59 | F9: 2.66 | G9: 364.59 | H9: 102.49 | I9: 0.94 | J9: 0.2 | K9: 356.69 | L9: Maint. | M9: Maint. | N9: 4.5 | O9: 0 | P9: 2.6 | Q9: 168.48
A10: 02-11-2022 00:30 | B10: 18.49 | C10: 157.74 | D10: 101.88 | E10: 21.4 | F10: 6.35 | G10: 319.6 | H10: 100.2 | I10: 0.92 | J10: 0.28 | K10: 350.8 | L10: Maint. | M10: Maint. | N10: 4.2 | O10: 0 | P10: 2.34 | Q10: 151.02
A11: 02-11-2022 00:45 | B11: 8.47 | C11: 155.04 | D11: 92.36 | E11: 30.55 | F11: 8.98 | G11: 319.6 | H11: 99.41 | I11: 0.93 | J11: 0.69 | K11: 349.85 | L11: Maint. | M11: Maint. | N11: 3.9 | O11: 0 | P11: 2.24 | Q11: 110.95
A12: 02-11-2022 01:00 | B12: 7.22 | C12: 137.55 | D12: 81.7 | E12: 50.66 | F12: 16.41 | G12: 319.6 | H12: 99.41 | I12: 0.91 | J12: 0.86 | K12: 344.67 | L12: Maint. | M12: Maint. | N12: 4.5 | O12: 0 | P12: 1.71 | Q12: 100.93
A13: 02-11-2022 01:15 | B13: 1.55 | C13: 89.12 | D13: 50.43 | E13: 45.36 | F13: 33.74 | G13: 319.6 | H13: 99.41 | I13: 0.78 | J13: 0.69 | K13: 348.35 | L13: Maint. | M13: Maint. | N13: 4.9 | O13: 0 | P13: 0.93 | Q13: 87.28
A14: 02-11-2022 01:30 | B14: 0.7 | C14: 73.34 | D14: 41.03 | E14: 51.59 | F14: 38.41 | G14: 270.31 | H14: 107.37 | I14: 0.48 | J14: 0.11 | K14: 310.72 | L14: Maint. | M14: Maint. | N14: 5.2 | O14: 0 | P14: 0.77 | Q14: 72.35
A15: 02-11-2022 01:45 | B15: 0.6 | C15: 71.75 | D15: 40.08 | E15: 64.66 | F15: 36.5 | G15: 270.31 | H15: 110.1 | I15: 0.24 | J15: 0.15 | K15: 30.66 | L15: Maint. | M15: Maint. | N15: 5 | O15: 0 | P15: 0.8 | Q15: 64.06
A16: 02-11-2022 02:00 | B16: 2.23 | C16: 80.41 | D16: 46.17 | E16: 66.81 | F16: 33.37 | G16: 270.31 | H16: 110.1 | I16: 0.16 | J16: 0.13 | K16: 53.69 | L16: Maint. | M16: Maint. | N16: 4.8 | O16: 0 | P16: 0.82 | Q16: 61.23
A17: 02-11-2022 02:15 | B17: 1.43 | C17: 84.29 | D17: 47.66 | E17: 65.56 | F17: 30.88 | G17: 270.31 | H17: 110.1 | I17: 0.13 | J17: 0.35 | K17: 32.53 | L17: Maint. | M17: Maint. | N17: 4.6 | O17: 0 | P17: 1.19 | Q17: 64.04
A18: 02-11-2022 02:30 | B18: 0.49 | C18: 72.54 | D18: 40.42 | E18: 55.6 | F18: 48.2 | G18: 251.68 | H18: 111.36 | I18: 0.13 | J18: 1.15 | K18: 22.25 | L18: Maint. | M18: Maint. | N18: 4.1 | O18: 0 | P18: 1.02 | Q18: 66.51
A19: 02-11-2022 02:45 | B19: 0.43 | C19: 53.75 | D19: 30.01 | E19: 54.21 | F19: 56.45 | G19: 251.68 | H19: 111.8 | I19: 0.14 | J19: 0.69 | K19: 16.84 | L19: Maint. | M19: Maint. | N19: 4.7 | O19: 0 | P19: 0.6 | Q19: 62.26
A20: 02-11-2022 03:00 | B20: 0.65 | C20: 74.02 | D20: 41.37 | E20: 98.27 | F20: 42.23 | G20: 251.68 | H20: 111.8 | I20: 0.12 | J20: 0.17 | K20: 318.76 | L20: Maint. | M20: Maint. | N20: 4.9 | O20: 0 | P20: 0.68 | Q20: 59.86
... A43: 02-11-2022 08:45 | B43: 50.74 | C43: 168.1 | D43: 133.46 | E43: 51.19 | F43: 3.71 | G43: 241.61 | H43: 94.82 | I43: 0.29 | J43: 0.73 | K43: 45.62 | L43: Maint. | M43: Maint. | N43: 184.1 | O43: 0 | P43: 1.96 | Q43: 234.04
A44: 02-11-2022 09:00 | B44: 49.89 | C44: 163.79 | D44: 130.4 | E44: 52.72 | F44: 3.95 | G44: 241.61 | H44: 94.82 | I44: Link F | J44: 0.68 | K44: 34.37 | L44: Maint. | M44: Maint. | N44: 233.9 | O44: 0 | P44: 1.88 | Q44: 243.96
A45: 02-11-2022 09:15 | B45: 49.07 | C45: 161.36 | D45: 128.4 | E45: 53.98 | F45: 4.03 | G45: 241.61 | H45: 94.82 | I45: Link F | J45: 0.51 | K45: 46.04 | L45: Maint. | M45: Maint. | N45: 356.3 | O45: 0 | P45: 1.81 | Q45: 244.13
A46: 02-11-2022 09:30 | B46: 47.8 | C46: 158.8 | D46: 125.97 | E46: 53.35 | F46: 4.01 | G46: 200.27 | H46: 86.28 | I46: Link F | J46: 1.34 | K46: 121.64 | L46: Maint. | M46: Maint. | N46: 448.4 | O46: 0 | P46: 1.75 | Q46: 253
A47: 02-11-2022 09:45 | B47: 43.48 | C47: 152.47 | D47: 119.01 | E47: 51.45 | F47: 4.36 | G47: 200.27 | H47: 83.34 | I47: Link F | J47: 1.47 | K47: 124.99 | L47: Maint. | M47: Maint. | N47: 457.1 | O47: 0 | P47: 1.65 | Q47: 253.85
A48: 02-11-2022 10:00 | B48: 39.25 | C48: 147.46 | D48: 112.86 | E48: 50.35 | F48: 4.46 | G48: 200.27 | H48: 83.34 | I48: Link F | J48: 1.28 | K48: 110.03 | L48: Maint. | M48: Maint. | N48: 600 | O48: 0 | P48: 1.55 | Q48: 262.99
A49: 02-11-2022 10:15 | B49: Pw.Off | C49: Pw.Off | D49: Pw.Off | E49: Pw.Off | F49: Pw.Off | G49: Pw.Off | H49: Pw.Off | I49: Pw.Off | J49: Pw.Off | K49: Pw.Off | L49: Pw.Off | M49: Pw.Off | N49: Pw.Off | O49: Pw.Off | P49: Pw.Off | Q49: Pw.Off
A50: 02-11-2022 10:30 | B50: Pw.Off | C50: Pw.Off | D50: Pw.Off | E50: Pw.Off | F50: Pw.Off | G50: Pw.Off | H50: Pw.Off | I50: Pw.Off | J50: Pw.Off | K50: Pw.Off | L50: Pw.Off | M50: Pw.Off | N50: Pw.Off | O50: Pw.Off | P50: Pw.Off | Q50: Pw.Off
A51: 02-11-2022 10:45 | B51: Pw.Off | C51: Pw.Off | D51: Pw.Off | E51: Pw.Off | F51: Pw.Off | G51: Pw.Off | H51: Pw.Off | I51: Pw.Off | J51: Pw.Off | K51: Pw.Off | L51: Pw.Off | M51: Pw.Off | N51: Pw.Off | O51: Pw.Off | P51: Pw.Off | Q51: Pw.Off
A52: 02-11-2022 11:00 | B52: Pw.Off | C52: Pw.Off | D52: Pw.Off | E52: Pw.Off | F52: Pw.Off | G52: Pw.Off | H52: Pw.Off | I52: Pw.Off | J52: Pw.Off | K52: Pw.Off | L52: Pw.Off | M52: Pw.Off | N52: Pw.Off | O52: Pw.Off | P52: Pw.Off | Q52: Pw.Off
A53: 02-11-2022 11:15 | B53: Pw.Off | C53: Pw.Off | D53: Pw.Off | E53: Pw.Off | F53: Pw.Off | G53: Pw.Off | H53: Pw.Off | I53: Pw.Off | J53: Pw.Off | K53: Pw.Off | L53: Pw.Off | M53: Pw.Off | N53: Pw.Off | O53: Pw.Off | P53: Pw.Off | Q53: Pw.Off
A54: 02-11-2022 11:30 | B54: Pw.Off | C54: Pw.Off | D54: Pw.Off | E54: Pw.Off | F54: Pw.Off | G54: Pw.Off | H54: Pw.Off | I54: Pw.Off | J54: Pw.Off | K54: Pw.Off | L54: Pw.Off | M54: Pw.Off | N54: Pw.Off | O54: Pw.Off | P54: Pw.Off | Q54: Pw.Off
A55: 02-11-2022 11:45 | B55: Pw.Off | C55: Pw.Off | D55: Pw.Off | E55: Pw.Off | F55: Pw.Off | G55: Pw.Off | H55: Pw.Off | I55: Pw.Off | J55: Pw.Off | K55: Pw.Off | L55: Pw.Off | M55: Pw.Off | N55: Pw.Off | O55: Pw.Off | P55: Pw.Off | Q55: Pw.Off
A56: 02-11-2022 12:00 | B56: Pw.Off | C56: Pw.Off | D56: Pw.Off | E56: Pw.Off | F56: Pw.Off | G56: Pw.Off | H56: Pw.Off | I56: Pw.Off | J56: Pw.Off | K56: Pw.Off | L56: Pw.Off | M56: Pw.Off | N56: Pw.Off | O56: Pw.Off | P56: Pw.Off | Q56: Pw.Off
A57: 02-11-2022 12:15 | B57: Pw.Off | C57: Pw.Off | D57: Pw.Off | E57: Pw.Off | F57: Pw.Off | G57: Pw.Off | H57: Pw.Off | I57: Pw.Off | J57: Pw.Off | K57: Pw.Off | L57: Pw.Off | M57: Pw.Off | N57: Pw.Off | O57: Pw.Off | P57: Pw.Off | Q57: Pw.Off
A58: 02-11-2022 12:30 | B58: Pw.Off | C58: Pw.Off | D58: Pw.Off | E58: Pw.Off | F58: Pw.Off | G58: Pw.Off | H58: Pw.Off | I58: Pw.Off | J58: Pw.Off | K58: Pw.Off | L58: Pw.Off | M58: Pw.Off | N58: Pw.Off | O58: Pw.Off | P58: Pw.Off | Q58: Pw.Off
A59: 02-11-2022 12:45 | B59: Pw.Off | C59: Pw.Off | D59: Pw.Off | E59: Pw.Off | F59: Pw.Off | G59: Pw.Off | H59: Pw.Off | I59: Pw.Off | J59: Pw.Off | K59: Pw.Off | L59: Pw.Off | M59: Pw.Off | N59: Pw.Off | O59: Pw.Off | P59: Pw.Off | Q59: Pw.Off
A60: 02-11-2022 13:00 | B60: Pw.Off | C60: Pw.Off | D60: Pw.Off | E60: Pw.Off | F60: Pw.Off | G60: Pw.Off | H60: Pw.Off | I60: Pw.Off | J60: Pw.Off | K60: Pw.Off | L60: Pw.Off | M60: Pw.Off | N60: Pw.Off | O60: Pw.Off | P60: Pw.Off | Q60: Pw.Off
... A104: 02-11-2022 24:00 | B104: Pw.Off | C104: Pw.Off | D104: Pw.Off | E104: Pw.Off | F104: Pw.Off | G104: Pw.Off | H104: Pw.Off | I104: Pw.Off | J104: Pw.Off | K104: Pw.Off | L104: Pw.Off | M104: Pw.Off | N104: Pw.Off | O104: Pw.Off | P104: Pw.Off | Q104: Pw.Off
A106: Min | B106: =MIN(B9:B104) -> 0.43 | C106: =MIN(C9:C104) -> 53.75 | D106: =MIN(D9:D104) -> 30.01 | E106: =MIN(E9:E104) -> 17.59 | F106: =MIN(F9:F104) -> 2.66 | G106: =MIN(G9:G104) -> 180.8 | H106: =MIN(H9:H104) -> 83.34 | I106: =MIN(I9:I104) -> 0.1 | ... Q106: =MIN(Q9:Q104) -> 53.25
A107: Max | B107: =MAX(B9:B104) -> 55.3 | C107: =MAX(C9:C104) -> 188.81 | D107: =MAX(D9:D104) -> 146.63 | E107: =MAX(E9:E104) -> 163.85 | F107: =MAX(F9:F104) -> 56.45 | G107: =MAX(G9:G104) -> 364.59 | H107: =MAX(H9:H104) -> 111.8 | I107: =MAX(I9:I104) -> 0.94 | ... Q107: =MAX(Q9:Q104) -> 262.99
A108: Avg | B108: =AVERAGE(B9:B104) -> 21.4125 | C108: =AVERAGE(C9:C104) -> 124.0875 | D108: =AVERAGE(D9:D104) -> 85.65225 | E108: =AVERAGE(E9:E104) -> 85.1745 | F108: =AVERAGE(F9:F104) -> 20.0595 | G108: =AVERAGE(G9:G104) -> 247.157 | H108: =AVERAGE(H9:H104) -> 101.4325 | I108: =AVERAGE(I9:I104) -> 0.26314286 | ... Q108: =AVERAGE(Q9:Q104) -> 119.862
...

Sheet 03
A1: Station: | B1: Bhatagaon, RAIPUR
A2: Date: | B2: =$A$9 -> 03-11-2022 00:15 | D2: Power Off | G2: Pw.Off | L2: Link Fail | N2: Link F | P2: Maintenance | R2: Maint.
A3: Report Type: | B3: Mean | D3: Calibration | G3: Calib. | L3: Data Fail | N3: Data F | P3: Invalid | R3: Invalid
A4: Time Base: | B4: 15 Min | D4: Zero Referrence | G4: Z.Ref | L4: Warm Up | N4: Wm. Up
A7: Date & Time | B7: NO_BHATAGAON | C7: NO2__BHATAGAON | D7: NOX_BHATAGAON | E7: SO2__BHATAGAON | F7: O3__BHATAGAON | G7: PM10__BHATAGAON | H7: PM2_5__BHATAGAON | I7: BENZ__BHATAGAON | J7: WS__BHATAGAON | K7: WD__BHATAGAON | L7: TEMP__BHATAGAON | M7: HUM__BHATAGAON | N7: SR__BHATAGAON | O7: RG__BHATAGAON | P7: CO__BHATAGAON | Q7: NH3__BHATAGAON
B8: ug/m3 | C8: ug/m3 | D8: ug/m3 | E8: ug/m3 | F8: ug/m3 | G8: ug/m3 | H8: ug/m3 | I8: ug/m3 | J8: m/sec | K8: deg | L8: degreC | M8: % | N8: w/m2 | O8: mm | P8: mg/m3 | Q8: ug/m3
A9: 03-11-2022 00:15 | B9: Pw.Off | C9: Pw.Off | D9: Pw.Off | E9: Pw.Off | F9: Pw.Off | G9: Pw.Off | H9: Pw.Off | I9: Pw.Off | J9: Pw.Off | K9: Pw.Off | L9: Pw.Off | M9: Pw.Off | N9: Pw.Off | O9: Pw.Off | P9: Pw.Off | Q9: Pw.Off
A10: 03-11-2022 00:30 | B10: Pw.Off | C10: Pw.Off | D10: Pw.Off | E10: Pw.Off | F10: Pw.Off | G10: Pw.Off | H10: Pw.Off | I10: Pw.Off | J10: Pw.Off | K10: Pw.Off | L10: Pw.Off | M10: Pw.Off | N10: Pw.Off | O10: Pw.Off | P10: Pw.Off | Q10: Pw.Off
A11: 03-11-2022 00:45 | B11: Pw.Off | C11: Pw.Off | D11: Pw.Off | E11: Pw.Off | F11: Pw.Off | G11: Pw.Off | H11: Pw.Off | I11: Pw.Off | J11: Pw.Off | K11: Pw.Off | L11: Pw.Off | M11: Pw.Off | N11: Pw.Off | O11: Pw.Off | P11: Pw.Off | Q11: Pw.Off
A12: 03-11-2022 01:00 | B12: Pw.Off | C12: Pw.Off | D12: Pw.Off | E12: Pw.Off | F12: Pw.Off | G12: Pw.Off | H12: Pw.Off | I12: Pw.Off | J12: Pw.Off | K12: Pw.Off | L12: Pw.Off | M12: Pw.Off | N12: Pw.Off | O12: Pw.Off | P12: Pw.Off | Q12: Pw.Off
A13: 03-11-2022 01:15 | B13: Pw.Off | C13: Pw.Off | D13: Pw.Off | E13: Pw.Off | F13: Pw.Off | G13: Pw.Off | H13: Pw.Off | I13: Pw.Off | J13: Pw.Off | K13: Pw.Off | L13: Pw.Off | M13: Pw.Off | N13: Pw.Off | O13: Pw.Off | P13: Pw.Off | Q13: Pw.Off
A14: 03-11-2022 01:30 | B14: Pw.Off | C14: Pw.Off | D14: Pw.Off | E14: Pw.Off | F14: Pw.Off | G14: Pw.Off | H14: Pw.Off | I14: Pw.Off | J14: Pw.Off | K14: Pw.Off | L14: Pw.Off | M14: Pw.Off | N14: Pw.Off | O14: Pw.Off | P14: Pw.Off | Q14: Pw.Off
A15: 03-11-2022 01:45 | B15: Pw.Off | C15: Pw.Off | D15: Pw.Off | E15: Pw.Off | F15: Pw.Off | G15: Pw.Off | H15: Pw.Off | I15: Pw.Off | J15: Pw.Off | K15: Pw.Off | L15: Pw.Off | M15: Pw.Off | N15: Pw.Off | O15: Pw.Off | P15: Pw.Off | Q15: Pw.Off
A16: 03-11-2022 02:00 | B16: Pw.Off | C16: Pw.Off | D16: Pw.Off | E16: Pw.Off | F16: Pw.Off | G16: Pw.Off | H16: Pw.Off | I16: Pw.Off | J16: Pw.Off | K16: Pw.Off | L16: Pw.Off | M16: Pw.Off | N16: Pw.Off | O16: Pw.Off | P16: Pw.Off | Q16: Pw.Off
A17: 03-11-2022 02:15 | B17: Pw.Off | C17: Pw.Off | D17: Pw.Off | E17: Pw.Off | F17: Pw.Off | G17: Pw.Off | H17: Pw.Off | I17: Pw.Off | J17: Pw.Off | K17: Pw.Off | L17: Pw.Off | M17: Pw.Off | N17: Pw.Off | O17: Pw.Off | P17: Pw.Off | Q17: Pw.Off
A18: 03-11-2022 02:30 | B18: Pw.Off | C18: Pw.Off | D18: Pw.Off | E18: Pw.Off | F18: Pw.Off | G18: Pw.Off | H18: Pw.Off | I18: Pw.Off | J18: Pw.Off | K18: Pw.Off | L18: Pw.Off | M18: Pw.Off | N18: Pw.Off | O18: Pw.Off | P18: Pw.Off | Q18: Pw.Off
A19: 03-11-2022 02:45 | B19: Pw.Off | C19: Pw.Off | D19: Pw.Off | E19: Pw.Off | F19: Pw.Off | G19: Pw.Off | H19: Pw.Off | I19: Pw.Off | J19: Pw.Off | K19: Pw.Off | L19: Pw.Off | M19: Pw.Off | N19: Pw.Off | O19: Pw.Off | P19: Pw.Off | Q19: Pw.Off
A20: 03-11-2022 03:00 | B20: Pw.Off | C20: Pw.Off | D20: Pw.Off | E20: Pw.Off | F20: Pw.Off | G20: Pw.Off | H20: Pw.Off | I20: Pw.Off | J20: Pw.Off | K20: Pw.Off | L20: Pw.Off | M20: Pw.Off | N20: Pw.Off | O20: Pw.Off | P20: Pw.Off | Q20: Pw.Off
... A104: 03-11-2022 24:00 | B104: Pw.Off | C104: Pw.Off | D104: Pw.Off | E104: Pw.Off | F104: Pw.Off | G104: Pw.Off | H104: Pw.Off | I104: Pw.Off | J104: Pw.Off | K104: Pw.Off | L104: Pw.Off | M104: Pw.Off | N104: Pw.Off | O104: Pw.Off | P104: Pw.Off | Q104: Pw.Off
A106: Min | B106: =MIN(B9:B104) -> 0 | C106: =MIN(C9:C104) -> 0 | D106: =MIN(D9:D104) -> 0 | E106: =MIN(E9:E104) -> 0 | F106: =MIN(F9:F104) -> 0 | G106: =MIN(G9:G104) -> 0 | H106: =MIN(H9:H104) -> 0 | I106: =MIN(I9:I104) -> 0 | ... Q106: =MIN(Q9:Q104) -> 0
A107: Max | B107: =MAX(B9:B104) -> 0 | C107: =MAX(C9:C104) -> 0 | D107: =MAX(D9:D104) -> 0 | E107: =MAX(E9:E104) -> 0 | F107: =MAX(F9:F104) -> 0 | G107: =MAX(G9:G104) -> 0 | H107: =MAX(H9:H104) -> 0 | I107: =MAX(I9:I104) -> 0 | ... Q107: =MAX(Q9:Q104) -> 0
A108: Avg | B108: =AVERAGE(B9:B104) -> #DIV/0! | C108: =AVERAGE(C9:C104) -> #DIV/0! | D108: =AVERAGE(D9:D104) -> #DIV/0! | E108: =AVERAGE(E9:E104) -> #DIV/0! | F108: =AVERAGE(F9:F104) -> #DIV/0! | G108: =AVERAGE(G9:G104) -> #DIV/0! | H108: =AVERAGE(H9:H104) -> #DIV/0! | I108: =AVERAGE(I9:I104) -> #DIV/0! | ... Q108: =AVERAGE(Q9:Q104) -> #DIV/0!
A109: Stdev | B109: =STDEV(B9:B104) -> #DIV/0! | C109: =STDEV(C9:C104) -> #DIV/0! | D109: =STDEV(D9:D104) -> #DIV/0! | E109: =STDEV(E9:E104) -> #DIV/0! | F109: =STDEV(F9:F104) -> #DIV/0! | G109: =STDEV(G9:G104) -> #DIV/0! | H109: =STDEV(H9:H104) -> #DIV/0! | I109: =STDEV(I9:I104) -> #DIV/0! | ... Q109: =STDEV(Q9:Q104) -> #DIV/0!
A110: Num | B110: =COUNT(B9:B104)+96 -> 96 | C110: =COUNT(C9:C104)+96 -> 96 | D110: =COUNT(D9:D104)+96 -> 96 | E110: =COUNT(E9:E104)+96 -> 96 | F110: =COUNT(F9:F104)+96 -> 96 | G110: =COUNT(G9:G104)+96 -> 96 | H110: =COUNT(H9:H104)+96 -> 96 | I110: =COUNT(I9:I104)+96 -> 96 | ... Q110: =COUNT(Q9:Q104)+96 -> 96
A111: DCR | B111: =IF(B110>=87,">90%",IF(B110<=87,"<90%")) -> >90% | C111: =IF(C110>=87,">90%",IF(C110<=87,"<90%")) -> >90% | D111: =IF(D110>=87,">90%",IF(D110<=87,"<90%")) -> >90% | E111: =IF(E110>=87,">90%",IF(E110<=87,"<90%")) -> >90% | F111: =IF(F110>=87,">90%",IF(F110<=87,"<90%")) -> >90% | G111: =IF(G110>=87,">90%",IF(G110<=87,"<90%")) -> >90% | H111: =IF(H110>=87,">90%",IF(H110<=87,"<90%")) -> >90% | I111: =IF(I110>=87,">90%",IF(I110<=87,"<90%")) -> >90% | ... Q111: =IF(Q110>=87,">90%",IF(Q110<=87,"<90%")) -> >90%
A112: Status | B112: =IF(B110>=87,"OK",IF(B110<=87,"LESS")) -> OK | C112: =IF(C110>=87,"OK",IF(C110<=87,"LESS")) -> OK | D112: =IF(D110>=87,"OK",IF(D110<=87,"LESS")) -> OK | E112: =IF(E110>=87,"OK",IF(E110<=87,"LESS")) -> OK | F112: =IF(F110>=87,"OK",IF(F110<=87,"LESS")) -> OK | G112: =IF(G110>=87,"OK",IF(G110<=87,"LESS")) -> OK | H112: =IF(H110>=87,"OK",IF(H110<=87,"LESS")) -> OK | I112: =IF(I110>=87,"OK",IF(I110<=87,"LESS")) -> OK | ... Q112: =IF(Q110>=87,"OK",IF(Q110<=87,"LESS")) -> OK
A115: Done by | B115: RK
A117: Comment

Sheet 04
A1: Station: | B1: Bhatagaon, RAIPUR
A2: Date: | B2: =$A$9 -> 04-11-2022 00:15 | D2: Power Off | G2: Pw.Off | L2: Link Fail | N2: Link F | P2: Maintenance | R2: Maint.
A3: Report Type: | B3: Mean | D3: Calibration | G3: Calib. | L3: Data Fail | N3: Data F | P3: Invalid | R3: Invalid
A4: Time Base: | B4: 15 Min | D4: Zero Referrence | G4: Z.Ref | L4: Warm Up | N4: Wm. Up
A7: Date & Time | B7: NO_BHATAGAON | C7: NO2__BHATAGAON | D7: NOX_BHATAGAON | E7: SO2__BHATAGAON | F7: O3__BHATAGAON | G7: PM10__BHATAGAON | H7: PM2_5__BHATAGAON | I7: BENZ__BHATAGAON | J7: WS__BHATAGAON | K7: WD__BHATAGAON | L7: TEMP__BHATAGAON | M7: HUM__BHATAGAON | N7: SR__BHATAGAON | O7: RG__BHATAGAON | P7: CO__BHATAGAON | Q7: NH3__BHATAGAON
B8: ug/m3 | C8: ug/m3 | D8: ug/m3 | E8: ug/m3 | F8: ug/m3 | G8: ug/m3 | H8: ug/m3 | I8: ug/m3 | J8: m/sec | K8: deg | L8: degreC | M8: % | N8: w/m2 | O8: mm | P8: mg/m3 | Q8: ug/m3
A9: 04-11-2022 00:15 | B9: Pw.Off | C9: Pw.Off | D9: Pw.Off | E9: Pw.Off | F9: Pw.Off | G9: Pw.Off | H9: Pw.Off | I9: Pw.Off | J9: Pw.Off | K9: Pw.Off | L9: Pw.Off | M9: Pw.Off | N9: Pw.Off | O9: Pw.Off | P9: Pw.Off | Q9: Pw.Off
A10: 04-11-2022 00:30 | B10: Pw.Off | C10: Pw.Off | D10: Pw.Off | E10: Pw.Off | F10: Pw.Off | G10: Pw.Off | H10: Pw.Off | I10: Pw.Off | J10: Pw.Off | K10: Pw.Off | L10: Pw.Off | M10: Pw.Off | N10: Pw.Off | O10: Pw.Off | P10: Pw.Off | Q10: Pw.Off
A11: 04-11-2022 00:45 | B11: Pw.Off | C11: Pw.Off | D11: Pw.Off | E11: Pw.Off | F11: Pw.Off | G11: Pw.Off | H11: Pw.Off | I11: Pw.Off | J11: Pw.Off | K11: Pw.Off | L11: Pw.Off | M11: Pw.Off | N11: Pw.Off | O11: Pw.Off | P11: Pw.Off | Q11: Pw.Off
A12: 04-11-2022 01:00 | B12: Pw.Off | C12: Pw.Off | D12: Pw.Off | E12: Pw.Off | F12: Pw.Off | G12: Pw.Off | H12: Pw.Off | I12: Pw.Off | J12: Pw.Off | K12: Pw.Off | L12: Pw.Off | M12: Pw.Off | N12: Pw.Off | O12: Pw.Off | P12: Pw.Off | Q12: Pw.Off
A13: 04-11-2022 01:15 | B13: Pw.Off | C13: Pw.Off | D13: Pw.Off | E13: Pw.Off | F13: Pw.Off | G13: Pw.Off | H13: Pw.Off | I13: Pw.Off | J13: Pw.Off | K13: Pw.Off | L13: Pw.Off | M13: Pw.Off | N13: Pw.Off | O13: Pw.Off | P13: Pw.Off | Q13: Pw.Off
A14: 04-11-2022 01:30 | B14: Pw.Off | C14: Pw.Off | D14: Pw.Off | E14: Pw.Off | F14: Pw.Off | G14: Pw.Off | H14: Pw.Off | I14: Pw.Off | J14: Pw.Off | K14: Pw.Off | L14: Pw.Off | M14: Pw.Off | N14: Pw.Off | O14: Pw.Off | P14: Pw.Off | Q14: Pw.Off
A15: 04-11-2022 01:45 | B15: Pw.Off | C15: Pw.Off | D15: Pw.Off | E15: Pw.Off | F15: Pw.Off | G15: Pw.Off | H15: Pw.Off | I15: Pw.Off | J15: Pw.Off | K15: Pw.Off | L15: Pw.Off | M15: Pw.Off | N15: Pw.Off | O15: Pw.Off | P15: Pw.Off | Q15: Pw.Off
A16: 04-11-2022 02:00 | B16: Pw.Off | C16: Pw.Off | D16: Pw.Off | E16: Pw.Off | F16: Pw.Off | G16: Pw.Off | H16: Pw.Off | I16: Pw.Off | J16: Pw.Off | K16: Pw.Off | L16: Pw.Off | M16: Pw.Off | N16: Pw.Off | O16: Pw.Off | P16: Pw.Off | Q16: Pw.Off
A17: 04-11-2022 02:15 | B17: Pw.Off | C17: Pw.Off | D17: Pw.Off | E17: Pw.Off | F17: Pw.Off | G17: Pw.Off | H17: Pw.Off | I17: Pw.Off | J17: Pw.Off | K17: Pw.Off | L17: Pw.Off | M17: Pw.Off | N17: Pw.Off | O17: Pw.Off | P17: Pw.Off | Q17: Pw.Off
A18: 04-11-2022 02:30 | B18: Pw.Off | C18: Pw.Off | D18: Pw.Off | E18: Pw.Off | F18: Pw.Off | G18: Pw.Off | H18: Pw.Off | I18: Pw.Off | J18: Pw.Off | K18: Pw.Off | L18: Pw.Off | M18: Pw.Off | N18: Pw.Off | O18: Pw.Off | P18: Pw.Off | Q18: Pw.Off
A19: 04-11-2022 02:45 | B19: Pw.Off | C19: Pw.Off | D19: Pw.Off | E19: Pw.Off | F19: Pw.Off | G19: Pw.Off | H19: Pw.Off | I19: Pw.Off | J19: Pw.Off | K19: Pw.Off | L19: Pw.Off | M19: Pw.Off | N19: Pw.Off | O19: Pw.Off | P19: Pw.Off | Q19: Pw.Off
A20: 04-11-2022 03:00 | B20: Pw.Off | C20: Pw.Off | D20: Pw.Off | E20: Pw.Off | F20: Pw.Off | G20: Pw.Off | H20: Pw.Off | I20: Pw.Off | J20: Pw.Off | K20: Pw.Off | L20: Pw.Off | M20: Pw.Off | N20: Pw.Off | O20: Pw.Off | P20: Pw.Off | Q20: Pw.Off
... A104: 04-11-2022 24:00 | B104: Pw.Off | C104: Pw.Off | D104: Pw.Off | E104: Pw.Off | F104: Pw.Off | G104: Pw.Off | H104: Pw.Off | I104: Pw.Off | J104: Pw.Off | K104: Pw.Off | L104: Pw.Off | M104: Pw.Off | N104: Pw.Off | O104: Pw.Off | P104: Pw.Off | Q104: Pw.Off
A106: Min | B106: =MIN(B9:B104) -> 0 | C106: =MIN(C9:C104) -> 0 | D106: =MIN(D9:D104) -> 0 | E106: =MIN(E9:E104) -> 0 | F106: =MIN(F9:F104) -> 0 | G106: =MIN(G9:G104) -> 0 | H106: =MIN(H9:H104) -> 0 | I106: =MIN(I9:I104) -> 0 | ... Q106: =MIN(Q9:Q104) -> 0
A107: Max | B107: =MAX(B9:B104) -> 0 | C107: =MAX(C9:C104) -> 0 | D107: =MAX(D9:D104) -> 0 | E107: =MAX(E9:E104) -> 0 | F107: =MAX(F9:F104) -> 0 | G107: =MAX(G9:G104) -> 0 | H107: =MAX(H9:H104) -> 0 | I107: =MAX(I9:I104) -> 0 | ... Q107: =MAX(Q9:Q104) -> 0
A108: Avg | B108: =AVERAGE(B9:B104) -> #DIV/0! | C108: =AVERAGE(C9:C104) -> #DIV/0! | D108: =AVERAGE(D9:D104) -> #DIV/0! | E108: =AVERAGE(E9:E104) -> #DIV/0! | F108: =AVERAGE(F9:F104) -> #DIV/0! | G108: =AVERAGE(G9:G104) -> #DIV/0! | H108: =AVERAGE(H9:H104) -> #DIV/0! | I108: =AVERAGE(I9:I104) -> #DIV/0! | ... Q108: =AVERAGE(Q9:Q104) -> #DIV/0!
A109: Stdev | B109: =STDEV(B9:B104) -> #DIV/0! | C109: =STDEV(C9:C104) -> #DIV/0! | D109: =STDEV(D9:D104) -> #DIV/0! | E109: =STDEV(E9:E104) -> #DIV/0! | F109: =STDEV(F9:F104) -> #DIV/0! | G109: =STDEV(G9:G104) -> #DIV/0! | H109: =STDEV(H9:H104) -> #DIV/0! | I109: =STDEV(I9:I104) -> #DIV/0! | ... Q109: =STDEV(Q9:Q104) -> #DIV/0!
A110: Num | B110: =COUNT(B9:B104)+96 -> 96 | C110: =COUNT(C9:C104)+96 -> 96 | D110: =COUNT(D9:D104)+96 -> 96 | E110: =COUNT(E9:E104)+96 -> 96 | F110: =COUNT(F9:F104)+96 -> 96 | G110: =COUNT(G9:G104)+96 -> 96 | H110: =COUNT(H9:H104)+96 -> 96 | I110: =COUNT(I9:I104)+96 -> 96 | ... Q110: =COUNT(Q9:Q104)+96 -> 96
A111: DCR | B111: =IF(B110>=87,">90%",IF(B110<=87,"<90%")) -> >90% | C111: =IF(C110>=87,">90%",IF(C110<=87,"<90%")) -> >90% | D111: =IF(D110>=87,">90%",IF(D110<=87,"<90%")) -> >90% | E111: =IF(E110>=87,">90%",IF(E110<=87,"<90%")) -> >90% | F111: =IF(F110>=87,">90%",IF(F110<=87,"<90%")) -> >90% | G111: =IF(G110>=87,">90%",IF(G110<=87,"<90%")) -> >90% | H111: =IF(H110>=87,">90%",IF(H110<=87,"<90%")) -> >90% | I111: =IF(I110>=87,">90%",IF(I110<=87,"<90%")) -> >90% | ... Q111: =IF(Q110>=87,">90%",IF(Q110<=87,"<90%")) -> >90%
A112: Status | B112: =IF(B110>=87,"OK",IF(B110<=87,"LESS")) -> OK | C112: =IF(C110>=87,"OK",IF(C110<=87,"LESS")) -> OK | D112: =IF(D110>=87,"OK",IF(D110<=87,"LESS")) -> OK | E112: =IF(E110>=87,"OK",IF(E110<=87,"LESS")) -> OK | F112: =IF(F110>=87,"OK",IF(F110<=87,"LESS")) -> OK | G112: =IF(G110>=87,"OK",IF(G110<=87,"LESS")) -> OK | H112: =IF(H110>=87,"OK",IF(H110<=87,"LESS")) -> OK | I112: =IF(I110>=87,"OK",IF(I110<=87,"LESS")) -> OK | ... Q112: =IF(Q110>=87,"OK",IF(Q110<=87,"LESS")) -> OK
A115: Done by | B115: RK
A117: Comment

Sheet 05
A1: Station: | B1: Bhatagaon, RAIPUR
A2: Date: | B2: =$A$9 -> 05-11-2022 00:15 | D2: Power Off | G2: Pw.Off | L2: Link Fail | N2: Link F | P2: Maintenance | R2: Maint.
A3: Report Type: | B3: Mean | D3: Calibration | G3: Calib. | L3: Data Fail | N3: Data F | P3: Invalid | R3: Invalid
A4: Time Base: | B4: 15 Min | D4: Zero Referrence | G4: Z.Ref | L4: Warm Up | N4: Wm. Up
A7: Date & Time | B7: NO_BHATAGAON | C7: NO2__BHATAGAON | D7: NOX_BHATAGAON | E7: SO2__BHATAGAON | F7: O3__BHATAGAON | G7: PM10__BHATAGAON | H7: PM2_5__BHATAGAON | I7: BENZ__BHATAGAON | J7: WS__BHATAGAON | K7: WD__BHATAGAON | L7: TEMP__BHATAGAON | M7: HUM__BHATAGAON | N7: SR__BHATAGAON | O7: RG__BHATAGAON | P7: CO__BHATAGAON | Q7: NH3__BHATAGAON
B8: ug/m3 | C8: ug/m3 | D8: ug/m3 | E8: ug/m3 | F8: ug/m3 | G8: ug/m3 | H8: ug/m3 | I8: ug/m3 | J8: m/sec | K8: deg | L8: degreC | M8: % | N8: w/m2 | O8: mm | P8: mg/m3 | Q8: ug/m3
A9: 05-11-2022 00:15 | B9: Pw.Off | C9: Pw.Off | D9: Pw.Off | E9: Pw.Off | F9: Pw.Off | G9: Pw.Off | H9: Pw.Off | I9: Pw.Off | J9: Pw.Off | K9: Pw.Off | L9: Pw.Off | M9: Pw.Off | N9: Pw.Off | O9: Pw.Off | P9: Pw.Off | Q9: Pw.Off
A10: 05-11-2022 00:30 | B10: Pw.Off | C10: Pw.Off | D10: Pw.Off | E10: Pw.Off | F10: Pw.Off | G10: Pw.Off | H10: Pw.Off | I10: Pw.Off | J10: Pw.Off | K10: Pw.Off | L10: Pw.Off | M10: Pw.Off | N10: Pw.Off | O10: Pw.Off | P10: Pw.Off | Q10: Pw.Off
A11: 05-11-2022 00:45 | B11: Pw.Off | C11: Pw.Off | D11: Pw.Off | E11: Pw.Off | F11: Pw.Off | G11: Pw.Off | H11: Pw.Off | I11: Pw.Off | J11: Pw.Off | K11: Pw.Off | L11: Pw.Off | M11: Pw.Off | N11: Pw.Off | O11: Pw.Off | P11: Pw.Off | Q11: Pw.Off
A12: 05-11-2022 01:00 | B12: Pw.Off | C12: Pw.Off | D12: Pw.Off | E12: Pw.Off | F12: Pw.Off | G12: Pw.Off | H12: Pw.Off | I12: Pw.Off | J12: Pw.Off | K12: Pw.Off | L12: Pw.Off | M12: Pw.Off | N12: Pw.Off | O12: Pw.Off | P12: Pw.Off | Q12: Pw.Off
A13: 05-11-2022 01:15 | B13: Pw.Off | C13: Pw.Off | D13: Pw.Off | E13: Pw.Off | F13: Pw.Off | G13: Pw.Off | H13: Pw.Off | I13: Pw.Off | J13: Pw.Off | K13: Pw.Off | L13: Pw.Off | M13: Pw.Off | N13: Pw.Off | O13: Pw.Off | P13: Pw.Off | Q13: Pw.Off
A14: 05-11-2022 01:30 | B14: Pw.Off | C14: Pw.Off | D14: Pw.Off | E14: Pw.Off | F14: Pw.Off | G14: Pw.Off | H14: Pw.Off | I14: Pw.Off | J14: Pw.Off | K14: Pw.Off | L14: Pw.Off | M14: Pw.Off | N14: Pw.Off | O14: Pw.Off | P14: Pw.Off | Q14: Pw.Off
A15: 05-11-2022 01:45 | B15: Pw.Off | C15: Pw.Off | D15: Pw.Off | E15: Pw.Off | F15: Pw.Off | G15: Pw.Off | H15: Pw.Off | I15: Pw.Off | J15: Pw.Off | K15: Pw.Off | L15: Pw.Off | M15: Pw.Off | N15: Pw.Off | O15: Pw.Off | P15: Pw.Off | Q15: Pw.Off
A16: 05-11-2022 02:00 | B16: Pw.Off | C16: Pw.Off | D16: Pw.Off | E16: Pw.Off | F16: Pw.Off | G16: Pw.Off | H16: Pw.Off | I16: Pw.Off | J16: Pw.Off | K16: Pw.Off | L16: Pw.Off | M16: Pw.Off | N16: Pw.Off | O16: Pw.Off | P16: Pw.Off | Q16: Pw.Off
A17: 05-11-2022 02:15 | B17: Pw.Off | C17: Pw.Off | D17: Pw.Off | E17: Pw.Off | F17: Pw.Off | G17: Pw.Off | H17: Pw.Off | I17: Pw.Off | J17: Pw.Off | K17: Pw.Off | L17: Pw.Off | M17: Pw.Off | N17: Pw.Off | O17: Pw.Off | P17: Pw.Off | Q17: Pw.Off
A18: 05-11-2022 02:30 | B18: Pw.Off | C18: Pw.Off | D18: Pw.Off | E18: Pw.Off | F18: Pw.Off | G18: Pw.Off | H18: Pw.Off | I18: Pw.Off | J18: Pw.Off | K18: Pw.Off | L18: Pw.Off | M18: Pw.Off | N18: Pw.Off | O18: Pw.Off | P18: Pw.Off | Q18: Pw.Off
A19: 05-11-2022 02:45 | B19: Pw.Off | C19: Pw.Off | D19: Pw.Off | E19: Pw.Off | F19: Pw.Off | G19: Pw.Off | H19: Pw.Off | I19: Pw.Off | J19: Pw.Off | K19: Pw.Off | L19: Pw.Off | M19: Pw.Off | N19: Pw.Off | O19: Pw.Off | P19: Pw.Off | Q19: Pw.Off
A20: 05-11-2022 03:00 | B20: Pw.Off | C20: Pw.Off | D20: Pw.Off | E20: Pw.Off | F20: Pw.Off | G20: Pw.Off | H20: Pw.Off | I20: Pw.Off | J20: Pw.Off | K20: Pw.Off | L20: Pw.Off | M20: Pw.Off | N20: Pw.Off | O20: Pw.Off | P20: Pw.Off | Q20: Pw.Off
... A104: 05-11-2022 24:00 | B104: Pw.Off | C104: Pw.Off | D104: Pw.Off | E104: Pw.Off | F104: Pw.Off | G104: Pw.Off | H104: Pw.Off | I104: Pw.Off | J104: Pw.Off | K104: Pw.Off | L104: Pw.Off | M104: Pw.Off | N104: Pw.Off | O104: Pw.Off | P104: Pw.Off | Q104: Pw.Off
A106: Min | B106: =MIN(B9:B104) -> 0 | C106: =MIN(C9:C104) -> 0 | D106: =MIN(D9:D104) -> 0 | E106: =MIN(E9:E104) -> 0 | F106: =MIN(F9:F104) -> 0 | G106: =MIN(G9:G104) -> 0 | H106: =MIN(H9:H104) -> 0 | I106: =MIN(I9:I104) -> 0 | ... Q106: =MIN(Q9:Q104) -> 0
A107: Max | B107: =MAX(B9:B104) -> 0 | C107: =MAX(C9:C104) -> 0 | D107: =MAX(D9:D104) -> 0 | E107: =MAX(E9:E104) -> 0 | F107: =MAX(F9:F104) -> 0 | G107: =MAX(G9:G104) -> 0 | H107: =MAX(H9:H104) -> 0 | I107: =MAX(I9:I104) -> 0 | ... Q107: =MAX(Q9:Q104) -> 0
A108: Avg | B108: =AVERAGE(B9:B104) -> #DIV/0! | C108: =AVERAGE(C9:C104) -> #DIV/0! | D108: =AVERAGE(D9:D104) -> #DIV/0! | E108: =AVERAGE(E9:E104) -> #DIV/0! | F108: =AVERAGE(F9:F104) -> #DIV/0! | G108: =AVERAGE(G9:G104) -> #DIV/0! | H108: =AVERAGE(H9:H104) -> #DIV/0! | I108: =AVERAGE(I9:I104) -> #DIV/0! | ... Q108: =AVERAGE(Q9:Q104) -> #DIV/0!
A109: Stdev | B109: =STDEV(B9:B104) -> #DIV/0! | C109: =STDEV(C9:C104) -> #DIV/0! | D109: =STDEV(D9:D104) -> #DIV/0! | E109: =STDEV(E9:E104) -> #DIV/0! | F109: =STDEV(F9:F104) -> #DIV/0! | G109: =STDEV(G9:G104) -> #DIV/0! | H109: =STDEV(H9:H104) -> #DIV/0! | I109: =STDEV(I9:I104) -> #DIV/0! | ... Q109: =STDEV(Q9:Q104) -> #DIV/0!
A110: Num | B110: =COUNT(B9:B104)+96 -> 96 | C110: =COUNT(C9:C104)+96 -> 96 | D110: =COUNT(D9:D104)+96 -> 96 | E110: =COUNT(E9:E104)+96 -> 96 | F110: =COUNT(F9:F104)+96 -> 96 | G110: =COUNT(G9:G104)+96 -> 96 | H110: =COUNT(H9:H104)+96 -> 96 | I110: =COUNT(I9:I104)+96 -> 96 | ... Q110: =COUNT(Q9:Q104)+96 -> 96
A111: DCR | B111: =IF(B110>=87,">90%",IF(B110<=87,"<90%")) -> >90% | C111: =IF(C110>=87,">90%",IF(C110<=87,"<90%")) -> >90% | D111: =IF(D110>=87,">90%",IF(D110<=87,"<90%")) -> >90% | E111: =IF(E110>=87,">90%",IF(E110<=87,"<90%")) -> >90% | F111: =IF(F110>=87,">90%",IF(F110<=87,"<90%")) -> >90% | G111: =IF(G110>=87,">90%",IF(G110<=87,"<90%")) -> >90% | H111: =IF(H110>=87,">90%",IF(H110<=87,"<90%")) -> >90% | I111: =IF(I110>=87,">90%",IF(I110<=87,"<90%")) -> >90% | ... Q111: =IF(Q110>=87,">90%",IF(Q110<=87,"<90%")) -> >90%
A112: Status | B112: =IF(B110>=87,"OK",IF(B110<=87,"LESS")) -> OK | C112: =IF(C110>=87,"OK",IF(C110<=87,"LESS")) -> OK | D112: =IF(D110>=87,"OK",IF(D110<=87,"LESS")) -> OK | E112: =IF(E110>=87,"OK",IF(E110<=87,"LESS")) -> OK | F112: =IF(F110>=87,"OK",IF(F110<=87,"LESS")) -> OK | G112: =IF(G110>=87,"OK",IF(G110<=87,"LESS")) -> OK | H112: =IF(H110>=87,"OK",IF(H110<=87,"LESS")) -> OK | I112: =IF(I110>=87,"OK",IF(I110<=87,"LESS")) -> OK | ... Q112: =IF(Q110>=87,"OK",IF(Q110<=87,"LESS")) -> OK
A115: Done by | B115: RK
A117: Comment

Sheet 06
A1: Station: | B1: Bhatagaon, RAIPUR
A2: Date: | B2: =$A$9 -> 06-11-2022 00:15 | D2: Power Off | G2: Pw.Off | L2: Link Fail | N2: Link F | P2: Maintenance | R2: Maint.
A3: Report Type: | B3: Mean | D3: Calibration | G3: Calib. | L3: Data Fail | N3: Data F | P3: Invalid | R3: Invalid
A4: Time Base: | B4: 15 Min | D4: Zero Referrence | G4: Z.Ref | L4: Warm Up | N4: Wm. Up
A7: Date & Time | B7: NO_BHATAGAON | C7: NO2__BHATAGAON | D7: NOX_BHATAGAON | E7: SO2__BHATAGAON | F7: O3__BHATAGAON | G7: PM10__BHATAGAON | H7: PM2_5__BHATAGAON | I7: BENZ__BHATAGAON | J7: WS__BHATAGAON | K7: WD__BHATAGAON | L7: TEMP__BHATAGAON | M7: HUM__BHATAGAON | N7: SR__BHATAGAON | O7: RG__BHATAGAON | P7: CO__BHATAGAON | Q7: NH3__BHATAGAON
B8: ug/m3 | C8: ug/m3 | D8: ug/m3 | E8: ug/m3 | F8: ug/m3 | G8: ug/m3 | H8: ug/m3 | I8: ug/m3 | J8: m/sec | K8: deg | L8: degreC | M8: % | N8: w/m2 | O8: mm | P8: mg/m3 | Q8: ug/m3
A9: 06-11-2022 00:15 | B9: Pw.Off | C9: Pw.Off | D9: Pw.Off | E9: Pw.Off | F9: Pw.Off | G9: Pw.Off | H9: Pw.Off | I9: Pw.Off | J9: Pw.Off | K9: Pw.Off | L9: Pw.Off | M9: Pw.Off | N9: Pw.Off | O9: Pw.Off | P9: Pw.Off | Q9: Pw.Off
A10: 06-11-2022 00:30 | B10: Pw.Off | C10: Pw.Off | D10: Pw.Off | E10: Pw.Off | F10: Pw.Off | G10: Pw.Off | H10: Pw.Off | I10: Pw.Off | J10: Pw.Off | K10: Pw.Off | L10: Pw.Off | M10: Pw.Off | N10: Pw.Off | O10: Pw.Off | P10: Pw.Off | Q10: Pw.Off
A11: 06-11-2022 00:45 | B11: Pw.Off | C11: Pw.Off | D11: Pw.Off | E11: Pw.Off | F11: Pw.Off | G11: Pw.Off | H11: Pw.Off | I11: Pw.Off | J11: Pw.Off | K11: Pw.Off | L11: Pw.Off | M11: Pw.Off | N11: Pw.Off | O11: Pw.Off | P11: Pw.Off | Q11: Pw.Off
A12: 06-11-2022 01:00 | B12: Pw.Off | C12: Pw.Off | D12: Pw.Off | E12: Pw.Off | F12: Pw.Off | G12: Pw.Off | H12: Pw.Off | I12: Pw.Off | J12: Pw.Off | K12: Pw.Off | L12: Pw.Off | M12: Pw.Off | N12: Pw.Off | O12: Pw.Off | P12: Pw.Off | Q12: Pw.Off
A13: 06-11-2022 01:15 | B13: Pw.Off | C13: Pw.Off | D13: Pw.Off | E13: Pw.Off | F13: Pw.Off | G13: Pw.Off | H13: Pw.Off | I13: Pw.Off | J13: Pw.Off | K13: Pw.Off | L13: Pw.Off | M13: Pw.Off | N13: Pw.Off | O13: Pw.Off | P13: Pw.Off | Q13: Pw.Off
A14: 06-11-2022 01:30 | B14: Pw.Off | C14: Pw.Off | D14: Pw.Off | E14: Pw.Off | F14: Pw.Off | G14: Pw.Off | H14: Pw.Off | I14: Pw.Off | J14: Pw.Off | K14: Pw.Off | L14: Pw.Off | M14: Pw.Off | N14: Pw.Off | O14: Pw.Off | P14: Pw.Off | Q14: Pw.Off
A15: 06-11-2022 01:45 | B15: Pw.Off | C15: Pw.Off | D15: Pw.Off | E15: Pw.Off | F15: Pw.Off | G15: Pw.Off | H15: Pw.Off | I15: Pw.Off | J15: Pw.Off | K15: Pw.Off | L15: Pw.Off | M15: Pw.Off | N15: Pw.Off | O15: Pw.Off | P15: Pw.Off | Q15: Pw.Off
A16: 06-11-2022 02:00 | B16: Pw.Off | C16: Pw.Off | D16: Pw.Off | E16: Pw.Off | F16: Pw.Off | G16: Pw.Off | H16: Pw.Off | I16: Pw.Off | J16: Pw.Off | K16: Pw.Off | L16: Pw.Off | M16: Pw.Off | N16: Pw.Off | O16: Pw.Off | P16: Pw.Off | Q16: Pw.Off
A17: 06-11-2022 02:15 | B17: Pw.Off | C17: Pw.Off | D17: Pw.Off | E17: Pw.Off | F17: Pw.Off | G17: Pw.Off | H17: Pw.Off | I17: Pw.Off | J17: Pw.Off | K17: Pw.Off | L17: Pw.Off | M17: Pw.Off | N17: Pw.Off | O17: Pw.Off | P17: Pw.Off | Q17: Pw.Off
A18: 06-11-2022 02:30 | B18: Pw.Off | C18: Pw.Off | D18: Pw.Off | E18: Pw.Off | F18: Pw.Off | G18: Pw.Off | H18: Pw.Off | I18: Pw.Off | J18: Pw.Off | K18: Pw.Off | L18: Pw.Off | M18: Pw.Off | N18: Pw.Off | O18: Pw.Off | P18: Pw.Off | Q18: Pw.Off
A19: 06-11-2022 02:45 | B19: Pw.Off | C19: Pw.Off | D19: Pw.Off | E19: Pw.Off | F19: Pw.Off | G19: Pw.Off | H19: Pw.Off | I19: Pw.Off | J19: Pw.Off | K19: Pw.Off | L19: Pw.Off | M19: Pw.Off | N19: Pw.Off | O19: Pw.Off | P19: Pw.Off | Q19: Pw.Off
A20: 06-11-2022 03:00 | B20: Pw.Off | C20: Pw.Off | D20: Pw.Off | E20: Pw.Off | F20: Pw.Off | G20: Pw.Off | H20: Pw.Off | I20: Pw.Off | J20: Pw.Off | K20: Pw.Off | L20: Pw.Off | M20: Pw.Off | N20: Pw.Off | O20: Pw.Off | P20: Pw.Off | Q20: Pw.Off
... A104: 06-11-2022 24:00 | B104: Pw.Off | C104: Pw.Off | D104: Pw.Off | E104: Pw.Off | F104: Pw.Off | G104: Pw.Off | H104: Pw.Off | I104: Pw.Off | J104: Pw.Off | K104: Pw.Off | L104: Pw.Off | M104: Pw.Off | N104: Pw.Off | O104: Pw.Off | P104: Pw.Off | Q104: Pw.Off
A106: Min | B106: =MIN(B9:B104) -> 0 | C106: =MIN(C9:C104) -> 0 | D106: =MIN(D9:D104) -> 0 | E106: =MIN(E9:E104) -> 0 | F106: =MIN(F9:F104) -> 0 | G106: =MIN(G9:G104) -> 0 | H106: =MIN(H9:H104) -> 0 | I106: =MIN(I9:I104) -> 0 | ... Q106: =MIN(Q9:Q104) -> 0
A107: Max | B107: =MAX(B9:B104) -> 0 | C107: =MAX(C9:C104) -> 0 | D107: =MAX(D9:D104) -> 0 | E107: =MAX(E9:E104) -> 0 | F107: =MAX(F9:F104) -> 0 | G107: =MAX(G9:G104) -> 0 | H107: =MAX(H9:H104) -> 0 | I107: =MAX(I9:I104) -> 0 | ... Q107: =MAX(Q9:Q104) -> 0
A108: Avg | B108: =AVERAGE(B9:B104) -> #DIV/0! | C108: =AVERAGE(C9:C104) -> #DIV/0! | D108: =AVERAGE(D9:D104) -> #DIV/0! | E108: =AVERAGE(E9:E104) -> #DIV/0! | F108: =AVERAGE(F9:F104) -> #DIV/0! | G108: =AVERAGE(G9:G104) -> #DIV/0! | H108: =AVERAGE(H9:H104) -> #DIV/0! | I108: =AVERAGE(I9:I104) -> #DIV/0! | ... Q108: =AVERAGE(Q9:Q104) -> #DIV/0!
A109: Stdev | B109: =STDEV(B9:B104) -> #DIV/0! | C109: =STDEV(C9:C104) -> #DIV/0! | D109: =STDEV(D9:D104) -> #DIV/0! | E109: =STDEV(E9:E104) -> #DIV/0! | F109: =STDEV(F9:F104) -> #DIV/0! | G109: =STDEV(G9:G104) -> #DIV/0! | H109: =STDEV(H9:H104) -> #DIV/0! | I109: =STDEV(I9:I104) -> #DIV/0! | ... Q109: =STDEV(Q9:Q104) -> #DIV/0!
A110: Num | B110: =COUNT(B9:B104)+96 -> 96 | C110: =COUNT(C9:C104)+96 -> 96 | D110: =COUNT(D9:D104)+96 -> 96 | E110: =COUNT(E9:E104)+96 -> 96 | F110: =COUNT(F9:F104)+96 -> 96 | G110: =COUNT(G9:G104)+96 -> 96 | H110: =COUNT(H9:H104)+96 -> 96 | I110: =COUNT(I9:I104)+96 -> 96 | ... Q110: =COUNT(Q9:Q104)+96 -> 96
A111: DCR | B111: =IF(B110>=87,">90%",IF(B110<=87,"<90%")) -> >90% | C111: =IF(C110>=87,">90%",IF(C110<=87,"<90%")) -> >90% | D111: =IF(D110>=87,">90%",IF(D110<=87,"<90%")) -> >90% | E111: =IF(E110>=87,">90%",IF(E110<=87,"<90%")) -> >90% | F111: =IF(F110>=87,">90%",IF(F110<=87,"<90%")) -> >90% | G111: =IF(G110>=87,">90%",IF(G110<=87,"<90%")) -> >90% | H111: =IF(H110>=87,">90%",IF(H110<=87,"<90%")) -> >90% | I111: =IF(I110>=87,">90%",IF(I110<=87,"<90%")) -> >90% | ... Q111: =IF(Q110>=87,">90%",IF(Q110<=87,"<90%")) -> >90%
A112: Status | B112: =IF(B110>=87,"OK",IF(B110<=87,"LESS")) -> OK | C112: =IF(C110>=87,"OK",IF(C110<=87,"LESS")) -> OK | D112: =IF(D110>=87,"OK",IF(D110<=87,"LESS")) -> OK | E112: =IF(E110>=87,"OK",IF(E110<=87,"LESS")) -> OK | F112: =IF(F110>=87,"OK",IF(F110<=87,"LESS")) -> OK | G112: =IF(G110>=87,"OK",IF(G110<=87,"LESS")) -> OK | H112: =IF(H110>=87,"OK",IF(H110<=87,"LESS")) -> OK | I112: =IF(I110>=87,"OK",IF(I110<=87,"LESS")) -> OK | ... Q112: =IF(Q110>=87,"OK",IF(Q110<=87,"LESS")) -> OK
A115: Done by | B115: RK
A117: Comment

Sheet 07
A1: Station: | B1: Bhatagaon, RAIPUR
A2: Date: | B2: =$A$9 -> 07-11-2022 00:15 | D2: Power Off | G2: Pw.Off | L2: Link Fail | N2: Link F | P2: Maintenance | R2: Maint.
A3: Report Type: | B3: Mean | D3: Calibration | G3: Calib. | L3: Data Fail | N3: Data F | P3: Invalid | R3: Invalid
A4: Time Base: | B4: 15 Min | D4: Zero Referrence | G4: Z.Ref | L4: Warm Up | N4: Wm. Up
A7: Date & Time | B7: NO_BHATAGAON | C7: NO2__BHATAGAON | D7: NOX_BHATAGAON | E7: SO2__BHATAGAON | F7: O3__BHATAGAON | G7: PM10__BHATAGAON | H7: PM2_5__BHATAGAON | I7: BENZ__BHATAGAON | J7: WS__BHATAGAON | K7: WD__BHATAGAON | L7: TEMP__BHATAGAON | M7: HUM__BHATAGAON | N7: SR__BHATAGAON | O7: RG__BHATAGAON | P7: CO__BHATAGAON | Q7: NH3__BHATAGAON
B8: ug/m3 | C8: ug/m3 | D8: ug/m3 | E8: ug/m3 | F8: ug/m3 | G8: ug/m3 | H8: ug/m3 | I8: ug/m3 | J8: m/sec | K8: deg | L8: degreC | M8: % | N8: w/m2 | O8: mm | P8: mg/m3 | Q8: ug/m3
A9: 07-11-2022 00:15 | B9: Pw.Off | C9: Pw.Off | D9: Pw.Off | E9: Pw.Off | F9: Pw.Off | G9: Pw.Off | H9: Pw.Off | I9: Pw.Off | J9: Pw.Off | K9: Pw.Off | L9: Pw.Off | M9: Pw.Off | N9: Pw.Off | O9: Pw.Off | P9: Pw.Off | Q9: Pw.Off
A10: 07-11-2022 00:30 | B10: Pw.Off | C10: Pw.Off | D10: Pw.Off | E10: Pw.Off | F10: Pw.Off | G10: Pw.Off | H10: Pw.Off | I10: Pw.Off | J10: Pw.Off | K10: Pw.Off | L10: Pw.Off | M10: Pw.Off | N10: Pw.Off | O10: Pw.Off | P10: Pw.Off | Q10: Pw.Off
A11: 07-11-2022 00:45 | B11: Pw.Off | C11: Pw.Off | D11: Pw.Off | E11: Pw.Off | F11: Pw.Off | G11: Pw.Off | H11: Pw.Off | I11: Pw.Off | J11: Pw.Off | K11: Pw.Off | L11: Pw.Off | M11: Pw.Off | N11: Pw.Off | O11: Pw.Off | P11: Pw.Off | Q11: Pw.Off
A12: 07-11-2022 01:00 | B12: Pw.Off | C12: Pw.Off | D12: Pw.Off | E12: Pw.Off | F12: Pw.Off | G12: Pw.Off | H12: Pw.Off | I12: Pw.Off | J12: Pw.Off | K12: Pw.Off | L12: Pw.Off | M12: Pw.Off | N12: Pw.Off | O12: Pw.Off | P12: Pw.Off | Q12: Pw.Off
A13: 07-11-2022 01:15 | B13: Pw.Off | C13: Pw.Off | D13: Pw.Off | E13: Pw.Off | F13: Pw.Off | G13: Pw.Off | H13: Pw.Off | I13: Pw.Off | J13: Pw.Off | K13: Pw.Off | L13: Pw.Off | M13: Pw.Off | N13: Pw.Off | O13: Pw.Off | P13: Pw.Off | Q13: Pw.Off
A14: 07-11-2022 01:30 | B14: Pw.Off | C14: Pw.Off | D14: Pw.Off | E14: Pw.Off | F14: Pw.Off | G14: Pw.Off | H14: Pw.Off | I14: Pw.Off | J14: Pw.Off | K14: Pw.Off | L14: Pw.Off | M14: Pw.Off | N14: Pw.Off | O14: Pw.Off | P14: Pw.Off | Q14: Pw.Off
A15: 07-11-2022 01:45 | B15: Pw.Off | C15: Pw.Off | D15: Pw.Off | E15: Pw.Off | F15: Pw.Off | G15: Pw.Off | H15: Pw.Off | I15: Pw.Off | J15: Pw.Off | K15: Pw.Off | L15: Pw.Off | M15: Pw.Off | N15: Pw.Off | O15: Pw.Off | P15: Pw.Off | Q15: Pw.Off
A16: 07-11-2022 02:00 | B16: Pw.Off | C16: Pw.Off | D16: Pw.Off | E16: Pw.Off | F16: Pw.Off | G16: Pw.Off | H16: Pw.Off | I16: Pw.Off | J16: Pw.Off | K16: Pw.Off | L16: Pw.Off | M16: Pw.Off | N16: Pw.Off | O16: Pw.Off | P16: Pw.Off | Q16: Pw.Off
A17: 07-11-2022 02:15 | B17: Pw.Off | C17: Pw.Off | D17: Pw.Off | E17: Pw.Off | F17: Pw.Off | G17: Pw.Off | H17: Pw.Off | I17: Pw.Off | J17: Pw.Off | K17: Pw.Off | L17: Pw.Off | M17: Pw.Off | N17: Pw.Off | O17: Pw.Off | P17: Pw.Off | Q17: Pw.Off
A18: 07-11-2022 02:30 | B18: Pw.Off | C18: Pw.Off | D18: Pw.Off | E18: Pw.Off | F18: Pw.Off | G18: Pw.Off | H18: Pw.Off | I18: Pw.Off | J18: Pw.Off | K18: Pw.Off | L18: Pw.Off | M18: Pw.Off | N18: Pw.Off | O18: Pw.Off | P18: Pw.Off | Q18: Pw.Off
A19: 07-11-2022 02:45 | B19: Pw.Off | C19: Pw.Off | D19: Pw.Off | E19: Pw.Off | F19: Pw.Off | G19: Pw.Off | H19: Pw.Off | I19: Pw.Off | J19: Pw.Off | K19: Pw.Off | L19: Pw.Off | M19: Pw.Off | N19: Pw.Off | O19: Pw.Off | P19: Pw.Off | Q19: Pw.Off
A20: 07-11-2022 03:00 | B20: Pw.Off | C20: Pw.Off | D20: Pw.Off | E20: Pw.Off | F20: Pw.Off | G20: Pw.Off | H20: Pw.Off | I20: Pw.Off | J20: Pw.Off | K20: Pw.Off | L20: Pw.Off | M20: Pw.Off | N20: Pw.Off | O20: Pw.Off | P20: Pw.Off | Q20: Pw.Off
... A104: 07-11-2022 24:00 | B104: Pw.Off | C104: Pw.Off | D104: Pw.Off | E104: Pw.Off | F104: Pw.Off | G104: Pw.Off | H104: Pw.Off | I104: Pw.Off | J104: Pw.Off | K104: Pw.Off | L104: Pw.Off | M104: Pw.Off | N104: Pw.Off | O104: Pw.Off | P104: Pw.Off | Q104: Pw.Off
A106: Min | B106: =MIN(B9:B104) -> 0 | C106: =MIN(C9:C104) -> 0 | D106: =MIN(D9:D104) -> 0 | E106: =MIN(E9:E104) -> 0 | F106: =MIN(F9:F104) -> 0 | G106: =MIN(G9:G104) -> 0 | H106: =MIN(H9:H104) -> 0 | I106: =MIN(I9:I104) -> 0 | ... Q106: =MIN(Q9:Q104) -> 0
A107: Max | B107: =MAX(B9:B104) -> 0 | C107: =MAX(C9:C104) -> 0 | D107: =MAX(D9:D104) -> 0 | E107: =MAX(E9:E104) -> 0 | F107: =MAX(F9:F104) -> 0 | G107: =MAX(G9:G104) -> 0 | H107: =MAX(H9:H104) -> 0 | I107: =MAX(I9:I104) -> 0 | ... Q107: =MAX(Q9:Q104) -> 0
A108: Avg | B108: =AVERAGE(B9:B104) -> #DIV/0! | C108: =AVERAGE(C9:C104) -> #DIV/0! | D108: =AVERAGE(D9:D104) -> #DIV/0! | E108: =AVERAGE(E9:E104) -> #DIV/0! | F108: =AVERAGE(F9:F104) -> #DIV/0! | G108: =AVERAGE(G9:G104) -> #DIV/0! | H108: =AVERAGE(H9:H104) -> #DIV/0! | I108: =AVERAGE(I9:I104) -> #DIV/0! | ... Q108: =AVERAGE(Q9:Q104) -> #DIV/0!
A109: Stdev | B109: =STDEV(B9:B104) -> #DIV/0! | C109: =STDEV(C9:C104) -> #DIV/0! | D109: =STDEV(D9:D104) -> #DIV/0! | E109: =STDEV(E9:E104) -> #DIV/0! | F109: =STDEV(F9:F104) -> #DIV/0! | G109: =STDEV(G9:G104) -> #DIV/0! | H109: =STDEV(H9:H104) -> #DIV/0! | I109: =STDEV(I9:I104) -> #DIV/0! | ... Q109: =STDEV(Q9:Q104) -> #DIV/0!
A110: Num | B110: =COUNT(B9:B104)+96 -> 96 | C110: =COUNT(C9:C104)+96 -> 96 | D110: =COUNT(D9:D104)+96 -> 96 | E110: =COUNT(E9:E104)+96 -> 96 | F110: =COUNT(F9:F104)+96 -> 96 | G110: =COUNT(G9:G104)+96 -> 96 | H110: =COUNT(H9:H104)+96 -> 96 | I110: =COUNT(I9:I104)+96 -> 96 | ... Q110: =COUNT(Q9:Q104)+96 -> 96
A111: DCR | B111: =IF(B110>=87,">90%",IF(B110<=87,"<90%")) -> >90% | C111: =IF(C110>=87,">90%",IF(C110<=87,"<90%")) -> >90% | D111: =IF(D110>=87,">90%",IF(D110<=87,"<90%")) -> >90% | E111: =IF(E110>=87,">90%",IF(E110<=87,"<90%")) -> >90% | F111: =IF(F110>=87,">90%",IF(F110<=87,"<90%")) -> >90% | G111: =IF(G110>=87,">90%",IF(G110<=87,"<90%")) -> >90% | H111: =IF(H110>=87,">90%",IF(H110<=87,"<90%")) -> >90% | I111: =IF(I110>=87,">90%",IF(I110<=87,"<90%")) -> >90% | ... Q111: =IF(Q110>=87,">90%",IF(Q110<=87,"<90%")) -> >90%
A112: Status | B112: =IF(B110>=87,"OK",IF(B110<=87,"LESS")) -> OK | C112: =IF(C110>=87,"OK",IF(C110<=87,"LESS")) -> OK | D112: =IF(D110>=87,"OK",IF(D110<=87,"LESS")) -> OK | E112: =IF(E110>=87,"OK",IF(E110<=87,"LESS")) -> OK | F112: =IF(F110>=87,"OK",IF(F110<=87,"LESS")) -> OK | G112: =IF(G110>=87,"OK",IF(G110<=87,"LESS")) -> OK | H112: =IF(H110>=87,"OK",IF(H110<=87,"LESS")) -> OK | I112: =IF(I110>=87,"OK",IF(I110<=87,"LESS")) -> OK | ... Q112: =IF(Q110>=87,"OK",IF(Q110<=87,"LESS")) -> OK
A115: Done by | B115: RK
A117: Comment

Sheet 08
A1: Station: | B1: Bhatagaon, RAIPUR
A2: Date: | B2: =$A$9 -> 08-11-2022 00:15 | D2: Power Off | G2: Pw.Off | L2: Link Fail | N2: Link F | P2: Maintenance | R2: Maint.
A3: Report Type: | B3: Mean | D3: Calibration | G3: Calib. | L3: Data Fail | N3: Data F | P3: Invalid | R3: Invalid
A4: Time Base: | B4: 15 Min | D4: Zero Referrence | G4: Z.Ref | L4: Warm Up | N4: Wm. Up
A7: Date & Time | B7: NO_BHATAGAON | C7: NO2__BHATAGAON | D7: NOX_BHATAGAON | E7: SO2__BHATAGAON | F7: O3__BHATAGAON | G7: PM10__BHATAGAON | H7: PM2_5__BHATAGAON | I7: BENZ__BHATAGAON | J7: WS__BHATAGAON | K7: WD__BHATAGAON | L7: TEMP__BHATAGAON | M7: HUM__BHATAGAON | N7: SR__BHATAGAON | O7: RG__BHATAGAON | P7: CO__BHATAGAON | Q7: NH3__BHATAGAON
B8: ug/m3 | C8: ug/m3 | D8: ug/m3 | E8: ug/m3 | F8: ug/m3 | G8: ug/m3 | H8: ug/m3 | I8: ug/m3 | J8: m/sec | K8: deg | L8: degreC | M8: % | N8: w/m2 | O8: mm | P8: mg/m3 | Q8: ug/m3
A9: 08-11-2022 00:15 | B9: Pw.Off | C9: Pw.Off | D9: Pw.Off | E9: Pw.Off | F9: Pw.Off | G9: Pw.Off | H9: Pw.Off | I9: Pw.Off | J9: Pw.Off | K9: Pw.Off | L9: Pw.Off | M9: Pw.Off | N9: Pw.Off | O9: Pw.Off | P9: Pw.Off | Q9: Pw.Off
A10: 08-11-2022 00:30 | B10: Pw.Off | C10: Pw.Off | D10: Pw.Off | E10: Pw.Off | F10: Pw.Off | G10: Pw.Off | H10: Pw.Off | I10: Pw.Off | J10: Pw.Off | K10: Pw.Off | L10: Pw.Off | M10: Pw.Off | N10: Pw.Off | O10: Pw.Off | P10: Pw.Off | Q10: Pw.Off
A11: 08-11-2022 00:45 | B11: Pw.Off | C11: Pw.Off | D11: Pw.Off | E11: Pw.Off | F11: Pw.Off | G11: Pw.Off | H11: Pw.Off | I11: Pw.Off | J11: Pw.Off | K11: Pw.Off | L11: Pw.Off | M11: Pw.Off | N11: Pw.Off | O11: Pw.Off | P11: Pw.Off | Q11: Pw.Off
A12: 08-11-2022 01:00 | B12: Pw.Off | C12: Pw.Off | D12: Pw.Off | E12: Pw.Off | F12: Pw.Off | G12: Pw.Off | H12: Pw.Off | I12: Pw.Off | J12: Pw.Off | K12: Pw.Off | L12: Pw.Off | M12: Pw.Off | N12: Pw.Off | O12: Pw.Off | P12: Pw.Off | Q12: Pw.Off
A13: 08-11-2022 01:15 | B13: Pw.Off | C13: Pw.Off | D13: Pw.Off | E13: Pw.Off | F13: Pw.Off | G13: Pw.Off | H13: Pw.Off | I13: Pw.Off | J13: Pw.Off | K13: Pw.Off | L13: Pw.Off | M13: Pw.Off | N13: Pw.Off | O13: Pw.Off | P13: Pw.Off | Q13: Pw.Off
A14: 08-11-2022 01:30 | B14: Pw.Off | C14: Pw.Off | D14: Pw.Off | E14: Pw.Off | F14: Pw.Off | G14: Pw.Off | H14: Pw.Off | I14: Pw.Off | J14: Pw.Off | K14: Pw.Off | L14: Pw.Off | M14: Pw.Off | N14: Pw.Off | O14: Pw.Off | P14: Pw.Off | Q14: Pw.Off
A15: 08-11-2022 01:45 | B15: Pw.Off | C15: Pw.Off | D15: Pw.Off | E15: Pw.Off | F15: Pw.Off | G15: Pw.Off | H15: Pw.Off | I15: Pw.Off | J15: Pw.Off | K15: Pw.Off | L15: Pw.Off | M15: Pw.Off | N15: Pw.Off | O15: Pw.Off | P15: Pw.Off | Q15: Pw.Off
A16: 08-11-2022 02:00 | B16: Pw.Off | C16: Pw.Off | D16: Pw.Off | E16: Pw.Off | F16: Pw.Off | G16: Pw.Off | H16: Pw.Off | I16: Pw.Off | J16: Pw.Off | K16: Pw.Off | L16: Pw.Off | M16: Pw.Off | N16: Pw.Off | O16: Pw.Off | P16: Pw.Off | Q16: Pw.Off
A17: 08-11-2022 02:15 | B17: Pw.Off | C17: Pw.Off | D17: Pw.Off | E17: Pw.Off | F17: Pw.Off | G17: Pw.Off | H17: Pw.Off | I17: Pw.Off | J17: Pw.Off | K17: Pw.Off | L17: Pw.Off | M17: Pw.Off | N17: Pw.Off | O17: Pw.Off | P17: Pw.Off | Q17: Pw.Off
A18: 08-11-2022 02:30 | B18: Pw.Off | C18: Pw.Off | D18: Pw.Off | E18: Pw.Off | F18: Pw.Off | G18: Pw.Off | H18: Pw.Off | I18: Pw.Off | J18: Pw.Off | K18: Pw.Off | L18: Pw.Off | M18: Pw.Off | N18: Pw.Off | O18: Pw.Off | P18: Pw.Off | Q18: Pw.Off
A19: 08-11-2022 02:45 | B19: Pw.Off | C19: Pw.Off | D19: Pw.Off | E19: Pw.Off | F19: Pw.Off | G19: Pw.Off | H19: Pw.Off | I19: Pw.Off | J19: Pw.Off | K19: Pw.Off | L19: Pw.Off | M19: Pw.Off | N19: Pw.Off | O19: Pw.Off | P19: Pw.Off | Q19: Pw.Off
A20: 08-11-2022 03:00 | B20: Pw.Off | C20: Pw.Off | D20: Pw.Off | E20: Pw.Off | F20: Pw.Off | G20: Pw.Off | H20: Pw.Off | I20: Pw.Off | J20: Pw.Off | K20: Pw.Off | L20: Pw.Off | M20: Pw.Off | N20: Pw.Off | O20: Pw.Off | P20: Pw.Off | Q20: Pw.Off
... A104: 08-11-2022 24:00 | B104: Pw.Off | C104: Pw.Off | D104: Pw.Off | E104: Pw.Off | F104: Pw.Off | G104: Pw.Off | H104: Pw.Off | I104: Pw.Off | J104: Pw.Off | K104: Pw.Off | L104: Pw.Off | M104: Pw.Off | N104: Pw.Off | O104: Pw.Off | P104: Pw.Off | Q104: Pw.Off
A106: Min | B106: =MIN(B9:B104) -> 0 | C106: =MIN(C9:C104) -> 0 | D106: =MIN(D9:D104) -> 0 | E106: =MIN(E9:E104) -> 0 | F106: =MIN(F9:F104) -> 0 | G106: =MIN(G9:G104) -> 0 | H106: =MIN(H9:H104) -> 0 | I106: =MIN(I9:I104) -> 0 | ... Q106: =MIN(Q9:Q104) -> 0
A107: Max | B107: =MAX(B9:B104) -> 0 | C107: =MAX(C9:C104) -> 0 | D107: =MAX(D9:D104) -> 0 | E107: =MAX(E9:E104) -> 0 | F107: =MAX(F9:F104) -> 0 | G107: =MAX(G9:G104) -> 0 | H107: =MAX(H9:H104) -> 0 | I107: =MAX(I9:I104) -> 0 | ... Q107: =MAX(Q9:Q104) -> 0
A108: Avg | B108: =AVERAGE(B9:B104) -> #DIV/0! | C108: =AVERAGE(C9:C104) -> #DIV/0! | D108: =AVERAGE(D9:D104) -> #DIV/0! | E108: =AVERAGE(E9:E104) -> #DIV/0! | F108: =AVERAGE(F9:F104) -> #DIV/0! | G108: =AVERAGE(G9:G104) -> #DIV/0! | H108: =AVERAGE(H9:H104) -> #DIV/0! | I108: =AVERAGE(I9:I104) -> #DIV/0! | ... Q108: =AVERAGE(Q9:Q104) -> #DIV/0!
A109: Stdev | B109: =STDEV(B9:B104) -> #DIV/0! | C109: =STDEV(C9:C104) -> #DIV/0! | D109: =STDEV(D9:D104) -> #DIV/0! | E109: =STDEV(E9:E104) -> #DIV/0! | F109: =STDEV(F9:F104) -> #DIV/0! | G109: =STDEV(G9:G104) -> #DIV/0! | H109: =STDEV(H9:H104) -> #DIV/0! | I109: =STDEV(I9:I104) -> #DIV/0! | ... Q109: =STDEV(Q9:Q104) -> #DIV/0!
A110: Num | B110: =COUNT(B9:B104)+96 -> 96 | C110: =COUNT(C9:C104)+96 -> 96 | D110: =COUNT(D9:D104)+96 -> 96 | E110: =COUNT(E9:E104)+96 -> 96 | F110: =COUNT(F9:F104)+96 -> 96 | G110: =COUNT(G9:G104)+96 -> 96 | H110: =COUNT(H9:H104)+96 -> 96 | I110: =COUNT(I9:I104)+96 -> 96 | ... Q110: =COUNT(Q9:Q104)+96 -> 96
A111: DCR | B111: =IF(B110>=87,">90%",IF(B110<=87,"<90%")) -> >90% | C111: =IF(C110>=87,">90%",IF(C110<=87,"<90%")) -> >90% | D111: =IF(D110>=87,">90%",IF(D110<=87,"<90%")) -> >90% | E111: =IF(E110>=87,">90%",IF(E110<=87,"<90%")) -> >90% | F111: =IF(F110>=87,">90%",IF(F110<=87,"<90%")) -> >90% | G111: =IF(G110>=87,">90%",IF(G110<=87,"<90%")) -> >90% | H111: =IF(H110>=87,">90%",IF(H110<=87,"<90%")) -> >90% | I111: =IF(I110>=87,">90%",IF(I110<=87,"<90%")) -> >90% | ... Q111: =IF(Q110>=87,">90%",IF(Q110<=87,"<90%")) -> >90%
A112: Status | B112: =IF(B110>=87,"OK",IF(B110<=87,"LESS")) -> OK | C112: =IF(C110>=87,"OK",IF(C110<=87,"LESS")) -> OK | D112: =IF(D110>=87,"OK",IF(D110<=87,"LESS")) -> OK | E112: =IF(E110>=87,"OK",IF(E110<=87,"LESS")) -> OK | F112: =IF(F110>=87,"OK",IF(F110<=87,"LESS")) -> OK | G112: =IF(G110>=87,"OK",IF(G110<=87,"LESS")) -> OK | H112: =IF(H110>=87,"OK",IF(H110<=87,"LESS")) -> OK | I112: =IF(I110>=87,"OK",IF(I110<=87,"LESS")) -> OK | ... Q112: =IF(Q110>=87,"OK",IF(Q110<=87,"LESS")) -> OK
A115: Done by | B115: RK
A117: Comment

Sheet 09
A1: Station: | B1: Bhatagaon, RAIPUR
A2: Date: | B2: =$A$9 -> 09-11-2022 00:15 | D2: Power Off | G2: Pw.Off | L2: Link Fail | N2: Link F | P2: Maintenance | R2: Maint.
A3: Report Type: | B3: Mean | D3: Calibration | G3: Calib. | L3: Data Fail | N3: Data F | P3: Invalid | R3: Invalid
A4: Time Base: | B4: 15 Min | D4: Zero Referrence | G4: Z.Ref | L4: Warm Up | N4: Wm. Up
A7: Date & Time | B7: NO_BHATAGAON | C7: NO2__BHATAGAON | D7: NOX_BHATAGAON | E7: SO2__BHATAGAON | F7: O3__BHATAGAON | G7: PM10__BHATAGAON | H7: PM2_5__BHATAGAON | I7: BENZ__BHATAGAON | J7: WS__BHATAGAON | K7: WD__BHATAGAON | L7: TEMP__BHATAGAON | M7: HUM__BHATAGAON | N7: SR__BHATAGAON | O7: RG__BHATAGAON | P7: CO__BHATAGAON | Q7: NH3__BHATAGAON
B8: ug/m3 | C8: ug/m3 | D8: ug/m3 | E8: ug/m3 | F8: ug/m3 | G8: ug/m3 | H8: ug/m3 | I8: ug/m3 | J8: m/sec | K8: deg | L8: degreC | M8: % | N8: w/m2 | O8: mm | P8: mg/m3 | Q8: ug/m3
A9: 09-11-2022 00:15 | B9: Pw.Off | C9: Pw.Off | D9: Pw.Off | E9: Pw.Off | F9: Pw.Off | G9: Pw.Off | H9: Pw.Off | I9: Pw.Off | J9: Pw.Off | K9: Pw.Off | L9: Pw.Off | M9: Pw.Off | N9: Pw.Off | O9: Pw.Off | P9: Pw.Off | Q9: Pw.Off
A10: 09-11-2022 00:30 | B10: Pw.Off | C10: Pw.Off | D10: Pw.Off | E10: Pw.Off | F10: Pw.Off | G10: Pw.Off | H10: Pw.Off | I10: Pw.Off | J10: Pw.Off | K10: Pw.Off | L10: Pw.Off | M10: Pw.Off | N10: Pw.Off | O10: Pw.Off | P10: Pw.Off | Q10: Pw.Off
A11: 09-11-2022 00:45 | B11: Pw.Off | C11: Pw.Off | D11: Pw.Off | E11: Pw.Off | F11: Pw.Off | G11: Pw.Off | H11: Pw.Off | I11: Pw.Off | J11: Pw.Off | K11: Pw.Off | L11: Pw.Off | M11: Pw.Off | N11: Pw.Off | O11: Pw.Off | P11: Pw.Off | Q11: Pw.Off
A12: 09-11-2022 01:00 | B12: Pw.Off | C12: Pw.Off | D12: Pw.Off | E12: Pw.Off | F12: Pw.Off | G12: Pw.Off | H12: Pw.Off | I12: Pw.Off | J12: Pw.Off | K12: Pw.Off | L12: Pw.Off | M12: Pw.Off | N12: Pw.Off | O12: Pw.Off | P12: Pw.Off | Q12: Pw.Off
A13: 09-11-2022 01:15 | B13: Pw.Off | C13: Pw.Off | D13: Pw.Off | E13: Pw.Off | F13: Pw.Off | G13: Pw.Off | H13: Pw.Off | I13: Pw.Off | J13: Pw.Off | K13: Pw.Off | L13: Pw.Off | M13: Pw.Off | N13: Pw.Off | O13: Pw.Off | P13: Pw.Off | Q13: Pw.Off
A14: 09-11-2022 01:30 | B14: Pw.Off | C14: Pw.Off | D14: Pw.Off | E14: Pw.Off | F14: Pw.Off | G14: Pw.Off | H14: Pw.Off | I14: Pw.Off | J14: Pw.Off | K14: Pw.Off | L14: Pw.Off | M14: Pw.Off | N14: Pw.Off | O14: Pw.Off | P14: Pw.Off | Q14: Pw.Off
A15: 09-11-2022 01:45 | B15: Pw.Off | C15: Pw.Off | D15: Pw.Off | E15: Pw.Off | F15: Pw.Off | G15: Pw.Off | H15: Pw.Off | I15: Pw.Off | J15: Pw.Off | K15: Pw.Off | L15: Pw.Off | M15: Pw.Off | N15: Pw.Off | O15: Pw.Off | P15: Pw.Off | Q15: Pw.Off
A16: 09-11-2022 02:00 | B16: Pw.Off | C16: Pw.Off | D16: Pw.Off | E16: Pw.Off | F16: Pw.Off | G16: Pw.Off | H16: Pw.Off | I16: Pw.Off | J16: Pw.Off | K16: Pw.Off | L16: Pw.Off | M16: Pw.Off | N16: Pw.Off | O16: Pw.Off | P16: Pw.Off | Q16: Pw.Off
A17: 09-11-2022 02:15 | B17: Pw.Off | C17: Pw.Off | D17: Pw.Off | E17: Pw.Off | F17: Pw.Off | G17: Pw.Off | H17: Pw.Off | I17: Pw.Off | J17: Pw.Off | K17: Pw.Off | L17: Pw.Off | M17: Pw.Off | N17: Pw.Off | O17: Pw.Off | P17: Pw.Off | Q17: Pw.Off
A18: 09-11-2022 02:30 | B18: Pw.Off | C18: Pw.Off | D18: Pw.Off | E18: Pw.Off | F18: Pw.Off | G18: Pw.Off | H18: Pw.Off | I18: Pw.Off | J18: Pw.Off | K18: Pw.Off | L18: Pw.Off | M18: Pw.Off | N18: Pw.Off | O18: Pw.Off | P18: Pw.Off | Q18: Pw.Off
A19: 09-11-2022 02:45 | B19: Pw.Off | C19: Pw.Off | D19: Pw.Off | E19: Pw.Off | F19: Pw.Off | G19: Pw.Off | H19: Pw.Off | I19: Pw.Off | J19: Pw.Off | K19: Pw.Off | L19: Pw.Off | M19: Pw.Off | N19: Pw.Off | O19: Pw.Off | P19: Pw.Off | Q19: Pw.Off
A20: 09-11-2022 03:00 | B20: Pw.Off | C20: Pw.Off | D20: Pw.Off | E20: Pw.Off | F20: Pw.Off | G20: Pw.Off | H20: Pw.Off | I20: Pw.Off | J20: Pw.Off | K20: Pw.Off | L20: Pw.Off | M20: Pw.Off | N20: Pw.Off | O20: Pw.Off | P20: Pw.Off | Q20: Pw.Off
... A104: 09-11-2022 24:00 | B104: Pw.Off | C104: Pw.Off | D104: Pw.Off | E104: Pw.Off | F104: Pw.Off | G104: Pw.Off | H104: Pw.Off | I104: Pw.Off | J104: Pw.Off | K104: Pw.Off | L104: Pw.Off | M104: Pw.Off | N104: Pw.Off | O104: Pw.Off | P104: Pw.Off | Q104: Pw.Off
