Workbook

Sheet 01
A1: Station: | B1: IGKV RAIPUR
A2: Date: | B2: =$A$9 -> 45474.01 | C2: Power Off | G2: Pw.Off | J2: Link Fail | L2: Link F | N2: Maintenance | P2: Maint.
A3: Report Type: | B3: Mean | C3: Calibration | G3: Calib. | J3: Data Fail | L3: Data F | N3: Invalid | P3: Invalid
A4: Time Base: | B4: 15 Min | C4: Zero Referrence | G4: Z.Ref | J4: Warm Up | L4: Wm. Up
A7: Date & Time | B7: NO | C7: NO2 | D7: NOX | E7: SO2 | F7: O3 | G7: PM 10 | H7: PM 2.5 | I7: BENZ | J7: WS | K7: WD | L7: TEMP | M7: HUM | N7: SR | O7: RG | P7: CO | Q7: NH3
B8: ug/m3 | C8: ug/m3 | D8: ppb | E8: ug/m3 | F8: ug/m3 | G8: ug/m3 | H8: ug/m3 | I8: ug/m3 | J8: m/sec | K8: deg | L8: degreC | M8: % | N8: w/m2 | O8: mm | P8: mg/m3 | Q8: ug/m3
A9: 45474.01 | B9: 9.21 | C9: 4.15 | D9: 14.01 | E9: 7.07 | F9: 5.79 | G9: 8.26 | H9: 4.61 | I9: 3.62 | J9: 0.1 | K9: 259.9 | L9: 25.74 | M9: 101.35 | N9: 2.1 | O9: 0 | P9: 0.33 | Q9: 4.62
A10: 45474.021 | B10: 9.23 | C10: 4.07 | D10: 13.98 | E10: 7.55 | F10: 6.11 | G10: 8.93 | H10: 3.89 | I10: 3.69 | J10: 0.11 | K10: 229.17 | L10: 25.84 | M10: 101.9 | N10: 2.1 | O10: 0 | P10: 0.33 | Q10: 4.62
A11: 45474.031 | B11: 9.24 | C11: 4.06 | D11: 13.98 | E11: 7.95 | F11: 5.27 | G11: 9.94 | H11: 3.24 | I11: 3.64 | J11: 0.12 | K11: 236.75 | L11: 25.88 | M11: 98.89 | N11: 2.1 | O11: 0 | P11: 0.33 | Q11: 4.62
A12: 45474.042 | B12: 9.22 | C12: 4.07 | D12: 13.97 | E12: 7.66 | F12: 5.22 | G12: 9.94 | H12: 3.24 | I12: 3.62 | J12: 0.1 | K12: 270.82 | L12: 25.83 | M12: 98.79 | N12: 2.1 | O12: 0 | P12: 0.32 | Q12: 4.61
A13: 45474.052 | B13: 9.23 | C13: 4.08 | D13: 13.98 | E13: 7.85 | F13: 4.65 | G13: 9.94 | H13: 3.24 | I13: 3.58 | J13: 0.15 | K13: 231.87 | L13: 25.85 | M13: 98.84 | N13: 2.1 | O13: 0 | P13: 0.32 | Q13: 4.62
A14: 45474.062 | B14: 9.23 | C14: 4.06 | D14: 13.97 | E14: 7.91 | F14: 4.93 | G14: 9.66 | H14: 2.83 | I14: 3.56 | J14: 0.18 | K14: 252.47 | L14: 25.87 | M14: 97.47 | N14: 2.3 | O14: 0 | P14: 0.31 | Q14: 4.61
A15: 45474.073 | B15: 9.23 | C15: 4.06 | D15: 13.97 | E15: 8.34 | F15: 5.23 | G15: 9.25 | H15: 2.47 | I15: 3.51 | J15: 0.37 | K15: 251.43 | L15: 25.94 | M15: 96.07 | N15: 2.7 | O15: 0 | P15: 0.31 | Q15: 4.6
A16: 45474.083 | B16: 9.23 | C16: 4.06 | D16: 13.97 | E16: 8.88 | F16: 4.59 | G16: 9.25 | H16: 2.47 | I16: 3.47 | J16: 0.48 | K16: 246.14 | L16: 26.06 | M16: 94.45 | N16: 2.6 | O16: 0 | P16: 0.31 | Q16: 4.61
A17: 45474.094 | B17: 9.25 | C17: 4.07 | D17: 14 | E17: 6.4 | F17: 4.13 | G17: 9.25 | H17: 2.47 | I17: 3.48 | J17: 0.57 | K17: 248.68 | L17: 26.12 | M17: 94.51 | N17: 2.8 | O17: 0 | P17: 0.3 | Q17: 4.64
A18: 45474.104 | B18: 9.25 | C18: 4.05 | D18: 13.98 | E18: 8.59 | F18: 4.15 | G18: 10.36 | H18: 2.89 | I18: 3.45 | J18: 0.56 | K18: 254.59 | L18: 26.22 | M18: 95.28 | N18: 2.8 | O18: 0 | P18: 0.3 | Q18: 4.63
A19: 45474.115 | B19: 9.24 | C19: 4.05 | D19: 13.98 | E19: 8.4 | F19: 3.74 | G19: 12.04 | H19: 3.28 | I19: 3.46 | J19: 0.74 | K19: 260.75 | L19: 26.29 | M19: 95.21 | N19: 3.1 | O19: 0 | P19: 0.31 | Q19: 4.63
A20: 45474.125 | B20: 9.23 | C20: 4.06 | D20: 13.97 | E20: 8.24 | F20: 4.02 | G20: 12.04 | H20: 3.28 | I20: 3.38 | J20: 0.86 | K20: 260.14 | L20: 26.42 | M20: 94.25 | N20: 3 | O20: 0 | P20: 0.3 | Q20: 4.63
... A104: 45475 | B104: 9.2 | C104: 4.07 | D104: 13.95 | E104: 10.33 | F104: 9.69 | G104: 17.19 | H104: 6.36 | I104: 3.1 | J104: 0.24 | K104: 242.5 | L104: 26.73 | M104: 93.68 | N104: 2.2 | O104: 0 | P104: 0.3 | Q104: 4.63
A106: Min | B106: =MIN(B9:B104) -> 9.16 | C106: =MIN(C9:C104) -> 4.02 | D106: =MIN(D9:D104) -> 13.92 | E106: =MIN(E9:E104) -> 5.42 | F106: =MIN(F9:F104) -> 3.47 | G106: =MIN(G9:G104) -> 6.49 | H106: =MIN(H9:H104) -> 2.36 | I106: =MIN(I9:I104) -> 2.66 | ... Q106: =MIN(Q9:Q104) -> 4.6
A107: Max | B107: =MAX(B9:B104) -> 9.28 | C107: =MAX(C9:C104) -> 4.15 | D107: =MAX(D9:D104) -> 14.02 | E107: =MAX(E9:E104) -> 11.95 | F107: =MAX(F9:F104) -> 13.77 | G107: =MAX(G9:G104) -> 17.9 | H107: =MAX(H9:H104) -> 8.3 | I107: =MAX(I9:I104) -> 4.85 | ... Q107: =MAX(Q9:Q104) -> 4.66
A108: Avg | B108: =AVERAGE(B9:B104) -> 9.2105208 | C108: =AVERAGE(C9:C104) -> 4.0697917 | D108: =AVERAGE(D9:D104) -> 13.962188 | E108: =AVERAGE(E9:E104) -> 8.6421875 | F108: =AVERAGE(F9:F104) -> 6.2196875 | G108: =AVERAGE(G9:G104) -> 12.108021 | H108: =AVERAGE(H9:H104) -> 4.8102083 | I108: =AVERAGE(I9:I104) -> 3.461875 | ... Q108: =AVERAGE(Q9:Q104) -> 4.6335417
A109: Stdev | B109: =STDEV(B9:B104) -> 0.024851974 | C109: =STDEV(C9:C104) -> 0.020569736 | D109: =STDEV(D9:D104) -> 0.022766694 | E109: =STDEV(E9:E104) -> 1.5528624 | F109: =STDEV(F9:F104) -> 2.4051591 | G109: =STDEV(G9:G104) -> 3.3897352 | H109: =STDEV(H9:H104) -> 1.4638536 | I109: =STDEV(I9:I104) -> 0.41431062 | ... Q109: =STDEV(Q9:Q104) -> 0.012309959
A110: Num | B110: =COUNT(B9:B104) -> 96 | C110: =COUNT(C9:C104) -> 96 | D110: =COUNT(D9:D104) -> 96 | E110: =COUNT(E9:E104) -> 96 | F110: =COUNT(F9:F104) -> 96 | G110: =COUNT(G9:G104) -> 96 | H110: =COUNT(H9:H104) -> 96 | I110: =COUNT(I9:I104) -> 96 | ... Q110: =COUNT(Q9:Q104) -> 96
A111: DCR | B111: =IF(B110>=87,">90%",IF(B110<=87,"<90%")) -> >90% | C111: =IF(C110>=87,">90%",IF(C110<=87,"<90%")) -> >90% | D111: =IF(D110>=87,">90%",IF(D110<=87,"<90%")) -> >90% | E111: =IF(E110>=87,">90%",IF(E110<=87,"<90%")) -> >90% | F111: =IF(F110>=87,">90%",IF(F110<=87,"<90%")) -> >90% | G111: =IF(G110>=87,">90%",IF(G110<=87,"<90%")) -> >90% | H111: =IF(H110>=87,">90%",IF(H110<=87,"<90%")) -> >90% | I111: =IF(I110>=87,">90%",IF(I110<=87,"<90%")) -> >90% | ... Q111: =IF(Q110>=87,">90%",IF(Q110<=87,"<90%")) -> >90%
A112: Status | B112: =IF(B110>=87,"OK",IF(B110<=87,"LESS")) -> OK | C112: =IF(C110>=87,"OK",IF(C110<=87,"LESS")) -> OK | D112: =IF(D110>=87,"OK",IF(D110<=87,"LESS")) -> OK | E112: =IF(E110>=87,"OK",IF(E110<=87,"LESS")) -> OK | F112: =IF(F110>=87,"OK",IF(F110<=87,"LESS")) -> OK | G112: =IF(G110>=87,"OK",IF(G110<=87,"LESS")) -> OK | H112: =IF(H110>=87,"OK",IF(H110<=87,"LESS")) -> OK | I112: =IF(I110>=87,"OK",IF(I110<=87,"LESS")) -> OK | ... Q112: =IF(Q110>=87,"OK",IF(Q110<=87,"LESS")) -> OK
A115: Done by | B115: AKASH
A117: Comment

Sheet 02
A1: Station: | B1: IGKV RAIPUR
A2: Date: | B2: =$A$9 -> 45475.01 | C2: Power Off | G2: Pw.Off | J2: Link Fail | L2: Link F | N2: Maintenance | P2: Maint.
A3: Report Type: | B3: Mean | C3: Calibration | G3: Calib. | J3: Data Fail | L3: Data F | N3: Invalid | P3: Invalid
A4: Time Base: | B4: 15 Min | C4: Zero Referrence | G4: Z.Ref | J4: Warm Up | L4: Wm. Up
A7: Date & Time | B7: NO | C7: NO2 | D7: NOX | E7: SO2 | F7: O3 | G7: PM 10 | H7: PM 2.5 | I7: BENZ | J7: WS | K7: WD | L7: TEMP | M7: HUM | N7: SR | O7: RG | P7: CO | Q7: NH3
B8: ug/m3 | C8: ug/m3 | D8: ppb | E8: ug/m3 | F8: ug/m3 | G8: ug/m3 | H8: ug/m3 | I8: ug/m3 | J8: m/sec | K8: deg | L8: degreC | M8: % | N8: w/m2 | O8: mm | P8: mg/m3 | Q8: ug/m3
A9: 45475.01 | B9: 9.3 | C9: 4.1 | D9: 14.05 | E9: 10.15 | F9: 9.07 | G9: 17.19 | H9: 6.36 | I9: 2.93 | J9: 0.49 | K9: 256.39 | L9: 26.81 | M9: 92.5 | N9: 2.1 | O9: 0 | P9: 0.29 | Q9: 4.64
A10: 45475.021 | B10: 9.29 | C10: 4.07 | D10: 14.03 | E10: 9.75 | F10: 10.92 | G10: 16.2 | H10: 5.4 | I10: 2.69 | J10: 0.57 | K10: 251.91 | L10: 26.85 | M10: 91.26 | N10: 2.1 | O10: 0 | P10: 0.28 | Q10: 4.65
A11: 45475.031 | B11: 9.31 | C11: 4.08 | D11: 14.05 | E11: 9.56 | F11: 9.85 | G11: 14.72 | H11: 4.56 | I11: 2.73 | J11: 0.57 | K11: 262.89 | L11: 26.92 | M11: 91.27 | N11: 2.1 | O11: 0 | P11: 0.27 | Q11: 4.66
A12: 45475.042 | B12: 9.31 | C12: 4.13 | D12: 14.07 | E12: 9.55 | F12: 10.68 | G12: 14.72 | H12: 4.56 | I12: 2.68 | J12: 0.54 | K12: 251.51 | L12: 26.99 | M12: 89.94 | N12: 2.1 | O12: 0 | P12: 0.28 | Q12: 4.66
A13: 45475.052 | B13: 9.3 | C13: 4.1 | D13: 14.05 | E13: 9.56 | F13: 10.78 | G13: 14.72 | H13: 4.56 | I13: 2.72 | J13: 0.73 | K13: 257.58 | L13: 27.06 | M13: 89.13 | N13: 2.1 | O13: 0 | P13: 0.27 | Q13: 4.64
A14: 45475.062 | B14: 9.3 | C14: 4.07 | D14: 14.03 | E14: 9.86 | F14: 8.98 | G14: 14.86 | H14: 4.17 | I14: 2.68 | J14: 0.95 | K14: 260.29 | L14: 27.05 | M14: 88.51 | N14: 2.2 | O14: 0 | P14: 0.28 | Q14: 4.63
A15: 45475.073 | B15: 9.3 | C15: 4.07 | D15: 14.04 | E15: 10.04 | F15: 7.21 | G15: 15.06 | H15: 3.84 | I15: 2.75 | J15: 1.07 | K15: 258.91 | L15: 27.04 | M15: 88.25 | N15: 2.3 | O15: 0 | P15: 0.27 | Q15: 4.64
A16: 45475.083 | B16: 9.32 | C16: 4.03 | D16: 14.03 | E16: 9.55 | F16: 6.97 | G16: 15.06 | H16: 3.84 | I16: 2.85 | J16: 0.92 | K16: 259.28 | L16: 26.77 | M16: 89.41 | N16: 2.6 | O16: 0 | P16: 0.27 | Q16: 4.65
A17: 45475.094 | B17: 9.3 | C17: 4.07 | D17: 14.04 | E17: 6.61 | F17: 5.72 | G17: 15.06 | H17: 3.84 | I17: 2.9 | J17: 0.96 | K17: 259.95 | L17: 26.56 | M17: 86.55 | N17: 2.6 | O17: 0 | P17: 0.28 | Q17: 4.64
A18: 45475.104 | B18: 9.3 | C18: 4.09 | D18: 14.04 | E18: 7.29 | F18: 5.9 | G18: 14.51 | H18: 3.4 | I18: 2.84 | J18: 1.12 | K18: 256.17 | L18: 26.33 | M18: 82.81 | N18: 2.5 | O18: 0 | P18: 0.28 | Q18: 4.66
A19: 45475.115 | B19: 9.29 | C19: 4.09 | D19: 14.04 | E19: 7.65 | F19: 5.68 | G19: 13.68 | H19: 3.01 | I19: 2.87 | J19: 1.06 | K19: 262.99 | L19: 26.07 | M19: 80.64 | N19: 2.7 | O19: 0 | P19: 0.28 | Q19: 4.65
A20: 45475.125 | B20: 9.3 | C20: 4.06 | D20: 14.03 | E20: 7.31 | F20: 5.47 | G20: 13.68 | H20: 3.01 | I20: 2.89 | J20: 1.38 | K20: 260.75 | L20: 25.92 | M20: 80.59 | N20: 2.5 | O20: 0 | P20: 0.26 | Q20: 4.63
... A53: 45475.469 | B53: 9.41 | C53: 4.08 | D53: 14.13 | E53: 5.66 | F53: 16.56 | G53: 13.91 | H53: 5.28 | I53: 2.73 | J53: 1.31 | K53: 272.1 | L53: 30.09 | M53: 72.78 | N53: 328.7 | O53: 0 | P53: 0.27 | Q53: 4.6
A54: 45475.479 | B54: 9.4 | C54: 4.08 | D54: 14.12 | E54: 5.91 | F54: 16.12 | G54: Calib. | H54: Calib. | I54: 2.4 | J54: 1.35 | K54: 267.36 | L54: 29.98 | M54: 72.86 | N54: 294.9 | O54: 0 | P54: 0.26 | Q54: 4.62
A55: 45475.49 | B55: 9.42 | C55: 4.07 | D55: 14.13 | E55: 5.85 | F55: 16.64 | G55: Calib. | H55: Calib. | I55: 2.22 | J55: 1.26 | K55: 264.12 | L55: 30.17 | M55: 74.2 | N55: 392.4 | O55: 0 | P55: 0.25 | Q55: 4.65
A56: 45475.5 | B56: 9.43 | C56: 4.08 | D56: 14.14 | E56: 5.54 | F56: 15.09 | G56: Calib. | H56: Calib. | I56: 2.12 | J56: 1.23 | K56: 264.8 | L56: 31.08 | M56: 71.14 | N56: 772.6 | O56: 0 | P56: 0.26 | Q56: 4.65
A57: 45475.51 | B57: 9.43 | C57: 4.09 | D57: 14.15 | E57: 5.81 | F57: 17.14 | G57: Calib. | H57: Calib. | I57: 2.04 | J57: 1.29 | K57: 278.56 | L57: 31.22 | M57: 70.08 | N57: 413 | O57: 0 | P57: 0.25 | Q57: 4.63
A58: 45475.521 | B58: 9.43 | C58: 4.11 | D58: 14.16 | E58: 5.66 | F58: 17.36 | G58: Calib. | H58: Calib. | I58: 1.97 | J58: 1.06 | K58: 268.71 | L58: 30.81 | M58: 69.13 | N58: 260.2 | O58: 0 | P58: 0.27 | Q58: 4.64
A59: 45475.531 | B59: 9.44 | C59: 4.08 | D59: 14.15 | E59: 5.79 | F59: 15.42 | G59: Calib. | H59: Calib. | I59: 1.96 | J59: 1.19 | K59: 264.88 | L59: 30.48 | M59: 72.23 | N59: 311.3 | O59: 0 | P59: 0.34 | Q59: 4.64
A60: 45475.542 | B60: 9.43 | C60: 4.09 | D60: 14.15 | E60: 5.42 | F60: 17.39 | G60: Calib. | H60: Calib. | I60: 2.01 | J60: 0.97 | K60: 271.13 | L60: 30.71 | M60: 71.59 | N60: 291.4 | O60: 0 | P60: 0.32 | Q60: 4.64
A61: 45475.552 | B61: 9.4 | C61: 4.12 | D61: 14.14 | E61: 5.3 | F61: 16.75 | G61: Calib. | H61: Calib. | I61: 2.4 | J61: 0.89 | K61: 256.56 | L61: 30.36 | M61: 69.43 | N61: 148 | O61: 0 | P61: 0.31 | Q61: 4.65
A62: 45475.562 | B62: 9.36 | C62: 4.08 | D62: 14.09 | E62: 5.67 | F62: 16.46 | G62: Calib. | H62: Calib. | I62: 2.4 | J62: 0.75 | K62: 258.33 | L62: 30.46 | M62: 69.37 | N62: 237.2 | O62: 0 | P62: 0.31 | Q62: 4.62
A63: 45475.573 | B63: 9.34 | C63: 4.05 | D63: 14.05 | E63: 5.31 | F63: 17.1 | G63: 14.58 | H63: Calib. | I63: 2.4 | J63: 0.85 | K63: 265.36 | L63: 30.66 | M63: 68.41 | N63: 277.7 | O63: 0 | P63: 0.28 | Q63: 4.63
A64: 45475.583 | B64: 9.35 | C64: 4.06 | D64: 14.07 | E64: 5.64 | F64: 21.65 | G64: 25.73 | H64: Calib. | I64: 2.27 | J64: 1.24 | K64: 263.96 | L64: 30.78 | M64: 66.42 | N64: 298.3 | O64: 0 | P64: 0.22 | Q64: 4.65
A65: 45475.594 | B65: 9.46 | C65: 4.07 | D65: 14.16 | E65: 5.87 | F65: 20.68 | G65: 25.73 | H65: Calib. | I65: 2.17 | J65: 0.99 | K65: 282.69 | L65: 30.88 | M65: 66.4 | N65: 185.6 | O65: 0 | P65: 0.23 | Q65: 4.66
A66: 45475.604 | B66: 9.48 | C66: 4.08 | D66: 14.18 | E66: 6.52 | F66: 17.25 | G66: 25.73 | H66: Calib. | I66: 2 | J66: 1.26 | K66: 264.5 | L66: 30.37 | M66: 67.03 | N66: 165.6 | O66: 0 | P66: 0.22 | Q66: 4.66
A67: 45475.615 | B67: 9.47 | C67: 4.07 | D67: 14.17 | E67: 6.94 | F67: 15.36 | G67: 26.51 | H67: Calib. | I67: 2.24 | J67: 0.96 | K67: 264.98 | L67: 30.11 | M67: 69.69 | N67: 113.6 | O67: 0 | P67: 0.21 | Q67: 4.65
A68: 45475.625 | B68: 9.45 | C68: 4.08 | D68: 14.16 | E68: 6.61 | F68: 9.1 | G68: 27.11 | H68: Calib. | I68: 2.07 | J68: 0.61 | K68: 254.15 | L68: 30.15 | M68: 70.3 | N68: 118.9 | O68: 0 | P68: 0.22 | Q68: 4.64
A69: 45475.635 | B69: 9.43 | C69: 4.1 | D69: 14.15 | E69: 6.71 | F69: 7.28 | G69: 27.11 | H69: Calib. | I69: 2.12 | J69: 1.1 | K69: 269.57 | L69: 30.1 | M69: 71.05 | N69: 130.6 | O69: 0 | P69: 0.24 | Q69: 4.62
A70: 45475.646 | B70: 9.42 | C70: 4.08 | D70: 14.13 | E70: 7.24 | F70: 6.88 | G70: 27.11 | H70: Calib. | I70: 2.19 | J70: 0.59 | K70: 260.18 | L70: 30.06 | M70: 73.47 | N70: 80.5 | O70: 0 | P70: 0.23 | Q70: 4.65
A71: 45475.656 | B71: 9.41 | C71: 4.06 | D71: 14.12 | E71: 7.76 | F71: 5.06 | G71: 26.2 | H71: 0.21 | I71: 2.32 | J71: 0.79 | K71: 258.26 | L71: 30.03 | M71: 72.58 | N71: 123.1 | O71: 0 | P71: 0.24 | Q71: 4.63
A72: 45475.667 | B72: 9.4 | C72: 4.05 | D72: 14.1 | E72: 7.86 | F72: 7.02 | G72: 25.51 | H72: 0.28 | I72: 2.37 | J72: 0.51 | K72: 265.97 | L72: 30.32 | M72: 73.99 | N72: 131.3 | O72: 0 | P72: 0.23 | Q72: 4.66
A73: 45475.677 | B73: 9.39 | C73: 4.06 | D73: 14.1 | E73: 7.99 | F73: 5.58 | G73: 25.51 | H73: 0.28 | I73: 2.57 | J73: 0.48 | K73: 251.02 | L73: 30.16 | M73: 75.82 | N73: 126.6 | O73: 0 | P73: 0.25 | Q73: 4.66
A74: 45475.688 | B74: 9.39 | C74: 4.09 | D74: 14.11 | E74: 8.26 | F74: 5.85 | G74: 25.51 | H74: 0.28 | I74: 2.47 | J74: 0.59 | K74: 259.31 | L74: 30.22 | M74: 74.77 | N74: 86.5 | O74: 0 | P74: 0.23 | Q74: 4.64
...

Sheet 03
A1: Station: | B1: IGKV RAIPUR
A2: Date: | B2: =$A$9 -> 45476.01 | C2: Power Off | G2: Pw.Off | J2: Link Fail | L2: Link F | N2: Maintenance | P2: Maint.
A3: Report Type: | B3: Mean | C3: Calibration | G3: Calib. | J3: Data Fail | L3: Data F | N3: Invalid | P3: Invalid
A4: Time Base: | B4: 15 Min | C4: Zero Referrence | G4: Z.Ref | J4: Warm Up | L4: Wm. Up
A7: Date & Time | B7: NO | C7: NO2 | D7: NOX | E7: SO2 | F7: O3 | G7: PM 10 | H7: PM 2.5 | I7: BENZ | J7: WS | K7: WD | L7: TEMP | M7: HUM | N7: SR | O7: RG | P7: CO | Q7: NH3
B8: ug/m3 | C8: ug/m3 | D8: ppb | E8: ug/m3 | F8: ug/m3 | G8: ug/m3 | H8: ug/m3 | I8: ug/m3 | J8: m/sec | K8: deg | L8: degreC | M8: % | N8: w/m2 | O8: mm | P8: mg/m3 | Q8: ug/m3
A9: 45476.01 | B9: 9.2 | C9: 4.03 | D9: 13.93 | E9: 8 | F9: 4.19 | G9: 14.69 | H9: 4.78 | I9: 4.3 | J9: 1.21 | K9: 265.86 | L9: 26.33 | M9: 89.83 | N9: 2.5 | O9: 0 | P9: 0.37 | Q9: 4.66
A10: 45476.021 | B10: 9.21 | C10: 4.06 | D10: 13.96 | E10: 8.35 | F10: 4.11 | G10: 14.69 | H10: 4.78 | I10: 4.28 | J10: 0.97 | K10: 263.78 | L10: 26.16 | M10: 89.11 | N10: 2.5 | O10: 0 | P10: 0.36 | Q10: 4.65
A11: 45476.031 | B11: 9.21 | C11: 4.09 | D11: 13.97 | E11: 8.27 | F11: 3.99 | G11: 13.88 | H11: 4.2 | I11: 4.18 | J11: 0.69 | K11: 261.76 | L11: 25.95 | M11: 91.44 | N11: 2.4 | O11: 0 | P11: 0.36 | Q11: 4.65
A12: 45476.042 | B12: 9.22 | C12: 4.09 | D12: 13.98 | E12: 8.11 | F12: 3.89 | G12: 13.27 | H12: 3.82 | I12: 4.08 | J12: 1.04 | K12: 268.46 | L12: 25.79 | M12: 91.68 | N12: 2.4 | O12: 0 | P12: 0.34 | Q12: 4.67
A13: 45476.052 | B13: 9.24 | C13: 4.06 | D13: 13.98 | E13: 8.32 | F13: 4.26 | G13: 13.27 | H13: 3.82 | I13: 3.99 | J13: 0.87 | K13: 262 | L13: 25.68 | M13: 93.91 | N13: 2.3 | O13: 0 | P13: 0.34 | Q13: 4.66
A14: 45476.062 | B14: 9.22 | C14: 4.07 | D14: 13.97 | E14: 8.2 | F14: 4.13 | G14: 13.27 | H14: 3.82 | I14: 3.93 | J14: 0.79 | K14: 264.38 | L14: 25.65 | M14: 92.79 | N14: 2.2 | O14: 0 | P14: 0.33 | Q14: 4.67
A15: 45476.073 | B15: 9.23 | C15: 4.05 | D15: 13.96 | E15: 8.54 | F15: 3.86 | G15: 11.2 | H15: 3.13 | I15: 3.85 | J15: 0.97 | K15: 263.87 | L15: 25.59 | M15: 93.91 | N15: 2.3 | O15: 0 | P15: 0.32 | Q15: 4.64
A16: 45476.083 | B16: 9.22 | C16: 4.07 | D16: 13.97 | E16: 8.08 | F16: 3.74 | G16: 9.55 | H16: 2.9 | I16: 3.78 | J16: 0.82 | K16: 262.44 | L16: 25.6 | M16: 92.92 | N16: 2.2 | O16: 0 | P16: 0.33 | Q16: 4.65
A17: 45476.094 | B17: 9.23 | C17: 4.12 | D17: 14 | E17: 7.3 | F17: 4.15 | G17: 9.55 | H17: 2.9 | I17: 3.75 | J17: 0.85 | K17: 271.39 | L17: 25.58 | M17: 92.52 | N17: 2.2 | O17: 0 | P17: 0.31 | Q17: 4.66
A18: 45476.104 | B18: 9.25 | C18: 4.09 | D18: 14 | E18: 8.84 | F18: 3.65 | G18: 9.55 | H18: 2.9 | I18: 3.65 | J18: 0.81 | K18: 262.49 | L18: 25.61 | M18: 91.76 | N18: 2.1 | O18: 0 | P18: 0.31 | Q18: 4.63
A19: 45476.115 | B19: 9.22 | C19: 4.09 | D19: 13.98 | E19: 9.24 | F19: 3.7 | G19: 9.28 | H19: 2.48 | I19: 3.58 | J19: 0.97 | K19: 271.2 | L19: 25.6 | M19: 91.65 | N19: 2.2 | O19: 0 | P19: 0.3 | Q19: 4.63
A20: 45476.125 | B20: 9.22 | C20: 4.06 | D20: 13.96 | E20: 8.98 | F20: 3.35 | G20: 9.06 | H20: 2.33 | I20: 3.47 | J20: 0.99 | K20: 271 | L20: 25.58 | M20: 92.68 | N20: 2.2 | O20: 0 | P20: 0.3 | Q20: 4.66
... A104: 45477 | B104: 9.04 | C104: 4.13 | D104: 13.86 | E104: 11.9 | F104: 7.34 | G104: 16.98 | H104: 5.5 | I104: 3.37 | J104: 0.19 | K104: 243.02 | L104: 26.93 | M104: 85.69 | N104: 2.1 | O104: 0 | P104: 0.3 | Q104: 4.62
A106: Min | B106: =MIN(B9:B104) -> 9.04 | C106: =MIN(C9:C104) -> 4.02 | D106: =MIN(D9:D104) -> 13.84 | E106: =MIN(E9:E104) -> 6.05 | F106: =MIN(F9:F104) -> 3.19 | G106: =MIN(G9:G104) -> 6.71 | H106: =MIN(H9:H104) -> 1.9 | I106: =MIN(I9:I104) -> 2.91 | ... Q106: =MIN(Q9:Q104) -> 4.62
A107: Max | B107: =MAX(B9:B104) -> 9.25 | C107: =MAX(C9:C104) -> 4.13 | D107: =MAX(D9:D104) -> 14 | E107: =MAX(E9:E104) -> 13.65 | F107: =MAX(F9:F104) -> 16.04 | G107: =MAX(G9:G104) -> 33.88 | H107: =MAX(H9:H104) -> 13.01 | I107: =MAX(I9:I104) -> 5.2 | ... Q107: =MAX(Q9:Q104) -> 4.67
A108: Avg | B108: =AVERAGE(B9:B104) -> 9.1577083 | C108: =AVERAGE(C9:C104) -> 4.0645833 | D108: =AVERAGE(D9:D104) -> 13.916458 | E108: =AVERAGE(E9:E104) -> 9.0827083 | F108: =AVERAGE(F9:F104) -> 6.0028125 | G108: =AVERAGE(G9:G104) -> 17.731562 | H108: =AVERAGE(H9:H104) -> 6.6530208 | I108: =AVERAGE(I9:I104) -> 3.7551042 | ... Q108: =AVERAGE(Q9:Q104) -> 4.6410417
A109: Stdev | B109: =STDEV(B9:B104) -> 0.05493497 | C109: =STDEV(C9:C104) -> 0.021904898 | D109: =STDEV(D9:D104) -> 0.045421515 | E109: =STDEV(E9:E104) -> 1.9939791 | F109: =STDEV(F9:F104) -> 2.4041853 | G109: =STDEV(G9:G104) -> 8.0575426 | H109: =STDEV(H9:H104) -> 3.6660121 | I109: =STDEV(I9:I104) -> 0.67685961 | ... Q109: =STDEV(Q9:Q104) -> 0.013177266
A110: Num | B110: =COUNT(B9:B104) -> 96 | C110: =COUNT(C9:C104) -> 96 | D110: =COUNT(D9:D104) -> 96 | E110: =COUNT(E9:E104) -> 96 | F110: =COUNT(F9:F104) -> 96 | G110: =COUNT(G9:G104) -> 96 | H110: =COUNT(H9:H104) -> 96 | I110: =COUNT(I9:I104) -> 96 | ... Q110: =COUNT(Q9:Q104) -> 96
A111: DCR | B111: =IF(B110>=87,">90%",IF(B110<=87,"<90%")) -> >90% | C111: =IF(C110>=87,">90%",IF(C110<=87,"<90%")) -> >90% | D111: =IF(D110>=87,">90%",IF(D110<=87,"<90%")) -> >90% | E111: =IF(E110>=87,">90%",IF(E110<=87,"<90%")) -> >90% | F111: =IF(F110>=87,">90%",IF(F110<=87,"<90%")) -> >90% | G111: =IF(G110>=87,">90%",IF(G110<=87,"<90%")) -> >90% | H111: =IF(H110>=87,">90%",IF(H110<=87,"<90%")) -> >90% | I111: =IF(I110>=87,">90%",IF(I110<=87,"<90%")) -> >90% | ... Q111: =IF(Q110>=87,">90%",IF(Q110<=87,"<90%")) -> >90%
A112: Status | B112: =IF(B110>=87,"OK",IF(B110<=87,"LESS")) -> OK | C112: =IF(C110>=87,"OK",IF(C110<=87,"LESS")) -> OK | D112: =IF(D110>=87,"OK",IF(D110<=87,"LESS")) -> OK | E112: =IF(E110>=87,"OK",IF(E110<=87,"LESS")) -> OK | F112: =IF(F110>=87,"OK",IF(F110<=87,"LESS")) -> OK | G112: =IF(G110>=87,"OK",IF(G110<=87,"LESS")) -> OK | H112: =IF(H110>=87,"OK",IF(H110<=87,"LESS")) -> OK | I112: =IF(I110>=87,"OK",IF(I110<=87,"LESS")) -> OK | ... Q112: =IF(Q110>=87,"OK",IF(Q110<=87,"LESS")) -> OK
A115: Done by | B115: AKASH
A117: Comment

Sheet 04
A1: Station: | B1: IGKV RAIPUR
A2: Date: | B2: =$A$9 -> 45477.01 | C2: Power Off | G2: Pw.Off | J2: Link Fail | L2: Link F | N2: Maintenance | P2: Maint.
A3: Report Type: | B3: Mean | C3: Calibration | G3: Calib. | J3: Data Fail | L3: Data F | N3: Invalid | P3: Invalid
A4: Time Base: | B4: 15 Min | C4: Zero Referrence | G4: Z.Ref | J4: Warm Up | L4: Wm. Up
A7: Date & Time | B7: NO | C7: NO2 | D7: NOX | E7: SO2 | F7: O3 | G7: PM 10 | H7: PM 2.5 | I7: BENZ | J7: WS | K7: WD | L7: TEMP | M7: HUM | N7: SR | O7: RG | P7: CO | Q7: NH3
B8: ug/m3 | C8: ug/m3 | D8: ppb | E8: ug/m3 | F8: ug/m3 | G8: ug/m3 | H8: ug/m3 | I8: ug/m3 | J8: m/sec | K8: deg | L8: degreC | M8: % | N8: w/m2 | O8: mm | P8: mg/m3 | Q8: ug/m3
A9: 45477.01 | B9: 9.26 | C9: 4.08 | D9: 14.01 | E9: 11.82 | F9: 6.8 | G9: 16.98 | H9: 5.5 | I9: 3.33 | J9: 0.19 | K9: 229.55 | L9: 26.84 | M9: 84.95 | N9: 2.1 | O9: 0 | P9: 0.3 | Q9: 4.63
A10: 45477.021 | B10: 9.27 | C10: 4.05 | D10: 14 | E10: 11.58 | F10: 6.87 | G10: 16.98 | H10: 5.5 | I10: 3.41 | J10: 0.15 | K10: 218.8 | L10: 26.77 | M10: 84.71 | N10: 2.1 | O10: 0 | P10: 0.3 | Q10: 4.63
A11: 45477.031 | B11: 9.26 | C11: 4.1 | D11: 14.02 | E11: 10.75 | F11: 9.63 | G11: 15.19 | H11: 5.99 | I11: 3.41 | J11: 0.15 | K11: 244.39 | L11: 26.7 | M11: 85.62 | N11: 2.1 | O11: 0 | P11: 0.29 | Q11: 4.63
A12: 45477.042 | B12: 9.28 | C12: 4.09 | D12: 14.02 | E12: 11 | F12: 8.57 | G12: 13.81 | H12: 6.29 | I12: 3.41 | J12: 0.09 | K12: 219.98 | L12: 26.68 | M12: 86.22 | N12: 2.1 | O12: 0 | P12: 0.28 | Q12: 4.63
A13: 45477.052 | B13: 9.28 | C13: 4.07 | D13: 14.02 | E13: 10.64 | F13: 8.23 | G13: 13.81 | H13: 6.29 | I13: 3.17 | J13: 0.09 | K13: 252.03 | L13: 26.66 | M13: 86.29 | N13: 2.1 | O13: 0 | P13: 0.28 | Q13: 4.63
A14: 45477.062 | B14: 9.29 | C14: 4.06 | D14: 14.02 | E14: 11.3 | F14: 6.71 | G14: 13.81 | H14: 6.29 | I14: 3.11 | J14: 0.81 | K14: 306.26 | L14: 26.78 | M14: 84.66 | N14: 1.9 | O14: 0 | P14: 0.29 | Q14: 4.63
A15: 45477.073 | B15: 9.29 | C15: 4.06 | D15: 14.03 | E15: 11.4 | F15: 6.81 | G15: 14.6 | H15: 5.02 | I15: 3.04 | J15: 0.67 | K15: 282.24 | L15: 26.91 | M15: 83.02 | N15: 2.1 | O15: 0 | P15: 0.28 | Q15: 4.65
A16: 45477.083 | B16: 9.29 | C16: 4.08 | D16: 14.03 | E16: 11.11 | F16: 6.35 | G16: 15.2 | H16: 4.57 | I16: 3.22 | J16: 0.49 | K16: 265.59 | L16: 26.81 | M16: 84.3 | N16: 2.2 | O16: 0 | P16: 0.28 | Q16: 4.64
A17: 45477.094 | B17: 9.29 | C17: 4.08 | D17: 14.03 | E17: 8.64 | F17: 6.39 | G17: 15.2 | H17: 4.57 | I17: 3.16 | J17: 0.71 | K17: 296.62 | L17: 26.75 | M17: 85.19 | N17: 2.3 | O17: 0 | P17: 0.28 | Q17: 4.65
A18: 45477.104 | B18: 9.29 | C18: 4.07 | D18: 14.03 | E18: 9.89 | F18: 6.25 | G18: 15.2 | H18: 4.57 | I18: 3.14 | J18: 0.49 | K18: 322.34 | L18: 26.63 | M18: 87.44 | N18: 1.6 | O18: 0 | P18: 0.29 | Q18: 4.64
A19: 45477.115 | B19: 9.29 | C19: 4.09 | D19: 14.04 | E19: 10.2 | F19: 7.18 | G19: 15.15 | H19: 5.04 | I19: 3.17 | J19: 0.74 | K19: 321.77 | L19: 26.53 | M19: 87.51 | N19: 2.4 | O19: 0 | P19: 0.29 | Q19: 4.63
A20: 45477.125 | B20: 9.3 | C20: 4.1 | D20: 14.05 | E20: 10.39 | F20: 6.56 | G20: 15.11 | H20: 5.2 | I20: 3.08 | J20: 1.47 | K20: 320.54 | L20: 26.03 | M20: 90.85 | N20: 3.1 | O20: 0 | P20: 0.28 | Q20: 4.63
... A104: 45478 | B104: 9.43 | C104: 4.09 | D104: 14.15 | E104: 9.16 | F104: 6.16 | G104: 13.92 | H104: 7.49 | I104: 2.97 | J104: 0.2 | K104: 240.23 | L104: 26.63 | M104: 89.6 | N104: 2.1 | O104: 0 | P104: 0.3 | Q104: 4.63
A106: Min | B106: =MIN(B9:B104) -> 9.26 | C106: =MIN(C9:C104) -> 4.04 | D106: =MIN(D9:D104) -> 13.99 | E106: =MIN(E9:E104) -> 7 | F106: =MIN(F9:F104) -> 3.47 | G106: =MIN(G9:G104) -> 5.57 | H106: =MIN(H9:H104) -> 2.08 | I106: =MIN(I9:I104) -> 2.64 | ... Q106: =MIN(Q9:Q104) -> 4.6
A107: Max | B107: =MAX(B9:B104) -> 9.43 | C107: =MAX(C9:C104) -> 4.12 | D107: =MAX(D9:D104) -> 14.16 | E107: =MAX(E9:E104) -> 12.44 | F107: =MAX(F9:F104) -> 15 | G107: =MAX(G9:G104) -> 19.39 | H107: =MAX(H9:H104) -> 9.08 | I107: =MAX(I9:I104) -> 3.42 | ... Q107: =MAX(Q9:Q104) -> 4.66
A108: Avg | B108: =AVERAGE(B9:B104) -> 9.3610417 | C108: =AVERAGE(C9:C104) -> 4.0742708 | D108: =AVERAGE(D9:D104) -> 14.085937 | E108: =AVERAGE(E9:E104) -> 9.6691667 | F108: =AVERAGE(F9:F104) -> 6.3870833 | G108: =AVERAGE(G9:G104) -> 13.000104 | H108: =AVERAGE(H9:H104) -> 5.0514583 | I108: =AVERAGE(I9:I104) -> 3.1295833 | ... Q108: =AVERAGE(Q9:Q104) -> 4.6364583
A109: Stdev | B109: =STDEV(B9:B104) -> 0.045939988 | C109: =STDEV(C9:C104) -> 0.017516596 | D109: =STDEV(D9:D104) -> 0.039458923 | E109: =STDEV(E9:E104) -> 1.5048061 | F109: =STDEV(F9:F104) -> 2.3660257 | G109: =STDEV(G9:G104) -> 3.5229364 | H109: =STDEV(H9:H104) -> 1.9231838 | I109: =STDEV(I9:I104) -> 0.17483777 | ... Q109: =STDEV(Q9:Q104) -> 0.011605731
A110: Num | B110: =COUNT(B9:B104) -> 96 | C110: =COUNT(C9:C104) -> 96 | D110: =COUNT(D9:D104) -> 96 | E110: =COUNT(E9:E104) -> 96 | F110: =COUNT(F9:F104) -> 96 | G110: =COUNT(G9:G104) -> 96 | H110: =COUNT(H9:H104) -> 96 | I110: =COUNT(I9:I104) -> 96 | ... Q110: =COUNT(Q9:Q104) -> 96
A111: DCR | B111: =IF(B110>=87,">90%",IF(B110<=87,"<90%")) -> >90% | C111: =IF(C110>=87,">90%",IF(C110<=87,"<90%")) -> >90% | D111: =IF(D110>=87,">90%",IF(D110<=87,"<90%")) -> >90% | E111: =IF(E110>=87,">90%",IF(E110<=87,"<90%")) -> >90% | F111: =IF(F110>=87,">90%",IF(F110<=87,"<90%")) -> >90% | G111: =IF(G110>=87,">90%",IF(G110<=87,"<90%")) -> >90% | H111: =IF(H110>=87,">90%",IF(H110<=87,"<90%")) -> >90% | I111: =IF(I110>=87,">90%",IF(I110<=87,"<90%")) -> >90% | ... Q111: =IF(Q110>=87,">90%",IF(Q110<=87,"<90%")) -> >90%
A112: Status | B112: =IF(B110>=87,"OK",IF(B110<=87,"LESS")) -> OK | C112: =IF(C110>=87,"OK",IF(C110<=87,"LESS")) -> OK | D112: =IF(D110>=87,"OK",IF(D110<=87,"LESS")) -> OK | E112: =IF(E110>=87,"OK",IF(E110<=87,"LESS")) -> OK | F112: =IF(F110>=87,"OK",IF(F110<=87,"LESS")) -> OK | G112: =IF(G110>=87,"OK",IF(G110<=87,"LESS")) -> OK | H112: =IF(H110>=87,"OK",IF(H110<=87,"LESS")) -> OK | I112: =IF(I110>=87,"OK",IF(I110<=87,"LESS")) -> OK | ... Q112: =IF(Q110>=87,"OK",IF(Q110<=87,"LESS")) -> OK
A115: Done by | B115: AKASH
A117: Comment

Sheet 05
A1: Station: | B1: IGKV RAIPUR
A2: Date: | B2: =$A$9 -> 45478.01 | C2: Power Off | G2: Pw.Off | J2: Link Fail | L2: Link F | N2: Maintenance | P2: Maint.
A3: Report Type: | B3: Mean | C3: Calibration | G3: Calib. | J3: Data Fail | L3: Data F | N3: Invalid | P3: Invalid
A4: Time Base: | B4: 15 Min | C4: Zero Referrence | G4: Z.Ref | J4: Warm Up | L4: Wm. Up
A7: Date & Time | B7: NO | C7: NO2 | D7: NOX | E7: SO2 | F7: O3 | G7: PM 10 | H7: PM 2.5 | I7: BENZ | J7: WS | K7: WD | L7: TEMP | M7: HUM | N7: SR | O7: RG | P7: CO | Q7: NH3
B8: ug/m3 | C8: ug/m3 | D8: ppb | E8: ug/m3 | F8: ug/m3 | G8: ug/m3 | H8: ug/m3 | I8: ug/m3 | J8: m/sec | K8: deg | L8: degreC | M8: % | N8: w/m2 | O8: mm | P8: mg/m3 | Q8: ug/m3
A9: 45478.01 | B9: 9.18 | C9: 4.1 | D9: 13.96 | E9: 9 | F9: 5.42 | G9: 13.92 | H9: 7.49 | I9: 2.87 | J9: 0.23 | K9: 248.91 | L9: 26.45 | M9: 90.16 | N9: 2.1 | O9: 0 | P9: 0.3 | Q9: 4.63
A10: 45478.021 | B10: 9.2 | C10: 4.07 | D10: 13.95 | E10: 9.3 | F10: 4.8 | G10: 13.92 | H10: 7.49 | I10: 2.92 | J10: 0.24 | K10: 240.57 | L10: 26.51 | M10: 89.33 | N10: 2.1 | O10: 0 | P10: 0.3 | Q10: 4.64
A11: 45478.031 | B11: 9.19 | C11: 4.08 | D11: 13.95 | E11: 9.41 | F11: 6.04 | G11: 13.16 | H11: 7.56 | I11: 2.89 | J11: 0.26 | K11: 245.97 | L11: 26.43 | M11: 88.53 | N11: 2.1 | O11: 0 | P11: 0.31 | Q11: 4.66
A12: 45478.042 | B12: 9.19 | C12: 4.08 | D12: 13.95 | E12: 9.89 | F12: 4.49 | G12: 12.57 | H12: 7.61 | I12: 2.87 | J12: 0.31 | K12: 248.7 | L12: 26.48 | M12: 88.78 | N12: 2.1 | O12: 0 | P12: 0.3 | Q12: 4.65
A13: 45478.052 | B13: 9.21 | C13: 4.07 | D13: 13.96 | E13: 9.63 | F13: 4.51 | G13: 12.57 | H13: 7.61 | I13: 2.83 | J13: 0.31 | K13: 252.18 | L13: 26.42 | M13: 88.79 | N13: 2.1 | O13: 0 | P13: 0.3 | Q13: 4.64
A14: 45478.062 | B14: 9.21 | C14: 4.07 | D14: 13.96 | E14: 9.8 | F14: 4.44 | G14: 12.57 | H14: 7.61 | I14: 2.86 | J14: 0.15 | K14: 222.58 | L14: 26.43 | M14: 89.1 | N14: 2.1 | O14: 0 | P14: 0.3 | Q14: 4.65
A15: 45478.073 | B15: 9.21 | C15: 4.06 | D15: 13.95 | E15: 9.6 | F15: 5.03 | G15: 10.57 | H15: 5.99 | I15: 2.84 | J15: 0.19 | K15: 228.33 | L15: 26.28 | M15: 90.71 | N15: 2.1 | O15: 0 | P15: 0.3 | Q15: 4.64
A16: 45478.083 | B16: 9.2 | C16: 4.09 | D16: 13.97 | E16: 9.95 | F16: 4.15 | G16: 9.03 | H16: 5.43 | I16: 2.82 | J16: 0.14 | K16: 211.31 | L16: 26.14 | M16: 91.87 | N16: 2.1 | O16: 0 | P16: 0.3 | Q16: 4.66
A17: 45478.094 | B17: 9.21 | C17: 4.08 | D17: 13.97 | E17: 9.09 | F17: 3.84 | G17: 9.03 | H17: 5.43 | I17: 2.78 | J17: 0.13 | K17: 218.98 | L17: 26.05 | M17: 91.32 | N17: 2.1 | O17: 0 | P17: 0.3 | Q17: 4.66
A18: 45478.104 | B18: 9.2 | C18: 4.08 | D18: 13.96 | E18: 10.59 | F18: 3.83 | G18: 9.03 | H18: 5.43 | I18: 2.8 | J18: 0.15 | K18: 227.63 | L18: 26.07 | M18: 91.62 | N18: 2.1 | O18: 0 | P18: 0.3 | Q18: 4.63
A19: 45478.115 | B19: 9.21 | C19: 4.04 | D19: 13.95 | E19: 10.71 | F19: 4.09 | G19: 8.55 | H19: 4.25 | I19: 2.77 | J19: 0.14 | K19: 223.46 | L19: 25.9 | M19: 93.48 | N19: 2.1 | O19: 0 | P19: 0.31 | Q19: 4.63
A20: 45478.125 | B20: 9.2 | C20: 4.07 | D20: 13.95 | E20: 10.85 | F20: 3.81 | G20: 8.18 | H20: 3.84 | I20: 2.77 | J20: 0.28 | K20: 255.44 | L20: 25.94 | M20: 92.17 | N20: 2.1 | O20: 0 | P20: 0.3 | Q20: 4.64
... A104: 45479 | B104: 9.18 | C104: 4.06 | D104: 13.93 | E104: 9.07 | F104: 5.44 | G104: 14.9 | H104: 4.83 | I104: 3.33 | J104: 0.58 | K104: 267.6 | L104: 27.04 | M104: 84.49 | N104: 2.1 | O104: 0 | P104: 0.31 | Q104: 4.62
A106: Min | B106: =MIN(B9:B104) -> 9.12 | C106: =MIN(C9:C104) -> 4.02 | D106: =MIN(D9:D104) -> 13.89 | E106: =MIN(E9:E104) -> 7.01 | F106: =MIN(F9:F104) -> 3.15 | G106: =MIN(G9:G104) -> 8.18 | H106: =MIN(H9:H104) -> 2.45 | I106: =MIN(I9:I104) -> 2.64 | ... Q106: =MIN(Q9:Q104) -> 4.61
A107: Max | B107: =MAX(B9:B104) -> 9.21 | C107: =MAX(C9:C104) -> 4.1 | D107: =MAX(D9:D104) -> 13.97 | E107: =MAX(E9:E104) -> 11.66 | F107: =MAX(F9:F104) -> 17.07 | G107: =MAX(G9:G104) -> 23.88 | H107: =MAX(H9:H104) -> 11.93 | I107: =MAX(I9:I104) -> 4.28 | ... Q107: =MAX(Q9:Q104) -> 4.66
A108: Avg | B108: =AVERAGE(B9:B104) -> 9.1665625 | C108: =AVERAGE(C9:C104) -> 4.0655208 | D108: =AVERAGE(D9:D104) -> 13.924479 | E108: =AVERAGE(E9:E104) -> 9.353125 | F108: =AVERAGE(F9:F104) -> 7.1175 | G108: =AVERAGE(G9:G104) -> 14.994062 | H108: =AVERAGE(H9:H104) -> 5.8453125 | I108: =AVERAGE(I9:I104) -> 3.1078125 | ... Q108: =AVERAGE(Q9:Q104) -> 4.640625
A109: Stdev | B109: =STDEV(B9:B104) -> 0.023745498 | C109: =STDEV(C9:C104) -> 0.015885763 | D109: =STDEV(D9:D104) -> 0.020202647 | E109: =STDEV(E9:E104) -> 0.96656888 | F109: =STDEV(F9:F104) -> 3.6898972 | G109: =STDEV(G9:G104) -> 5.3136324 | H109: =STDEV(H9:H104) -> 2.8124924 | I109: =STDEV(I9:I104) -> 0.36679035 | ... Q109: =STDEV(Q9:Q104) -> 0.01203613
A110: Num | B110: =COUNT(B9:B104) -> 96 | C110: =COUNT(C9:C104) -> 96 | D110: =COUNT(D9:D104) -> 96 | E110: =COUNT(E9:E104) -> 96 | F110: =COUNT(F9:F104) -> 96 | G110: =COUNT(G9:G104) -> 96 | H110: =COUNT(H9:H104) -> 96 | I110: =COUNT(I9:I104) -> 96 | ... Q110: =COUNT(Q9:Q104) -> 96
A111: DCR | B111: =IF(B110>=87,">90%",IF(B110<=87,"<90%")) -> >90% | C111: =IF(C110>=87,">90%",IF(C110<=87,"<90%")) -> >90% | D111: =IF(D110>=87,">90%",IF(D110<=87,"<90%")) -> >90% | E111: =IF(E110>=87,">90%",IF(E110<=87,"<90%")) -> >90% | F111: =IF(F110>=87,">90%",IF(F110<=87,"<90%")) -> >90% | G111: =IF(G110>=87,">90%",IF(G110<=87,"<90%")) -> >90% | H111: =IF(H110>=87,">90%",IF(H110<=87,"<90%")) -> >90% | I111: =IF(I110>=87,">90%",IF(I110<=87,"<90%")) -> >90% | ... Q111: =IF(Q110>=87,">90%",IF(Q110<=87,"<90%")) -> >90%
A112: Status | B112: =IF(B110>=87,"OK",IF(B110<=87,"LESS")) -> OK | C112: =IF(C110>=87,"OK",IF(C110<=87,"LESS")) -> OK | D112: =IF(D110>=87,"OK",IF(D110<=87,"LESS")) -> OK | E112: =IF(E110>=87,"OK",IF(E110<=87,"LESS")) -> OK | F112: =IF(F110>=87,"OK",IF(F110<=87,"LESS")) -> OK | G112: =IF(G110>=87,"OK",IF(G110<=87,"LESS")) -> OK | H112: =IF(H110>=87,"OK",IF(H110<=87,"LESS")) -> OK | I112: =IF(I110>=87,"OK",IF(I110<=87,"LESS")) -> OK | ... Q112: =IF(Q110>=87,"OK",IF(Q110<=87,"LESS")) -> OK
A115: Done by | B115: AKASH
A117: Comment

Sheet 06
A1: Station: | B1: IGKV RAIPUR
A2: Date: | B2: =$A$9 -> 45479.01 | C2: Power Off | G2: Pw.Off | J2: Link Fail | L2: Link F | N2: Maintenance | P2: Maint.
A3: Report Type: | B3: Mean | C3: Calibration | G3: Calib. | J3: Data Fail | L3: Data F | N3: Invalid | P3: Invalid
A4: Time Base: | B4: 15 Min | C4: Zero Referrence | G4: Z.Ref | J4: Warm Up | L4: Wm. Up
A7: Date & Time | B7: NO | C7: NO2 | D7: NOX | E7: SO2 | F7: O3 | G7: PM 10 | H7: PM 2.5 | I7: BENZ | J7: WS | K7: WD | L7: TEMP | M7: HUM | N7: SR | O7: RG | P7: CO | Q7: NH3
B8: ug/m3 | C8: ug/m3 | D8: ppb | E8: ug/m3 | F8: ug/m3 | G8: ug/m3 | H8: ug/m3 | I8: ug/m3 | J8: m/sec | K8: deg | L8: degreC | M8: % | N8: w/m2 | O8: mm | P8: mg/m3 | Q8: ug/m3
A9: 45479.01 | B9: 9.28 | C9: 4.11 | D9: 14.04 | E9: 8.93 | F9: 4.95 | G9: 14.9 | H9: 4.83 | I9: 3.22 | J9: 0.65 | K9: 267.88 | L9: 27.12 | M9: 83.76 | N9: 2.1 | O9: 0 | P9: 0.32 | Q9: 4.64
A10: 45479.021 | B10: 9.3 | C10: 4.11 | D10: 14.05 | E10: 9.14 | F10: 5.03 | G10: 14.9 | H10: 4.83 | I10: 3.18 | J10: 0.6 | K10: 258.07 | L10: 27.03 | M10: 85.29 | N10: 2.1 | O10: 0 | P10: 0.31 | Q10: 4.64
A11: 45479.031 | B11: 9.31 | C11: 4.08 | D11: 14.05 | E11: 8.39 | F11: 6.51 | G11: 15.67 | H11: 5.21 | I11: 3.22 | J11: 0.37 | K11: 256.68 | L11: 26.97 | M11: 86.29 | N11: 2.4 | O11: 0 | P11: 0.31 | Q11: 4.63
A12: 45479.042 | B12: 9.31 | C12: 4.07 | D12: 14.04 | E12: 8.61 | F12: 6.22 | G12: 16.25 | H12: 5.44 | I12: 3.15 | J12: 0.32 | K12: 260.59 | L12: 26.78 | M12: 88.93 | N12: 2.4 | O12: 0 | P12: 0.31 | Q12: 4.64
A13: 45479.052 | B13: 9.3 | C13: 4.1 | D13: 14.05 | E13: 8.68 | F13: 5.39 | G13: 16.25 | H13: 5.44 | I13: 3.29 | J13: 0.35 | K13: 255.58 | L13: 26.54 | M13: 89.66 | N13: 2.2 | O13: 0 | P13: 0.31 | Q13: 4.62
A14: 45479.062 | B14: 9.32 | C14: 4.08 | D14: 14.06 | E14: 8.4 | F14: 5.64 | G14: 16.25 | H14: 5.44 | I14: 3.21 | J14: 0.23 | K14: 241.76 | L14: 26.41 | M14: 90.74 | N14: 2.1 | O14: 0 | P14: 0.3 | Q14: 4.6
A15: 45479.073 | B15: 9.34 | C15: 4.07 | D15: 14.07 | E15: 8.45 | F15: 6.9 | G15: 14.5 | H15: 4.23 | I15: 3.22 | J15: 0.31 | K15: 248.89 | L15: 26.36 | M15: 90.96 | N15: 2.1 | O15: 0 | P15: 0.3 | Q15: 4.62
A16: 45479.083 | B16: 9.32 | C16: 4.07 | D16: 14.05 | E16: 8.05 | F16: 5.92 | G16: 13.16 | H16: 3.81 | I16: 3.09 | J16: 0.38 | K16: 263.4 | L16: 26.29 | M16: 90.9 | N16: 2.1 | O16: 0 | P16: 0.3 | Q16: 4.62
A17: 45479.094 | B17: 9.32 | C17: 4.06 | D17: 14.05 | E17: 8.51 | F17: 5.88 | G17: 13.16 | H17: 3.81 | I17: 3.12 | J17: 0.38 | K17: 253.95 | L17: 26.24 | M17: 90.83 | N17: 2.1 | O17: 0 | P17: 0.3 | Q17: 4.63
A18: 45479.104 | B18: 9.32 | C18: 4.07 | D18: 14.05 | E18: 10.25 | F18: 5.24 | G18: 13.16 | H18: 3.81 | I18: 3.08 | J18: 0.35 | K18: 259.29 | L18: 26.17 | M18: 89.17 | N18: 2.1 | O18: 0 | P18: 0.3 | Q18: 4.63
A19: 45479.115 | B19: 9.3 | C19: 4.08 | D19: 14.04 | E19: 9.68 | F19: 6.55 | G19: 12.76 | H19: 2.96 | I19: 3.16 | J19: 0.24 | K19: 252.62 | L19: 26.1 | M19: 90.1 | N19: 2.1 | O19: 0 | P19: 0.29 | Q19: 4.63
A20: 45479.125 | B20: 9.31 | C20: 4.05 | D20: 14.03 | E20: 10.39 | F20: 5.53 | G20: 12.46 | H20: 2.67 | I20: 3.18 | J20: 0.42 | K20: 263.34 | L20: 26.15 | M20: 90.61 | N20: 2.1 | O20: 0 | P20: 0.27 | Q20: 4.63
... A104: 45480 | B104: 9.36 | C104: 4.08 | D104: 14.08 | E104: 8.62 | F104: 5.13 | G104: 25.48 | H104: 8.03 | I104: 2.95 | J104: 0.67 | K104: 263.92 | L104: 28.34 | M104: 82.03 | N104: 1.8 | O104: 0 | P104: 0.31 | Q104: 4.64
A106: Min | B106: =MIN(B9:B104) -> 9.28 | C106: =MIN(C9:C104) -> 4.04 | D106: =MIN(D9:D104) -> 14.01 | E106: =MIN(E9:E104) -> 6.2 | F106: =MIN(F9:F104) -> 3.11 | G106: =MIN(G9:G104) -> 5.36 | H106: =MIN(H9:H104) -> 1.4 | I106: =MIN(I9:I104) -> 2.28 | ... Q106: =MIN(Q9:Q104) -> 4.6
A107: Max | B107: =MAX(B9:B104) -> 9.39 | C107: =MAX(C9:C104) -> 4.11 | D107: =MAX(D9:D104) -> 14.11 | E107: =MAX(E9:E104) -> 12.67 | F107: =MAX(F9:F104) -> 19.07 | G107: =MAX(G9:G104) -> 25.48 | H107: =MAX(H9:H104) -> 8.22 | I107: =MAX(I9:I104) -> 3.29 | ... Q107: =MAX(Q9:Q104) -> 4.66
A108: Avg | B108: =AVERAGE(B9:B104) -> 9.3259375 | C108: =AVERAGE(C9:C104) -> 4.0739583 | D108: =AVERAGE(D9:D104) -> 14.057187 | E108: =AVERAGE(E9:E104) -> 9.82625 | F108: =AVERAGE(F9:F104) -> 7.5789583 | G108: =AVERAGE(G9:G104) -> 13.906458 | H108: =AVERAGE(H9:H104) -> 3.9854167 | I108: =AVERAGE(I9:I104) -> 2.9365625 | ... Q108: =AVERAGE(Q9:Q104) -> 4.6296875
A109: Stdev | B109: =STDEV(B9:B104) -> 0.027321791 | C109: =STDEV(C9:C104) -> 0.016057736 | D109: =STDEV(D9:D104) -> 0.024352807 | E109: =STDEV(E9:E104) -> 1.8944908 | F109: =STDEV(F9:F104) -> 4.0065295 | G109: =STDEV(G9:G104) -> 5.7210919 | H109: =STDEV(H9:H104) -> 2.1052525 | I109: =STDEV(I9:I104) -> 0.2139101 | ... Q109: =STDEV(Q9:Q104) -> 0.01293328
A110: Num | B110: =COUNT(B9:B104) -> 96 | C110: =COUNT(C9:C104) -> 96 | D110: =COUNT(D9:D104) -> 96 | E110: =COUNT(E9:E104) -> 96 | F110: =COUNT(F9:F104) -> 96 | G110: =COUNT(G9:G104) -> 96 | H110: =COUNT(H9:H104) -> 96 | I110: =COUNT(I9:I104) -> 96 | ... Q110: =COUNT(Q9:Q104) -> 96
A111: DCR | B111: =IF(B110>=87,">90%",IF(B110<=87,"<90%")) -> >90% | C111: =IF(C110>=87,">90%",IF(C110<=87,"<90%")) -> >90% | D111: =IF(D110>=87,">90%",IF(D110<=87,"<90%")) -> >90% | E111: =IF(E110>=87,">90%",IF(E110<=87,"<90%")) -> >90% | F111: =IF(F110>=87,">90%",IF(F110<=87,"<90%")) -> >90% | G111: =IF(G110>=87,">90%",IF(G110<=87,"<90%")) -> >90% | H111: =IF(H110>=87,">90%",IF(H110<=87,"<90%")) -> >90% | I111: =IF(I110>=87,">90%",IF(I110<=87,"<90%")) -> >90% | ... Q111: =IF(Q110>=87,">90%",IF(Q110<=87,"<90%")) -> >90%
A112: Status | B112: =IF(B110>=87,"OK",IF(B110<=87,"LESS")) -> OK | C112: =IF(C110>=87,"OK",IF(C110<=87,"LESS")) -> OK | D112: =IF(D110>=87,"OK",IF(D110<=87,"LESS")) -> OK | E112: =IF(E110>=87,"OK",IF(E110<=87,"LESS")) -> OK | F112: =IF(F110>=87,"OK",IF(F110<=87,"LESS")) -> OK | G112: =IF(G110>=87,"OK",IF(G110<=87,"LESS")) -> OK | H112: =IF(H110>=87,"OK",IF(H110<=87,"LESS")) -> OK | I112: =IF(I110>=87,"OK",IF(I110<=87,"LESS")) -> OK | ... Q112: =IF(Q110>=87,"OK",IF(Q110<=87,"LESS")) -> OK
A115: Done by | B115: AKASH
A117: Comment

Sheet 07
A1: Station: | B1: IGKV RAIPUR
A2: Date: | B2: =$A$9 -> 45480.01 | C2: Power Off | G2: Pw.Off | J2: Link Fail | L2: Link F | N2: Maintenance | P2: Maint.
A3: Report Type: | B3: Mean | C3: Calibration | G3: Calib. | J3: Data Fail | L3: Data F | N3: Invalid | P3: Invalid
A4: Time Base: | B4: 15 Min | C4: Zero Referrence | G4: Z.Ref | J4: Warm Up | L4: Wm. Up
A7: Date & Time | B7: NO | C7: NO2 | D7: NOX | E7: SO2 | F7: O3 | G7: PM 10 | H7: PM 2.5 | I7: BENZ | J7: WS | K7: WD | L7: TEMP | M7: HUM | N7: SR | O7: RG | P7: CO | Q7: NH3
B8: ug/m3 | C8: ug/m3 | D8: ppb | E8: ug/m3 | F8: ug/m3 | G8: ug/m3 | H8: ug/m3 | I8: ug/m3 | J8: m/sec | K8: deg | L8: degreC | M8: % | N8: w/m2 | O8: mm | P8: mg/m3 | Q8: ug/m3
A9: 45480.01 | B9: 9.25 | C9: 4.06 | D9: 13.99 | E9: 8.76 | F9: 5.06 | G9: 25.48 | H9: 8.03 | I9: 3.14 | J9: 0.56 | K9: 262.69 | L9: 28.13 | M9: 81.38 | N9: 2.3 | O9: 0 | P9: 0.31 | Q9: 4.64
A10: 45480.021 | B10: 9.22 | C10: 4.07 | D10: 13.97 | E10: 8.79 | F10: 5.16 | G10: 25.48 | H10: 8.03 | I10: 3.22 | J10: 0.74 | K10: 268.47 | L10: 27.55 | M10: 78.93 | N10: 2.6 | O10: 0 | P10: 0.3 | Q10: 4.63
A11: 45480.031 | B11: 9.2 | C11: 4.08 | D11: 13.96 | E11: 9.07 | F11: 5.34 | G11: 24.32 | H11: 6.54 | I11: 3.05 | J11: 0.52 | K11: 263.52 | L11: 27.11 | M11: 80.39 | N11: 2.4 | O11: 0 | P11: 0.31 | Q11: 4.62
A12: 45480.042 | B12: 9.19 | C12: 4.1 | D12: 13.96 | E12: 9.07 | F12: 5.5 | G12: 23.44 | H12: 5.62 | I12: 2.96 | J12: 0.35 | K12: 261.63 | L12: 27 | M12: 82.31 | N12: 2.1 | O12: 0 | P12: 0.31 | Q12: 4.63
A13: 45480.052 | B13: 9.19 | C13: 4.07 | D13: 13.95 | E13: 9.04 | F13: 4.85 | G13: 23.44 | H13: 5.62 | I13: 3.07 | J13: 0.4 | K13: 257.12 | L13: 26.81 | M13: 83.2 | N13: 2.2 | O13: 0 | P13: 0.31 | Q13: 4.63
A14: 45480.062 | B14: 9.2 | C14: 4.03 | D14: 13.94 | E14: 9.12 | F14: 5.11 | G14: 23.44 | H14: 5.62 | I14: 2.92 | J14: 0.24 | K14: 238.83 | L14: 26.63 | M14: 85.23 | N14: 2.1 | O14: 0 | P14: 0.3 | Q14: 4.63
A15: 45480.073 | B15: 9.2 | C15: 4.06 | D15: 13.94 | E15: 9.44 | F15: 5.24 | G15: 19.69 | H15: 4.44 | I15: 2.86 | J15: 0.38 | K15: 268.3 | L15: 26.47 | M15: 85.7 | N15: 2.1 | O15: 0 | P15: 0.31 | Q15: 4.64
A16: 45480.083 | B16: 9.19 | C16: 4.07 | D16: 13.94 | E16: 9.95 | F16: 4.38 | G16: 16.69 | H16: 4.04 | I16: 2.79 | J16: 0.6 | K16: 266.77 | L16: 26.44 | M16: 86.85 | N16: 2.1 | O16: 0 | P16: 0.3 | Q16: 4.63
A17: 45480.094 | B17: 9.2 | C17: 4.05 | D17: 13.94 | E17: 7.73 | F17: 3.99 | G17: 16.69 | H17: 4.04 | I17: 2.77 | J17: 0.78 | K17: 269.2 | L17: 26.5 | M17: 86.87 | N17: 2.1 | O17: 0 | P17: 0.3 | Q17: 4.61
A18: 45480.104 | B18: 9.19 | C18: 4.07 | D18: 13.95 | E18: 9.14 | F18: 4.32 | G18: 16.69 | H18: 4.04 | I18: 2.74 | J18: 0.64 | K18: 274.82 | L18: 26.46 | M18: 87.58 | N18: 2.1 | O18: 0 | P18: 0.3 | Q18: 4.63
A19: 45480.115 | B19: 9.19 | C19: 4.07 | D19: 13.94 | E19: 9.39 | F19: 4.88 | G19: 16.15 | H19: 3.25 | I19: 2.71 | J19: 0.58 | K19: 267.75 | L19: 26.41 | M19: 89.07 | N19: 2.1 | O19: 0 | P19: 0.32 | Q19: 4.6
A20: 45480.125 | B20: 9.18 | C20: 4.08 | D20: 13.94 | E20: 9.84 | F20: 4.26 | G20: 15.72 | H20: 2.98 | I20: 2.71 | J20: 0.83 | K20: 270.03 | L20: 26.33 | M20: 89.11 | N20: 2.3 | O20: 0 | P20: 0.35 | Q20: 4.62
... A104: 45481 | B104: 9.25 | C104: 4.07 | D104: 13.99 | E104: 7.81 | F104: 6.02 | G104: 28.28 | H104: 13.68 | I104: 4.65 | J104: 0.11 | K104: 185.75 | L104: 27.24 | M104: 94.69 | N104: 2.1 | O104: 0 | P104: 0.43 | Q104: 4.57
A106: Min | B106: =MIN(B9:B104) -> 9.15 | C106: =MIN(C9:C104) -> 4.03 | D106: =MIN(D9:D104) -> 13.9 | E106: =MIN(E9:E104) -> 5.9 | F106: =MIN(F9:F104) -> 3.22 | G106: =MIN(G9:G104) -> 5.47 | H106: =MIN(H9:H104) -> 2.26 | I106: =MIN(I9:I104) -> 2.66 | ... Q106: =MIN(Q9:Q104) -> 4.54
A107: Max | B107: =MAX(B9:B104) -> 9.27 | C107: =MAX(C9:C104) -> 4.11 | D107: =MAX(D9:D104) -> 14 | E107: =MAX(E9:E104) -> 10.68 | F107: =MAX(F9:F104) -> 11.4 | G107: =MAX(G9:G104) -> 28.28 | H107: =MAX(H9:H104) -> 146.72 | I107: =MAX(I9:I104) -> 5.18 | ... Q107: =MAX(Q9:Q104) -> 4.65
A108: Avg | B108: =AVERAGE(B9:B104) -> 9.2160417 | C108: =AVERAGE(C9:C104) -> 4.0639583 | D108: =AVERAGE(D9:D104) -> 13.963542 | E108: =AVERAGE(E9:E104) -> 8.3879167 | F108: =AVERAGE(F9:F104) -> 6.2819792 | G108: =AVERAGE(G9:G104) -> 14.578646 | H108: =AVERAGE(H9:H104) -> 32.828437 | I108: =AVERAGE(I9:I104) -> 3.555625 | ... Q108: =AVERAGE(Q9:Q104) -> 4.5939583
A109: Stdev | B109: =STDEV(B9:B104) -> 0.028152934 | C109: =STDEV(C9:C104) -> 0.018092113 | D109: =STDEV(D9:D104) -> 0.023439919 | E109: =STDEV(E9:E104) -> 1.2034144 | F109: =STDEV(F9:F104) -> 2.0753352 | G109: =STDEV(G9:G104) -> 5.5430555 | H109: =STDEV(H9:H104) -> 43.211699 | I109: =STDEV(I9:I104) -> 0.71470982 | ... Q109: =STDEV(Q9:Q104) -> 0.022733197
A110: Num | B110: =COUNT(B9:B104) -> 96 | C110: =COUNT(C9:C104) -> 96 | D110: =COUNT(D9:D104) -> 96 | E110: =COUNT(E9:E104) -> 96 | F110: =COUNT(F9:F104) -> 96 | G110: =COUNT(G9:G104) -> 96 | H110: =COUNT(H9:H104) -> 96 | I110: =COUNT(I9:I104) -> 96 | ... Q110: =COUNT(Q9:Q104) -> 96
A111: DCR | B111: =IF(B110>=87,">90%",IF(B110<=87,"<90%")) -> >90% | C111: =IF(C110>=87,">90%",IF(C110<=87,"<90%")) -> >90% | D111: =IF(D110>=87,">90%",IF(D110<=87,"<90%")) -> >90% | E111: =IF(E110>=87,">90%",IF(E110<=87,"<90%")) -> >90% | F111: =IF(F110>=87,">90%",IF(F110<=87,"<90%")) -> >90% | G111: =IF(G110>=87,">90%",IF(G110<=87,"<90%")) -> >90% | H111: =IF(H110>=87,">90%",IF(H110<=87,"<90%")) -> >90% | I111: =IF(I110>=87,">90%",IF(I110<=87,"<90%")) -> >90% | ... Q111: =IF(Q110>=87,">90%",IF(Q110<=87,"<90%")) -> >90%
A112: Status | B112: =IF(B110>=87,"OK",IF(B110<=87,"LESS")) -> OK | C112: =IF(C110>=87,"OK",IF(C110<=87,"LESS")) -> OK | D112: =IF(D110>=87,"OK",IF(D110<=87,"LESS")) -> OK | E112: =IF(E110>=87,"OK",IF(E110<=87,"LESS")) -> OK | F112: =IF(F110>=87,"OK",IF(F110<=87,"LESS")) -> OK | G112: =IF(G110>=87,"OK",IF(G110<=87,"LESS")) -> OK | H112: =IF(H110>=87,"OK",IF(H110<=87,"LESS")) -> OK | I112: =IF(I110>=87,"OK",IF(I110<=87,"LESS")) -> OK | ... Q112: =IF(Q110>=87,"OK",IF(Q110<=87,"LESS")) -> OK
A115: Done by | B115: AKASH
A117: Comment

Sheet 08
A1: Station: | B1: IGKV RAIPUR
A2: Date: | B2: =$A$9 -> 45481.01 | C2: Power Off | G2: Pw.Off | J2: Link Fail | L2: Link F | N2: Maintenance | P2: Maint.
A3: Report Type: | B3: Mean | C3: Calibration | G3: Calib. | J3: Data Fail | L3: Data F | N3: Invalid | P3: Invalid
A4: Time Base: | B4: 15 Min | C4: Zero Referrence | G4: Z.Ref | J4: Warm Up | L4: Wm. Up
A7: Date & Time | B7: NO | C7: NO2 | D7: NOX | E7: SO2 | F7: O3 | G7: PM 10 | H7: PM 2.5 | I7: BENZ | J7: WS | K7: WD | L7: TEMP | M7: HUM | N7: SR | O7: RG | P7: CO | Q7: NH3
B8: ug/m3 | C8: ug/m3 | D8: ppb | E8: ug/m3 | F8: ug/m3 | G8: ug/m3 | H8: ug/m3 | I8: ug/m3 | J8: m/sec | K8: deg | L8: degreC | M8: % | N8: w/m2 | O8: mm | P8: mg/m3 | Q8: ug/m3
A9: 45481.01 | B9: 9.32 | C9: 4.01 | D9: 14.02 | E9: 8.36 | F9: 5.61 | G9: 28.28 | H9: 13.68 | I9: 4.46 | J9: 0.1 | K9: 183.91 | L9: 27.24 | M9: 94.96 | N9: 2.1 | O9: 0 | P9: 0.42 | Q9: 4.58
A10: 45481.021 | B10: 9.3 | C10: 4.05 | D10: 14.03 | E10: 7.62 | F10: 5.64 | G10: 28.28 | H10: 13.68 | I10: 4.45 | J10: 0.14 | K10: 175.54 | L10: 27.22 | M10: 94.81 | N10: 2.1 | O10: 0 | P10: 0.42 | Q10: 4.57
A11: 45481.031 | B11: 9.29 | C11: 4.07 | D11: 14.03 | E11: 8 | F11: 5.47 | G11: 28.64 | H11: 10.57 | I11: 4.43 | J11: 0.11 | K11: 183.67 | L11: 27.44 | M11: 94.31 | N11: 2.1 | O11: 0 | P11: 0.44 | Q11: 4.58
A12: 45481.042 | B12: 9.3 | C12: 4.07 | D12: 14.04 | E12: 7.92 | F12: 5.62 | G12: 28.92 | H12: 8.66 | I12: 4.47 | J12: 0.07 | K12: 196.89 | L12: 27.29 | M12: 95.36 | N12: 2.6 | O12: 0.6 | P12: 0.43 | Q12: 4.57
A13: 45481.052 | B13: 9.3 | C13: 4.1 | D13: 14.05 | E13: 8.18 | F13: 5.88 | G13: 28.92 | H13: 8.66 | I13: 4.56 | J13: 0.1 | K13: 192.78 | L13: 27.05 | M13: 96.9 | N13: 2.6 | O13: 0 | P13: 0.42 | Q13: 4.54
A14: 45481.062 | B14: 9.29 | C14: 4.07 | D14: 14.03 | E14: 8.06 | F14: 6.43 | G14: 28.92 | H14: 8.66 | I14: 4.56 | J14: 0.11 | K14: 150.35 | L14: 26.96 | M14: 98.51 | N14: 2.3 | O14: 0 | P14: 0.42 | Q14: 4.55
A15: 45481.073 | B15: 9.3 | C15: 4.06 | D15: 14.03 | E15: 8.1 | F15: 6.82 | G15: 26.66 | H15: 3.99 | I15: 4.4 | J15: 0.09 | K15: 111.91 | L15: 26.88 | M15: 99.23 | N15: 2.5 | O15: 0 | P15: 0.41 | Q15: 4.57
A16: 45481.083 | B16: 9.28 | C16: 4.1 | D16: 14.03 | E16: 8.02 | F16: 6.87 | G16: 24.85 | H16: 2.38 | I16: 4.4 | J16: 0.08 | K16: 143.74 | L16: 26.74 | M16: 98.86 | N16: 2.5 | O16: 0 | P16: 0.39 | Q16: 4.57
A17: 45481.094 | B17: 9.26 | C17: 4.08 | D17: 14.01 | E17: 7.71 | F17: 6.46 | G17: 24.85 | H17: 2.38 | I17: 4.34 | J17: 0.11 | K17: 192.51 | L17: 26.67 | M17: 98.4 | N17: 2.5 | O17: 0 | P17: 0.4 | Q17: 4.58
A18: 45481.104 | B18: 9.28 | C18: 4.06 | D18: 14.02 | E18: 9.21 | F18: 6.26 | G18: 24.85 | H18: 2.38 | I18: 4.42 | J18: 0.14 | K18: 163.19 | L18: 26.64 | M18: 99.02 | N18: 2.3 | O18: 0 | P18: 0.35 | Q18: 4.56
A19: 45481.115 | B19: 9.31 | C19: 4.07 | D19: 14.04 | E19: 9.43 | F19: 6.25 | G19: 22.82 | H19: 4.64 | I19: 4.61 | J19: 0.12 | K19: 144.9 | L19: 26.67 | M19: 98.59 | N19: 2.3 | O19: 0 | P19: 0.34 | Q19: 4.58
A20: 45481.125 | B20: 9.31 | C20: 4.07 | D20: 14.04 | E20: 9.7 | F20: 6.45 | G20: 21.26 | H20: 5.41 | I20: 4.68 | J20: 0.13 | K20: 148.18 | L20: 26.8 | M20: 98.99 | N20: 2.4 | O20: 0 | P20: 0.34 | Q20: 4.56
... A104: 45482 | B104: 9.21 | C104: 4.08 | D104: 13.96 | E104: 9.48 | F104: 4.23 | G104: 44.02 | H104: 14.56 | I104: 6.08 | J104: 0.12 | K104: 223.17 | L104: 27.73 | M104: 98.22 | N104: 1.9 | O104: 0 | P104: 0.5 | Q104: 4.55
A106: Min | B106: =MIN(B9:B104) -> 9.2 | C106: =MIN(C9:C104) -> 4.01 | D106: =MIN(D9:D104) -> 13.96 | E106: =MIN(E9:E104) -> 6.92 | F106: =MIN(F9:F104) -> 2.97 | G106: =MIN(G9:G104) -> 7.59 | H106: =MIN(H9:H104) -> 0.89 | I106: =MIN(I9:I104) -> 3.11 | ... Q106: =MIN(Q9:Q104) -> 4.52
A107: Max | B107: =MAX(B9:B104) -> 9.32 | C107: =MAX(C9:C104) -> 4.12 | D107: =MAX(D9:D104) -> 14.06 | E107: =MAX(E9:E104) -> 15.29 | F107: =MAX(F9:F104) -> 22.46 | G107: =MAX(G9:G104) -> 47.2 | H107: =MAX(H9:H104) -> 84.21 | I107: =MAX(I9:I104) -> 6.08 | ... Q107: =MAX(Q9:Q104) -> 4.6
A108: Avg | B108: =AVERAGE(B9:B104) -> 9.2626042 | C108: =AVERAGE(C9:C104) -> 4.07 | D108: =AVERAGE(D9:D104) -> 14.005104 | E108: =AVERAGE(E9:E104) -> 10.366771 | F108: =AVERAGE(F9:F104) -> 7.7141667 | G108: =AVERAGE(G9:G104) -> 25.574375 | H108: =AVERAGE(H9:H104) -> 27.839792 | I108: =AVERAGE(I9:I104) -> 4.3471875 | ... Q108: =AVERAGE(Q9:Q104) -> 4.5571875
A109: Stdev | B109: =STDEV(B9:B104) -> 0.022998617 | C109: =STDEV(C9:C104) -> 0.017229106 | D109: =STDEV(D9:D104) -> 0.020875309 | E109: =STDEV(E9:E104) -> 2.2469903 | F109: =STDEV(F9:F104) -> 4.0880279 | G109: =STDEV(G9:G104) -> 10.301324 | H109: =STDEV(H9:H104) -> 27.089555 | I109: =STDEV(I9:I104) -> 0.67601262 | ... Q109: =STDEV(Q9:Q104) -> 0.016777374
A110: Num | B110: =COUNT(B9:B104) -> 96 | C110: =COUNT(C9:C104) -> 96 | D110: =COUNT(D9:D104) -> 96 | E110: =COUNT(E9:E104) -> 96 | F110: =COUNT(F9:F104) -> 96 | G110: =COUNT(G9:G104) -> 96 | H110: =COUNT(H9:H104) -> 96 | I110: =COUNT(I9:I104) -> 96 | ... Q110: =COUNT(Q9:Q104) -> 96
A111: DCR | B111: =IF(B110>=87,">90%",IF(B110<=87,"<90%")) -> >90% | C111: =IF(C110>=87,">90%",IF(C110<=87,"<90%")) -> >90% | D111: =IF(D110>=87,">90%",IF(D110<=87,"<90%")) -> >90% | E111: =IF(E110>=87,">90%",IF(E110<=87,"<90%")) -> >90% | F111: =IF(F110>=87,">90%",IF(F110<=87,"<90%")) -> >90% | G111: =IF(G110>=87,">90%",IF(G110<=87,"<90%")) -> >90% | H111: =IF(H110>=87,">90%",IF(H110<=87,"<90%")) -> >90% | I111: =IF(I110>=87,">90%",IF(I110<=87,"<90%")) -> >90% | ... Q111: =IF(Q110>=87,">90%",IF(Q110<=87,"<90%")) -> >90%
A112: Status | B112: =IF(B110>=87,"OK",IF(B110<=87,"LESS")) -> OK | C112: =IF(C110>=87,"OK",IF(C110<=87,"LESS")) -> OK | D112: =IF(D110>=87,"OK",IF(D110<=87,"LESS")) -> OK | E112: =IF(E110>=87,"OK",IF(E110<=87,"LESS")) -> OK | F112: =IF(F110>=87,"OK",IF(F110<=87,"LESS")) -> OK | G112: =IF(G110>=87,"OK",IF(G110<=87,"LESS")) -> OK | H112: =IF(H110>=87,"OK",IF(H110<=87,"LESS")) -> OK | I112: =IF(I110>=87,"OK",IF(I110<=87,"LESS")) -> OK | ... Q112: =IF(Q110>=87,"OK",IF(Q110<=87,"LESS")) -> OK
A115: Done by | B115: AKASH
A117: Comment

Sheet 09
A1: Station: | B1: IGKV RAIPUR
A2: Date: | B2: =$A$9 -> 45482.01 | C2: Power Off | G2: Pw.Off | J2: Link Fail | L2: Link F | N2: Maintenance | P2: Maint.
A3: Report Type: | B3: Mean | C3: Calibration | G3: Calib. | J3: Data Fail | L3: Data F | N3: Invalid | P3: Invalid
A4: Time Base: | B4: 15 Min | C4: Zero Referrence | G4: Z.Ref | J4: Warm Up | L4: Wm. Up
A7: Date & Time | B7: NO | C7: NO2 | D7: NOX | E7: SO2 | F7: O3 | G7: PM 10 | H7: PM 2.5 | I7: BENZ | J7: WS | K7: WD | L7: TEMP | M7: HUM | N7: SR | O7: RG | P7: CO | Q7: NH3
B8: ug/m3 | C8: ug/m3 | D8: ppb | E8: ug/m3 | F8: ug/m3 | G8: ug/m3 | H8: ug/m3 | I8: ug/m3 | J8: m/sec | K8: deg | L8: degreC | M8: % | N8: w/m2 | O8: mm | P8: mg/m3 | Q8: ug/m3
A9: 45482.01 | B9: 9.24 | C9: 4.17 | D9: 14.03 | E9: 9.65 | F9: 5.88 | G9: 44.02 | H9: 14.56 | I9: 6.08 | J9: 0.32 | K9: 263.88 | L9: 27.83 | M9: 92.75 | N9: 2 | O9: 0 | P9: 0.49 | Q9: 4.56
A10: 45482.021 | B10: 9.25 | C10: 4.09 | D10: 14.01 | E10: 9.86 | F10: 5.46 | G10: 44.02 | H10: 14.56 | I10: 6.02 | J10: 0.24 | K10: 275.24 | L10: 27.78 | M10: 88.47 | N10: 2.3 | O10: 0 | P10: 0.48 | Q10: 4.55
A11: 45482.031 | B11: 9.25 | C11: 4.11 | D11: 14.01 | E11: 9.88 | F11: 5.51 | G11: 39.72 | H11: 10.87 | I11: 5.85 | J11: 0.4 | K11: 268.04 | L11: 27.39 | M11: 87.45 | N11: 2.6 | O11: 0 | P11: 0.47 | Q11: 4.55
A12: 45482.042 | B12: 9.25 | C12: 4.1 | D12: 14.01 | E12: 9.99 | F12: 3.55 | G12: 36.44 | H12: 8.59 | I12: 5.66 | J12: 0.18 | K12: 275.48 | L12: 27.09 | M12: 88.68 | N12: 2.4 | O12: 0 | P12: 0.45 | Q12: 4.54
A13: 45482.052 | B13: 9.26 | C13: 4.08 | D13: 14.01 | E13: 10.32 | F13: 3.06 | G13: 36.44 | H13: 8.59 | I13: 5.62 | J13: 0.27 | K13: 259.81 | L13: 26.76 | M13: 91.1 | N13: 2.3 | O13: 0 | P13: 0.44 | Q13: 4.54
A14: 45482.062 | B14: 9.25 | C14: 4.09 | D14: 14 | E14: 10.28 | F14: 3.63 | G14: 36.44 | H14: 8.59 | I14: 5.54 | J14: 0.23 | K14: 258.69 | L14: 26.58 | M14: 91.59 | N14: 2.1 | O14: 0 | P14: 0.44 | Q14: 4.54
A15: 45482.073 | B15: 9.26 | C15: 4.04 | D15: 13.98 | E15: 9.86 | F15: 5.13 | G15: 32.83 | H15: 6.57 | I15: 5.3 | J15: 0.15 | K15: 235.13 | L15: 26.36 | M15: 91.48 | N15: 2.1 | O15: 0 | P15: 0.42 | Q15: 4.54
A16: 45482.083 | B16: 9.26 | C16: 4.01 | D16: 13.97 | E16: 10.26 | F16: 2.37 | G16: 30.07 | H16: 5.88 | I16: 5.28 | J16: 0.13 | K16: 191.99 | L16: 26.36 | M16: 91.99 | N16: 2.1 | O16: 0 | P16: 0.41 | Q16: 4.54
A17: 45482.094 | B17: 9.24 | C17: 4.05 | D17: 13.97 | E17: 7.61 | F17: 3.71 | G17: 30.07 | H17: 5.88 | I17: 5.14 | J17: 0.14 | K17: 187.89 | L17: 25.97 | M17: 93.47 | N17: 2 | O17: 0 | P17: 0.44 | Q17: 4.55
A18: 45482.104 | B18: 9.27 | C18: 4.06 | D18: 14.01 | E18: 8.76 | F18: 4.14 | G18: 30.07 | H18: 5.88 | I18: 5 | J18: 0.09 | K18: 107.38 | L18: 26.04 | M18: 95.27 | N18: 2 | O18: 0 | P18: 0.45 | Q18: 4.53
A19: 45482.115 | B19: 9.3 | C19: 4.04 | D19: 14.02 | E19: 7.61 | F19: 5.46 | G19: 25.23 | H19: 4.67 | I19: 4.95 | J19: 0.37 | K19: 38.97 | L19: 25.93 | M19: 94.21 | N19: 1.8 | O19: 0 | P19: 0.43 | Q19: 4.52
A20: 45482.125 | B20: 9.31 | C20: 4.05 | D20: 14.04 | E20: 7.71 | F20: 4.85 | G20: 21.52 | H20: 4.26 | I20: 4.92 | J20: 0.14 | K20: 197.44 | L20: 26.05 | M20: 94.9 | N20: 1.9 | O20: 0 | P20: 0.43 | Q20: 4.5
... A104: 45483 | B104: 9.3 | C104: 4.1 | D104: 14.04 | E104: 8.57 | F104: 8.22 | G104: 20.31 | H104: 8.98 | I104: 4.7 | J104: 0.26 | K104: 244.39 | L104: 26.07 | M104: 92.55 | N104: 2.5 | O104: 0 | P104: 0.41 | Q104: 4.52
A106: Min | B106: =MIN(B9:B104) -> 9.24 | C106: =MIN(C9:C104) -> 4.01 | D106: =MIN(D9:D104) -> 13.97 | E106: =MIN(E9:E104) -> 5.54 | F106: =MIN(F9:F104) -> 2.37 | G106: =MIN(G9:G104) -> 9.13 | H106: =MIN(H9:H104) -> 1.8 | I106: =MIN(I9:I104) -> 3.56 | ... Q106: =MIN(Q9:Q104) -> 3.25
A107: Max | B107: =MAX(B9:B104) -> 9.36 | C107: =MAX(C9:C104) -> 4.17 | D107: =MAX(D9:D104) -> 14.08 | E107: =MAX(E9:E104) -> 12.19 | F107: =MAX(F9:F104) -> 25.51 | G107: =MAX(G9:G104) -> 57.36 | H107: =MAX(H9:H104) -> 80.45 | I107: =MAX(I9:I104) -> 6.08 | ... Q107: =MAX(Q9:Q104) -> 4.56
A108: Avg | B108: =AVERAGE(B9:B104) -> 9.3016667 | C108: =AVERAGE(C9:C104) -> 4.0742708 | D108: =AVERAGE(D9:D104) -> 14.037604 | E108: =AVERAGE(E9:E104) -> 9.0109375 | F108: =AVERAGE(F9:F104) -> 7.9360417 | G108: =AVERAGE(G9:G104) -> 26.216146 | H108: =AVERAGE(H9:H104) -> 29.287083 | I108: =AVERAGE(I9:I104) -> 4.409375 | ... Q108: =AVERAGE(Q9:Q104) -> 4.5253125
A109: Stdev | B109: =STDEV(B9:B104) -> 0.029006956 | C109: =STDEV(C9:C104) -> 0.023248986 | D109: =STDEV(D9:D104) -> 0.023830312 | E109: =STDEV(E9:E104) -> 1.5354102 | F109: =STDEV(F9:F104) -> 5.7340338 | G109: =STDEV(G9:G104) -> 10.776315 | H109: =STDEV(H9:H104) -> 25.228364 | I109: =STDEV(I9:I104) -> 0.58885761 | ... Q109: =STDEV(Q9:Q104) -> 0.13235481
A110: Num | B110: =COUNT(B9:B104) -> 96 | C110: =COUNT(C9:C104) -> 96 | D110: =COUNT(D9:D104) -> 96 | E110: =COUNT(E9:E104) -> 96 | F110: =COUNT(F9:F104) -> 96 | G110: =COUNT(G9:G104) -> 96 | H110: =COUNT(H9:H104) -> 96 | I110: =COUNT(I9:I104) -> 96 | ... Q110: =COUNT(Q9:Q104) -> 96
A111: DCR | B111: =IF(B110>=87,">90%",IF(B110<=87,"<90%")) -> >90% | C111: =IF(C110>=87,">90%",IF(C110<=87,"<90%")) -> >90% | D111: =IF(D110>=87,">90%",IF(D110<=87,"<90%")) -> >90% | E111: =IF(E110>=87,">90%",IF(E110<=87,"<90%")) -> >90% | F111: =IF(F110>=87,">90%",IF(F110<=87,"<90%")) -> >90% | G111: =IF(G110>=87,">90%",IF(G110<=87,"<90%")) -> >90% | H111: =IF(H110>=87,">90%",IF(H110<=87,"<90%")) -> >90% | I111: =IF(I110>=87,">90%",IF(I110<=87,"<90%")) -> >90% | ... Q111: =IF(Q110>=87,">90%",IF(Q110<=87,"<90%")) -> >90%
A112: Status | B112: =IF(B110>=87,"OK",IF(B110<=87,"LESS")) -> OK | C112: =IF(C110>=87,"OK",IF(C110<=87,"LESS")) -> OK | D112: =IF(D110>=87,"OK",IF(D110<=87,"LESS")) -> OK | E112: =IF(E110>=87,"OK",IF(E110<=87,"LESS")) -> OK | F112: =IF(F110>=87,"OK",IF(F110<=87,"LESS")) -> OK | G112: =IF(G110>=87,"OK",IF(G110<=87,"LESS")) -> OK | H112: =IF(H110>=87,"OK",IF(H110<=87,"LESS")) -> OK | I112: =IF(I110>=87,"OK",IF(I110<=87,"LESS")) -> OK | ... Q112: =IF(Q110>=87,"OK",IF(Q110<=87,"LESS")) -> OK
A115: Done by | B115: AKASH
A117: Comment

Sheet 10
A1: Station: | B1: IGKV RAIPUR
A2: Date: | B2: =$A$9 -> 45483.01 | C2: Power Off | G2: Pw.Off | J2: Link Fail | L2: Link F | N2: Maintenance | P2: Maint.
A3: Report Type: | B3: Mean | C3: Calibration | G3: Calib. | J3: Data Fail | L3: Data F | N3: Invalid | P3: Invalid
A4: Time Base: | B4: 15 Min | C4: Zero Referrence | G4: Z.Ref | J4: Warm Up | L4: Wm. Up
A7: Date & Time | B7: NO | C7: NO2 | D7: NOX | E7: SO2 | F7: O3 | G7: PM 10 | H7: PM 2.5 | I7: BENZ | J7: WS | K7: WD | L7: TEMP | M7: HUM | N7: SR | O7: RG | P7: CO | Q7: NH3
B8: ug/m3 | C8: ug/m3 | D8: ppb | E8: ug/m3 | F8: ug/m3 | G8: ug/m3 | H8: ug/m3 | I8: ug/m3 | J8: m/sec | K8: deg | L8: degreC | M8: % | N8: w/m2 | O8: mm | P8: mg/m3 | Q8: ug/m3
A9: 45483.01 | B9: 9.32 | C9: 4.04 | D9: 14.03 | E9: 8.26 | F9: 8.18 | G9: 20.31 | H9: 8.98 | I9: 4.42 | J9: 0.28 | K9: 263.88 | L9: 25.89 | M9: 92.68 | N9: 2.5 | O9: 0 | P9: 0.4 | Q9: 4.58
A10: 45483.021 | B10: 9.3 | C10: 4.08 | D10: 14.04 | E10: 7.71 | F10: 7.56 | G10: 20.31 | H10: 8.98 | I10: 4.51 | J10: 0.37 | K10: 262.46 | L10: 25.82 | M10: 92.22 | N10: 2.4 | O10: 0 | P10: 0.4 | Q10: 4.57
A11: 45483.031 | B11: 9.31 | C11: 4.07 | D11: 14.04 | E11: 7.78 | F11: 9.54 | G11: 17.59 | H11: 7.75 | I11: 4.32 | J11: 0.38 | K11: 256.6 | L11: 25.68 | M11: 92.91 | N11: 2.4 | O11: 0 | P11: 0.39 | Q11: 4.58
A12: 45483.042 | B12: 9.3 | C12: 4.1 | D12: 14.05 | E12: 8.17 | F12: 7.21 | G12: 15.5 | H12: 6.99 | I12: 4.44 | J12: 0.19 | K12: 223.87 | L12: 25.57 | M12: 94.53 | N12: 2.1 | O12: 0 | P12: 0.39 | Q12: 4.57
A13: 45483.052 | B13: 9.3 | C13: 4.09 | D13: 14.04 | E13: 7.9 | F13: 5.18 | G13: 15.5 | H13: 6.99 | I13: 4.21 | J13: 0.29 | K13: 258.41 | L13: 25.47 | M13: 95.9 | N13: 2.1 | O13: 0 | P13: 0.41 | Q13: 4.54
A14: 45483.062 | B14: 9.3 | C14: 4.08 | D14: 14.03 | E14: 8.86 | F14: 4.47 | G14: 15.5 | H14: 6.99 | I14: 4.46 | J14: 0.16 | K14: 228.63 | L14: 25.49 | M14: 96.7 | N14: 2 | O14: 0 | P14: 0.42 | Q14: 4.55
A15: 45483.073 | B15: 9.31 | C15: 4.08 | D15: 14.05 | E15: 8.74 | F15: 4.85 | G15: 12.87 | H15: 5.32 | I15: 4.48 | J15: 0.14 | K15: 250.35 | L15: 25.35 | M15: 97.65 | N15: 2.1 | O15: 0 | P15: 0.38 | Q15: 4.57
A16: 45483.083 | B16: 9.32 | C16: 4.09 | D16: 14.06 | E16: 8.63 | F16: 4.49 | G16: 10.85 | H16: 4.74 | I16: 4.54 | J16: 0.16 | K16: 221.64 | L16: 25.41 | M16: 96.3 | N16: 2 | O16: 0 | P16: 0.35 | Q16: 4.57
A17: 45483.094 | B17: 9.33 | C17: 4.08 | D17: 14.06 | E17: 9.08 | F17: 4.19 | G17: 10.85 | H17: 4.74 | I17: 4.4 | J17: 0.15 | K17: 176.82 | L17: 25.29 | M17: 96.23 | N17: 2.1 | O17: 0 | P17: 0.34 | Q17: 4.58
A18: 45483.104 | B18: 9.32 | C18: 4.06 | D18: 14.05 | E18: 11.19 | F18: 3.8 | G18: 10.85 | H18: 4.74 | I18: 4.39 | J18: 0.11 | K18: 172.78 | L18: 25.18 | M18: 97.24 | N18: 2.1 | O18: 0 | P18: 0.34 | Q18: 4.56
A19: 45483.115 | B19: 9.29 | C19: 4.08 | D19: 14.03 | E19: 10.87 | F19: 5.36 | G19: 9.04 | H19: 3.84 | I19: 4.34 | J19: 0.12 | K19: 186.55 | L19: 25.04 | M19: 98.6 | N19: 2.1 | O19: 0 | P19: 0.33 | Q19: 4.58
A20: 45483.125 | B20: 9.27 | C20: 4.09 | D20: 14.02 | E20: 11.01 | F20: 4.29 | G20: 7.6 | H20: 3.53 | I20: 4.28 | J20: 0.11 | K20: 181.02 | L20: 24.97 | M20: 98.4 | N20: 1.9 | O20: 0 | P20: 0.33 | Q20: 4.56
... A104: 45484 | B104: 9.29 | C104: 4.07 | D104: 14.03 | E104: 10.24 | F104: 6.68 | G104: 25.12 | H104: 8.57 | I104: 4.45 | J104: 0.29 | K104: 261.9 | L104: 27.97 | M104: 87.7 | N104: 2.1 | O104: 0 | P104: 0.35 | Q104: 4.55
