Workbook

Sheet 01
A1: Station: | B1: BHATAGAON ,RAIPUR
A2: Date: | B2: =$A$9 -> 01-03-2023 01:00 | D2: Power Off | G2: Pw.Off | L2: Link Fail | N2: Link F | P2: Maintenance | R2: Maint.
A3: Report Type: | B3: Mean | D3: Calibration | G3: Calib. | L3: Data Fail | N3: Data F | P3: Invalid | R3: Invalid
A4: Time Base: | B4: 01 Hour | D4: Zero Referrence | G4: Z.Ref | L4: Warm Up | N4: Wm. Up
A7: Date & Time | B7: NO_BHATAGAON | C7: NO2_BHATAGAON | D7: NOX_BHATAGAON | E7: SO2_BHATAGAON | F7: O3_BHATAGAON | G7: PM10_BHATAGAON | H7: PM2_5_BHATAGAON | I7: BENZ_BHATAGAON | J7: WS_BHATAGAON | K7: WD_BHATAGAON | L7: TEMP_BHATAGAON | M7: HUM BHATAGAON | N7: SR_BHATAGAON | O7: RG_BHATAGAON | P7: CO_BHATAGAON | Q7: NH3_BHATAGAON
B8: ug/m3 | C8: ug/m3 | D8: ppb | E8: ug/m3 | F8: ug/m3 | G8: mg/m3 | H8: ug/m3 | I8: ug/m3 | J8: m/sec | K8: deg | L8: degreC | M8: % | N8: w/m2 | O8: mm | P8: ug/m3 | Q8: ug/m3
A9: 01-03-2023 01:00 | B9: 113.61 | C9: 128.97 | D9: 161.25 | E9: 3.83 | F9: 4.3 | G9: 174.34 | H9: 66.95 | I9: 1.53 | J9: 0.06 | K9: 346.95 | L9: 22.82 | M9: 57.24 | N9: 4.5 | O9: 0 | P9: 3.29 | Q9: 37.31
A10: 01-03-2023 02:00 | B10: 94.16 | C10: 123.72 | D10: 142.74 | E10: 3.65 | F10: 4.84 | G10: 143.64 | H10: 60.07 | I10: 1.48 | J10: 0.29 | K10: 357.7 | L10: 23.12 | M10: 56.58 | N10: 4.5 | O10: 0 | P10: 2.65 | Q10: 35.45
A11: 01-03-2023 03:00 | B11: 76.78 | C11: 113.66 | D11: 121.44 | E11: 4.4 | F11: 5.29 | G11: 103.76 | H11: 56.37 | I11: 1.39 | J11: 0.3 | K11: 258.4 | L11: 22.07 | M11: 55.28 | N11: 4.4 | O11: 0 | P11: 2.4 | Q11: 35.93
A12: 01-03-2023 04:00 | B12: 68.95 | C12: 113.09 | D12: 116.64 | E12: 3.73 | F12: 4.3 | G12: 134.2 | H12: 65.32 | I12: 1.25 | J12: 0.12 | K12: 348.12 | L12: 21.57 | M12: 64.07 | N12: 4.7 | O12: 0 | P12: 2.26 | Q12: 35.99
A13: 01-03-2023 05:00 | B13: 63.03 | C13: 114.87 | D13: 112.49 | E13: 4.55 | F13: 4.31 | G13: 169.76 | H13: 79.58 | I13: 1.22 | J13: 0.14 | K13: 334.89 | L13: 21.22 | M13: 62.73 | N13: 4.5 | O13: 0 | P13: 2.13 | Q13: 34.99
A14: 01-03-2023 06:00 | B14: 81.35 | C14: 115.07 | D14: 125.96 | E14: 4.99 | F14: 4.91 | G14: 173.73 | H14: 82.43 | I14: 1.1 | J14: 0.15 | K14: 357.2 | L14: 20.55 | M14: 70.1 | N14: 4.7 | O14: 0 | P14: 2.09 | Q14: 33.96
A15: 01-03-2023 07:00 | B15: 102.61 | C15: 114.79 | D15: 144.32 | E15: 5.44 | F15: 4.3 | G15: 176.56 | H15: 82.43 | I15: 1.12 | J15: 0.33 | K15: 281.57 | L15: 20.8 | M15: 67.7 | N15: 36.4 | O15: 0 | P15: 2.09 | Q15: 36.8
A16: 01-03-2023 08:00 | B16: 95.8 | C16: 113.62 | D16: 136.94 | E16: 5.03 | F16: 4.3 | G16: 176.56 | H16: 80.67 | I16: 1.07 | J16: 0.23 | K16: 359.36 | L16: 25.49 | M16: 64.13 | N16: 148.6 | O16: 0 | P16: 2.12 | Q16: 36.04
A17: 01-03-2023 09:00 | B17: 85.69 | C17: 121.28 | D17: 131.61 | E17: 17.79 | F17: 6.44 | G17: 128.86 | H17: 136.25 | I17: 0.97 | J17: 0.45 | K17: 113.91 | L17: 27.76 | M17: 44.94 | N17: 281.9 | O17: 0 | P17: 2.31 | Q17: 34.49
A18: 01-03-2023 10:00 | B18: 73.7 | C18: 126.92 | D18: 126.93 | E18: 19.24 | F18: 8.59 | G18: 233.38 | H18: 136.25 | I18: 0.96 | J18: 0.39 | K18: 142.3 | L18: 33.68 | M18: 36.64 | N18: 402.2 | O18: 0 | P18: 2.34 | Q18: 35.67
A19: 01-03-2023 11:00 | B19: 57.36 | C19: 147.64 | D19: 117.67 | E19: 8.17 | F19: 7.84 | G19: 233.38 | H19: 105 | I19: 0.95 | J19: 0.65 | K19: 352.66 | L19: 35.86 | M19: 25.99 | N19: 466.8 | O19: 0 | P19: 2.29 | Q19: 36.39
A20: 01-03-2023 12:00 | B20: 2.9 | C20: 93.42 | D20: 52.84 | E20: 24.03 | F20: 63.33 | G20: 146.41 | H20: 79.39 | I20: 0.81 | J20: 0.49 | K20: 359.51 | L20: 36.38 | M20: 24.22 | N20: 497.7 | O20: 0 | P20: 1.16 | Q20: 22.79
... A32: 01-03-2023 24:00 | B32: 53.19 | C32: 129.66 | D32: 113.17 | E32: 31.95 | F32: 12.52 | G32: 145.81 | H32: 71.92 | I32: 1.23 | J32: 1.15 | K32: 18.55 | L32: 27.01 | M32: 38.03 | N32: 4.5 | O32: 0 | P32: 2.49 | Q32: 33.11
A34: Min | B34: =MIN(B9:B32) -> 1.55 | C34: =MIN(C9:C32) -> 63.23 | D34: =MIN(D9:D32) -> 34.97 | E34: =MIN(E9:E32) -> 3.65 | F34: =MIN(F9:F32) -> 4.3 | G34: =MIN(G9:G32) -> 42.13 | H34: =MIN(H9:H32) -> 19.9 | I34: =MIN(I9:I32) -> 0.49 | ... Q34: =MIN(Q9:Q32) -> 18.39
A35: Max | B35: =MAX(B9:B32) -> 113.61 | C35: =MAX(C9:C32) -> 148.32 | D35: =MAX(D9:D32) -> 161.25 | E35: =MAX(E9:E32) -> 31.95 | F35: =MAX(F9:F32) -> 63.33 | G35: =MAX(G9:G32) -> 233.38 | H35: =MAX(H9:H32) -> 136.25 | I35: =MAX(I9:I32) -> 1.53 | ... Q35: =MAX(Q9:Q32) -> 37.31
A36: Avg | B36: =AVERAGE(B9:B32) -> 58.80375 | C36: =AVERAGE(C9:C32) -> 113.81458 | D36: =AVERAGE(D9:D32) -> 107.6075 | E36: =AVERAGE(E9:E32) -> 11.603333 | F36: =AVERAGE(F9:F32) -> 15.049167 | G36: =AVERAGE(G9:G32) -> 142.06125 | H36: =AVERAGE(H9:H32) -> 66.828333 | I36: =AVERAGE(I9:I32) -> 1.0166667 | ... Q36: =AVERAGE(Q9:Q32) -> 31.01625
A37: Stdev | B37: =STDEV(B9:B32) -> 37.065047 | C37: =STDEV(C9:C32) -> 26.824678 | D37: =STDEV(D9:D32) -> 41.993997 | E37: =STDEV(E9:E32) -> 8.0193509 | F37: =STDEV(F9:F32) -> 15.421672 | G37: =STDEV(G9:G32) -> 60.241524 | H37: =STDEV(H9:H32) -> 30.531005 | I37: =STDEV(I9:I32) -> 0.33830353 | ... Q37: =STDEV(Q9:Q32) -> 6.0667697
A38: Num | B38: =COUNT(B9:B32) -> 24 | C38: =COUNT(C9:C32) -> 24 | D38: =COUNT(D9:D32) -> 24 | E38: =COUNT(E9:E32) -> 24 | F38: =COUNT(F9:F32) -> 24 | G38: =COUNT(G9:G32) -> 24 | H38: =COUNT(H9:H32) -> 24 | I38: =COUNT(I9:I32) -> 24 | ... Q38: =COUNT(Q9:Q32) -> 24
A39: DCR | B39: =IF(B38>=22,">90%",IF(B38<=22,"<90%")) -> >90% | C39: =IF(C38>=22,">90%",IF(C38<=22,"<90%")) -> >90% | D39: =IF(D38>=22,">90%",IF(D38<=22,"<90%")) -> >90% | E39: =IF(E38>=22,">90%",IF(E38<=22,"<90%")) -> >90% | F39: =IF(F38>=22,">90%",IF(F38<=22,"<90%")) -> >90% | G39: =IF(G38>=22,">90%",IF(G38<=22,"<90%")) -> >90% | H39: =IF(H38>=22,">90%",IF(H38<=22,"<90%")) -> >90% | I39: =IF(I38>=22,">90%",IF(I38<=22,"<90%")) -> >90% | ... Q39: =IF(Q38>=22,">90%",IF(Q38<=22,"<90%")) -> >90%
A40: Status | B40: =IF(B38>=22,"OK",IF(B38<=22,"LESS")) -> OK | C40: =IF(C38>=22,"OK",IF(C38<=22,"LESS")) -> OK | D40: =IF(D38>=22,"OK",IF(D38<=22,"LESS")) -> OK | E40: =IF(E38>=22,"OK",IF(E38<=22,"LESS")) -> OK | F40: =IF(F38>=22,"OK",IF(F38<=22,"LESS")) -> OK | G40: =IF(G38>=22,"OK",IF(G38<=22,"LESS")) -> OK | H40: =IF(H38>=22,"OK",IF(H38<=22,"LESS")) -> OK | I40: =IF(I38>=22,"OK",IF(I38<=22,"LESS")) -> OK | ... Q40: =IF(Q38>=22,"OK",IF(Q38<=22,"LESS")) -> OK
A43: Done by | B43: RAHUL
A45: Comment

Sheet 02
A1: Station: | B1: BHATAGAON RAIPUR
A2: Date: | B2: =$A$9 -> 02-03-2023 01:00 | D2: Power Off | G2: Pw.Off | L2: Link Fail | N2: Link F | P2: Maintenance | R2: Maint.
A3: Report Type: | B3: Mean | D3: Calibration | G3: Calib. | L3: Data Fail | N3: Data F | P3: Invalid | R3: Invalid
A4: Time Base: | B4: 01 Hour | D4: Zero Referrence | G4: Z.Ref | L4: Warm Up | N4: Wm. Up
A7: Date & Time | B7: NO_BHATAGAON | C7: NO2_BHATAGAON | D7: NOX_BHATAGAON | E7: SO2_BHATAGAON | F7: O3_BHATAGAON | G7: PM10_BHATAGAON | H7: PM2_5_BHATAGAON | I7: BENZ_BHATAGAON | J7: WS_BHATAGAON | K7: WD_BHATAGAON | L7: TEMP_BHATAGAON | M7: HUM BHATAGAON | N7: SR_BHATAGAON | O7: RG_BHATAGAON | P7: CO_BHATAGAON | Q7: NH3_BHATAGAON
B8: ug/m3 | C8: ug/m3 | D8: ppb | E8: ug/m3 | F8: ug/m3 | G8: mg/m3 | H8: ug/m3 | I8: ug/m3 | J8: m/sec | K8: deg | L8: degreC | M8: % | N8: w/m2 | O8: mm | P8: ug/m3 | Q8: ug/m3
A9: 02-03-2023 01:00 | B9: 39.32 | C9: 130.42 | D9: 101.97 | E9: 10.57 | F9: 6.96 | G9: 114.24 | H9: 60.41 | I9: 1.03 | J9: 0.81 | K9: 17.96 | L9: 26.47 | M9: 43.24 | N9: 4.6 | O9: 0 | P9: 2.36 | Q9: 33.05
A10: 02-03-2023 02:00 | B10: 28.29 | C10: 128.05 | D10: 92.31 | E10: 10.02 | F10: 4.54 | G10: 150.8 | H10: 61.53 | I10: 0.9 | J10: 0.59 | K10: 231.07 | L10: 25.19 | M10: 50.39 | N10: 5.1 | O10: 0 | P10: 2.04 | Q10: 32.97
A11: 02-03-2023 03:00 | B11: 20.6 | C11: 117.39 | D11: 80.26 | E11: 5.83 | F11: 5.87 | G11: 150.8 | H11: 61.53 | I11: 0.82 | J11: 0.18 | K11: 331.8 | L11: 23.3 | M11: 58.61 | N11: 4.8 | O11: 0 | P11: 1.89 | Q11: 31.16
A12: 02-03-2023 04:00 | B12: 21.32 | C12: 109.81 | D12: 76.29 | E12: 4.82 | F12: 6.33 | G12: 104.57 | H12: 53.72 | I12: 0.77 | J12: 0.2 | K12: 358.7 | L12: 22.27 | M12: 59.39 | N12: 4.7 | O12: 0 | P12: 1.76 | Q12: 33.09
A13: 02-03-2023 05:00 | B13: 21.23 | C13: 109.48 | D13: 76.4 | E13: 4.8 | F13: 4.85 | G13: 104.57 | H13: 48.17 | I13: 0.76 | J13: 0.16 | K13: 310.5 | L13: 22.21 | M13: 58 | N13: 4.6 | O13: 0 | P13: 1.66 | Q13: 33.61
A14: 02-03-2023 06:00 | B14: 29.53 | C14: 108.39 | D14: 82.39 | E14: 4.71 | F14: 4.3 | G14: 102.92 | H14: 46.79 | I14: 0.73 | J14: 0.06 | K14: 150.49 | L14: 22.03 | M14: 62.15 | N14: 4.6 | O14: 0 | P14: 1.5 | Q14: 33.57
A15: 02-03-2023 07:00 | B15: 50.39 | C15: 109.41 | D15: 99.71 | E15: 5.39 | F15: 4.41 | G15: 135.68 | H15: 64.82 | I15: 0.75 | J15: 0.15 | K15: 280.34 | L15: 21.87 | M15: 64.93 | N15: 33.4 | O15: 0 | P15: 1.63 | Q15: 32.88
A16: 02-03-2023 08:00 | B16: 65.62 | C16: 119.09 | D16: 117.3 | E16: 7 | F16: 4.37 | G16: 135.68 | H16: 134.31 | I16: 0.81 | J16: 0.15 | K16: 269.21 | L16: 27.21 | M16: 60.27 | N16: 143.1 | O16: 0 | P16: 1.84 | Q16: 35.98
A17: 02-03-2023 09:00 | B17: 70.58 | C17: 124.12 | D17: 123.07 | E17: 4.56 | F17: 4.32 | G17: 196.53 | H17: 134.31 | I17: 0.88 | J17: 1.69 | K17: 217.39 | L17: 27.04 | M17: 56.25 | N17: 265.3 | O17: 0 | P17: 1.93 | Q17: 36.64
A18: 02-03-2023 10:00 | B18: 50.21 | C18: 120.02 | D18: 104.93 | E18: 4.36 | F18: 5.71 | G18: 196.53 | H18: 95.52 | I18: 0.84 | J18: 0.68 | K18: 240.32 | L18: 28.56 | M18: 48.55 | N18: 362.7 | O18: 0 | P18: 1.8 | Q18: 34.41
A19: 02-03-2023 11:00 | B19: 32.76 | C19: 121.24 | D19: 88.85 | E19: 7.35 | F19: 7.99 | G19: 89.69 | H19: 55.26 | I19: 0.79 | J19: 0.47 | K19: 354.29 | L19: 33.31 | M19: 37.26 | N19: 393.9 | O19: 0 | P19: 1.6 | Q19: 32.64
A20: 02-03-2023 12:00 | B20: 23.07 | C20: 137.72 | D20: 88.28 | E20: 5.93 | F20: 6.03 | G20: 157.25 | H20: 70.33 | I20: 0.76 | J20: 0.65 | K20: 359.78 | L20: 34.92 | M20: 30.96 | N20: 438.9 | O20: 0 | P20: 1.64 | Q20: 34.38
... A32: 02-03-2023 24:00 | B32: 127.69 | C32: 149.49 | D32: 181.69 | E32: 11.31 | F32: 4.32 | G32: 196.63 | H32: 76.91 | I32: 1.47 | J32: 0.16 | K32: 70.38 | L32: 24.2 | M32: 63.52 | N32: 4.6 | O32: 0 | P32: 3.5 | Q32: 38.26
A34: Min | B34: =MIN(B9:B32) -> 4.24 | C34: =MIN(C9:C32) -> 108.39 | D34: =MIN(D9:D32) -> 62.96 | E34: =MIN(E9:E32) -> 4.36 | F34: =MIN(F9:F32) -> 4.3 | G34: =MIN(G9:G32) -> 59.6 | H34: =MIN(H9:H32) -> 27.31 | I34: =MIN(I9:I32) -> 0.61 | ... Q34: =MIN(Q9:Q32) -> 30.35
A35: Max | B35: =MAX(B9:B32) -> 127.69 | C35: =MAX(C9:C32) -> 159.53 | D35: =MAX(D9:D32) -> 182.96 | E35: =MAX(E9:E32) -> 29.69 | F35: =MAX(F9:F32) -> 27.55 | G35: =MAX(G9:G32) -> 196.63 | H35: =MAX(H9:H32) -> 134.31 | I35: =MAX(I9:I32) -> 1.51 | ... Q35: =MAX(Q9:Q32) -> 38.26
A36: Avg | B36: =AVERAGE(B9:B32) -> 40.33875 | C36: =AVERAGE(C9:C32) -> 127.01667 | D36: =AVERAGE(D9:D32) -> 100.33375 | E36: =AVERAGE(E9:E32) -> 11.07625 | F36: =AVERAGE(F9:F32) -> 9.6166667 | G36: =AVERAGE(G9:G32) -> 128.83125 | H36: =AVERAGE(H9:H32) -> 63.351667 | I36: =AVERAGE(I9:I32) -> 0.88791667 | ... Q36: =AVERAGE(Q9:Q32) -> 33.680417
A37: Stdev | B37: =STDEV(B9:B32) -> 34.268714 | C37: =STDEV(C9:C32) -> 16.235466 | D37: =STDEV(D9:D32) -> 33.497545 | E37: =STDEV(E9:E32) -> 6.5403289 | F37: =STDEV(F9:F32) -> 7.5851936 | G37: =STDEV(G9:G32) -> 40.613815 | H37: =STDEV(H9:H32) -> 26.321067 | I37: =STDEV(I9:I32) -> 0.26863551 | ... Q37: =STDEV(Q9:Q32) -> 2.107402
A38: Num | B38: =COUNT(B9:B32) -> 24 | C38: =COUNT(C9:C32) -> 24 | D38: =COUNT(D9:D32) -> 24 | E38: =COUNT(E9:E32) -> 24 | F38: =COUNT(F9:F32) -> 24 | G38: =COUNT(G9:G32) -> 24 | H38: =COUNT(H9:H32) -> 24 | I38: =COUNT(I9:I32) -> 24 | ... Q38: =COUNT(Q9:Q32) -> 24
A39: DCR | B39: =IF(B38>=22,">90%",IF(B38<=22,"<90%")) -> >90% | C39: =IF(C38>=22,">90%",IF(C38<=22,"<90%")) -> >90% | D39: =IF(D38>=22,">90%",IF(D38<=22,"<90%")) -> >90% | E39: =IF(E38>=22,">90%",IF(E38<=22,"<90%")) -> >90% | F39: =IF(F38>=22,">90%",IF(F38<=22,"<90%")) -> >90% | G39: =IF(G38>=22,">90%",IF(G38<=22,"<90%")) -> >90% | H39: =IF(H38>=22,">90%",IF(H38<=22,"<90%")) -> >90% | I39: =IF(I38>=22,">90%",IF(I38<=22,"<90%")) -> >90% | ... Q39: =IF(Q38>=22,">90%",IF(Q38<=22,"<90%")) -> >90%
A40: Status | B40: =IF(B38>=22,"OK",IF(B38<=22,"LESS")) -> OK | C40: =IF(C38>=22,"OK",IF(C38<=22,"LESS")) -> OK | D40: =IF(D38>=22,"OK",IF(D38<=22,"LESS")) -> OK | E40: =IF(E38>=22,"OK",IF(E38<=22,"LESS")) -> OK | F40: =IF(F38>=22,"OK",IF(F38<=22,"LESS")) -> OK | G40: =IF(G38>=22,"OK",IF(G38<=22,"LESS")) -> OK | H40: =IF(H38>=22,"OK",IF(H38<=22,"LESS")) -> OK | I40: =IF(I38>=22,"OK",IF(I38<=22,"LESS")) -> OK | ... Q40: =IF(Q38>=22,"OK",IF(Q38<=22,"LESS")) -> OK
A43: Done by | B43: RAHUL
A45: Comment

Sheet 03
A1: Station: | B1: BHATAGAON RAIPUR
A2: Date: | B2: =$A$9 -> 03-03-2023 01:00 | D2: Power Off | G2: Pw.Off | L2: Link Fail | N2: Link F | P2: Maintenance | R2: Maint.
A3: Report Type: | B3: Mean | D3: Calibration | G3: Calib. | L3: Data Fail | N3: Data F | P3: Invalid | R3: Invalid
A4: Time Base: | B4: 01 Hour | D4: Zero Referrence | G4: Z.Ref | L4: Warm Up | N4: Wm. Up
A7: Date & Time | B7: NO_BHATAGAON | C7: NO2_BHATAGAON | D7: NOX_BHATAGAON | E7: SO2_BHATAGAON | F7: O3_BHATAGAON | G7: PM10_BHATAGAON | H7: PM2_5_BHATAGAON | I7: BENZ_BHATAGAON | J7: WS_BHATAGAON | K7: WD_BHATAGAON | L7: TEMP_BHATAGAON | M7: HUM BHATAGAON | N7: SR_BHATAGAON | O7: RG_BHATAGAON | P7: CO_BHATAGAON | Q7: NH3_BHATAGAON
B8: ug/m3 | C8: ug/m3 | D8: ppb | E8: ug/m3 | F8: ug/m3 | G8: mg/m3 | H8: ug/m3 | I8: ug/m3 | J8: m/sec | K8: deg | L8: degreC | M8: % | N8: w/m2 | O8: mm | P8: ug/m3 | Q8: ug/m3
A9: 03-03-2023 01:00 | B9: 105.39 | C9: 139.24 | D9: 160.32 | E9: 15.03 | F9: 5.2 | G9: 204.8 | H9: 88.42 | I9: 1.51 | J9: 0.66 | K9: 40.23 | L9: 23.78 | M9: 62.17 | N9: 4.4 | O9: 0 | P9: 3.41 | Q9: 38.93
A10: 03-03-2023 02:00 | B10: 97.93 | C10: 129.35 | D10: 148.48 | E10: 14.98 | F10: 6.11 | G10: 204.8 | H10: 92.33 | I10: 1.43 | J10: 0.66 | K10: 13.79 | L10: 24.14 | M10: 52.39 | N10: 4.5 | O10: 0 | P10: 3.03 | Q10: 39.42
A11: 03-03-2023 03:00 | B11: 76.93 | C11: 129 | D11: 131.84 | E11: 17.62 | F11: 4.56 | G11: 196.78 | H11: 92.33 | I11: 1.37 | J11: 0.44 | K11: 66.39 | L11: 24.49 | M11: 49.74 | N11: 4.6 | O11: 0 | P11: 2.67 | Q11: 38.59
A12: 03-03-2023 04:00 | B12: 49.69 | C12: 120.74 | D12: 105.44 | E12: 19.44 | F12: 5.69 | G12: 165.31 | H12: 86.05 | I12: 1.16 | J12: 0.39 | K12: 94.43 | L12: 23.64 | M12: 52.34 | N12: 4.5 | O12: 0 | P12: 2.31 | Q12: 35.92
A13: 03-03-2023 05:00 | B13: 49.03 | C13: 115.82 | D13: 101.6 | E13: 8.67 | F13: 5.19 | G13: 165.31 | H13: 86.05 | I13: 0.95 | J13: 0.29 | K13: 283.69 | L13: 22.93 | M13: 65.52 | N13: 4.8 | O13: 0 | P13: 2.28 | Q13: 36.32
A14: 03-03-2023 06:00 | B14: 53.76 | C14: 114.78 | D14: 103.82 | E14: 5.84 | F14: 4.32 | G14: 149.37 | H14: 70.7 | I14: 0.94 | J14: 0.24 | K14: 284.86 | L14: 21.19 | M14: 72.22 | N14: 4.7 | O14: 0 | P14: 2.23 | Q14: 36.99
A15: 03-03-2023 07:00 | B15: 67.92 | C15: 111.47 | D15: 114.02 | E15: 5.02 | F15: 4.31 | G15: 149.37 | H15: 69.14 | I15: 0.91 | J15: 0.18 | K15: 333.4 | L15: 20.97 | M15: 73.76 | N15: 40.9 | O15: 0 | P15: 2.12 | Q15: 36.53
A16: 03-03-2023 08:00 | B16: 72.25 | C16: 112.31 | D16: 117.72 | E16: 5.29 | F16: 4.4 | G16: 147.91 | H16: 69.14 | I16: 0.9 | J16: 0.17 | K16: 353.06 | L16: 26.51 | M16: 69.7 | N16: 175.1 | O16: 0 | P16: 2.07 | Q16: 35.08
A17: 03-03-2023 09:00 | B17: 68.43 | C17: 118.53 | D17: 117.16 | E17: 5.89 | F17: 4.42 | G17: 147.91 | H17: 67.58 | I17: 0.9 | J17: 1.27 | K17: 111.41 | L17: 27.92 | M17: 46.71 | N17: 342.2 | O17: 0 | P17: 2.03 | Q17: 37.09
A18: 03-03-2023 10:00 | B18: 56.93 | C18: 129.26 | D18: 111.53 | E18: 5.94 | F18: 4.81 | G18: 146 | H18: 64.48 | I18: 0.89 | J18: 1.34 | K18: 112.59 | L18: 30.84 | M18: 32.92 | N18: 468.2 | O18: 0 | P18: 1.87 | Q18: 36.82
A19: 03-03-2023 11:00 | B19: 33.88 | C19: 124.07 | D19: 94.59 | E19: 15.13 | F19: 58.27 | G19: 113.45 | H19: 54.68 | I19: 0.8 | J19: 1.27 | K19: 120.88 | L19: 32.06 | M19: 29.48 | N19: 490.4 | O19: 0 | P19: 1.53 | Q19: 34.37
A20: 03-03-2023 12:00 | B20: 3.06 | C20: 59.99 | D20: 34.51 | E20: 17.29 | F20: 61.89 | G20: Calib. | H20: Calib. | I20: 0.47 | J20: 0.74 | K20: 158.28 | L20: 35.33 | M20: 24.06 | N20: 511.8 | O20: 0 | P20: 0.53 | Q20: Calib.
A21: 03-03-2023 13:00 | B21: 3.86 | C21: 71.84 | D21: 41.7 | E21: 37.1 | F21: 55.08 | G21: 64.18 | H21: 39.37 | I21: 0.5 | J21: 1.24 | K21: 43.13 | L21: 39 | M21: 20.34 | N21: 497.2 | O21: 0 | P21: 0.82 | Q21: Calib.
A22: 03-03-2023 14:00 | B22: 4.34 | C22: 66.01 | D22: 39.84 | E22: 44.27 | F22: 49.42 | G22: 67.12 | H22: 39.37 | I22: 0.5 | J22: 0.99 | K22: 95.23 | L22: 37.58 | M22: 20.13 | N22: 445.2 | O22: 0 | P22: 0.79 | Q22: 19.34
A23: 03-03-2023 15:00 | B23: 4.6 | C23: 74.9 | D23: 45.02 | E23: 19.16 | F23: 23.63 | G23: 67.12 | H23: 36.25 | I23: 0.55 | J23: 1.85 | K23: 13.2 | L23: 39.12 | M23: 12.49 | N23: 437.6 | O23: 0 | P23: 0.77 | Q23: 17.93
A24: 03-03-2023 16:00 | B24: 6.68 | C24: 72.13 | D24: 44.32 | E24: 9.37 | F24: 15.03 | G24: 63.54 | H24: 36.25 | I24: 0.57 | J24: 2.1 | K24: 27.37 | L24: 38.41 | M24: 13.18 | N24: 366.3 | O24: 0 | P24: 0.72 | Q24: 22.76
A25: 03-03-2023 17:00 | B25: 7.51 | C25: 77.1 | D25: 47.63 | E25: 9.16 | F25: 22.07 | G25: 61.74 | H25: 31.84 | I25: 0.58 | J25: 1.84 | K25: 34.45 | L25: 35.64 | M25: 15.06 | N25: 119.2 | O25: 0 | P25: 0.75 | Q25: 23.49
A26: 03-03-2023 18:00 | B26: 24.71 | C26: 112.5 | D26: 81.9 | E26: 17.34 | F26: 21.92 | G26: 60.42 | H26: 29.68 | I26: 0.54 | J26: 1.6 | K26: 29.7 | L26: 33.33 | M26: 18.71 | N26: 43.3 | O26: 0 | P26: 1.36 | Q26: 22.19
A27: 03-03-2023 19:00 | B27: 64.74 | C27: 133.11 | D27: 123.23 | E27: 22.72 | F27: 8.19 | G27: 76.01 | H27: 30.66 | I27: 0.84 | J27: 0.36 | K27: 93.5 | L27: 30.75 | M27: 24.48 | N27: 5.4 | O27: 0 | P27: 2.51 | Q27: 21.33
A28: 03-03-2023 20:00 | B28: 69.62 | C28: 124.27 | D28: 124.41 | E28: 14.55 | F28: 4.24 | G28: 156.7 | H28: 41.14 | I28: 1.07 | J28: 0.27 | K28: 281.89 | L28: 27.63 | M28: 31.69 | N28: 4.8 | O28: 0 | P28: 2.31 | Q28: 28.64
A29: 03-03-2023 21:00 | B29: 165.18 | C29: 131.5 | D29: 205.03 | E29: 8.5 | F29: 3.22 | G29: 156.7 | H29: 44.51 | I29: 1.12 | J29: 0.18 | K29: 323.69 | L29: 26.46 | M29: 39.64 | N29: 4.4 | O29: 0 | P29: 3.28 | Q29: 30.88
A30: 03-03-2023 22:00 | B30: 176.66 | C30: 129.31 | D30: 210.56 | E30: 10.22 | F30: 3.3 | G30: 205.04 | H30: 53.85 | I30: 1.42 | J30: 0.23 | K30: 305.19 | L30: 25.34 | M30: 45.09 | N30: 4.7 | O30: 0 | P30: 3.44 | Q30: 29.36
A31: 03-03-2023 23:00 | B31: 167.4 | C31: 121.83 | D31: 199.63 | E31: 8.04 | F31: 3.25 | G31: 211.96 | H31: 63.48 | I31: 1.66 | J31: 0.24 | K31: 287.7 | L31: 24.41 | M31: 49.67 | N31: 4.5 | O31: 0 | P31: 3.45 | Q31: 36.76
A32: 03-03-2023 24:00 | B32: 191.89 | C32: 115.18 | D32: 217.05 | E32: 6.31 | F32: 3.02 | G32: 211.96 | H32: 67.78 | I32: 1.72 | J32: 0.13 | K32: 324.4 | L32: 23.55 | M32: 55.52 | N32: 4.4 | O32: 0 | P32: 3.7 | Q32: 40.05
A34: Min | B34: =MIN(B9:B32) -> 3.06 | C34: =MIN(C9:C32) -> 59.99 | D34: =MIN(D9:D32) -> 34.51 | E34: =MIN(E9:E32) -> 5.02 | F34: =MIN(F9:F32) -> 3.02 | G34: =MIN(G9:G32) -> 60.42 | H34: =MIN(H9:H32) -> 29.68 | I34: =MIN(I9:I32) -> 0.47 | ... Q34: =MIN(Q9:Q32) -> 17.93
A35: Max | B35: =MAX(B9:B32) -> 191.89 | C35: =MAX(C9:C32) -> 139.24 | D35: =MAX(D9:D32) -> 217.05 | E35: =MAX(E9:E32) -> 44.27 | F35: =MAX(F9:F32) -> 61.89 | G35: =MAX(G9:G32) -> 211.96 | H35: =MAX(H9:H32) -> 92.33 | I35: =MAX(I9:I32) -> 1.72 | ... Q35: =MAX(Q9:Q32) -> 40.05
A36: Avg | B36: =AVERAGE(B9:B32) -> 67.599583 | C36: =AVERAGE(C9:C32) -> 109.76 | D36: =AVERAGE(D9:D32) -> 113.38958 | E36: =AVERAGE(E9:E32) -> 14.286667 | F36: =AVERAGE(F9:F32) -> 15.8975 | G36: =AVERAGE(G9:G32) -> 138.84783 | H36: =AVERAGE(H9:H32) -> 58.916522 | I36: =AVERAGE(I9:I32) -> 0.97083333 | ... Q36: =AVERAGE(Q9:Q32) -> 31.763182
A37: Stdev | B37: =STDEV(B9:B32) -> 57.771055 | C37: =STDEV(C9:C32) -> 24.492218 | D37: =STDEV(D9:D32) -> 56.040093 | E37: =STDEV(E9:E32) -> 9.7471207 | F37: =STDEV(F9:F32) -> 19.513617 | G37: =STDEV(G9:G32) -> 55.525965 | H37: =STDEV(H9:H32) -> 21.185652 | I37: =STDEV(I9:I32) -> 0.38476324 | ... Q37: =STDEV(Q9:Q32) -> 7.3097003
A38: Num | B38: =COUNT(B9:B32) -> 24 | C38: =COUNT(C9:C32) -> 24 | D38: =COUNT(D9:D32) -> 24 | E38: =COUNT(E9:E32) -> 24 | F38: =COUNT(F9:F32) -> 24 | G38: =COUNT(G9:G32)+1 -> 24 | H38: =COUNT(H9:H32)+1 -> 24 | I38: =COUNT(I9:I32) -> 24 | J38: =COUNT(J9:J32) -> 24 | K38: =COUNT(K9:K32) -> 24 | L38: =COUNT(L9:L32) -> 24 | M38: =COUNT(M9:M32) -> 24 | N38: =COUNT(N9:N32) -> 24 | O38: =COUNT(O9:O32) -> 24 | P38: =COUNT(P9:P32) -> 24 | Q38: =COUNT(Q9:Q32)+2 -> 24
A39: DCR | B39: =IF(B38>=22,">90%",IF(B38<=22,"<90%")) -> >90% | C39: =IF(C38>=22,">90%",IF(C38<=22,"<90%")) -> >90% | D39: =IF(D38>=22,">90%",IF(D38<=22,"<90%")) -> >90% | E39: =IF(E38>=22,">90%",IF(E38<=22,"<90%")) -> >90% | F39: =IF(F38>=22,">90%",IF(F38<=22,"<90%")) -> >90% | G39: =IF(G38>=22,">90%",IF(G38<=22,"<90%")) -> >90% | H39: =IF(H38>=22,">90%",IF(H38<=22,"<90%")) -> >90% | I39: =IF(I38>=22,">90%",IF(I38<=22,"<90%")) -> >90% | ... Q39: =IF(Q38>=22,">90%",IF(Q38<=22,"<90%")) -> >90%
A40: Status | B40: =IF(B38>=22,"OK",IF(B38<=22,"LESS")) -> OK | C40: =IF(C38>=22,"OK",IF(C38<=22,"LESS")) -> OK | D40: =IF(D38>=22,"OK",IF(D38<=22,"LESS")) -> OK | E40: =IF(E38>=22,"OK",IF(E38<=22,"LESS")) -> OK | F40: =IF(F38>=22,"OK",IF(F38<=22,"LESS")) -> OK | G40: =IF(G38>=22,"OK",IF(G38<=22,"LESS")) -> OK | H40: =IF(H38>=22,"OK",IF(H38<=22,"LESS")) -> OK | I40: =IF(I38>=22,"OK",IF(I38<=22,"LESS")) -> OK | ... Q40: =IF(Q38>=22,"OK",IF(Q38<=22,"LESS")) -> OK
A43: Done by | B43: RAHUL
A45: Comment

Sheet 04
A1: Station: | B1: BHATAGAON RAIPUR
A2: Date: | B2: =$A$9 -> 04-03-2023 01:00 | D2: Power Off | G2: Pw.Off | L2: Link Fail | N2: Link F | P2: Maintenance | R2: Maint.
A3: Report Type: | B3: Mean | D3: Calibration | G3: Calib. | L3: Data Fail | N3: Data F | P3: Invalid | R3: Invalid
A4: Time Base: | B4: 01 Hour | D4: Zero Referrence | G4: Z.Ref | L4: Warm Up | N4: Wm. Up
A7: Date & Time | B7: NO_BHATAGAON | C7: NO2_BHATAGAON | D7: NOX_BHATAGAON | E7: SO2_BHATAGAON | F7: O3_BHATAGAON | G7: PM10_BHATAGAON | H7: PM2_5_BHATAGAON | I7: BENZ_BHATAGAON | J7: WS_BHATAGAON | K7: WD_BHATAGAON | L7: TEMP_BHATAGAON | M7: HUM BHATAGAON | N7: SR_BHATAGAON | O7: RG_BHATAGAON | P7: CO_BHATAGAON | Q7: NH3_BHATAGAON
B8: ug/m3 | C8: ug/m3 | D8: ppb | E8: ug/m3 | F8: ug/m3 | G8: mg/m3 | H8: ug/m3 | I8: ug/m3 | J8: m/sec | K8: deg | L8: degreC | M8: % | N8: w/m2 | O8: mm | P8: ug/m3 | Q8: ug/m3
A9: 04-03-2023 01:00 | B9: 202.05 | C9: 114.89 | D9: 224.45 | E9: 7.31 | F9: 2.95 | G9: 189.74 | H9: 71.98 | I9: 1.93 | J9: 0.18 | K9: 321.69 | L9: 22.6 | M9: 56.57 | N9: 4.4 | O9: 0 | P9: 4.06 | Q9: 40.34
A10: 04-03-2023 02:00 | B10: 194.74 | C10: 109.97 | D10: 216.86 | E10: 7.42 | F10: 3.11 | G10: 187.6 | H10: 71.98 | I10: 1.97 | J10: 0.38 | K10: 352.12 | L10: 22.73 | M10: 56.93 | N10: 4.6 | O10: 0 | P10: 3.75 | Q10: 39.73
A11: 04-03-2023 03:00 | B11: 182.94 | C11: 105.71 | D11: 205.04 | E11: 6.9 | F11: 3.07 | G11: 164.33 | H11: 70.72 | I11: 1.95 | J11: 0.15 | K11: 343.18 | L11: 21.14 | M11: 59.7 | N11: 4.7 | O11: 0 | P11: 3.6 | Q11: 40.71
A12: 04-03-2023 04:00 | B12: 168.68 | C12: 100.9 | D12: 190.95 | E12: 6.32 | F12: 3.02 | G12: 179.47 | H12: 73.68 | I12: 1.88 | J12: 0.15 | K12: 290.58 | L12: 20.76 | M12: 67.68 | N12: 4.4 | O12: 0 | P12: 3.33 | Q12: 40.15
A13: 04-03-2023 05:00 | B13: 146.47 | C13: 96.18 | D13: 170.43 | E13: 6.42 | F13: 3.05 | G13: 179.47 | H13: 75.78 | I13: 1.74 | J13: 0.11 | K13: 325.97 | L13: 20.4 | M13: 69.09 | N13: 4.4 | O13: 0 | P13: 2.98 | Q13: 37.75
A14: 04-03-2023 06:00 | B14: 149.5 | C14: 93.52 | D14: 170.42 | E14: 6.76 | F14: 3.06 | G14: 184.89 | H14: 75.78 | I14: 1.63 | J14: 0.16 | K14: 307.06 | L14: 19.71 | M14: 67.93 | N14: 4.4 | O14: 0 | P14: 2.79 | Q14: 37.31
A15: 04-03-2023 07:00 | B15: 160.59 | C15: 93.7 | D15: 180.49 | E15: 6.47 | F15: 2.89 | G15: 184.89 | H15: 75.25 | I15: 1.55 | J15: 0.14 | K15: 335.06 | L15: 19.79 | M15: 67.31 | N15: 44.4 | O15: 0 | P15: 2.54 | Q15: 38.82
A16: 04-03-2023 08:00 | B16: 168.73 | C16: 103.12 | D16: 191.32 | E16: 7.5 | F16: 3.19 | G16: 156.63 | H16: 73.04 | I16: 1.42 | J16: 0.32 | K16: 358.79 | L16: 28.97 | M16: 59.2 | N16: 242 | O16: 0 | P16: 2.43 | Q16: 38.9
A17: 04-03-2023 09:00 | B17: 155.96 | C17: 106.95 | D17: 183.13 | E17: 9.19 | F17: 5.53 | G17: 156.63 | H17: 69.04 | I17: 1.35 | J17: 0.67 | K17: 119.01 | L17: 31.76 | M17: 31.36 | N17: 402.4 | O17: 0 | P17: 2.38 | Q17: 37.74
A18: 04-03-2023 10:00 | B18: 133.56 | C18: 115.44 | D18: 165.9 | E18: 6.97 | F18: 4.43 | G18: 144.98 | H18: 68.23 | I18: 1.25 | J18: 1.23 | K18: 114.13 | L18: 32.68 | M18: 23.22 | N18: 549.9 | O18: 0 | P18: 2.21 | Q18: 37.57
A19: 04-03-2023 11:00 | B19: 91.76 | C19: 140.65 | D19: 140.02 | E19: 38.01 | F19: 37.55 | G19: 99.43 | H19: 59.03 | I19: 1.13 | J19: 1 | K19: 124.89 | L19: 34.31 | M19: 20.14 | N19: 549.5 | O19: 0 | P19: 1.95 | Q19: 37.09
A20: 04-03-2023 12:00 | B20: 0.31 | C20: 62.55 | D20: 34.63 | E20: 43.45 | F20: 44.25 | G20: 84.21 | H20: 55.52 | I20: 0.79 | J20: 1.09 | K20: 125.36 | L20: 35 | M20: 16.69 | N20: 571 | O20: 0 | P20: 0.55 | Q20: 16.41
... A32: 04-03-2023 24:00 | B32: 176.8 | C32: 113.77 | D32: 203.45 | E32: 5.18 | F32: 3.09 | G32: 207.57 | H32: 62.82 | I32: 1.52 | J32: 0.14 | K32: 306.5 | L32: 23.29 | M32: 51.01 | N32: 4.4 | O32: 0 | P32: 2.97 | Q32: 39.31
A34: Min | B34: =MIN(B9:B32) -> 0.31 | C34: =MIN(C9:C32) -> 62.55 | D34: =MIN(D9:D32) -> 34.63 | E34: =MIN(E9:E32) -> 4.72 | F34: =MIN(F9:F32) -> 2.89 | G34: =MIN(G9:G32) -> 42.63 | H34: =MIN(H9:H32) -> 14.75 | I34: =MIN(I9:I32) -> 0.55 | ... Q34: =MIN(Q9:Q32) -> 16.41
A35: Max | B35: =MAX(B9:B32) -> 202.05 | C35: =MAX(C9:C32) -> 140.65 | D35: =MAX(D9:D32) -> 224.45 | E35: =MAX(E9:E32) -> 43.45 | F35: =MAX(F9:F32) -> 44.25 | G35: =MAX(G9:G32) -> 207.57 | H35: =MAX(H9:H32) -> 75.78 | I35: =MAX(I9:I32) -> 1.97 | ... Q35: =MAX(Q9:Q32) -> 40.71
A36: Avg | B36: =AVERAGE(B9:B32) -> 100.56708 | C36: =AVERAGE(C9:C32) -> 101.53208 | D36: =AVERAGE(D9:D32) -> 135.74792 | E36: =AVERAGE(E9:E32) -> 11.95625 | F36: =AVERAGE(F9:F32) -> 11.819167 | G36: =AVERAGE(G9:G32) -> 139.60208 | H36: =AVERAGE(H9:H32) -> 54.800833 | I36: =AVERAGE(I9:I32) -> 1.3154167 | ... Q36: =AVERAGE(Q9:Q32) -> 32.069167
A37: Stdev | B37: =STDEV(B9:B32) -> 75.037969 | C37: =STDEV(C9:C32) -> 17.118847 | D37: =STDEV(D9:D32) -> 65.531724 | E37: =STDEV(E9:E32) -> 10.448377 | F37: =STDEV(F9:F32) -> 13.26262 | G37: =STDEV(G9:G32) -> 61.319989 | H37: =STDEV(H9:H32) -> 20.010768 | I37: =STDEV(I9:I32) -> 0.51192713 | ... Q37: =STDEV(Q9:Q32) -> 8.1146502
A38: Num | B38: =COUNT(B9:B32) -> 24 | C38: =COUNT(C9:C32) -> 24 | D38: =COUNT(D9:D32) -> 24 | E38: =COUNT(E9:E32) -> 24 | F38: =COUNT(F9:F32) -> 24 | G38: =COUNT(G9:G32) -> 24 | H38: =COUNT(H9:H32) -> 24 | I38: =COUNT(I9:I32) -> 24 | ... Q38: =COUNT(Q9:Q32) -> 24
A39: DCR | B39: =IF(B38>=22,">90%",IF(B38<=22,"<90%")) -> >90% | C39: =IF(C38>=22,">90%",IF(C38<=22,"<90%")) -> >90% | D39: =IF(D38>=22,">90%",IF(D38<=22,"<90%")) -> >90% | E39: =IF(E38>=22,">90%",IF(E38<=22,"<90%")) -> >90% | F39: =IF(F38>=22,">90%",IF(F38<=22,"<90%")) -> >90% | G39: =IF(G38>=22,">90%",IF(G38<=22,"<90%")) -> >90% | H39: =IF(H38>=22,">90%",IF(H38<=22,"<90%")) -> >90% | I39: =IF(I38>=22,">90%",IF(I38<=22,"<90%")) -> >90% | ... Q39: =IF(Q38>=22,">90%",IF(Q38<=22,"<90%")) -> >90%
A40: Status | B40: =IF(B38>=22,"OK",IF(B38<=22,"LESS")) -> OK | C40: =IF(C38>=22,"OK",IF(C38<=22,"LESS")) -> OK | D40: =IF(D38>=22,"OK",IF(D38<=22,"LESS")) -> OK | E40: =IF(E38>=22,"OK",IF(E38<=22,"LESS")) -> OK | F40: =IF(F38>=22,"OK",IF(F38<=22,"LESS")) -> OK | G40: =IF(G38>=22,"OK",IF(G38<=22,"LESS")) -> OK | H40: =IF(H38>=22,"OK",IF(H38<=22,"LESS")) -> OK | I40: =IF(I38>=22,"OK",IF(I38<=22,"LESS")) -> OK | ... Q40: =IF(Q38>=22,"OK",IF(Q38<=22,"LESS")) -> OK
A43: Done by | B43: RAHUL
A45: Comment

Sheet 05
A1: Station: | B1: BHATAGAON RAIPUR
A2: Date: | B2: =$A$9 -> 05-03-2023 01:00 | D2: Power Off | G2: Pw.Off | L2: Link Fail | N2: Link F | P2: Maintenance | R2: Maint.
A3: Report Type: | B3: Mean | D3: Calibration | G3: Calib. | L3: Data Fail | N3: Data F | P3: Invalid | R3: Invalid
A4: Time Base: | B4: 01 Hour | D4: Zero Referrence | G4: Z.Ref | L4: Warm Up | N4: Wm. Up
A7: Date & Time | B7: NO_BHATAGAON | C7: NO2_BHATAGAON | D7: NOX_BHATAGAON | E7: SO2_BHATAGAON | F7: O3_BHATAGAON | G7: PM10_BHATAGAON | H7: PM2_5_BHATAGAON | I7: BENZ_BHATAGAON | J7: WS_BHATAGAON | K7: WD_BHATAGAON | L7: TEMP_BHATAGAON | M7: HUM BHATAGAON | N7: SR_BHATAGAON | O7: RG_BHATAGAON | P7: CO_BHATAGAON | Q7: NH3_BHATAGAON
B8: ug/m3 | C8: ug/m3 | D8: ppb | E8: ug/m3 | F8: ug/m3 | G8: mg/m3 | H8: ug/m3 | I8: ug/m3 | J8: m/sec | K8: deg | L8: degreC | M8: % | N8: w/m2 | O8: mm | P8: ug/m3 | Q8: ug/m3
A9: 05-03-2023 01:00 | B9: 180.9 | C9: 111.58 | D9: 206.35 | E9: 6.98 | F9: 2.95 | G9: 158.53 | H9: 61.56 | I9: 1.49 | J9: 0.48 | K9: 60.62 | L9: 24.77 | M9: 52.8 | N9: 4.2 | O9: 0 | P9: 2.87 | Q9: 40.55
A10: 05-03-2023 02:00 | B10: 163.11 | C10: 110.63 | D10: 191.84 | E10: 7.46 | F10: 3.85 | G10: 158.53 | H10: 74.92 | I10: 1.48 | J10: 0.27 | K10: 151.39 | L10: 24.36 | M10: 38.74 | N10: 4.7 | O10: 0 | P10: 2.76 | Q10: 39.84
A11: 05-03-2023 03:00 | B11: 144.83 | C11: 108 | D11: 175.75 | E11: 5.91 | F11: 3.02 | G11: Maint. | H11: 77.58 | I11: 1.23 | J11: 0.17 | K11: 341.36 | L11: 21.95 | M11: 51.56 | N11: 4.8 | O11: 0 | P11: 2.51 | Q11: 37.82
A12: 05-03-2023 04:00 | B12: 134.61 | C12: 105.3 | D12: 165.73 | E12: 5.68 | F12: 3.08 | G12: 136.96 | H12: 77.58 | I12: 1.21 | J12: 0.35 | K12: 86.93 | L12: 23.62 | M12: 42.78 | N12: 4 | O12: 0 | P12: 2.3 | Q12: 38.67
A13: 05-03-2023 05:00 | B13: 109.19 | C13: 105.71 | D13: 145.05 | E13: 7.09 | F13: 3.1 | G13: 136.96 | H13: 73.53 | I13: 1.2 | J13: 0.49 | K13: 43.27 | L13: 23.47 | M13: 36.09 | N13: 4.3 | O13: 0 | P13: 2.16 | Q13: 38.34
A14: 05-03-2023 06:00 | B14: 87.5 | C14: 105.35 | D14: 128.31 | E14: 6.63 | F14: 3 | G14: 130.67 | H14: 65.31 | I14: 1.08 | J14: 0.59 | K14: 35.1 | L14: 23.4 | M14: 36.44 | N14: 4.6 | O14: 0 | P14: 2.17 | Q14: 36.17
A15: 05-03-2023 07:00 | B15: 76.39 | C15: 103.43 | D15: 118.34 | E15: 6.59 | F15: 3.14 | G15: 130.67 | H15: 63.81 | I15: 0.89 | J15: 0.42 | K15: 62.49 | L15: 23.08 | M15: 41.34 | N15: 51.1 | O15: 0 | P15: 2.14 | Q15: 34.86
A16: 05-03-2023 08:00 | B16: 76.07 | C16: 106.67 | D16: 118.6 | E16: 7.48 | F16: 3.25 | G16: Maint. | H16: 60.13 | I16: 0.87 | J16: 0.72 | K16: 30.71 | L16: 26.98 | M16: 39.79 | N16: 205.7 | O16: 0 | P16: 2.05 | Q16: 36.13
A17: 05-03-2023 09:00 | B17: 69.46 | C17: 111.52 | D17: 115.41 | E17: 7.32 | F17: 3.74 | G17: 114.71 | H17: 60.13 | I17: 0.82 | J17: 1.5 | K17: 102.11 | L17: 27.66 | M17: 34.27 | N17: 375.7 | O17: 0 | P17: 1.94 | Q17: 35.29
A18: 05-03-2023 10:00 | B18: 57.71 | C18: 113.29 | D18: 108.05 | E18: 5.52 | F18: 3.2 | G18: 114.71 | H18: 54.13 | I18: 0.75 | J18: 1.37 | K18: 99.55 | L18: 30.36 | M18: 32.16 | N18: 497.1 | O18: 0 | P18: 1.62 | Q18: 32.3
A19: 05-03-2023 11:00 | B19: 41.63 | C19: 113.66 | D19: 95.8 | E19: 5.65 | F19: 3.6 | G19: 77.3 | H19: 45.73 | I19: 0.66 | J19: 1.78 | K19: 116.45 | L19: 31.99 | M19: 26.63 | N19: 533 | O19: 0 | P19: 1.29 | Q19: 30.58
A20: 05-03-2023 12:00 | B20: 24.32 | C20: 116.75 | D20: 82.45 | E20: 5.96 | F20: 3.54 | G20: 63.52 | H20: 37.55 | I20: 0.63 | J20: 1.31 | K20: 129.16 | L20: 33.82 | M20: 22.19 | N20: 532.3 | O20: 0 | P20: 1.04 | Q20: 30.24
A21: 05-03-2023 13:00 | B21: 7.96 | C21: 117.29 | D21: 71.11 | E21: 6.14 | F21: 4.78 | G21: 59.75 | H21: 33.5 | I21: 0.59 | J21: 0.71 | K21: 351.36 | L21: 36.25 | M21: 18.06 | N21: 511.9 | O21: 0 | P21: 0.83 | Q21: 28.71
A22: 05-03-2023 14:00 | B22: 4.11 | C22: 114.98 | D22: 66.75 | E22: 7.76 | F22: 4.06 | G22: 49.63 | H22: 27.53 | I22: 0.6 | J22: 0.57 | K22: 353.69 | L22: 39.21 | M22: 15.2 | N22: 463.6 | O22: 0 | P22: 0.8 | Q22: 27.93
A23: 05-03-2023 15:00 | B23: 2.38 | C23: 110.69 | D23: 63 | E23: 6.57 | F23: 5.16 | G23: 50.38 | H23: 26.92 | I23: 0.68 | J23: 0.69 | K23: 261.12 | L23: 38.07 | M23: 15.21 | N23: 404 | O23: 0 | P23: 0.79 | Q23: 29.88
A24: 05-03-2023 16:00 | B24: 1.5 | C24: 104.78 | D24: 58.82 | E24: 5.92 | F24: 5 | G24: 52.83 | H24: 27.31 | I24: 0.63 | J24: 0.84 | K24: 349.11 | L24: 37.46 | M24: 14.93 | N24: 342.7 | O24: 0 | P24: 0.76 | Q24: 29.89
A25: 05-03-2023 17:00 | B25: 2.29 | C25: 104.99 | D25: 59.74 | E25: 6.17 | F25: 4.75 | G25: 52.83 | H25: 27.31 | I25: 0.59 | J25: 1.46 | K25: 356.6 | L25: 36.06 | M25: 17.53 | N25: 112.6 | O25: 0 | P25: 0.75 | Q25: 28.35
A26: 05-03-2023 18:00 | B26: 3.79 | C26: 106.87 | D26: 62.01 | E26: 5.85 | F26: 4.46 | G26: 51.13 | H26: 24.45 | I26: 0.58 | J26: 0.86 | K26: 19.39 | L26: 33.36 | M26: 21.46 | N26: 44.6 | O26: 0 | P26: 1.26 | Q26: 29.52
A27: 05-03-2023 19:00 | B27: 11.13 | C27: 122.68 | D27: 76.63 | E27: 6.59 | F27: 3.92 | G27: 79.14 | H27: 27.08 | I27: 0.83 | J27: 0.36 | K27: 95.37 | L27: 30.58 | M27: 27.96 | N27: 5.9 | O27: 0 | P27: 2.09 | Q27: 31.28
A28: 05-03-2023 20:00 | B28: 23.66 | C28: 129.42 | D28: 90.4 | E28: 6.93 | F28: 3.3 | G28: 135.47 | H28: 38.25 | I28: 1.08 | J28: 0.19 | K28: 239.32 | L28: 28.59 | M28: 41.27 | N28: 4.6 | O28: 0 | P28: 3.28 | Q28: 31.45
... A32: 05-03-2023 24:00 | B32: 103.09 | C32: 134.16 | D32: 156.71 | E32: 6.69 | F32: 3.49 | G32: 234.48 | H32: 78.51 | I32: 1.46 | J32: 0.55 | K32: 352.65 | L32: 25.36 | M32: 44.11 | N32: 4.5 | O32: 0 | P32: 2.34 | Q32: 37.79
A34: Min | B34: =MIN(B9:B32) -> 1.5 | C34: =MIN(C9:C32) -> 103.43 | D34: =MIN(D9:D32) -> 58.82 | E34: =MIN(E9:E32) -> 5.52 | F34: =MIN(F9:F32) -> 2.95 | G34: =MIN(G9:G32) -> 49.63 | H34: =MIN(H9:H32) -> 24.45 | I34: =MIN(I9:I32) -> 0.58 | ... Q34: =MIN(Q9:Q32) -> 27.93
A35: Max | B35: =MAX(B9:B32) -> 180.9 | C35: =MAX(C9:C32) -> 135.47 | D35: =MAX(D9:D32) -> 206.35 | E35: =MAX(E9:E32) -> 7.76 | F35: =MAX(F9:F32) -> 5.16 | G35: =MAX(G9:G32) -> 240.29 | H35: =MAX(H9:H32) -> 78.51 | I35: =MAX(I9:I32) -> 2.07 | ... Q35: =MAX(Q9:Q32) -> 40.55
A36: Avg | B36: =AVERAGE(B9:B32) -> 66.077917 | C36: =AVERAGE(C9:C32) -> 114.79875 | D36: =AVERAGE(D9:D32) -> 115.985 | E36: =AVERAGE(E9:E32) -> 6.5383333 | F36: =AVERAGE(F9:F32) -> 3.66625 | G36: =AVERAGE(G9:G32) -> 121.30045 | H36: =AVERAGE(H9:H32) -> 52.812917 | I36: =AVERAGE(I9:I32) -> 1.04875 | ... Q36: =AVERAGE(Q9:Q32) -> 34.023333
A37: Stdev | B37: =STDEV(B9:B32) -> 55.742232 | C37: =STDEV(C9:C32) -> 10.294697 | D37: =STDEV(D9:D32) -> 45.041041 | E37: =STDEV(E9:E32) -> 0.69902209 | F37: =STDEV(F9:F32) -> 0.68966793 | G37: =STDEV(G9:G32) -> 64.115414 | H37: =STDEV(H9:H32) -> 20.142162 | I37: =STDEV(I9:I32) -> 0.45585383 | ... Q37: =STDEV(Q9:Q32) -> 4.1451949
A38: Num | B38: =COUNT(B9:B32) -> 24 | C38: =COUNT(C9:C32) -> 24 | D38: =COUNT(D9:D32) -> 24 | E38: =COUNT(E9:E32) -> 24 | F38: =COUNT(F9:F32) -> 24 | G38: =COUNT(G9:G32)+2 -> 24 | H38: =COUNT(H9:H32) -> 24 | I38: =COUNT(I9:I32) -> 24 | J38: =COUNT(J9:J32) -> 24 | K38: =COUNT(K9:K32) -> 24 | L38: =COUNT(L9:L32) -> 24 | M38: =COUNT(M9:M32) -> 24 | N38: =COUNT(N9:N32) -> 24 | O38: =COUNT(O9:O32) -> 24 | ... Q38: =COUNT(Q9:Q32) -> 24
A39: DCR | B39: =IF(B38>=22,">90%",IF(B38<=22,"<90%")) -> >90% | C39: =IF(C38>=22,">90%",IF(C38<=22,"<90%")) -> >90% | D39: =IF(D38>=22,">90%",IF(D38<=22,"<90%")) -> >90% | E39: =IF(E38>=22,">90%",IF(E38<=22,"<90%")) -> >90% | F39: =IF(F38>=22,">90%",IF(F38<=22,"<90%")) -> >90% | G39: =IF(G38>=22,">90%",IF(G38<=22,"<90%")) -> >90% | H39: =IF(H38>=22,">90%",IF(H38<=22,"<90%")) -> >90% | I39: =IF(I38>=22,">90%",IF(I38<=22,"<90%")) -> >90% | ... Q39: =IF(Q38>=22,">90%",IF(Q38<=22,"<90%")) -> >90%
A40: Status | B40: =IF(B38>=22,"OK",IF(B38<=22,"LESS")) -> OK | C40: =IF(C38>=22,"OK",IF(C38<=22,"LESS")) -> OK | D40: =IF(D38>=22,"OK",IF(D38<=22,"LESS")) -> OK | E40: =IF(E38>=22,"OK",IF(E38<=22,"LESS")) -> OK | F40: =IF(F38>=22,"OK",IF(F38<=22,"LESS")) -> OK | G40: =IF(G38>=22,"OK",IF(G38<=22,"LESS")) -> OK | H40: =IF(H38>=22,"OK",IF(H38<=22,"LESS")) -> OK | I40: =IF(I38>=22,"OK",IF(I38<=22,"LESS")) -> OK | ... Q40: =IF(Q38>=22,"OK",IF(Q38<=22,"LESS")) -> OK
A43: Done by | B43: RAHUL
A45: Comment

Sheet 06
A1: Station: | B1: BHATAGAON RAIPUR
A2: Date: | B2: =$A$9 -> 06-03-2023 01:00 | D2: Power Off | G2: Pw.Off | L2: Link Fail | N2: Link F | P2: Maintenance | R2: Maint.
A3: Report Type: | B3: Mean | D3: Calibration | G3: Calib. | L3: Data Fail | N3: Data F | P3: Invalid | R3: Invalid
A4: Time Base: | B4: 01 Hour | D4: Zero Referrence | G4: Z.Ref | L4: Warm Up | N4: Wm. Up
A7: Date & Time | B7: NO_BHATAGAON | C7: NO2_BHATAGAON | D7: NOX_BHATAGAON | E7: SO2_BHATAGAON | F7: O3_BHATAGAON | G7: PM10_BHATAGAON | H7: PM2_5_BHATAGAON | I7: BENZ_BHATAGAON | J7: WS_BHATAGAON | K7: WD_BHATAGAON | L7: TEMP_BHATAGAON | M7: HUM BHATAGAON | N7: SR_BHATAGAON | O7: RG_BHATAGAON | P7: CO_BHATAGAON | Q7: NH3_BHATAGAON
B8: ug/m3 | C8: ug/m3 | D8: ppb | E8: ug/m3 | F8: ug/m3 | G8: mg/m3 | H8: ug/m3 | I8: ug/m3 | J8: m/sec | K8: deg | L8: degreC | M8: % | N8: w/m2 | O8: mm | P8: ug/m3 | Q8: ug/m3
A9: 06-03-2023 01:00 | B9: 92.62 | C9: 128.95 | D9: 145.43 | E9: 6.44 | F9: 3.71 | G9: 129.2 | H9: 72.84 | I9: 1.06 | J9: 0.9 | K9: 358.22 | L9: 25.13 | M9: 42.82 | N9: 4.6 | O9: 0 | P9: 2.4 | Q9: 37.17
A10: 06-03-2023 02:00 | B10: 74.26 | C10: 123.55 | D10: 127.74 | E10: 6.79 | F10: 3.02 | G10: 111.58 | H10: 69.02 | I10: 1.25 | J10: 0.58 | K10: 64.12 | L10: 24.3 | M10: 44.21 | N10: 4.8 | O10: 0 | P10: 2.41 | Q10: 37.74
A11: 06-03-2023 03:00 | B11: 54.32 | C11: 119.62 | D11: 109.58 | E11: 6.74 | F11: 3.06 | G11: 111.58 | H11: 62.86 | I11: 1.17 | J11: 0.16 | K11: 213.81 | L11: 24.16 | M11: 44.1 | N11: 4.7 | O11: 0 | P11: 2.08 | Q11: 36.65
A12: 06-03-2023 04:00 | B12: 44.6 | C12: 115.62 | D12: 99.57 | E12: 5.87 | F12: 3.34 | G12: 140.85 | H12: 64.87 | I12: 0.73 | J12: 0.34 | K12: 116.05 | L12: 23.54 | M12: 46.58 | N12: 4.6 | O12: 0 | P12: 1.86 | Q12: 34.93
A13: 06-03-2023 05:00 | B13: 41.64 | C13: 112.65 | D13: 95.56 | E13: 7.62 | F13: 3.11 | G13: 146.19 | H13: 66.31 | I13: 0.79 | J13: 0.23 | K13: 86.77 | L13: 23.34 | M13: 47.36 | N13: 4.5 | O13: 0 | P13: 1.81 | Q13: 36.79
A14: 06-03-2023 06:00 | B14: 44.23 | C14: 110.12 | D14: 96.16 | E14: 7.58 | F14: 3.05 | G14: 146.19 | H14: 66.31 | I14: 0.83 | J14: 0.19 | K14: 258.96 | L14: 22.7 | M14: 46.85 | N14: 4.5 | O14: 0 | P14: 1.75 | Q14: 36.76
A15: 06-03-2023 07:00 | B15: 45.58 | C15: 110.26 | D15: 96.52 | E15: 7.32 | F15: 3.57 | G15: 124.24 | H15: 60.79 | I15: 0.8 | J15: 0.66 | K15: 266.69 | L15: 22.38 | M15: 61.3 | N15: 48.5 | O15: 0 | P15: 1.65 | Q15: 35.89
A16: 06-03-2023 08:00 | B16: 44.88 | C16: 106.3 | D16: 94.65 | E16: 6.07 | F16: 3.12 | G16: 123.57 | H16: 58.48 | I16: 0.74 | J16: 0.38 | K16: 286.99 | L16: 24.55 | M16: 59.43 | N16: 199.9 | O16: 0 | P16: 1.58 | Q16: 33.72
A17: 06-03-2023 09:00 | B17: 41.49 | C17: 114.43 | D17: 92.15 | E17: 5.67 | F17: 3.03 | G17: 102.97 | H17: 56.08 | I17: 0.72 | J17: 0.39 | K17: 352.5 | L17: 29.72 | M17: 47.42 | N17: 360 | O17: 0 | P17: 1.61 | Q17: 35.47
A18: 06-03-2023 10:00 | B18: 33.81 | C18: 119.19 | D18: 91.81 | E18: 5.38 | F18: 2.9 | G18: 90.52 | H18: 54.24 | I18: 0.72 | J18: 1.77 | K18: 119.14 | L18: 30.07 | M18: 30.87 | N18: 525.7 | O18: 0 | P18: 1.56 | Q18: 35.29
A19: 06-03-2023 11:00 | B19: 18.97 | C19: 115.93 | D19: 79.2 | E19: 10.74 | F19: 10.18 | G19: 89.52 | H19: 51.8 | I19: 0.68 | J19: 1.84 | K19: 115.17 | L19: 32.56 | M19: 28.02 | N19: 584.5 | O19: 0 | P19: 1.26 | Q19: 31.56
A20: 06-03-2023 12:00 | B20: 2.63 | C20: 90.04 | D20: 51.8 | E20: 9.18 | F20: 7.68 | G20: 58.21 | H20: 41.39 | I20: 0.57 | J20: 1.09 | K20: 119.63 | L20: 35.7 | M20: 23.55 | N20: 586.1 | O20: 0 | P20: 0.68 | Q20: 19.3
... A24: 06-03-2023 16:00 | B24: 2.76 | C24: 84.48 | D24: 48.76 | E24: 7.98 | F24: 5.26 | G24: 50.78 | H24: 22.22 | I24: 0.5 | J24: 1.18 | K24: 359.64 | L24: 38.4 | M24: 15.26 | N24: 427.7 | O24: 0 | P24: 0.72 | Q24: 20.95
A25: 06-03-2023 17:00 | B25: 5.55 | C25: 89.53 | D25: 53.86 | E25: 5.16 | F25: 3.65 | G25: Maint. | H25: Maint. | I25: 0.53 | J25: 1.15 | K25: 354.95 | L25: 36.04 | M25: 18.03 | N25: 106.2 | O25: 0 | P25: 0.79 | Q25: 24.06
A26: 06-03-2023 18:00 | B26: 15.61 | C26: 117.78 | D26: 76.59 | E26: 5.51 | F26: 4.36 | G26: 63.05 | H26: 20.55 | I26: 0.55 | J26: 0.74 | K26: 84.65 | L26: 33.47 | M26: 22.02 | N26: 45.8 | O26: 0 | P26: 1.4 | Q26: 24.32
A27: 06-03-2023 19:00 | B27: 19.58 | C27: 119.47 | D27: 81.64 | E27: 4.96 | F27: 3.65 | G27: 62.23 | H27: 21.55 | I27: 0.99 | J27: 0.44 | K27: 87.5 | L27: 31.07 | M27: 25.79 | N27: 5.5 | O27: 0 | P27: 2.76 | Q27: 22.99
A28: 06-03-2023 20:00 | B28: 55.78 | C28: 122.4 | D28: 112.28 | E28: 5.05 | F28: 3.27 | G28: 77.91 | H28: 28.67 | I28: 1.21 | J28: 0.2 | K28: 340.43 | L28: 29.19 | M28: 37.37 | N28: 4.6 | O28: 0 | P28: 3.52 | Q28: 29.74
A29: 06-03-2023 21:00 | B29: 96.93 | C29: 123.94 | D29: 144.21 | E29: 6.25 | F29: 3.15 | G29: 167.43 | H29: 39.08 | I29: 1.59 | J29: 0.17 | K29: 343.73 | L29: 27.16 | M29: 40.65 | N29: 4.4 | O29: 0 | P29: 4.6 | Q29: 32.46
A30: 06-03-2023 22:00 | B30: 109.16 | C30: 118.99 | D30: 150.91 | E30: 6.56 | F30: 3.21 | G30: 163.59 | H30: 49.4 | I30: 1.48 | J30: 0.22 | K30: 313.19 | L30: 26.43 | M30: 44.86 | N30: 4.6 | O30: 0 | P30: 3.86 | Q30: 34.45
A31: 06-03-2023 23:00 | B31: 137.16 | C31: 113.69 | D31: 172.32 | E31: 7.2 | F31: 3.03 | G31: 164.7 | H31: 52.72 | I31: 1.68 | J31: 0.12 | K31: 352.62 | L31: 24.87 | M31: 49.98 | N31: 4.6 | O31: 0 | P31: 3.92 | Q31: 38.6
A32: 06-03-2023 24:00 | B32: 160.01 | C32: 116.64 | D32: 192.69 | E32: 7.82 | F32: 3.05 | G32: 228.95 | H32: 61.58 | I32: 1.54 | J32: 0.77 | K32: 307.69 | L32: 24.26 | M32: 53.42 | N32: 4.6 | O32: 0 | P32: 3.28 | Q32: 40
A34: Min | B34: =MIN(B9:B32) -> 0.9 | C34: =MIN(C9:C32) -> 84.48 | D34: =MIN(D9:D32) -> 48.76 | E34: =MIN(E9:E32) -> 4.96 | F34: =MIN(F9:F32) -> 2.9 | G34: =MIN(G9:G32) -> 50.78 | H34: =MIN(H9:H32) -> 20.55 | I34: =MIN(I9:I32) -> 0.5 | ... Q34: =MIN(Q9:Q32) -> 19.3
A35: Max | B35: =MAX(B9:B32) -> 160.01 | C35: =MAX(C9:C32) -> 128.95 | D35: =MAX(D9:D32) -> 192.69 | E35: =MAX(E9:E32) -> 19.13 | F35: =MAX(F9:F32) -> 22.91 | G35: =MAX(G9:G32) -> 228.95 | H35: =MAX(H9:H32) -> 72.84 | I35: =MAX(I9:I32) -> 1.68 | ... Q35: =MAX(Q9:Q32) -> 40
A36: Avg | B36: =AVERAGE(B9:B32) -> 47.86875 | C36: =AVERAGE(C9:C32) -> 110.57833 | D36: =AVERAGE(D9:D32) -> 98.895833 | E36: =AVERAGE(E9:E32) -> 7.2304167 | F36: =AVERAGE(F9:F32) -> 4.8533333 | G36: =AVERAGE(G9:G32) -> 116.08652 | H36: =AVERAGE(H9:H32) -> 47.694783 | I36: =AVERAGE(I9:I32) -> 0.90708333 | ... Q36: =AVERAGE(Q9:Q32) -> 31.014583
A37: Stdev | B37: =STDEV(B9:B32) -> 44.024856 | C37: =STDEV(C9:C32) -> 12.791174 | D37: =STDEV(D9:D32) -> 39.860601 | E37: =STDEV(E9:E32) -> 2.8710511 | F37: =STDEV(F9:F32) -> 4.2270204 | G37: =STDEV(G9:G32) -> 44.092806 | H37: =STDEV(H9:H32) -> 17.811479 | I37: =STDEV(I9:I32) -> 0.37603745 | ... Q37: =STDEV(Q9:Q32) -> 6.8344536
A38: Num | B38: =COUNT(B9:B32) -> 24 | C38: =COUNT(C9:C32) -> 24 | D38: =COUNT(D9:D32) -> 24 | E38: =COUNT(E9:E32) -> 24 | F38: =COUNT(F9:F32) -> 24 | G38: =COUNT(G9:G32)+1 -> 24 | H38: =COUNT(H9:H32)+1 -> 24 | I38: =COUNT(I9:I32) -> 24 | J38: =COUNT(J9:J32) -> 24 | K38: =COUNT(K9:K32) -> 24 | L38: =COUNT(L9:L32) -> 24 | M38: =COUNT(M9:M32) -> 24 | N38: =COUNT(N9:N32) -> 24 | O38: =COUNT(O9:O32) -> 24 | P38: =COUNT(P9:P32) -> 24 | Q38: =COUNT(Q9:Q32) -> 24
A39: DCR | B39: =IF(B38>=22,">90%",IF(B38<=22,"<90%")) -> >90% | C39: =IF(C38>=22,">90%",IF(C38<=22,"<90%")) -> >90% | D39: =IF(D38>=22,">90%",IF(D38<=22,"<90%")) -> >90% | E39: =IF(E38>=22,">90%",IF(E38<=22,"<90%")) -> >90% | F39: =IF(F38>=22,">90%",IF(F38<=22,"<90%")) -> >90% | G39: =IF(G38>=22,">90%",IF(G38<=22,"<90%")) -> >90% | H39: =IF(H38>=22,">90%",IF(H38<=22,"<90%")) -> >90% | I39: =IF(I38>=22,">90%",IF(I38<=22,"<90%")) -> >90% | ... Q39: =IF(Q38>=22,">90%",IF(Q38<=22,"<90%")) -> >90%
A40: Status | B40: =IF(B38>=22,"OK",IF(B38<=22,"LESS")) -> OK | C40: =IF(C38>=22,"OK",IF(C38<=22,"LESS")) -> OK | D40: =IF(D38>=22,"OK",IF(D38<=22,"LESS")) -> OK | E40: =IF(E38>=22,"OK",IF(E38<=22,"LESS")) -> OK | F40: =IF(F38>=22,"OK",IF(F38<=22,"LESS")) -> OK | G40: =IF(G38>=22,"OK",IF(G38<=22,"LESS")) -> OK | H40: =IF(H38>=22,"OK",IF(H38<=22,"LESS")) -> OK | I40: =IF(I38>=22,"OK",IF(I38<=22,"LESS")) -> OK | ... Q40: =IF(Q38>=22,"OK",IF(Q38<=22,"LESS")) -> OK
A43: Done by | B43: RAHUL
A45: Comment

Sheet 07
A1: Station: | B1: BHATAGAON RAIPUR
A2: Date: | B2: =$A$9 -> 07-03-2023 01:00 | D2: Power Off | G2: Pw.Off | L2: Link Fail | N2: Link F | P2: Maintenance | R2: Maint.
A3: Report Type: | B3: Mean | D3: Calibration | G3: Calib. | L3: Data Fail | N3: Data F | P3: Invalid | R3: Invalid
A4: Time Base: | B4: 01 Hour | D4: Zero Referrence | G4: Z.Ref | L4: Warm Up | N4: Wm. Up
A7: Date & Time | B7: NO_BHATAGAON | C7: NO2_BHATAGAON | D7: NOX_BHATAGAON | E7: SO2_BHATAGAON | F7: O3_BHATAGAON | G7: PM10_BHATAGAON | H7: PM2_5_BHATAGAON | I7: BENZ_BHATAGAON | J7: WS_BHATAGAON | K7: WD_BHATAGAON | L7: TEMP_BHATAGAON | M7: HUM BHATAGAON | N7: SR_BHATAGAON | O7: RG_BHATAGAON | P7: CO_BHATAGAON | Q7: NH3_BHATAGAON
B8: ug/m3 | C8: ug/m3 | D8: ppb | E8: ug/m3 | F8: ug/m3 | G8: mg/m3 | H8: ug/m3 | I8: ug/m3 | J8: m/sec | K8: deg | L8: degreC | M8: % | N8: w/m2 | O8: mm | P8: ug/m3 | Q8: ug/m3
A9: 07-03-2023 01:00 | B9: 156.19 | C9: 117.34 | D9: 190.01 | E9: 5.07 | F9: 2.96 | G9: 197.63 | H9: 65.19 | I9: 1.54 | J9: 0.92 | K9: 37.2 | L9: 24.64 | M9: 46.6 | N9: 4.1 | O9: 0 | P9: 2.7 | Q9: 39.36
A10: 07-03-2023 02:00 | B10: 127.77 | C10: 112.42 | D10: 164.5 | E10: 5.23 | F10: 3.3 | G10: 72.18 | H10: 58.5 | I10: 1.17 | J10: 0.66 | K10: 78.24 | L10: 25.27 | M10: 43.7 | N10: 4.7 | O10: 0 | P10: 2.27 | Q10: 37.06
A11: 07-03-2023 03:00 | B11: 105.88 | C11: 110.94 | D11: 145.89 | E11: 5.91 | F11: 3.1 | G11: 143.26 | H11: 58.5 | I11: 1.2 | J11: 0.51 | K11: 195.31 | L11: 24.16 | M11: 46.45 | N11: 4.5 | O11: 0 | P11: 2.44 | Q11: 38
A12: 07-03-2023 04:00 | B12: 78.77 | C12: 111.31 | D12: 124.6 | E12: 5.64 | F12: 2.88 | G12: 68.65 | H12: 58.59 | I12: 1.16 | J12: 0.36 | K12: 353.38 | L12: 23.46 | M12: 57.46 | N12: 4.9 | O12: 0 | P12: 2.34 | Q12: 37.22
A13: 07-03-2023 05:00 | B13: 64.17 | C13: 107.26 | D13: 110.65 | E13: 4.95 | F13: 3.23 | G13: 131.88 | H13: 52.78 | I13: 0.88 | J13: 0.65 | K13: 359.35 | L13: 22 | M13: 58.64 | N13: 4.4 | O13: 0 | P13: 2.09 | Q13: 34.85
A14: 07-03-2023 06:00 | B14: 57.33 | C14: 104.42 | D14: 103.6 | E14: 5.92 | F14: 3.08 | G14: 188.65 | H14: 49.95 | I14: 0.81 | J14: 0.69 | K14: 348.09 | L14: 21.59 | M14: 57.03 | N14: 4.5 | O14: 0 | P14: 1.88 | Q14: 36.39
A15: 07-03-2023 07:00 | B15: 58.89 | C15: 106.12 | D15: 105.79 | E15: 7.7 | F15: 3.14 | G15: 55.63 | H15: 53.04 | I15: 0.82 | J15: 0.8 | K15: 358.82 | L15: 22.32 | M15: 51.87 | N15: 48.9 | O15: 0 | P15: 1.83 | Q15: 36.09
A16: 07-03-2023 08:00 | B16: 65.14 | C16: 107.1 | D16: 110.7 | E16: 7.29 | F16: 3.55 | G16: Invalid | H16: Invalid | I16: 0.77 | J16: 1.08 | K16: 23.19 | L16: 27.2 | M16: 41.65 | N16: 170.9 | O16: 0 | P16: 1.89 | Q16: 35.44
A17: 07-03-2023 09:00 | B17: 64.58 | C17: 106.17 | D17: 110.38 | E17: 7.07 | F17: 3.41 | G17: Invalid | H17: Invalid | I17: 0.71 | J17: 1.01 | K17: 29.46 | L17: 29.54 | M17: 29.8 | N17: 312.4 | O17: 0 | P17: 1.97 | Q17: 33.32
A18: 07-03-2023 10:00 | B18: 55.98 | C18: 111.19 | D18: 103.72 | E18: 6.77 | F18: 3.26 | G18: Invalid | H18: Invalid | I18: 0.69 | J18: 1.31 | K18: 47.64 | L18: 31.16 | M18: 28.38 | N18: 379.2 | O18: 0 | P18: 1.79 | Q18: 33.14
A19: 07-03-2023 11:00 | B19: 32.71 | C19: 115.85 | D19: 88.08 | E19: 6.02 | F19: 3.2 | G19: Invalid | H19: Invalid | I19: 0.68 | J19: 1.98 | K19: 29.28 | L19: 34.05 | M19: 26.09 | N19: 528.9 | O19: 0 | P19: 1.5 | Q19: 31.52
A20: 07-03-2023 12:00 | B20: 11.73 | C20: 116.2 | D20: 73.35 | E20: 4.81 | F20: 3.46 | G20: 86.24 | H20: 39.45 | I20: 0.61 | J20: 1.95 | K20: 36 | L20: 35.67 | M20: 21.55 | N20: 529.3 | O20: 0 | P20: 1.21 | Q20: 28.08
A21: 07-03-2023 13:00 | B21: 4.56 | C21: 113.13 | D21: 66.09 | E21: 6.26 | F21: 4.06 | G21: 71.61 | H21: 32.53 | I21: 0.58 | J21: 1.78 | K21: 33.68 | L21: 36.79 | M21: 19.87 | N21: 475.2 | O21: 0 | P21: 1.05 | Q21: 27.86
A22: 07-03-2023 14:00 | B22: 2.52 | C22: 110.44 | D22: 62.97 | E22: 6.9 | F22: 4.54 | G22: 3.96 | H22: 28.12 | I22: 0.6 | J22: 1.45 | K22: 27.49 | L22: 36.96 | M22: 20.37 | N22: 473.4 | O22: 0 | P22: 0.98 | Q22: 28.71
A23: 07-03-2023 15:00 | B23: 1.46 | C23: 102.15 | D23: 57.29 | E23: 5.99 | F23: 4.74 | G23: 162.39 | H23: 27.28 | I23: 0.57 | J23: 1.48 | K23: 32.65 | L23: 36.39 | M23: 19.88 | N23: 468.5 | O23: 0 | P23: 0.89 | Q23: 27.81
A24: 07-03-2023 16:00 | B24: 2.04 | C24: 99.58 | D24: 56.3 | E24: 5.49 | F24: 4.39 | G24: 40.78 | H24: 23.62 | I24: 0.55 | J24: 1.71 | K24: 31.94 | L24: 35.7 | M24: 21.97 | N24: 373.2 | O24: 0 | P24: 0.81 | Q24: 26.25
A25: 07-03-2023 17:00 | B25: 1.98 | C25: 99.42 | D25: 56.45 | E25: 6.18 | F25: 4.74 | G25: Invalid | H25: Invalid | I25: 0.57 | J25: 1.48 | K25: 23.56 | L25: 33.55 | M25: 23.73 | N25: 128 | O25: 0 | P25: 0.79 | Q25: 28.63
A26: 07-03-2023 18:00 | B26: 1.54 | C26: 98.57 | D26: 55.58 | E26: 5.89 | F26: 4.71 | G26: Invalid | H26: Invalid | I26: 0.57 | J26: 1.2 | K26: 20.39 | L26: 31.1 | M26: 27.83 | N26: 42.5 | O26: 0 | P26: 0.79 | Q26: 28.44
A27: 07-03-2023 19:00 | B27: 3.45 | C27: 103.03 | D27: 59.63 | E27: 5.11 | F27: 4.41 | G27: Invalid | H27: Invalid | I27: 0.58 | J27: 1.01 | K27: 36.39 | L27: 29.37 | M27: 31.02 | N27: 5.1 | O27: 0 | P27: 1 | Q27: 27.74
A28: 07-03-2023 20:00 | B28: 3.59 | C28: 103.19 | D28: 59.82 | E28: 5.21 | F28: 3.51 | G28: Invalid | H28: Invalid | I28: 0.58 | J28: 0.92 | K28: 19.55 | L28: 27.98 | M28: 37.45 | N28: 4.3 | O28: 0 | P28: 0.84 | Q28: 28.2
A29: 07-03-2023 21:00 | B29: 3.2 | C29: 101.91 | D29: 58.41 | E29: 5.62 | F29: 3.71 | G29: Invalid | H29: Invalid | I29: 0.58 | J29: 1.34 | K29: 13.65 | L29: 26.6 | M29: 38.47 | N29: 4.3 | O29: 0 | P29: 0.85 | Q29: 29.08
A30: 07-03-2023 22:00 | B30: 4.17 | C30: 105.22 | D30: 61.41 | E30: 5.69 | F30: 3.38 | G30: Invalid | H30: Invalid | I30: 0.58 | J30: 1.43 | K30: 11.42 | L30: 25.86 | M30: 42.47 | N30: 4.6 | O30: 0 | P30: 0.92 | Q30: 28.51
A31: 07-03-2023 23:00 | B31: 4.64 | C31: 106.41 | D31: 62.36 | E31: 4.76 | F31: 3.22 | G31: 37.35 | H31: 24.75 | I31: 0.58 | J31: 1.44 | K31: 33.27 | L31: 24.88 | M31: 43 | N31: 4.4 | O31: 0 | P31: 0.99 | Q31: 26.95
A32: 07-03-2023 24:00 | B32: 5.42 | C32: 104.43 | D32: 61.94 | E32: 4.88 | F32: 3.32 | G32: 52.75 | H32: 24.48 | I32: 0.56 | J32: 1.09 | K32: 38.06 | L32: 24.35 | M32: 43.86 | N32: 4.2 | O32: 0 | P32: 1.08 | Q32: 29.46
A34: Min | B34: =MIN(B9:B32) -> 1.46 | C34: =MIN(C9:C32) -> 98.57 | D34: =MIN(D9:D32) -> 55.58 | E34: =MIN(E9:E32) -> 4.76 | F34: =MIN(F9:F32) -> 2.88 | G34: =MIN(G9:G32) -> 3.96 | H34: =MIN(H9:H32) -> 23.62 | I34: =MIN(I9:I32) -> 0.55 | ... Q34: =MIN(Q9:Q32) -> 26.25
A35: Max | B35: =MAX(B9:B32) -> 156.19 | C35: =MAX(C9:C32) -> 117.34 | D35: =MAX(D9:D32) -> 190.01 | E35: =MAX(E9:E32) -> 7.7 | F35: =MAX(F9:F32) -> 4.74 | G35: =MAX(G9:G32) -> 197.63 | H35: =MAX(H9:H32) -> 65.19 | I35: =MAX(I9:I32) -> 1.54 | ... Q35: =MAX(Q9:Q32) -> 39.36
A36: Avg | B36: =AVERAGE(B9:B32) -> 38.237917 | C36: =AVERAGE(C9:C32) -> 107.24167 | D36: =AVERAGE(D9:D32) -> 89.563333 | E36: =AVERAGE(E9:E32) -> 5.8483333 | F36: =AVERAGE(F9:F32) -> 3.6375 | G36: =AVERAGE(G9:G32) -> 93.782857 | H36: =AVERAGE(H9:H32) -> 42.627143 | I36: =AVERAGE(I9:I32) -> 0.7475 | ... Q36: =AVERAGE(Q9:Q32) -> 31.587917
A37: Stdev | B37: =STDEV(B9:B32) -> 45.115868 | C37: =STDEV(C9:C32) -> 5.4394818 | D37: =STDEV(D9:D32) -> 37.913124 | E37: =STDEV(E9:E32) -> 0.82070313 | F37: =STDEV(F9:F32) -> 0.6145005 | G37: =STDEV(G9:G32) -> 60.28053 | H37: =STDEV(H9:H32) -> 15.445049 | I37: =STDEV(I9:I32) -> 0.26339341 | ... Q37: =STDEV(Q9:Q32) -> 4.1775913
A38: Num | B38: =COUNT(B9:B32) -> 24 | C38: =COUNT(C9:C32) -> 24 | D38: =COUNT(D9:D32) -> 24 | E38: =COUNT(E9:E32) -> 24 | F38: =COUNT(F9:F32) -> 24 | G38: =COUNT(G9:G32) -> 14 | H38: =COUNT(H9:H32) -> 14 | I38: =COUNT(I9:I32) -> 24 | ... Q38: =COUNT(Q9:Q32) -> 24
A39: DCR | B39: =IF(B38>=22,">90%",IF(B38<=22,"<90%")) -> >90% | C39: =IF(C38>=22,">90%",IF(C38<=22,"<90%")) -> >90% | D39: =IF(D38>=22,">90%",IF(D38<=22,"<90%")) -> >90% | E39: =IF(E38>=22,">90%",IF(E38<=22,"<90%")) -> >90% | F39: =IF(F38>=22,">90%",IF(F38<=22,"<90%")) -> >90% | G39: =IF(G38>=22,">90%",IF(G38<=22,"<90%")) -> <90% | H39: =IF(H38>=22,">90%",IF(H38<=22,"<90%")) -> <90% | I39: =IF(I38>=22,">90%",IF(I38<=22,"<90%")) -> >90% | ... Q39: =IF(Q38>=22,">90%",IF(Q38<=22,"<90%")) -> >90%
A40: Status | B40: =IF(B38>=22,"OK",IF(B38<=22,"LESS")) -> OK | C40: =IF(C38>=22,"OK",IF(C38<=22,"LESS")) -> OK | D40: =IF(D38>=22,"OK",IF(D38<=22,"LESS")) -> OK | E40: =IF(E38>=22,"OK",IF(E38<=22,"LESS")) -> OK | F40: =IF(F38>=22,"OK",IF(F38<=22,"LESS")) -> OK | G40: =IF(G38>=22,"OK",IF(G38<=22,"LESS")) -> LESS | H40: =IF(H38>=22,"OK",IF(H38<=22,"LESS")) -> LESS | I40: =IF(I38>=22,"OK",IF(I38<=22,"LESS")) -> OK | ... Q40: =IF(Q38>=22,"OK",IF(Q38<=22,"LESS")) -> OK
A43: Done by | B43: RAHUL
A45: Comment

Sheet 08
A1: Station: | B1: BHATAGAON RAIPUR
A2: Date: | B2: =$A$9 -> 08-03-2023 01:00 | D2: Power Off | G2: Pw.Off | L2: Link Fail | N2: Link F | P2: Maintenance | R2: Maint.
A3: Report Type: | B3: Mean | D3: Calibration | G3: Calib. | L3: Data Fail | N3: Data F | P3: Invalid | R3: Invalid
A4: Time Base: | B4: 01 Hour | D4: Zero Referrence | G4: Z.Ref | L4: Warm Up | N4: Wm. Up
A7: Date & Time | B7: NO_BHATAGAON | C7: NO2_BHATAGAON | D7: NOX_BHATAGAON | E7: SO2_BHATAGAON | F7: O3_BHATAGAON | G7: PM10_BHATAGAON | H7: PM2_5_BHATAGAON | I7: BENZ_BHATAGAON | J7: WS_BHATAGAON | K7: WD_BHATAGAON | L7: TEMP_BHATAGAON | M7: HUM BHATAGAON | N7: SR_BHATAGAON | O7: RG_BHATAGAON | P7: CO_BHATAGAON | Q7: NH3_BHATAGAON
B8: ug/m3 | C8: ug/m3 | D8: ppb | E8: ug/m3 | F8: ug/m3 | G8: mg/m3 | H8: ug/m3 | I8: ug/m3 | J8: m/sec | K8: deg | L8: degreC | M8: % | N8: w/m2 | O8: mm | P8: ug/m3 | Q8: ug/m3
A9: 08-03-2023 01:00 | B9: 5.18 | C9: 104.84 | D9: 62.02 | E9: 6.12 | F9: 3.38 | G9: 55.84 | H9: 26.86 | I9: 0.56 | J9: 0.71 | K9: 56.14 | L9: 24.58 | M9: 43.01 | N9: 4.7 | O9: 0 | P9: 1.14 | Q9: 30.06
A10: 08-03-2023 02:00 | B10: 4.51 | C10: 104.54 | D10: 61.19 | E10: 5.71 | F10: 3.06 | G10: 62.07 | H10: 25.72 | I10: 0.56 | J10: 1.21 | K10: 358.98 | L10: 24.2 | M10: 46.26 | N10: 6.6 | O10: 0.6 | P10: 1.14 | Q10: 29.9
A11: 08-03-2023 03:00 | B11: 5.64 | C11: 100.15 | D11: 59.07 | E11: 4.49 | F11: 3.11 | G11: 48.99 | H11: 26.63 | I11: 0.54 | J11: 1.68 | K11: 70.9 | L11: 21.66 | M11: 74.25 | N11: 8.5 | O11: 2 | P11: 1.06 | Q11: 28.57
A12: 08-03-2023 04:00 | B12: 5.81 | C12: 94.25 | D12: 56.6 | E12: 4.53 | F12: 3.06 | G12: 67.24 | H12: 26.39 | I12: 0.55 | J12: 0.58 | K12: 220.9 | L12: 21.23 | M12: 69.86 | N12: 6.7 | O12: 0 | P12: 1.02 | Q12: 30.33
A13: 08-03-2023 05:00 | B13: 7.33 | C13: 94.38 | D13: 57.61 | E13: 4.71 | F13: 3.25 | G13: 73.13 | H13: 28.13 | I13: 0.55 | J13: 0.99 | K13: 235.45 | L13: 20.97 | M13: 72.74 | N13: 5.2 | O13: 0 | P13: 1 | Q13: 30.54
A14: 08-03-2023 06:00 | B14: 8.99 | C14: 91.88 | D14: 57.73 | E14: 4.39 | F14: 2.95 | G14: 46.73 | H14: 26.26 | I14: 0.54 | J14: 0.32 | K14: 342.56 | L14: 20.8 | M14: 74.29 | N14: 5 | O14: 0 | P14: 0.93 | Q14: 29.95
A15: 08-03-2023 07:00 | B15: 14.13 | C15: 91.54 | D15: 61.77 | E15: 4.54 | F15: 2.95 | G15: 43.2 | H15: 25.28 | I15: 0.55 | J15: 0.13 | K15: 234.62 | L15: 20.61 | M15: 80.75 | N15: 54.7 | O15: 0 | P15: 0.95 | Q15: 31.74
A16: 08-03-2023 08:00 | B16: 15.9 | C16: 91.61 | D16: 62.68 | E16: 4.64 | F16: 2.94 | G16: 57.56 | H16: 25.01 | I16: 0.57 | J16: 0.19 | K16: 45.31 | L16: 23.99 | M16: 75.34 | N16: 178.8 | O16: 0 | P16: 0.99 | Q16: 31.94
A17: 08-03-2023 09:00 | B17: 14.21 | C17: 95.33 | D17: 63.52 | E17: 4.03 | F17: 3.09 | G17: 57.06 | H17: 25.73 | I17: 0.57 | J17: 0.28 | K17: 319.34 | L17: 24.97 | M17: 58.51 | N17: 444.4 | O17: 0 | P17: 0.99 | Q17: 31.59
A18: 08-03-2023 10:00 | B18: 12.89 | C18: 98.26 | D18: 63.72 | E18: 4.25 | F18: 2.96 | G18: 14.53 | H18: 26.84 | I18: 0.57 | J18: 0.86 | K18: 344.6 | L18: 29.72 | M18: 48.53 | N18: 636.3 | O18: 0 | P18: 0.98 | Q18: 31.48
A19: 08-03-2023 11:00 | B19: 10.93 | C19: 104.41 | D19: 63.13 | E19: 4.9 | F19: 3.37 | G19: 109.94 | H19: 27.77 | I19: 0.59 | J19: 0.52 | K19: 232.03 | L19: 33.37 | M19: 46.34 | N19: 765.2 | O19: 0 | P19: 1 | Q19: 33.56
A20: 08-03-2023 12:00 | B20: 2.78 | C20: 105.51 | D20: 60.46 | E20: 4.6 | F20: 3.96 | G20: 71.47 | H20: 31.26 | I20: 0.58 | J20: 0.48 | K20: 333.45 | L20: 33.76 | M20: 33.77 | N20: 829.8 | O20: 0 | P20: 1 | Q20: 33.53
... A32: 08-03-2023 24:00 | B32: 15.73 | C32: 101.7 | D32: 68.26 | E32: 3.58 | F32: 3.22 | G32: 51.38 | H32: 24.06 | I32: 0.71 | J32: 0.14 | K32: 332.52 | L32: 23.68 | M32: 60.06 | N32: 4.9 | O32: 0 | P32: 1.25 | Q32: 34.68
A34: Min | B34: =MIN(B9:B32) -> 1.2 | C34: =MIN(C9:C32) -> 90.39 | D34: =MIN(D9:D32) -> 51.53 | E34: =MIN(E9:E32) -> 3.28 | F34: =MIN(F9:F32) -> 2.93 | G34: =MIN(G9:G32) -> 14.53 | H34: =MIN(H9:H32) -> 17.62 | I34: =MIN(I9:I32) -> 0.51 | ... Q34: =MIN(Q9:Q32) -> 28.57
A35: Max | B35: =MAX(B9:B32) -> 15.9 | C35: =MAX(C9:C32) -> 105.51 | D35: =MAX(D9:D32) -> 68.26 | E35: =MAX(E9:E32) -> 6.12 | F35: =MAX(F9:F32) -> 4.68 | G35: =MAX(G9:G32) -> 109.94 | H35: =MAX(H9:H32) -> 33.79 | I35: =MAX(I9:I32) -> 0.93 | ... Q35: =MAX(Q9:Q32) -> 36.53
A36: Avg | B36: =AVERAGE(B9:B32) -> 7.4866667 | C36: =AVERAGE(C9:C32) -> 97.65875 | D36: =AVERAGE(D9:D32) -> 59.520417 | E36: =AVERAGE(E9:E32) -> 4.2379167 | F36: =AVERAGE(F9:F32) -> 3.5620833 | G36: =AVERAGE(G9:G32) -> 50.979583 | H36: =AVERAGE(H9:H32) -> 25.793333 | I36: =AVERAGE(I9:I32) -> 0.60708333 | ... Q36: =AVERAGE(Q9:Q32) -> 32.47125
A37: Stdev | B37: =STDEV(B9:B32) -> 5.2204536 | C37: =STDEV(C9:C32) -> 4.9818979 | D37: =STDEV(D9:D32) -> 4.8974914 | E37: =STDEV(E9:E32) -> 0.68415596 | F37: =STDEV(F9:F32) -> 0.61817388 | G37: =STDEV(G9:G32) -> 19.330771 | H37: =STDEV(H9:H32) -> 4.1975652 | I37: =STDEV(I9:I32) -> 0.098708141 | ... Q37: =STDEV(Q9:Q32) -> 2.0258446
A38: Num | B38: =COUNT(B9:B32) -> 24 | C38: =COUNT(C9:C32) -> 24 | D38: =COUNT(D9:D32) -> 24 | E38: =COUNT(E9:E32) -> 24 | F38: =COUNT(F9:F32) -> 24 | G38: =COUNT(G9:G32) -> 24 | H38: =COUNT(H9:H32) -> 24 | I38: =COUNT(I9:I32) -> 24 | ... Q38: =COUNT(Q9:Q32) -> 24
A39: DCR | B39: =IF(B38>=22,">90%",IF(B38<=22,"<90%")) -> >90% | C39: =IF(C38>=22,">90%",IF(C38<=22,"<90%")) -> >90% | D39: =IF(D38>=22,">90%",IF(D38<=22,"<90%")) -> >90% | E39: =IF(E38>=22,">90%",IF(E38<=22,"<90%")) -> >90% | F39: =IF(F38>=22,">90%",IF(F38<=22,"<90%")) -> >90% | G39: =IF(G38>=22,">90%",IF(G38<=22,"<90%")) -> >90% | H39: =IF(H38>=22,">90%",IF(H38<=22,"<90%")) -> >90% | I39: =IF(I38>=22,">90%",IF(I38<=22,"<90%")) -> >90% | ... Q39: =IF(Q38>=22,">90%",IF(Q38<=22,"<90%")) -> >90%
A40: Status | B40: =IF(B38>=22,"OK",IF(B38<=22,"LESS")) -> OK | C40: =IF(C38>=22,"OK",IF(C38<=22,"LESS")) -> OK | D40: =IF(D38>=22,"OK",IF(D38<=22,"LESS")) -> OK | E40: =IF(E38>=22,"OK",IF(E38<=22,"LESS")) -> OK | F40: =IF(F38>=22,"OK",IF(F38<=22,"LESS")) -> OK | G40: =IF(G38>=22,"OK",IF(G38<=22,"LESS")) -> OK | H40: =IF(H38>=22,"OK",IF(H38<=22,"LESS")) -> OK | I40: =IF(I38>=22,"OK",IF(I38<=22,"LESS")) -> OK | ... Q40: =IF(Q38>=22,"OK",IF(Q38<=22,"LESS")) -> OK
A43: Done by | B43: RAHUL
A45: Comment

Sheet 09
A1: Station: | B1: BHATAGAON RAIPUR
A2: Date: | B2: =$A$9 -> 09-03-2023 01:00 | D2: Power Off | G2: Pw.Off | L2: Link Fail | N2: Link F | P2: Maintenance | R2: Maint.
A3: Report Type: | B3: Mean | D3: Calibration | G3: Calib. | L3: Data Fail | N3: Data F | P3: Invalid | R3: Invalid
A4: Time Base: | B4: 01 Hour | D4: Zero Referrence | G4: Z.Ref | L4: Warm Up | N4: Wm. Up
A7: Date & Time | B7: NO_BHATAGAON | C7: NO2_BHATAGAON | D7: NOX_BHATAGAON | E7: SO2_BHATAGAON | F7: O3_BHATAGAON | G7: PM10_BHATAGAON | H7: PM2_5_BHATAGAON | I7: BENZ_BHATAGAON | J7: WS_BHATAGAON | K7: WD_BHATAGAON | L7: TEMP_BHATAGAON | M7: HUM BHATAGAON | N7: SR_BHATAGAON | O7: RG_BHATAGAON | P7: CO_BHATAGAON | Q7: NH3_BHATAGAON
B8: ug/m3 | C8: ug/m3 | D8: ppb | E8: ug/m3 | F8: ug/m3 | G8: mg/m3 | H8: ug/m3 | I8: ug/m3 | J8: m/sec | K8: deg | L8: degreC | M8: % | N8: w/m2 | O8: mm | P8: ug/m3 | Q8: ug/m3
