Workbook

Sheet 01
A1: Station: | B1: BHATAGAON RAIPPUR
A2: Date: | B2: =$A$9 -> 01-03-2023 00:15 | D2: Power Off | G2: Pw.Off | L2: Link Fail | N2: Link F | P2: Maintenance | R2: Maint.
A3: Report Type: | B3: Mean | D3: Calibration | G3: Calib. | L3: Data Fail | N3: Data F | P3: Invalid | R3: Invalid
A4: Time Base: | B4: 15 Min | D4: Zero Referrence | G4: Z.Ref | L4: Warm Up | N4: Wm. Up
A7: Date & Time | B7: NO_BHATAGAON | C7: NO2__BHATAGAON | D7: NOX_BHATAGAON | E7: SO2__BHATAGAON | F7: O3__BHATAGAON | G7: PM10__BHATAGAON | H7: PM2_5__BHATAGAON | I7: BENZ__BHATAGAON | J7: WS__BHATAGAON | K7: WD__BHATAGAON | L7: TEMP__BHATAGAON | M7: HUM__BHATAGAON | N7: SR__BHATAGAON | O7: RG__BHATAGAON | P7: CO__BHATAGAON | Q7: NH3__BHATAGAON
B8: ug/m3 | C8: ug/m3 | D8: ppb | E8: ug/m3 | F8: ug/m3 | G8: ug/m3 | H8: ug/m3 | I8: ug/m3 | J8: m/sec | K8: deg | L8: degreC | M8: % | N8: w/m2 | O8: mm | P8: mg/m3 | Q8: ug/m3
A9: 01-03-2023 00:15 | B9: 113.61 | C9: 128.97 | D9: 161.25 | E9: 3.83 | F9: 4.3 | G9: 174.34 | H9: 66.95 | I9: 1.51 | J9: 0.03 | K9: 30.05 | L9: 22.82 | M9: 54.47 | N9: 3.5 | O9: 0 | P9: 3.29 | Q9: 37.31
A10: 01-03-2023 00:30 | B10: 112.17 | C10: 128.68 | D10: 159.93 | E10: 3.66 | F10: 4.3 | G10: 174.34 | H10: 66.95 | I10: 1.53 | J10: 0.06 | K10: 164.68 | L10: 22.48 | M10: 57.24 | N10: 4.5 | O10: 0 | P10: 3.23 | Q10: 37.23
A11: 01-03-2023 00:45 | B11: 108.79 | C11: 127.35 | D11: 156.48 | E11: 3.24 | F11: 4.3 | G11: 153.53 | H11: 62.36 | I11: 1.52 | J11: 0.06 | K11: 346.95 | L11: 22.42 | M11: 55.31 | N11: 4.1 | O11: 0 | P11: 3.15 | Q11: 36.87
A12: 01-03-2023 01:00 | B12: 95.19 | C12: 125.65 | D12: 144.63 | E12: 3.04 | F12: 4.3 | G12: 143.64 | H12: 60.07 | I12: 1.5 | J12: 0.03 | K12: 132.2 | L12: 22.38 | M12: 53.93 | N12: 3.9 | O12: 0 | P12: 2.96 | Q12: 36.21
A13: 01-03-2023 01:15 | B13: 94.16 | C13: 123.72 | D13: 142.74 | E13: 3.61 | F13: 4.3 | G13: 143.64 | H13: 60.07 | I13: 1.48 | J13: 0.05 | K13: 226.41 | L13: 23.12 | M13: 49.92 | N13: 3.5 | O13: 0 | P13: 2.6 | Q13: 35.45
A14: 01-03-2023 01:30 | B14: 89.71 | C14: 119.88 | D14: 137.06 | E14: 3.65 | F14: 4.3 | G14: 143.64 | H14: 60.07 | I14: 1.44 | J14: 0.08 | K14: 357.7 | L14: 22.7 | M14: 53.78 | N14: 4.5 | O14: 0 | P14: 2.65 | Q14: 35.11
A15: 01-03-2023 01:45 | B15: 88.32 | C15: 116.78 | D15: 134.23 | E15: 3.57 | F15: 4.33 | G15: 117.05 | H15: 57.6 | I15: 1.43 | J15: 0.29 | K15: 5.78 | L15: 22.38 | M15: 56.58 | N15: 4.4 | O15: 0 | P15: 2.6 | Q15: 34.98
A16: 01-03-2023 02:00 | B16: 81.81 | C16: 112.72 | D16: 126.77 | E16: 3.21 | F16: 4.84 | G16: 103.76 | H16: 56.37 | I16: 1.41 | J16: 0.04 | K16: 335.18 | L16: 21.86 | M16: 55.99 | N16: 4.2 | O16: 0 | P16: 2.47 | Q16: 34.9
A17: 01-03-2023 02:15 | B17: 76.78 | C17: 110.38 | D17: 121.44 | E17: 3.6 | F17: 5.29 | G17: 103.76 | H17: 56.37 | I17: 1.39 | J17: 0.15 | K17: 18.23 | L17: 21.71 | M17: 55.28 | N17: 4.4 | O17: 0 | P17: 2.4 | Q17: 34.8
A18: 01-03-2023 02:30 | B18: 69.61 | C18: 112.95 | D18: 117.11 | E18: 4.24 | F18: 4.9 | G18: 103.76 | H18: 56.37 | I18: 1.35 | J18: 0.06 | K18: 194.32 | L18: 22.02 | M18: 51.67 | N18: 4.1 | O18: 0 | P18: 2.3 | Q18: 34.91
A19: 01-03-2023 02:45 | B19: 73.22 | C19: 113.66 | D19: 120.41 | E19: 4.4 | F19: 4.4 | G19: 96.35 | H19: 51.79 | I19: 1.32 | J19: 0.13 | K19: 217.94 | L19: 22.07 | M19: 51.93 | N19: 4.3 | O19: 0 | P19: 2.34 | Q19: 35.15
A20: 01-03-2023 03:00 | B20: 72.97 | C20: 113.24 | D20: 119.97 | E20: 3.53 | F20: 4.3 | G20: 92.65 | H20: 49.5 | I20: 1.22 | J20: 0.3 | K20: 258.4 | L20: 22.06 | M20: 53.38 | N20: 3.7 | O20: 0 | P20: 2.31 | Q20: 35.93
... A104: 01-03-2023 24:00 | B104: 38.56 | C104: 122.74 | D104: 97.61 | E104: 18.81 | F104: 12.52 | G104: 114.24 | H104: 60.41 | I104: 1.05 | J104: 1.05 | K104: 15.98 | L104: 26.73 | M104: 37.3 | N104: 4.2 | O104: 0 | P104: 2.35 | Q104: 32.12
A106: Min | B106: =MIN(B9:B104) -> 1.3 | C106: =MIN(C9:C104) -> 55.97 | D106: =MIN(D9:D104) -> 31.11 | E106: =MIN(E9:E104) -> 2.95 | F106: =MIN(F9:F104) -> 4.3 | G106: =MIN(G9:G104) -> 34.85 | H106: =MIN(H9:H104) -> 14.41 | I106: =MIN(I9:I104) -> 0.47 | ... Q106: =MIN(Q9:Q104) -> 15.5
A107: Max | B107: =MAX(B9:B104) -> 113.61 | C107: =MAX(C9:C104) -> 148.32 | D107: =MAX(D9:D104) -> 161.25 | E107: =MAX(E9:E104) -> 31.95 | F107: =MAX(F9:F104) -> 63.33 | G107: =MAX(G9:G104) -> 296.78 | H107: =MAX(H9:H104) -> 136.25 | I107: =MAX(I9:I104) -> 1.53 | ... Q107: =MAX(Q9:Q104) -> 37.31
A108: Avg | B108: =AVERAGE(B9:B104) -> 52.425208 | C108: =AVERAGE(C9:C104) -> 108.0476 | D108: =AVERAGE(D9:D104) -> 100.6276 | E108: =AVERAGE(E9:E104) -> 8.5639583 | F108: =AVERAGE(F9:F104) -> 11.576771 | G108: =AVERAGE(G9:G104) -> 129.99792 | H108: =AVERAGE(H9:H104) -> 59.900417 | I108: =AVERAGE(I9:I104) -> 0.97083333 | ... Q108: =AVERAGE(Q9:Q104) -> 30.007917
A109: Stdev | B109: =STDEV(B9:B104) -> 36.063854 | C109: =STDEV(C9:C104) -> 28.253752 | D109: =STDEV(D9:D104) -> 42.200419 | E109: =STDEV(E9:E104) -> 5.5348742 | F109: =STDEV(F9:F104) -> 11.256452 | G109: =STDEV(G9:G104) -> 64.641219 | H109: =STDEV(H9:H104) -> 27.770265 | I109: =STDEV(I9:I104) -> 0.33298543 | ... Q109: =STDEV(Q9:Q104) -> 6.4220374
A110: Num | B110: =COUNT(B9:B104) -> 96 | C110: =COUNT(C9:C104) -> 96 | D110: =COUNT(D9:D104) -> 96 | E110: =COUNT(E9:E104) -> 96 | F110: =COUNT(F9:F104) -> 96 | G110: =COUNT(G9:G104) -> 96 | H110: =COUNT(H9:H104) -> 96 | I110: =COUNT(I9:I104) -> 96 | ... Q110: =COUNT(Q9:Q104) -> 96
A111: DCR | B111: =IF(B110>=87,">90%",IF(B110<=87,"<90%")) -> >90% | C111: =IF(C110>=87,">90%",IF(C110<=87,"<90%")) -> >90% | D111: =IF(D110>=87,">90%",IF(D110<=87,"<90%")) -> >90% | E111: =IF(E110>=87,">90%",IF(E110<=87,"<90%")) -> >90% | F111: =IF(F110>=87,">90%",IF(F110<=87,"<90%")) -> >90% | G111: =IF(G110>=87,">90%",IF(G110<=87,"<90%")) -> >90% | H111: =IF(H110>=87,">90%",IF(H110<=87,"<90%")) -> >90% | I111: =IF(I110>=87,">90%",IF(I110<=87,"<90%")) -> >90% | ... Q111: =IF(Q110>=87,">90%",IF(Q110<=87,"<90%")) -> >90%
A112: Status | B112: =IF(B110>=87,"OK",IF(B110<=87,"LESS")) -> OK | C112: =IF(C110>=87,"OK",IF(C110<=87,"LESS")) -> OK | D112: =IF(D110>=87,"OK",IF(D110<=87,"LESS")) -> OK | E112: =IF(E110>=87,"OK",IF(E110<=87,"LESS")) -> OK | F112: =IF(F110>=87,"OK",IF(F110<=87,"LESS")) -> OK | G112: =IF(G110>=87,"OK",IF(G110<=87,"LESS")) -> OK | H112: =IF(H110>=87,"OK",IF(H110<=87,"LESS")) -> OK | I112: =IF(I110>=87,"OK",IF(I110<=87,"LESS")) -> OK | ... Q112: =IF(Q110>=87,"OK",IF(Q110<=87,"LESS")) -> OK
A115: Done by | B115: RK
A117: Comment

Sheet 02
A1: Station: | B1: BHATAGAON RAIPUR
A2: Date: | B2: =$A$9 -> 02-03-2023 00:15 | D2: Power Off | G2: Pw.Off | L2: Link Fail | N2: Link F | P2: Maintenance | R2: Maint.
A3: Report Type: | B3: Mean | D3: Calibration | G3: Calib. | L3: Data Fail | N3: Data F | P3: Invalid | R3: Invalid
A4: Time Base: | B4: 15 Min | D4: Zero Referrence | G4: Z.Ref | L4: Warm Up | N4: Wm. Up
A7: Date & Time | B7: NO_BHATAGAON | C7: NO2__BHATAGAON | D7: NOX_BHATAGAON | E7: SO2__BHATAGAON | F7: O3__BHATAGAON | G7: PM10__BHATAGAON | H7: PM2_5__BHATAGAON | I7: BENZ__BHATAGAON | J7: WS__BHATAGAON | K7: WD__BHATAGAON | L7: TEMP__BHATAGAON | M7: HUM__BHATAGAON | N7: SR__BHATAGAON | O7: RG__BHATAGAON | P7: CO__BHATAGAON | Q7: NH3__BHATAGAON
B8: ug/m3 | C8: ug/m3 | D8: ppb | E8: ug/m3 | F8: ug/m3 | G8: ug/m3 | H8: ug/m3 | I8: ug/m3 | J8: m/sec | K8: deg | L8: degreC | M8: % | N8: w/m2 | O8: mm | P8: mg/m3 | Q8: ug/m3
A9: 02-03-2023 00:15 | B9: 39.32 | C9: 129.52 | D9: 101.97 | E9: 10.57 | F9: 6.96 | G9: 114.24 | H9: 60.41 | I9: 1.02 | J9: 0.78 | K9: 16.44 | L9: 26.47 | M9: 38.1 | N9: 4.5 | O9: 0 | P9: 2.36 | Q9: 32.08
A10: 02-03-2023 00:30 | B10: 36.98 | C10: 130.42 | D10: 100.59 | E10: 8.94 | F10: 5.04 | G10: 114.24 | H10: 60.41 | I10: 1.01 | J10: 0.81 | K10: 16.8 | L10: 26.1 | M10: 40.25 | N10: 4.5 | O10: 0 | P10: 2.3 | Q10: 32.92
A11: 02-03-2023 00:45 | B11: 33.6 | C11: 129.82 | D11: 97.55 | E11: 9.84 | F11: 4.81 | G11: 113.88 | H11: 56.96 | I11: 1.03 | J11: 0.69 | K11: 16.76 | L11: 25.72 | M11: 42.09 | N11: 4.6 | O11: 0 | P11: 2.23 | Q11: 33.05
A12: 02-03-2023 01:00 | B12: 31.46 | C12: 129.56 | D12: 95.69 | E12: 8.74 | F12: 4.37 | G12: 113.7 | H12: 55.32 | I12: 0.95 | J12: 0.63 | K12: 17.96 | L12: 25.44 | M12: 43.24 | N12: 4.5 | O12: 0 | P12: 2.16 | Q12: 33.03
A13: 02-03-2023 01:15 | B13: 28.29 | C13: 128.05 | D13: 92.31 | E13: 10.02 | F13: 4.51 | G13: 113.7 | H13: 55.32 | I13: 0.9 | J13: 0.19 | K13: 48.62 | L13: 25.19 | M13: 44.34 | N13: 4.7 | O13: 0 | P13: 2.03 | Q13: 32.97
A14: 02-03-2023 01:30 | B14: 26.37 | C14: 127.89 | D14: 90.68 | E14: 8.72 | F14: 4.54 | G14: 113.7 | H14: 55.32 | I14: 0.88 | J14: 0.59 | K14: 211.32 | L14: 24.97 | M14: 44.78 | N14: 4.1 | O14: 0 | P14: 2.04 | Q14: 32.89
A15: 02-03-2023 01:45 | B15: 25.07 | C15: 127.77 | D15: 89.57 | E15: 7.59 | F15: 4.5 | G15: 138.43 | H15: 59.46 | I15: 0.85 | J15: 0.26 | K15: 231.07 | L15: 24.18 | M15: 48.05 | N15: 5.1 | O15: 0 | P15: 2 | Q15: 32.57
A16: 02-03-2023 02:00 | B16: 22.95 | C16: 124.13 | D16: 85.86 | E16: 6.38 | F16: 4.36 | G16: 150.8 | H16: 61.53 | I16: 0.83 | J16: 0.51 | K16: 207.03 | L16: 23.62 | M16: 50.39 | N16: 4.6 | O16: 0 | P16: 1.95 | Q16: 31.86
A17: 02-03-2023 02:15 | B17: 20.6 | C17: 117.39 | D17: 80.26 | E17: 5.45 | F17: 5.16 | G17: 150.8 | H17: 61.53 | I17: 0.82 | J17: 0.11 | K17: 322.57 | L17: 23.3 | M17: 51.65 | N17: 4.8 | O17: 0 | P17: 1.89 | Q17: 31.11
A18: 02-03-2023 02:30 | B18: 19.76 | C18: 115.16 | D18: 78.36 | E18: 5.76 | F18: 5.25 | G18: 150.8 | H18: 61.53 | I18: 0.8 | J18: 0.09 | K18: 313 | L18: 22.56 | M18: 55.38 | N18: 4.8 | O18: 0 | P18: 1.84 | Q18: 30.78
A19: 02-03-2023 02:45 | B19: 19.55 | C19: 110.13 | D19: 75.41 | E19: 5.83 | F19: 5.87 | G19: 117.14 | H19: 56.32 | I19: 0.78 | J19: 0.16 | K19: 331.8 | L19: 22.26 | M19: 55.98 | N19: 4.5 | O19: 0 | P19: 1.79 | Q19: 30.91
A20: 02-03-2023 03:00 | B20: 20.52 | C20: 113.07 | D20: 77.81 | E20: 4.8 | F20: 5.02 | G20: 100.32 | H20: 53.72 | I20: 0.76 | J20: 0.18 | K20: 308.56 | L20: 22.11 | M20: 58.61 | N20: 4.4 | O20: 0 | P20: 1.81 | Q20: 31.16
... A104: 02-03-2023 24:00 | B104: 114.1 | C104: 140.5 | D104: 168 | E104: 5.01 | F104: 4.32 | G104: 196.63 | H104: 76.91 | I104: 1.47 | J104: 0.1 | K104: 27.84 | L104: 23.54 | M104: 63.52 | N104: 4.6 | O104: 0 | P104: 3.5 | Q104: 37.23
A106: Min | B106: =MIN(B9:B104) -> 2.85 | C106: =MIN(C9:C104) -> 102.08 | D106: =MIN(D9:D104) -> 60.67 | E106: =MIN(E9:E104) -> 2.55 | F106: =MIN(F9:F104) -> 4.3 | G106: =MIN(G9:G104) -> 50.99 | H106: =MIN(H9:H104) -> 26.61 | I106: =MIN(I9:I104) -> 0.6 | ... Q106: =MIN(Q9:Q104) -> 29.28
A107: Max | B107: =MAX(B9:B104) -> 127.69 | C107: =MAX(C9:C104) -> 159.53 | D107: =MAX(D9:D104) -> 182.96 | E107: =MAX(E9:E104) -> 29.69 | F107: =MAX(F9:F104) -> 27.55 | G107: =MAX(G9:G104) -> 297.24 | H107: =MAX(H9:H104) -> 134.31 | I107: =MAX(I9:I104) -> 1.51 | ... Q107: =MAX(Q9:Q104) -> 38.26
A108: Avg | B108: =AVERAGE(B9:B104) -> 34.283437 | C108: =AVERAGE(C9:C104) -> 123.66031 | D108: =AVERAGE(D9:D104) -> 94.695104 | E108: =AVERAGE(E9:E104) -> 9.0703125 | F108: =AVERAGE(F9:F104) -> 8.0680208 | G108: =AVERAGE(G9:G104) -> 120.12375 | H108: =AVERAGE(H9:H104) -> 56.708854 | I108: =AVERAGE(I9:I104) -> 0.85791667 | ... Q108: =AVERAGE(Q9:Q104) -> 32.965938
A109: Stdev | B109: =STDEV(B9:B104) -> 28.928496 | C109: =STDEV(C9:C104) -> 15.211547 | D109: =STDEV(D9:D104) -> 28.98395 | E109: =STDEV(E9:E104) -> 5.2639186 | F109: =STDEV(F9:F104) -> 6.024104 | G109: =STDEV(G9:G104) -> 49.445016 | H109: =STDEV(H9:H104) -> 21.54652 | I109: =STDEV(I9:I104) -> 0.24586653 | ... Q109: =STDEV(Q9:Q104) -> 2.1320114
A110: Num | B110: =COUNT(B9:B104) -> 96 | C110: =COUNT(C9:C104) -> 96 | D110: =COUNT(D9:D104) -> 96 | E110: =COUNT(E9:E104) -> 96 | F110: =COUNT(F9:F104) -> 96 | G110: =COUNT(G9:G104) -> 96 | H110: =COUNT(H9:H104) -> 96 | I110: =COUNT(I9:I104) -> 96 | ... Q110: =COUNT(Q9:Q104) -> 96
A111: DCR | B111: =IF(B110>=87,">90%",IF(B110<=87,"<90%")) -> >90% | C111: =IF(C110>=87,">90%",IF(C110<=87,"<90%")) -> >90% | D111: =IF(D110>=87,">90%",IF(D110<=87,"<90%")) -> >90% | E111: =IF(E110>=87,">90%",IF(E110<=87,"<90%")) -> >90% | F111: =IF(F110>=87,">90%",IF(F110<=87,"<90%")) -> >90% | G111: =IF(G110>=87,">90%",IF(G110<=87,"<90%")) -> >90% | H111: =IF(H110>=87,">90%",IF(H110<=87,"<90%")) -> >90% | I111: =IF(I110>=87,">90%",IF(I110<=87,"<90%")) -> >90% | ... Q111: =IF(Q110>=87,">90%",IF(Q110<=87,"<90%")) -> >90%
A112: Status | B112: =IF(B110>=87,"OK",IF(B110<=87,"LESS")) -> OK | C112: =IF(C110>=87,"OK",IF(C110<=87,"LESS")) -> OK | D112: =IF(D110>=87,"OK",IF(D110<=87,"LESS")) -> OK | E112: =IF(E110>=87,"OK",IF(E110<=87,"LESS")) -> OK | F112: =IF(F110>=87,"OK",IF(F110<=87,"LESS")) -> OK | G112: =IF(G110>=87,"OK",IF(G110<=87,"LESS")) -> OK | H112: =IF(H110>=87,"OK",IF(H110<=87,"LESS")) -> OK | I112: =IF(I110>=87,"OK",IF(I110<=87,"LESS")) -> OK | ... Q112: =IF(Q110>=87,"OK",IF(Q110<=87,"LESS")) -> OK
A115: Done by | B115: RK
A117: Comment

Sheet 03
A1: Station: | B1: BHATAGAON RAIPUR
A2: Date: | B2: =$A$9 -> 03-03-2023 00:15 | D2: Power Off | G2: Pw.Off | L2: Link Fail | N2: Link F | P2: Maintenance | R2: Maint.
A3: Report Type: | B3: Mean | D3: Calibration | G3: Calib. | L3: Data Fail | N3: Data F | P3: Invalid | R3: Invalid
A4: Time Base: | B4: 15 Min | D4: Zero Referrence | G4: Z.Ref | L4: Warm Up | N4: Wm. Up
A7: Date & Time | B7: NO_BHATAGAON | C7: NO2__BHATAGAON | D7: NOX_BHATAGAON | E7: SO2__BHATAGAON | F7: O3__BHATAGAON | G7: PM10__BHATAGAON | H7: PM2_5__BHATAGAON | I7: BENZ__BHATAGAON | J7: WS__BHATAGAON | K7: WD__BHATAGAON | L7: TEMP__BHATAGAON | M7: HUM__BHATAGAON | N7: SR__BHATAGAON | O7: RG__BHATAGAON | P7: CO__BHATAGAON | Q7: NH3__BHATAGAON
B8: ug/m3 | C8: ug/m3 | D8: ppb | E8: ug/m3 | F8: ug/m3 | G8: ug/m3 | H8: ug/m3 | I8: ug/m3 | J8: m/sec | K8: deg | L8: degreC | M8: % | N8: w/m2 | O8: mm | P8: mg/m3 | Q8: ug/m3
A9: 03-03-2023 00:15 | B9: 105.39 | C9: 139.24 | D9: 160.32 | E9: 10.02 | F9: 4.32 | G9: 196.63 | H9: 76.91 | I9: 1.51 | J9: 0.13 | K9: 26.76 | L9: 23.63 | M9: 62.17 | N9: 4.4 | O9: 0 | P9: 3.41 | Q9: 37.84
A10: 03-03-2023 00:30 | B10: 99.49 | C10: 135.63 | D10: 153.59 | E10: 12.1 | F10: 4.32 | G10: 196.63 | H10: 76.91 | I10: 1.5 | J10: 0.18 | K10: 40.23 | L10: 23.65 | M10: 60.54 | N10: 4.4 | O10: 0 | P10: 3.35 | Q10: 38.45
A11: 03-03-2023 00:45 | B11: 93.2 | C11: 133.36 | D11: 147.29 | E11: 14.92 | F11: 4.35 | G11: 202.16 | H11: 84.59 | I11: 1.49 | J11: 0.32 | K11: 18.14 | L11: 23.71 | M11: 59.41 | N11: 3.9 | O11: 0 | P11: 3.24 | Q11: 38.82
A12: 03-03-2023 01:00 | B12: 93.26 | C12: 131.42 | D12: 146.28 | E12: 15.03 | F12: 5.2 | G12: 204.8 | H12: 88.42 | I12: 1.48 | J12: 0.66 | K12: 15.97 | L12: 23.78 | M12: 54.61 | N12: 3.3 | O12: 0 | P12: 3.14 | Q12: 38.93
A13: 03-03-2023 01:15 | B13: 94.2 | C13: 128.5 | D13: 145.41 | E13: 14.98 | F13: 6.11 | G13: 204.8 | H13: 88.42 | I13: 1.43 | J13: 0.66 | K13: 6.72 | L13: 23.83 | M13: 52.24 | N13: 3.5 | O13: 0 | P13: 2.85 | Q13: 38.92
A14: 03-03-2023 01:30 | B14: 97.93 | C14: 128.64 | D14: 148.48 | E14: 8.18 | F14: 4.83 | G14: 204.8 | H14: 88.42 | I14: 1.41 | J14: 0.51 | K14: 2.08 | L14: 24.06 | M14: 52.39 | N14: 4.1 | O14: 0 | P14: 3.03 | Q14: 39.42
A15: 03-03-2023 01:45 | B15: 88.94 | C15: 127.04 | D15: 140.39 | E15: 7.89 | F15: 4.47 | G15: 199.36 | H15: 91.03 | I15: 1.43 | J15: 0.55 | K15: 13.79 | L15: 24.12 | M15: 50.76 | N15: 3.9 | O15: 0 | P15: 2.91 | Q15: 39.27
A16: 03-03-2023 02:00 | B16: 83 | C16: 129.35 | D16: 136.91 | E16: 7.26 | F16: 4.32 | G16: 196.78 | H16: 92.33 | I16: 1.42 | J16: 0.39 | K16: 11.83 | L16: 24.14 | M16: 49.82 | N16: 4.5 | O16: 0 | P16: 2.78 | Q16: 39.04
A17: 03-03-2023 02:15 | B17: 76.93 | C17: 129 | D17: 131.84 | E17: 6.73 | F17: 4.39 | G17: 196.78 | H17: 92.33 | I17: 1.37 | J17: 0.39 | K17: 34.3 | L17: 24.07 | M17: 48.64 | N17: 4.2 | O17: 0 | P17: 2.67 | Q17: 38.59
A18: 03-03-2023 02:30 | B18: 69.75 | C18: 126.22 | D18: 124.55 | E18: 5.73 | F18: 4.38 | G18: 196.78 | H18: 92.33 | I18: 1.31 | J18: 0.44 | K18: 66.39 | L18: 24.49 | M18: 46.27 | N18: 4 | O18: 0 | P18: 2.57 | Q18: 38
A19: 03-03-2023 02:45 | B19: 62.97 | C19: 125.23 | D19: 118.57 | E19: 6.77 | F19: 4.33 | G19: 167.93 | H19: 85.84 | I19: 1.26 | J19: 0.39 | K19: 44.46 | L19: 24.29 | M19: 47.77 | N19: 4.5 | O19: 0 | P19: 2.47 | Q19: 37.32
A20: 03-03-2023 03:00 | B20: 52.59 | C20: 121.85 | D20: 108.37 | E20: 17.62 | F20: 4.56 | G20: 153.51 | H20: 82.59 | I20: 1.2 | J20: 0.28 | K20: 61.14 | L20: 23.82 | M20: 49.74 | N20: 4.6 | O20: 0 | P20: 2.32 | Q20: 36.62
... A54: 03-03-2023 11:30 | B54: 1.43 | C54: 47.82 | D54: 26.49 | E54: 316.24 | F54: 28.95 | G54: 105.89 | H54: 51.64 | I54: 0.45 | J54: 0.54 | K54: 158.28 | L54: 33.47 | M54: 23.08 | N54: 509 | O54: 0 | P54: 0.51 | Q54: 11.89
A55: 03-03-2023 11:45 | B55: 2.74 | C55: 54.29 | D55: 31.11 | E55: 252.22 | F55: 25.29 | G55: Calib. | H55: Calib. | I55: 0.45 | J55: 0.58 | K55: 67.74 | L55: 34.21 | M55: 21.54 | N55: 511.8 | O55: 0 | P55: Calib. | Q55: 12.72
A56: 03-03-2023 12:00 | B56: 3.06 | C56: 59.99 | D56: 34.51 | E56: 17.29 | F56: 22.71 | G56: Calib. | H56: Calib. | I56: 0.47 | J56: 0.74 | K56: 107.96 | L56: 35.33 | M56: 21.04 | N56: 504.9 | O56: 0 | P56: 0.35 | Q56: 14.39
A57: 03-03-2023 12:15 | B57: 3.03 | C57: 69.5 | D57: 39.74 | E57: 19.09 | F57: 26.76 | G57: Calib. | H57: Calib. | I57: 0.48 | J57: 0.68 | K57: 18.89 | L57: 36.48 | M57: 20.34 | N57: 497.2 | O57: 0 | P57: 4.49 | Q57: 15.74
A58: 03-03-2023 12:30 | B58: 3.86 | C58: 71.84 | D58: 41.7 | E58: 27.8 | F58: 38.22 | G58: Invalid | H58: Invalid | I58: 0.49 | J58: 0.96 | K58: 2.81 | L58: 38.36 | M58: 17.99 | N58: 489.1 | O58: 0 | P58: 3.96 | Q58: 17.25
A59: 03-03-2023 12:45 | B59: 91.55 | C59: 19.74 | D59: 84.26 | E59: 37.1 | F59: 55.08 | G59: 64.18 | H59: 39.37 | I59: 0.5 | J59: 1.24 | K59: 8.4 | L59: 39 | M59: 16.79 | N59: 483.3 | O59: 0 | P59: 0.8 | Q59: 17.1
A60: 03-03-2023 13:00 | B60: 152.5 | C60: 12.19 | D60: 129.02 | E60: 24.86 | F60: 40.46 | G60: 64.18 | H60: 39.37 | I60: 0.49 | J60: 0.42 | K60: 43.13 | L60: 37.97 | M60: 17.65 | N60: 455.4 | O60: 0 | P60: 0.82 | Q60: 16.5
A61: 03-03-2023 13:15 | B61: 174.79 | C61: 13.59 | D61: 147.67 | E61: 30.9 | F61: 40.25 | G61: 64.18 | H61: 39.37 | I61: 0.48 | J61: 0.91 | K61: 95.23 | L61: 36.91 | M61: 17.89 | N61: 445.2 | O61: 0 | P61: 0.73 | Q61: 17.78
A62: 03-03-2023 13:30 | B62: 186.41 | C62: 14.87 | D62: 157.7 | E62: 14.74 | F62: 22.35 | G62: 64.41 | H62: 39.03 | I62: 0.48 | J62: 0.56 | K62: 93.41 | L62: 35.05 | M62: 20.13 | N62: 357.4 | O62: 0 | P62: 0.77 | Q62: 17.8
A63: 03-03-2023 13:45 | B63: 3.27 | C63: 54 | D63: 32.42 | E63: 44.27 | F63: 33.99 | G63: 67.12 | H63: 35.09 | I63: 0.48 | J63: 0.99 | K63: 11.67 | L63: 37.58 | M63: 17.31 | N63: 343 | O63: 0 | P63: 0.79 | Q63: 18.39
A64: 03-03-2023 14:00 | B64: 4.34 | C64: 66.01 | D64: 39.84 | E64: 38.19 | F64: 49.42 | G64: 67.12 | H64: 35.09 | I64: 0.5 | J64: 0.94 | K64: 45 | L64: 36.72 | M64: 16.21 | N64: 390.3 | O64: 0 | P64: 0.76 | Q64: 19.34
A65: 03-03-2023 14:15 | B65: 4.6 | C65: 74.9 | D65: 45.02 | E65: 19.16 | F65: 22.09 | G65: 67.12 | H65: 35.09 | I65: 0.49 | J65: 1.38 | K65: 2.88 | L65: 38.75 | M65: 12.49 | N65: 437.6 | O65: 0 | P65: 0.77 | Q65: 17.93
A66: 03-03-2023 14:30 | B66: 2.12 | C66: 67.17 | D66: 38.77 | E66: 17.09 | F66: 23.63 | G66: 66.84 | H66: 35.18 | I66: 0.49 | J66: 1.85 | K66: 13.2 | L66: 39.12 | M66: 11.19 | N66: 421 | O66: 0 | P66: 0.75 | Q66: 17.26
A67: 03-03-2023 14:45 | B67: 3.7 | C67: 67.78 | D67: 40.37 | E67: 12.92 | F67: 12.2 | G67: 63.54 | H67: 36.25 | I67: 0.54 | J67: 1.59 | K67: 12.54 | L67: 38.58 | M67: 11.39 | N67: 401.2 | O67: 0 | P67: 0.74 | Q67: 17.41
A68: 03-03-2023 15:00 | B68: 3.62 | C68: 67.77 | D68: 40.3 | E68: 10.32 | F68: 14.78 | G68: 63.54 | H68: 36.25 | I68: 0.55 | J68: 1.53 | K68: 3.2 | L68: 38.98 | M68: 10.91 | N68: 409 | O68: 0 | P68: 0.71 | Q68: 17.92
A69: 03-03-2023 15:15 | B69: 6.68 | C69: 66.78 | D69: 42.21 | E69: 9.37 | F69: 15.03 | G69: 63.54 | H69: 36.25 | I69: 0.55 | J69: 1.35 | K69: 15.21 | L69: 38.41 | M69: 12.15 | N69: 366.3 | O69: 0 | P69: 0.72 | Q69: 18.61
A70: 03-03-2023 15:30 | B70: 5.63 | C70: 72.13 | D70: 44.32 | E70: 7.94 | F70: 10.11 | G70: 63.4 | H70: 35.91 | I70: 0.57 | J70: 1.66 | K70: 14.78 | L70: 37.93 | M70: 11.99 | N70: 346.4 | O70: 0 | P70: 0.72 | Q70: 19.4
... A104: 03-03-2023 24:00 | B104: 191.89 | C104: 114.46 | D104: 217.05 | E104: 4.35 | F104: 2.94 | G104: 189.74 | H104: 67.78 | I104: 1.72 | J104: 0.03 | K104: 324.4 | L104: 22.41 | M104: 55.29 | N104: 4.3 | O104: 0 | P104: 3.7 | Q104: 40.05
A106: Min | B106: =MIN(B9:B104) -> 1.43 | C106: =MIN(C9:C104) -> 12.19 | D106: =MIN(D9:D104) -> 26.18 | E106: =MIN(E9:E104) -> 0.2 | F106: =MIN(F9:F104) -> 2.92 | G106: =MIN(G9:G104) -> 60.33 | H106: =MIN(H9:H104) -> 29.2 | I106: =MIN(I9:I104) -> 0.45 | ... Q106: =MIN(Q9:Q104) -> 11.89
A107: Max | B107: =MAX(B9:B104) -> 191.89 | C107: =MAX(C9:C104) -> 139.24 | D107: =MAX(D9:D104) -> 217.05 | E107: =MAX(E9:E104) -> 316.24 | F107: =MAX(F9:F104) -> 266.87 | G107: =MAX(G9:G104) -> 211.96 | H107: =MAX(H9:H104) -> 92.33 | I107: =MAX(I9:I104) -> 1.72 | ... Q107: =MAX(Q9:Q104) -> 40.05
A108: Avg | B108: =AVERAGE(B9:B104) -> 63.941667 | C108: =AVERAGE(C9:C104) -> 102.44823 | D108: =AVERAGE(D9:D104) -> 107.27052 | E108: =AVERAGE(E9:E104) -> 19.051667 | F108: =AVERAGE(F9:F104) -> 17.860417 | G108: =AVERAGE(G9:G104) -> 131.84435 | H108: =AVERAGE(H9:H104) -> 56.902935 | I108: =AVERAGE(I9:I104) -> 0.93083333 | ... Q108: =AVERAGE(Q9:Q104) -> 28.931146
A109: Stdev | B109: =STDEV(B9:B104) -> 53.685693 | C109: =STDEV(C9:C104) -> 30.493235 | D109: =STDEV(D9:D104) -> 50.475428 | E109: =STDEV(E9:E104) -> 44.200319 | F109: =STDEV(F9:F104) -> 41.978376 | G109: =STDEV(G9:G104) -> 51.584781 | H109: =STDEV(H9:H104) -> 20.078313 | I109: =STDEV(I9:I104) -> 0.36802365 | ... Q109: =STDEV(Q9:Q104) -> 8.7029968
...

Sheet 04
A1: Station: | B1: BHATAGAON RAIPUR
A2: Date: | B2: =$A$9 -> 04-03-2023 00:15 | D2: Power Off | G2: Pw.Off | L2: Link Fail | N2: Link F | P2: Maintenance | R2: Maint.
A3: Report Type: | B3: Mean | D3: Calibration | G3: Calib. | L3: Data Fail | N3: Data F | P3: Invalid | R3: Invalid
A4: Time Base: | B4: 15 Min | D4: Zero Referrence | G4: Z.Ref | L4: Warm Up | N4: Wm. Up
A7: Date & Time | B7: NO_BHATAGAON | C7: NO2__BHATAGAON | D7: NOX_BHATAGAON | E7: SO2__BHATAGAON | F7: O3__BHATAGAON | G7: PM10__BHATAGAON | H7: PM2_5__BHATAGAON | I7: BENZ__BHATAGAON | J7: WS__BHATAGAON | K7: WD__BHATAGAON | L7: TEMP__BHATAGAON | M7: HUM__BHATAGAON | N7: SR__BHATAGAON | O7: RG__BHATAGAON | P7: CO__BHATAGAON | Q7: NH3__BHATAGAON
B8: ug/m3 | C8: ug/m3 | D8: ppb | E8: ug/m3 | F8: ug/m3 | G8: ug/m3 | H8: ug/m3 | I8: ug/m3 | J8: m/sec | K8: deg | L8: degreC | M8: % | N8: w/m2 | O8: mm | P8: mg/m3 | Q8: ug/m3
A9: 04-03-2023 00:15 | B9: 197.27 | C9: 114.89 | D9: 221.6 | E9: 6.34 | F9: 2.94 | G9: 189.74 | H9: 67.78 | I9: 1.77 | J9: 0.16 | K9: 11.48 | L9: 22.35 | M9: 56.14 | N9: 4.4 | O9: 0 | P9: 3.8 | Q9: 40.34
A10: 04-03-2023 00:30 | B10: 200.32 | C10: 114.69 | D10: 223.94 | E10: 7.31 | F10: 2.91 | G10: 189.57 | H10: 68.11 | I10: 1.81 | J10: 0.18 | K10: 255.48 | L10: 22.6 | M10: 55.45 | N10: 3.4 | O10: 0 | P10: 3.97 | Q10: 40.28
A11: 04-03-2023 00:45 | B11: 202.05 | C11: 113.11 | D11: 224.45 | E11: 7.09 | F11: 2.92 | G11: 187.6 | H11: 71.98 | I11: 1.86 | J11: 0.16 | K11: 18.72 | L11: 22.58 | M11: 55.86 | N11: 4.4 | O11: 0 | P11: 4.04 | Q11: 39.64
A12: 04-03-2023 01:00 | B12: 201.15 | C12: 111.22 | D12: 222.69 | E12: 7.1 | F12: 2.95 | G12: 187.6 | H12: 71.98 | I12: 1.93 | J12: 0.05 | K12: 321.69 | L12: 22.1 | M12: 56.57 | N12: 4.4 | O12: 0 | P12: 4.06 | Q12: 39.09
A13: 04-03-2023 01:15 | B13: 194.74 | C13: 109.97 | D13: 216.86 | E13: 7.26 | F13: 2.94 | G13: 187.6 | H13: 71.98 | I13: 1.96 | J13: 0.38 | K13: 215.14 | L13: 22.73 | M13: 50.79 | N13: 2.7 | O13: 0 | P13: 3.64 | Q13: 39.24
A14: 04-03-2023 01:30 | B14: 191.76 | C14: 107.91 | D14: 213.33 | E14: 7.42 | F14: 2.96 | G14: 185.79 | H14: 71.89 | I14: 1.97 | J14: 0.09 | K14: 352.12 | L14: 22.66 | M14: 53.3 | N14: 4.5 | O14: 0 | P14: 3.75 | Q14: 39.42
A15: 04-03-2023 01:45 | B15: 185.31 | C15: 107.59 | D15: 207.98 | E15: 7.36 | F15: 3.11 | G15: 164.33 | H15: 70.72 | I15: 1.94 | J15: 0.13 | K15: 179.12 | L15: 22.71 | M15: 50.8 | N15: 3.8 | O15: 0 | P15: 3.66 | Q15: 39.55
A16: 04-03-2023 02:00 | B16: 186.82 | C16: 104.1 | D16: 207.26 | E16: 7.04 | F16: 3.01 | G16: 164.33 | H16: 70.72 | I16: 1.95 | J16: 0.12 | K16: 333.96 | L16: 21.94 | M16: 56.93 | N16: 4.6 | O16: 0 | P16: 3.67 | Q16: 39.73
A17: 04-03-2023 02:15 | B17: 182.35 | C17: 102.69 | D17: 202.9 | E17: 6.9 | F17: 3.05 | G17: 164.33 | H17: 70.72 | I17: 1.95 | J17: 0.09 | K17: 343.18 | L17: 21.14 | M17: 58.32 | N17: 4.7 | O17: 0 | P17: 3.6 | Q17: 39.57
A18: 04-03-2023 02:30 | B18: 182.94 | C18: 105.71 | D18: 205.04 | E18: 6.54 | F18: 3.07 | G18: 162.55 | H18: 70.45 | I18: 1.93 | J18: 0.15 | K18: 2.66 | L18: 20.95 | M18: 59.61 | N18: 4.5 | O18: 0 | P18: 3.59 | Q18: 40.34
A19: 04-03-2023 02:45 | B19: 181.06 | C19: 103.09 | D19: 202.09 | E19: 6.72 | F19: 2.98 | G19: 141.49 | H19: 67.21 | I19: 1.91 | J19: 0.08 | K19: 265.32 | L19: 20.9 | M19: 58.71 | N19: 4.1 | O19: 0 | P19: 3.51 | Q19: 40.71
A20: 04-03-2023 03:00 | B20: 175.12 | C20: 101.91 | D20: 196.68 | E20: 6.78 | F20: 2.91 | G20: 141.49 | H20: 67.21 | I20: 1.9 | J20: 0.04 | K20: 292.53 | L20: 20.77 | M20: 59.7 | N20: 4.2 | O20: 0 | P20: 3.43 | Q20: 40.5
... A104: 04-03-2023 24:00 | B104: 176.8 | C104: 111.75 | D104: 203.45 | E104: 2.73 | F104: 2.97 | G104: 157.13 | H104: 61.56 | I104: 1.48 | J104: 0.06 | K104: 13.25 | L104: 22.54 | M104: 51.01 | N104: 4.3 | O104: 0 | P104: 2.86 | Q104: 39.31
A106: Min | B106: =MIN(B9:B104) -> 0.14 | C106: =MIN(C9:C104) -> 57.8 | D106: =MIN(D9:D104) -> 32.07 | E106: =MIN(E9:E104) -> 2.36 | F106: =MIN(F9:F104) -> 2.78 | G106: =MIN(G9:G104) -> 35.85 | H106: =MIN(H9:H104) -> 13.42 | I106: =MIN(I9:I104) -> 0.47 | ... Q106: =MIN(Q9:Q104) -> 14.66
A107: Max | B107: =MAX(B9:B104) -> 202.05 | C107: =MAX(C9:C104) -> 140.65 | D107: =MAX(D9:D104) -> 224.45 | E107: =MAX(E9:E104) -> 43.45 | F107: =MAX(F9:F104) -> 44.25 | G107: =MAX(G9:G104) -> 207.57 | H107: =MAX(H9:H104) -> 75.78 | I107: =MAX(I9:I104) -> 1.97 | ... Q107: =MAX(Q9:Q104) -> 40.71
A108: Avg | B108: =AVERAGE(B9:B104) -> 93.409583 | C108: =AVERAGE(C9:C104) -> 98.724479 | D108: =AVERAGE(D9:D104) -> 129.39146 | E108: =AVERAGE(E9:E104) -> 9.2415625 | F108: =AVERAGE(F9:F104) -> 8.7592708 | G108: =AVERAGE(G9:G104) -> 126.97667 | H108: =AVERAGE(H9:H104) -> 52.030729 | I108: =AVERAGE(I9:I104) -> 1.2376042 | ... Q108: =AVERAGE(Q9:Q104) -> 30.999792
A109: Stdev | B109: =STDEV(B9:B104) -> 73.762563 | C109: =STDEV(C9:C104) -> 16.247195 | D109: =STDEV(D9:D104) -> 64.388054 | E109: =STDEV(E9:E104) -> 7.1437371 | F109: =STDEV(F9:F104) -> 9.9194287 | G109: =STDEV(G9:G104) -> 58.873189 | H109: =STDEV(H9:H104) -> 20.699384 | I109: =STDEV(I9:I104) -> 0.497913 | ... Q109: =STDEV(Q9:Q104) -> 8.306001
A110: Num | B110: =COUNT(B9:B104) -> 96 | C110: =COUNT(C9:C104) -> 96 | D110: =COUNT(D9:D104) -> 96 | E110: =COUNT(E9:E104) -> 96 | F110: =COUNT(F9:F104) -> 96 | G110: =COUNT(G9:G104) -> 96 | H110: =COUNT(H9:H104) -> 96 | I110: =COUNT(I9:I104) -> 96 | ... Q110: =COUNT(Q9:Q104) -> 96
A111: DCR | B111: =IF(B110>=87,">90%",IF(B110<=87,"<90%")) -> >90% | C111: =IF(C110>=87,">90%",IF(C110<=87,"<90%")) -> >90% | D111: =IF(D110>=87,">90%",IF(D110<=87,"<90%")) -> >90% | E111: =IF(E110>=87,">90%",IF(E110<=87,"<90%")) -> >90% | F111: =IF(F110>=87,">90%",IF(F110<=87,"<90%")) -> >90% | G111: =IF(G110>=87,">90%",IF(G110<=87,"<90%")) -> >90% | H111: =IF(H110>=87,">90%",IF(H110<=87,"<90%")) -> >90% | I111: =IF(I110>=87,">90%",IF(I110<=87,"<90%")) -> >90% | ... Q111: =IF(Q110>=87,">90%",IF(Q110<=87,"<90%")) -> >90%
A112: Status | B112: =IF(B110>=87,"OK",IF(B110<=87,"LESS")) -> OK | C112: =IF(C110>=87,"OK",IF(C110<=87,"LESS")) -> OK | D112: =IF(D110>=87,"OK",IF(D110<=87,"LESS")) -> OK | E112: =IF(E110>=87,"OK",IF(E110<=87,"LESS")) -> OK | F112: =IF(F110>=87,"OK",IF(F110<=87,"LESS")) -> OK | G112: =IF(G110>=87,"OK",IF(G110<=87,"LESS")) -> OK | H112: =IF(H110>=87,"OK",IF(H110<=87,"LESS")) -> OK | I112: =IF(I110>=87,"OK",IF(I110<=87,"LESS")) -> OK | ... Q112: =IF(Q110>=87,"OK",IF(Q110<=87,"LESS")) -> OK
A115: Done by | B115: RK
A117: Comment

Sheet 05
A1: Station: | B1: BHATAGAON RAIPUR
A2: Date: | B2: =$A$9 -> 05-03-2023 00:15 | D2: Power Off | G2: Pw.Off | L2: Link Fail | N2: Link F | P2: Maintenance | R2: Maint.
A3: Report Type: | B3: Mean | D3: Calibration | G3: Calib. | L3: Data Fail | N3: Data F | P3: Invalid | R3: Invalid
A4: Time Base: | B4: 15 Min | D4: Zero Referrence | G4: Z.Ref | L4: Warm Up | N4: Wm. Up
A7: Date & Time | B7: NO_BHATAGAON | C7: NO2__BHATAGAON | D7: NOX_BHATAGAON | E7: SO2__BHATAGAON | F7: O3__BHATAGAON | G7: PM10__BHATAGAON | H7: PM2_5__BHATAGAON | I7: BENZ__BHATAGAON | J7: WS__BHATAGAON | K7: WD__BHATAGAON | L7: TEMP__BHATAGAON | M7: HUM__BHATAGAON | N7: SR__BHATAGAON | O7: RG__BHATAGAON | P7: CO__BHATAGAON | Q7: NH3__BHATAGAON
B8: ug/m3 | C8: ug/m3 | D8: ppb | E8: ug/m3 | F8: ug/m3 | G8: ug/m3 | H8: ug/m3 | I8: ug/m3 | J8: m/sec | K8: deg | L8: degreC | M8: % | N8: w/m2 | O8: mm | P8: mg/m3 | Q8: ug/m3
A9: 05-03-2023 00:15 | B9: 179.84 | C9: 111.58 | D9: 205.8 | E9: 5.54 | F9: 2.87 | G9: 157.13 | H9: 61.56 | I9: 1.48 | J9: 0.11 | K9: 11.61 | L9: 22.76 | M9: 52.8 | N9: 4.2 | O9: 0 | P9: 2.87 | Q9: 40.13
A10: 05-03-2023 00:30 | B10: 180.9 | C10: 111.04 | D10: 206.35 | E10: 5.41 | F10: 2.95 | G10: 157.24 | H10: 61.3 | I10: 1.48 | J10: 0.23 | K10: 35.41 | L10: 22.7 | M10: 51.43 | N10: 3.9 | O10: 0 | P10: 2.86 | Q10: 40.55
A11: 05-03-2023 00:45 | B11: 176.96 | C11: 110.62 | D11: 202.96 | E11: 5.68 | F11: 2.95 | G11: 158.53 | H11: 58.28 | I11: 1.48 | J11: 0.48 | K11: 60.62 | L11: 24.09 | M11: 39.46 | N11: 1.5 | O11: 0 | P11: 2.84 | Q11: 40.43
A12: 05-03-2023 01:00 | B12: 169.68 | C12: 110.49 | D12: 197.05 | E12: 6.98 | F12: 2.89 | G12: 158.53 | H12: 58.28 | I12: 1.49 | J12: 0.42 | K12: 25.31 | L12: 24.77 | M12: 33.09 | N12: 3.4 | O12: 0 | P12: 2.85 | Q12: 40.15
A13: 05-03-2023 01:15 | B13: 163.11 | C13: 110.61 | D13: 191.84 | E13: 7.01 | F13: 2.98 | G13: 158.53 | H13: 58.28 | I13: 1.48 | J13: 0.27 | K13: 72.87 | L13: 24.36 | M13: 33.69 | N13: 4.3 | O13: 0 | P13: 2.64 | Q13: 39.84
A14: 05-03-2023 01:30 | B14: 157.32 | C14: 110.63 | D14: 187.22 | E14: 7.46 | F14: 2.97 | G14: 146.2 | H14: 59.57 | I14: 1.47 | J14: 0.22 | K14: 88.34 | L14: 24.11 | M14: 32.68 | N14: 4.3 | O14: 0 | P14: 2.76 | Q14: 39.3
A15: 05-03-2023 01:45 | B15: 152.19 | C15: 109.22 | D15: 182.32 | E15: 6.4 | F15: 2.84 | G15: Maint. | H15: 74.92 | I15: 1.44 | J15: 0.06 | K15: 151.39 | L15: 23.69 | M15: 33.45 | N15: 4.6 | O15: 0 | P15: 2.4 | Q15: 38.6
A16: 05-03-2023 02:00 | B16: 148.06 | C16: 108.52 | D16: 178.62 | E16: 6.01 | F16: 3.85 | G16: Maint. | H16: 74.92 | I16: 1.26 | J16: 0.12 | K16: 30.98 | L16: 22.86 | M16: 38.74 | N16: 4.7 | O16: 0 | P16: 2.5 | Q16: 37.78
A17: 05-03-2023 02:15 | B17: 144.83 | C17: 108 | D17: 175.75 | E17: 5.91 | F17: 3.02 | G17: Maint. | H17: 74.92 | I17: 1.23 | J17: 0.13 | K17: 41.86 | L17: 21.95 | M17: 43.85 | N17: 4.8 | O17: 0 | P17: 2.46 | Q17: 37.55
A18: 05-03-2023 02:30 | B18: 142.27 | C18: 107.45 | D18: 173.39 | E18: 5.63 | F18: 2.89 | G18: Maint. | H18: 75.13 | I18: 1.19 | J18: 0.1 | K18: 7.28 | L18: 21.78 | M18: 45.43 | N18: 4.3 | O18: 0 | P18: 2.51 | Q18: 37.61
A19: 05-03-2023 02:45 | B19: 140.27 | C19: 106.59 | D19: 171.31 | E19: 5.43 | F19: 2.94 | G19: Invalid | H19: 77.58 | I19: 1.22 | J19: 0.11 | K19: 341.36 | L19: 21.43 | M19: 50.18 | N19: 4.4 | O19: 0 | P19: 2.48 | Q19: 37.69
A20: 05-03-2023 03:00 | B20: 137.84 | C20: 105.64 | D20: 168.84 | E20: 5.03 | F20: 3.01 | G20: Invalid | H20: 77.58 | I20: 1.22 | J20: 0.17 | K20: 31.38 | L20: 21.19 | M20: 51.56 | N20: 4.4 | O20: 0 | P20: 2.44 | Q20: 37.82
A21: 05-03-2023 03:15 | B21: 134.61 | C21: 104.7 | D21: 165.73 | E21: 5.25 | F21: 2.97 | G21: Invalid | H21: 77.58 | I21: 1.21 | J21: 0.24 | K21: 56.64 | L21: 22.33 | M21: 42.78 | N21: 2.8 | O21: 0 | P21: 1.91 | Q21: 37.9
A22: 05-03-2023 03:30 | B22: 130.07 | C22: 104.51 | D22: 161.98 | E22: 5.57 | F22: 3.05 | G22: 136.96 | H22: 77.26 | I22: 1.21 | J22: 0.35 | K22: 86.93 | L22: 23.62 | M22: 33.1 | N22: 2.7 | O22: 0 | P22: 2.09 | Q22: 38.18
A23: 05-03-2023 03:45 | B23: 124.02 | C23: 105.3 | D23: 157.57 | E23: 5.68 | F23: 3.08 | G23: 136.96 | H23: 73.53 | I23: 1.02 | J23: 0.26 | K23: 31.85 | L23: 23.49 | M23: 34.07 | N23: 4 | O23: 0 | P23: 2.3 | Q23: 38.63
A24: 05-03-2023 04:00 | B24: 116.72 | C24: 104.63 | D24: 151.34 | E24: 2.61 | F24: 2.99 | G24: 136.96 | H24: 73.53 | I24: 1.06 | J24: 0.31 | K24: 40.8 | L24: 23.58 | M24: 32.88 | N24: 3.9 | O24: 0 | P24: 2.23 | Q24: 38.67
A25: 05-03-2023 04:15 | B25: 109.19 | C25: 104.17 | D25: 145.05 | E25: 6.29 | F25: 3.1 | G25: 136.96 | H25: 73.53 | I25: 1.19 | J25: 0.28 | K25: 36.53 | L25: 23.47 | M25: 33.25 | N25: 4.2 | O25: 0 | P25: 2.15 | Q25: 38.34
A26: 05-03-2023 04:30 | B26: 102.19 | C26: 104.75 | D26: 139.76 | E26: 6.5 | F26: 2.93 | G26: 133.38 | H26: 72.89 | I26: 1.2 | J26: 0.24 | K26: 43.27 | L26: 23.22 | M26: 33.49 | N26: 4.3 | O26: 0 | P26: 2.09 | Q26: 37.81
A27: 05-03-2023 04:45 | B27: 96.61 | C27: 105.3 | D27: 135.58 | E27: 6.64 | F27: 2.94 | G27: 90.98 | H27: 65.31 | I27: 1.16 | J27: 0.27 | K27: 29.54 | L27: 23.1 | M27: 35.41 | N27: 4.2 | O27: 0 | P27: 2.06 | Q27: 37.32
A28: 05-03-2023 05:00 | B28: 91.92 | C28: 105.71 | D28: 132.05 | E28: 7.09 | F28: 2.96 | G28: 90.98 | H28: 65.31 | I28: 1.12 | J28: 0.49 | K28: 25.69 | L28: 23.23 | M28: 36.09 | N28: 3.6 | O28: 0 | P28: 2.16 | Q28: 36.95
A29: 05-03-2023 05:15 | B29: 87.5 | C29: 105.35 | D29: 128.31 | E29: 6.63 | F29: 2.9 | G29: 90.98 | H29: 65.31 | I29: 1.08 | J29: 0.28 | K29: 32.78 | L29: 23.3 | M29: 35.32 | N29: 4.2 | O29: 0 | P29: 2.17 | Q29: 36.17
A30: 05-03-2023 05:30 | B30: 84.07 | C30: 104.75 | D30: 125.23 | E30: 5.43 | F30: 2.91 | G30: 94.07 | H30: 65.19 | I30: 0.98 | J30: 0.59 | K30: 26.15 | L30: 23.4 | M30: 35.31 | N30: 3.5 | O30: 0 | P30: 1.93 | Q30: 35.28
A31: 05-03-2023 05:45 | B31: 81.08 | C31: 104.55 | D31: 122.72 | E31: 5.75 | F31: 3 | G31: 130.67 | H31: 63.81 | I31: 0.84 | J31: 0.44 | K31: 23.47 | L31: 23.33 | M31: 35.66 | N31: 4.2 | O31: 0 | P31: 2.05 | Q31: 34.67
A32: 05-03-2023 06:00 | B32: 78 | C32: 103.81 | D32: 119.84 | E32: 5.46 | F32: 2.95 | G32: 130.67 | H32: 63.81 | I32: 0.8 | J32: 0.23 | K32: 35.1 | L32: 23.12 | M32: 36.44 | N32: 4.6 | O32: 0 | P32: 1.98 | Q32: 34.41
A33: 05-03-2023 06:15 | B33: 76.39 | C33: 103.43 | D33: 118.34 | E33: 5.48 | F33: 2.99 | G33: 130.67 | H33: 63.81 | I33: 0.89 | J33: 0.23 | K33: 62.49 | L33: 22.82 | M33: 38.55 | N33: 5.6 | O33: 0 | P33: 2 | Q33: 34.33
A34: 05-03-2023 06:30 | B34: 75.86 | C34: 103.4 | D34: 117.9 | E34: 6.48 | F34: 3.06 | G34: 120.51 | H34: 63.4 | I34: 0.86 | J34: 0.3 | K34: 56.75 | L34: 22.58 | M34: 40.07 | N34: 10.7 | O34: 0 | P34: 2.14 | Q34: 34.48
A35: 05-03-2023 06:45 | B35: 75.62 | C35: 103.03 | D35: 117.51 | E35: 6.13 | F35: 3.07 | G35: Maint. | H35: 58.53 | I35: 0.87 | J35: 0.42 | K35: 22.72 | L35: 22.62 | M35: 41.34 | N35: 22.8 | O35: 0 | P35: 2.04 | Q35: 34.64
A36: 05-03-2023 07:00 | B36: 74.64 | C36: 102.74 | D36: 116.56 | E36: 6.59 | F36: 3.14 | G36: Maint. | H36: 58.53 | I36: 0.82 | J36: 0.35 | K36: 26.83 | L36: 23.08 | M36: 41.02 | N36: 51.1 | O36: 0 | P36: 2.06 | Q36: 34.86
A37: 05-03-2023 07:15 | B37: 75.38 | C37: 103.64 | D37: 117.65 | E37: 7.1 | F37: 3.04 | G37: Maint. | H37: 58.53 | I37: 0.81 | J37: 0.42 | K37: 28.1 | L37: 24.13 | M37: 39.79 | N37: 90.1 | O37: 0 | P37: 1.98 | Q37: 35.8
A38: 05-03-2023 07:30 | B38: 76.07 | C38: 104.36 | D38: 118.6 | E38: 7.48 | F38: 3.02 | G38: Maint. | H38: 58.64 | I38: 0.87 | J38: 0.6 | K38: 27.15 | L38: 25.31 | M38: 36.93 | N38: 129.5 | O38: 0 | P38: 2.05 | Q38: 36.13
A39: 05-03-2023 07:45 | B39: 74.32 | C39: 105.6 | D39: 117.88 | E39: 7.11 | F39: 3.08 | G39: 250.29 | H39: 60.13 | I39: 0.85 | J39: 0.67 | K39: 30.71 | L39: 26.1 | M39: 35.31 | N39: 167.5 | O39: 0 | P39: 2.01 | Q39: 35.69
A40: 05-03-2023 08:00 | B40: 71.75 | C40: 106.67 | D40: 116.4 | E40: 3.09 | F40: 3.25 | G40: 250.29 | H40: 60.13 | I40: 0.82 | J40: 0.72 | K40: 27.9 | L40: 26.98 | M40: 33.49 | N40: 205.7 | O40: 0 | P40: 1.98 | Q40: 35.55
A41: 05-03-2023 08:15 | B41: 69.46 | C41: 108.2 | D41: 115.41 | E41: 7.32 | F41: 3.09 | G41: 250.29 | H41: 60.13 | I41: 0.8 | J41: 0.57 | K41: 53.97 | L41: 27.44 | M41: 33.09 | N41: 244.3 | O41: 0 | P41: 1.94 | Q41: 35.29
A42: 05-03-2023 08:30 | B42: 67.38 | C42: 110.12 | D42: 114.8 | E42: 7.04 | F42: 3.05 | G42: 114.71 | H42: 59.66 | I42: 0.82 | J42: 0.81 | K42: 79.41 | L42: 27.66 | M42: 33.17 | N42: 288.3 | O42: 0 | P42: 1.88 | Q42: 35.12
...

Sheet 06
A1: Station: | B1: BHATAGAON RAIPUR
A2: Date: | B2: =$A$9 -> 06-03-2023 00:15 | D2: Power Off | G2: Pw.Off | L2: Link Fail | N2: Link F | P2: Maintenance | R2: Maint.
A3: Report Type: | B3: Mean | D3: Calibration | G3: Calib. | L3: Data Fail | N3: Data F | P3: Invalid | R3: Invalid
A4: Time Base: | B4: 15 Min | D4: Zero Referrence | G4: Z.Ref | L4: Warm Up | N4: Wm. Up
A7: Date & Time | B7: NO_BHATAGAON | C7: NO2__BHATAGAON | D7: NOX_BHATAGAON | E7: SO2__BHATAGAON | F7: O3__BHATAGAON | G7: PM10__BHATAGAON | H7: PM2_5__BHATAGAON | I7: BENZ__BHATAGAON | J7: WS__BHATAGAON | K7: WD__BHATAGAON | L7: TEMP__BHATAGAON | M7: HUM__BHATAGAON | N7: SR__BHATAGAON | O7: RG__BHATAGAON | P7: CO__BHATAGAON | Q7: NH3__BHATAGAON
B8: ug/m3 | C8: ug/m3 | D8: ppb | E8: ug/m3 | F8: ug/m3 | G8: ug/m3 | H8: ug/m3 | I8: ug/m3 | J8: m/sec | K8: deg | L8: degreC | M8: % | N8: w/m2 | O8: mm | P8: mg/m3 | Q8: ug/m3
A9: 06-03-2023 00:15 | B9: 92.62 | C9: 128.95 | D9: 145.43 | E9: 6.09 | F9: 3.35 | G9: 129.2 | H9: 72.84 | I9: 0.89 | J9: 0.68 | K9: 7.41 | L9: 24.75 | M9: 42.82 | N9: 3.5 | O9: 0 | P9: 2.38 | Q9: 37.17
A10: 06-03-2023 00:30 | B10: 88.37 | C10: 127.28 | D10: 141.11 | E10: 5.76 | F10: 3.52 | G10: 126.81 | H10: 72.54 | I10: 0.99 | J10: 0.9 | K10: 17.67 | L10: 25.13 | M10: 40.91 | N10: 3.7 | O10: 0 | P10: 2.17 | Q10: 37.13
A11: 06-03-2023 00:45 | B11: 83.52 | C11: 125.59 | D11: 136.29 | E11: 6.15 | F11: 3.71 | G11: 98.46 | H11: 69.02 | I11: 1.06 | J11: 0.74 | K11: 17.52 | L11: 25.13 | M11: 40.47 | N11: 4.1 | O11: 0 | P11: 2.04 | Q11: 36.83
A12: 06-03-2023 01:00 | B12: 79.27 | C12: 124.19 | D12: 132.1 | E12: 6.44 | F12: 3.14 | G12: 98.46 | H12: 69.02 | I12: 0.9 | J12: 0.3 | K12: 358.22 | L12: 24.75 | M12: 41.97 | N12: 4.6 | O12: 0 | P12: 2.4 | Q12: 36.91
A13: 06-03-2023 01:15 | B13: 74.26 | C13: 123.55 | D13: 127.74 | E13: 6.39 | F13: 3.02 | G13: 98.46 | H13: 69.02 | I13: 0.83 | J13: 0.16 | K13: 0.13 | L13: 24.28 | M13: 43.38 | N13: 4.8 | O13: 0 | P13: 2.39 | Q13: 37.65
A14: 06-03-2023 01:30 | B14: 69.13 | C14: 122.7 | D14: 123.15 | E14: 6.79 | F14: 3.02 | G14: 99.48 | H14: 68.18 | I14: 1.14 | J14: 0.12 | K14: 64.12 | L14: 24.11 | M14: 44.21 | N14: 4.7 | O14: 0 | P14: 2.41 | Q14: 37.74
A15: 06-03-2023 01:45 | B15: 64.02 | C15: 121.61 | D15: 118.45 | E15: 6.13 | F15: 2.93 | G15: 111.58 | H15: 58.24 | I15: 1.25 | J15: 0.54 | K15: 18 | L15: 24.23 | M15: 42.79 | N15: 3.7 | O15: 0 | P15: 2.3 | Q15: 37.34
A16: 06-03-2023 02:00 | B16: 58.68 | C16: 120.72 | D16: 113.68 | E16: 6.56 | F16: 2.92 | G16: 111.58 | H16: 58.24 | I16: 1.21 | J16: 0.58 | K16: 20.74 | L16: 24.3 | M16: 42.92 | N16: 4 | O16: 0 | P16: 2.18 | Q16: 36.99
A17: 06-03-2023 02:15 | B17: 54.32 | C17: 119.62 | D17: 109.58 | E17: 6.57 | F17: 3.06 | G17: 111.58 | H17: 58.24 | I17: 1.17 | J17: 0.16 | K17: 30.31 | L17: 24.16 | M17: 42.9 | N17: 4.7 | O17: 0 | P17: 2.08 | Q17: 36.65
A18: 06-03-2023 02:30 | B18: 50.53 | C18: 118.75 | D18: 106.06 | E18: 6.74 | F18: 2.86 | G18: 111.01 | H18: 58.6 | I18: 1.11 | J18: 0.06 | K18: 213.81 | L18: 23.73 | M18: 44.1 | N18: 4.6 | O18: 0 | P18: 2 | Q18: 36.33
A19: 06-03-2023 02:45 | B19: 47.45 | C19: 117.41 | D19: 102.85 | E19: 5.68 | F19: 2.49 | G19: 104.21 | H19: 62.86 | I19: 1.06 | J19: 0.16 | K19: 111.49 | L19: 23.77 | M19: 43.59 | N19: 4 | O19: 0 | P19: 1.52 | Q19: 35.5
A20: 06-03-2023 03:00 | B20: 45.69 | C20: 115.91 | D20: 100.61 | E20: 5.56 | F20: 2.74 | G20: 104.21 | H20: 62.86 | I20: 1.02 | J20: 0.15 | K20: 76.89 | L20: 23.87 | M20: 43.18 | N20: 4.3 | O20: 0 | P20: 1.55 | Q20: 34.8
... A54: 06-03-2023 11:30 | B54: 2.26 | C54: 88.66 | D54: 50.74 | E54: 6.3 | F54: 6.35 | G54: 55.45 | H54: 40.73 | I54: 0.5 | J54: 0.81 | K54: 25.35 | L54: 35.7 | M54: 19.76 | N54: 582.7 | O54: 0 | P54: 0.64 | Q54: 16.83
A55: 06-03-2023 11:45 | B55: 2.63 | C55: 90.04 | D55: 51.8 | E55: 5.81 | F55: 5.2 | G55: Maint. | H55: Maint. | I55: 0.49 | J55: 1.09 | K55: 111.41 | L55: 33.9 | M55: 22.79 | N55: 584.1 | O55: 0 | P55: 0.62 | Q55: 17.72
A56: 06-03-2023 12:00 | B56: 2.32 | C56: 89.05 | D56: 51.01 | E56: 4.26 | F56: 4.48 | G56: Maint. | H56: Maint. | I56: 0.48 | J56: 1.07 | K56: 119.63 | L56: 33.35 | M56: 22.8 | N56: 576.5 | O56: 0 | P56: 0.65 | Q56: 19.3
A57: 06-03-2023 12:15 | B57: 1.54 | C57: 85.32 | D57: 48.32 | E57: 5.74 | F57: 4.8 | G57: Maint. | H57: Maint. | I57: 0.49 | J57: 0.95 | K57: 50.09 | L57: 34.08 | M57: 21.6 | N57: 555.8 | O57: 0 | P57: 0.62 | Q57: 19.67
A58: 06-03-2023 12:30 | B58: 1.91 | C58: 84.95 | D58: 48.42 | E58: 6.47 | F58: 4.47 | G58: Maint. | H58: Maint. | I58: 0.52 | J58: 0.47 | K58: 26.57 | L58: 36.56 | M58: 19.22 | N58: 536.2 | O58: 0 | P58: 0.62 | Q58: 20.19
A59: 06-03-2023 12:45 | B59: 2.08 | C59: 87.24 | D59: 49.81 | E59: 5.82 | F59: 4.43 | G59: Maint. | H59: Maint. | I59: 0.53 | J59: 0.82 | K59: 14.32 | L59: 37.5 | M59: 18.07 | N59: 522.6 | O59: 0 | P59: 0.63 | Q59: 20.74
A60: 06-03-2023 13:00 | B60: 2.55 | C60: 90.64 | D60: 52.07 | E60: 5.2 | F60: 3.7 | G60: 58.85 | H60: 25.53 | I60: 0.54 | J60: 0.25 | K60: 9.17 | L60: 37.7 | M60: 17.48 | N60: 506.3 | O60: 0 | P60: 0.63 | Q60: 21.55
A61: 06-03-2023 13:15 | B61: 3.02 | C61: 92.51 | D61: 53.48 | E61: 5.42 | F61: 3.3 | G61: 58.85 | H61: 25.53 | I61: 0.55 | J61: 0.67 | K61: 21.91 | L61: 37.32 | M61: 18.07 | N61: 496.8 | O61: 0 | P61: 0.61 | Q61: 22.65
A62: 06-03-2023 13:30 | B62: 2.97 | C62: 93.44 | D62: 53.95 | E62: 5.34 | F62: 3.5 | G62: 58.85 | H62: 25.53 | I62: 0.54 | J62: 0.48 | K62: 104.48 | L62: 36.85 | M62: 17.98 | N62: 486.8 | O62: 0 | P62: 0.64 | Q62: 23.32
A63: 06-03-2023 13:45 | B63: 3.22 | C63: 93.47 | D63: 54.17 | E63: 5.62 | F63: 3.18 | G63: 58.85 | H63: 25.53 | I63: 0.56 | J63: 0.25 | K63: 162.58 | L63: 35 | M63: 19.82 | N63: 475.9 | O63: 0 | P63: 0.63 | Q63: 23.64
A64: 06-03-2023 14:00 | B64: 3.83 | C64: 93.17 | D64: 54.49 | E64: 6.04 | F64: 6.37 | G64: 122.1 | H64: 25.22 | I64: 0.54 | J64: 0.75 | K64: 36.67 | L64: 36.3 | M64: 18.82 | N64: 427 | O64: 0 | P64: 0.74 | Q64: 23.04
A65: 06-03-2023 14:15 | B65: 0.54 | C65: 96.19 | D65: 53.51 | E65: 8.93 | F65: 9.11 | G65: 135.78 | H65: 25.16 | I65: 0.54 | J65: 0.92 | K65: 21.74 | L65: 36.75 | M65: 18.9 | N65: 444.8 | O65: 0 | P65: 0.72 | Q65: 20.32
A66: 06-03-2023 14:30 | B66: 0.9 | C66: 71.93 | D66: 40.42 | E66: 19.13 | F66: 22.91 | G66: 135.78 | H66: 25.16 | I66: 0.52 | J66: 0.97 | K66: 10.03 | L66: 36.96 | M66: 17.66 | N66: 497.9 | O66: 0 | P66: 0.7 | Q66: 16.9
A67: 06-03-2023 14:45 | B67: 0.68 | C67: 71.03 | D67: 39.74 | E67: 16.86 | F67: 15.57 | G67: 135.78 | H67: 25.16 | I67: 0.51 | J67: 0.88 | K67: 350.98 | L67: 38.08 | M67: 16.75 | N67: 505.6 | O67: 0 | P67: 0.74 | Q67: 15.19
A68: 06-03-2023 15:00 | B68: 0.52 | C68: 76.9 | D68: 42.86 | E68: 10.59 | F68: 7.39 | G68: 65.89 | H68: 22.74 | I68: 0.48 | J68: 1.35 | K68: 6.33 | L68: 38.74 | M68: 15.54 | N68: 486.2 | O68: 0 | P68: 0.73 | Q68: 15.31
A69: 06-03-2023 15:15 | B69: 1.22 | C69: 79.44 | D69: 44.82 | E69: 7.98 | F69: 5.26 | G69: 50.78 | H69: 22.22 | I69: 0.47 | J69: 1.18 | K69: 12.9 | L69: 38.4 | M69: 13.7 | N69: 427.7 | O69: 0 | P69: 0.69 | Q69: 16.08
A70: 06-03-2023 15:30 | B70: 2.15 | C70: 82.14 | D70: 47.06 | E70: 6.72 | F70: 3.82 | G70: 50.78 | H70: 22.22 | I70: 0.47 | J70: 0.89 | K70: 359.64 | L70: 38.12 | M70: 13.68 | N70: 401.8 | O70: 0 | P70: 0.72 | Q70: 18.32
A71: 06-03-2023 15:45 | B71: 2.76 | C71: 83.64 | D71: 48.38 | E71: 5.72 | F71: 3.62 | G71: 50.78 | H71: 22.22 | I71: 0.49 | J71: 0.34 | K71: 6.85 | L71: 37.23 | M71: 14.18 | N71: 330.5 | O71: 0 | P71: 0.72 | Q71: 20.17
A72: 06-03-2023 16:00 | B72: 2.67 | C72: 84.48 | D72: 48.76 | E72: 3.53 | F72: 3.82 | G72: Maint. | H72: Maint. | I72: 0.5 | J72: 0.65 | K72: 348.01 | L72: 36.24 | M72: 15.26 | N72: 132 | O72: 0 | P72: 0.69 | Q72: 20.95
A73: 06-03-2023 16:15 | B73: 2.47 | C73: 84.8 | D73: 48.78 | E73: 5.16 | F73: 3.58 | G73: Maint. | H73: Maint. | I73: 0.51 | J73: 0.45 | K73: 354.95 | L73: 36.04 | M73: 14.45 | N73: 106.2 | O73: 0 | P73: 0.6 | Q73: 21.72
A74: 06-03-2023 16:30 | B74: 2.9 | C74: 85.16 | D74: 49.32 | E74: 4.34 | F74: 3.65 | G74: Maint. | H74: Maint. | I74: 0.53 | J74: 1.15 | K74: 16.77 | L74: 35.36 | M74: 14.94 | N74: 104.7 | O74: 0 | P74: 0.67 | Q74: 22.44
A75: 06-03-2023 16:45 | B75: 4.2 | C75: 87.15 | D75: 51.46 | E75: 4.22 | F75: 3.26 | G75: Maint. | H75: Maint. | I75: 0.5 | J75: 0.58 | K75: 353.46 | L75: 34.81 | M75: 17 | N75: 76.7 | O75: 0 | P75: 0.68 | Q75: 23.43
...

Sheet 07
A1: Station: | B1: BHATAGAON RAIPUR
A2: Date: | B2: =$A$9 -> 07-03-2023 00:15 | D2: Power Off | G2: Pw.Off | L2: Link Fail | N2: Link F | P2: Maintenance | R2: Maint.
A3: Report Type: | B3: Mean | D3: Calibration | G3: Calib. | L3: Data Fail | N3: Data F | P3: Invalid | R3: Invalid
A4: Time Base: | B4: 15 Min | D4: Zero Referrence | G4: Z.Ref | L4: Warm Up | N4: Wm. Up
A7: Date & Time | B7: NO_BHATAGAON | C7: NO2__BHATAGAON | D7: NOX_BHATAGAON | E7: SO2__BHATAGAON | F7: O3__BHATAGAON | G7: PM10__BHATAGAON | H7: PM2_5__BHATAGAON | I7: BENZ__BHATAGAON | J7: WS__BHATAGAON | K7: WD__BHATAGAON | L7: TEMP__BHATAGAON | M7: HUM__BHATAGAON | N7: SR__BHATAGAON | O7: RG__BHATAGAON | P7: CO__BHATAGAON | Q7: NH3__BHATAGAON
B8: ug/m3 | C8: ug/m3 | D8: ppb | E8: ug/m3 | F8: ug/m3 | G8: ug/m3 | H8: ug/m3 | I8: ug/m3 | J8: m/sec | K8: deg | L8: degreC | M8: % | N8: w/m2 | O8: mm | P8: mg/m3 | Q8: ug/m3
A9: 07-03-2023 00:15 | B9: 156.19 | C9: 117.34 | D9: 190.01 | E9: 4.71 | F9: 2.65 | G9: 197.63 | H9: 65.11 | I9: 1.54 | J9: 0.74 | K9: 17.38 | L9: 24.13 | M9: 46.6 | N9: 3 | O9: 0 | P9: 2.66 | Q9: 39.36
A10: 07-03-2023 00:30 | B10: 148.9 | C10: 115.65 | D10: 183.23 | E10: 4.91 | F10: 2.79 | G10: 196.92 | H10: 65.19 | I10: 1.52 | J10: 0.58 | K10: 28.67 | L10: 24.33 | M10: 44.84 | N10: 4.1 | O10: 0 | P10: 2.45 | Q10: 38.22
A11: 07-03-2023 00:45 | B11: 142.32 | C11: 115.22 | D11: 177.72 | E11: 4.52 | F11: 2.87 | G11: 196.92 | H11: 65.19 | I11: 1.29 | J11: 0.92 | K11: 37.2 | L11: 24.48 | M11: 43.66 | N11: 3.5 | O11: 0 | P11: 2.7 | Q11: 37.6
A12: 07-03-2023 01:00 | B12: 135.03 | C12: 113.84 | D12: 171.11 | E12: 5.07 | F12: 2.96 | G12: 196.92 | H12: 65.19 | I12: 1.13 | J12: 0.75 | K12: 22.08 | L12: 24.64 | M12: 42.21 | N12: 4 | O12: 0 | P12: 2.18 | Q12: 37.35
A13: 07-03-2023 01:15 | B13: 127.77 | C13: 112.42 | D13: 164.5 | E13: 4.9 | F13: 3.25 | G13: 72.18 | H13: 58.5 | I13: 1.17 | J13: 0.66 | K13: 24.71 | L13: 25.03 | M13: 40.57 | N13: 3.8 | O13: 0 | P13: 1.9 | Q13: 37.06
A14: 07-03-2023 01:30 | B14: 121.09 | C14: 111.15 | D14: 158.44 | E14: 5.23 | F14: 3.3 | G14: 69.35 | H14: 58.34 | I14: 1.04 | J14: 0.45 | K14: 47.24 | L14: 25.27 | M14: 39.95 | N14: 4.4 | O14: 0 | P14: 2.12 | Q14: 36.81
A15: 07-03-2023 01:45 | B15: 115 | C15: 110.33 | D15: 153.11 | E15: 4.87 | F15: 3.04 | G15: 69.35 | H15: 58.34 | I15: 0.92 | J15: 0.34 | K15: 78.24 | L15: 24.69 | M15: 42.11 | N15: 4.7 | O15: 0 | P15: 2.09 | Q15: 36.76
A16: 07-03-2023 02:00 | B16: 110.55 | C16: 109.47 | D16: 149.07 | E16: 5.02 | F16: 3.18 | G16: 69.35 | H16: 58.34 | I16: 1.02 | J16: 0.15 | K16: 55.01 | L16: 24.23 | M16: 43.7 | N16: 4.6 | O16: 0 | P16: 2.27 | Q16: 36.85
A17: 07-03-2023 02:15 | B17: 105.88 | C17: 110.49 | D17: 145.89 | E17: 5.31 | F17: 3.05 | G17: 141.62 | H17: 58.5 | I17: 1.03 | J17: 0.25 | K17: 21.67 | L17: 24.16 | M17: 44.99 | N17: 4.3 | O17: 0 | P17: 2.44 | Q17: 37.61
A18: 07-03-2023 02:30 | B18: 99.38 | C18: 110.53 | D18: 140.7 | E18: 5.78 | F18: 3.1 | G18: 143.26 | H18: 58.5 | I18: 1.07 | J18: 0.51 | K18: 23.4 | L18: 24.06 | M18: 44.77 | N18: 4.1 | O18: 0 | P18: 2.44 | Q18: 38
A19: 07-03-2023 02:45 | B19: 91.73 | C19: 110.37 | D19: 134.48 | E19: 5.42 | F19: 2.95 | G19: 143.26 | H19: 58.5 | I19: 1.19 | J19: 0.2 | K19: 61.85 | L19: 23.76 | M19: 46.45 | N19: 4.5 | O19: 0 | P19: 2.43 | Q19: 37.91
A20: 07-03-2023 03:00 | B20: 84.58 | C20: 110.94 | D20: 129.05 | E20: 5.91 | F20: 2.76 | G20: 143.26 | H20: 58.5 | I20: 1.2 | J20: 0.15 | K20: 195.31 | L20: 24.02 | M20: 45.13 | N20: 3.9 | O20: 0 | P20: 2.39 | Q20: 37.64
... A33: 07-03-2023 06:15 | B33: 54.75 | C33: 104.04 | D33: 101.32 | E33: 5.55 | F33: 3.1 | G33: 55.63 | H33: 52.97 | I33: 0.81 | J33: 0.61 | K33: 358.82 | L33: 21.58 | M33: 51.87 | N33: 5 | O33: 0 | P33: 1.83 | Q33: 36.09
A34: 07-03-2023 06:30 | B34: 54.75 | C34: 104.06 | D34: 101.33 | E34: 7.06 | F34: 3.12 | G34: Invalid | H34: Invalid | I34: 0.82 | J34: 0.51 | K34: 7.79 | L34: 21.44 | M34: 51.83 | N34: 11.6 | O34: 0 | P34: 1.82 | Q34: 35.99
A35: 07-03-2023 06:45 | B35: 56.53 | C35: 104.54 | D35: 103.03 | E35: 7.55 | F35: 3.14 | G35: Invalid | H35: Invalid | I35: 0.8 | J35: 0.8 | K35: 0.34 | L35: 21.62 | M35: 50.47 | N35: 23.4 | O35: 0 | P35: 1.82 | Q35: 35.96
A36: 07-03-2023 07:00 | B36: 58.89 | C36: 106.12 | D36: 105.79 | E36: 7.7 | F36: 2.83 | G36: Invalid | H36: Invalid | I36: 0.78 | J36: 0.75 | K36: 19.69 | L36: 22.32 | M36: 46.93 | N36: 48.9 | O36: 0 | P36: 1.82 | Q36: 35.74
A37: 07-03-2023 07:15 | B37: 61.58 | C37: 107.1 | D37: 108.49 | E37: 7.29 | F37: 2.86 | G37: Invalid | H37: Invalid | I37: 0.77 | J37: 0.55 | K37: 23.19 | L37: 23.49 | M37: 41.65 | N37: 80.2 | O37: 0 | P37: 1.84 | Q37: 35.44
A38: 07-03-2023 07:30 | B38: 63.78 | C38: 106.34 | D38: 109.83 | E38: 6.61 | F38: 2.89 | G38: Invalid | H38: Invalid | I38: 0.75 | J38: 0.77 | K38: 21.46 | L38: 24.96 | M38: 37.22 | N38: 113.2 | O38: 0 | P38: 1.89 | Q38: 35.02
A39: 07-03-2023 07:45 | B39: 65.14 | C39: 105.93 | D39: 110.7 | E39: 5.94 | F39: 3.14 | G39: Invalid | H39: Invalid | I39: 0.72 | J39: 1.08 | K39: 18.99 | L39: 26.02 | M39: 32.89 | N39: 145.1 | O39: 0 | P39: 1.87 | Q39: 34.34
A40: 07-03-2023 08:00 | B40: 64.93 | C40: 105.95 | D40: 110.54 | E40: 2.81 | F40: 3.55 | G40: Invalid | H40: Invalid | I40: 0.71 | J40: 1.04 | K40: 19.51 | L40: 27.2 | M40: 31.61 | N40: 170.9 | O40: 0 | P40: 1.84 | Q40: 33.7
A41: 07-03-2023 08:15 | B41: 64.58 | C41: 106.17 | D41: 110.38 | E41: 6.55 | F41: 3.41 | G41: Invalid | H41: Invalid | I41: 0.71 | J41: 1.01 | K41: 17.52 | L41: 27.84 | M41: 29.8 | N41: 210.4 | O41: 0 | P41: 1.93 | Q41: 33.32
A42: 07-03-2023 08:30 | B42: 64.28 | C42: 105.86 | D42: 109.97 | E42: 7.07 | F42: 3.35 | G42: Invalid | H42: Invalid | I42: 0.67 | J42: 0.77 | K42: 25.03 | L42: 28.11 | M42: 28.51 | N42: 241.3 | O42: 0 | P42: 1.97 | Q42: 33.17
A43: 07-03-2023 08:45 | B43: 62.39 | C43: 105.72 | D43: 108.37 | E43: 6.94 | F43: 3.36 | G43: Invalid | H43: Invalid | I43: 0.66 | J43: 0.91 | K43: 29.46 | L43: 28.59 | M43: 27.22 | N43: 290.5 | O43: 0 | P43: 1.83 | Q43: 33.06
A44: 07-03-2023 09:00 | B44: 59.12 | C44: 105.6 | D44: 105.69 | E44: 6.14 | F44: 3.36 | G44: Invalid | H44: Invalid | I44: 0.68 | J44: 0.92 | K44: 22.67 | L44: 29.54 | M44: 26.77 | N44: 312.4 | O44: 0 | P44: 1.71 | Q44: 32.62
A45: 07-03-2023 09:15 | B45: 55.98 | C45: 106.59 | D45: 103.72 | E45: 6.3 | F45: 3.17 | G45: Invalid | H45: Invalid | I45: 0.67 | J45: 0.78 | K45: 34.84 | L45: 30.91 | M45: 25.37 | N45: 306.3 | O45: 0 | P45: 1.79 | Q45: 32.32
... A49: 07-03-2023 10:15 | B49: 32.71 | C49: 112.06 | D49: 88.08 | E49: 6.02 | F49: 3.04 | G49: Invalid | H49: Invalid | I49: 0.68 | J49: 1.17 | K49: 23.42 | L49: 32.05 | M49: 26.09 | N49: 452.8 | O49: 0 | P49: 1.5 | Q49: 31.52
A50: 07-03-2023 10:30 | B50: 26.31 | C50: 113.25 | D50: 83.6 | E50: 6.01 | F50: 3.03 | G50: 297.69 | H50: 49.65 | I50: 0.65 | J50: 1.65 | K50: 22.97 | L50: 32.57 | M50: 24.77 | N50: 448.9 | O50: 0 | P50: 1.41 | Q50: 31.07
A51: 07-03-2023 10:45 | B51: 20.54 | C51: 114.96 | D51: 79.91 | E51: 5.66 | F51: 3.2 | G51: 297.69 | H51: 49.65 | I51: 0.63 | J51: 1.98 | K51: 29.28 | L51: 33.1 | M51: 22.96 | N51: 516.2 | O51: 0 | P51: 1.33 | Q51: 30.43
A52: 07-03-2023 11:00 | B52: 15.16 | C52: 115.85 | D52: 76.09 | E52: 5.59 | F52: 3.18 | G52: 297.69 | H52: 49.65 | I52: 0.62 | J52: 1.66 | K52: 27.65 | L52: 34.05 | M52: 22.04 | N52: 528.9 | O52: 0 | P52: 1.25 | Q52: 29.47
A53: 07-03-2023 11:15 | B53: 11.73 | C53: 115.86 | D53: 73.35 | E53: 4.81 | F53: 2.94 | G53: 86.24 | H53: 39.45 | I53: 0.61 | J53: 1.95 | K53: 32.99 | L53: 34.65 | M53: 21.34 | N53: 529.3 | O53: 0 | P53: 1.21 | Q53: 28.08
A54: 07-03-2023 11:30 | B54: 9.37 | C54: 116.2 | D54: 71.64 | E54: 4.61 | F54: 3.09 | G54: 86.24 | H54: 39.22 | I54: 0.59 | J54: 1.88 | K54: 31.36 | L54: 34.76 | M54: 21.55 | N54: 515 | O54: 0 | P54: 1.16 | Q54: 26.93
A55: 07-03-2023 11:45 | B55: 7.53 | C55: 116.06 | D55: 70.1 | E55: 4.65 | F55: 3.27 | G55: 86.24 | H55: 39.22 | I55: 0.59 | J55: 1.31 | K55: 26.18 | L55: 35.55 | M55: 20.43 | N55: 528.1 | O55: 0 | P55: 1.13 | Q55: 26.56
A56: 07-03-2023 12:00 | B56: 6.03 | C56: 114.38 | D56: 67.96 | E56: 3.54 | F56: 3.46 | G56: 86.24 | H56: 39.22 | I56: 0.59 | J56: 1.91 | K56: 36 | L56: 35.67 | M56: 19.94 | N56: 525.2 | O56: 0 | P56: 1.06 | Q56: 26.53
A57: 07-03-2023 12:15 | B57: 4.56 | C57: 113.13 | D57: 66.09 | E57: 5.63 | F57: 3.8 | G57: 71.61 | H57: 32.53 | I57: 0.58 | J57: 1.78 | K57: 29.14 | L57: 35.54 | M57: 19.87 | N57: 474.9 | O57: 0 | P57: 1.05 | Q57: 26.3
...

Sheet 08
A1: Station: | B1: BHATAGAON RAIPUR
A2: Date: | B2: =$A$9 -> 08-03-2023 00:15 | D2: Power Off | G2: Pw.Off | L2: Link Fail | N2: Link F | P2: Maintenance | R2: Maint.
A3: Report Type: | B3: Mean | D3: Calibration | G3: Calib. | L3: Data Fail | N3: Data F | P3: Invalid | R3: Invalid
A4: Time Base: | B4: 15 Min | D4: Zero Referrence | G4: Z.Ref | L4: Warm Up | N4: Wm. Up
A7: Date & Time | B7: NO_BHATAGAON | C7: NO2__BHATAGAON | D7: NOX_BHATAGAON | E7: SO2__BHATAGAON | F7: O3__BHATAGAON | G7: PM10__BHATAGAON | H7: PM2_5__BHATAGAON | I7: BENZ__BHATAGAON | J7: WS__BHATAGAON | K7: WD__BHATAGAON | L7: TEMP__BHATAGAON | M7: HUM__BHATAGAON | N7: SR__BHATAGAON | O7: RG__BHATAGAON | P7: CO__BHATAGAON | Q7: NH3__BHATAGAON
B8: ug/m3 | C8: ug/m3 | D8: ppb | E8: ug/m3 | F8: ug/m3 | G8: ug/m3 | H8: ug/m3 | I8: ug/m3 | J8: m/sec | K8: deg | L8: degreC | M8: % | N8: w/m2 | O8: mm | P8: mg/m3 | Q8: ug/m3
A9: 08-03-2023 00:15 | B9: 5.18 | C9: 104.84 | D9: 62.02 | E9: 4.43 | F9: 3.21 | G9: 55.77 | H9: 26.81 | I9: 0.56 | J9: 0.71 | K9: 31.4 | L9: 24.55 | M9: 39.85 | N9: 4 | O9: 0 | P9: 1.1 | Q9: 29.59
A10: 08-03-2023 00:30 | B10: 4.65 | C10: 103.73 | D10: 60.98 | E10: 4.26 | F10: 3.38 | G10: 55.84 | H10: 26.86 | I10: 0.56 | J10: 0.71 | K10: 32.75 | L10: 24.58 | M10: 42.29 | N10: 4.7 | O10: 0 | P10: 1.1 | Q10: 29.83
A11: 08-03-2023 00:45 | B11: 4.13 | C11: 103.43 | D11: 60.4 | E11: 4.99 | F11: 3.22 | G11: 55.84 | H11: 26.86 | I11: 0.56 | J11: 0.43 | K11: 56.14 | L11: 24.25 | M11: 42.58 | N11: 4.7 | O11: 0 | P11: 1.11 | Q11: 29.9
A12: 08-03-2023 01:00 | B12: 4.29 | C12: 104.23 | D12: 60.96 | E12: 6.12 | F12: 2.29 | G12: 55.84 | H12: 26.86 | I12: 0.56 | J12: 0.66 | K12: 35.08 | L12: 24.14 | M12: 43.01 | N12: 4.6 | O12: 0 | P12: 1.14 | Q12: 30.06
A13: 08-03-2023 01:15 | B13: 4.36 | C13: 104.54 | D13: 61.19 | E13: 5.71 | F13: 3.05 | G13: 61.93 | H13: 25.72 | I13: 0.56 | J13: 0.85 | K13: 11.69 | L13: 24.2 | M13: 43.26 | N13: 4.6 | O13: 0 | P13: 1.09 | Q13: 29.9
A14: 08-03-2023 01:30 | B14: 4.41 | C14: 102.83 | D14: 60.29 | E14: 5.63 | F14: 3.06 | G14: 62.07 | H14: 25.7 | I14: 0.56 | J14: 1.21 | K14: 358.98 | L14: 24.07 | M14: 43.67 | N14: 4.7 | O14: 0 | P14: 1.14 | Q14: 29.17
A15: 08-03-2023 01:45 | B15: 4.49 | C15: 101.81 | D15: 59.78 | E15: 5.18 | F15: 2.84 | G15: 62.07 | H15: 25.7 | I15: 0.55 | J15: 0.8 | K15: 41.36 | L15: 24.03 | M15: 42.73 | N15: 4.7 | O15: 0 | P15: 1.09 | Q15: 28.3
A16: 08-03-2023 02:00 | B16: 4.51 | C16: 100.75 | D16: 59.22 | E16: 4.68 | F16: 2.88 | G16: 62.07 | H16: 25.7 | I16: 0.54 | J16: 0.56 | K16: 60.75 | L16: 24.17 | M16: 46.26 | N16: 6.6 | O16: 0.6 | P16: 1.1 | Q16: 28.19
A17: 08-03-2023 02:15 | B17: 4.74 | C17: 100.15 | D17: 59.07 | E17: 4.24 | F17: 3.11 | G17: 48.99 | H17: 26.61 | I17: 0.54 | J17: 0.28 | K17: 70.9 | L17: 21.66 | M17: 70.06 | N17: 8.5 | O17: 2 | P17: 1.06 | Q17: 28.27
A18: 08-03-2023 02:30 | B18: 5.1 | C18: 98.08 | D18: 58.21 | E18: 3.98 | F18: 3.07 | G18: 48.69 | H18: 26.63 | I18: 0.53 | J18: 0.83 | K18: 26.02 | L18: 20.4 | M18: 74.25 | N18: 6.7 | O18: 0.4 | P18: 1.01 | Q18: 28.5
A19: 08-03-2023 02:45 | B19: 5.57 | C19: 96.03 | D19: 57.46 | E19: 4.49 | F19: 2.92 | G19: 48.69 | H19: 26.63 | I19: 0.54 | J19: 1.68 | K19: 29.25 | L19: 20.63 | M19: 71.91 | N19: 6.8 | O19: 0 | P19: 1.04 | Q19: 28.57
A20: 08-03-2023 03:00 | B20: 5.64 | C20: 94.01 | D20: 56.41 | E20: 4.28 | F20: 2.97 | G20: 48.69 | H20: 26.63 | I20: 0.54 | J20: 1.57 | K20: 39.01 | L20: 20.88 | M20: 69.13 | N20: 7.6 | O20: 0 | P20: 1.01 | Q20: 28.42
... A104: 08-03-2023 24:00 | B104: 15.73 | C104: 100.83 | D104: 68.26 | E104: 1.9 | F104: 3.08 | G104: 51.38 | H104: 24.06 | I104: 0.61 | J104: 0.09 | K104: 24.74 | L104: 22.68 | M104: 60.06 | N104: 4.8 | O104: 0 | P104: 1.15 | Q104: 34.68
A106: Min | B106: =MIN(B9:B104) -> 0.78 | C106: =MIN(C9:C104) -> 89.46 | D106: =MIN(D9:D104) -> 50.28 | E106: =MIN(E9:E104) -> 1.43 | F106: =MIN(F9:F104) -> 2.22 | G106: =MIN(G9:G104) -> 12.55 | H106: =MIN(H9:H104) -> 17.5 | I106: =MIN(I9:I104) -> 0.47 | ... Q106: =MIN(Q9:Q104) -> 28.19
A107: Max | B107: =MAX(B9:B104) -> 15.9 | C107: =MAX(C9:C104) -> 105.51 | D107: =MAX(D9:D104) -> 68.26 | E107: =MAX(E9:E104) -> 6.12 | F107: =MAX(F9:F104) -> 4.68 | G107: =MAX(G9:G104) -> 109.94 | H107: =MAX(H9:H104) -> 33.79 | I107: =MAX(I9:I104) -> 0.93 | ... Q107: =MAX(Q9:Q104) -> 36.53
A108: Avg | B108: =AVERAGE(B9:B104) -> 6.733125 | C108: =AVERAGE(C9:C104) -> 96.578542 | D108: =AVERAGE(D9:D104) -> 58.699271 | E108: =AVERAGE(E9:E104) -> 3.8479167 | F108: =AVERAGE(F9:F104) -> 3.3419792 | G108: =AVERAGE(G9:G104) -> 50.767917 | H108: =AVERAGE(H9:H104) -> 25.774167 | I108: =AVERAGE(I9:I104) -> 0.58427083 | ... Q108: =AVERAGE(Q9:Q104) -> 31.999792
A109: Stdev | B109: =STDEV(B9:B104) -> 4.9731666 | C109: =STDEV(C9:C104) -> 4.7505025 | D109: =STDEV(D9:D104) -> 4.925145 | E109: =STDEV(E9:E104) -> 0.77495659 | F109: =STDEV(F9:F104) -> 0.59593645 | G109: =STDEV(G9:G104) -> 19.081321 | H109: =STDEV(H9:H104) -> 4.1352204 | I109: =STDEV(I9:I104) -> 0.073566938 | ... Q109: =STDEV(Q9:Q104) -> 2.0375827
A110: Num | B110: =COUNT(B9:B104) -> 96 | C110: =COUNT(C9:C104) -> 96 | D110: =COUNT(D9:D104) -> 96 | E110: =COUNT(E9:E104) -> 96 | F110: =COUNT(F9:F104) -> 96 | G110: =COUNT(G9:G104) -> 96 | H110: =COUNT(H9:H104) -> 96 | I110: =COUNT(I9:I104) -> 96 | ... Q110: =COUNT(Q9:Q104) -> 96
A111: DCR | B111: =IF(B110>=87,">90%",IF(B110<=87,"<90%")) -> >90% | C111: =IF(C110>=87,">90%",IF(C110<=87,"<90%")) -> >90% | D111: =IF(D110>=87,">90%",IF(D110<=87,"<90%")) -> >90% | E111: =IF(E110>=87,">90%",IF(E110<=87,"<90%")) -> >90% | F111: =IF(F110>=87,">90%",IF(F110<=87,"<90%")) -> >90% | G111: =IF(G110>=87,">90%",IF(G110<=87,"<90%")) -> >90% | H111: =IF(H110>=87,">90%",IF(H110<=87,"<90%")) -> >90% | I111: =IF(I110>=87,">90%",IF(I110<=87,"<90%")) -> >90% | ... Q111: =IF(Q110>=87,">90%",IF(Q110<=87,"<90%")) -> >90%
A112: Status | B112: =IF(B110>=87,"OK",IF(B110<=87,"LESS")) -> OK | C112: =IF(C110>=87,"OK",IF(C110<=87,"LESS")) -> OK | D112: =IF(D110>=87,"OK",IF(D110<=87,"LESS")) -> OK | E112: =IF(E110>=87,"OK",IF(E110<=87,"LESS")) -> OK | F112: =IF(F110>=87,"OK",IF(F110<=87,"LESS")) -> OK | G112: =IF(G110>=87,"OK",IF(G110<=87,"LESS")) -> OK | H112: =IF(H110>=87,"OK",IF(H110<=87,"LESS")) -> OK | I112: =IF(I110>=87,"OK",IF(I110<=87,"LESS")) -> OK | ... Q112: =IF(Q110>=87,"OK",IF(Q110<=87,"LESS")) -> OK
A115: Done by | B115: RK
A117: Comment

Sheet 09
A1: Station: | B1: BHATAGAON RAIPUR
A2: Date: | B2: =$A$9 -> 09-03-2023 00:15 | D2: Power Off | G2: Pw.Off | L2: Link Fail | N2: Link F | P2: Maintenance | R2: Maint.
