Workbook

Sheet 01
A1: Station: | B1: BHATAGAON RAIPUR
A2: Date: | B2: =$A$9 -> 01/09/2025 01:00 | D2: Power Off | G2: Pw.Off | L2: Link Fail | N2: Link F | P2: Maintenance | R2: Maint.
A3: Report Type: | B3: Mean | D3: Calibration | G3: Calib. | L3: Data Fail | N3: Data F | P3: Invalid | R3: Invalid
A4: Time Base: | B4: 01 Hour | D4: Zero Referrence | G4: Z.Ref | L4: Warm Up | N4: Wm. Up
A7: Date & Time | B7: NO_BHATAGAON | C7: NO2__BHATAGAON | D7: NOX_BHATAGAON | E7: SO2__BHATAGAON | F7: O3__BHATAGAON | G7: PM10__BHATAGAON | H7: PM2_5__BHATAGAON | I7: BENZ__BHATAGAON | J7: WS__BHATAGAON | K7: WD__BHATAGAON | L7: TEMP__BHATAGAON | M7: HUM__BHATAGAON | N7: SR__BHATAGAON | O7: RG__BHATAGAON | P7: CO__BHATAGAON | Q7: NH3__BHATAGAON
B8: ug/m3 | C8: ug/m3 | D8: ppb | E8: ug/m3 | F8: ug/m3 | G8: mg/m3 | H8: ug/m3 | I8: ug/m3 | J8: m/sec | K8: deg | L8: degreC | M8: % | N8: w/m2 | O8: mm | P8: ug/m3 | Q8: ug/m3
A9: 01/09/2025 01:00 | B9: 6.63 | C9: 6.45 | D9: 8.49 | E9: 4.85 | F9: 6.7 | G9: 20.68 | H9: 4.96 | I9: 1.78 | J9: 0.1 | K9: 329.11 | L9: 24.65 | M9: 98.14 | N9: 30.8 | O9: 0 | P9: 0.34 | Q9: 9.55
A10: 01/09/2025 02:00 | B10: 5.77 | C10: 6.18 | D10: 7.83 | E10: 4.57 | F10: 9.28 | G10: 16.76 | H10: 4.14 | I10: 1.53 | J10: 0.06 | K10: 305.12 | L10: 24.02 | M10: 98.16 | N10: 30.5 | O10: 0 | P10: 0.36 | Q10: 9.48
A11: 01/09/2025 03:00 | B11: 5.32 | C11: 6.38 | D11: 7.6 | E11: 4.61 | F11: 9.08 | G11: 14.34 | H11: 2.94 | I11: 1.36 | J11: 0.09 | K11: 295.96 | L11: 23.8 | M11: 98.18 | N11: 30.6 | O11: 0 | P11: 0.28 | Q11: 9.46
A12: 01/09/2025 04:00 | B12: 5.29 | C12: 6.26 | D12: 7.52 | E12: 4.73 | F12: 8.67 | G12: 10.99 | H12: 2.1 | I12: 1.24 | J12: 0.27 | K12: 269.11 | L12: 23.42 | M12: 98.19 | N12: 30.6 | O12: 0 | P12: 0.25 | Q12: 9.5
A13: 01/09/2025 05:00 | B13: 6.01 | C13: 7.14 | D13: 8.12 | E13: 4.93 | F13: 9.26 | G13: 10.13 | H13: 1.67 | I13: 1.17 | J13: 0.78 | K13: 157.29 | L13: 23.05 | M13: 98.24 | N13: 30.7 | O13: 0 | P13: 0.29 | Q13: 9.49
A14: 01/09/2025 06:00 | B14: 6.28 | C14: 6.4 | D14: 8.35 | E14: 4.58 | F14: 6.75 | G14: 9.75 | H14: 1.56 | I14: 1.11 | J14: 0.32 | K14: 171.04 | L14: 23.06 | M14: 98.27 | N14: 38.7 | O14: 0 | P14: 0.25 | Q14: 9.48
A15: 01/09/2025 07:00 | B15: 6.69 | C15: 7.27 | D15: 9.02 | E15: 4.52 | F15: 6.25 | G15: 8.82 | H15: 1.39 | I15: 0.97 | J15: 0.11 | K15: 282.89 | L15: 23.61 | M15: 98.27 | N15: 90 | O15: 0 | P15: 0.26 | Q15: 9.47
A16: 01/09/2025 08:00 | B16: 8.83 | C16: 9.11 | D16: 11.85 | E16: 4.41 | F16: 5.11 | G16: 12.87 | H16: 1.41 | I16: 0.98 | J16: 0.14 | K16: 303.82 | L16: 24.63 | M16: 98.14 | N16: 163.1 | O16: 0 | P16: 0.29 | Q16: 9.52
A17: 01/09/2025 09:00 | B17: 9.49 | C17: 9.2 | D17: 11.69 | E17: 3.86 | F17: 5.08 | G17: 21.68 | H17: 1.31 | I17: 1.14 | J17: 0.46 | K17: 323.85 | L17: 26.81 | M17: 98.07 | N17: 254.4 | O17: 0 | P17: 0.42 | Q17: 9.57
A18: 01/09/2025 10:00 | B18: 10.3 | C18: 8.8 | D18: 12.83 | E18: 3.89 | F18: 5.81 | G18: 39.38 | H18: 1.26 | I18: 1.31 | J18: 0.36 | K18: 319.2 | L18: 29.12 | M18: 97.97 | N18: 325.9 | O18: 0 | P18: 0.42 | Q18: 9.59
A19: 01/09/2025 11:00 | B19: 12.73 | C19: 10.1 | D19: 15.48 | E19: 3.79 | F19: 8.98 | G19: 44.48 | H19: 1.36 | I19: 1.35 | J19: 0.78 | K19: 339.04 | L19: 29.89 | M19: 88.03 | N19: 357.2 | O19: 0 | P19: 0.49 | Q19: 9.63
A20: 01/09/2025 12:00 | B20: 11.64 | C20: 10.49 | D20: 14.59 | E20: 3.8 | F20: 9.11 | G20: 43.83 | H20: 1.96 | I20: 1.38 | J20: 1.24 | K20: 336.54 | L20: 31.02 | M20: 80.59 | N20: 565 | O20: 0 | P20: 0.5 | Q20: 9.62
A21: 01/09/2025 13:00 | B21: 10.3 | C21: 11.38 | D21: 13.18 | E21: 4.06 | F21: 3.89 | G21: 43.78 | H21: 2.6 | I21: 1.39 | J21: 1.31 | K21: 337.59 | L21: 31.87 | M21: 74.01 | N21: 576 | O21: 0 | P21: 0.51 | Q21: 9.62
A22: 01/09/2025 14:00 | B22: 13.47 | C22: 17.47 | D22: 19.65 | E22: 3.87 | F22: 10.96 | G22: Calib. | H22: Calib. | I22: 1.28 | J22: 1 | K22: 359.27 | L22: 31.58 | M22: 76.31 | N22: 306.3 | O22: 0 | P22: 0.66 | Q22: 9.55
A23: 01/09/2025 15:00 | B23: 10.21 | C23: 16.87 | D23: 17 | E23: 3.76 | F23: 10.97 | G23: 118.7 | H23: Calib. | I23: 1.15 | J23: 0.66 | K23: 151.43 | L23: 29.19 | M23: 98.17 | N23: 115.5 | O23: 0 | P23: 0.62 | Q23: 9.56
A24: 01/09/2025 16:00 | B24: 6.92 | C24: 15.48 | D24: 13.01 | E24: 3.65 | F24: 7.71 | G24: 118.7 | H24: Calib. | I24: 1.21 | J24: 0.55 | K24: 329.22 | L24: 23.73 | M24: 98.21 | N24: 92.3 | O24: 3 | P24: 0.45 | Q24: 9.58
A25: 01/09/2025 17:00 | B25: 16.47 | C25: 17.7 | D25: 22.46 | E25: 3.7 | F25: 9.55 | G25: 82.58 | H25: 20.2 | I25: 1.15 | J25: 0.1 | K25: 275.57 | L25: 23.51 | M25: 98.2 | N25: 131.9 | O25: 0 | P25: 0.66 | Q25: 9.61
A26: 01/09/2025 18:00 | B26: 19.72 | C26: 15.44 | D26: 23.45 | E26: 3.91 | F26: 8.82 | G26: 52.92 | H26: 40.91 | I26: 1.12 | J26: 0.24 | K26: 343.45 | L26: 24.12 | M26: 98.22 | N26: 84.5 | O26: 0 | P26: 0.98 | Q26: 9.62
A27: 01/09/2025 19:00 | B27: 12.54 | C27: 17.76 | D27: 18.3 | E27: 4.06 | F27: 6.15 | G27: 29.3 | H27: 40.91 | I27: 1.26 | J27: 0.07 | K27: 354.92 | L27: 24.12 | M27: 98.24 | N27: 32.7 | O27: 0 | P27: 0.88 | Q27: 9.63
A28: 01/09/2025 20:00 | B28: 16.84 | C28: 13.6 | D28: 19.47 | E28: 4.02 | F28: 5.31 | G28: 22.79 | H28: 23.32 | I28: 1.43 | J28: 0.06 | K28: 302.25 | L28: 24.15 | M28: 98.25 | N28: 31.3 | O28: 0 | P28: 0.9 | Q28: 9.62
A29: 01/09/2025 21:00 | B29: 12.05 | C29: 16.24 | D29: 17.99 | E29: 3.98 | F29: 5.43 | G29: 27.46 | H29: 13.76 | I29: 1.57 | J29: 0.06 | K29: 346.58 | L29: 24.11 | M29: 98.26 | N29: 31.1 | O29: 0 | P29: 0.71 | Q29: 9.64
A30: 01/09/2025 22:00 | B30: 14.31 | C30: 15.56 | D30: 19.27 | E30: 3.96 | F30: 5.48 | G30: 27.46 | H30: 36.04 | I30: 1.62 | J30: 0.06 | K30: 304.9 | L30: 24.03 | M30: 98.32 | N30: 30.8 | O30: 0 | P30: 0.79 | Q30: 9.64
A31: 01/09/2025 23:00 | B31: 18.52 | C31: 15.62 | D31: 19.83 | E31: 3.79 | F31: 5.14 | G31: 31.15 | H31: 3248.78 | I31: 1.64 | J31: 0.07 | K31: 312.15 | L31: 24.12 | M31: 98.38 | N31: 30.8 | O31: 0 | P31: 0.7 | Q31: 9.65
A32: 01/09/2025 24:00 | B32: 10.86 | C32: 10.1 | D32: 13.81 | E32: 5.03 | F32: 5.68 | G32: 31.15 | H32: 3248.78 | I32: 1.72 | J32: 0.07 | K32: 292.88 | L32: 24.24 | M32: 98.38 | N32: 31.8 | O32: 0 | P32: 0.53 | Q32: 9.66
A34: Min | B34: =MIN(B9:B32) -> 5.29 | C34: =MIN(C9:C32) -> 6.18 | D34: =MIN(D9:D32) -> 7.52 | E34: =MIN(E9:E32) -> 3.65 | F34: =MIN(F9:F32) -> 3.89 | G34: =MIN(G9:G32) -> 8.82 | H34: =MIN(H9:H32) -> 1.26 | I34: =MIN(I9:I32) -> 0.97 | ... Q34: =MIN(Q9:Q32) -> 9.46
A35: Max | B35: =MAX(B9:B32) -> 19.72 | C35: =MAX(C9:C32) -> 17.76 | D35: =MAX(D9:D32) -> 23.45 | E35: =MAX(E9:E32) -> 5.03 | F35: =MAX(F9:F32) -> 10.97 | G35: =MAX(G9:G32) -> 118.7 | H35: =MAX(H9:H32) -> 3248.78 | I35: =MAX(I9:I32) -> 1.78 | ... Q35: =MAX(Q9:Q32) -> 9.66
A36: Avg | B36: =AVERAGE(B9:B32) -> 10.71625 | C36: =AVERAGE(C9:C32) -> 11.541667 | D36: =AVERAGE(D9:D32) -> 14.199583 | E36: =AVERAGE(E9:E32) -> 4.1804167 | F36: =AVERAGE(F9:F32) -> 7.29875 | G36: =AVERAGE(G9:G32) -> 36.508696 | H36: =AVERAGE(H9:H32) -> 319.11238 | I36: =AVERAGE(I9:I32) -> 1.3275 | ... Q36: =AVERAGE(Q9:Q32) -> 9.5725
A37: Stdev | B37: =STDEV(B9:B32) -> 4.2780865 | C37: =STDEV(C9:C32) -> 4.3107516 | D37: =STDEV(D9:D32) -> 5.0440007 | E37: =STDEV(E9:E32) -> 0.43421573 | F37: =STDEV(F9:F32) -> 2.0645124 | G37: =STDEV(G9:G32) -> 31.10302 | H37: =STDEV(H9:H32) -> 974.07708 | I37: =STDEV(I9:I32) -> 0.22370886 | ... Q37: =STDEV(Q9:Q32) -> 0.064757071
A38: Num | B38: =COUNT(B9:B32) -> 24 | C38: =COUNT(C9:C32) -> 24 | D38: =COUNT(D9:D32) -> 24 | E38: =COUNT(E9:E32) -> 24 | F38: =COUNT(F9:F32) -> 24 | G38: =COUNT(G9:G32)+1 -> 24 | H38: =COUNT(H9:H32)+3 -> 24 | I38: =COUNT(I9:I32) -> 24 | J38: =COUNT(J9:J32) -> 24 | K38: =COUNT(K9:K32) -> 24 | L38: =COUNT(L9:L32) -> 24 | M38: =COUNT(M9:M32) -> 24 | N38: =COUNT(N9:N32) -> 24 | O38: =COUNT(O9:O32) -> 24 | P38: =COUNT(P9:P32) -> 24 | Q38: =COUNT(Q9:Q32) -> 24
A39: DCR | B39: =IF(B38>=22,">90%",IF(B38<=22,"<90%")) -> >90% | C39: =IF(C38>=22,">90%",IF(C38<=22,"<90%")) -> >90% | D39: =IF(D38>=22,">90%",IF(D38<=22,"<90%")) -> >90% | E39: =IF(E38>=22,">90%",IF(E38<=22,"<90%")) -> >90% | F39: =IF(F38>=22,">90%",IF(F38<=22,"<90%")) -> >90% | G39: =IF(G38>=22,">90%",IF(G38<=22,"<90%")) -> >90% | H39: =IF(H38>=22,">90%",IF(H38<=22,"<90%")) -> >90% | I39: =IF(I38>=22,">90%",IF(I38<=22,"<90%")) -> >90% | ... Q39: =IF(Q38>=22,">90%",IF(Q38<=22,"<90%")) -> >90%
A40: Status | B40: =IF(B38>=22,"OK",IF(B38<=22,"LESS")) -> OK | C40: =IF(C38>=22,"OK",IF(C38<=22,"LESS")) -> OK | D40: =IF(D38>=22,"OK",IF(D38<=22,"LESS")) -> OK | E40: =IF(E38>=22,"OK",IF(E38<=22,"LESS")) -> OK | F40: =IF(F38>=22,"OK",IF(F38<=22,"LESS")) -> OK | G40: =IF(G38>=22,"OK",IF(G38<=22,"LESS")) -> OK | H40: =IF(H38>=22,"OK",IF(H38<=22,"LESS")) -> OK | I40: =IF(I38>=22,"OK",IF(I38<=22,"LESS")) -> OK | ... Q40: =IF(Q38>=22,"OK",IF(Q38<=22,"LESS")) -> OK
A43: Done by | B43: RAHUL
A45: Comment

Sheet 02
A1: Station: | B1: BHATAGAON RAIPUR
A2: Date: | B2: =$A$9 -> 02/09/2025 01:00 | D2: Power Off | G2: Pw.Off | L2: Link Fail | N2: Link F | P2: Maintenance | R2: Maint.
A3: Report Type: | B3: Mean | D3: Calibration | G3: Calib. | L3: Data Fail | N3: Data F | P3: Invalid | R3: Invalid
A4: Time Base: | B4: 01 Hour | D4: Zero Referrence | G4: Z.Ref | L4: Warm Up | N4: Wm. Up
A7: Date & Time | B7: NO_BHATAGAON | C7: NO2__BHATAGAON | D7: NOX_BHATAGAON | E7: SO2__BHATAGAON | F7: O3__BHATAGAON | G7: PM10__BHATAGAON | H7: PM2_5__BHATAGAON | I7: BENZ__BHATAGAON | J7: WS__BHATAGAON | K7: WD__BHATAGAON | L7: TEMP__BHATAGAON | M7: HUM__BHATAGAON | N7: SR__BHATAGAON | O7: RG__BHATAGAON | P7: CO__BHATAGAON | Q7: NH3__BHATAGAON
B8: ug/m3 | C8: ug/m3 | D8: ppb | E8: ug/m3 | F8: ug/m3 | G8: mg/m3 | H8: ug/m3 | I8: ug/m3 | J8: m/sec | K8: deg | L8: degreC | M8: % | N8: w/m2 | O8: mm | P8: ug/m3 | Q8: ug/m3
A9: 02/09/2025 01:00 | B9: 10.41 | C9: 18.17 | D9: 17.84 | E9: 5.19 | F9: 6.32 | G9: 29.33 | H9: 1.6 | I9: 1.57 | J9: 0.11 | K9: 297.48 | L9: 23.8 | M9: 98.39 | N9: 32.1 | O9: 0 | P9: 0.44 | Q9: 9.66
A10: 02/09/2025 02:00 | B10: 9.38 | C10: 5.6 | D10: 10.44 | E10: 5.06 | F10: 5.16 | G10: 28.67 | H10: 1.2 | I10: 1.47 | J10: 0.14 | K10: 310.42 | L10: 23.32 | M10: 98.38 | N10: 31.1 | O10: 0 | P10: 0.41 | Q10: 9.65
A11: 02/09/2025 03:00 | B11: 7.92 | C11: 5.62 | D11: 9.09 | E11: 5.15 | F11: 4.72 | G11: 24.03 | H11: 1.2 | I11: 1.27 | J11: 0.11 | K11: 303.41 | L11: 22.99 | M11: 98.42 | N11: 31 | O11: 0 | P11: 0.34 | Q11: 9.61
A12: 02/09/2025 04:00 | B12: 7.41 | C12: 6.09 | D12: 8.88 | E12: 5.15 | F12: 3.57 | G12: 21.71 | H12: 1.79 | I12: 1.04 | J12: 0.13 | K12: 297.56 | L12: 23.03 | M12: 98.42 | N12: 31 | O12: 0 | P12: 0.31 | Q12: 9.54
A13: 02/09/2025 05:00 | B13: 7.07 | C13: 7.42 | D13: 9.55 | E13: 4.91 | F13: 4.1 | G13: 17.91 | H13: 3.02 | I13: 0.98 | J13: 0.12 | K13: 309.2 | L13: 23.14 | M13: 98.44 | N13: 30.9 | O13: 0 | P13: 0.29 | Q13: 9.49
A14: 02/09/2025 06:00 | B14: 7.72 | C14: 8.49 | D14: 10.53 | E14: 5.08 | F14: 5.83 | G14: 13.99 | H14: 3.02 | I14: 1.07 | J14: 0.13 | K14: 325.99 | L14: 23.11 | M14: 98.45 | N14: 37.9 | O14: 0 | P14: 0.3 | Q14: 9.52
A15: 02/09/2025 07:00 | B15: 10.75 | C15: 9.75 | D15: 13.55 | E15: 5.07 | F15: 5.5 | G15: 15.24 | H15: 0.36 | I15: 1.32 | J15: 0.1 | K15: 318.08 | L15: 23.32 | M15: 98.48 | N15: 75.9 | O15: 0 | P15: 0.39 | Q15: 9.56
A16: 02/09/2025 08:00 | B16: 15 | C16: 8.06 | D16: 16.24 | E16: 5.12 | F16: 4.59 | G16: 21.01 | H16: 0.78 | I16: 1.46 | J16: 0.2 | K16: 324.65 | L16: 24.67 | M16: 98.44 | N16: 102.8 | O16: 0 | P16: 0.49 | Q16: 9.6
A17: 02/09/2025 09:00 | B17: 13.53 | C17: 7.37 | D17: 14.7 | E17: 4.85 | F17: 5.84 | G17: 35.62 | H17: 1.2 | I17: 1.58 | J17: 0.85 | K17: 338.45 | L17: 27.61 | M17: 98.38 | N17: 405.1 | O17: 0 | P17: 0.47 | Q17: 9.63
A18: 02/09/2025 10:00 | B18: 16.17 | C18: 8.61 | D18: 17 | E18: 4.63 | F18: 9.18 | G18: 38.52 | H18: 1.2 | I18: 1.57 | J18: 1.1 | K18: 334.63 | L18: 29.5 | M18: 91.99 | N18: 364.7 | O18: 0 | P18: 0.52 | Q18: 9.63
A19: 02/09/2025 11:00 | B19: 15.36 | C19: 7.81 | D19: 16.33 | E19: 4.63 | F19: 6.95 | G19: 38.52 | H19: 1.06 | I19: 1.61 | J19: 1.61 | K19: 337.5 | L19: 28.73 | M19: 94.75 | N19: 456.4 | O19: 0 | P19: 0.52 | Q19: 9.65
A20: 02/09/2025 12:00 | B20: 14.18 | C20: 7.34 | D20: 14.55 | E20: 4.76 | F20: 4.7 | G20: 40.06 | H20: 0.23 | I20: 1.6 | J20: 1.76 | K20: 338.58 | L20: 30.8 | M20: 93.98 | N20: 667.9 | O20: 0 | P20: 0.52 | Q20: 9.64
... A32: 02/09/2025 24:00 | B32: 12.8 | C32: 14.75 | D32: 17.22 | E32: 5.14 | F32: 6.42 | G32: 17.86 | H32: 0.5 | I32: 1.47 | J32: 0.25 | K32: 332.96 | L32: 21.78 | M32: 98.63 | N32: 31 | O32: 0 | P32: 0.53 | Q32: 9.65
A34: Min | B34: =MIN(B9:B32) -> 7.07 | C34: =MIN(C9:C32) -> 5.6 | D34: =MIN(D9:D32) -> 8.88 | E34: =MIN(E9:E32) -> 4.39 | F34: =MIN(F9:F32) -> 3.57 | G34: =MIN(G9:G32) -> 13.99 | H34: =MIN(H9:H32) -> 0.01 | I34: =MIN(I9:I32) -> 0.98 | ... Q34: =MIN(Q9:Q32) -> 9.49
A35: Max | B35: =MAX(B9:B32) -> 27.16 | C35: =MAX(C9:C32) -> 33.01 | D35: =MAX(D9:D32) -> 39.03 | E35: =MAX(E9:E32) -> 5.71 | F35: =MAX(F9:F32) -> 15.3 | G35: =MAX(G9:G32) -> 47.36 | H35: =MAX(H9:H32) -> 4.69 | I35: =MAX(I9:I32) -> 1.61 | ... Q35: =MAX(Q9:Q32) -> 9.66
A36: Avg | B36: =AVERAGE(B9:B32) -> 14.436667 | C36: =AVERAGE(C9:C32) -> 11.928333 | D36: =AVERAGE(D9:D32) -> 17.654583 | E36: =AVERAGE(E9:E32) -> 5.0675 | F36: =AVERAGE(F9:F32) -> 7.2379167 | G36: =AVERAGE(G9:G32) -> 32.816667 | H36: =AVERAGE(H9:H32) -> 1.6504167 | I36: =AVERAGE(I9:I32) -> 1.40125 | ... Q36: =AVERAGE(Q9:Q32) -> 9.6179167
A37: Stdev | B37: =STDEV(B9:B32) -> 5.3344595 | C37: =STDEV(C9:C32) -> 6.6890882 | D37: =STDEV(D9:D32) -> 7.3223909 | E37: =STDEV(E9:E32) -> 0.35887808 | F37: =STDEV(F9:F32) -> 3.0154169 | G37: =STDEV(G9:G32) -> 10.632058 | H37: =STDEV(H9:H32) -> 1.1578822 | I37: =STDEV(I9:I32) -> 0.18262131 | ... Q37: =STDEV(Q9:Q32) -> 0.044719334
A38: Num | B38: =COUNT(B9:B32) -> 24 | C38: =COUNT(C9:C32) -> 24 | D38: =COUNT(D9:D32) -> 24 | E38: =COUNT(E9:E32) -> 24 | F38: =COUNT(F9:F32) -> 24 | G38: =COUNT(G9:G32) -> 24 | H38: =COUNT(H9:H32) -> 24 | I38: =COUNT(I9:I32) -> 24 | ... Q38: =COUNT(Q9:Q32) -> 24
A39: DCR | B39: =IF(B38>=22,">90%",IF(B38<=22,"<90%")) -> >90% | C39: =IF(C38>=22,">90%",IF(C38<=22,"<90%")) -> >90% | D39: =IF(D38>=22,">90%",IF(D38<=22,"<90%")) -> >90% | E39: =IF(E38>=22,">90%",IF(E38<=22,"<90%")) -> >90% | F39: =IF(F38>=22,">90%",IF(F38<=22,"<90%")) -> >90% | G39: =IF(G38>=22,">90%",IF(G38<=22,"<90%")) -> >90% | H39: =IF(H38>=22,">90%",IF(H38<=22,"<90%")) -> >90% | I39: =IF(I38>=22,">90%",IF(I38<=22,"<90%")) -> >90% | ... Q39: =IF(Q38>=22,">90%",IF(Q38<=22,"<90%")) -> >90%
A40: Status | B40: =IF(B38>=22,"OK",IF(B38<=22,"LESS")) -> OK | C40: =IF(C38>=22,"OK",IF(C38<=22,"LESS")) -> OK | D40: =IF(D38>=22,"OK",IF(D38<=22,"LESS")) -> OK | E40: =IF(E38>=22,"OK",IF(E38<=22,"LESS")) -> OK | F40: =IF(F38>=22,"OK",IF(F38<=22,"LESS")) -> OK | G40: =IF(G38>=22,"OK",IF(G38<=22,"LESS")) -> OK | H40: =IF(H38>=22,"OK",IF(H38<=22,"LESS")) -> OK | I40: =IF(I38>=22,"OK",IF(I38<=22,"LESS")) -> OK | ... Q40: =IF(Q38>=22,"OK",IF(Q38<=22,"LESS")) -> OK
A43: Done by | B43: RAHUL
A45: Comment

Sheet 03
A1: Station: | B1: BHATAGAON RAIPUR
A2: Date: | B2: =$A$9 -> 03/09/2025 01:00 | D2: Power Off | G2: Pw.Off | L2: Link Fail | N2: Link F | P2: Maintenance | R2: Maint.
A3: Report Type: | B3: Mean | D3: Calibration | G3: Calib. | L3: Data Fail | N3: Data F | P3: Invalid | R3: Invalid
A4: Time Base: | B4: 01 Hour | D4: Zero Referrence | G4: Z.Ref | L4: Warm Up | N4: Wm. Up
A7: Date & Time | B7: NO_BHATAGAON | C7: NO2__BHATAGAON | D7: NOX_BHATAGAON | E7: SO2__BHATAGAON | F7: O3__BHATAGAON | G7: PM10__BHATAGAON | H7: PM2_5__BHATAGAON | I7: BENZ__BHATAGAON | J7: WS__BHATAGAON | K7: WD__BHATAGAON | L7: TEMP__BHATAGAON | M7: HUM__BHATAGAON | N7: SR__BHATAGAON | O7: RG__BHATAGAON | P7: CO__BHATAGAON | Q7: NH3__BHATAGAON
B8: ug/m3 | C8: ug/m3 | D8: ppb | E8: ug/m3 | F8: ug/m3 | G8: mg/m3 | H8: ug/m3 | I8: ug/m3 | J8: m/sec | K8: deg | L8: degreC | M8: % | N8: w/m2 | O8: mm | P8: ug/m3 | Q8: ug/m3
A9: 03/09/2025 01:00 | B9: 10.9 | C9: 8.14 | D9: 12.31 | E9: 4.01 | F9: 7.02 | G9: 12.75 | H9: 1.5 | I9: 1.53 | J9: 0.06 | K9: 251.63 | L9: 21.83 | M9: 98.65 | N9: 31 | O9: 0 | P9: 0.52 | Q9: 9.65
A10: 03/09/2025 02:00 | B10: 13.05 | C10: 6.38 | D10: 12.97 | E10: 3.98 | F10: 4.1 | G10: 16.24 | H10: 2.6 | I10: 1.42 | J10: 0.06 | K10: 263.73 | L10: 21.77 | M10: 98.67 | N10: 31 | O10: 0 | P10: 0.53 | Q10: 9.65
A11: 03/09/2025 03:00 | B11: 11.25 | C11: 6.25 | D11: 11.87 | E11: 3.96 | F11: 4.47 | G11: 16.24 | H11: 2.4 | I11: 1.38 | J11: 0.07 | K11: 334.86 | L11: 21.91 | M11: 98.68 | N11: 31 | O11: 0 | P11: 0.51 | Q11: 9.65
A12: 03/09/2025 04:00 | B12: 9.92 | C12: 9.46 | D12: 11.9 | E12: 3.89 | F12: 5.25 | G12: 12.4 | H12: 1.6 | I12: 1.25 | J12: 0.13 | K12: 316.95 | L12: 21.87 | M12: 98.7 | N12: 31 | O12: 0.4 | P12: 0.48 | Q12: 9.64
A13: 03/09/2025 05:00 | B13: 8.98 | C13: 9.02 | D13: 11.84 | E13: 4 | F13: 4.88 | G13: 12.89 | H13: 1.9 | I13: 1.19 | J13: 0.05 | K13: 201.47 | L13: 21.95 | M13: 98.74 | N13: 31 | O13: 0 | P13: 0.44 | Q13: 9.64
A14: 03/09/2025 06:00 | B14: 10.69 | C14: 7.73 | D14: 11.65 | E14: 4.24 | F14: 4.77 | G14: 15.95 | H14: 1.5 | I14: 1.15 | J14: 0.07 | K14: 326.51 | L14: 22.02 | M14: 98.77 | N14: 33.2 | O14: 0 | P14: 0.46 | Q14: 9.64
A15: 03/09/2025 07:00 | B15: 12.89 | C15: 10.48 | D15: 15.32 | E15: 4.15 | F15: 5.11 | G15: 15.95 | H15: 2.9 | I15: 1.16 | J15: 0.38 | K15: 175.82 | L15: 22.38 | M15: 98.83 | N15: 69.3 | O15: 0 | P15: 0.41 | Q15: 9.65
A16: 03/09/2025 08:00 | B16: 12.22 | C16: 9.71 | D16: 14.11 | E16: 4.67 | F16: 5.82 | G16: 14.23 | H16: 59.46 | I16: 1.15 | J16: 0.27 | K16: 175.86 | L16: 22.49 | M16: 98.82 | N16: 95.2 | O16: 0 | P16: 0.36 | Q16: 9.65
A17: 03/09/2025 09:00 | B17: 11.68 | C17: 9.33 | D17: 13.88 | E17: 4.64 | F17: 8.28 | G17: 14.23 | H17: 59.46 | I17: 1.22 | J17: 0.37 | K17: 156.06 | L17: 23.72 | M17: 98.52 | N17: 289 | O17: 0 | P17: 0.34 | Q17: 9.64
A18: 03/09/2025 10:00 | B18: 11.27 | C18: 10.72 | D18: 13.36 | E18: 4.74 | F18: 9.1 | G18: 14.25 | H18: 2.38 | I18: 1.23 | J18: 0.42 | K18: 155.78 | L18: 25.23 | M18: 98.42 | N18: 285.1 | O18: 0 | P18: 0.34 | Q18: 9.64
A19: 03/09/2025 11:00 | B19: 10.14 | C19: 12.96 | D19: 13.85 | E19: 4.79 | F19: 10.76 | G19: 14.25 | H19: 0.48 | I19: 1.22 | J19: 0.46 | K19: 149.59 | L19: 26.34 | M19: 98.35 | N19: 421.6 | O19: 0 | P19: 0.28 | Q19: 9.64
A20: 03/09/2025 12:00 | B20: 6.26 | C20: 15.51 | D20: 13.13 | E20: 4.64 | F20: 11.52 | G20: 20.52 | H20: 0.48 | I20: 1.04 | J20: 0.87 | K20: 144.44 | L20: 27.11 | M20: 98.27 | N20: 393.2 | O20: 0 | P20: 0.17 | Q20: 9.54
... A32: 03/09/2025 24:00 | B32: 10.88 | C32: 7.7 | D32: 12.72 | E32: 4.34 | F32: 3.43 | G32: 63.08 | H32: 7.43 | I32: 2.06 | J32: 0.24 | K32: 339.34 | L32: 23.06 | M32: 98.32 | N32: 27.4 | O32: 0 | P32: 0.81 | Q32: 9.63
A34: Min | B34: =MIN(B9:B32) -> 6.17 | C34: =MIN(C9:C32) -> 6.25 | D34: =MIN(D9:D32) -> 11.65 | E34: =MIN(E9:E32) -> 3.89 | F34: =MIN(F9:F32) -> 3.43 | G34: =MIN(G9:G32) -> 12.4 | H34: =MIN(H9:H32) -> 0.48 | I34: =MIN(I9:I32) -> 0.87 | ... Q34: =MIN(Q9:Q32) -> 9.49
A35: Max | B35: =MAX(B9:B32) -> 32.65 | C35: =MAX(C9:C32) -> 29.11 | D35: =MAX(D9:D32) -> 38.03 | E35: =MAX(E9:E32) -> 5.31 | F35: =MAX(F9:F32) -> 19.4 | G35: =MAX(G9:G32) -> 99.13 | H35: =MAX(H9:H32) -> 76.97 | I35: =MAX(I9:I32) -> 2.66 | ... Q35: =MAX(Q9:Q32) -> 9.66
A36: Avg | B36: =AVERAGE(B9:B32) -> 13.8575 | C36: =AVERAGE(C9:C32) -> 13.789583 | D36: =AVERAGE(D9:D32) -> 17.663333 | E36: =AVERAGE(E9:E32) -> 4.5975 | F36: =AVERAGE(F9:F32) -> 9.1516667 | G36: =AVERAGE(G9:G32) -> 39.6425 | H36: =AVERAGE(H9:H32) -> 15.509583 | I36: =AVERAGE(I9:I32) -> 1.3991667 | ... Q36: =AVERAGE(Q9:Q32) -> 9.61
A37: Stdev | B37: =STDEV(B9:B32) -> 7.000992 | C37: =STDEV(C9:C32) -> 6.8611581 | D37: =STDEV(D9:D32) -> 8.0674675 | E37: =STDEV(E9:E32) -> 0.43784303 | F37: =STDEV(F9:F32) -> 5.1698698 | G37: =STDEV(G9:G32) -> 30.445102 | H37: =STDEV(H9:H32) -> 22.778134 | I37: =STDEV(I9:I32) -> 0.48407614 | ... Q37: =STDEV(Q9:Q32) -> 0.052750438
A38: Num | B38: =COUNT(B9:B32) -> 24 | C38: =COUNT(C9:C32) -> 24 | D38: =COUNT(D9:D32) -> 24 | E38: =COUNT(E9:E32) -> 24 | F38: =COUNT(F9:F32) -> 24 | G38: =COUNT(G9:G32) -> 24 | H38: =COUNT(H9:H32) -> 24 | I38: =COUNT(I9:I32) -> 24 | ... Q38: =COUNT(Q9:Q32) -> 24
A39: DCR | B39: =IF(B38>=22,">90%",IF(B38<=22,"<90%")) -> >90% | C39: =IF(C38>=22,">90%",IF(C38<=22,"<90%")) -> >90% | D39: =IF(D38>=22,">90%",IF(D38<=22,"<90%")) -> >90% | E39: =IF(E38>=22,">90%",IF(E38<=22,"<90%")) -> >90% | F39: =IF(F38>=22,">90%",IF(F38<=22,"<90%")) -> >90% | G39: =IF(G38>=22,">90%",IF(G38<=22,"<90%")) -> >90% | H39: =IF(H38>=22,">90%",IF(H38<=22,"<90%")) -> >90% | I39: =IF(I38>=22,">90%",IF(I38<=22,"<90%")) -> >90% | ... Q39: =IF(Q38>=22,">90%",IF(Q38<=22,"<90%")) -> >90%
A40: Status | B40: =IF(B38>=22,"OK",IF(B38<=22,"LESS")) -> OK | C40: =IF(C38>=22,"OK",IF(C38<=22,"LESS")) -> OK | D40: =IF(D38>=22,"OK",IF(D38<=22,"LESS")) -> OK | E40: =IF(E38>=22,"OK",IF(E38<=22,"LESS")) -> OK | F40: =IF(F38>=22,"OK",IF(F38<=22,"LESS")) -> OK | G40: =IF(G38>=22,"OK",IF(G38<=22,"LESS")) -> OK | H40: =IF(H38>=22,"OK",IF(H38<=22,"LESS")) -> OK | I40: =IF(I38>=22,"OK",IF(I38<=22,"LESS")) -> OK | ... Q40: =IF(Q38>=22,"OK",IF(Q38<=22,"LESS")) -> OK
A43: Done by | B43: RAHUL
A45: Comment

Sheet 04
A1: Station: | B1: BHATAGAON RAIPUR
A2: Date: | B2: =$A$9 -> 04/09/2025 01:00 | D2: Power Off | G2: Pw.Off | L2: Link Fail | N2: Link F | P2: Maintenance | R2: Maint.
A3: Report Type: | B3: Mean | D3: Calibration | G3: Calib. | L3: Data Fail | N3: Data F | P3: Invalid | R3: Invalid
A4: Time Base: | B4: 01 Hour | D4: Zero Referrence | G4: Z.Ref | L4: Warm Up | N4: Wm. Up
A7: Date & Time | B7: NO_BHATAGAON | C7: NO2__BHATAGAON | D7: NOX_BHATAGAON | E7: SO2__BHATAGAON | F7: O3__BHATAGAON | G7: PM10__BHATAGAON | H7: PM2_5__BHATAGAON | I7: BENZ__BHATAGAON | J7: WS__BHATAGAON | K7: WD__BHATAGAON | L7: TEMP__BHATAGAON | M7: HUM__BHATAGAON | N7: SR__BHATAGAON | O7: RG__BHATAGAON | P7: CO__BHATAGAON | Q7: NH3__BHATAGAON
B8: ug/m3 | C8: ug/m3 | D8: ppb | E8: ug/m3 | F8: ug/m3 | G8: mg/m3 | H8: ug/m3 | I8: ug/m3 | J8: m/sec | K8: deg | L8: degreC | M8: % | N8: w/m2 | O8: mm | P8: ug/m3 | Q8: ug/m3
A9: 04/09/2025 01:00 | B9: 11.34 | C9: 9.73 | D9: 13.9 | E9: 3.98 | F9: 4.94 | G9: 44.98 | H9: 7.67 | I9: 1.85 | J9: 0.13 | K9: 320.76 | L9: 22.88 | M9: 98.37 | N9: 27.6 | O9: 0 | P9: 0.73 | Q9: 9.64
A10: 04/09/2025 02:00 | B10: 10.05 | C10: 7.42 | D10: 11.73 | E10: 4.21 | F10: 7.85 | G10: 36.1 | H10: 7.67 | I10: 1.86 | J10: 0.04 | K10: 286.27 | L10: 22.92 | M10: 98.37 | N10: 27.6 | O10: 0 | P10: 0.57 | Q10: 9.64
A11: 04/09/2025 03:00 | B11: 8.05 | C11: 6.22 | D11: 9.5 | E11: 4.33 | F11: 6.94 | G11: 26.24 | H11: 10.94 | I11: 1.82 | J11: 0.06 | K11: 324.59 | L11: 22.84 | M11: 98.38 | N11: 27.6 | O11: 0 | P11: 0.44 | Q11: 9.64
A12: 04/09/2025 04:00 | B12: 9.59 | C12: 5.49 | D12: 10.56 | E12: 4.32 | F12: 5.68 | G12: 17.41 | H12: 10.94 | I12: 1.68 | J12: 0.09 | K12: 326.09 | L12: 22.88 | M12: 98.39 | N12: 27.6 | O12: 0 | P12: 0.49 | Q12: 9.64
A13: 04/09/2025 05:00 | B13: 9.08 | C13: 6.15 | D13: 10.4 | E13: 4.03 | F13: 4.87 | G13: 15.62 | H13: 8.33 | I13: 1.51 | J13: 0.05 | K13: 327.21 | L13: 22.89 | M13: 98.4 | N13: 27.6 | O13: 0 | P13: 0.41 | Q13: 9.6
A14: 04/09/2025 06:00 | B14: 8.93 | C14: 6.07 | D14: 10.21 | E14: 4.03 | F14: 4.43 | G14: 15.62 | H14: 7.23 | I14: 1.39 | J14: 0.05 | K14: 264.39 | L14: 22.94 | M14: 98.4 | N14: 29.1 | O14: 0 | P14: 0.37 | Q14: 9.59
A15: 04/09/2025 07:00 | B15: 8.75 | C15: 7.3 | D15: 10.74 | E15: 4.04 | F15: 5.75 | G15: 13.76 | H15: 5.06 | I15: 1.39 | J15: 0.06 | K15: 296.91 | L15: 23 | M15: 98.4 | N15: 54.7 | O15: 0 | P15: 0.31 | Q15: 9.63
A16: 04/09/2025 08:00 | B16: 9.84 | C16: 7 | D16: 11.03 | E16: 5.42 | F16: 5.79 | G16: 10.12 | H16: 3.54 | I16: 1.37 | J16: 0.1 | K16: 321.55 | L16: 23.48 | M16: 98.4 | N16: 94.6 | O16: 0 | P16: 0.39 | Q16: 9.63
A17: 04/09/2025 09:00 | B17: 10.37 | C17: 6.12 | D17: 11.18 | E17: 5.19 | F17: 3.51 | G17: 14.33 | H17: 2.48 | I17: 1.31 | J17: 0.16 | K17: 307.75 | L17: 23.99 | M17: 98.4 | N17: 162.2 | O17: 0 | P17: 0.4 | Q17: 9.61
A18: 04/09/2025 10:00 | B18: 9.95 | C18: 6.62 | D18: 11.42 | E18: 4.81 | F18: 3.67 | G18: 14.33 | H18: 1.79 | I18: 1.22 | J18: 0.1 | K18: 318.14 | L18: 24.52 | M18: 98.32 | N18: 290.5 | O18: 0 | P18: 0.36 | Q18: 9.59
A19: 04/09/2025 11:00 | B19: 9.48 | C19: 7.52 | D19: 11.54 | E19: 4.87 | F19: 5.36 | G19: 15.73 | H19: 5.69 | I19: 1.16 | J19: 0.11 | K19: 287.37 | L19: 25.2 | M19: 98.06 | N19: 238.9 | O19: 0 | P19: 0.35 | Q19: 9.57
A20: 04/09/2025 12:00 | B20: 8.4 | C20: 7.36 | D20: 10.58 | E20: 4.86 | F20: 5.77 | G20: 20.42 | H20: 5.69 | I20: 1.12 | J20: 0.12 | K20: 231.93 | L20: 27.42 | M20: 98.03 | N20: 499.7 | O20: 0 | P20: 0.32 | Q20: 9.58
... A32: 04/09/2025 24:00 | B32: 8.13 | C32: 7.45 | D32: 10.41 | E32: 5.65 | F32: 8.05 | G32: 20.01 | H32: 5.93 | I32: 1.05 | J32: 0.11 | K32: 188.92 | L32: 23.01 | M32: 98.34 | N32: 48.1 | O32: 0 | P32: 0.33 | Q32: 9.54
A34: Min | B34: =MIN(B9:B32) -> 6.41 | C34: =MIN(C9:C32) -> 5.49 | D34: =MIN(D9:D32) -> 9.25 | E34: =MIN(E9:E32) -> 3.98 | F34: =MIN(F9:F32) -> 3.51 | G34: =MIN(G9:G32) -> 10.12 | H34: =MIN(H9:H32) -> 1.79 | I34: =MIN(I9:I32) -> 0.89 | ... Q34: =MIN(Q9:Q32) -> 9.48
A35: Max | B35: =MAX(B9:B32) -> 11.34 | C35: =MAX(C9:C32) -> 15.54 | D35: =MAX(D9:D32) -> 15.18 | E35: =MAX(E9:E32) -> 5.65 | F35: =MAX(F9:F32) -> 8.81 | G35: =MAX(G9:G32) -> 44.98 | H35: =MAX(H9:H32) -> 10.94 | I35: =MAX(I9:I32) -> 1.86 | ... Q35: =MAX(Q9:Q32) -> 9.64
A36: Avg | B36: =AVERAGE(B9:B32) -> 8.6166667 | C36: =AVERAGE(C9:C32) -> 8.3070833 | D36: =AVERAGE(D9:D32) -> 11.117917 | E36: =AVERAGE(E9:E32) -> 4.7291667 | F36: =AVERAGE(F9:F32) -> 6.0541667 | G36: =AVERAGE(G9:G32) -> 20.602083 | H36: =AVERAGE(H9:H32) -> 5.9816667 | I36: =AVERAGE(I9:I32) -> 1.2216667 | ... Q36: =AVERAGE(Q9:Q32) -> 9.5608333
A37: Stdev | B37: =STDEV(B9:B32) -> 1.2539803 | C37: =STDEV(C9:C32) -> 2.4601352 | D37: =STDEV(D9:D32) -> 1.5793614 | E37: =STDEV(E9:E32) -> 0.45646007 | F37: =STDEV(F9:F32) -> 1.5158551 | G37: =STDEV(G9:G32) -> 7.4413919 | H37: =STDEV(H9:H32) -> 2.3688057 | I37: =STDEV(I9:I32) -> 0.32129719 | ... Q37: =STDEV(Q9:Q32) -> 0.059776152
A38: Num | B38: =COUNT(B9:B32) -> 24 | C38: =COUNT(C9:C32) -> 24 | D38: =COUNT(D9:D32) -> 24 | E38: =COUNT(E9:E32) -> 24 | F38: =COUNT(F9:F32) -> 24 | G38: =COUNT(G9:G32) -> 24 | H38: =COUNT(H9:H32) -> 24 | I38: =COUNT(I9:I32) -> 24 | ... Q38: =COUNT(Q9:Q32) -> 24
A39: DCR | B39: =IF(B38>=22,">90%",IF(B38<=22,"<90%")) -> >90% | C39: =IF(C38>=22,">90%",IF(C38<=22,"<90%")) -> >90% | D39: =IF(D38>=22,">90%",IF(D38<=22,"<90%")) -> >90% | E39: =IF(E38>=22,">90%",IF(E38<=22,"<90%")) -> >90% | F39: =IF(F38>=22,">90%",IF(F38<=22,"<90%")) -> >90% | G39: =IF(G38>=22,">90%",IF(G38<=22,"<90%")) -> >90% | H39: =IF(H38>=22,">90%",IF(H38<=22,"<90%")) -> >90% | I39: =IF(I38>=22,">90%",IF(I38<=22,"<90%")) -> >90% | ... Q39: =IF(Q38>=22,">90%",IF(Q38<=22,"<90%")) -> >90%
A40: Status | B40: =IF(B38>=22,"OK",IF(B38<=22,"LESS")) -> OK | C40: =IF(C38>=22,"OK",IF(C38<=22,"LESS")) -> OK | D40: =IF(D38>=22,"OK",IF(D38<=22,"LESS")) -> OK | E40: =IF(E38>=22,"OK",IF(E38<=22,"LESS")) -> OK | F40: =IF(F38>=22,"OK",IF(F38<=22,"LESS")) -> OK | G40: =IF(G38>=22,"OK",IF(G38<=22,"LESS")) -> OK | H40: =IF(H38>=22,"OK",IF(H38<=22,"LESS")) -> OK | I40: =IF(I38>=22,"OK",IF(I38<=22,"LESS")) -> OK | ... Q40: =IF(Q38>=22,"OK",IF(Q38<=22,"LESS")) -> OK
A43: Done by | B43: RAHUL
A45: Comment

Sheet 05
A1: Station: | B1: BHATAGAON RAIPUR
A2: Date: | B2: =$A$9 -> 05/09/2025 01:00 | D2: Power Off | G2: Pw.Off | L2: Link Fail | N2: Link F | P2: Maintenance | R2: Maint.
A3: Report Type: | B3: Mean | D3: Calibration | G3: Calib. | L3: Data Fail | N3: Data F | P3: Invalid | R3: Invalid
A4: Time Base: | B4: 01 Hour | D4: Zero Referrence | G4: Z.Ref | L4: Warm Up | N4: Wm. Up
A7: Date & Time | B7: NO_BHATAGAON | C7: NO2__BHATAGAON | D7: NOX_BHATAGAON | E7: SO2__BHATAGAON | F7: O3__BHATAGAON | G7: PM10__BHATAGAON | H7: PM2_5__BHATAGAON | I7: BENZ__BHATAGAON | J7: WS__BHATAGAON | K7: WD__BHATAGAON | L7: TEMP__BHATAGAON | M7: HUM__BHATAGAON | N7: SR__BHATAGAON | O7: RG__BHATAGAON | P7: CO__BHATAGAON | Q7: NH3__BHATAGAON
B8: ug/m3 | C8: ug/m3 | D8: ppb | E8: ug/m3 | F8: ug/m3 | G8: mg/m3 | H8: ug/m3 | I8: ug/m3 | J8: m/sec | K8: deg | L8: degreC | M8: % | N8: w/m2 | O8: mm | P8: ug/m3 | Q8: ug/m3
A9: 05/09/2025 01:00 | B9: 6.64 | C9: 7.01 | D9: 8.81 | E9: 5.86 | F9: 7.45 | G9: 22.38 | H9: 4.8 | I9: 0.92 | J9: 0.13 | K9: 154.49 | L9: 22.9 | M9: 98.47 | N9: 45 | O9: 0 | P9: 0.3 | Q9: 9.57
A10: 05/09/2025 02:00 | B10: 7.94 | C10: 6.06 | D10: 9.36 | E10: 6.05 | F10: 7.98 | G10: 22.38 | H10: 3.36 | I10: 0.89 | J10: 0.08 | K10: 192.62 | L10: 22.84 | M10: 98.58 | N10: 47.4 | O10: 0 | P10: 0.3 | Q10: 9.57
A11: 05/09/2025 03:00 | B11: 7.79 | C11: 5.52 | D11: 9.11 | E11: 5.9 | F11: 7.58 | G11: 16.08 | H11: 9.26 | I11: 0.85 | J11: 0.24 | K11: 131.35 | L11: 22.74 | M11: 98.7 | N11: 45.6 | O11: 0 | P11: 0.29 | Q11: 9.55
A12: 05/09/2025 04:00 | B12: 7.98 | C12: 5.85 | D12: 9.08 | E12: 5.9 | F12: 6.8 | G12: 13.8 | H12: 9.26 | I12: 0.9 | J12: 0.22 | K12: 204.43 | L12: 22.73 | M12: 98.77 | N12: 42.6 | O12: 0 | P12: 0.29 | Q12: 9.55
A13: 05/09/2025 05:00 | B13: 7.29 | C13: 6.9 | D13: 9.45 | E13: 6.04 | F13: 8.28 | G13: 16.74 | H13: 6.48 | I13: 0.89 | J13: 0.41 | K13: 136.07 | L13: 22.8 | M13: 98.65 | N13: 43.5 | O13: 0 | P13: 0.23 | Q13: 9.59
A14: 05/09/2025 06:00 | B14: 9.34 | C14: 9.9 | D14: 12.67 | E14: 6.07 | F14: 8.21 | G14: 16.74 | H14: 4.54 | I14: 0.83 | J14: 0.37 | K14: 155.67 | L14: 22.82 | M14: 98.67 | N14: 50.4 | O14: 0 | P14: 0.26 | Q14: 9.6
A15: 05/09/2025 07:00 | B15: 11.56 | C15: 8.38 | D15: 13.65 | E15: 6.07 | F15: 5.04 | G15: 13.79 | H15: 10.49 | I15: 0.83 | J15: 0.76 | K15: 157.86 | L15: 23.26 | M15: 98.68 | N15: 111.1 | O15: 0 | P15: 0.28 | Q15: 9.59
A16: 05/09/2025 08:00 | B16: 10.71 | C16: 7.51 | D16: 12.44 | E16: 5.99 | F16: 5.16 | G16: 15.38 | H16: 10.49 | I16: 0.82 | J16: 1.04 | K16: 171.7 | L16: 23.61 | M16: 98.68 | N16: 173.1 | O16: 0 | P16: 0.27 | Q16: 9.6
A17: 05/09/2025 09:00 | B17: 11.11 | C17: 7.91 | D17: 12.94 | E17: 4.55 | F17: 7.85 | G17: 15.38 | H17: 7.34 | I17: 0.84 | J17: 1.04 | K17: 150.75 | L17: 24.06 | M17: 98.67 | N17: 229.4 | O17: 0 | P17: 0.29 | Q17: 9.59
A18: 05/09/2025 10:00 | B18: 9.7 | C18: 7.63 | D18: 11.5 | E18: 4.8 | F18: 9.47 | G18: 14.18 | H18: 5.14 | I18: 0.83 | J18: 0.82 | K18: 145.26 | L18: 27.09 | M18: 98.6 | N18: 686.4 | O18: 0 | P18: 0.28 | Q18: 9.58
A19: 05/09/2025 11:00 | B19: 9.05 | C19: 7.22 | D19: 10.93 | E19: 4.79 | F19: 7.4 | G19: 17.35 | H19: 8.99 | I19: 0.83 | J19: 0.89 | K19: 144.19 | L19: 28.35 | M19: 97.03 | N19: 809.3 | O19: 0 | P19: 0.27 | Q19: 9.57
A20: 05/09/2025 12:00 | B20: 8.61 | C20: 8.49 | D20: 10.95 | E20: 4.67 | F20: 10.42 | G20: 17.35 | H20: 8.99 | I20: 0.82 | J20: 0.54 | K20: 213.17 | L20: 29.04 | M20: 91.44 | N20: 705.4 | O20: 0 | P20: 0.27 | Q20: 9.54
... A32: 05/09/2025 24:00 | B32: 9.03 | C32: 9.28 | D32: 12.09 | E32: 5.5 | F32: 9.36 | G32: 35.48 | H32: 7.45 | I32: 0.9 | J32: 0.52 | K32: 145.45 | L32: 24.12 | M32: 98.66 | N32: 35.3 | O32: 0 | P32: 0.3 | Q32: 9.56
A34: Min | B34: =MIN(B9:B32) -> 6.22 | C34: =MIN(C9:C32) -> 5.52 | D34: =MIN(D9:D32) -> 8.81 | E34: =MIN(E9:E32) -> 4.55 | F34: =MIN(F9:F32) -> 5.04 | G34: =MIN(G9:G32) -> 13.79 | H34: =MIN(H9:H32) -> 3.36 | I34: =MIN(I9:I32) -> 0.8 | ... Q34: =MIN(Q9:Q32) -> 9.47
A35: Max | B35: =MAX(B9:B32) -> 13.89 | C35: =MAX(C9:C32) -> 14.03 | D35: =MAX(D9:D32) -> 16.51 | E35: =MAX(E9:E32) -> 6.07 | F35: =MAX(F9:F32) -> 14.34 | G35: =MAX(G9:G32) -> 36.43 | H35: =MAX(H9:H32) -> 10.49 | I35: =MAX(I9:I32) -> 0.98 | ... Q35: =MAX(Q9:Q32) -> 9.6
A36: Avg | B36: =AVERAGE(B9:B32) -> 9.01375 | C36: =AVERAGE(C9:C32) -> 9.1054167 | D36: =AVERAGE(D9:D32) -> 11.784167 | E36: =AVERAGE(E9:E32) -> 5.375 | F36: =AVERAGE(F9:F32) -> 8.6254167 | G36: =AVERAGE(G9:G32) -> 24.08125 | H36: =AVERAGE(H9:H32) -> 6.8275 | I36: =AVERAGE(I9:I32) -> 0.85625 | ... Q36: =AVERAGE(Q9:Q32) -> 9.5479167
A37: Stdev | B37: =STDEV(B9:B32) -> 1.6556328 | C37: =STDEV(C9:C32) -> 2.4202587 | D37: =STDEV(D9:D32) -> 1.9572739 | E37: =STDEV(E9:E32) -> 0.50573236 | F37: =STDEV(F9:F32) -> 2.2748626 | G37: =STDEV(G9:G32) -> 8.4142505 | H37: =STDEV(H9:H32) -> 2.1055233 | I37: =STDEV(I9:I32) -> 0.044897226 | ... Q37: =STDEV(Q9:Q32) -> 0.03967029
A38: Num | B38: =COUNT(B9:B32) -> 24 | C38: =COUNT(C9:C32) -> 24 | D38: =COUNT(D9:D32) -> 24 | E38: =COUNT(E9:E32) -> 24 | F38: =COUNT(F9:F32) -> 24 | G38: =COUNT(G9:G32) -> 24 | H38: =COUNT(H9:H32) -> 24 | I38: =COUNT(I9:I32) -> 24 | ... Q38: =COUNT(Q9:Q32) -> 24
A39: DCR | B39: =IF(B38>=22,">90%",IF(B38<=22,"<90%")) -> >90% | C39: =IF(C38>=22,">90%",IF(C38<=22,"<90%")) -> >90% | D39: =IF(D38>=22,">90%",IF(D38<=22,"<90%")) -> >90% | E39: =IF(E38>=22,">90%",IF(E38<=22,"<90%")) -> >90% | F39: =IF(F38>=22,">90%",IF(F38<=22,"<90%")) -> >90% | G39: =IF(G38>=22,">90%",IF(G38<=22,"<90%")) -> >90% | H39: =IF(H38>=22,">90%",IF(H38<=22,"<90%")) -> >90% | I39: =IF(I38>=22,">90%",IF(I38<=22,"<90%")) -> >90% | ... Q39: =IF(Q38>=22,">90%",IF(Q38<=22,"<90%")) -> >90%
A40: Status | B40: =IF(B38>=22,"OK",IF(B38<=22,"LESS")) -> OK | C40: =IF(C38>=22,"OK",IF(C38<=22,"LESS")) -> OK | D40: =IF(D38>=22,"OK",IF(D38<=22,"LESS")) -> OK | E40: =IF(E38>=22,"OK",IF(E38<=22,"LESS")) -> OK | F40: =IF(F38>=22,"OK",IF(F38<=22,"LESS")) -> OK | G40: =IF(G38>=22,"OK",IF(G38<=22,"LESS")) -> OK | H40: =IF(H38>=22,"OK",IF(H38<=22,"LESS")) -> OK | I40: =IF(I38>=22,"OK",IF(I38<=22,"LESS")) -> OK | ... Q40: =IF(Q38>=22,"OK",IF(Q38<=22,"LESS")) -> OK
A43: Done by | B43: RAHUL
A45: Comment

Sheet 06
A1: Station: | B1: BHATAGAON RAIPUR
A2: Date: | B2: =$A$9 -> 06/09/2025 01:00 | D2: Power Off | G2: Pw.Off | L2: Link Fail | N2: Link F | P2: Maintenance | R2: Maint.
A3: Report Type: | B3: Mean | D3: Calibration | G3: Calib. | L3: Data Fail | N3: Data F | P3: Invalid | R3: Invalid
A4: Time Base: | B4: 01 Hour | D4: Zero Referrence | G4: Z.Ref | L4: Warm Up | N4: Wm. Up
A7: Date & Time | B7: NO_BHATAGAON | C7: NO2__BHATAGAON | D7: NOX_BHATAGAON | E7: SO2__BHATAGAON | F7: O3__BHATAGAON | G7: PM10__BHATAGAON | H7: PM2_5__BHATAGAON | I7: BENZ__BHATAGAON | J7: WS__BHATAGAON | K7: WD__BHATAGAON | L7: TEMP__BHATAGAON | M7: HUM__BHATAGAON | N7: SR__BHATAGAON | O7: RG__BHATAGAON | P7: CO__BHATAGAON | Q7: NH3__BHATAGAON
B8: ug/m3 | C8: ug/m3 | D8: ppb | E8: ug/m3 | F8: ug/m3 | G8: mg/m3 | H8: ug/m3 | I8: ug/m3 | J8: m/sec | K8: deg | L8: degreC | M8: % | N8: w/m2 | O8: mm | P8: ug/m3 | Q8: ug/m3
A9: 06/09/2025 01:00 | B9: 19.83 | C9: 9.12 | D9: 20.37 | E9: 5.56 | F9: 7.82 | G9: 36.51 | H9: 5.21 | I9: 0.95 | J9: 0.11 | K9: 245.63 | L9: 23.86 | M9: 98.76 | N9: 35.4 | O9: 0 | P9: 0.28 | Q9: 9.62
A10: 06/09/2025 02:00 | B10: 8.03 | C10: 8.05 | D10: 10.6 | E10: 5.77 | F10: 7.43 | G10: 36.51 | H10: 3.65 | I10: 1 | J10: 0.34 | K10: 155.22 | L10: 23.53 | M10: 98.72 | N10: 35 | O10: 0 | P10: 0.25 | Q10: 9.65
A11: 06/09/2025 03:00 | B11: 8.45 | C11: 7.34 | D11: 10.17 | E11: 5.7 | F11: 7.16 | G11: 23.84 | H11: 8.38 | I11: 1.01 | J11: 0.22 | K11: 160.5 | L11: 23.49 | M11: 98.69 | N11: 35.1 | O11: 0 | P11: 0.26 | Q11: 9.63
A12: 06/09/2025 04:00 | B12: 8.79 | C12: 7.82 | D12: 10.25 | E12: 5.75 | F12: 5.73 | G12: 25.06 | H12: 8.38 | I12: 0.97 | J12: 0.29 | K12: 152.5 | L12: 23.64 | M12: 98.7 | N12: 35.1 | O12: 0 | P12: 0.26 | Q12: 9.61
A13: 06/09/2025 05:00 | B13: 9.6 | C13: 8.1 | D13: 11.7 | E13: 5.93 | F13: 5.04 | G13: 25.06 | H13: 6.73 | I13: 0.94 | J13: 0.58 | K13: 146.94 | L13: 23.82 | M13: 98.64 | N13: 35.1 | O13: 0 | P13: 0.25 | Q13: 9.6
A14: 06/09/2025 06:00 | B14: 8.46 | C14: 8.08 | D14: 10.94 | E14: 5.56 | F14: 6.27 | G14: 24.49 | H14: 5.21 | I14: 0.93 | J14: 0.58 | K14: 155.53 | L14: 23.87 | M14: 98.58 | N14: 37.9 | O14: 0 | P14: 0.25 | Q14: 9.63
A15: 06/09/2025 07:00 | B15: 12.04 | C15: 7.59 | D15: 12.28 | E15: 5.81 | F15: 4.33 | G15: 24.49 | H15: 10.58 | I15: 0.96 | J15: 0.59 | K15: 145.02 | L15: 24.18 | M15: 98.57 | N15: 96.4 | O15: 0 | P15: 0.28 | Q15: 9.64
A16: 06/09/2025 08:00 | B16: 12.33 | C16: 7.26 | D16: 12.65 | E16: 5.71 | F16: 7.15 | G16: 23.48 | H16: 10.58 | I16: 0.99 | J16: 0.61 | K16: 148.79 | L16: 27.54 | M16: 98.53 | N16: 502.9 | O16: 0.2 | P16: 0.29 | Q16: 9.63
A17: 06/09/2025 09:00 | B17: 9.41 | C17: 7.36 | D17: 11.09 | E17: 4.87 | F17: 13.02 | G17: 25.15 | H17: 7.56 | I17: 1 | J17: 1.14 | K17: 139.28 | L17: 29.22 | M17: 89.43 | N17: 596.2 | O17: 0 | P17: 0.25 | Q17: 9.62
A18: 06/09/2025 10:00 | B18: 8.21 | C18: 7.89 | D18: 10.58 | E18: 5.11 | F18: 13.63 | G18: 25.15 | H18: 5.29 | I18: 0.97 | J18: 0.65 | K18: 145.71 | L18: 30.74 | M18: 85 | N18: 796.9 | O18: 0 | P18: 0.23 | Q18: 9.59
A19: 06/09/2025 11:00 | B19: 10.68 | C19: 8.32 | D19: 12.81 | E19: 5.27 | F19: 11.76 | G19: 25.33 | H19: 9.63 | I19: 0.94 | J19: 0.16 | K19: 287.65 | L19: 30.79 | M19: 85.35 | N19: 873.6 | O19: 0 | P19: 0.28 | Q19: 9.58
A20: 06/09/2025 12:00 | B20: 8.56 | C20: 8.56 | D20: 11.1 | E20: 4.95 | F20: 6.2 | G20: 28.84 | H20: 9.63 | I20: 0.96 | J20: 0.35 | K20: 277.37 | L20: 31.41 | M20: 77.18 | N20: 996.6 | O20: 0 | P20: 0.28 | Q20: 9.55
... A32: 06/09/2025 24:00 | B32: 8.55 | C32: 6.71 | D32: 10.31 | E32: 4.51 | F32: 10.32 | G32: 47.39 | H32: 8.12 | I32: 1.42 | J32: 0.8 | K32: 236.8 | L32: 24.57 | M32: 98.35 | N32: 36.8 | O32: 0 | P32: 0.3 | Q32: 9.64
A34: Min | B34: =MIN(B9:B32) -> 6.63 | C34: =MIN(C9:C32) -> 6.71 | D34: =MIN(D9:D32) -> 9.83 | E34: =MIN(E9:E32) -> 4.02 | F34: =MIN(F9:F32) -> 4.33 | G34: =MIN(G9:G32) -> 23.48 | H34: =MIN(H9:H32) -> 3.65 | I34: =MIN(I9:I32) -> 0.74 | ... Q34: =MIN(Q9:Q32) -> 9.46
A35: Max | B35: =MAX(B9:B32) -> 25.87 | C35: =MAX(C9:C32) -> 25.37 | D35: =MAX(D9:D32) -> 26.53 | E35: =MAX(E9:E32) -> 5.93 | F35: =MAX(F9:F32) -> 18.98 | G35: =MAX(G9:G32) -> 53.23 | H35: =MAX(H9:H32) -> 10.58 | I35: =MAX(I9:I32) -> 1.43 | ... Q35: =MAX(Q9:Q32) -> 9.65
A36: Avg | B36: =AVERAGE(B9:B32) -> 11.02625 | C36: =AVERAGE(C9:C32) -> 11.28625 | D36: =AVERAGE(D9:D32) -> 14.179583 | E36: =AVERAGE(E9:E32) -> 5.025 | F36: =AVERAGE(F9:F32) -> 9.9508333 | G36: =AVERAGE(G9:G32) -> 34.39875 | H36: =AVERAGE(H9:H32) -> 7.2979167 | I36: =AVERAGE(I9:I32) -> 1.0058333 | ... Q36: =AVERAGE(Q9:Q32) -> 9.57375
A37: Stdev | B37: =STDEV(B9:B32) -> 4.5658199 | C37: =STDEV(C9:C32) -> 5.6499171 | D37: =STDEV(D9:D32) -> 5.0172342 | E37: =STDEV(E9:E32) -> 0.61849748 | F37: =STDEV(F9:F32) -> 4.2173646 | G37: =STDEV(G9:G32) -> 11.069773 | H37: =STDEV(H9:H32) -> 1.8569446 | I37: =STDEV(I9:I32) -> 0.17136071 | ... Q37: =STDEV(Q9:Q32) -> 0.064525863
A38: Num | B38: =COUNT(B9:B32) -> 24 | C38: =COUNT(C9:C32) -> 24 | D38: =COUNT(D9:D32) -> 24 | E38: =COUNT(E9:E32) -> 24 | F38: =COUNT(F9:F32) -> 24 | G38: =COUNT(G9:G32) -> 24 | H38: =COUNT(H9:H32) -> 24 | I38: =COUNT(I9:I32) -> 24 | ... Q38: =COUNT(Q9:Q32) -> 24
A39: DCR | B39: =IF(B38>=22,">90%",IF(B38<=22,"<90%")) -> >90% | C39: =IF(C38>=22,">90%",IF(C38<=22,"<90%")) -> >90% | D39: =IF(D38>=22,">90%",IF(D38<=22,"<90%")) -> >90% | E39: =IF(E38>=22,">90%",IF(E38<=22,"<90%")) -> >90% | F39: =IF(F38>=22,">90%",IF(F38<=22,"<90%")) -> >90% | G39: =IF(G38>=22,">90%",IF(G38<=22,"<90%")) -> >90% | H39: =IF(H38>=22,">90%",IF(H38<=22,"<90%")) -> >90% | I39: =IF(I38>=22,">90%",IF(I38<=22,"<90%")) -> >90% | ... Q39: =IF(Q38>=22,">90%",IF(Q38<=22,"<90%")) -> >90%
A40: Status | B40: =IF(B38>=22,"OK",IF(B38<=22,"LESS")) -> OK | C40: =IF(C38>=22,"OK",IF(C38<=22,"LESS")) -> OK | D40: =IF(D38>=22,"OK",IF(D38<=22,"LESS")) -> OK | E40: =IF(E38>=22,"OK",IF(E38<=22,"LESS")) -> OK | F40: =IF(F38>=22,"OK",IF(F38<=22,"LESS")) -> OK | G40: =IF(G38>=22,"OK",IF(G38<=22,"LESS")) -> OK | H40: =IF(H38>=22,"OK",IF(H38<=22,"LESS")) -> OK | I40: =IF(I38>=22,"OK",IF(I38<=22,"LESS")) -> OK | ... Q40: =IF(Q38>=22,"OK",IF(Q38<=22,"LESS")) -> OK
A43: Done by | B43: RAHUL
A45: Comment

Sheet 07
A1: Station: | B1: BHATAGAON RAIPUR
A2: Date: | B2: =$A$9 -> 07/09/2025 01:00 | D2: Power Off | G2: Pw.Off | L2: Link Fail | N2: Link F | P2: Maintenance | R2: Maint.
A3: Report Type: | B3: Mean | D3: Calibration | G3: Calib. | L3: Data Fail | N3: Data F | P3: Invalid | R3: Invalid
A4: Time Base: | B4: 01 Hour | D4: Zero Referrence | G4: Z.Ref | L4: Warm Up | N4: Wm. Up
A7: Date & Time | B7: NO_BHATAGAON | C7: NO2__BHATAGAON | D7: NOX_BHATAGAON | E7: SO2__BHATAGAON | F7: O3__BHATAGAON | G7: PM10__BHATAGAON | H7: PM2_5__BHATAGAON | I7: BENZ__BHATAGAON | J7: WS__BHATAGAON | K7: WD__BHATAGAON | L7: TEMP__BHATAGAON | M7: HUM__BHATAGAON | N7: SR__BHATAGAON | O7: RG__BHATAGAON | P7: CO__BHATAGAON | Q7: NH3__BHATAGAON
B8: ug/m3 | C8: ug/m3 | D8: ppb | E8: ug/m3 | F8: ug/m3 | G8: mg/m3 | H8: ug/m3 | I8: ug/m3 | J8: m/sec | K8: deg | L8: degreC | M8: % | N8: w/m2 | O8: mm | P8: ug/m3 | Q8: ug/m3
A9: 07/09/2025 01:00 | B9: 8.41 | C9: 6.45 | D9: 9.92 | E9: 5.08 | F9: 9.15 | G9: 39.21 | H9: 5.69 | I9: 1.35 | J9: 0.53 | K9: 253.37 | L9: 24.25 | M9: 98.38 | N9: 36.2 | O9: 0 | P9: 0.31 | Q9: 9.66
A10: 07/09/2025 02:00 | B10: 7.38 | C10: 5.92 | D10: 8.96 | E10: 4.83 | F10: 9.62 | G10: 32.44 | H10: 4.21 | I10: 1.26 | J10: 0.29 | K10: 282.25 | L10: 24.23 | M10: 98.41 | N10: 36.1 | O10: 0 | P10: 0.23 | Q10: 9.64
A11: 07/09/2025 03:00 | B11: 7.81 | C11: 5.73 | D11: 9.1 | E11: 4.93 | F11: 7.84 | G11: 29 | H11: 9.1 | I11: 1.14 | J11: 0.25 | K11: 208.38 | L11: 23.96 | M11: 98.43 | N11: 36 | O11: 0 | P11: 0.25 | Q11: 9.59
A12: 07/09/2025 04:00 | B12: 7.9 | C12: 5.99 | D12: 8.97 | E12: 4.99 | F12: 8.24 | G12: 20.67 | H12: 9.1 | I12: 1.06 | J12: 0.2 | K12: 168.53 | L12: 23.67 | M12: 98.47 | N12: 35.9 | O12: 0 | P12: 0.24 | Q12: 9.57
A13: 07/09/2025 05:00 | B13: 7.2 | C13: 6.46 | D13: 9.03 | E13: 4.76 | F13: 7.35 | G13: 20.31 | H13: 6.37 | I13: 1 | J13: 0.42 | K13: 297.58 | L13: 23.54 | M13: 98.48 | N13: 35.8 | O13: 0 | P13: 0.21 | Q13: 9.58
A14: 07/09/2025 06:00 | B14: 7.15 | C14: 7.21 | D14: 9.24 | E14: 5.02 | F14: 6.24 | G14: 19.35 | H14: 4.46 | I14: 1.03 | J14: 0.22 | K14: 332.96 | L14: 23.61 | M14: 98.48 | N14: 42 | O14: 0 | P14: 0.25 | Q14: 9.57
A15: 07/09/2025 07:00 | B15: 18.53 | C15: 7.38 | D15: 17.84 | E15: 4.79 | F15: 5.04 | G15: 23.96 | H15: 8.73 | I15: 1.01 | J15: 0.06 | K15: 287.45 | L15: 25.15 | M15: 98.48 | N15: 159 | O15: 0 | P15: 0.33 | Q15: 9.55
A16: 07/09/2025 08:00 | B16: 13.3 | C16: 8.54 | D16: 13.92 | E16: 4.74 | F16: 6.37 | G16: 32.19 | H16: 8.73 | I16: 1.04 | J16: 0.12 | K16: 305.15 | L16: 26.86 | M16: 98.35 | N16: 301.6 | O16: 0 | P16: 0.4 | Q16: 9.59
A17: 07/09/2025 09:00 | B17: 13.3 | C17: 9.59 | D17: 15.67 | E17: 4.56 | F17: 8.64 | G17: 41.05 | H17: 6.11 | I17: 1.35 | J17: 0.2 | K17: 330.6 | L17: 30.18 | M17: 92.43 | N17: 564.7 | O17: 0 | P17: 0.62 | Q17: 9.64
A18: 07/09/2025 10:00 | B18: 11.74 | C18: 9.76 | D18: 14.51 | E18: 4.69 | F18: 8.73 | G18: 42.17 | H18: 4.28 | I18: 1.59 | J18: 0.27 | K18: 338.59 | L18: 32.41 | M18: 79.41 | N18: 781.4 | O18: 0 | P18: 0.5 | Q18: 9.63
A19: 07/09/2025 11:00 | B19: 9.98 | C19: 13.91 | D19: 15.27 | E19: 4.65 | F19: 13.05 | G19: 42.17 | H19: 10.5 | I19: 1.67 | J19: 0.2 | K19: 318.79 | L19: 32.12 | M19: 78.2 | N19: 772.6 | O19: 0 | P19: 0.62 | Q19: 9.6
A20: 07/09/2025 12:00 | B20: 9.73 | C20: 10.41 | D20: 13.24 | E20: 4.65 | F20: 10.25 | G20: 46.96 | H20: 10.5 | I20: 1.96 | J20: 0.58 | K20: 334.91 | L20: 31.91 | M20: 80.01 | N20: 651.2 | O20: 0 | P20: 0.54 | Q20: 9.53
... A29: 07/09/2025 21:00 | B29: 5.01 | C29: 4.6 | D29: 6.42 | E29: 3.74 | F29: 8.43 | G29: 22.47 | H29: 7.66 | I29: 0 | J29: 0.27 | K29: 151.77 | L29: 21.22 | M29: 98.57 | N29: 29.9 | O29: 0 | P29: 0.25 | Q29: 9.44
A30: 07/09/2025 22:00 | B30: Pw.Off | C30: Pw.Off | D30: Pw.Off | E30: Pw.Off | F30: Pw.Off | G30: Pw.Off | H30: Pw.Off | I30: Pw.Off | J30: Pw.Off | K30: Pw.Off | L30: Pw.Off | M30: Pw.Off | N30: Pw.Off | O30: Pw.Off | P30: Pw.Off | Q30: Pw.Off
A31: 07/09/2025 23:00 | B31: 12.17 | C31: 5.42 | D31: 12.59 | E31: 5.23 | F31: 5.16 | G31: 11.97 | H31: 4.21 | I31: 0 | J31: 0.44 | K31: 265.92 | L31: 22.59 | M31: 98.52 | N31: 30.2 | O31: 0 | P31: 0.36 | Q31: 9.4
A32: 07/09/2025 24:00 | B32: 14.33 | C32: 15.46 | D32: 18.42 | E32: 4.07 | F32: 2.87 | G32: 33.75 | H32: 22.43 | I32: 1.76 | J32: 0.06 | K32: 359.73 | L32: 22.78 | M32: 98.1 | N32: 30.4 | O32: 0 | P32: 0.28 | Q32: 9.67
A34: Min | B34: =MIN(B9:B32) -> 4.98 | C34: =MIN(C9:C32) -> 4.6 | D34: =MIN(D9:D32) -> 6.42 | E34: =MIN(E9:E32) -> 3.74 | F34: =MIN(F9:F32) -> 2.87 | G34: =MIN(G9:G32) -> 11.97 | H34: =MIN(H9:H32) -> 4.21 | I34: =MIN(I9:I32) -> 0 | ... Q34: =MIN(Q9:Q32) -> 9.4
A35: Max | B35: =MAX(B9:B32) -> 18.53 | C35: =MAX(C9:C32) -> 22.89 | D35: =MAX(D9:D32) -> 23.49 | E35: =MAX(E9:E32) -> 5.23 | F35: =MAX(F9:F32) -> 14.16 | G35: =MAX(G9:G32) -> 50.6 | H35: =MAX(H9:H32) -> 22.43 | I35: =MAX(I9:I32) -> 2.08 | ... Q35: =MAX(Q9:Q32) -> 9.67
A36: Avg | B36: =AVERAGE(B9:B32) -> 9.4882609 | C36: =AVERAGE(C9:C32) -> 10.133913 | D36: =AVERAGE(D9:D32) -> 12.607826 | E36: =AVERAGE(E9:E32) -> 4.7273913 | F36: =AVERAGE(F9:F32) -> 8.793913 | G36: =AVERAGE(G9:G32) -> 35.634783 | H36: =AVERAGE(H9:H32) -> 8.4426087 | I36: =AVERAGE(I9:I32) -> 1.3717391 | ... Q36: =AVERAGE(Q9:Q32) -> 9.5373913
A37: Stdev | B37: =STDEV(B9:B32) -> 3.4667874 | C37: =STDEV(C9:C32) -> 4.2922793 | D37: =STDEV(D9:D32) -> 3.8015618 | E37: =STDEV(E9:E32) -> 0.3159289 | F37: =STDEV(F9:F32) -> 2.9430114 | G37: =STDEV(G9:G32) -> 11.386548 | H37: =STDEV(H9:H32) -> 3.8532126 | I37: =STDEV(I9:I32) -> 0.55506472 | ... Q37: =STDEV(Q9:Q32) -> 0.08421927
A38: Num | B38: =COUNT(B9:B32)+1 -> 24 | C38: =COUNT(C9:C32)+1 -> 24 | D38: =COUNT(D9:D32)+1 -> 24 | E38: =COUNT(E9:E32)+1 -> 24 | F38: =COUNT(F9:F32)+1 -> 24 | G38: =COUNT(G9:G32)+1 -> 24 | H38: =COUNT(H9:H32)+1 -> 24 | I38: =COUNT(I9:I32)+1 -> 24 | ... Q38: =COUNT(Q9:Q32)+1 -> 24
A39: DCR | B39: =IF(B38>=22,">90%",IF(B38<=22,"<90%")) -> >90% | C39: =IF(C38>=22,">90%",IF(C38<=22,"<90%")) -> >90% | D39: =IF(D38>=22,">90%",IF(D38<=22,"<90%")) -> >90% | E39: =IF(E38>=22,">90%",IF(E38<=22,"<90%")) -> >90% | F39: =IF(F38>=22,">90%",IF(F38<=22,"<90%")) -> >90% | G39: =IF(G38>=22,">90%",IF(G38<=22,"<90%")) -> >90% | H39: =IF(H38>=22,">90%",IF(H38<=22,"<90%")) -> >90% | I39: =IF(I38>=22,">90%",IF(I38<=22,"<90%")) -> >90% | ... Q39: =IF(Q38>=22,">90%",IF(Q38<=22,"<90%")) -> >90%
A40: Status | B40: =IF(B38>=22,"OK",IF(B38<=22,"LESS")) -> OK | C40: =IF(C38>=22,"OK",IF(C38<=22,"LESS")) -> OK | D40: =IF(D38>=22,"OK",IF(D38<=22,"LESS")) -> OK | E40: =IF(E38>=22,"OK",IF(E38<=22,"LESS")) -> OK | F40: =IF(F38>=22,"OK",IF(F38<=22,"LESS")) -> OK | G40: =IF(G38>=22,"OK",IF(G38<=22,"LESS")) -> OK | H40: =IF(H38>=22,"OK",IF(H38<=22,"LESS")) -> OK | I40: =IF(I38>=22,"OK",IF(I38<=22,"LESS")) -> OK | ... Q40: =IF(Q38>=22,"OK",IF(Q38<=22,"LESS")) -> OK
A43: Done by | B43: RAHUL
A45: Comment

Sheet 08
A1: Station: | B1: BHATAGAON RAIPUR
A2: Date: | B2: =$A$9 -> 08/09/2025 01:00 | D2: Power Off | G2: Pw.Off | L2: Link Fail | N2: Link F | P2: Maintenance | R2: Maint.
A3: Report Type: | B3: Mean | D3: Calibration | G3: Calib. | L3: Data Fail | N3: Data F | P3: Invalid | R3: Invalid
A4: Time Base: | B4: 01 Hour | D4: Zero Referrence | G4: Z.Ref | L4: Warm Up | N4: Wm. Up
A7: Date & Time | B7: NO_BHATAGAON | C7: NO2__BHATAGAON | D7: NOX_BHATAGAON | E7: SO2__BHATAGAON | F7: O3__BHATAGAON | G7: PM10__BHATAGAON | H7: PM2_5__BHATAGAON | I7: BENZ__BHATAGAON | J7: WS__BHATAGAON | K7: WD__BHATAGAON | L7: TEMP__BHATAGAON | M7: HUM__BHATAGAON | N7: SR__BHATAGAON | O7: RG__BHATAGAON | P7: CO__BHATAGAON | Q7: NH3__BHATAGAON
B8: ug/m3 | C8: ug/m3 | D8: ppb | E8: ug/m3 | F8: ug/m3 | G8: mg/m3 | H8: ug/m3 | I8: ug/m3 | J8: m/sec | K8: deg | L8: degreC | M8: % | N8: w/m2 | O8: mm | P8: ug/m3 | Q8: ug/m3
A9: 08/09/2025 01:00 | B9: 11.27 | C9: 11.36 | D9: 12.98 | E9: 4 | F9: 7.02 | G9: 33.75 | H9: 22.43 | I9: 1.76 | J9: 0.25 | K9: 303.44 | L9: 22.83 | M9: 98.24 | N9: 30.2 | O9: 0 | P9: 0.13 | Q9: 9.52
A10: 08/09/2025 02:00 | B10: 9.65 | C10: 11.64 | D10: 12.58 | E10: 2.29 | F10: 7.74 | G10: 22.46 | H10: 15.03 | I10: 1.68 | J10: 0.66 | K10: 136.27 | L10: 22.77 | M10: 97.99 | N10: 30.3 | O10: 0 | P10: 0.29 | Q10: 9.49
A11: 08/09/2025 03:00 | B11: 8.22 | C11: 11.38 | D11: 12.53 | E11: 1.83 | F11: 7.28 | G11: 21.44 | H11: 12.28 | I11: 1.6 | J11: 0.35 | K11: 337.15 | L11: 22.81 | M11: 98.08 | N11: 30.2 | O11: 0 | P11: 0.26 | Q11: 9.49
A12: 08/09/2025 04:00 | B12: 9.16 | C12: 7.2 | D12: 10.11 | E12: 1.73 | F12: 6.49 | G12: 21.44 | H12: 12.28 | I12: 1.5 | J12: 0.07 | K12: 209.57 | L12: 22.79 | M12: 97.95 | N12: 30.3 | O12: 0 | P12: 0.31 | Q12: 9.43
A13: 08/09/2025 05:00 | B13: 9.31 | C13: 10.24 | D13: 12.82 | E13: 1.39 | F13: 4.66 | G13: 16.55 | H13: 11.12 | I13: 1.39 | J13: 0.09 | K13: 282.63 | L13: 22.77 | M13: 98.2 | N13: 30.1 | O13: 0 | P13: 0.31 | Q13: 9.39
A14: 08/09/2025 06:00 | B14: 9.49 | C14: 9.3 | D14: 11.8 | E14: 1.12 | F14: 3.29 | G14: 16.55 | H14: 8.04 | I14: 1.3 | J14: 0.07 | K14: 306.72 | L14: 22.89 | M14: 98.3 | N14: 42.7 | O14: 0 | P14: 0.28 | Q14: 9.41
A15: 08/09/2025 07:00 | B15: 11.03 | C15: 8.59 | D15: 12.99 | E15: 1.22 | F15: 4.08 | G15: 16.94 | H15: 9.3 | I15: 1.23 | J15: 0.1 | K15: 140.76 | L15: 23.35 | M15: 98.24 | N15: 98.6 | O15: 0 | P15: 0.27 | Q15: 9.43
A16: 08/09/2025 08:00 | B16: 13.04 | C16: 8.15 | D16: 13.65 | E16: 3.29 | F16: 4.58 | G16: 16.94 | H16: 9.3 | I16: 1.24 | J16: 0.16 | K16: 234.21 | L16: 25.38 | M16: 98.3 | N16: 309.3 | O16: 0.2 | P16: 0.29 | Q16: 9.44
A17: 08/09/2025 09:00 | B17: 11.67 | C17: 9.73 | D17: 12.68 | E17: 3.75 | F17: 6.64 | G17: Maint. | H17: Maint. | I17: 1.42 | J17: 0.12 | K17: 303.57 | L17: 29.53 | M17: 98.25 | N17: 575.7 | O17: 0 | P17: 0.41 | Q17: 9.44
A18: 08/09/2025 10:00 | B18: 9.29 | C18: 13.7 | D18: 13.72 | E18: 3.87 | F18: 5.73 | G18: 73.37 | H18: Maint. | I18: 2.41 | J18: 0.17 | K18: 301.81 | L18: 30.57 | M18: 92.06 | N18: 556.1 | O18: 0.2 | P18: 0.6 | Q18: 9.32
A19: 08/09/2025 11:00 | B19: 7.85 | C19: 12.79 | D19: 12.44 | E19: 3.79 | F19: 12.08 | G19: 132.07 | H19: Maint. | I19: 2.82 | J19: 0.18 | K19: 325.42 | L19: 31.94 | M19: 94.52 | N19: 927.6 | O19: 0 | P19: 0.59 | Q19: 9.29
A20: 08/09/2025 12:00 | B20: 12.09 | C20: 13.7 | D20: 15.78 | E20: 4.03 | F20: 9.25 | G20: 100.5 | H20: Maint. | I20: 2.8 | J20: 0.51 | K20: 330 | L20: 30.74 | M20: 90.74 | N20: 318.7 | O20: 0 | P20: 0.62 | Q20: 9.31
A21: 08/09/2025 13:00 | B21: 10.43 | C21: 9.92 | D21: 13.26 | E21: 4.17 | F21: 6.82 | G21: 79.25 | H21: Maint. | I21: 2.7 | J21: 1.67 | K21: 339.22 | L21: 28.6 | M21: 98.57 | N21: 153 | O21: 0.8 | P21: 0.55 | Q21: 9.31
A22: 08/09/2025 14:00 | B22: 12.95 | C22: 11.25 | D22: 15.84 | E22: 4.08 | F22: 6.26 | G22: 60.18 | H22: Maint. | I22: 2.33 | J22: 0.85 | K22: 341.9 | L22: 24.38 | M22: 98.65 | N22: 258.1 | O22: 0.8 | P22: 0.57 | Q22: 9.34
A23: 08/09/2025 15:00 | B23: 13.83 | C23: 11.49 | D23: 17.1 | E23: 4.05 | F23: 6.84 | G23: 49.32 | H23: Maint. | I23: 2.18 | J23: 0.98 | K23: 339.25 | L23: 26.35 | M23: 98.71 | N23: 280.8 | O23: 0 | P23: 0.56 | Q23: 9.38
A24: 08/09/2025 16:00 | B24: 14.15 | C24: 10.22 | D24: 16.64 | E24: 4.09 | F24: 9.29 | G24: 43.36 | H24: Maint. | I24: 2.1 | J24: 1.46 | K24: 340.24 | L24: 27.45 | M24: 98.51 | N24: 204.5 | O24: 0 | P24: 0.55 | Q24: 9.44
A25: 08/09/2025 17:00 | B25: 24.49 | C25: 14.89 | D25: 27.39 | E25: 4.06 | F25: 9.17 | G25: 53.21 | H25: Maint. | I25: 1.99 | J25: 1.45 | K25: 339.26 | L25: 27.61 | M25: 98.49 | N25: 157.4 | O25: 0 | P25: 0.7 | Q25: 9.53
A26: 08/09/2025 18:00 | B26: 36.44 | C26: 22.48 | D26: 38.5 | E26: 4.47 | F26: 6.84 | G26: 63.72 | H26: Maint. | I26: 1.86 | J26: 0.51 | K26: 341.42 | L26: 26.78 | M26: 98.4 | N26: 42.8 | O26: 0 | P26: 1.72 | Q26: 9.61
A27: 08/09/2025 19:00 | B27: 42.36 | C27: 23.95 | D27: 44.6 | E27: 4.69 | F27: 4.09 | G27: 73.58 | H27: Maint. | I27: 2.17 | J27: 0.1 | K27: 355.93 | L27: 26.2 | M27: 98.35 | N27: 33.5 | O27: 0 | P27: 1.67 | Q27: 9.64
A28: 08/09/2025 20:00 | B28: 41.86 | C28: 14.78 | D28: 39.83 | E28: 4.69 | F28: 3.48 | G28: 79.42 | H28: Maint. | I28: 2.42 | J28: 0.38 | K28: 334.72 | L28: 25.72 | M28: 98.45 | N28: 32.5 | O28: 0 | P28: 2.06 | Q28: 9.65
A29: 08/09/2025 21:00 | B29: 42.67 | C29: 17.55 | D29: 41.49 | E29: 4.43 | F29: 3.03 | G29: 81.2 | H29: Maint. | I29: 2.55 | J29: 0.55 | K29: 340.91 | L29: 25.52 | M29: 98.53 | N29: 32.5 | O29: 0 | P29: 1.44 | Q29: 9.66
... A32: 08/09/2025 24:00 | B32: 20.13 | C32: 10.91 | D32: 20.61 | E32: 4.5 | F32: 5.36 | G32: 58.69 | H32: Maint. | I32: 2.51 | J32: 0.06 | K32: 318.87 | L32: 23.75 | M32: 98.74 | N32: 32.5 | O32: 0 | P32: 0.75 | Q32: 9.7
A34: Min | B34: =MIN(B9:B32) -> 7.85 | C34: =MIN(C9:C32) -> 7.2 | D34: =MIN(D9:D32) -> 10.11 | E34: =MIN(E9:E32) -> 1.12 | F34: =MIN(F9:F32) -> 3.03 | G34: =MIN(G9:G32) -> 16.55 | H34: =MIN(H9:H32) -> 8.04 | I34: =MIN(I9:I32) -> 1.23 | ... Q34: =MIN(Q9:Q32) -> 9.29
A35: Max | B35: =MAX(B9:B32) -> 82.11 | C35: =MAX(C9:C32) -> 23.95 | D35: =MAX(D9:D32) -> 66.38 | E35: =MAX(E9:E32) -> 4.72 | F35: =MAX(F9:F32) -> 12.08 | G35: =MAX(G9:G32) -> 132.07 | H35: =MAX(H9:H32) -> 22.43 | I35: =MAX(I9:I32) -> 2.82 | ... Q35: =MAX(Q9:Q32) -> 9.7
A36: Avg | B36: =AVERAGE(B9:B32) -> 20.249167 | C36: =AVERAGE(C9:C32) -> 12.455417 | D36: =AVERAGE(D9:D32) -> 21.516667 | E36: =AVERAGE(E9:E32) -> 3.5258333 | F36: =AVERAGE(F9:F32) -> 6.15375 | G36: =AVERAGE(G9:G32) -> 55.413043 | H36: =AVERAGE(H9:H32) -> 12.4725 | I36: =AVERAGE(I9:I32) -> 2.0570833 | ... Q36: =AVERAGE(Q9:Q32) -> 9.4833333
A37: Stdev | B37: =STDEV(B9:B32) -> 17.502399 | C37: =STDEV(C9:C32) -> 4.0782274 | D37: =STDEV(D9:D32) -> 14.249979 | E37: =STDEV(E9:E32) -> 1.2007024 | F37: =STDEV(F9:F32) -> 2.2856562 | G37: =STDEV(G9:G32) -> 31.436901 | H37: =STDEV(H9:H32) -> 4.588379 | I37: =STDEV(I9:I32) -> 0.54232574 | ... Q37: =STDEV(Q9:Q32) -> 0.13457394
A38: Num | B38: =COUNT(B9:B32) -> 24 | C38: =COUNT(C9:C32) -> 24 | D38: =COUNT(D9:D32) -> 24 | E38: =COUNT(E9:E32) -> 24 | F38: =COUNT(F9:F32) -> 24 | G38: =COUNT(G9:G32)+1 -> 24 | H38: 24 | I38: =COUNT(I9:I32) -> 24 | J38: =COUNT(J9:J32) -> 24 | K38: =COUNT(K9:K32) -> 24 | L38: =COUNT(L9:L32) -> 24 | M38: =COUNT(M9:M32) -> 24 | N38: =COUNT(N9:N32) -> 24 | O38: =COUNT(O9:O32) -> 24 | P38: =COUNT(P9:P32) -> 24 | Q38: =COUNT(Q9:Q32) -> 24
A39: DCR | B39: =IF(B38>=22,">90%",IF(B38<=22,"<90%")) -> >90% | C39: =IF(C38>=22,">90%",IF(C38<=22,"<90%")) -> >90% | D39: =IF(D38>=22,">90%",IF(D38<=22,"<90%")) -> >90% | E39: =IF(E38>=22,">90%",IF(E38<=22,"<90%")) -> >90% | F39: =IF(F38>=22,">90%",IF(F38<=22,"<90%")) -> >90% | G39: =IF(G38>=22,">90%",IF(G38<=22,"<90%")) -> >90% | H39: =IF(H38>=22,">90%",IF(H38<=22,"<90%")) -> >90% | I39: =IF(I38>=22,">90%",IF(I38<=22,"<90%")) -> >90% | ... Q39: =IF(Q38>=22,">90%",IF(Q38<=22,"<90%")) -> >90%
A40: Status | B40: =IF(B38>=22,"OK",IF(B38<=22,"LESS")) -> OK | C40: =IF(C38>=22,"OK",IF(C38<=22,"LESS")) -> OK | D40: =IF(D38>=22,"OK",IF(D38<=22,"LESS")) -> OK | E40: =IF(E38>=22,"OK",IF(E38<=22,"LESS")) -> OK | F40: =IF(F38>=22,"OK",IF(F38<=22,"LESS")) -> OK | G40: =IF(G38>=22,"OK",IF(G38<=22,"LESS")) -> OK | H40: =IF(H38>=22,"OK",IF(H38<=22,"LESS")) -> OK | I40: =IF(I38>=22,"OK",IF(I38<=22,"LESS")) -> OK | ... Q40: =IF(Q38>=22,"OK",IF(Q38<=22,"LESS")) -> OK
A43: Done by | B43: RAHUL
A45: Comment

Sheet 09
A1: Station: | B1: BHATAGAON RAIPUR
A2: Date: | B2: =$A$9 -> 09/09/2025 01:00 | D2: Power Off | G2: Pw.Off | L2: Link Fail | N2: Link F | P2: Maintenance | R2: Maint.
A3: Report Type: | B3: Mean | D3: Calibration | G3: Calib. | L3: Data Fail | N3: Data F | P3: Invalid | R3: Invalid
A4: Time Base: | B4: 01 Hour | D4: Zero Referrence | G4: Z.Ref | L4: Warm Up | N4: Wm. Up
A7: Date & Time | B7: NO_BHATAGAON | C7: NO2__BHATAGAON | D7: NOX_BHATAGAON | E7: SO2__BHATAGAON | F7: O3__BHATAGAON | G7: PM10__BHATAGAON | H7: PM2_5__BHATAGAON | I7: BENZ__BHATAGAON | J7: WS__BHATAGAON | K7: WD__BHATAGAON | L7: TEMP__BHATAGAON | M7: HUM__BHATAGAON | N7: SR__BHATAGAON | O7: RG__BHATAGAON | P7: CO__BHATAGAON | Q7: NH3__BHATAGAON
B8: ug/m3 | C8: ug/m3 | D8: ppb | E8: ug/m3 | F8: ug/m3 | G8: mg/m3 | H8: ug/m3 | I8: ug/m3 | J8: m/sec | K8: deg | L8: degreC | M8: % | N8: w/m2 | O8: mm | P8: ug/m3 | Q8: ug/m3
A9: 09/09/2025 01:00 | B9: 16.25 | C9: 11.79 | D9: 18.31 | E9: 5.07 | F9: 4.14 | G9: 49.74 | H9: 1.6 | I9: 2.29 | J9: 0.08 | K9: 234.49 | L9: 23.83 | M9: 98.81 | N9: 32.4 | O9: 0 | P9: 0.68 | Q9: 9.68
A10: 09/09/2025 02:00 | B10: 12.91 | C10: 12.14 | D10: 15.77 | E10: 5.18 | F10: 5.77 | G10: 48.71 | H10: 1.58 | I10: 2.3 | J10: 0.16 | K10: 180.75 | L10: 23.95 | M10: 98.82 | N10: 32.5 | O10: 0 | P10: 0.64 | Q10: 9.68
A11: 09/09/2025 03:00 | B11: 16.58 | C11: 5.36 | D11: 15.54 | E11: 5.1 | F11: 8.48 | G11: 45.2 | H11: 1.2 | I11: 2.32 | J11: 0.11 | K11: 218.79 | L11: 23.81 | M11: 98.73 | N11: 32.5 | O11: 0 | P11: 0.5 | Q11: 9.67
A12: 09/09/2025 04:00 | B12: 12.43 | C12: 6.82 | D12: 13.14 | E12: 5.2 | F12: 6.22 | G12: 35.98 | H12: 1.1 | I12: 2.14 | J12: 0.07 | K12: 275.03 | L12: 23.46 | M12: 98.65 | N12: 32.5 | O12: 0 | P12: 0.42 | Q12: 9.66
A13: 09/09/2025 05:00 | B13: 12.97 | C13: 7.73 | D13: 13.1 | E13: 4.79 | F13: 5.11 | G13: 24.07 | H13: 1.93 | I13: 1.92 | J13: 0.22 | K13: 182.94 | L13: 23.29 | M13: 98.64 | N13: 32.3 | O13: 0 | P13: 0.46 | Q13: 9.64
A14: 09/09/2025 06:00 | B14: 13.22 | C14: 7.79 | D14: 14.4 | E14: 4.91 | F14: 4.04 | G14: 24.19 | H14: 2.27 | I14: 1.75 | J14: 0.13 | K14: 262.73 | L14: 23.17 | M14: 98.63 | N14: 41.3 | O14: 0 | P14: 0.35 | Q14: 9.62
A15: 09/09/2025 07:00 | B15: 19.11 | C15: 6.56 | D15: 18.54 | E15: 5.06 | F15: 4.2 | G15: 22.49 | H15: 0.59 | I15: 1.73 | J15: 0.19 | K15: 275.2 | L15: 24.34 | M15: 98.5 | N15: 125.2 | O15: 0 | P15: 0.5 | Q15: 9.61
A16: 09/09/2025 08:00 | B16: 24.11 | C16: 8.34 | D16: 23.47 | E16: 5.47 | F16: 5.32 | G16: 27.93 | H16: 0.17 | I16: 1.7 | J16: 0.26 | K16: 354.09 | L16: 26.08 | M16: 98.45 | N16: 212.3 | O16: 0 | P16: 0.69 | Q16: 9.59
A17: 09/09/2025 09:00 | B17: 18.88 | C17: 9.73 | D17: 20.07 | E17: 5.05 | F17: 8.67 | G17: 34.14 | H17: 0.26 | I17: 1.61 | J17: 0.37 | K17: 354.59 | L17: 32.04 | M17: 97.9 | N17: 562 | O17: 0 | P17: 0.51 | Q17: 9.62
A18: 09/09/2025 10:00 | B18: 17.24 | C18: 15.41 | D18: 20.93 | E18: 5.36 | F18: 12.53 | G18: 37.11 | H18: 0.6 | I18: 1.64 | J18: 0.43 | K18: 135.09 | L18: 32.79 | M18: 89.64 | N18: 609.9 | O18: 0 | P18: 0.58 | Q18: 9.65
A19: 09/09/2025 11:00 | B19: 15.85 | C19: 18.08 | D19: 22.13 | E19: 5.48 | F19: 18.62 | G19: 37.29 | H19: 0.8 | I19: 1.68 | J19: 0.48 | K19: 338.47 | L19: 30.29 | M19: 87.18 | N19: 622.6 | O19: 0 | P19: 0.73 | Q19: 9.63
A20: 09/09/2025 12:00 | B20: 9.25 | C20: 25.78 | D20: 20.89 | E20: 5.22 | F20: 15.75 | G20: 35.7 | H20: 0.59 | I20: 1.65 | J20: 0.52 | K20: 324.89 | L20: 30.23 | M20: 91 | N20: 376.8 | O20: 0 | P20: 0.7 | Q20: 9.23
... A32: 09/09/2025 24:00 | B32: 13.88 | C32: 21.84 | D32: 20.08 | E32: 4.42 | F32: 8.25 | G32: 99.69 | H32: 6.28 | I32: 2.76 | J32: 0.87 | K32: 338.22 | L32: 25.22 | M32: 97.85 | N32: 32.6 | O32: 0 | P32: 1.23 | Q32: 9.63
A34: Min | B34: =MIN(B9:B32) -> 4.77 | C34: =MIN(C9:C32) -> 5.36 | D34: =MIN(D9:D32) -> 10.64 | E34: =MIN(E9:E32) -> 4.06 | F34: =MIN(F9:F32) -> 4.04 | G34: =MIN(G9:G32) -> 22.49 | H34: =MIN(H9:H32) -> 0.17 | I34: =MIN(I9:I32) -> 1.49 | ... Q34: =MIN(Q9:Q32) -> 9.23
A35: Max | B35: =MAX(B9:B32) -> 45.95 | C35: =MAX(C9:C32) -> 41.88 | D35: =MAX(D9:D32) -> 54.6 | E35: =MAX(E9:E32) -> 5.92 | F35: =MAX(F9:F32) -> 29.55 | G35: =MAX(G9:G32) -> 130.09 | H35: =MAX(H9:H32) -> 11.41 | I35: =MAX(I9:I32) -> 2.76 | ... Q35: =MAX(Q9:Q32) -> 9.68
A36: Avg | B36: =AVERAGE(B9:B32) -> 17.539167 | C36: =AVERAGE(C9:C32) -> 19.2575 | D36: =AVERAGE(D9:D32) -> 23.38625 | E36: =AVERAGE(E9:E32) -> 5.0291667 | F36: =AVERAGE(F9:F32) -> 12.658333 | G36: =AVERAGE(G9:G32) -> 68.443333 | H36: =AVERAGE(H9:H32) -> 3.8775 | I36: =AVERAGE(I9:I32) -> 1.9745833 | ... Q36: =AVERAGE(Q9:Q32) -> 9.5166667
A37: Stdev | B37: =STDEV(B9:B32) -> 10.443264 | C37: =STDEV(C9:C32) -> 11.389004 | D37: =STDEV(D9:D32) -> 12.286765 | E37: =STDEV(E9:E32) -> 0.42622628 | F37: =STDEV(F9:F32) -> 8.7307058 | G37: =STDEV(G9:G32) -> 37.401714 | H37: =STDEV(H9:H32) -> 3.4946459 | I37: =STDEV(I9:I32) -> 0.36728119 | ... Q37: =STDEV(Q9:Q32) -> 0.16985074
