Workbook

Sheet 01
A1: Station: | B1: BHATAGAON RAIPUR
A2: Date: | B2: =$A$9 -> 01/11/2024 00:15 | D2: Power Off | G2: Pw.Off | L2: Link Fail | N2: Link F | P2: Maintenance | R2: Maint.
A3: Report Type: | B3: Mean | D3: Calibration | G3: Calib. | L3: Data Fail | N3: Data F | P3: Invalid | R3: Invalid
A4: Time Base: | B4: 15 Min | D4: Zero Referrence | G4: Z.Ref | L4: Warm Up | N4: Wm. Up
A7: Date & Time | B7: NO_BHATAGAON | C7: NO2__BHATAGAON | D7: NOX_BHATAGAON | E7: SO2__BHATAGAON | F7: O3__BHATAGAON | G7: PM10__BHATAGAON | H7: PM2_5__BHATAGAON | I7: BENZ__BHATAGAON | J7: WS__BHATAGAON | K7: WD__BHATAGAON | L7: TEMP__BHATAGAON | M7: HUM__BHATAGAON | N7: SR__BHATAGAON | O7: RG__BHATAGAON | P7: CO__BHATAGAON | Q7: NH3__BHATAGAON
B8: ug/m3 | C8: ug/m3 | D8: ppb | E8: ug/m3 | F8: ug/m3 | G8: ug/m3 | H8: ug/m3 | I8: ug/m3 | J8: m/sec | K8: deg | L8: degreC | M8: % | N8: w/m2 | O8: mm | P8: mg/m3 | Q8: ug/m3
A9: 01/11/2024 00:15 | B9: 34.03 | C9: 13.77 | D9: 33.11 | E9: 14.5 | F9: 7.31 | G9: Data F | H9: Data F | I9: 5.94 | J9: 0.61 | K9: 328.52 | L9: 23.62 | M9: 102.48 | N9: 26.1 | O9: 0 | P9: 1.43 | Q9: 9.61
A10: 01/11/2024 00:30 | B10: 35.12 | C10: 13.58 | D10: 33.88 | E10: 14.11 | F10: 7.82 | G10: Data F | H10: Data F | I10: 6.44 | J10: 0.57 | K10: 308.34 | L10: 23.2 | M10: 102.74 | N10: 26.1 | O10: 0 | P10: 1.33 | Q10: 9.62
A11: 01/11/2024 00:45 | B11: 34.81 | C11: 13.04 | D11: 33.35 | E11: 12.82 | F11: 7.58 | G11: Data F | H11: Data F | I11: 6.15 | J11: 0.54 | K11: 311.6 | L11: 22.88 | M11: 102.76 | N11: 26.1 | O11: 0 | P11: 1.17 | Q11: 9.62
A12: 01/11/2024 01:00 | B12: 34.49 | C12: 13.22 | D12: 33.19 | E12: 12.38 | F12: 6.25 | G12: Data F | H12: Data F | I12: 5.25 | J12: 0.66 | K12: 339.42 | L12: 22.74 | M12: 102.78 | N12: 26 | O12: 0 | P12: 1.24 | Q12: 9.62
A13: 01/11/2024 01:15 | B13: 35.01 | C13: 12.81 | D13: 33.39 | E13: 12.31 | F13: 6.78 | G13: Data F | H13: Data F | I13: 5.84 | J13: 0.45 | K13: 327.54 | L13: 22.54 | M13: 102.78 | N13: 26 | O13: 0 | P13: 1.17 | Q13: 9.63
A14: 01/11/2024 01:30 | B14: 35.79 | C14: 12.14 | D14: 33.66 | E14: 12.27 | F14: 6.8 | G14: Data F | H14: Data F | I14: 5.63 | J14: 0.19 | K14: 285.68 | L14: 22.46 | M14: 102.78 | N14: 25.9 | O14: 0 | P14: 1.07 | Q14: 9.63
A15: 01/11/2024 01:45 | B15: 35.54 | C15: 12.35 | D15: 33.58 | E15: 11.52 | F15: 6.6 | G15: Data F | H15: Data F | I15: 5.3 | J15: 0.56 | K15: 324.41 | L15: 22.4 | M15: 102.78 | N15: 25.8 | O15: 0 | P15: 1.02 | Q15: 9.64
A16: 01/11/2024 02:00 | B16: 35.62 | C16: 11.15 | D16: 33.01 | E16: 10.67 | F16: 6.25 | G16: Data F | H16: Data F | I16: 5.94 | J16: 0.57 | K16: 301.94 | L16: 22.36 | M16: 102.78 | N16: 25.7 | O16: 0 | P16: 0.87 | Q16: 9.62
A17: 01/11/2024 02:15 | B17: 34.74 | C17: 10.28 | D17: 31.86 | E17: 9.93 | F17: 5.96 | G17: Data F | H17: Data F | I17: 5.24 | J17: 0.4 | K17: 336.83 | L17: 22.15 | M17: 102.78 | N17: 25.9 | O17: 0 | P17: 0.84 | Q17: 9.63
A18: 01/11/2024 02:30 | B18: 33.66 | C18: 9.94 | D18: 30.81 | E18: 9.45 | F18: 6.28 | G18: 324.59 | H18: 194.67 | I18: 4.18 | J18: 0.54 | K18: 344.37 | L18: 21.96 | M18: 102.78 | N18: 25.9 | O18: 0 | P18: 0.85 | Q18: 9.62
A19: 01/11/2024 02:45 | B19: 32.64 | C19: 9.73 | D19: 29.88 | E19: 9.14 | F19: 6.21 | G19: 254.84 | H19: 160.06 | I19: 3.88 | J19: 0.85 | K19: 347.76 | L19: 21.92 | M19: 102.78 | N19: 25.7 | O19: 0 | P19: 0.87 | Q19: 9.62
A20: 01/11/2024 03:00 | B20: 31.55 | C20: 9.73 | D20: 29 | E20: 8.52 | F20: 5.5 | G20: 254.84 | H20: 160.06 | I20: 4.3 | J20: 1.07 | K20: 340.05 | L20: 21.81 | M20: 102.77 | N20: 25.3 | O20: 0 | P20: 0.87 | Q20: 9.62
A21: 01/11/2024 03:15 | B21: 30.35 | C21: 9.52 | D21: 27.94 | E21: 8 | F21: 5.24 | G21: 254.84 | H21: 160.06 | I21: 4.55 | J21: 0.6 | K21: 334.42 | L21: 21.86 | M21: 102.75 | N21: 25.6 | O21: 0 | P21: 0.73 | Q21: 9.62
A22: 01/11/2024 03:30 | B22: 29.29 | C22: 9.16 | D22: 26.9 | E22: 8.05 | F22: 5.12 | G22: 212.54 | H22: 128.22 | I22: 4.35 | J22: 0.49 | K22: 339.66 | L22: 21.62 | M22: 102.22 | N22: 25.8 | O22: 0 | P22: 0.78 | Q22: 9.62
A23: 01/11/2024 03:45 | B23: 28.25 | C23: 9.37 | D23: 26.18 | E23: 7.49 | F23: 4.81 | G23: 176.44 | H23: 121.15 | I23: 3.68 | J23: 0.29 | K23: 318.54 | L23: 21.34 | M23: 98.3 | N23: 26 | O23: 0 | P23: 1.01 | Q23: 9.63
A24: 01/11/2024 04:00 | B24: 26.85 | C24: 9.91 | D24: 25.33 | E24: 6.59 | F24: 5.18 | G24: 176.44 | H24: 121.15 | I24: 4.2 | J24: 0.38 | K24: 343.75 | L24: 21.25 | M24: 96.51 | N24: 26 | O24: 0 | P24: 1.03 | Q24: 9.62
A25: 01/11/2024 04:15 | B25: 25.15 | C25: 9.66 | D25: 23.84 | E25: 6.93 | F25: 4.78 | G25: 176.44 | H25: 121.15 | I25: 5.86 | J25: 0.33 | K25: 9.2 | L25: 21.22 | M25: 90.69 | N25: 26 | O25: 0 | P25: 1 | Q25: 9.62
A26: 01/11/2024 04:30 | B26: 23.78 | C26: 9.54 | D26: 22.68 | E26: 6.77 | F26: 4.59 | G26: 138.28 | H26: 59.86 | I26: 6.16 | J26: 0.43 | K26: 333.19 | L26: 21 | M26: 90.69 | N26: 26.1 | O26: 0 | P26: 0.96 | Q26: 9.6
A27: 01/11/2024 04:45 | B27: 22.69 | C27: 9.61 | D27: 21.84 | E27: 6.52 | F27: 4.44 | G27: 115.11 | H27: 46.48 | I27: 5.88 | J27: 0.35 | K27: 346.75 | L27: 20.87 | M27: 92.94 | N27: 25.9 | O27: 0 | P27: 0.98 | Q27: 9.61
A28: 01/11/2024 05:00 | B28: 21.73 | C28: 9.73 | D28: 21.14 | E28: 6.06 | F28: 4.22 | G28: 115.11 | H28: 46.48 | I28: 5.79 | J28: 0.38 | K28: 309.27 | L28: 20.68 | M28: 90.43 | N28: 26.1 | O28: 0 | P28: 0.97 | Q28: 9.61
A29: 01/11/2024 05:15 | B29: 20.75 | C29: 9.97 | D29: 20.47 | E29: 6.28 | F29: 4.38 | G29: 115.11 | H29: 46.48 | I29: 5.82 | J29: 0.94 | K29: 336.41 | L29: 20.64 | M29: 88 | N29: 25.2 | O29: 0 | P29: 0.96 | Q29: 9.62
... A104: 01/11/2024 24:00 | B104: 55.11 | C104: 11.9 | D104: 49.04 | E104: 6.86 | F104: 5.53 | G104: 279.72 | H104: 237.21 | I104: 5.84 | J104: 0.59 | K104: 317.75 | L104: 22.02 | M104: 91.24 | N104: 26.1 | O104: 0 | P104: 1.42 | Q104: 9.62
A106: Min | B106: =MIN(B9:B104) -> 0.03 | C106: =MIN(C9:C104) -> 8.59 | D106: =MIN(D9:D104) -> 3.63 | E106: =MIN(E9:E104) -> 4.55 | F106: =MIN(F9:F104) -> 3.42 | G106: =MIN(G9:G104) -> 14.8 | H106: =MIN(H9:H104) -> 2.09 | I106: =MIN(I9:I104) -> 1.61 | ... Q106: =MIN(Q9:Q104) -> 9.6
A107: Max | B107: =MAX(B9:B104) -> 56.64 | C107: =MAX(C9:C104) -> 17.15 | D107: =MAX(D9:D104) -> 51.52 | E107: =MAX(E9:E104) -> 14.5 | F107: =MAX(F9:F104) -> 8.9 | G107: =MAX(G9:G104) -> 483.55 | H107: =MAX(H9:H104) -> 451.5 | I107: =MAX(I9:I104) -> 8.5 | ... Q107: =MAX(Q9:Q104) -> 9.64
A108: Avg | B108: =AVERAGE(B9:B104) -> 16.357813 | C108: =AVERAGE(C9:C104) -> 11.590521 | D108: =AVERAGE(D9:D104) -> 17.796771 | E108: =AVERAGE(E9:E104) -> 6.8891667 | F108: =AVERAGE(F9:F104) -> 5.615625 | G108: =AVERAGE(G9:G104) -> 142.17494 | H108: =AVERAGE(H9:H104) -> 93.096092 | I108: =AVERAGE(I9:I104) -> 5.1329167 | ... Q108: =AVERAGE(Q9:Q104) -> 9.6189583
A109: Stdev | B109: =STDEV(B9:B104) -> 16.99752 | C109: =STDEV(C9:C104) -> 2.3954362 | D109: =STDEV(D9:D104) -> 14.117623 | E109: =STDEV(E9:E104) -> 2.4964934 | F109: =STDEV(F9:F104) -> 1.2997383 | G109: =STDEV(G9:G104) -> 122.94766 | H109: =STDEV(H9:H104) -> 113.19195 | I109: =STDEV(I9:I104) -> 1.7258962 | ... Q109: =STDEV(Q9:Q104) -> 0.0086425102
A110: Num | B110: =COUNT(B9:B104) -> 96 | C110: =COUNT(C9:C104) -> 96 | D110: =COUNT(D9:D104) -> 96 | E110: =COUNT(E9:E104) -> 96 | F110: =COUNT(F9:F104) -> 96 | G110: =COUNT(G9:G104)+9 -> 96 | H110: =COUNT(H9:H104)+9 -> 96 | I110: =COUNT(I9:I104) -> 96 | J110: =COUNT(J9:J104) -> 96 | K110: =COUNT(K9:K104) -> 96 | L110: =COUNT(L9:L104) -> 96 | M110: =COUNT(M9:M104) -> 96 | N110: =COUNT(N9:N104) -> 96 | O110: =COUNT(O9:O104) -> 96 | P110: =COUNT(P9:P104) -> 96 | Q110: =COUNT(Q9:Q104) -> 96
A111: DCR | B111: =IF(B110>=87,">90%",IF(B110<=87,"<90%")) -> >90% | C111: =IF(C110>=87,">90%",IF(C110<=87,"<90%")) -> >90% | D111: =IF(D110>=87,">90%",IF(D110<=87,"<90%")) -> >90% | E111: =IF(E110>=87,">90%",IF(E110<=87,"<90%")) -> >90% | F111: =IF(F110>=87,">90%",IF(F110<=87,"<90%")) -> >90% | G111: =IF(G110>=87,">90%",IF(G110<=87,"<90%")) -> >90% | H111: =IF(H110>=87,">90%",IF(H110<=87,"<90%")) -> >90% | I111: =IF(I110>=87,">90%",IF(I110<=87,"<90%")) -> >90% | ... Q111: =IF(Q110>=87,">90%",IF(Q110<=87,"<90%")) -> >90%
A112: Status | B112: =IF(B110>=87,"OK",IF(B110<=87,"LESS")) -> OK | C112: =IF(C110>=87,"OK",IF(C110<=87,"LESS")) -> OK | D112: =IF(D110>=87,"OK",IF(D110<=87,"LESS")) -> OK | E112: =IF(E110>=87,"OK",IF(E110<=87,"LESS")) -> OK | F112: =IF(F110>=87,"OK",IF(F110<=87,"LESS")) -> OK | G112: =IF(G110>=87,"OK",IF(G110<=87,"LESS")) -> OK | H112: =IF(H110>=87,"OK",IF(H110<=87,"LESS")) -> OK | I112: =IF(I110>=87,"OK",IF(I110<=87,"LESS")) -> OK | ... Q112: =IF(Q110>=87,"OK",IF(Q110<=87,"LESS")) -> OK
A115: Done by | B115: RK
A117: Comment

Sheet 02
A1: Station: | B1: BHATAGAON RAIPUR
A2: Date: | B2: =$A$9 -> 02/11/2024 00:15 | D2: Power Off | G2: Pw.Off | L2: Link Fail | N2: Link F | P2: Maintenance | R2: Maint.
A3: Report Type: | B3: Mean | D3: Calibration | G3: Calib. | L3: Data Fail | N3: Data F | P3: Invalid | R3: Invalid
A4: Time Base: | B4: 15 Min | D4: Zero Referrence | G4: Z.Ref | L4: Warm Up | N4: Wm. Up
A7: Date & Time | B7: NO_BHATAGAON | C7: NO2__BHATAGAON | D7: NOX_BHATAGAON | E7: SO2__BHATAGAON | F7: O3__BHATAGAON | G7: PM10__BHATAGAON | H7: PM2_5__BHATAGAON | I7: BENZ__BHATAGAON | J7: WS__BHATAGAON | K7: WD__BHATAGAON | L7: TEMP__BHATAGAON | M7: HUM__BHATAGAON | N7: SR__BHATAGAON | O7: RG__BHATAGAON | P7: CO__BHATAGAON | Q7: NH3__BHATAGAON
B8: ug/m3 | C8: ug/m3 | D8: ppb | E8: ug/m3 | F8: ug/m3 | G8: ug/m3 | H8: ug/m3 | I8: ug/m3 | J8: m/sec | K8: deg | L8: degreC | M8: % | N8: w/m2 | O8: mm | P8: mg/m3 | Q8: ug/m3
A9: 02/11/2024 00:15 | B9: 54.81 | C9: 11.49 | D9: 48.58 | E9: 7.79 | F9: 5.45 | G9: 279.72 | H9: 237.21 | I9: 5.92 | J9: 0.5 | K9: 333.27 | L9: 21.81 | M9: 89.29 | N9: 26.1 | O9: 0 | P9: 1.27 | Q9: 9.64
A10: 02/11/2024 00:30 | B10: 53.55 | C10: 10.96 | D10: 47.29 | E10: 7.43 | F10: 5.35 | G10: 243.79 | H10: 107.15 | I10: 5.87 | J10: 0.24 | K10: 345.6 | L10: 22 | M10: 80.83 | N10: 25.8 | O10: 0 | P10: 1.11 | Q10: 9.63
A11: 02/11/2024 00:45 | B11: 51.25 | C11: 11.36 | D11: 45.65 | E11: 7.04 | F11: 4.6 | G11: 221.98 | H11: 78.77 | I11: 5.31 | J11: 0.32 | K11: 12.08 | L11: 21.97 | M11: 83.24 | N11: 26 | O11: 0 | P11: 1.3 | Q11: 9.63
A12: 02/11/2024 01:00 | B12: 48.42 | C12: 11.21 | D12: 43.31 | E12: 6.59 | F12: 4.95 | G12: 221.98 | H12: 78.77 | I12: 6.35 | J12: 0.25 | K12: 192.6 | L12: 21.75 | M12: 83.66 | N12: 25.7 | O12: 0 | P12: 1.24 | Q12: 9.61
A13: 02/11/2024 01:15 | B13: 45.34 | C13: 11.3 | D13: 40.89 | E13: 6.21 | F13: 4.53 | G13: 221.98 | H13: 78.77 | I13: 6.72 | J13: 0.26 | K13: 359.6 | L13: 21.68 | M13: 85.11 | N13: 26 | O13: 0 | P13: 1.13 | Q13: 9.62
A14: 02/11/2024 01:30 | B14: 42.49 | C14: 11.36 | D14: 38.64 | E14: 5.71 | F14: 4.61 | G14: 136.89 | H14: 91.18 | I14: 6.38 | J14: 0.29 | K14: 255.53 | L14: 21.58 | M14: 83.84 | N14: 25.7 | O14: 0 | P14: 1.1 | Q14: 9.63
A15: 02/11/2024 01:45 | B15: 39.92 | C15: 11.51 | D15: 36.65 | E15: 5.96 | F15: 4.92 | G15: 85.23 | H15: 93.89 | I15: 6.88 | J15: 0.42 | K15: 273.43 | L15: 21.36 | M15: 84.97 | N15: 26 | O15: 0 | P15: 1.1 | Q15: 9.63
A16: 02/11/2024 02:00 | B16: 37.44 | C16: 11.87 | D16: 34.85 | E16: 5.49 | F16: 4.44 | G16: 85.23 | H16: 93.89 | I16: 6.79 | J16: 0.36 | K16: 279.34 | L16: 21.28 | M16: 86.46 | N16: 26.1 | O16: 0 | P16: 1.08 | Q16: 9.63
A17: 02/11/2024 02:15 | B17: 35.16 | C17: 12.12 | D17: 33.15 | E17: 5.42 | F17: 4.29 | G17: 85.23 | H17: 93.89 | I17: 6.71 | J17: 0.15 | K17: 211.37 | L17: 21.25 | M17: 86.14 | N17: 25.7 | O17: 0 | P17: 1.05 | Q17: 9.61
A18: 02/11/2024 02:30 | B18: 32.97 | C18: 12.1 | D18: 31.39 | E18: 5.04 | F18: 4.47 | G18: 85.14 | H18: 47.71 | I18: 6.7 | J18: 0.13 | K18: 194.6 | L18: 21.29 | M18: 87 | N18: 25.6 | O18: 0 | P18: 1.01 | Q18: 9.62
A19: 02/11/2024 02:45 | B19: 30.9 | C19: 12.16 | D19: 29.76 | E19: 5.32 | F19: 4.27 | G19: 85.08 | H19: 37.63 | I19: 6.58 | J19: 0.27 | K19: 293.34 | L19: 21.42 | M19: 86.12 | N19: 26 | O19: 0 | P19: 0.89 | Q19: 9.63
A20: 02/11/2024 03:00 | B20: 29.59 | C20: 11.31 | D20: 28.26 | E20: 4.8 | F20: 3.7 | G20: 85.08 | H20: 37.63 | I20: 6.41 | J20: 0.26 | K20: 218.13 | L20: 21.14 | M20: 86.82 | N20: 26 | O20: 0 | P20: 0.73 | Q20: 9.64
... A104: 02/11/2024 24:00 | B104: 19.02 | C104: 16.33 | D104: 22.41 | E104: 5.05 | F104: 4.82 | G104: 91.75 | H104: 49.45 | I104: 4.77 | J104: 0.64 | K104: 163.26 | L104: 24.17 | M104: 60.44 | N104: 25.7 | O104: 0 | P104: 0.55 | Q104: 9.61
A106: Min | B106: =MIN(B9:B104) -> -0.12 | C106: =MIN(C9:C104) -> 9.45 | D106: =MIN(D9:D104) -> 3.86 | E106: =MIN(E9:E104) -> 4.04 | F106: =MIN(F9:F104) -> 3.4 | G106: =MIN(G9:G104) -> 44.31 | H106: =MIN(H9:H104) -> 21.08 | I106: =MIN(I9:I104) -> 1.09 | ... Q106: =MIN(Q9:Q104) -> 9.6
A107: Max | B107: =MAX(B9:B104) -> 54.81 | C107: =MAX(C9:C104) -> 21.59 | D107: =MAX(D9:D104) -> 48.58 | E107: =MAX(E9:E104) -> 7.79 | F107: =MAX(F9:F104) -> 9.03 | G107: =MAX(G9:G104) -> 279.72 | H107: =MAX(H9:H104) -> 237.21 | I107: =MAX(I9:I104) -> 6.88 | ... Q107: =MAX(Q9:Q104) -> 9.64
A108: Avg | B108: =AVERAGE(B9:B104) -> 19.360417 | C108: =AVERAGE(C9:C104) -> 13.743333 | D108: =AVERAGE(D9:D104) -> 21.329375 | E108: =AVERAGE(E9:E104) -> 5.6892708 | F108: =AVERAGE(F9:F104) -> 5.0896875 | G108: =AVERAGE(G9:G104) -> 106.36812 | H108: =AVERAGE(H9:H104) -> 52.447604 | I108: =AVERAGE(I9:I104) -> 4.9038542 | ... Q108: =AVERAGE(Q9:Q104) -> 9.6209375
A109: Stdev | B109: =STDEV(B9:B104) -> 15.433373 | C109: =STDEV(C9:C104) -> 3.882235 | D109: =STDEV(D9:D104) -> 12.544333 | E109: =STDEV(E9:E104) -> 1.0293506 | F109: =STDEV(F9:F104) -> 1.3073834 | G109: =STDEV(G9:G104) -> 44.356396 | H109: =STDEV(H9:H104) -> 28.049835 | I109: =STDEV(I9:I104) -> 1.3583166 | ... Q109: =STDEV(Q9:Q104) -> 0.0088351124
A110: Num | B110: =COUNT(B9:B104) -> 96 | C110: =COUNT(C9:C104) -> 96 | D110: =COUNT(D9:D104) -> 96 | E110: =COUNT(E9:E104) -> 96 | F110: =COUNT(F9:F104) -> 96 | G110: =COUNT(G9:G104) -> 96 | H110: =COUNT(H9:H104) -> 96 | I110: =COUNT(I9:I104) -> 96 | ... Q110: =COUNT(Q9:Q104) -> 96
A111: DCR | B111: =IF(B110>=87,">90%",IF(B110<=87,"<90%")) -> >90% | C111: =IF(C110>=87,">90%",IF(C110<=87,"<90%")) -> >90% | D111: =IF(D110>=87,">90%",IF(D110<=87,"<90%")) -> >90% | E111: =IF(E110>=87,">90%",IF(E110<=87,"<90%")) -> >90% | F111: =IF(F110>=87,">90%",IF(F110<=87,"<90%")) -> >90% | G111: =IF(G110>=87,">90%",IF(G110<=87,"<90%")) -> >90% | H111: =IF(H110>=87,">90%",IF(H110<=87,"<90%")) -> >90% | I111: =IF(I110>=87,">90%",IF(I110<=87,"<90%")) -> >90% | ... Q111: =IF(Q110>=87,">90%",IF(Q110<=87,"<90%")) -> >90%
A112: Status | B112: =IF(B110>=87,"OK",IF(B110<=87,"LESS")) -> OK | C112: =IF(C110>=87,"OK",IF(C110<=87,"LESS")) -> OK | D112: =IF(D110>=87,"OK",IF(D110<=87,"LESS")) -> OK | E112: =IF(E110>=87,"OK",IF(E110<=87,"LESS")) -> OK | F112: =IF(F110>=87,"OK",IF(F110<=87,"LESS")) -> OK | G112: =IF(G110>=87,"OK",IF(G110<=87,"LESS")) -> OK | H112: =IF(H110>=87,"OK",IF(H110<=87,"LESS")) -> OK | I112: =IF(I110>=87,"OK",IF(I110<=87,"LESS")) -> OK | ... Q112: =IF(Q110>=87,"OK",IF(Q110<=87,"LESS")) -> OK
A115: Done by | B115: RK
A117: Comment

Sheet 03
A1: Station: | B1: BHATAGAON RAIPUR
A2: Date: | B2: =$A$9 -> 03/11/2024 00:15 | D2: Power Off | G2: Pw.Off | L2: Link Fail | N2: Link F | P2: Maintenance | R2: Maint.
A3: Report Type: | B3: Mean | D3: Calibration | G3: Calib. | L3: Data Fail | N3: Data F | P3: Invalid | R3: Invalid
A4: Time Base: | B4: 15 Min | D4: Zero Referrence | G4: Z.Ref | L4: Warm Up | N4: Wm. Up
A7: Date & Time | B7: NO_BHATAGAON | C7: NO2__BHATAGAON | D7: NOX_BHATAGAON | E7: SO2__BHATAGAON | F7: O3__BHATAGAON | G7: PM10__BHATAGAON | H7: PM2_5__BHATAGAON | I7: BENZ__BHATAGAON | J7: WS__BHATAGAON | K7: WD__BHATAGAON | L7: TEMP__BHATAGAON | M7: HUM__BHATAGAON | N7: SR__BHATAGAON | O7: RG__BHATAGAON | P7: CO__BHATAGAON | Q7: NH3__BHATAGAON
B8: ug/m3 | C8: ug/m3 | D8: ppb | E8: ug/m3 | F8: ug/m3 | G8: ug/m3 | H8: ug/m3 | I8: ug/m3 | J8: m/sec | K8: deg | L8: degreC | M8: % | N8: w/m2 | O8: mm | P8: mg/m3 | Q8: ug/m3
A9: 03/11/2024 00:15 | B9: 17.52 | C9: 15.67 | D9: 20.85 | E9: 5.09 | F9: 4.91 | G9: 91.75 | H9: 49.45 | I9: 3.34 | J9: 0.65 | K9: 151.42 | L9: 23.99 | M9: 62.52 | N9: 25.9 | O9: 0 | P9: 0.59 | Q9: 9.63
A10: 03/11/2024 00:30 | B10: 16.14 | C10: 15.27 | D10: 19.54 | E10: 5.07 | F10: 5.14 | G10: 73.8 | H10: 39.68 | I10: 2.43 | J10: 0.41 | K10: 122.17 | L10: 23.87 | M10: 63.49 | N10: 26 | O10: 0 | P10: 0.49 | Q10: 9.62
A11: 03/11/2024 00:45 | B11: 14.88 | C11: 14.63 | D11: 18.2 | E11: 4.51 | F11: 4.83 | G11: 62.91 | H11: 37.55 | I11: 2.9 | J11: 0.47 | K11: 350.85 | L11: 23.64 | M11: 66.29 | N11: 26.2 | O11: 0 | P11: 0.56 | Q11: 9.63
A12: 03/11/2024 01:00 | B12: 13.78 | C12: 14.11 | D12: 17.05 | E12: 4.5 | F12: 4.15 | G12: 62.91 | H12: 37.55 | I12: 2.52 | J12: 0.26 | K12: 340.83 | L12: 23.17 | M12: 71.65 | N12: 26.4 | O12: 0 | P12: 0.6 | Q12: 9.63
A13: 03/11/2024 01:15 | B13: 12.76 | C13: 13.52 | D13: 15.91 | E13: 4.63 | F13: 6.36 | G13: 62.91 | H13: 37.55 | I13: 3.31 | J13: 0.36 | K13: 347.52 | L13: 22.9 | M13: 72.3 | N13: 26.2 | O13: 0 | P13: 0.6 | Q13: 9.63
A14: 03/11/2024 01:30 | B14: 11.82 | C14: 13.13 | D14: 14.96 | E14: 5.11 | F14: 5.08 | G14: 62.65 | H14: 34.04 | I14: 3.64 | J14: 0.38 | K14: 325.35 | L14: 22.54 | M14: 72.98 | N14: 26.1 | O14: 0 | P14: 0.52 | Q14: 9.62
A15: 03/11/2024 01:45 | B15: 10.87 | C15: 13.47 | D15: 14.37 | E15: 4.83 | F15: 4.22 | G15: 62.5 | H15: 33.27 | I15: 3.05 | J15: 0.33 | K15: 312.01 | L15: 22.34 | M15: 74.44 | N15: 26.1 | O15: 0 | P15: 0.67 | Q15: 9.62
A16: 03/11/2024 02:00 | B16: 9.67 | C16: 13.54 | D16: 13.45 | E16: 4.96 | F16: 4.31 | G16: 62.5 | H16: 33.27 | I16: 4.02 | J16: 0.37 | K16: 325.47 | L16: 22.3 | M16: 75.82 | N16: 26.1 | O16: 0 | P16: 0.65 | Q16: 9.62
A17: 03/11/2024 02:15 | B17: 8.58 | C17: 13.47 | D17: 12.54 | E17: 4.95 | F17: 4.04 | G17: 62.5 | H17: 33.27 | I17: 4.97 | J17: 0.6 | K17: 338.27 | L17: 22.18 | M17: 77.12 | N17: 25.7 | O17: 0 | P17: 0.64 | Q17: 9.62
A18: 03/11/2024 02:30 | B18: 7.52 | C18: 13.75 | D18: 11.83 | E18: 4.77 | F18: 4.34 | G18: 58.6 | H18: 26.85 | I18: 4.89 | J18: 0.26 | K18: 204.43 | L18: 22.36 | M18: 76.61 | N18: 26.1 | O18: 0 | P18: 0.56 | Q18: 9.62
A19: 03/11/2024 02:45 | B19: 6.72 | C19: 13.77 | D19: 11.21 | E19: 4.86 | F19: 4.36 | G19: 56.12 | H19: 25.45 | I19: 4.79 | J19: 0.24 | K19: 94.2 | L19: 22.56 | M19: 76.52 | N19: 26.1 | O19: 0 | P19: 0.6 | Q19: 9.62
A20: 03/11/2024 03:00 | B20: 6.02 | C20: 13.25 | D20: 10.38 | E20: 4.95 | F20: 4.35 | G20: 56.12 | H20: 25.45 | I20: 4.32 | J20: 0.27 | K20: 281.86 | L20: 22.57 | M20: 77.41 | N20: 26.1 | O20: 0 | P20: 0.57 | Q20: 9.61
... A104: 03/11/2024 24:00 | B104: 60.83 | C104: 18.45 | D104: 57.04 | E104: 6.15 | F104: 4.42 | G104: 148.36 | H104: 77.13 | I104: 7.27 | J104: 0.45 | K104: 168.94 | L104: 21.92 | M104: 86.67 | N104: 26.1 | O104: 0 | P104: 1.43 | Q104: 9.66
A106: Min | B106: =MIN(B9:B104) -> -0.05 | C106: =MIN(C9:C104) -> 10.92 | D106: =MIN(D9:D104) -> 4.43 | E106: =MIN(E9:E104) -> 4.44 | F106: =MIN(F9:F104) -> 3.78 | G106: =MIN(G9:G104) -> 56.12 | H106: =MIN(H9:H104) -> 21.67 | I106: =MIN(I9:I104) -> 1.16 | ... Q106: =MIN(Q9:Q104) -> 9.6
A107: Max | B107: =MAX(B9:B104) -> 60.83 | C107: =MAX(C9:C104) -> 25.22 | D107: =MAX(D9:D104) -> 57.04 | E107: =MAX(E9:E104) -> 7.52 | F107: =MAX(F9:F104) -> 9.07 | G107: =MAX(G9:G104) -> 148.36 | H107: =MAX(H9:H104) -> 118.11 | I107: =MAX(I9:I104) -> 8.99 | ... Q107: =MAX(Q9:Q104) -> 9.66
A108: Avg | B108: =AVERAGE(B9:B104) -> 14.221042 | C108: =AVERAGE(C9:C104) -> 15.084375 | D108: =AVERAGE(D9:D104) -> 17.908646 | E108: =AVERAGE(E9:E104) -> 5.7720833 | F108: =AVERAGE(F9:F104) -> 5.1382292 | G108: =AVERAGE(G9:G104) -> 86.8875 | H108: =AVERAGE(H9:H104) -> 42.773333 | I108: =AVERAGE(I9:I104) -> 4.7923958 | ... Q108: =AVERAGE(Q9:Q104) -> 9.6214583
A109: Stdev | B109: =STDEV(B9:B104) -> 18.904614 | C109: =STDEV(C9:C104) -> 3.8385304 | D109: =STDEV(D9:D104) -> 16.7304 | E109: =STDEV(E9:E104) -> 0.77934374 | F109: =STDEV(F9:F104) -> 1.1963972 | G109: =STDEV(G9:G104) -> 25.014886 | H109: =STDEV(H9:H104) -> 20.950906 | I109: =STDEV(I9:I104) -> 1.8824339 | ... Q109: =STDEV(Q9:Q104) -> 0.0098386099
A110: Num | B110: =COUNT(B9:B104) -> 96 | C110: =COUNT(C9:C104) -> 96 | D110: =COUNT(D9:D104) -> 96 | E110: =COUNT(E9:E104) -> 96 | F110: =COUNT(F9:F104) -> 96 | G110: =COUNT(G9:G104) -> 96 | H110: =COUNT(H9:H104) -> 96 | I110: =COUNT(I9:I104) -> 96 | ... Q110: =COUNT(Q9:Q104) -> 96
A111: DCR | B111: =IF(B110>=87,">90%",IF(B110<=87,"<90%")) -> >90% | C111: =IF(C110>=87,">90%",IF(C110<=87,"<90%")) -> >90% | D111: =IF(D110>=87,">90%",IF(D110<=87,"<90%")) -> >90% | E111: =IF(E110>=87,">90%",IF(E110<=87,"<90%")) -> >90% | F111: =IF(F110>=87,">90%",IF(F110<=87,"<90%")) -> >90% | G111: =IF(G110>=87,">90%",IF(G110<=87,"<90%")) -> >90% | H111: =IF(H110>=87,">90%",IF(H110<=87,"<90%")) -> >90% | I111: =IF(I110>=87,">90%",IF(I110<=87,"<90%")) -> >90% | ... Q111: =IF(Q110>=87,">90%",IF(Q110<=87,"<90%")) -> >90%
A112: Status | B112: =IF(B110>=87,"OK",IF(B110<=87,"LESS")) -> OK | C112: =IF(C110>=87,"OK",IF(C110<=87,"LESS")) -> OK | D112: =IF(D110>=87,"OK",IF(D110<=87,"LESS")) -> OK | E112: =IF(E110>=87,"OK",IF(E110<=87,"LESS")) -> OK | F112: =IF(F110>=87,"OK",IF(F110<=87,"LESS")) -> OK | G112: =IF(G110>=87,"OK",IF(G110<=87,"LESS")) -> OK | H112: =IF(H110>=87,"OK",IF(H110<=87,"LESS")) -> OK | I112: =IF(I110>=87,"OK",IF(I110<=87,"LESS")) -> OK | ... Q112: =IF(Q110>=87,"OK",IF(Q110<=87,"LESS")) -> OK
A115: Done by | B115: RK
A117: Comment

Sheet 04
A1: Station: | B1: BHATAGAON RAIPUR
A2: Date: | B2: =$A$9 -> 04/11/2024 00:15 | D2: Power Off | G2: Pw.Off | L2: Link Fail | N2: Link F | P2: Maintenance | R2: Maint.
A3: Report Type: | B3: Mean | D3: Calibration | G3: Calib. | L3: Data Fail | N3: Data F | P3: Invalid | R3: Invalid
A4: Time Base: | B4: 15 Min | D4: Zero Referrence | G4: Z.Ref | L4: Warm Up | N4: Wm. Up
A7: Date & Time | B7: NO_BHATAGAON | C7: NO2__BHATAGAON | D7: NOX_BHATAGAON | E7: SO2__BHATAGAON | F7: O3__BHATAGAON | G7: PM10__BHATAGAON | H7: PM2_5__BHATAGAON | I7: BENZ__BHATAGAON | J7: WS__BHATAGAON | K7: WD__BHATAGAON | L7: TEMP__BHATAGAON | M7: HUM__BHATAGAON | N7: SR__BHATAGAON | O7: RG__BHATAGAON | P7: CO__BHATAGAON | Q7: NH3__BHATAGAON
B8: ug/m3 | C8: ug/m3 | D8: ppb | E8: ug/m3 | F8: ug/m3 | G8: ug/m3 | H8: ug/m3 | I8: ug/m3 | J8: m/sec | K8: deg | L8: degreC | M8: % | N8: w/m2 | O8: mm | P8: mg/m3 | Q8: ug/m3
A9: 04/11/2024 00:15 | B9: 61.05 | C9: 18.41 | D9: 57.2 | E9: 6.87 | F9: 4.52 | G9: 148.36 | H9: 77.13 | I9: 7.51 | J9: 0.55 | K9: 347.07 | L9: 21.62 | M9: 90.09 | N9: 26.2 | O9: 0 | P9: 1.44 | Q9: 9.63
A10: 04/11/2024 00:30 | B10: 61.58 | C10: 18.29 | D10: 57.56 | E10: 6.74 | F10: 3.77 | G10: 152.86 | H10: 69.64 | I10: 7.39 | J10: 0.62 | K10: 220.63 | L10: 21.73 | M10: 87.74 | N10: 25.6 | O10: 0 | P10: 1.32 | Q10: 9.62
A11: 04/11/2024 00:45 | B11: 60.25 | C11: 18.19 | D11: 56.44 | E11: 6.38 | F11: 3.91 | G11: 155.59 | H11: 68 | I11: 7.03 | J11: 0.46 | K11: 301.04 | L11: 21.65 | M11: 88.6 | N11: 26.2 | O11: 0 | P11: 1.22 | Q11: 9.61
A12: 04/11/2024 01:00 | B12: 59.03 | C12: 16.23 | D12: 54.45 | E12: 6.09 | F12: 4.66 | G12: 155.59 | H12: 68 | I12: 7.03 | J12: 0.17 | K12: 268.46 | L12: 21.3 | M12: 90.79 | N12: 26 | O12: 0 | P12: 1.19 | Q12: 9.62
A13: 04/11/2024 01:15 | B13: 57.21 | C13: 15.39 | D13: 52.54 | E13: 5.99 | F13: 4.19 | G13: 155.59 | H13: 68 | I13: 5.55 | J13: 0.27 | K13: 299.09 | L13: 21.43 | M13: 85.71 | N13: 25.8 | O13: 0 | P13: 0.93 | Q13: 9.62
A14: 04/11/2024 01:30 | B14: 55.13 | C14: 14.7 | D14: 50.51 | E14: 6.07 | F14: 4.06 | G14: 133.37 | H14: 50.47 | I14: 4.86 | J14: 0.32 | K14: 333.71 | L14: 21.04 | M14: 89.25 | N14: 26 | O14: 0 | P14: 0.91 | Q14: 9.64
A15: 04/11/2024 01:45 | B15: 52.68 | C15: 14.35 | D15: 48.37 | E15: 5.74 | F15: 4.06 | G15: 119.88 | H15: 46.65 | I15: 4.17 | J15: 0.25 | K15: 209.98 | L15: 21.08 | M15: 89.52 | N15: 25.5 | O15: 0 | P15: 0.95 | Q15: 9.64
A16: 04/11/2024 02:00 | B16: 50.36 | C16: 13.61 | D16: 46.12 | E16: 5.78 | F16: 4.17 | G16: 119.88 | H16: 46.65 | I16: 4.52 | J16: 0.46 | K16: 248.21 | L16: 20.97 | M16: 90.92 | N16: 25.8 | O16: 0 | P16: 0.99 | Q16: 9.62
A17: 04/11/2024 02:15 | B17: 48.11 | C17: 13.07 | D17: 44.03 | E17: 5.48 | F17: 3.76 | G17: 119.88 | H17: 46.65 | I17: 5.31 | J17: 0.36 | K17: 290.36 | L17: 20.86 | M17: 92.48 | N17: 26.1 | O17: 0 | P17: 0.96 | Q17: 9.63
A18: 04/11/2024 02:30 | B18: 45.98 | C18: 12.48 | D18: 42.02 | E18: 5.23 | F18: 3.89 | G18: 102.19 | H18: 39.85 | I18: 5.2 | J18: 0.14 | K18: 270.69 | L18: 20.62 | M18: 93.46 | N18: 25.9 | O18: 0 | P18: 0.91 | Q18: 9.64
A19: 04/11/2024 02:45 | B19: 43.74 | C19: 12.92 | D19: 40.45 | E19: 5.34 | F19: 4.02 | G19: 90.92 | H19: 38.37 | I19: 4.62 | J19: 0.18 | K19: 300.19 | L19: 20.59 | M19: 94.36 | N19: 25.9 | O19: 0 | P19: 1.1 | Q19: 9.63
A20: 04/11/2024 03:00 | B20: 41.36 | C20: 12.99 | D20: 38.58 | E20: 5.44 | F20: 3.64 | G20: 90.92 | H20: 38.37 | I20: 5.91 | J20: 0.37 | K20: 309.9 | L20: 20.56 | M20: 95.29 | N20: 26 | O20: 0 | P20: 1.06 | Q20: 9.62
... A55: 04/11/2024 11:45 | B55: -0.03 | C55: 18.16 | D55: 8.09 | E55: 7.88 | F55: 12 | G55: 83.25 | H55: 33.55 | I55: 3.34 | J55: 0.21 | K55: 46.58 | L55: 29.81 | M55: 31.03 | N55: 690.4 | O55: 0 | P55: 0.47 | Q55: 9.61
A56: 04/11/2024 12:00 | B56: -0.13 | C56: 18.83 | D56: 8.35 | E56: 6.31 | F56: 12.76 | G56: Calib. | H56: Calib. | I56: 2.99 | J56: 0.22 | K56: 45.91 | L56: 29.82 | M56: 30.07 | N56: 672.2 | O56: 0 | P56: 0.42 | Q56: 9.62
A57: 04/11/2024 12:15 | B57: -0.17 | C57: 17.5 | D57: 7.63 | E57: 6.29 | F57: 12.59 | G57: Calib. | H57: Calib. | I57: 2.67 | J57: 0.61 | K57: 126.38 | L57: 28.57 | M57: 31.77 | N57: 653.9 | O57: 0 | P57: 0.4 | Q57: 9.62
A58: 04/11/2024 12:30 | B58: 1.61 | C58: 19.45 | D58: 10.08 | E58: 6.55 | F58: 10.62 | G58: Calib. | H58: Calib. | I58: 2.63 | J58: 1.32 | K58: 332.49 | L58: 30.92 | M58: 30.19 | N58: 628.6 | O58: 0 | P58: 0.41 | Q58: 9.61
A59: 04/11/2024 12:45 | B59: 1.89 | C59: 20.44 | D59: 10.82 | E59: 6.98 | F59: 12.46 | G59: Calib. | H59: Calib. | I59: 2.83 | J59: 0.36 | K59: 341.05 | L59: 30.31 | M59: 31.09 | N59: 596.1 | O59: 0 | P59: 0.41 | Q59: 9.62
A60: 04/11/2024 13:00 | B60: 1.54 | C60: 20.74 | D60: 10.69 | E60: 6.27 | F60: 12.18 | G60: 31.31 | H60: 10.56 | I60: 2.7 | J60: 0.82 | K60: 328.36 | L60: 30.92 | M60: 29.88 | N60: 559.7 | O60: 0 | P60: 0.43 | Q60: 9.62
A61: 04/11/2024 13:15 | B61: 1.73 | C61: 21.57 | D61: 11.29 | E61: 6.53 | F61: 8.58 | G61: 122.53 | H61: 30.75 | I61: 2.52 | J61: 1.46 | K61: 329.35 | L61: 31.24 | M61: 27.73 | N61: 418.2 | O61: 0 | P61: 0.53 | Q61: 9.62
A62: 04/11/2024 13:30 | B62: 1.95 | C62: 20.53 | D62: 10.91 | E62: 6.17 | F62: 7.27 | G62: 122.53 | H62: 30.75 | I62: 2.49 | J62: 1.84 | K62: 331.01 | L62: 30.97 | M62: 28.68 | N62: 315.3 | O62: 0 | P62: 0.53 | Q62: 9.61
A63: 04/11/2024 13:45 | B63: 2.09 | C63: 20.7 | D63: 11.11 | E63: 6.46 | F63: 8.28 | G63: 122.53 | H63: 30.75 | I63: 2.53 | J63: 1.29 | K63: 338.54 | L63: 30.44 | M63: 28.9 | N63: 431.8 | O63: 0 | P63: 0.57 | Q63: 9.62
A64: 04/11/2024 14:00 | B64: 2.23 | C64: 21.62 | D64: 11.7 | E64: 5.64 | F64: 7.85 | G64: 116.77 | H64: 31.02 | I64: 2.44 | J64: 1.72 | K64: 337.88 | L64: 29.29 | M64: 30.5 | N64: 213.4 | O64: 0 | P64: 0.57 | Q64: 9.62
A65: 04/11/2024 14:15 | B65: 2.59 | C65: 23.73 | D65: 13.1 | E65: 6.11 | F65: 9.15 | G65: 99.99 | H65: 31.53 | I65: 2.28 | J65: 1.16 | K65: 338.72 | L65: 27.96 | M65: 32.73 | N65: 118 | O65: 0 | P65: 0.74 | Q65: 9.62
A66: 04/11/2024 14:30 | B66: 2.63 | C66: 25.18 | D66: 13.88 | E66: 5.77 | F66: 6.91 | G66: 99.99 | H66: 31.53 | I66: 2.24 | J66: 1.54 | K66: 333.2 | L66: 28.15 | M66: 34.39 | N66: 148.2 | O66: 0 | P66: 0.67 | Q66: 9.64
A67: 04/11/2024 14:45 | B67: 2.87 | C67: 25.02 | D67: 13.99 | E67: 5.77 | F67: 10.14 | G67: 99.99 | H67: 31.53 | I67: 2.49 | J67: 1.34 | K67: 334.7 | L67: 28.42 | M67: 33.37 | N67: 147.1 | O67: 0 | P67: 0.68 | Q67: 9.63
A68: 04/11/2024 15:00 | B68: 2.64 | C68: 28 | D68: 15.37 | E68: 6.21 | F68: 9.62 | G68: 98.15 | H68: 31.7 | I68: 2.5 | J68: 1.61 | K68: 335.89 | L68: 28.15 | M68: 31.98 | N68: 126.5 | O68: 0 | P68: 0.64 | Q68: 9.61
A69: 04/11/2024 15:15 | B69: 2.7 | C69: 28.58 | D69: 15.72 | E69: 5.94 | F69: 6.72 | G69: 92.78 | H69: 32.02 | I69: 2.51 | J69: 1.81 | K69: 336.95 | L69: 27.69 | M69: 33.67 | N69: 109 | O69: 0 | P69: 0.68 | Q69: 9.6
A70: 04/11/2024 15:30 | B70: 3.19 | C70: 27.84 | D70: 15.73 | E70: 5.68 | F70: 6.06 | G70: 92.78 | H70: 32.02 | I70: 2.8 | J70: 2.09 | K70: 335.08 | L70: 27.14 | M70: 33.16 | N70: 91.8 | O70: 0 | P70: 0.66 | Q70: 9.61
A71: 04/11/2024 15:45 | B71: 5.34 | C71: 29.17 | D71: 18.15 | E71: 5.6 | F71: 5.68 | G71: 92.78 | H71: 32.02 | I71: 2.97 | J71: 1.84 | K71: 332.21 | L71: 26.74 | M71: 33.59 | N71: 84.4 | O71: 0 | P71: 0.65 | Q71: 9.62
... A104: 04/11/2024 24:00 | B104: 92.33 | C104: 20.81 | D104: 83.54 | E104: 6.01 | F104: 3.97 | G104: 114.57 | H104: 57.56 | I104: 8.9 | J104: 0.41 | K104: 327.97 | L104: 18.47 | M104: 82.47 | N104: 26.1 | O104: 0 | P104: 1.94 | Q104: 9.66
A106: Min | B106: =MIN(B9:B104) -> -0.17 | C106: =MIN(C9:C104) -> 11.01 | D106: =MIN(D9:D104) -> 6.83 | E106: =MIN(E9:E104) -> 5 | F106: =MIN(F9:F104) -> 3.22 | G106: =MIN(G9:G104) -> 31.31 | H106: =MIN(H9:H104) -> 10.56 | I106: =MIN(I9:I104) -> 2.24 | ... Q106: =MIN(Q9:Q104) -> 9.6
A107: Max | B107: =MAX(B9:B104) -> 92.33 | C107: =MAX(C9:C104) -> 34.6 | D107: =MAX(D9:D104) -> 83.54 | E107: =MAX(E9:E104) -> 10.19 | F107: =MAX(F9:F104) -> 33.56 | G107: =MAX(G9:G104) -> 155.59 | H107: =MAX(H9:H104) -> 77.13 | I107: =MAX(I9:I104) -> 9.37 | ... Q107: =MAX(Q9:Q104) -> 9.66
A108: Avg | B108: =AVERAGE(B9:B104) -> 31.443125 | C108: =AVERAGE(C9:C104) -> 19.303125 | D108: =AVERAGE(D9:D104) -> 33.92375 | E108: =AVERAGE(E9:E104) -> 6.77625 | F108: =AVERAGE(F9:F104) -> 5.7176042 | G108: =AVERAGE(G9:G104) -> 98.166413 | H108: =AVERAGE(H9:H104) -> 41.36163 | I108: =AVERAGE(I9:I104) -> 5.1920833 | ... Q108: =AVERAGE(Q9:Q104) -> 9.6242708
A109: Stdev | B109: =STDEV(B9:B104) -> 27.890748 | C109: =STDEV(C9:C104) -> 6.5218311 | D109: =STDEV(D9:D104) -> 22.297031 | E109: =STDEV(E9:E104) -> 1.2319546 | F109: =STDEV(F9:F104) -> 4.0537156 | G109: =STDEV(G9:G104) -> 21.002418 | H109: =STDEV(H9:H104) -> 14.459646 | I109: =STDEV(I9:I104) -> 2.0704766 | ... Q109: =STDEV(Q9:Q104) -> 0.0109299
...

Sheet 05
A1: Station: | B1: BHATAGAON RAIPUR
A2: Date: | B2: =$A$9 -> 05/11/2024 00:15 | D2: Power Off | G2: Pw.Off | L2: Link Fail | N2: Link F | P2: Maintenance | R2: Maint.
A3: Report Type: | B3: Mean | D3: Calibration | G3: Calib. | L3: Data Fail | N3: Data F | P3: Invalid | R3: Invalid
A4: Time Base: | B4: 15 Min | D4: Zero Referrence | G4: Z.Ref | L4: Warm Up | N4: Wm. Up
A7: Date & Time | B7: NO_BHATAGAON | C7: NO2__BHATAGAON | D7: NOX_BHATAGAON | E7: SO2__BHATAGAON | F7: O3__BHATAGAON | G7: PM10__BHATAGAON | H7: PM2_5__BHATAGAON | I7: BENZ__BHATAGAON | J7: WS__BHATAGAON | K7: WD__BHATAGAON | L7: TEMP__BHATAGAON | M7: HUM__BHATAGAON | N7: SR__BHATAGAON | O7: RG__BHATAGAON | P7: CO__BHATAGAON | Q7: NH3__BHATAGAON
B8: ug/m3 | C8: ug/m3 | D8: ppb | E8: ug/m3 | F8: ug/m3 | G8: ug/m3 | H8: ug/m3 | I8: ug/m3 | J8: m/sec | K8: deg | L8: degreC | M8: % | N8: w/m2 | O8: mm | P8: mg/m3 | Q8: ug/m3
A9: 05/11/2024 00:15 | B9: 93.79 | C9: 20.85 | D9: 84.73 | E9: 7.23 | F9: 4.04 | G9: 117.47 | H9: 53.84 | I9: 8.9 | J9: 0.26 | K9: 294.14 | L9: 18.8 | M9: 72.4 | N9: 25.5 | O9: 0 | P9: 1.66 | Q9: 9.64
A10: 05/11/2024 00:30 | B10: 91.11 | C10: 21 | D10: 82.66 | E10: 6.59 | F10: 4.06 | G10: 117.47 | H10: 53.84 | I10: 9.07 | J10: 0.37 | K10: 346.37 | L10: 19.33 | M10: 68.07 | N10: 25.6 | O10: 0 | P10: 1.7 | Q10: 9.65
A11: 05/11/2024 00:45 | B11: 86.37 | C11: 20.78 | D11: 78.75 | E11: 6.49 | F11: 4.31 | G11: 117.47 | H11: 53.84 | I11: 7.51 | J11: 0.25 | K11: 15.22 | L11: 19.34 | M11: 67.59 | N11: 25.8 | O11: 0 | P11: 1.6 | Q11: 9.65
A12: 05/11/2024 01:00 | B12: 81.38 | C12: 20.77 | D12: 74.74 | E12: 6.22 | F12: 4.01 | G12: 112.09 | H12: 50.44 | I12: 6.89 | J12: 0.18 | K12: 350.3 | L12: 19.13 | M12: 69.95 | N12: 26.1 | O12: 0 | P12: 1.66 | Q12: 9.63
A13: 05/11/2024 01:15 | B13: 76.64 | C13: 20.17 | D13: 70.62 | E13: 6.36 | F13: 3.97 | G13: 96.44 | H13: 43.94 | I13: 7.68 | J13: 0.43 | K13: 331.18 | L13: 19.05 | M13: 71.26 | N13: 26 | O13: 0 | P13: 1.46 | Q13: 9.62
A14: 05/11/2024 01:30 | B14: 71.97 | C14: 19.83 | D14: 66.7 | E14: 6.13 | F14: 4 | G14: 96.44 | H14: 43.94 | I14: 7.82 | J14: 0.41 | K14: 318.79 | L14: 18.4 | M14: 78.03 | N14: 26.2 | O14: 0 | P14: 1.48 | Q14: 9.69
A15: 05/11/2024 01:45 | B15: 67.84 | C15: 19.73 | D15: 63.33 | E15: 6.05 | F15: 4.28 | G15: 96.44 | H15: 43.94 | I15: 7.87 | J15: 0.52 | K15: 304.5 | L15: 18.04 | M15: 77.39 | N15: 26.1 | O15: 0 | P15: 1.11 | Q15: 9.71
A16: 05/11/2024 02:00 | B16: 64.82 | C16: 17.27 | D16: 59.63 | E16: 5.86 | F16: 4.97 | G16: 94.76 | H16: 42.81 | I16: 7.87 | J16: 0.23 | K16: 25.48 | L16: 17.95 | M16: 79.14 | N16: 26.1 | O16: 0 | P16: 1.04 | Q16: 9.63
A17: 05/11/2024 02:15 | B17: 61.93 | C17: 16.52 | D17: 56.92 | E17: 5.83 | F17: 4.51 | G17: 89.87 | H17: 40.53 | I17: 5.62 | J17: 0.3 | K17: 62.98 | L17: 18.25 | M17: 75.83 | N17: 25.9 | O17: 0 | P17: 0.99 | Q17: 9.65
A18: 05/11/2024 02:30 | B18: 59.16 | C18: 16.05 | D18: 54.45 | E18: 5.6 | F18: 3.81 | G18: 89.87 | H18: 40.53 | I18: 5.12 | J18: 0.5 | K18: 136.84 | L18: 18.29 | M18: 76.21 | N18: 25.7 | O18: 0 | P18: 0.96 | Q18: 9.66
A19: 05/11/2024 02:45 | B19: 56.52 | C19: 15.5 | D19: 52.05 | E19: 5.65 | F19: 3.87 | G19: 89.87 | H19: 40.53 | I19: 5.97 | J19: 0.46 | K19: 268.44 | L19: 18.01 | M19: 81.52 | N19: 26.2 | O19: 0 | P19: 1.06 | Q19: 9.65
A20: 05/11/2024 03:00 | B20: 54.19 | C20: 15.18 | D20: 50.01 | E20: 5.88 | F20: 3.5 | G20: 88.73 | H20: 38.19 | I20: 6.77 | J20: 0.31 | K20: 32.41 | L20: 17.54 | M20: 87.09 | N20: 26.1 | O20: 0 | P20: 1.07 | Q20: 9.64
... A104: 05/11/2024 24:00 | B104: 3.73 | C104: 16.07 | D104: 10.01 | E104: 6.56 | F104: 3.43 | G104: 69.82 | H104: 26.09 | I104: 6.28 | J104: 1.28 | K104: 102.28 | L104: 19.87 | M104: 72.88 | N104: 26 | O104: 0 | P104: 0.65 | Q104: 9.63
A106: Min | B106: =MIN(B9:B104) -> 2.55 | C106: =MIN(C9:C104) -> 14.29 | D106: =MIN(D9:D104) -> 9.98 | E106: =MIN(E9:E104) -> 4.16 | F106: =MIN(F9:F104) -> 3.1 | G106: =MIN(G9:G104) -> 59.58 | H106: =MIN(H9:H104) -> 15.56 | I106: =MIN(I9:I104) -> 2.1 | ... Q106: =MIN(Q9:Q104) -> 9.6
A107: Max | B107: =MAX(B9:B104) -> 93.79 | C107: =MAX(C9:C104) -> 23.48 | D107: =MAX(D9:D104) -> 84.73 | E107: =MAX(E9:E104) -> 7.23 | F107: =MAX(F9:F104) -> 7.12 | G107: =MAX(G9:G104) -> 117.47 | H107: =MAX(H9:H104) -> 53.84 | I107: =MAX(I9:I104) -> 9.07 | ... Q107: =MAX(Q9:Q104) -> 9.71
A108: Avg | B108: =AVERAGE(B9:B104) -> 21.640208 | C108: =AVERAGE(C9:C104) -> 18.836354 | D108: =AVERAGE(D9:D104) -> 25.818333 | E108: =AVERAGE(E9:E104) -> 5.506875 | F108: =AVERAGE(F9:F104) -> 4.5245833 | G108: =AVERAGE(G9:G104) -> 73.675521 | H108: =AVERAGE(H9:H104) -> 30.116354 | I108: =AVERAGE(I9:I104) -> 5.8417708 | ... Q108: =AVERAGE(Q9:Q104) -> 9.6263542
A109: Stdev | B109: =STDEV(B9:B104) -> 23.739231 | C109: =STDEV(C9:C104) -> 2.5700846 | D109: =STDEV(D9:D104) -> 18.594982 | E109: =STDEV(E9:E104) -> 0.68440725 | F109: =STDEV(F9:F104) -> 0.85717273 | G109: =STDEV(G9:G104) -> 12.789347 | H109: =STDEV(H9:H104) -> 8.3062962 | I109: =STDEV(I9:I104) -> 1.4463413 | ... Q109: =STDEV(Q9:Q104) -> 0.015363648
A110: Num | B110: =COUNT(B9:B104) -> 96 | C110: =COUNT(C9:C104) -> 96 | D110: =COUNT(D9:D104) -> 96 | E110: =COUNT(E9:E104) -> 96 | F110: =COUNT(F9:F104) -> 96 | G110: =COUNT(G9:G104) -> 96 | H110: =COUNT(H9:H104) -> 96 | I110: =COUNT(I9:I104) -> 96 | ... Q110: =COUNT(Q9:Q104) -> 96
A111: DCR | B111: =IF(B110>=87,">90%",IF(B110<=87,"<90%")) -> >90% | C111: =IF(C110>=87,">90%",IF(C110<=87,"<90%")) -> >90% | D111: =IF(D110>=87,">90%",IF(D110<=87,"<90%")) -> >90% | E111: =IF(E110>=87,">90%",IF(E110<=87,"<90%")) -> >90% | F111: =IF(F110>=87,">90%",IF(F110<=87,"<90%")) -> >90% | G111: =IF(G110>=87,">90%",IF(G110<=87,"<90%")) -> >90% | H111: =IF(H110>=87,">90%",IF(H110<=87,"<90%")) -> >90% | I111: =IF(I110>=87,">90%",IF(I110<=87,"<90%")) -> >90% | ... Q111: =IF(Q110>=87,">90%",IF(Q110<=87,"<90%")) -> >90%
A112: Status | B112: =IF(B110>=87,"OK",IF(B110<=87,"LESS")) -> OK | C112: =IF(C110>=87,"OK",IF(C110<=87,"LESS")) -> OK | D112: =IF(D110>=87,"OK",IF(D110<=87,"LESS")) -> OK | E112: =IF(E110>=87,"OK",IF(E110<=87,"LESS")) -> OK | F112: =IF(F110>=87,"OK",IF(F110<=87,"LESS")) -> OK | G112: =IF(G110>=87,"OK",IF(G110<=87,"LESS")) -> OK | H112: =IF(H110>=87,"OK",IF(H110<=87,"LESS")) -> OK | I112: =IF(I110>=87,"OK",IF(I110<=87,"LESS")) -> OK | ... Q112: =IF(Q110>=87,"OK",IF(Q110<=87,"LESS")) -> OK
A115: Done by | B115: RK
A117: Comment

Sheet 06
A1: Station: | B1: BHATAGAON RAIPUR
A2: Date: | B2: =$A$9 -> 06/11/2024 00:15 | D2: Power Off | G2: Pw.Off | L2: Link Fail | N2: Link F | P2: Maintenance | R2: Maint.
A3: Report Type: | B3: Mean | D3: Calibration | G3: Calib. | L3: Data Fail | N3: Data F | P3: Invalid | R3: Invalid
A4: Time Base: | B4: 15 Min | D4: Zero Referrence | G4: Z.Ref | L4: Warm Up | N4: Wm. Up
A7: Date & Time | B7: NO_BHATAGAON | C7: NO2__BHATAGAON | D7: NOX_BHATAGAON | E7: SO2__BHATAGAON | F7: O3__BHATAGAON | G7: PM10__BHATAGAON | H7: PM2_5__BHATAGAON | I7: BENZ__BHATAGAON | J7: WS__BHATAGAON | K7: WD__BHATAGAON | L7: TEMP__BHATAGAON | M7: HUM__BHATAGAON | N7: SR__BHATAGAON | O7: RG__BHATAGAON | P7: CO__BHATAGAON | Q7: NH3__BHATAGAON
B8: ug/m3 | C8: ug/m3 | D8: ppb | E8: ug/m3 | F8: ug/m3 | G8: ug/m3 | H8: ug/m3 | I8: ug/m3 | J8: m/sec | K8: deg | L8: degreC | M8: % | N8: w/m2 | O8: mm | P8: mg/m3 | Q8: ug/m3
A9: 06/11/2024 00:15 | B9: 3.57 | C9: 15.48 | D9: 9.58 | E9: 6.13 | F9: 4.14 | G9: 64.8 | H9: 22.49 | I9: 5.85 | J9: 1.32 | K9: 99.79 | L9: 19.75 | M9: 73.08 | N9: 26 | O9: 0 | P9: 0.67 | Q9: 9.62
A10: 06/11/2024 00:30 | B10: 3.41 | C10: 14.99 | D10: 9.19 | E10: 6.01 | F10: 4.08 | G10: 64.8 | H10: 22.49 | I10: 5.84 | J10: 1.26 | K10: 110.15 | L10: 19.61 | M10: 73.94 | N10: 26 | O10: 0 | P10: 0.68 | Q10: 9.61
A11: 06/11/2024 00:45 | B11: 3.23 | C11: 15.02 | D11: 9.06 | E11: 5.89 | F11: 4.26 | G11: 64.8 | H11: 22.49 | I11: 5.87 | J11: 0.6 | K11: 110.97 | L11: 19.5 | M11: 74.46 | N11: 26 | O11: 0 | P11: 0.69 | Q11: 9.61
A12: 06/11/2024 01:00 | B12: 3 | C12: 14.66 | D12: 8.69 | E12: 5.89 | F12: 4.19 | G12: 63.99 | H12: 24.03 | I12: 6.94 | J12: 0.26 | K12: 90.07 | L12: 19.18 | M12: 76.61 | N12: 26.1 | O12: 0 | P12: 0.66 | Q12: 9.61
A13: 06/11/2024 01:15 | B13: 2.88 | C13: 14.47 | D13: 8.49 | E13: 5.84 | F13: 4.5 | G13: 61.62 | H13: 26.97 | I13: 7.23 | J13: 0.53 | K13: 105.01 | L13: 19.13 | M13: 77.23 | N13: 26 | O13: 0 | P13: 0.62 | Q13: 9.62
A14: 06/11/2024 01:30 | B14: 2.75 | C14: 14.38 | D14: 8.35 | E14: 5.53 | F14: 4.28 | G14: 61.62 | H14: 26.97 | I14: 7.04 | J14: 0.29 | K14: 156.16 | L14: 18.91 | M14: 77.34 | N14: 26 | O14: 0 | P14: 0.64 | Q14: 9.62
A15: 06/11/2024 01:45 | B15: 2.68 | C15: 14.09 | D15: 8.13 | E15: 5.4 | F15: 4.4 | G15: 61.62 | H15: 26.97 | I15: 6.88 | J15: 0.49 | K15: 177.41 | L15: 18.8 | M15: 77.08 | N15: 25.9 | O15: 0 | P15: 0.62 | Q15: 9.63
A16: 06/11/2024 02:00 | B16: 2.57 | C16: 14.07 | D16: 8.03 | E16: 5.7 | F16: 4.4 | G16: 60.84 | H16: 26.82 | I16: 6.63 | J16: 0.48 | K16: 202.3 | L16: 18.69 | M16: 77.5 | N16: 26 | O16: 0 | P16: 0.59 | Q16: 9.62
A17: 06/11/2024 02:15 | B17: 2.47 | C17: 14.24 | D17: 8.04 | E17: 5.46 | F17: 4.33 | G17: 58.42 | H17: 26.53 | I17: 6.4 | J17: 0.32 | K17: 207.92 | L17: 18.56 | M17: 78.48 | N17: 26 | O17: 0 | P17: 0.59 | Q17: 9.63
A18: 06/11/2024 02:30 | B18: 2.42 | C18: 14.3 | D18: 8.04 | E18: 5.32 | F18: 4.51 | G18: 58.42 | H18: 26.53 | I18: 5.88 | J18: 0.34 | K18: 196.48 | L18: 18.36 | M18: 80.04 | N18: 26.1 | O18: 0 | P18: 0.57 | Q18: 9.62
A19: 06/11/2024 02:45 | B19: 2.41 | C19: 14.14 | D19: 7.95 | E19: 5.59 | F19: 4.63 | G19: 58.42 | H19: 26.53 | I19: 5.82 | J19: 0.41 | K19: 291.22 | L19: 18.09 | M19: 83.47 | N19: 26.1 | O19: 0 | P19: 0.5 | Q19: 9.62
A20: 06/11/2024 03:00 | B20: 2.52 | C20: 13.39 | D20: 7.64 | E20: 5.39 | F20: 4.08 | G20: 58.69 | H20: 25.3 | I20: 5.5 | J20: 0.6 | K20: 311.72 | L20: 17.65 | M20: 89.85 | N20: 26.2 | O20: 0 | P20: 0.5 | Q20: 9.63
... A104: 06/11/2024 24:00 | B104: 3.04 | C104: 19.78 | D104: 11.39 | E104: 4.72 | F104: 5.72 | G104: 96.66 | H104: 45.01 | I104: 4.36 | J104: 0.79 | K104: 104.5 | L104: 19.66 | M104: 72.44 | N104: 25.8 | O104: 0 | P104: 0.63 | Q104: 9.63
A106: Min | B106: =MIN(B9:B104) -> 1.47 | C106: =MIN(C9:C104) -> 13.12 | D106: =MIN(D9:D104) -> 7.64 | E106: =MIN(E9:E104) -> 4.24 | F106: =MIN(F9:F104) -> 3.48 | G106: =MIN(G9:G104) -> 51.29 | H106: =MIN(H9:H104) -> 0.98 | I106: =MIN(I9:I104) -> 1.75 | ... Q106: =MIN(Q9:Q104) -> 9.6
A107: Max | B107: =MAX(B9:B104) -> 29.59 | C107: =MAX(C9:C104) -> 70.45 | D107: =MAX(D9:D104) -> 59.15 | E107: =MAX(E9:E104) -> 11.19 | F107: =MAX(F9:F104) -> 39.18 | G107: =MAX(G9:G104) -> 158.67 | H107: =MAX(H9:H104) -> 88.62 | I107: =MAX(I9:I104) -> 7.23 | ... Q107: =MAX(Q9:Q104) -> 9.64
A108: Avg | B108: =AVERAGE(B9:B104) -> 7.4004167 | C108: =AVERAGE(C9:C104) -> 23.692292 | D108: =AVERAGE(D9:D104) -> 16.936354 | E108: =AVERAGE(E9:E104) -> 6.52375 | F108: =AVERAGE(F9:F104) -> 5.9789583 | G108: =AVERAGE(G9:G104) -> 89.389479 | H108: =AVERAGE(H9:H104) -> 44.204792 | I108: =AVERAGE(I9:I104) -> 4.4283333 | ... Q108: =AVERAGE(Q9:Q104) -> 9.6213542
A109: Stdev | B109: =STDEV(B9:B104) -> 7.117543 | C109: =STDEV(C9:C104) -> 10.291113 | D109: =STDEV(D9:D104) -> 9.3461429 | E109: =STDEV(E9:E104) -> 1.2867644 | F109: =STDEV(F9:F104) -> 4.1095384 | G109: =STDEV(G9:G104) -> 28.445097 | H109: =STDEV(H9:H104) -> 21.720037 | I109: =STDEV(I9:I104) -> 1.2236715 | ... Q109: =STDEV(Q9:Q104) -> 0.0088994135
A110: Num | B110: =COUNT(B9:B104) -> 96 | C110: =COUNT(C9:C104) -> 96 | D110: =COUNT(D9:D104) -> 96 | E110: =COUNT(E9:E104) -> 96 | F110: =COUNT(F9:F104) -> 96 | G110: =COUNT(G9:G104) -> 96 | H110: =COUNT(H9:H104) -> 96 | I110: =COUNT(I9:I104) -> 96 | ... Q110: =COUNT(Q9:Q104) -> 96
A111: DCR | B111: =IF(B110>=87,">90%",IF(B110<=87,"<90%")) -> >90% | C111: =IF(C110>=87,">90%",IF(C110<=87,"<90%")) -> >90% | D111: =IF(D110>=87,">90%",IF(D110<=87,"<90%")) -> >90% | E111: =IF(E110>=87,">90%",IF(E110<=87,"<90%")) -> >90% | F111: =IF(F110>=87,">90%",IF(F110<=87,"<90%")) -> >90% | G111: =IF(G110>=87,">90%",IF(G110<=87,"<90%")) -> >90% | H111: =IF(H110>=87,">90%",IF(H110<=87,"<90%")) -> >90% | I111: =IF(I110>=87,">90%",IF(I110<=87,"<90%")) -> >90% | ... Q111: =IF(Q110>=87,">90%",IF(Q110<=87,"<90%")) -> >90%
A112: Status | B112: =IF(B110>=87,"OK",IF(B110<=87,"LESS")) -> OK | C112: =IF(C110>=87,"OK",IF(C110<=87,"LESS")) -> OK | D112: =IF(D110>=87,"OK",IF(D110<=87,"LESS")) -> OK | E112: =IF(E110>=87,"OK",IF(E110<=87,"LESS")) -> OK | F112: =IF(F110>=87,"OK",IF(F110<=87,"LESS")) -> OK | G112: =IF(G110>=87,"OK",IF(G110<=87,"LESS")) -> OK | H112: =IF(H110>=87,"OK",IF(H110<=87,"LESS")) -> OK | I112: =IF(I110>=87,"OK",IF(I110<=87,"LESS")) -> OK | ... Q112: =IF(Q110>=87,"OK",IF(Q110<=87,"LESS")) -> OK
A115: Done by | B115: RK
A117: Comment

Sheet 07
A1: Station: | B1: BHATAGAON RAIPUR
A2: Date: | B2: =$A$9 -> 07/11/2024 00:15 | D2: Power Off | G2: Pw.Off | L2: Link Fail | N2: Link F | P2: Maintenance | R2: Maint.
A3: Report Type: | B3: Mean | D3: Calibration | G3: Calib. | L3: Data Fail | N3: Data F | P3: Invalid | R3: Invalid
A4: Time Base: | B4: 15 Min | D4: Zero Referrence | G4: Z.Ref | L4: Warm Up | N4: Wm. Up
A7: Date & Time | B7: NO_BHATAGAON | C7: NO2__BHATAGAON | D7: NOX_BHATAGAON | E7: SO2__BHATAGAON | F7: O3__BHATAGAON | G7: PM10__BHATAGAON | H7: PM2_5__BHATAGAON | I7: BENZ__BHATAGAON | J7: WS__BHATAGAON | K7: WD__BHATAGAON | L7: TEMP__BHATAGAON | M7: HUM__BHATAGAON | N7: SR__BHATAGAON | O7: RG__BHATAGAON | P7: CO__BHATAGAON | Q7: NH3__BHATAGAON
B8: ug/m3 | C8: ug/m3 | D8: ppb | E8: ug/m3 | F8: ug/m3 | G8: ug/m3 | H8: ug/m3 | I8: ug/m3 | J8: m/sec | K8: deg | L8: degreC | M8: % | N8: w/m2 | O8: mm | P8: mg/m3 | Q8: ug/m3
A9: 07/11/2024 00:15 | B9: 3.03 | C9: 19 | D9: 10.98 | E9: 4.97 | F9: 5.78 | G9: 94.52 | H9: 77.29 | I9: 3.59 | J9: 1.07 | K9: 113.52 | L9: 19.63 | M9: 73.39 | N9: 25.8 | O9: 0 | P9: 0.65 | Q9: 9.63
A10: 07/11/2024 00:30 | B10: 3.03 | C10: 17.98 | D10: 10.45 | E10: 4.53 | F10: 5.53 | G10: 94.52 | H10: 77.29 | I10: 2.88 | J10: 0.89 | K10: 115.59 | L10: 19.54 | M10: 73.74 | N10: 25.8 | O10: 0 | P10: 0.65 | Q10: 9.63
A11: 07/11/2024 00:45 | B11: 2.98 | C11: 17.18 | D11: 9.99 | E11: 5.01 | F11: 5.49 | G11: 94.52 | H11: 77.29 | I11: 3.97 | J11: 0.73 | K11: 111.15 | L11: 19.42 | M11: 74.62 | N11: 25.9 | O11: 0 | P11: 0.62 | Q11: 9.63
A12: 07/11/2024 01:00 | B12: 2.95 | C12: 16.52 | D12: 9.62 | E12: 4.69 | F12: 6.02 | G12: 94.54 | H12: 68.07 | I12: 3.96 | J12: 0.28 | K12: 328.21 | L12: 19.04 | M12: 78.23 | N12: 26.1 | O12: 0 | P12: 0.58 | Q12: 9.62
A13: 07/11/2024 01:15 | B13: 2.94 | C13: 15.97 | D13: 9.33 | E13: 4.56 | F13: 5.52 | G13: 94.6 | H13: 48.42 | I13: 3.6 | J13: 0.57 | K13: 296.28 | L13: 18.43 | M13: 83.52 | N13: 26.2 | O13: 0 | P13: 0.68 | Q13: 9.63
A14: 07/11/2024 01:30 | B14: 2.98 | C14: 15.69 | D14: 9.21 | E14: 4.66 | F14: 4.43 | G14: 94.6 | H14: 48.42 | I14: 3.53 | J14: 0.51 | K14: 265.4 | L14: 18.2 | M14: 84 | N14: 26.1 | O14: 0 | P14: 0.69 | Q14: 9.62
A15: 07/11/2024 01:45 | B15: 2.98 | C15: 16.12 | D15: 9.44 | E15: 4.84 | F15: 4.56 | G15: 94.6 | H15: 48.42 | I15: 3.86 | J15: 0.44 | K15: 300.22 | L15: 17.95 | M15: 85.35 | N15: 26.1 | O15: 0 | P15: 0.69 | Q15: 9.61
A16: 07/11/2024 02:00 | B16: 2.88 | C16: 16.05 | D16: 9.32 | E16: 4.98 | F16: 4.92 | G16: 93.97 | H16: 41.66 | I16: 5.21 | J16: 0.52 | K16: 277.55 | L16: 17.93 | M16: 84.93 | N16: 26 | O16: 0 | P16: 0.68 | Q16: 9.59
A17: 07/11/2024 02:15 | B17: 3.06 | C17: 16.24 | D17: 9.56 | E17: 4.72 | F17: 4.78 | G17: 92.13 | H17: 21.97 | I17: 5.62 | J17: 0.52 | K17: 302.72 | L17: 17.67 | M17: 88.31 | N17: 26.1 | O17: 0 | P17: 0.68 | Q17: 9.62
A18: 07/11/2024 02:30 | B18: 3.12 | C18: 16.53 | D18: 9.76 | E18: 5.06 | F18: 4.69 | G18: 92.13 | H18: 21.97 | I18: 5.51 | J18: 0.55 | K18: 288.22 | L18: 17.39 | M18: 89.41 | N18: 26.1 | O18: 0 | P18: 0.67 | Q18: 9.63
A19: 07/11/2024 02:45 | B19: 3.09 | C19: 16.68 | D19: 9.81 | E19: 4.77 | F19: 4.78 | G19: 92.13 | H19: 21.97 | I19: 5.44 | J19: 0.24 | K19: 310.94 | L19: 17.17 | M19: 92.15 | N19: 26.1 | O19: 0 | P19: 0.66 | Q19: 9.62
A20: 07/11/2024 03:00 | B20: 3.15 | C20: 17.18 | D20: 10.13 | E20: 5.26 | F20: 4.29 | G20: 92.47 | H20: 38.94 | I20: 5.34 | J20: 0.25 | K20: 266.15 | L20: 16.98 | M20: 93.83 | N20: 25.9 | O20: 0 | P20: 0.66 | Q20: 9.63
... A104: 07/11/2024 24:00 | B104: 34.76 | C104: 25.55 | D104: 39.85 | E104: 4.51 | F104: 4.03 | G104: 94.24 | H104: 48.78 | I104: 7.25 | J104: 0.35 | K104: 279.07 | L104: 18.48 | M104: 83.56 | N104: 26.1 | O104: 0 | P104: 1.46 | Q104: 9.63
A106: Min | B106: =MIN(B9:B104) -> 2.4 | C106: =MIN(C9:C104) -> 15.41 | D106: =MIN(D9:D104) -> 9.06 | E106: =MIN(E9:E104) -> 4.26 | F106: =MIN(F9:F104) -> 3.82 | G106: =MIN(G9:G104) -> 63.02 | H106: =MIN(H9:H104) -> 21.97 | I106: =MIN(I9:I104) -> 1.96 | ... Q106: =MIN(Q9:Q104) -> 9.59
A107: Max | B107: =MAX(B9:B104) -> 37.92 | C107: =MAX(C9:C104) -> 25.79 | D107: =MAX(D9:D104) -> 41.14 | E107: =MAX(E9:E104) -> 8.36 | F107: =MAX(F9:F104) -> 7.38 | G107: =MAX(G9:G104) -> 150.49 | H107: =MAX(H9:H104) -> 102.08 | I107: =MAX(I9:I104) -> 9.89 | ... Q107: =MAX(Q9:Q104) -> 9.65
A108: Avg | B108: =AVERAGE(B9:B104) -> 11.765625 | C108: =AVERAGE(C9:C104) -> 20.031979 | D108: =AVERAGE(D9:D104) -> 18.525208 | E108: =AVERAGE(E9:E104) -> 5.7520833 | F108: =AVERAGE(F9:F104) -> 4.8701042 | G108: =AVERAGE(G9:G104) -> 99.736042 | H108: =AVERAGE(H9:H104) -> 50.638438 | I108: =AVERAGE(I9:I104) -> 5.2022917 | ... Q108: =AVERAGE(Q9:Q104) -> 9.6232292
A109: Stdev | B109: =STDEV(B9:B104) -> 11.785932 | C109: =STDEV(C9:C104) -> 3.2455779 | D109: =STDEV(D9:D104) -> 10.740897 | E109: =STDEV(E9:E104) -> 1.036758 | F109: =STDEV(F9:F104) -> 0.73545617 | G109: =STDEV(G9:G104) -> 25.32528 | H109: =STDEV(H9:H104) -> 20.239515 | I109: =STDEV(I9:I104) -> 1.6095665 | ... Q109: =STDEV(Q9:Q104) -> 0.0098936228
A110: Num | B110: =COUNT(B9:B104) -> 96 | C110: =COUNT(C9:C104) -> 96 | D110: =COUNT(D9:D104) -> 96 | E110: =COUNT(E9:E104) -> 96 | F110: =COUNT(F9:F104) -> 96 | G110: =COUNT(G9:G104) -> 96 | H110: =COUNT(H9:H104) -> 96 | I110: =COUNT(I9:I104) -> 96 | ... Q110: =COUNT(Q9:Q104) -> 96
A111: DCR | B111: =IF(B110>=87,">90%",IF(B110<=87,"<90%")) -> >90% | C111: =IF(C110>=87,">90%",IF(C110<=87,"<90%")) -> >90% | D111: =IF(D110>=87,">90%",IF(D110<=87,"<90%")) -> >90% | E111: =IF(E110>=87,">90%",IF(E110<=87,"<90%")) -> >90% | F111: =IF(F110>=87,">90%",IF(F110<=87,"<90%")) -> >90% | G111: =IF(G110>=87,">90%",IF(G110<=87,"<90%")) -> >90% | H111: =IF(H110>=87,">90%",IF(H110<=87,"<90%")) -> >90% | I111: =IF(I110>=87,">90%",IF(I110<=87,"<90%")) -> >90% | ... Q111: =IF(Q110>=87,">90%",IF(Q110<=87,"<90%")) -> >90%
A112: Status | B112: =IF(B110>=87,"OK",IF(B110<=87,"LESS")) -> OK | C112: =IF(C110>=87,"OK",IF(C110<=87,"LESS")) -> OK | D112: =IF(D110>=87,"OK",IF(D110<=87,"LESS")) -> OK | E112: =IF(E110>=87,"OK",IF(E110<=87,"LESS")) -> OK | F112: =IF(F110>=87,"OK",IF(F110<=87,"LESS")) -> OK | G112: =IF(G110>=87,"OK",IF(G110<=87,"LESS")) -> OK | H112: =IF(H110>=87,"OK",IF(H110<=87,"LESS")) -> OK | I112: =IF(I110>=87,"OK",IF(I110<=87,"LESS")) -> OK | ... Q112: =IF(Q110>=87,"OK",IF(Q110<=87,"LESS")) -> OK
A115: Done by | B115: RK
A117: Comment

Sheet 08
A1: Station: | B1: BHATAGAON RAIPUR
A2: Date: | B2: =$A$9 -> 08/11/2024 00:15 | D2: Power Off | G2: Pw.Off | L2: Link Fail | N2: Link F | P2: Maintenance | R2: Maint.
A3: Report Type: | B3: Mean | D3: Calibration | G3: Calib. | L3: Data Fail | N3: Data F | P3: Invalid | R3: Invalid
A4: Time Base: | B4: 15 Min | D4: Zero Referrence | G4: Z.Ref | L4: Warm Up | N4: Wm. Up
A7: Date & Time | B7: NO_BHATAGAON | C7: NO2__BHATAGAON | D7: NOX_BHATAGAON | E7: SO2__BHATAGAON | F7: O3__BHATAGAON | G7: PM10__BHATAGAON | H7: PM2_5__BHATAGAON | I7: BENZ__BHATAGAON | J7: WS__BHATAGAON | K7: WD__BHATAGAON | L7: TEMP__BHATAGAON | M7: HUM__BHATAGAON | N7: SR__BHATAGAON | O7: RG__BHATAGAON | P7: CO__BHATAGAON | Q7: NH3__BHATAGAON
B8: ug/m3 | C8: ug/m3 | D8: ppb | E8: ug/m3 | F8: ug/m3 | G8: ug/m3 | H8: ug/m3 | I8: ug/m3 | J8: m/sec | K8: deg | L8: degreC | M8: % | N8: w/m2 | O8: mm | P8: mg/m3 | Q8: ug/m3
A9: 08/11/2024 00:15 | B9: 34.01 | C9: 25.5 | D9: 39.22 | E9: 5.1 | F9: 4.03 | G9: 96.8 | H9: 45.58 | I9: 7.18 | J9: 0.57 | K9: 337.19 | L9: 18.02 | M9: 91.23 | N9: 26.1 | O9: 0 | P9: 1.43 | Q9: 9.67
A10: 08/11/2024 00:30 | B10: 32.79 | C10: 24.78 | D10: 37.87 | E10: 5.11 | F10: 3.99 | G10: 96.8 | H10: 45.58 | I10: 7.08 | J10: 0.54 | K10: 286.82 | L10: 17.63 | M10: 88 | N10: 26.1 | O10: 0 | P10: 1.4 | Q10: 9.68
A11: 08/11/2024 00:45 | B11: 31.15 | C11: 22.87 | D11: 35.55 | E11: 5.27 | F11: 4.3 | G11: 96.8 | H11: 45.58 | I11: 7.11 | J11: 0.55 | K11: 323.09 | L11: 17.5 | M11: 88.87 | N11: 26.1 | O11: 0 | P11: 1.06 | Q11: 9.65
A12: 08/11/2024 01:00 | B12: 30.1 | C12: 21.2 | D12: 33.84 | E12: 5.47 | F12: 4.05 | G12: 97.29 | H12: 44.58 | I12: 6.25 | J12: 0.53 | K12: 303.18 | L12: 17.45 | M12: 91.15 | N12: 26.1 | O12: 0 | P12: 1.2 | Q12: 9.63
A13: 08/11/2024 01:15 | B13: 29.38 | C13: 20.76 | D13: 33.03 | E13: 5.31 | F13: 3.97 | G13: 98.73 | H13: 42.65 | I13: 5.26 | J13: 0.58 | K13: 323.18 | L13: 17.27 | M13: 93.19 | N13: 26.1 | O13: 0 | P13: 0.98 | Q13: 9.62
A14: 08/11/2024 01:30 | B14: 28.62 | C14: 20.09 | D14: 32.07 | E14: 4.88 | F14: 3.98 | G14: 98.73 | H14: 42.65 | I14: 5.21 | J14: 0.42 | K14: 268.55 | L14: 17.35 | M14: 92.89 | N14: 25.6 | O14: 0 | P14: 1.1 | Q14: 9.64
A15: 08/11/2024 01:45 | B15: 27.7 | C15: 19.27 | D15: 30.9 | E15: 4.71 | F15: 3.92 | G15: 98.73 | H15: 42.65 | I15: 5.66 | J15: 0.42 | K15: 173.34 | L15: 17.65 | M15: 92.56 | N15: 25.8 | O15: 0 | P15: 1.06 | Q15: 9.62
A16: 08/11/2024 02:00 | B16: 26.83 | C16: 18.31 | D16: 29.7 | E16: 5.26 | F16: 4.2 | G16: 97.86 | H16: 44.21 | I16: 5.29 | J16: 0.54 | K16: 218 | L16: 17.25 | M16: 94.96 | N16: 26.1 | O16: 0 | P16: 1.11 | Q16: 9.62
A17: 08/11/2024 02:15 | B17: 26.04 | C17: 17.51 | D17: 28.65 | E17: 5.51 | F17: 3.93 | G17: 95.31 | H17: 47.33 | I17: 6.74 | J17: 0.21 | K17: 336.85 | L17: 16.94 | M17: 97.38 | N17: 26.1 | O17: 0 | P17: 1.07 | Q17: 9.63
A18: 08/11/2024 02:30 | B18: 25.29 | C18: 16.74 | D18: 27.65 | E18: 5.69 | F18: 3.92 | G18: 95.31 | H18: 47.33 | I18: 7.4 | J18: 0.54 | K18: 2.95 | L18: 16.78 | M18: 99.25 | N18: 26.1 | O18: 0 | P18: 1.09 | Q18: 9.62
A19: 08/11/2024 02:45 | B19: 24.6 | C19: 16.99 | D19: 27.23 | E19: 6.01 | F19: 3.95 | G19: 95.31 | H19: 47.33 | I19: 7.07 | J19: 0.51 | K19: 352.34 | L19: 16.58 | M19: 100.98 | N19: 26.1 | O19: 0 | P19: 1.14 | Q19: 9.62
A20: 08/11/2024 03:00 | B20: 23.77 | C20: 16.86 | D20: 26.5 | E20: 6.41 | F20: 4.23 | G20: 97.63 | H20: 48.46 | I20: 7.07 | J20: 0.55 | K20: 335.98 | L20: 16.29 | M20: 102.6 | N20: 26.1 | O20: 0 | P20: 1.13 | Q20: 9.62
... A104: 08/11/2024 24:00 | B104: 17.97 | C104: 22.01 | D104: 24.54 | E104: 5.55 | F104: 4 | G104: 108.36 | H104: 47.77 | I104: 6.96 | J104: 1.37 | K104: 111.13 | L104: 19.86 | M104: 74.92 | N104: 25.7 | O104: 0 | P104: 1.13 | Q104: 9.63
A106: Min | B106: =MIN(B9:B104) -> 1.5 | C106: =MIN(C9:C104) -> 13.76 | D106: =MIN(D9:D104) -> 7.65 | E106: =MIN(E9:E104) -> 4.71 | F106: =MIN(F9:F104) -> 3.35 | G106: =MIN(G9:G104) -> 59.37 | H106: =MIN(H9:H104) -> 33.23 | I106: =MIN(I9:I104) -> 1.59 | ... Q106: =MIN(Q9:Q104) -> 9.61
A107: Max | B107: =MAX(B9:B104) -> 42.52 | C107: =MAX(C9:C104) -> 32.61 | D107: =MAX(D9:D104) -> 41.2 | E107: =MAX(E9:E104) -> 8.3 | F107: =MAX(F9:F104) -> 29.24 | G107: =MAX(G9:G104) -> 120.85 | H107: =MAX(H9:H104) -> 57.5 | I107: =MAX(I9:I104) -> 7.81 | ... Q107: =MAX(Q9:Q104) -> 9.68
A108: Avg | B108: =AVERAGE(B9:B104) -> 20.632396 | C108: =AVERAGE(C9:C104) -> 21.1625 | D108: =AVERAGE(D9:D104) -> 26.225 | E108: =AVERAGE(E9:E104) -> 6.5880208 | F108: =AVERAGE(F9:F104) -> 5.5415625 | G108: =AVERAGE(G9:G104) -> 100.2674 | H108: =AVERAGE(H9:H104) -> 45.353021 | I108: =AVERAGE(I9:I104) -> 5.533125 | ... Q108: =AVERAGE(Q9:Q104) -> 9.6311458
A109: Stdev | B109: =STDEV(B9:B104) -> 12.618458 | C109: =STDEV(C9:C104) -> 4.2822898 | D109: =STDEV(D9:D104) -> 10.225622 | E109: =STDEV(E9:E104) -> 0.77694628 | F109: =STDEV(F9:F104) -> 3.2853279 | G109: =STDEV(G9:G104) -> 14.831442 | H109: =STDEV(H9:H104) -> 6.4752 | I109: =STDEV(I9:I104) -> 1.7356014 | ... Q109: =STDEV(Q9:Q104) -> 0.01263827
A110: Num | B110: =COUNT(B9:B104) -> 96 | C110: =COUNT(C9:C104) -> 96 | D110: =COUNT(D9:D104) -> 96 | E110: =COUNT(E9:E104) -> 96 | F110: =COUNT(F9:F104) -> 96 | G110: =COUNT(G9:G104) -> 96 | H110: =COUNT(H9:H104) -> 96 | I110: =COUNT(I9:I104) -> 96 | ... Q110: =COUNT(Q9:Q104) -> 96
A111: DCR | B111: =IF(B110>=87,">90%",IF(B110<=87,"<90%")) -> >90% | C111: =IF(C110>=87,">90%",IF(C110<=87,"<90%")) -> >90% | D111: =IF(D110>=87,">90%",IF(D110<=87,"<90%")) -> >90% | E111: =IF(E110>=87,">90%",IF(E110<=87,"<90%")) -> >90% | F111: =IF(F110>=87,">90%",IF(F110<=87,"<90%")) -> >90% | G111: =IF(G110>=87,">90%",IF(G110<=87,"<90%")) -> >90% | H111: =IF(H110>=87,">90%",IF(H110<=87,"<90%")) -> >90% | I111: =IF(I110>=87,">90%",IF(I110<=87,"<90%")) -> >90% | ... Q111: =IF(Q110>=87,">90%",IF(Q110<=87,"<90%")) -> >90%
A112: Status | B112: =IF(B110>=87,"OK",IF(B110<=87,"LESS")) -> OK | C112: =IF(C110>=87,"OK",IF(C110<=87,"LESS")) -> OK | D112: =IF(D110>=87,"OK",IF(D110<=87,"LESS")) -> OK | E112: =IF(E110>=87,"OK",IF(E110<=87,"LESS")) -> OK | F112: =IF(F110>=87,"OK",IF(F110<=87,"LESS")) -> OK | G112: =IF(G110>=87,"OK",IF(G110<=87,"LESS")) -> OK | H112: =IF(H110>=87,"OK",IF(H110<=87,"LESS")) -> OK | I112: =IF(I110>=87,"OK",IF(I110<=87,"LESS")) -> OK | ... Q112: =IF(Q110>=87,"OK",IF(Q110<=87,"LESS")) -> OK
A115: Done by | B115: RK
A117: Comment

Sheet 09
A1: Station: | B1: BHATAGAON RAIPUR
A2: Date: | B2: =$A$9 -> 09/11/2024 00:15 | D2: Power Off | G2: Pw.Off | L2: Link Fail | N2: Link F | P2: Maintenance | R2: Maint.
A3: Report Type: | B3: Mean | D3: Calibration | G3: Calib. | L3: Data Fail | N3: Data F | P3: Invalid | R3: Invalid
A4: Time Base: | B4: 15 Min | D4: Zero Referrence | G4: Z.Ref | L4: Warm Up | N4: Wm. Up
A7: Date & Time | B7: NO_BHATAGAON | C7: NO2__BHATAGAON | D7: NOX_BHATAGAON | E7: SO2__BHATAGAON | F7: O3__BHATAGAON | G7: PM10__BHATAGAON | H7: PM2_5__BHATAGAON | I7: BENZ__BHATAGAON | J7: WS__BHATAGAON | K7: WD__BHATAGAON | L7: TEMP__BHATAGAON | M7: HUM__BHATAGAON | N7: SR__BHATAGAON | O7: RG__BHATAGAON | P7: CO__BHATAGAON | Q7: NH3__BHATAGAON
B8: ug/m3 | C8: ug/m3 | D8: ppb | E8: ug/m3 | F8: ug/m3 | G8: ug/m3 | H8: ug/m3 | I8: ug/m3 | J8: m/sec | K8: deg | L8: degreC | M8: % | N8: w/m2 | O8: mm | P8: mg/m3 | Q8: ug/m3
A9: 09/11/2024 00:15 | B9: 15.99 | C9: 22.12 | D9: 23 | E9: 5.56 | F9: 4.12 | G9: 99.23 | H9: 47.53 | I9: 7.29 | J9: 1.35 | K9: 107.98 | L9: 19.8 | M9: 74.67 | N9: 25.9 | O9: 0 | P9: 1.1 | Q9: 9.62
A10: 09/11/2024 00:30 | B10: 14.2 | C10: 21.86 | D10: 21.43 | E10: 5.89 | F10: 4.51 | G10: 99.23 | H10: 47.53 | I10: 7.51 | J10: 0.17 | K10: 358.95 | L10: 19.66 | M10: 75.81 | N10: 26.2 | O10: 0 | P10: 1.04 | Q10: 9.63
A11: 09/11/2024 00:45 | B11: 13.03 | C11: 21.69 | D11: 20.4 | E11: 5.81 | F11: 4.92 | G11: 99.23 | H11: 47.53 | I11: 7.73 | J11: 0.11 | K11: 346.31 | L11: 19.24 | M11: 78.91 | N11: 26.2 | O11: 0 | P11: 0.99 | Q11: 9.63
A12: 09/11/2024 01:00 | B12: 12.09 | C12: 21.33 | D12: 19.46 | E12: 5.66 | F12: 3.99 | G12: 96.98 | H12: 46.43 | I12: 7.36 | J12: 0.26 | K12: 268.36 | L12: 18.94 | M12: 81.45 | N12: 26.1 | O12: 0 | P12: 0.98 | Q12: 9.65
A13: 09/11/2024 01:15 | B13: 11.2 | C13: 21.12 | D13: 18.64 | E13: 5.38 | F13: 3.61 | G13: 90.42 | H13: 44.32 | I13: 6.81 | J13: 0.48 | K13: 282.45 | L13: 18.72 | M13: 82.68 | N13: 26.1 | O13: 0 | P13: 0.92 | Q13: 9.63
A14: 09/11/2024 01:30 | B14: 10.35 | C14: 20.76 | D14: 17.77 | E14: 5.41 | F14: 3.14 | G14: 90.42 | H14: 44.32 | I14: 6.9 | J14: 0.64 | K14: 306.19 | L14: 18.51 | M14: 84.28 | N14: 26.1 | O14: 0 | P14: 0.93 | Q14: 9.63
A15: 09/11/2024 01:45 | B15: 9.82 | C15: 19.13 | D15: 16.5 | E15: 5.28 | F15: 3.61 | G15: 90.42 | H15: 44.32 | I15: 6.9 | J15: 0.48 | K15: 305.48 | L15: 18.23 | M15: 88.33 | N15: 26.1 | O15: 0 | P15: 0.69 | Q15: 9.61
A16: 09/11/2024 02:00 | B16: 9.49 | C16: 17.76 | D16: 15.51 | E16: 5.05 | F16: 4.89 | G16: 87.34 | H16: 43 | I16: 6.05 | J16: 0.21 | K16: 252.42 | L16: 18.29 | M16: 85.79 | N16: 25.8 | O16: 0 | P16: 0.67 | Q16: 9.62
A17: 09/11/2024 02:15 | B17: 9.26 | C17: 17.39 | D17: 15.13 | E17: 5.11 | F17: 4.73 | G17: 78.38 | H17: 40.46 | I17: 4.92 | J17: 0.51 | K17: 318.05 | L17: 18.2 | M17: 88.17 | N17: 26.1 | O17: 0 | P17: 0.72 | Q17: 9.62
A18: 09/11/2024 02:30 | B18: 9.07 | C18: 16.84 | D18: 14.7 | E18: 4.88 | F18: 4.38 | G18: 78.38 | H18: 40.46 | I18: 3.87 | J18: 0.49 | K18: 332.17 | L18: 18 | M18: 89.29 | N18: 26 | O18: 0 | P18: 0.72 | Q18: 9.63
A19: 09/11/2024 02:45 | B19: 8.89 | C19: 16.33 | D19: 14.28 | E19: 5.18 | F19: 3.91 | G19: 78.38 | H19: 40.46 | I19: 3.96 | J19: 0.55 | K19: 306.67 | L19: 17.68 | M19: 92.22 | N19: 26.1 | O19: 0 | P19: 0.67 | Q19: 9.62
A20: 09/11/2024 03:00 | B20: 8.85 | C20: 15.75 | D20: 13.95 | E20: 5.5 | F20: 4.45 | G20: 77.4 | H20: 39.36 | I20: 3.98 | J20: 0.49 | K20: 311.06 | L20: 17.41 | M20: 93.13 | N20: 26.1 | O20: 0 | P20: 0.73 | Q20: 9.61
... A104: 09/11/2024 24:00 | B104: 27.39 | C104: 20.79 | D104: 31.44 | E104: 5.61 | F104: 4 | G104: 88.32 | H104: 47.57 | I104: 4.37 | J104: 0.15 | K104: 199.06 | L104: 19.68 | M104: 70.7 | N104: 25.9 | O104: 0 | P104: 0.95 | Q104: 9.65
A106: Min | B106: =MIN(B9:B104) -> 2.96 | C106: =MIN(C9:C104) -> 15.17 | D106: =MIN(D9:D104) -> 11.1 | E106: =MIN(E9:E104) -> 3.89 | F106: =MIN(F9:F104) -> 3.14 | G106: =MIN(G9:G104) -> 62.84 | H106: =MIN(H9:H104) -> 24.25 | I106: =MIN(I9:I104) -> 2.04 | ... Q106: =MIN(Q9:Q104) -> 9.61
A107: Max | B107: =MAX(B9:B104) -> 33.17 | C107: =MAX(C9:C104) -> 28.14 | D107: =MAX(D9:D104) -> 39.92 | E107: =MAX(E9:E104) -> 6.77 | F107: =MAX(F9:F104) -> 6.78 | G107: =MAX(G9:G104) -> 117.72 | H107: =MAX(H9:H104) -> 61.08 | I107: =MAX(I9:I104) -> 9.45 | ... Q107: =MAX(Q9:Q104) -> 9.67
