Workbook

Sheet 01
A1: Station: | B1: BHATAGAON RAIPUR
A2: Date: | B2: =$A$9 -> 01/10/2025 01:00 | D2: Power Off | G2: Pw.Off | L2: Link Fail | N2: Link F | P2: Maintenance | R2: Maint.
A3: Report Type: | B3: Mean | D3: Calibration | G3: Calib. | L3: Data Fail | N3: Data F | P3: Invalid | R3: Invalid
A4: Time Base: | B4: 01 Hour | D4: Zero Referrence | G4: Z.Ref | L4: Warm Up | N4: Wm. Up
A7: Date & Time | B7: NO_BHATAGAON | C7: NO2__BHATAGAON | D7: NOX_BHATAGAON | E7: SO2__BHATAGAON | F7: O3__BHATAGAON | G7: PM10__BHATAGAON | H7: PM2_5__BHATAGAON | I7: BENZ__BHATAGAON | J7: WS__BHATAGAON | K7: WD__BHATAGAON | L7: TEMP__BHATAGAON | M7: HUM__BHATAGAON | N7: SR__BHATAGAON | O7: RG__BHATAGAON | P7: CO__BHATAGAON | Q7: NH3__BHATAGAON
B8: ug/m3 | C8: ug/m3 | D8: ppb | E8: ug/m3 | F8: ug/m3 | G8: mg/m3 | H8: ug/m3 | I8: ug/m3 | J8: m/sec | K8: deg | L8: degreC | M8: % | N8: w/m2 | O8: mm | P8: ug/m3 | Q8: ug/m3
A9: 01/10/2025 01:00 | B9: 10.17 | C9: 12.25 | D9: 13.48 | E9: 4.19 | F9: 17.11 | G9: 59.86 | H9: 6.59 | I9: 4.13 | J9: 0.29 | K9: 325.81 | L9: 23.75 | M9: 98.22 | N9: 54.2 | O9: 0 | P9: 0.71 | Q9: 9.24
A10: 01/10/2025 02:00 | B10: 7.81 | C10: 9.68 | D10: 10.45 | E10: 3.95 | F10: 14.24 | G10: 42.26 | H10: 7.74 | I10: 3.82 | J10: 0.13 | K10: 250.37 | L10: 23.61 | M10: 98.13 | N10: 54.4 | O10: 0 | P10: 0.46 | Q10: 9.18
A11: 01/10/2025 03:00 | B11: 7.13 | C11: 7.62 | D11: 9.49 | E11: 4.4 | F11: 263.9 | G11: 26.59 | H11: 7.38 | I11: 3.51 | J11: 0.11 | K11: 222.39 | L11: 23.68 | M11: 98.3 | N11: 54.9 | O11: 0 | P11: 0.44 | Q11: 9.2
A12: 01/10/2025 04:00 | B12: 6.74 | C12: 7.55 | D12: 9.35 | E12: 4.05 | F12: 23.61 | G12: 19.51 | H12: 8.82 | I12: 3.26 | J12: 0.2 | K12: 284.61 | L12: 23.66 | M12: 98.3 | N12: 54.6 | O12: 0 | P12: 0.3 | Q12: 9.19
A13: 01/10/2025 05:00 | B13: 7.35 | C13: 9.2 | D13: 10.7 | E13: 4.44 | F13: 292.25 | G13: 14.45 | H13: 7.33 | I13: 3.14 | J13: 0.07 | K13: 341.38 | L13: 23.53 | M13: 98.3 | N13: 54.6 | O13: 0 | P13: 0.32 | Q13: 9.16
A14: 01/10/2025 06:00 | B14: 9.21 | C14: 11.04 | D14: 12.4 | E14: 4.08 | F14: 347.62 | G14: 14.94 | H14: 6.29 | I14: 2.81 | J14: 0.08 | K14: 317.04 | L14: 23.51 | M14: 98.31 | N14: 60.5 | O14: 0 | P14: 0.36 | Q14: 9.1
A15: 01/10/2025 07:00 | B15: 13.41 | C15: 9.88 | D15: 14.65 | E15: 3.88 | F15: 10.59 | G15: 22.64 | H15: 6.2 | I15: 2.49 | J15: 0.19 | K15: 310.19 | L15: 24.74 | M15: 98.34 | N15: 174.6 | O15: 0 | P15: 0.4 | Q15: 9.12
A16: 01/10/2025 08:00 | B16: 14.3 | C16: 8.36 | D16: 15.29 | E16: 4.28 | F16: 8.61 | G16: 17.42 | H16: 10.19 | I16: 2.42 | J16: 0.35 | K16: 321.17 | L16: 29.17 | M16: 98.29 | N16: 430.2 | O16: 0 | P16: 0.53 | Q16: 9.2
A17: 01/10/2025 09:00 | B17: 17.95 | C17: 13.59 | D17: 19.75 | E17: 4.5 | F17: 10.97 | G17: 27.7 | H17: 8.29 | I17: 2.33 | J17: 0.72 | K17: 338.23 | L17: 34.24 | M17: 89.32 | N17: 688.8 | O17: 0 | P17: 0.56 | Q17: 9.21
A18: 01/10/2025 10:00 | B18: 18.34 | C18: 19.32 | D18: 24.8 | E18: 4.45 | F18: 14.04 | G18: 39.99 | H18: 6.96 | I18: 2.29 | J18: 0.59 | K18: 359.72 | L18: 34.51 | M18: 67.63 | N18: 794 | O18: 0 | P18: 0.61 | Q18: 9.18
A19: 01/10/2025 11:00 | B19: 12.3 | C19: 21.37 | D19: 19.01 | E19: 4.75 | F19: 22.36 | G19: 50.21 | H19: 6.03 | I19: 2.11 | J19: 0.31 | K19: 329.16 | L19: 32.52 | M19: 76.1 | N19: 811.9 | O19: 0 | P19: 0.66 | Q19: 9.18
A20: 01/10/2025 12:00 | B20: 11.65 | C20: 24.9 | D20: 20.08 | E20: 4.68 | F20: 16.36 | G20: 48.82 | H20: 8.61 | I20: 1.96 | J20: 0.55 | K20: 323.92 | L20: 31.38 | M20: 94.33 | N20: 158.6 | O20: 0 | P20: 0.65 | Q20: 9.17
... A32: 01/10/2025 24:00 | B32: 28.69 | C32: 19.26 | D32: 27.99 | E32: 6.5 | F32: 10.51 | G32: 61.64 | H32: 11.97 | I32: 2.82 | J32: 0.11 | K32: 338.77 | L32: 23.48 | M32: 98.22 | N32: 49 | O32: 0 | P32: 1.11 | Q32: 9.49
A34: Min | B34: =MIN(B9:B32) -> 6.74 | C34: =MIN(C9:C32) -> 7.55 | D34: =MIN(D9:D32) -> 9.35 | E34: =MIN(E9:E32) -> 3.88 | F34: =MIN(F9:F32) -> 8.61 | G34: =MIN(G9:G32) -> 14.45 | H34: =MIN(H9:H32) -> 6.03 | I34: =MIN(I9:I32) -> 1.63 | ... Q34: =MIN(Q9:Q32) -> 9.1
A35: Max | B35: =MAX(B9:B32) -> 34.69 | C35: =MAX(C9:C32) -> 25.34 | D35: =MAX(D9:D32) -> 36.91 | E35: =MAX(E9:E32) -> 6.66 | F35: =MAX(F9:F32) -> 347.62 | G35: =MAX(G9:G32) -> 62.13 | H35: =MAX(H9:H32) -> 12.64 | I35: =MAX(I9:I32) -> 4.13 | ... Q35: =MAX(Q9:Q32) -> 9.49
A36: Avg | B36: =AVERAGE(B9:B32) -> 16.922917 | C36: =AVERAGE(C9:C32) -> 14.96 | D36: =AVERAGE(D9:D32) -> 19.92 | E36: =AVERAGE(E9:E32) -> 5.10625 | F36: =AVERAGE(F9:F32) -> 51.955 | G36: =AVERAGE(G9:G32) -> 40.157917 | H36: =AVERAGE(H9:H32) -> 8.575 | I36: =AVERAGE(I9:I32) -> 2.4970833 | ... Q36: =AVERAGE(Q9:Q32) -> 9.24125
A37: Stdev | B37: =STDEV(B9:B32) -> 8.7230591 | C37: =STDEV(C9:C32) -> 6.0449361 | D37: =STDEV(D9:D32) -> 8.1191866 | E37: =STDEV(E9:E32) -> 1.0207662 | F37: =STDEV(F9:F32) -> 98.094694 | G37: =STDEV(G9:G32) -> 15.134547 | H37: =STDEV(H9:H32) -> 2.0159645 | I37: =STDEV(I9:I32) -> 0.6730623 | ... Q37: =STDEV(Q9:Q32) -> 0.12127269
A38: Num | B38: =COUNT(B9:B32) -> 24 | C38: =COUNT(C9:C32) -> 24 | D38: =COUNT(D9:D32) -> 24 | E38: =COUNT(E9:E32) -> 24 | F38: =COUNT(F9:F32) -> 24 | G38: =COUNT(G9:G32) -> 24 | H38: =COUNT(H9:H32) -> 24 | I38: =COUNT(I9:I32) -> 24 | ... Q38: =COUNT(Q9:Q32) -> 24
A39: DCR | B39: =IF(B38>=22,">90%",IF(B38<=22,"<90%")) -> >90% | C39: =IF(C38>=22,">90%",IF(C38<=22,"<90%")) -> >90% | D39: =IF(D38>=22,">90%",IF(D38<=22,"<90%")) -> >90% | E39: =IF(E38>=22,">90%",IF(E38<=22,"<90%")) -> >90% | F39: =IF(F38>=22,">90%",IF(F38<=22,"<90%")) -> >90% | G39: =IF(G38>=22,">90%",IF(G38<=22,"<90%")) -> >90% | H39: =IF(H38>=22,">90%",IF(H38<=22,"<90%")) -> >90% | I39: =IF(I38>=22,">90%",IF(I38<=22,"<90%")) -> >90% | ... Q39: =IF(Q38>=22,">90%",IF(Q38<=22,"<90%")) -> >90%
A40: Status | B40: =IF(B38>=22,"OK",IF(B38<=22,"LESS")) -> OK | C40: =IF(C38>=22,"OK",IF(C38<=22,"LESS")) -> OK | D40: =IF(D38>=22,"OK",IF(D38<=22,"LESS")) -> OK | E40: =IF(E38>=22,"OK",IF(E38<=22,"LESS")) -> OK | F40: =IF(F38>=22,"OK",IF(F38<=22,"LESS")) -> OK | G40: =IF(G38>=22,"OK",IF(G38<=22,"LESS")) -> OK | H40: =IF(H38>=22,"OK",IF(H38<=22,"LESS")) -> OK | I40: =IF(I38>=22,"OK",IF(I38<=22,"LESS")) -> OK | ... Q40: =IF(Q38>=22,"OK",IF(Q38<=22,"LESS")) -> OK
A43: Done by | B43: RAHUL
A45: Comment

Sheet 02
A1: Station: | B1: BHATAGAON RAIPUR
A2: Date: | B2: =$A$9 -> 02/10/2025 01:00 | D2: Power Off | G2: Pw.Off | L2: Link Fail | N2: Link F | P2: Maintenance | R2: Maint.
A3: Report Type: | B3: Mean | D3: Calibration | G3: Calib. | L3: Data Fail | N3: Data F | P3: Invalid | R3: Invalid
A4: Time Base: | B4: 01 Hour | D4: Zero Referrence | G4: Z.Ref | L4: Warm Up | N4: Wm. Up
A7: Date & Time | B7: NO_BHATAGAON | C7: NO2__BHATAGAON | D7: NOX_BHATAGAON | E7: SO2__BHATAGAON | F7: O3__BHATAGAON | G7: PM10__BHATAGAON | H7: PM2_5__BHATAGAON | I7: BENZ__BHATAGAON | J7: WS__BHATAGAON | K7: WD__BHATAGAON | L7: TEMP__BHATAGAON | M7: HUM__BHATAGAON | N7: SR__BHATAGAON | O7: RG__BHATAGAON | P7: CO__BHATAGAON | Q7: NH3__BHATAGAON
B8: ug/m3 | C8: ug/m3 | D8: ppb | E8: ug/m3 | F8: ug/m3 | G8: mg/m3 | H8: ug/m3 | I8: ug/m3 | J8: m/sec | K8: deg | L8: degreC | M8: % | N8: w/m2 | O8: mm | P8: ug/m3 | Q8: ug/m3
A9: 02/10/2025 01:00 | B9: 20.95 | C9: 19.64 | D9: 22.91 | E9: 4.64 | F9: 11.56 | G9: 71.24 | H9: 11.11 | I9: 2.98 | J9: 0.48 | K9: 339.47 | L9: 23.26 | M9: 98.14 | N9: 49.3 | O9: 0 | P9: 1.04 | Q9: 9.51
A10: 02/10/2025 02:00 | B10: 18.27 | C10: 14.38 | D10: 20.79 | E10: 4.52 | F10: 7.54 | G10: 75.03 | H10: 9.21 | I10: 3.05 | J10: 0.46 | K10: 346.51 | L10: 22.98 | M10: 98.15 | N10: 49.5 | O10: 0 | P10: 0.76 | Q10: 9.52
A11: 02/10/2025 03:00 | B11: 20.39 | C11: 13.7 | D11: 20.09 | E11: 4.51 | F11: 6.6 | G11: 78.61 | H11: 7.6 | I11: 3.03 | J11: 0.24 | K11: 357.04 | L11: 22.68 | M11: 98.24 | N11: 49.7 | O11: 0 | P11: 0.82 | Q11: 9.49
A12: 02/10/2025 04:00 | B12: 20.17 | C12: 9.34 | D12: 19.19 | E12: 4.24 | F12: 9.61 | G12: 78.27 | H12: 12.08 | I12: 2.96 | J12: 0.53 | K12: 342.84 | L12: 22.75 | M12: 98.28 | N12: 49.9 | O12: 0 | P12: 0.81 | Q12: 9.44
A13: 02/10/2025 05:00 | B13: 20.99 | C13: 11.75 | D13: 21.76 | E13: 3.98 | F13: 7.18 | G13: 81.23 | H13: 10.71 | I13: 2.93 | J13: 0.2 | K13: 346.42 | L13: 22.65 | M13: 98.48 | N13: 50.1 | O13: 0 | P13: 0.66 | Q13: 9.39
A14: 02/10/2025 06:00 | B14: 21.9 | C14: 10.36 | D14: 21.73 | E14: 4.25 | F14: 9.31 | G14: 80.7 | H14: 8.65 | I14: 2.85 | J14: 0.12 | K14: 359.69 | L14: 22.52 | M14: 98.48 | N14: 52.8 | O14: 0 | P14: 0.7 | Q14: 9.42
A15: 02/10/2025 07:00 | B15: 26.36 | C15: 10.7 | D15: 26.63 | E15: 4.29 | F15: 7.89 | G15: 76.96 | H15: 7.21 | I15: 2.67 | J15: 0.69 | K15: 339.79 | L15: 23.86 | M15: 98.4 | N15: 146.6 | O15: 0 | P15: 0.69 | Q15: 9.43
A16: 02/10/2025 08:00 | B16: 23.75 | C16: 10.21 | D16: 24.36 | E16: 4.74 | F16: 10.39 | G16: 72.24 | H16: 11.3 | I16: 2.61 | J16: 1.18 | K16: 338.96 | L16: 25.08 | M16: 98.32 | N16: 173.8 | O16: 0 | P16: 0.75 | Q16: 9.4
A17: 02/10/2025 09:00 | B17: 24.64 | C17: 12.66 | D17: 24.76 | E17: 4.94 | F17: 10.74 | G17: 79.65 | H17: 10 | I17: 2.43 | J17: 0.7 | K17: 339.74 | L17: 26.71 | M17: 98.35 | N17: 391.9 | O17: 0 | P17: 0.72 | Q17: 9.42
A18: 02/10/2025 10:00 | B18: 23.8 | C18: 13.19 | D18: 25.98 | E18: 6.16 | F18: 9.27 | G18: 85.87 | H18: 8.15 | I18: 2.37 | J18: 1.27 | K18: 339.15 | L18: 29.75 | M18: 91.94 | N18: 541 | O18: 0 | P18: 0.66 | Q18: 9.46
A19: 02/10/2025 11:00 | B19: 26.09 | C19: 11.69 | D19: 26.43 | E19: 8.49 | F19: 9.86 | G19: 79.19 | H19: 6.86 | I19: 2.19 | J19: 1.26 | K19: 338.99 | L19: 30.92 | M19: 79.95 | N19: 633.2 | O19: 0 | P19: 0.56 | Q19: 9.48
A20: 02/10/2025 12:00 | B20: 22.26 | C20: 12.41 | D20: 24.34 | E20: 10.91 | F20: 24.64 | G20: 69.89 | H20: 6.54 | I20: 2.01 | J20: 1.57 | K20: 337.74 | L20: 31.02 | M20: 80.15 | N20: 454.1 | O20: 0 | P20: 0.58 | Q20: 9.47
... A32: 02/10/2025 24:00 | B32: 14.4 | C32: 8.42 | D32: 15.78 | E32: 5.95 | F32: 10.99 | G32: 44.61 | H32: 9.06 | I32: 2.24 | J32: 0.41 | K32: 333 | L32: 22.78 | M32: 99.06 | N32: 60.4 | O32: 0 | P32: 0.67 | Q32: 9.34
A34: Min | B34: =MIN(B9:B32) -> 13.18 | C34: =MIN(C9:C32) -> 8.42 | D34: =MIN(D9:D32) -> 15.78 | E34: =MIN(E9:E32) -> 3.98 | F34: =MIN(F9:F32) -> 6.6 | G34: =MIN(G9:G32) -> 44.61 | H34: =MIN(H9:H32) -> 6.12 | I34: =MIN(I9:I32) -> 1.56 | ... Q34: =MIN(Q9:Q32) -> 9.17
A35: Max | B35: =MAX(B9:B32) -> 31.63 | C35: =MAX(C9:C32) -> 22.45 | D35: =MAX(D9:D32) -> 28.91 | E35: =MAX(E9:E32) -> 10.91 | F35: =MAX(F9:F32) -> 650.69 | G35: =MAX(G9:G32) -> 85.87 | H35: =MAX(H9:H32) -> 12.08 | I35: =MAX(I9:I32) -> 3.05 | ... Q35: =MAX(Q9:Q32) -> 9.52
A36: Avg | B36: =AVERAGE(B9:B32) -> 20.600417 | C36: =AVERAGE(C9:C32) -> 13.290417 | D36: =AVERAGE(D9:D32) -> 22.479583 | E36: =AVERAGE(E9:E32) -> 6.30875 | F36: =AVERAGE(F9:F32) -> 61.305 | G36: =AVERAGE(G9:G32) -> 71.351667 | H36: =AVERAGE(H9:H32) -> 8.65 | I36: =AVERAGE(I9:I32) -> 2.30875 | ... Q36: =AVERAGE(Q9:Q32) -> 9.36875
A37: Stdev | B37: =STDEV(B9:B32) -> 4.2555483 | C37: =STDEV(C9:C32) -> 3.3196955 | D37: =STDEV(D9:D32) -> 3.4423153 | E37: =STDEV(E9:E32) -> 1.7961101 | F37: =STDEV(F9:F32) -> 170.81491 | G37: =STDEV(G9:G32) -> 9.0592728 | H37: =STDEV(H9:H32) -> 1.6272676 | I37: =STDEV(I9:I32) -> 0.50280355 | ... Q37: =STDEV(Q9:Q32) -> 0.10165211
A38: Num | B38: =COUNT(B9:B32) -> 24 | C38: =COUNT(C9:C32) -> 24 | D38: =COUNT(D9:D32) -> 24 | E38: =COUNT(E9:E32) -> 24 | F38: =COUNT(F9:F32) -> 24 | G38: =COUNT(G9:G32) -> 24 | H38: =COUNT(H9:H32) -> 24 | I38: =COUNT(I9:I32) -> 24 | ... Q38: =COUNT(Q9:Q32) -> 24
A39: DCR | B39: =IF(B38>=22,">90%",IF(B38<=22,"<90%")) -> >90% | C39: =IF(C38>=22,">90%",IF(C38<=22,"<90%")) -> >90% | D39: =IF(D38>=22,">90%",IF(D38<=22,"<90%")) -> >90% | E39: =IF(E38>=22,">90%",IF(E38<=22,"<90%")) -> >90% | F39: =IF(F38>=22,">90%",IF(F38<=22,"<90%")) -> >90% | G39: =IF(G38>=22,">90%",IF(G38<=22,"<90%")) -> >90% | H39: =IF(H38>=22,">90%",IF(H38<=22,"<90%")) -> >90% | I39: =IF(I38>=22,">90%",IF(I38<=22,"<90%")) -> >90% | ... Q39: =IF(Q38>=22,">90%",IF(Q38<=22,"<90%")) -> >90%
A40: Status | B40: =IF(B38>=22,"OK",IF(B38<=22,"LESS")) -> OK | C40: =IF(C38>=22,"OK",IF(C38<=22,"LESS")) -> OK | D40: =IF(D38>=22,"OK",IF(D38<=22,"LESS")) -> OK | E40: =IF(E38>=22,"OK",IF(E38<=22,"LESS")) -> OK | F40: =IF(F38>=22,"OK",IF(F38<=22,"LESS")) -> OK | G40: =IF(G38>=22,"OK",IF(G38<=22,"LESS")) -> OK | H40: =IF(H38>=22,"OK",IF(H38<=22,"LESS")) -> OK | I40: =IF(I38>=22,"OK",IF(I38<=22,"LESS")) -> OK | ... Q40: =IF(Q38>=22,"OK",IF(Q38<=22,"LESS")) -> OK
A43: Done by | B43: RAHUL
A45: Comment

Sheet 03
A1: Station: | B1: BHATAGAON RAIPUR
A2: Date: | B2: =$A$9 -> 03/10/2025 01:00 | D2: Power Off | G2: Pw.Off | L2: Link Fail | N2: Link F | P2: Maintenance | R2: Maint.
A3: Report Type: | B3: Mean | D3: Calibration | G3: Calib. | L3: Data Fail | N3: Data F | P3: Invalid | R3: Invalid
A4: Time Base: | B4: 01 Hour | D4: Zero Referrence | G4: Z.Ref | L4: Warm Up | N4: Wm. Up
A7: Date & Time | B7: NO_BHATAGAON | C7: NO2__BHATAGAON | D7: NOX_BHATAGAON | E7: SO2__BHATAGAON | F7: O3__BHATAGAON | G7: PM10__BHATAGAON | H7: PM2_5__BHATAGAON | I7: BENZ__BHATAGAON | J7: WS__BHATAGAON | K7: WD__BHATAGAON | L7: TEMP__BHATAGAON | M7: HUM__BHATAGAON | N7: SR__BHATAGAON | O7: RG__BHATAGAON | P7: CO__BHATAGAON | Q7: NH3__BHATAGAON
B8: ug/m3 | C8: ug/m3 | D8: ppb | E8: ug/m3 | F8: ug/m3 | G8: mg/m3 | H8: ug/m3 | I8: ug/m3 | J8: m/sec | K8: deg | L8: degreC | M8: % | N8: w/m2 | O8: mm | P8: ug/m3 | Q8: ug/m3
A9: 03/10/2025 01:00 | B9: 14.85 | C9: 8.89 | D9: 16.56 | E9: 5.5 | F9: 9.95 | G9: 37.7 | H9: 7.5 | I9: 2.12 | J9: 0.77 | K9: 339.96 | L9: 22.75 | M9: 98.65 | N9: 60.7 | O9: 0 | P9: 0.65 | Q9: 9.33
A10: 03/10/2025 02:00 | B10: 12.82 | C10: 10.74 | D10: 14.88 | E10: 5.49 | F10: 8.87 | G10: 33.64 | H10: 6.4 | I10: 1.96 | J10: 1.2 | K10: 339.01 | L10: 22.55 | M10: 98.65 | N10: 61.9 | O10: 0.4 | P10: 0.63 | Q10: 9.26
A11: 03/10/2025 03:00 | B11: 12.27 | C11: 7.61 | D11: 13.63 | E11: 5.32 | F11: 9.83 | G11: 22.16 | H11: 5.69 | I11: 1.83 | J11: 1.37 | K11: 337.76 | L11: 22.37 | M11: 98.56 | N11: 62.9 | O11: 0.4 | P11: 0.59 | Q11: 9.2
A12: 03/10/2025 04:00 | B12: 11.2 | C12: 8.71 | D12: 12.72 | E12: 5.34 | F12: 9.5 | G12: 817.9 | H12: 10.02 | I12: 1.64 | J12: 1.29 | K12: 338.4 | L12: 22.21 | M12: 98.57 | N12: 62.8 | O12: 0 | P12: 0.53 | Q12: 9.18
A13: 03/10/2025 05:00 | B13: 10.82 | C13: 7.61 | D13: 12.65 | E13: 5.52 | F13: 8.96 | G13: 71.39 | H13: 8.17 | I13: 1.6 | J13: 1.21 | K13: 338.32 | L13: 22.13 | M13: 98.55 | N13: 62.7 | O13: 0 | P13: 0.46 | Q13: 9.17
A14: 03/10/2025 06:00 | B14: 10.69 | C14: 6.84 | D14: 12 | E14: 5.2 | F14: 9.17 | G14: 30.47 | H14: 6.87 | I14: 1.52 | J14: 1.31 | K14: 339.19 | L14: 22.33 | M14: 98.5 | N14: 64.1 | O14: 0 | P14: 0.41 | Q14: 9.17
A15: 03/10/2025 07:00 | B15: 12.8 | C15: 8.64 | D15: 14.56 | E15: 5.33 | F15: 8.64 | G15: 38.27 | H15: 5.97 | I15: 1.46 | J15: 1 | K15: 339.09 | L15: 22.66 | M15: 98.51 | N15: 90.6 | O15: 0 | P15: 0.42 | Q15: 9.13
A16: 03/10/2025 08:00 | B16: 14.77 | C16: 8.15 | D16: 16.1 | E16: 5.4 | F16: 8.38 | G16: 36.22 | H16: 10.66 | I16: 1.51 | J16: 0.78 | K16: 337.51 | L16: 22.78 | M16: 98.45 | N16: 92.3 | O16: 0 | P16: 0.47 | Q16: 9.18
A17: 03/10/2025 09:00 | B17: 14.71 | C17: 7.03 | D17: 15.2 | E17: 4.76 | F17: 8.09 | G17: 45.78 | H17: 8.62 | I17: 1.5 | J17: 1.19 | K17: 336.76 | L17: 23.47 | M17: 98.42 | N17: 178.3 | O17: 0 | P17: 0.48 | Q17: 9.24
A18: 03/10/2025 10:00 | B18: 15.22 | C18: 8.54 | D18: 16.46 | E18: 5.13 | F18: 8.2 | G18: 28.08 | H18: 7.19 | I18: 1.49 | J18: 1.14 | K18: 335.54 | L18: 23.68 | M18: 98.46 | N18: 163.4 | O18: 0 | P18: 0.54 | Q18: 9.25
A19: 03/10/2025 11:00 | B19: 19 | C19: 9.57 | D19: 20.22 | E19: 4.86 | F19: 16.11 | G19: 27.97 | H19: 6.19 | I19: 1.56 | J19: 0.98 | K19: 342.89 | L19: 24.55 | M19: 98.1 | N19: 297.9 | O19: 0 | P19: 0.74 | Q19: 9.23
A20: 03/10/2025 12:00 | B20: 23.21 | C20: 9.37 | D20: 23.35 | E20: 4.81 | F20: 9.7 | G20: 12.62 | H20: 12.21 | I20: 1.65 | J20: 1.33 | K20: 336.86 | L20: 27.55 | M20: 97.98 | N20: 447 | O20: 0 | P20: 0.74 | Q20: 9.27
... A32: 03/10/2025 24:00 | B32: 12.22 | C32: 8.23 | D32: 13.21 | E32: 5.47 | F32: 10.48 | G32: 10.27 | H32: 11.17 | I32: 1.64 | J32: 0.29 | K32: 283.53 | L32: 23.23 | M32: 98.15 | N32: 44.1 | O32: 0 | P32: 0.53 | Q32: 9.18
A34: Min | B34: =MIN(B9:B32) -> 10.06 | C34: =MIN(C9:C32) -> 6.84 | D34: =MIN(D9:D32) -> 12 | E34: =MIN(E9:E32) -> 4.76 | F34: =MIN(F9:F32) -> 7.92 | G34: =MIN(G9:G32) -> 4.01 | H34: =MIN(H9:H32) -> 5.69 | I34: =MIN(I9:I32) -> 1.09 | ... Q34: =MIN(Q9:Q32) -> 9.08
A35: Max | B35: =MAX(B9:B32) -> 23.21 | C35: =MAX(C9:C32) -> 19.59 | D35: =MAX(D9:D32) -> 24.64 | E35: =MAX(E9:E32) -> 5.55 | F35: =MAX(F9:F32) -> 395.77 | G35: =MAX(G9:G32) -> 817.9 | H35: =MAX(H9:H32) -> 12.91 | I35: =MAX(I9:I32) -> 2.12 | ... Q35: =MAX(Q9:Q32) -> 9.33
A36: Avg | B36: =AVERAGE(B9:B32) -> 14.025833 | C36: =AVERAGE(C9:C32) -> 10.819583 | D36: =AVERAGE(D9:D32) -> 16.51875 | E36: =AVERAGE(E9:E32) -> 5.22375 | F36: =AVERAGE(F9:F32) -> 37.699583 | G36: =AVERAGE(G9:G32) -> 61.881667 | H36: =AVERAGE(H9:H32) -> 8.2404167 | I36: =AVERAGE(I9:I32) -> 1.5270833 | ... Q36: =AVERAGE(Q9:Q32) -> 9.1908333
A37: Stdev | B37: =STDEV(B9:B32) -> 3.5688896 | C37: =STDEV(C9:C32) -> 3.7402656 | D37: =STDEV(D9:D32) -> 3.3057188 | E37: =STDEV(E9:E32) -> 0.26106492 | F37: =STDEV(F9:F32) -> 94.347392 | G37: =STDEV(G9:G32) -> 161.80483 | H37: =STDEV(H9:H32) -> 2.0731335 | I37: =STDEV(I9:I32) -> 0.23294857 | ... Q37: =STDEV(Q9:Q32) -> 0.065336365
A38: Num | B38: =COUNT(B9:B32) -> 24 | C38: =COUNT(C9:C32) -> 24 | D38: =COUNT(D9:D32) -> 24 | E38: =COUNT(E9:E32) -> 24 | F38: =COUNT(F9:F32) -> 24 | G38: =COUNT(G9:G32) -> 24 | H38: =COUNT(H9:H32) -> 24 | I38: =COUNT(I9:I32) -> 24 | ... Q38: =COUNT(Q9:Q32) -> 24
A39: DCR | B39: =IF(B38>=22,">90%",IF(B38<=22,"<90%")) -> >90% | C39: =IF(C38>=22,">90%",IF(C38<=22,"<90%")) -> >90% | D39: =IF(D38>=22,">90%",IF(D38<=22,"<90%")) -> >90% | E39: =IF(E38>=22,">90%",IF(E38<=22,"<90%")) -> >90% | F39: =IF(F38>=22,">90%",IF(F38<=22,"<90%")) -> >90% | G39: =IF(G38>=22,">90%",IF(G38<=22,"<90%")) -> >90% | H39: =IF(H38>=22,">90%",IF(H38<=22,"<90%")) -> >90% | I39: =IF(I38>=22,">90%",IF(I38<=22,"<90%")) -> >90% | ... Q39: =IF(Q38>=22,">90%",IF(Q38<=22,"<90%")) -> >90%
A40: Status | B40: =IF(B38>=22,"OK",IF(B38<=22,"LESS")) -> OK | C40: =IF(C38>=22,"OK",IF(C38<=22,"LESS")) -> OK | D40: =IF(D38>=22,"OK",IF(D38<=22,"LESS")) -> OK | E40: =IF(E38>=22,"OK",IF(E38<=22,"LESS")) -> OK | F40: =IF(F38>=22,"OK",IF(F38<=22,"LESS")) -> OK | G40: =IF(G38>=22,"OK",IF(G38<=22,"LESS")) -> OK | H40: =IF(H38>=22,"OK",IF(H38<=22,"LESS")) -> OK | I40: =IF(I38>=22,"OK",IF(I38<=22,"LESS")) -> OK | ... Q40: =IF(Q38>=22,"OK",IF(Q38<=22,"LESS")) -> OK
A43: Done by | B43: RAHUL
A45: Comment

Sheet 04
A1: Station: | B1: BHATAGAON RAIPUR
A2: Date: | B2: =$A$9 -> 04/10/2025 01:00 | D2: Power Off | G2: Pw.Off | L2: Link Fail | N2: Link F | P2: Maintenance | R2: Maint.
A3: Report Type: | B3: Mean | D3: Calibration | G3: Calib. | L3: Data Fail | N3: Data F | P3: Invalid | R3: Invalid
A4: Time Base: | B4: 01 Hour | D4: Zero Referrence | G4: Z.Ref | L4: Warm Up | N4: Wm. Up
A7: Date & Time | B7: NO_BHATAGAON | C7: NO2__BHATAGAON | D7: NOX_BHATAGAON | E7: SO2__BHATAGAON | F7: O3__BHATAGAON | G7: PM10__BHATAGAON | H7: PM2_5__BHATAGAON | I7: BENZ__BHATAGAON | J7: WS__BHATAGAON | K7: WD__BHATAGAON | L7: TEMP__BHATAGAON | M7: HUM__BHATAGAON | N7: SR__BHATAGAON | O7: RG__BHATAGAON | P7: CO__BHATAGAON | Q7: NH3__BHATAGAON
B8: ug/m3 | C8: ug/m3 | D8: ppb | E8: ug/m3 | F8: ug/m3 | G8: mg/m3 | H8: ug/m3 | I8: ug/m3 | J8: m/sec | K8: deg | L8: degreC | M8: % | N8: w/m2 | O8: mm | P8: ug/m3 | Q8: ug/m3
A9: 04/10/2025 01:00 | B9: 11.6 | C9: 5.74 | D9: 12.02 | E9: 4.92 | F9: 9.13 | G9: 13.43 | H9: 10.04 | I9: 1.52 | J9: 0.12 | K9: 310.8 | L9: 23.39 | M9: 98.15 | N9: 44.5 | O9: 0 | P9: 0.48 | Q9: 9.15
A10: 04/10/2025 02:00 | B10: 10.55 | C10: 6.4 | D10: 11.42 | E10: 4.78 | F10: 11.24 | G10: 15.52 | H10: 8.77 | I10: 1.37 | J10: 0.15 | K10: 301.52 | L10: 23.33 | M10: 98.15 | N10: 44.5 | O10: 0 | P10: 0.44 | Q10: 9.1
A11: 04/10/2025 03:00 | B11: 9.05 | C11: 6.41 | D11: 10.56 | E11: 5.03 | F11: 12.62 | G11: 11.01 | H11: 7.3 | I11: 1.31 | J11: 0.15 | K11: 297.25 | L11: 22.94 | M11: 98.15 | N11: 44.6 | O11: 0 | P11: 0.4 | Q11: 9.09
A12: 04/10/2025 04:00 | B12: 7.97 | C12: 6.4 | D12: 9.71 | E12: 4.95 | F12: 8.78 | G12: 5.3 | H12: 7.63 | I12: 1.35 | J12: 0.13 | K12: 300.7 | L12: 22.67 | M12: 98.17 | N12: 44.5 | O12: 0 | P12: 0.33 | Q12: 9.07
A13: 04/10/2025 05:00 | B13: 7.98 | C13: 6.44 | D13: 9.77 | E13: 4.84 | F13: 21.43 | G13: 2.53 | H13: 6.49 | I13: 1.28 | J13: 0.12 | K13: 314.84 | L13: 22.61 | M13: 98.19 | N13: 44.5 | O13: 0 | P13: 0.33 | Q13: 9.04
A14: 04/10/2025 06:00 | B14: 7.86 | C14: 6.41 | D14: 9.55 | E14: 4.78 | F14: 8.73 | G14: 6.12 | H14: 5.75 | I14: 1.17 | J14: 0.14 | K14: 308.48 | L14: 22.65 | M14: 98.23 | N14: 47.6 | O14: 0 | P14: 0.29 | Q14: 9.02
A15: 04/10/2025 07:00 | B15: 7.77 | C15: 7.22 | D15: 9.99 | E15: 4.72 | F15: 8.13 | G15: 11.03 | H15: 5.26 | I15: 1.07 | J15: 0.16 | K15: 295.16 | L15: 22.84 | M15: 98.22 | N15: 75.9 | O15: 0 | P15: 0.27 | Q15: 9.04
A16: 04/10/2025 08:00 | B16: 8.6 | C16: 7.69 | D16: 10.91 | E16: 4.57 | F16: 8.15 | G16: 12.75 | H16: 7.39 | I16: 1.09 | J16: 0.18 | K16: 304.65 | L16: 23.84 | M16: 98.2 | N16: 161.7 | O16: 0 | P16: 0.36 | Q16: 9.06
A17: 04/10/2025 09:00 | B17: 8.75 | C17: 7.39 | D17: 10.8 | E17: 3.47 | F17: 10.06 | G17: 18.25 | H17: 6.61 | I17: 1.36 | J17: 0.19 | K17: 297.3 | L17: 26.23 | M17: 98.1 | N17: 359.5 | O17: 0 | P17: 0.4 | Q17: 9.06
A18: 04/10/2025 10:00 | B18: 10.15 | C18: 7.62 | D18: 12.1 | E18: 3.35 | F18: 9.25 | G18: 23.92 | H18: 6.06 | I18: 1.67 | J18: 0.24 | K18: 293.89 | L18: 29.08 | M18: 97.98 | N18: 785.5 | O18: 0 | P18: 0.46 | Q18: 9.05
A19: 04/10/2025 11:00 | B19: 9.89 | C19: 10.55 | D19: 13.28 | E19: 3.62 | F19: 9.09 | G19: 34.3 | H19: 5.91 | I19: 1.85 | J19: 0.43 | K19: 311.37 | L19: 30.12 | M19: 92.53 | N19: 617.6 | O19: 0 | P19: 0.53 | Q19: 9.06
A20: 04/10/2025 12:00 | B20: 9.72 | C20: 10.47 | D20: 13.27 | E20: 3.49 | F20: 9.09 | G20: 28.26 | H20: 7.13 | I20: 1.85 | J20: 0.32 | K20: 298.98 | L20: 29.05 | M20: 97.47 | N20: 501.4 | O20: 0 | P20: 0.56 | Q20: 9.08
... A32: 04/10/2025 24:00 | B32: 9.26 | C32: 7.47 | D32: 11.01 | E32: 4.45 | F32: 39.21 | G32: 24.61 | H32: 11.1 | I32: 1.35 | J32: 0.15 | K32: 173.85 | L32: 23.2 | M32: 98.13 | N32: 40.4 | O32: 0 | P32: 0.35 | Q32: 9.11
A34: Min | B34: =MIN(B9:B32) -> 7.77 | C34: =MIN(C9:C32) -> 5.74 | D34: =MIN(D9:D32) -> 9.55 | E34: =MIN(E9:E32) -> 3.35 | F34: =MIN(F9:F32) -> 8.13 | G34: =MIN(G9:G32) -> 2.53 | H34: =MIN(H9:H32) -> 5.26 | I34: =MIN(I9:I32) -> 1.07 | ... Q34: =MIN(Q9:Q32) -> 9.02
A35: Max | B35: =MAX(B9:B32) -> 14.65 | C35: =MAX(C9:C32) -> 15.02 | D35: =MAX(D9:D32) -> 18.28 | E35: =MAX(E9:E32) -> 5.13 | F35: =MAX(F9:F32) -> 39.21 | G35: =MAX(G9:G32) -> 36.73 | H35: =MAX(H9:H32) -> 11.31 | I35: =MAX(I9:I32) -> 1.86 | ... Q35: =MAX(Q9:Q32) -> 9.15
A36: Avg | B36: =AVERAGE(B9:B32) -> 10.289167 | C36: =AVERAGE(C9:C32) -> 9.255 | D36: =AVERAGE(D9:D32) -> 12.842083 | E36: =AVERAGE(E9:E32) -> 4.4204167 | F36: =AVERAGE(F9:F32) -> 11.8 | G36: =AVERAGE(G9:G32) -> 22.274167 | H36: =AVERAGE(H9:H32) -> 7.3608333 | I36: =AVERAGE(I9:I32) -> 1.4941667 | ... Q36: =AVERAGE(Q9:Q32) -> 9.08375
A37: Stdev | B37: =STDEV(B9:B32) -> 1.9350742 | C37: =STDEV(C9:C32) -> 2.6934349 | D37: =STDEV(D9:D32) -> 2.491256 | E37: =STDEV(E9:E32) -> 0.61317761 | F37: =STDEV(F9:F32) -> 6.4572864 | G37: =STDEV(G9:G32) -> 10.316115 | H37: =STDEV(H9:H32) -> 1.6636077 | I37: =STDEV(I9:I32) -> 0.22852869 | ... Q37: =STDEV(Q9:Q32) -> 0.037971671
A38: Num | B38: =COUNT(B9:B32) -> 24 | C38: =COUNT(C9:C32) -> 24 | D38: =COUNT(D9:D32) -> 24 | E38: =COUNT(E9:E32) -> 24 | F38: =COUNT(F9:F32) -> 24 | G38: =COUNT(G9:G32) -> 24 | H38: =COUNT(H9:H32) -> 24 | I38: =COUNT(I9:I32) -> 24 | ... Q38: =COUNT(Q9:Q32) -> 24
A39: DCR | B39: =IF(B38>=22,">90%",IF(B38<=22,"<90%")) -> >90% | C39: =IF(C38>=22,">90%",IF(C38<=22,"<90%")) -> >90% | D39: =IF(D38>=22,">90%",IF(D38<=22,"<90%")) -> >90% | E39: =IF(E38>=22,">90%",IF(E38<=22,"<90%")) -> >90% | F39: =IF(F38>=22,">90%",IF(F38<=22,"<90%")) -> >90% | G39: =IF(G38>=22,">90%",IF(G38<=22,"<90%")) -> >90% | H39: =IF(H38>=22,">90%",IF(H38<=22,"<90%")) -> >90% | I39: =IF(I38>=22,">90%",IF(I38<=22,"<90%")) -> >90% | ... Q39: =IF(Q38>=22,">90%",IF(Q38<=22,"<90%")) -> >90%
A40: Status | B40: =IF(B38>=22,"OK",IF(B38<=22,"LESS")) -> OK | C40: =IF(C38>=22,"OK",IF(C38<=22,"LESS")) -> OK | D40: =IF(D38>=22,"OK",IF(D38<=22,"LESS")) -> OK | E40: =IF(E38>=22,"OK",IF(E38<=22,"LESS")) -> OK | F40: =IF(F38>=22,"OK",IF(F38<=22,"LESS")) -> OK | G40: =IF(G38>=22,"OK",IF(G38<=22,"LESS")) -> OK | H40: =IF(H38>=22,"OK",IF(H38<=22,"LESS")) -> OK | I40: =IF(I38>=22,"OK",IF(I38<=22,"LESS")) -> OK | ... Q40: =IF(Q38>=22,"OK",IF(Q38<=22,"LESS")) -> OK
A43: Done by | B43: RAHUL
A45: Comment

Sheet 05
A1: Station: | B1: BHATAGAON RAIPUR
A2: Date: | B2: =$A$9 -> 05/10/2025 01:00 | D2: Power Off | G2: Pw.Off | L2: Link Fail | N2: Link F | P2: Maintenance | R2: Maint.
A3: Report Type: | B3: Mean | D3: Calibration | G3: Calib. | L3: Data Fail | N3: Data F | P3: Invalid | R3: Invalid
A4: Time Base: | B4: 01 Hour | D4: Zero Referrence | G4: Z.Ref | L4: Warm Up | N4: Wm. Up
A7: Date & Time | B7: NO_BHATAGAON | C7: NO2__BHATAGAON | D7: NOX_BHATAGAON | E7: SO2__BHATAGAON | F7: O3__BHATAGAON | G7: PM10__BHATAGAON | H7: PM2_5__BHATAGAON | I7: BENZ__BHATAGAON | J7: WS__BHATAGAON | K7: WD__BHATAGAON | L7: TEMP__BHATAGAON | M7: HUM__BHATAGAON | N7: SR__BHATAGAON | O7: RG__BHATAGAON | P7: CO__BHATAGAON | Q7: NH3__BHATAGAON
B8: ug/m3 | C8: ug/m3 | D8: ppb | E8: ug/m3 | F8: ug/m3 | G8: mg/m3 | H8: ug/m3 | I8: ug/m3 | J8: m/sec | K8: deg | L8: degreC | M8: % | N8: w/m2 | O8: mm | P8: ug/m3 | Q8: ug/m3
A9: 05/10/2025 01:00 | B9: 8.26 | C9: 7.73 | D9: 10.52 | E9: 4.41 | F9: 10.98 | G9: 21.76 | H9: 9.01 | I9: 1.38 | J9: 0.19 | K9: 184.96 | L9: 22.86 | M9: 98.13 | N9: 40.4 | O9: 0 | P9: 0.29 | Q9: 9.14
A10: 05/10/2025 02:00 | B10: 9.35 | C10: 5.61 | D10: 10.13 | E10: 4.48 | F10: 12.21 | G10: 19.93 | H10: 7.46 | I10: 1.36 | J10: 0.08 | K10: 267.96 | L10: 22.66 | M10: 98.13 | N10: 40.4 | O10: 0 | P10: 0.29 | Q10: 9.13
A11: 05/10/2025 03:00 | B11: 9.07 | C11: 5.38 | D11: 10.04 | E11: 4.53 | F11: 9.51 | G11: 20.84 | H11: 6.38 | I11: 1.33 | J11: 0.12 | K11: 311.29 | L11: 22.67 | M11: 98.13 | N11: 40.4 | O11: 0 | P11: 0.29 | Q11: 9.09
A12: 05/10/2025 04:00 | B12: 9.31 | C12: 5.56 | D12: 10.18 | E12: 4.32 | F12: 10.02 | G12: 15.01 | H12: 10.95 | I12: 1.26 | J12: 0.1 | K12: 295.26 | L12: 22.64 | M12: 98.13 | N12: 40.4 | O12: 0 | P12: 0.28 | Q12: 9.07
A13: 05/10/2025 05:00 | B13: 8.94 | C13: 6.76 | D13: 10.49 | E13: 4.16 | F13: 11.63 | G13: 15.78 | H13: 8.82 | I13: 1.19 | J13: 0.11 | K13: 254.94 | L13: 22.5 | M13: 98.15 | N13: 40.4 | O13: 0 | P13: 0.24 | Q13: 9.08
A14: 05/10/2025 06:00 | B14: 10.81 | C14: 8.11 | D14: 12.91 | E14: 4.51 | F14: 12.24 | G14: 13.81 | H14: 7.33 | I14: 1.13 | J14: 0.1 | K14: 306.97 | L14: 22.72 | M14: 98.17 | N14: 42.4 | O14: 0 | P14: 0.27 | Q14: 9.11
A15: 05/10/2025 07:00 | B15: 11.8 | C15: 6.55 | D15: 12.89 | E15: 4.49 | F15: 11.93 | G15: 18.05 | H15: 6.28 | I15: 1.12 | J15: 0.12 | K15: 310.98 | L15: 23.21 | M15: 98.17 | N15: 73.4 | O15: 0 | P15: 0.29 | Q15: 9.11
A16: 05/10/2025 08:00 | B16: 11.65 | C16: 5.95 | D16: 12.45 | E16: 4.59 | F16: 9.94 | G16: 20.38 | H16: 10.72 | I16: 1.12 | J16: 0.14 | K16: 296.22 | L16: 25.28 | M16: 98 | N16: 257.7 | O16: 0 | P16: 0.38 | Q16: 9.09
A17: 05/10/2025 09:00 | B17: 12.38 | C17: 7.08 | D17: 13.62 | E17: 3.56 | F17: 9.54 | G17: 25.07 | H17: 8.66 | I17: 1.32 | J17: 0.19 | K17: 294.1 | L17: 26.5 | M17: 97.91 | N17: 289.6 | O17: 0 | P17: 0.48 | Q17: 9.11
A18: 05/10/2025 10:00 | B18: 11.55 | C18: 10.96 | D18: 14.52 | E18: 3.88 | F18: 10.12 | G18: 38.01 | H18: 7.22 | I18: 1.91 | J18: 0.17 | K18: 286.27 | L18: 28.21 | M18: 97.9 | N18: 467.8 | O18: 0 | P18: 0.61 | Q18: 9.14
A19: 05/10/2025 11:00 | B19: 12.25 | C19: 13.43 | D19: 16.4 | E19: 4.24 | F19: 11.98 | G19: 45.21 | H19: 6.21 | I19: 2.18 | J19: 0.21 | K19: 275.66 | L19: 28.6 | M19: 97.83 | N19: 457 | O19: 0 | P19: 0.63 | Q19: 9.13
A20: 05/10/2025 12:00 | B20: 16.84 | C20: 12.61 | D20: 20.08 | E20: 4.03 | F20: 14.42 | G20: 42.41 | H20: 10.34 | I20: 2.22 | J20: 0.61 | K20: 334.35 | L20: 28.35 | M20: 98.15 | N20: 685.2 | O20: 0.8 | P20: 0.66 | Q20: 9.1
... A32: 05/10/2025 24:00 | B32: 14.1 | C32: 5.62 | D32: 14.24 | E32: 5.03 | F32: 11.5 | G32: 24.66 | H32: 11.17 | I32: 1.87 | J32: 0.1 | K32: 331.62 | L32: 22.28 | M32: 98.12 | N32: 46.3 | O32: 0 | P32: 0.51 | Q32: 9.21
A34: Min | B34: =MIN(B9:B32) -> 8.26 | C34: =MIN(C9:C32) -> 5.38 | D34: =MIN(D9:D32) -> 10.04 | E34: =MIN(E9:E32) -> 3.56 | F34: =MIN(F9:F32) -> 9.51 | G34: =MIN(G9:G32) -> 13.81 | H34: =MIN(H9:H32) -> 6.21 | I34: =MIN(I9:I32) -> 1.12 | ... Q34: =MIN(Q9:Q32) -> 9.06
A35: Max | B35: =MAX(B9:B32) -> 23.88 | C35: =MAX(C9:C32) -> 17.84 | D35: =MAX(D9:D32) -> 23.88 | E35: =MAX(E9:E32) -> 5.43 | F35: =MAX(F9:F32) -> 16.19 | G35: =MAX(G9:G32) -> 45.21 | H35: =MAX(H9:H32) -> 12.71 | I35: =MAX(I9:I32) -> 2.22 | ... Q35: =MAX(Q9:Q32) -> 9.26
A36: Avg | B36: =AVERAGE(B9:B32) -> 12.895 | C36: =AVERAGE(C9:C32) -> 10.00875 | D36: =AVERAGE(D9:D32) -> 15.293333 | E36: =AVERAGE(E9:E32) -> 4.5583333 | F36: =AVERAGE(F9:F32) -> 11.734583 | G36: =AVERAGE(G9:G32) -> 26.012083 | H36: =AVERAGE(H9:H32) -> 8.99625 | I36: =AVERAGE(I9:I32) -> 1.6625 | ... Q36: =AVERAGE(Q9:Q32) -> 9.1245833
A37: Stdev | B37: =STDEV(B9:B32) -> 4.4205626 | C37: =STDEV(C9:C32) -> 3.851769 | D37: =STDEV(D9:D32) -> 4.2257715 | E37: =STDEV(E9:E32) -> 0.52157509 | F37: =STDEV(F9:F32) -> 2.0336367 | G37: =STDEV(G9:G32) -> 10.385586 | H37: =STDEV(H9:H32) -> 2.0181671 | I37: =STDEV(I9:I32) -> 0.36624119 | ... Q37: =STDEV(Q9:Q32) -> 0.057632959
A38: Num | B38: =COUNT(B9:B32) -> 24 | C38: =COUNT(C9:C32) -> 24 | D38: =COUNT(D9:D32) -> 24 | E38: =COUNT(E9:E32) -> 24 | F38: =COUNT(F9:F32) -> 24 | G38: =COUNT(G9:G32) -> 24 | H38: =COUNT(H9:H32) -> 24 | I38: =COUNT(I9:I32) -> 24 | ... Q38: =COUNT(Q9:Q32) -> 24
A39: DCR | B39: =IF(B38>=22,">90%",IF(B38<=22,"<90%")) -> >90% | C39: =IF(C38>=22,">90%",IF(C38<=22,"<90%")) -> >90% | D39: =IF(D38>=22,">90%",IF(D38<=22,"<90%")) -> >90% | E39: =IF(E38>=22,">90%",IF(E38<=22,"<90%")) -> >90% | F39: =IF(F38>=22,">90%",IF(F38<=22,"<90%")) -> >90% | G39: =IF(G38>=22,">90%",IF(G38<=22,"<90%")) -> >90% | H39: =IF(H38>=22,">90%",IF(H38<=22,"<90%")) -> >90% | I39: =IF(I38>=22,">90%",IF(I38<=22,"<90%")) -> >90% | ... Q39: =IF(Q38>=22,">90%",IF(Q38<=22,"<90%")) -> >90%
A40: Status | B40: =IF(B38>=22,"OK",IF(B38<=22,"LESS")) -> OK | C40: =IF(C38>=22,"OK",IF(C38<=22,"LESS")) -> OK | D40: =IF(D38>=22,"OK",IF(D38<=22,"LESS")) -> OK | E40: =IF(E38>=22,"OK",IF(E38<=22,"LESS")) -> OK | F40: =IF(F38>=22,"OK",IF(F38<=22,"LESS")) -> OK | G40: =IF(G38>=22,"OK",IF(G38<=22,"LESS")) -> OK | H40: =IF(H38>=22,"OK",IF(H38<=22,"LESS")) -> OK | I40: =IF(I38>=22,"OK",IF(I38<=22,"LESS")) -> OK | ... Q40: =IF(Q38>=22,"OK",IF(Q38<=22,"LESS")) -> OK
A43: Done by | B43: RAHUL
A45: Comment

Sheet 06
A1: Station: | B1: BHATAGAON RAIPUR
A2: Date: | B2: =$A$9 -> 06/10/2025 01:00 | D2: Power Off | G2: Pw.Off | L2: Link Fail | N2: Link F | P2: Maintenance | R2: Maint.
A3: Report Type: | B3: Mean | D3: Calibration | G3: Calib. | L3: Data Fail | N3: Data F | P3: Invalid | R3: Invalid
A4: Time Base: | B4: 01 Hour | D4: Zero Referrence | G4: Z.Ref | L4: Warm Up | N4: Wm. Up
A7: Date & Time | B7: NO_BHATAGAON | C7: NO2__BHATAGAON | D7: NOX_BHATAGAON | E7: SO2__BHATAGAON | F7: O3__BHATAGAON | G7: PM10__BHATAGAON | H7: PM2_5__BHATAGAON | I7: BENZ__BHATAGAON | J7: WS__BHATAGAON | K7: WD__BHATAGAON | L7: TEMP__BHATAGAON | M7: HUM__BHATAGAON | N7: SR__BHATAGAON | O7: RG__BHATAGAON | P7: CO__BHATAGAON | Q7: NH3__BHATAGAON
B8: ug/m3 | C8: ug/m3 | D8: ppb | E8: ug/m3 | F8: ug/m3 | G8: mg/m3 | H8: ug/m3 | I8: ug/m3 | J8: m/sec | K8: deg | L8: degreC | M8: % | N8: w/m2 | O8: mm | P8: ug/m3 | Q8: ug/m3
A9: 06/10/2025 01:00 | B9: 14.16 | C9: 7.29 | D9: 13.87 | E9: 4.33 | F9: 10.6 | G9: 20.29 | H9: 10.97 | I9: 1.74 | J9: 0.35 | K9: 326.72 | L9: 22.05 | M9: 98.17 | N9: 46.3 | O9: 0 | P9: 0.52 | Q9: 9.19
A10: 06/10/2025 02:00 | B10: 10.67 | C10: 7.88 | D10: 12.5 | E10: 4.18 | F10: 11.6 | G10: 15.47 | H10: 9.3 | I10: 1.63 | J10: 0.14 | K10: 208.84 | L10: 21.97 | M10: 98.18 | N10: 46.4 | O10: 0 | P10: 0.4 | Q10: 9.2
A11: 06/10/2025 03:00 | B11: 12.45 | C11: 5.02 | D11: 12.22 | E11: 4.36 | F11: 11 | G11: 11.61 | H11: 7.67 | I11: 1.59 | J11: 0.32 | K11: 144.31 | L11: 21.76 | M11: 98.2 | N11: 46.9 | O11: 0 | P11: 0.43 | Q11: 9.19
A12: 06/10/2025 04:00 | B12: 12.02 | C12: 4.8 | D12: 11.9 | E12: 4.27 | F12: 4.8 | G12: 8.17 | H12: 9.07 | I12: 1.53 | J12: 0.39 | K12: 130.04 | L12: 21.57 | M12: 98.2 | N12: 46.6 | O12: 0 | P12: 0.39 | Q12: 9.13
A13: 06/10/2025 05:00 | B13: 11.24 | C13: 5.37 | D13: 11.78 | E13: 4.21 | F13: 11.7 | G13: 5.72 | H13: 8.59 | I13: 1.45 | J13: 0.05 | K13: 247.21 | L13: 21.43 | M13: 98.18 | N13: 46.3 | O13: 0 | P13: 0.38 | Q13: 9.11
A14: 06/10/2025 06:00 | B14: 12.03 | C14: 7.26 | D14: 13.19 | E14: 4.34 | F14: 10.02 | G14: 6.18 | H14: 7.17 | I14: 1.42 | J14: 0.14 | K14: 293.53 | L14: 21.57 | M14: 98.23 | N14: 47.2 | O14: 0 | P14: 0.33 | Q14: 9.12
A15: 06/10/2025 07:00 | B15: 18.3 | C15: 7.78 | D15: 17.92 | E15: 4.44 | F15: 11.63 | G15: 7.47 | H15: 6.17 | I15: 1.35 | J15: 0.12 | K15: 326.88 | L15: 21.87 | M15: 98.24 | N15: 65.8 | O15: 0 | P15: 0.38 | Q15: 9.17
A16: 06/10/2025 08:00 | B16: 15.19 | C16: 6.09 | D16: 15.36 | E16: 4.69 | F16: 12.24 | G16: 5.54 | H16: 5.98 | I16: 1.35 | J16: 0.1 | K16: 326.42 | L16: 22.4 | M16: 98.22 | N16: 98.3 | O16: 0 | P16: 0.39 | Q16: 9.17
A17: 06/10/2025 09:00 | B17: 15.17 | C17: 7.18 | D17: 15.71 | E17: 4.8 | F17: 11.93 | G17: 8.62 | H17: 5.58 | I17: 1.38 | J17: 0.09 | K17: 299.06 | L17: 23.23 | M17: 98.21 | N17: 139.7 | O17: 0 | P17: 0.56 | Q17: 9.19
A18: 06/10/2025 10:00 | B18: 14.9 | C18: 7.37 | D18: 15.06 | E18: 4.54 | F18: 9.94 | G18: 21.06 | H18: 5.27 | I18: 1.85 | J18: 0.11 | K18: 278.12 | L18: 23.87 | M18: 98.2 | N18: 177.4 | O18: 0 | P18: 0.63 | Q18: 9.19
A19: 06/10/2025 11:00 | B19: 16.88 | C19: 9.9 | D19: 17.38 | E19: 4.99 | F19: 9.54 | G19: 35.61 | H19: 4.96 | I19: 2.53 | J19: 0.14 | K19: 278.83 | L19: 25.2 | M19: 98.17 | N19: 229.3 | O19: 0 | P19: 0.66 | Q19: 9.21
A20: 06/10/2025 12:00 | B20: 16.05 | C20: 9.59 | D20: 17.27 | E20: 4.72 | F20: 10.12 | G20: 37.57 | H20: 7.39 | I20: 2.53 | J20: 0.44 | K20: 313.71 | L20: 25.81 | M20: 98.07 | N20: 426.7 | O20: 0 | P20: 0.65 | Q20: 9.22
... A32: 06/10/2025 24:00 | B32: 21.49 | C32: 8.3 | D32: 20.55 | E32: 4.84 | F32: 11.8 | G32: 30.56 | H32: 7.63 | I32: 2.79 | J32: 0.2 | K32: 325.26 | L32: 21.68 | M32: 98.23 | N32: 44.1 | O32: 0 | P32: 0.95 | Q32: 9.35
A34: Min | B34: =MIN(B9:B32) -> 10.67 | C34: =MIN(C9:C32) -> 4.8 | D34: =MIN(D9:D32) -> 11.78 | E34: =MIN(E9:E32) -> 4.14 | F34: =MIN(F9:F32) -> 4.8 | G34: =MIN(G9:G32) -> 5.54 | H34: =MIN(H9:H32) -> 4.96 | I34: =MIN(I9:I32) -> 1.35 | ... Q34: =MIN(Q9:Q32) -> 9.08
A35: Max | B35: =MAX(B9:B32) -> 38.79 | C35: =MAX(C9:C32) -> 18.08 | D35: =MAX(D9:D32) -> 37.44 | E35: =MAX(E9:E32) -> 5.15 | F35: =MAX(F9:F32) -> 15.9 | G35: =MAX(G9:G32) -> 55.56 | H35: =MAX(H9:H32) -> 10.97 | I35: =MAX(I9:I32) -> 2.79 | ... Q35: =MAX(Q9:Q32) -> 9.35
A36: Avg | B36: =AVERAGE(B9:B32) -> 16.390417 | C36: =AVERAGE(C9:C32) -> 9.9025 | D36: =AVERAGE(D9:D32) -> 17.71375 | E36: =AVERAGE(E9:E32) -> 4.57125 | F36: =AVERAGE(F9:F32) -> 11.78 | G36: =AVERAGE(G9:G32) -> 26.969167 | H36: =AVERAGE(H9:H32) -> 7.4208333 | I36: =AVERAGE(I9:I32) -> 2.11375 | ... Q36: =AVERAGE(Q9:Q32) -> 9.1891667
A37: Stdev | B37: =STDEV(B9:B32) -> 6.1390797 | C37: =STDEV(C9:C32) -> 3.6910576 | D37: =STDEV(D9:D32) -> 5.4750984 | E37: =STDEV(E9:E32) -> 0.31519921 | F37: =STDEV(F9:F32) -> 2.1914319 | G37: =STDEV(G9:G32) -> 16.58709 | H37: =STDEV(H9:H32) -> 1.5183484 | I37: =STDEV(I9:I32) -> 0.52860614 | ... Q37: =STDEV(Q9:Q32) -> 0.064868876
A38: Num | B38: =COUNT(B9:B32) -> 24 | C38: =COUNT(C9:C32) -> 24 | D38: =COUNT(D9:D32) -> 24 | E38: =COUNT(E9:E32) -> 24 | F38: =COUNT(F9:F32) -> 24 | G38: =COUNT(G9:G32) -> 24 | H38: =COUNT(H9:H32) -> 24 | I38: =COUNT(I9:I32) -> 24 | ... Q38: =COUNT(Q9:Q32) -> 24
A39: DCR | B39: =IF(B38>=22,">90%",IF(B38<=22,"<90%")) -> >90% | C39: =IF(C38>=22,">90%",IF(C38<=22,"<90%")) -> >90% | D39: =IF(D38>=22,">90%",IF(D38<=22,"<90%")) -> >90% | E39: =IF(E38>=22,">90%",IF(E38<=22,"<90%")) -> >90% | F39: =IF(F38>=22,">90%",IF(F38<=22,"<90%")) -> >90% | G39: =IF(G38>=22,">90%",IF(G38<=22,"<90%")) -> >90% | H39: =IF(H38>=22,">90%",IF(H38<=22,"<90%")) -> >90% | I39: =IF(I38>=22,">90%",IF(I38<=22,"<90%")) -> >90% | ... Q39: =IF(Q38>=22,">90%",IF(Q38<=22,"<90%")) -> >90%
A40: Status | B40: =IF(B38>=22,"OK",IF(B38<=22,"LESS")) -> OK | C40: =IF(C38>=22,"OK",IF(C38<=22,"LESS")) -> OK | D40: =IF(D38>=22,"OK",IF(D38<=22,"LESS")) -> OK | E40: =IF(E38>=22,"OK",IF(E38<=22,"LESS")) -> OK | F40: =IF(F38>=22,"OK",IF(F38<=22,"LESS")) -> OK | G40: =IF(G38>=22,"OK",IF(G38<=22,"LESS")) -> OK | H40: =IF(H38>=22,"OK",IF(H38<=22,"LESS")) -> OK | I40: =IF(I38>=22,"OK",IF(I38<=22,"LESS")) -> OK | ... Q40: =IF(Q38>=22,"OK",IF(Q38<=22,"LESS")) -> OK
A43: Done by | B43: RAHUL
A45: Comment

Sheet 07
A1: Station: | B1: BHATAGAON RAIPUR
A2: Date: | B2: =$A$9 -> 07/10/2025 01:00 | D2: Power Off | G2: Pw.Off | L2: Link Fail | N2: Link F | P2: Maintenance | R2: Maint.
A3: Report Type: | B3: Mean | D3: Calibration | G3: Calib. | L3: Data Fail | N3: Data F | P3: Invalid | R3: Invalid
A4: Time Base: | B4: 01 Hour | D4: Zero Referrence | G4: Z.Ref | L4: Warm Up | N4: Wm. Up
A7: Date & Time | B7: NO_BHATAGAON | C7: NO2__BHATAGAON | D7: NOX_BHATAGAON | E7: SO2__BHATAGAON | F7: O3__BHATAGAON | G7: PM10__BHATAGAON | H7: PM2_5__BHATAGAON | I7: BENZ__BHATAGAON | J7: WS__BHATAGAON | K7: WD__BHATAGAON | L7: TEMP__BHATAGAON | M7: HUM__BHATAGAON | N7: SR__BHATAGAON | O7: RG__BHATAGAON | P7: CO__BHATAGAON | Q7: NH3__BHATAGAON
B8: ug/m3 | C8: ug/m3 | D8: ppb | E8: ug/m3 | F8: ug/m3 | G8: mg/m3 | H8: ug/m3 | I8: ug/m3 | J8: m/sec | K8: deg | L8: degreC | M8: % | N8: w/m2 | O8: mm | P8: ug/m3 | Q8: ug/m3
A9: 07/10/2025 01:00 | B9: 18.9 | C9: 5.9 | D9: 16.81 | E9: 5.36 | F9: 4.9 | G9: 27.1 | H9: 6.8 | I9: 2.86 | J9: 0.17 | K9: 331.06 | L9: 21.58 | M9: 98.25 | N9: 44.1 | O9: 0 | P9: 0.88 | Q9: 9.35
A10: 07/10/2025 02:00 | B10: 18.55 | C10: 5.61 | D10: 16.62 | E10: 5.33 | F10: 5.1 | G10: 33.64 | H10: 6.21 | I10: 2.93 | J10: 0.52 | K10: 330.27 | L10: 21.82 | M10: 98.24 | N10: 44.4 | O10: 0 | P10: 0.87 | Q10: 9.3
A11: 07/10/2025 03:00 | B11: 15.8 | C11: 8.31 | D11: 15.94 | E11: 5.5 | F11: 4.3 | G11: 31.87 | H11: 5.89 | I11: 2.99 | J11: 0.1 | K11: 325.25 | L11: 21.84 | M11: 98.21 | N11: 44.4 | O11: 0 | P11: 0.78 | Q11: 9.27
A12: 07/10/2025 04:00 | B12: 16.18 | C12: 8.84 | D12: 15.2 | E12: 5.24 | F12: 9.4 | G12: 24.13 | H12: 8.14 | I12: 2.94 | J12: 0.07 | K12: 299.92 | L12: 21.81 | M12: 98.25 | N12: 44.5 | O12: 0 | P12: 0.77 | Q12: 9.26
A13: 07/10/2025 05:00 | B13: 16.25 | C13: 10.3 | D13: 17.79 | E13: 5.51 | F13: 8.4 | G13: 27.46 | H13: 7.24 | I13: 2.81 | J13: 0.14 | K13: 344.39 | L13: 21.85 | M13: 98.3 | N13: 44.4 | O13: 0 | P13: 0.71 | Q13: 9.26
A14: 07/10/2025 06:00 | B14: 19.24 | C14: 10.42 | D14: 19.52 | E14: 5.58 | F14: 5.6 | G14: 33.55 | H14: 6.36 | I14: 2.87 | J14: 0.09 | K14: 353.37 | L14: 21.86 | M14: 98.32 | N14: 46.7 | O14: 0 | P14: 0.72 | Q14: 9.25
A15: 07/10/2025 07:00 | B15: 20.63 | C15: 5.45 | D15: 19.39 | E15: 5.47 | F15: 4.36 | G15: 49.34 | H15: 5.58 | I15: 2.97 | J15: 0.18 | K15: 322.23 | L15: 22.58 | M15: 98.33 | N15: 137.8 | O15: 0 | P15: 0.74 | Q15: 9.27
A16: 07/10/2025 08:00 | B16: 20.25 | C16: 6.7 | D16: 19.27 | E16: 5.32 | F16: 4.6 | G16: 46.07 | H16: 8.54 | I16: 3 | J16: 0.11 | K16: 289.93 | L16: 24.39 | M16: 98.25 | N16: 254.9 | O16: 0 | P16: 0.68 | Q16: 9.29
A17: 07/10/2025 09:00 | B17: 19.28 | C17: 7.47 | D17: 18.61 | E17: 5.38 | F17: 14.9 | G17: 44.78 | H17: 7.14 | I17: 3.3 | J17: 0.14 | K17: 284.68 | L17: 24.12 | M17: 98.23 | N17: 247.2 | O17: 0 | P17: 0.79 | Q17: 9.3
A18: 07/10/2025 10:00 | B18: 18.52 | C18: 8.67 | D18: 18.12 | E18: 5.24 | F18: 12 | G18: 61.42 | H18: 6.22 | I18: 3.7 | J18: 0.36 | K18: 177.73 | L18: 24.96 | M18: 98.21 | N18: 457.7 | O18: 0 | P18: 0.71 | Q18: 9.31
A19: 07/10/2025 11:00 | B19: 18.45 | C19: 16.21 | D19: 17.93 | E19: 5.46 | F19: 15.6 | G19: 59.92 | H19: 5.6 | I19: 3.73 | J19: 0.19 | K19: 288.36 | L19: 28.57 | M19: 97.97 | N19: 755.5 | O19: 0 | P19: 0.7 | Q19: 9.28
A20: 07/10/2025 12:00 | B20: 12 | C20: 23.54 | D20: 21.38 | E20: 5.49 | F20: 12.6 | G20: 40.28 | H20: 12.99 | I20: 2.91 | J20: 0.74 | K20: 343.5 | L20: 31 | M20: 88.56 | N20: 849.2 | O20: 0 | P20: 0.5 | Q20: 9.15
... A32: 07/10/2025 24:00 | B32: 9.8 | C32: 14.13 | D32: 15.24 | E32: 4.36 | F32: 27.4 | G32: 54.75 | H32: 7.28 | I32: 2.01 | J32: 0.11 | K32: 309.09 | L32: 23.75 | M32: 98.2 | N32: 46.6 | O32: 0 | P32: 0.49 | Q32: 9.18
A34: Min | B34: =MIN(B9:B32) -> 7.14 | C34: =MIN(C9:C32) -> 5.45 | D34: =MIN(D9:D32) -> 14.6 | E34: =MIN(E9:E32) -> 4.08 | F34: =MIN(F9:F32) -> 2.4 | G34: =MIN(G9:G32) -> 24.13 | H34: =MIN(H9:H32) -> 5.51 | I34: =MIN(I9:I32) -> 1.43 | ... Q34: =MIN(Q9:Q32) -> 9.06
A35: Max | B35: =MAX(B9:B32) -> 42.15 | C35: =MAX(C9:C32) -> 31.69 | D35: =MAX(D9:D32) -> 47.11 | E35: =MAX(E9:E32) -> 6.37 | F35: =MAX(F9:F32) -> 27.4 | G35: =MAX(G9:G32) -> 68.3 | H35: =MAX(H9:H32) -> 13.64 | I35: =MAX(I9:I32) -> 3.73 | ... Q35: =MAX(Q9:Q32) -> 9.35
A36: Avg | B36: =AVERAGE(B9:B32) -> 17.099583 | C36: =AVERAGE(C9:C32) -> 16.83625 | D36: =AVERAGE(D9:D32) -> 21.558333 | E36: =AVERAGE(E9:E32) -> 5.1166667 | F36: =AVERAGE(F9:F32) -> 10.177083 | G36: =AVERAGE(G9:G32) -> 47.825417 | H36: =AVERAGE(H9:H32) -> 7.8075 | I36: =AVERAGE(I9:I32) -> 2.4366667 | ... Q36: =AVERAGE(Q9:Q32) -> 9.2091667
A37: Stdev | B37: =STDEV(B9:B32) -> 6.8546769 | C37: =STDEV(C9:C32) -> 8.8400156 | D37: =STDEV(D9:D32) -> 7.3237705 | E37: =STDEV(E9:E32) -> 0.61743978 | F37: =STDEV(F9:F32) -> 5.5079243 | G37: =STDEV(G9:G32) -> 13.086822 | H37: =STDEV(H9:H32) -> 2.1980589 | I37: =STDEV(I9:I32) -> 0.72132527 | ... Q37: =STDEV(Q9:Q32) -> 0.082668361
A38: Num | B38: =COUNT(B9:B32) -> 24 | C38: =COUNT(C9:C32) -> 24 | D38: =COUNT(D9:D32) -> 24 | E38: =COUNT(E9:E32) -> 24 | F38: =COUNT(F9:F32) -> 24 | G38: =COUNT(G9:G32) -> 24 | H38: =COUNT(H9:H32) -> 24 | I38: =COUNT(I9:I32) -> 24 | ... Q38: =COUNT(Q9:Q32) -> 24
A39: DCR | B39: =IF(B38>=22,">90%",IF(B38<=22,"<90%")) -> >90% | C39: =IF(C38>=22,">90%",IF(C38<=22,"<90%")) -> >90% | D39: =IF(D38>=22,">90%",IF(D38<=22,"<90%")) -> >90% | E39: =IF(E38>=22,">90%",IF(E38<=22,"<90%")) -> >90% | F39: =IF(F38>=22,">90%",IF(F38<=22,"<90%")) -> >90% | G39: =IF(G38>=22,">90%",IF(G38<=22,"<90%")) -> >90% | H39: =IF(H38>=22,">90%",IF(H38<=22,"<90%")) -> >90% | I39: =IF(I38>=22,">90%",IF(I38<=22,"<90%")) -> >90% | ... Q39: =IF(Q38>=22,">90%",IF(Q38<=22,"<90%")) -> >90%
A40: Status | B40: =IF(B38>=22,"OK",IF(B38<=22,"LESS")) -> OK | C40: =IF(C38>=22,"OK",IF(C38<=22,"LESS")) -> OK | D40: =IF(D38>=22,"OK",IF(D38<=22,"LESS")) -> OK | E40: =IF(E38>=22,"OK",IF(E38<=22,"LESS")) -> OK | F40: =IF(F38>=22,"OK",IF(F38<=22,"LESS")) -> OK | G40: =IF(G38>=22,"OK",IF(G38<=22,"LESS")) -> OK | H40: =IF(H38>=22,"OK",IF(H38<=22,"LESS")) -> OK | I40: =IF(I38>=22,"OK",IF(I38<=22,"LESS")) -> OK | ... Q40: =IF(Q38>=22,"OK",IF(Q38<=22,"LESS")) -> OK
A43: Done by | B43: RAHUL
A45: Comment

Sheet 08
A1: Station: | B1: BHATAGAON RAIPUR
A2: Date: | B2: =$A$9 -> 08/10/2025 01:00 | D2: Power Off | G2: Pw.Off | L2: Link Fail | N2: Link F | P2: Maintenance | R2: Maint.
A3: Report Type: | B3: Mean | D3: Calibration | G3: Calib. | L3: Data Fail | N3: Data F | P3: Invalid | R3: Invalid
A4: Time Base: | B4: 01 Hour | D4: Zero Referrence | G4: Z.Ref | L4: Warm Up | N4: Wm. Up
A7: Date & Time | B7: NO_BHATAGAON | C7: NO2__BHATAGAON | D7: NOX_BHATAGAON | E7: SO2__BHATAGAON | F7: O3__BHATAGAON | G7: PM10__BHATAGAON | H7: PM2_5__BHATAGAON | I7: BENZ__BHATAGAON | J7: WS__BHATAGAON | K7: WD__BHATAGAON | L7: TEMP__BHATAGAON | M7: HUM__BHATAGAON | N7: SR__BHATAGAON | O7: RG__BHATAGAON | P7: CO__BHATAGAON | Q7: NH3__BHATAGAON
B8: ug/m3 | C8: ug/m3 | D8: ppb | E8: ug/m3 | F8: ug/m3 | G8: mg/m3 | H8: ug/m3 | I8: ug/m3 | J8: m/sec | K8: deg | L8: degreC | M8: % | N8: w/m2 | O8: mm | P8: ug/m3 | Q8: ug/m3
A9: 08/10/2025 01:00 | B9: 11.56 | C9: 10.89 | D9: 14.96 | E9: 4.16 | F9: 10.03 | G9: 48.15 | H9: 6.53 | I9: 1.95 | J9: 0.08 | K9: 357.78 | L9: 23.51 | M9: 98.2 | N9: 46.7 | O9: 0 | P9: 0.46 | Q9: 9.17
A10: 08/10/2025 02:00 | B10: 9.79 | C10: 8.9 | D10: 12.5 | E10: 4.26 | F10: 11.3 | G10: 44.77 | H10: 5.99 | I10: 1.84 | J10: 0.25 | K10: 356.14 | L10: 23.2 | M10: 98.24 | N10: 46.7 | O10: 0 | P10: 0.41 | Q10: 9.12
A11: 08/10/2025 03:00 | B11: 8.12 | C11: 9.4 | D11: 11.09 | E11: 4.18 | F11: 12.8 | G11: 43.5 | H11: 5.88 | I11: 1.76 | J11: 0.05 | K11: 349.18 | L11: 22.94 | M11: 98.27 | N11: 46.8 | O11: 0 | P11: 0.43 | Q11: 9.1
A12: 08/10/2025 04:00 | B12: 11.35 | C12: 10.09 | D12: 13.52 | E12: 4.29 | F12: 13.6 | G12: 36.37 | H12: 8.25 | I12: 1.83 | J12: 0.53 | K12: 343.1 | L12: 22.81 | M12: 98.35 | N12: 46.7 | O12: 0 | P12: 0.44 | Q12: 9.13
A13: 08/10/2025 05:00 | B13: 13.2 | C13: 9.24 | D13: 14.59 | E13: 4.06 | F13: 12.6 | G13: 44.39 | H13: 7.33 | I13: 1.84 | J13: 0.2 | K13: 322.46 | L13: 22.82 | M13: 98.37 | N13: 46.8 | O13: 0 | P13: 0.47 | Q13: 9.14
A14: 08/10/2025 06:00 | B14: 14.19 | C14: 7.97 | D14: 14.95 | E14: 4.11 | F14: 12.4 | G14: 46.41 | H14: 6.42 | I14: 1.82 | J14: 0.32 | K14: 331 | L14: 22.95 | M14: 98.35 | N14: 50.4 | O14: 0 | P14: 0.47 | Q14: 9.12
A15: 08/10/2025 07:00 | B15: 19.33 | C15: 8.56 | D15: 19.98 | E15: 3.86 | F15: 13.6 | G15: 61.57 | H15: 5.62 | I15: 1.83 | J15: 0.47 | K15: 339.76 | L15: 23.92 | M15: 98.31 | N15: 146.9 | O15: 0 | P15: 0.52 | Q15: 9.17
A16: 08/10/2025 08:00 | B16: 28.37 | C16: 14.19 | D16: 30.02 | E16: 5.51 | F16: 12.2 | G16: 73.13 | H16: 8.65 | I16: 1.89 | J16: 0.71 | K16: 347.24 | L16: 29.78 | M16: 98.11 | N16: 369 | O16: 0 | P16: 0.9 | Q16: 9.27
A17: 08/10/2025 09:00 | B17: 29.46 | C17: 20.5 | D17: 32.42 | E17: 6.46 | F17: 14.6 | G17: 209.82 | H17: 7.21 | I17: 2.03 | J17: 0.31 | K17: 342.46 | L17: 30.39 | M17: 84.92 | N17: 455.2 | O17: 0 | P17: 1.09 | Q17: 9.36
A18: 08/10/2025 10:00 | B18: 22.11 | C18: 32.7 | D18: 34.81 | E18: 6.39 | F18: 15.6 | G18: 250.24 | H18: 6.2 | I18: 2.14 | J18: 0.44 | K18: 353.73 | L18: 29.46 | M18: 89.16 | N18: 458.8 | O18: 0 | P18: 1.27 | Q18: 9.36
A19: 08/10/2025 11:00 | B19: 15.62 | C19: 29.74 | D19: 25.23 | E19: 7.15 | F19: 14.3 | G19: 205.18 | H19: 5.54 | I19: 2.26 | J19: 0.54 | K19: 282.97 | L19: 29.76 | M19: 88.42 | N19: 622.1 | O19: 0 | P19: 1.13 | Q19: 9.35
A20: 08/10/2025 12:00 | B20: 18.58 | C20: 32.74 | D20: 32.01 | E20: 6.79 | F20: 12.6 | G20: 160.65 | H20: 11.01 | I20: 2.32 | J20: 0.71 | K20: 155.58 | L20: 29.33 | M20: 93.64 | N20: 723.9 | O20: 0 | P20: 1.15 | Q20: 9.29
... A32: 08/10/2025 24:00 | B32: 13.38 | C32: 18.35 | D32: 20.31 | E32: 4.46 | F32: 2.47 | G32: 22.67 | H32: 7.25 | I32: 2.32 | J32: 0.29 | K32: 332.51 | L32: 23.92 | M32: 98.02 | N32: 43.9 | O32: 0 | P32: 0.47 | Q32: 9.31
A34: Min | B34: =MIN(B9:B32) -> 6.07 | C34: =MIN(C9:C32) -> 7.97 | D34: =MIN(D9:D32) -> 11.09 | E34: =MIN(E9:E32) -> 3.86 | F34: =MIN(F9:F32) -> 2.47 | G34: =MIN(G9:G32) -> 19.61 | H34: =MIN(H9:H32) -> 5.54 | I34: =MIN(I9:I32) -> 1.31 | ... Q34: =MIN(Q9:Q32) -> 9.07
A35: Max | B35: =MAX(B9:B32) -> 61.61 | C35: =MAX(C9:C32) -> 36.84 | D35: =MAX(D9:D32) -> 66.33 | E35: =MAX(E9:E32) -> 7.68 | F35: =MAX(F9:F32) -> 183.43 | G35: =MAX(G9:G32) -> 250.24 | H35: =MAX(H9:H32) -> 14.15 | I35: =MAX(I9:I32) -> 2.42 | ... Q35: =MAX(Q9:Q32) -> 9.36
A36: Avg | B36: =AVERAGE(B9:B32) -> 21.171667 | C36: =AVERAGE(C9:C32) -> 20.156667 | D36: =AVERAGE(D9:D32) -> 26.819167 | E36: =AVERAGE(E9:E32) -> 5.45375 | F36: =AVERAGE(F9:F32) -> 20.037083 | G36: =AVERAGE(G9:G32) -> 71.336667 | H36: =AVERAGE(H9:H32) -> 8.1716667 | I36: =AVERAGE(I9:I32) -> 2.01375 | ... Q36: =AVERAGE(Q9:Q32) -> 9.225
A37: Stdev | B37: =STDEV(B9:B32) -> 13.580464 | C37: =STDEV(C9:C32) -> 9.3059979 | D37: =STDEV(D9:D32) -> 13.761276 | E37: =STDEV(E9:E32) -> 1.1838949 | F37: =STDEV(F9:F32) -> 36.369439 | G37: =STDEV(G9:G32) -> 68.561169 | H37: =STDEV(H9:H32) -> 2.2367283 | I37: =STDEV(I9:I32) -> 0.31412837 | ... Q37: =STDEV(Q9:Q32) -> 0.10151033
A38: Num | B38: =COUNT(B9:B32) -> 24 | C38: =COUNT(C9:C32) -> 24 | D38: =COUNT(D9:D32) -> 24 | E38: =COUNT(E9:E32) -> 24 | F38: =COUNT(F9:F32) -> 24 | G38: =COUNT(G9:G32) -> 24 | H38: =COUNT(H9:H32) -> 24 | I38: =COUNT(I9:I32) -> 24 | ... Q38: =COUNT(Q9:Q32) -> 24
A39: DCR | B39: =IF(B38>=22,">90%",IF(B38<=22,"<90%")) -> >90% | C39: =IF(C38>=22,">90%",IF(C38<=22,"<90%")) -> >90% | D39: =IF(D38>=22,">90%",IF(D38<=22,"<90%")) -> >90% | E39: =IF(E38>=22,">90%",IF(E38<=22,"<90%")) -> >90% | F39: =IF(F38>=22,">90%",IF(F38<=22,"<90%")) -> >90% | G39: =IF(G38>=22,">90%",IF(G38<=22,"<90%")) -> >90% | H39: =IF(H38>=22,">90%",IF(H38<=22,"<90%")) -> >90% | I39: =IF(I38>=22,">90%",IF(I38<=22,"<90%")) -> >90% | ... Q39: =IF(Q38>=22,">90%",IF(Q38<=22,"<90%")) -> >90%
A40: Status | B40: =IF(B38>=22,"OK",IF(B38<=22,"LESS")) -> OK | C40: =IF(C38>=22,"OK",IF(C38<=22,"LESS")) -> OK | D40: =IF(D38>=22,"OK",IF(D38<=22,"LESS")) -> OK | E40: =IF(E38>=22,"OK",IF(E38<=22,"LESS")) -> OK | F40: =IF(F38>=22,"OK",IF(F38<=22,"LESS")) -> OK | G40: =IF(G38>=22,"OK",IF(G38<=22,"LESS")) -> OK | H40: =IF(H38>=22,"OK",IF(H38<=22,"LESS")) -> OK | I40: =IF(I38>=22,"OK",IF(I38<=22,"LESS")) -> OK | ... Q40: =IF(Q38>=22,"OK",IF(Q38<=22,"LESS")) -> OK
A43: Done by | B43: RAHUL
A45: Comment

Sheet 09
A1: Station: | B1: BHATAGAON RAIPUR
A2: Date: | B2: =$A$9 -> 09/10/2025 01:00 | D2: Power Off | G2: Pw.Off | L2: Link Fail | N2: Link F | P2: Maintenance | R2: Maint.
A3: Report Type: | B3: Mean | D3: Calibration | G3: Calib. | L3: Data Fail | N3: Data F | P3: Invalid | R3: Invalid
A4: Time Base: | B4: 01 Hour | D4: Zero Referrence | G4: Z.Ref | L4: Warm Up | N4: Wm. Up
A7: Date & Time | B7: NO_BHATAGAON | C7: NO2__BHATAGAON | D7: NOX_BHATAGAON | E7: SO2__BHATAGAON | F7: O3__BHATAGAON | G7: PM10__BHATAGAON | H7: PM2_5__BHATAGAON | I7: BENZ__BHATAGAON | J7: WS__BHATAGAON | K7: WD__BHATAGAON | L7: TEMP__BHATAGAON | M7: HUM__BHATAGAON | N7: SR__BHATAGAON | O7: RG__BHATAGAON | P7: CO__BHATAGAON | Q7: NH3__BHATAGAON
B8: ug/m3 | C8: ug/m3 | D8: ppb | E8: ug/m3 | F8: ug/m3 | G8: mg/m3 | H8: ug/m3 | I8: ug/m3 | J8: m/sec | K8: deg | L8: degreC | M8: % | N8: w/m2 | O8: mm | P8: ug/m3 | Q8: ug/m3
A9: 09/10/2025 01:00 | B9: 14.6 | C9: 10.54 | D9: 16.37 | E9: 4.43 | F9: 4.77 | G9: 22.75 | H9: 6.64 | I9: 2.2 | J9: 0.08 | K9: 306.12 | L9: 23.51 | M9: 98.01 | N9: 43.9 | O9: 0 | P9: 0.52 | Q9: 9.29
A10: 09/10/2025 02:00 | B10: 11.3 | C10: 9.11 | D10: 13.64 | E10: 4.34 | F10: 3.71 | G10: 24.27 | H10: 5.86 | I10: 2.08 | J10: 0.26 | K10: 329.94 | L10: 23.35 | M10: 98.02 | N10: 43.8 | O10: 0 | P10: 0.43 | Q10: 9.28
A11: 09/10/2025 03:00 | B11: 11.24 | C11: 8.27 | D11: 12.93 | E11: 4.46 | F11: 3.3 | G11: 12.37 | H11: 5.34 | I11: 2.02 | J11: 0.25 | K11: 322.05 | L11: 23.04 | M11: 98 | N11: 44.1 | O11: 0 | P11: 0.41 | Q11: 9.26
A12: 09/10/2025 04:00 | B12: 15.62 | C12: 7.81 | D12: 16.44 | E12: 4.31 | F12: 3.36 | G12: 11.75 | H12: 9.49 | I12: 1.92 | J12: 0.54 | K12: 343.6 | L12: 22.91 | M12: 98.03 | N12: 44 | O12: 0 | P12: 0.48 | Q12: 9.22
A13: 09/10/2025 05:00 | B13: 14.83 | C13: 7.96 | D13: 15.09 | E13: 4.12 | F13: 4.22 | G13: 23.02 | H13: 8.65 | I13: 1.8 | J13: 0.59 | K13: 342.34 | L13: 22.8 | M13: 98.06 | N13: 43.9 | O13: 0 | P13: 0.43 | Q13: 9.19
A14: 09/10/2025 06:00 | B14: 18.31 | C14: 9.96 | D14: 18.66 | E14: 4.47 | F14: 3.74 | G14: 23.45 | H14: 7.87 | I14: 1.72 | J14: 0.76 | K14: 337.46 | L14: 22.77 | M14: 98.03 | N14: 47.8 | O14: 0 | P14: 0.57 | Q14: 9.25
A15: 09/10/2025 07:00 | B15: 19.97 | C15: 9.85 | D15: 20.29 | E15: 4.73 | F15: 3.45 | G15: 32.16 | H15: 6.66 | I15: 1.77 | J15: 1 | K15: 338.28 | L15: 24.66 | M15: 98.04 | N15: 153.9 | O15: 0 | P15: 0.63 | Q15: 9.28
A16: 09/10/2025 08:00 | B16: 27.18 | C16: 12.18 | D16: 28.13 | E16: 5.28 | F16: 4.36 | G16: 37.42 | H16: 8.58 | I16: 1.82 | J16: 1.01 | K16: 341.57 | L16: 29.66 | M16: 97.83 | N16: 342.8 | O16: 0 | P16: 0.8 | Q16: 9.3
A17: 09/10/2025 09:00 | B17: 26.36 | C17: 14.88 | D17: 28.85 | E17: 6.42 | F17: 6.11 | G17: 49.73 | H17: 9.58 | I17: 1.96 | J17: 1.44 | K17: 340.45 | L17: 32.32 | M17: 79.63 | N17: 549.9 | O17: 0 | P17: 0.79 | Q17: 9.37
A18: 09/10/2025 10:00 | B18: 26.6 | C18: 18 | D18: 30.05 | E18: 7.05 | F18: 8.4 | G18: 52.74 | H18: 8.65 | I18: 2.07 | J18: 0.78 | K18: 337.38 | L18: 33.12 | M18: 76.94 | N18: 637.5 | O18: 0 | P18: 1 | Q18: 9.42
A19: 09/10/2025 11:00 | B19: 24.36 | C19: 24.06 | D19: 29.32 | E19: 7.21 | F19: 10.35 | G19: 50 | H19: 7.21 | I19: 2.15 | J19: 0.81 | K19: 347.55 | L19: 31.13 | M19: 82.85 | N19: 600.5 | O19: 0 | P19: 0.82 | Q19: 9.45
A20: 09/10/2025 12:00 | B20: 17.23 | C20: 18.5 | D20: 23.49 | E20: 6.86 | F20: 16.71 | G20: 43.12 | H20: 8.94 | I20: 2.16 | J20: 0.45 | K20: 137.61 | L20: 29.52 | M20: 87.98 | N20: 424.6 | O20: 0 | P20: 0.68 | Q20: 9.44
... A32: 09/10/2025 24:00 | B32: 12.45 | C32: 15.72 | D32: 15.23 | E32: 5.63 | F32: 3.01 | G32: 20.5 | H32: 8.37 | I32: 1.83 | J32: 0.14 | K32: 253.14 | L32: 22.69 | M32: 98.04 | N32: 41.1 | O32: 0 | P32: 0.65 | Q32: 9.2
A34: Min | B34: =MIN(B9:B32) -> 9.74 | C34: =MIN(C9:C32) -> 7.81 | D34: =MIN(D9:D32) -> 12.93 | E34: =MIN(E9:E32) -> 4.12 | F34: =MIN(F9:F32) -> 2.27 | G34: =MIN(G9:G32) -> 11.75 | H34: =MIN(H9:H32) -> 5.25 | I34: =MIN(I9:I32) -> 1.72 | ... Q34: =MIN(Q9:Q32) -> 9.16
A35: Max | B35: =MAX(B9:B32) -> 28.76 | C35: =MAX(C9:C32) -> 31.41 | D35: =MAX(D9:D32) -> 37.7 | E35: =MAX(E9:E32) -> 7.9 | F35: =MAX(F9:F32) -> 16.71 | G35: =MAX(G9:G32) -> 52.74 | H35: =MAX(H9:H32) -> 10.49 | I35: =MAX(I9:I32) -> 2.2 | ... Q35: =MAX(Q9:Q32) -> 9.45
A36: Avg | B36: =AVERAGE(B9:B32) -> 18.035417 | C36: =AVERAGE(C9:C32) -> 17.15375 | D36: =AVERAGE(D9:D32) -> 22.6325 | E36: =AVERAGE(E9:E32) -> 5.7970833 | F36: =AVERAGE(F9:F32) -> 7.52875 | G36: =AVERAGE(G9:G32) -> 31.596667 | H36: =AVERAGE(H9:H32) -> 7.76125 | I36: =AVERAGE(I9:I32) -> 1.9583333 | ... Q36: =AVERAGE(Q9:Q32) -> 9.2733333
A37: Stdev | B37: =STDEV(B9:B32) -> 6.2367417 | C37: =STDEV(C9:C32) -> 7.19394 | D37: =STDEV(D9:D32) -> 7.374946 | E37: =STDEV(E9:E32) -> 1.0933136 | F37: =STDEV(F9:F32) -> 4.4719097 | G37: =STDEV(G9:G32) -> 11.050424 | H37: =STDEV(H9:H32) -> 1.5281342 | I37: =STDEV(I9:I32) -> 0.14125729 | ... Q37: =STDEV(Q9:Q32) -> 0.087609145
A38: Num | B38: =COUNT(B9:B32) -> 24 | C38: =COUNT(C9:C32) -> 24 | D38: =COUNT(D9:D32) -> 24 | E38: =COUNT(E9:E32) -> 24 | F38: =COUNT(F9:F32) -> 24 | G38: =COUNT(G9:G32) -> 24 | H38: =COUNT(H9:H32) -> 24 | I38: =COUNT(I9:I32) -> 24 | ... Q38: =COUNT(Q9:Q32) -> 24
A39: DCR | B39: =IF(B38>=22,">90%",IF(B38<=22,"<90%")) -> >90% | C39: =IF(C38>=22,">90%",IF(C38<=22,"<90%")) -> >90% | D39: =IF(D38>=22,">90%",IF(D38<=22,"<90%")) -> >90% | E39: =IF(E38>=22,">90%",IF(E38<=22,"<90%")) -> >90% | F39: =IF(F38>=22,">90%",IF(F38<=22,"<90%")) -> >90% | G39: =IF(G38>=22,">90%",IF(G38<=22,"<90%")) -> >90% | H39: =IF(H38>=22,">90%",IF(H38<=22,"<90%")) -> >90% | I39: =IF(I38>=22,">90%",IF(I38<=22,"<90%")) -> >90% | ... Q39: =IF(Q38>=22,">90%",IF(Q38<=22,"<90%")) -> >90%
A40: Status | B40: =IF(B38>=22,"OK",IF(B38<=22,"LESS")) -> OK | C40: =IF(C38>=22,"OK",IF(C38<=22,"LESS")) -> OK | D40: =IF(D38>=22,"OK",IF(D38<=22,"LESS")) -> OK | E40: =IF(E38>=22,"OK",IF(E38<=22,"LESS")) -> OK | F40: =IF(F38>=22,"OK",IF(F38<=22,"LESS")) -> OK | G40: =IF(G38>=22,"OK",IF(G38<=22,"LESS")) -> OK | H40: =IF(H38>=22,"OK",IF(H38<=22,"LESS")) -> OK | I40: =IF(I38>=22,"OK",IF(I38<=22,"LESS")) -> OK | ... Q40: =IF(Q38>=22,"OK",IF(Q38<=22,"LESS")) -> OK
A43: Done by | B43: RAHUL
A45: Comment

Sheet 10
A1: Station: | B1: BHATAGAON RAIPUR
A2: Date: | B2: =$A$9 -> 10/10/2025 01:00 | D2: Power Off | G2: Pw.Off | L2: Link Fail | N2: Link F | P2: Maintenance | R2: Maint.
A3: Report Type: | B3: Mean | D3: Calibration | G3: Calib. | L3: Data Fail | N3: Data F | P3: Invalid | R3: Invalid
A4: Time Base: | B4: 01 Hour | D4: Zero Referrence | G4: Z.Ref | L4: Warm Up | N4: Wm. Up
A7: Date & Time | B7: NO_BHATAGAON | C7: NO2__BHATAGAON | D7: NOX_BHATAGAON | E7: SO2__BHATAGAON | F7: O3__BHATAGAON | G7: PM10__BHATAGAON | H7: PM2_5__BHATAGAON | I7: BENZ__BHATAGAON | J7: WS__BHATAGAON | K7: WD__BHATAGAON | L7: TEMP__BHATAGAON | M7: HUM__BHATAGAON | N7: SR__BHATAGAON | O7: RG__BHATAGAON | P7: CO__BHATAGAON | Q7: NH3__BHATAGAON
B8: ug/m3 | C8: ug/m3 | D8: ppb | E8: ug/m3 | F8: ug/m3 | G8: mg/m3 | H8: ug/m3 | I8: ug/m3 | J8: m/sec | K8: deg | L8: degreC | M8: % | N8: w/m2 | O8: mm | P8: ug/m3 | Q8: ug/m3
A9: 10/10/2025 01:00 | B9: 13.26 | C9: 19.29 | D9: 19.19 | E9: 6.02 | F9: 2.35 | G9: 20.36 | H9: 7.46 | I9: 1.79 | J9: 0.52 | K9: 340.48 | L9: 22.81 | M9: 98.03 | N9: 41.3 | O9: 0 | P9: 0.63 | Q9: 9.21
A10: 10/10/2025 02:00 | B10: 13.78 | C10: 16.89 | D10: 17.54 | E10: 6.53 | F10: 2.25 | G10: 20.8 | H10: 6.56 | I10: 1.83 | J10: 1.02 | K10: 339.71 | L10: 22.8 | M10: 98.01 | N10: 41.9 | O10: 0 | P10: 0.7 | Q10: 9.21
A11: 10/10/2025 03:00 | B11: 12.39 | C11: 8.27 | D11: 14.22 | E11: 6.09 | F11: 2.1 | G11: 28.94 | H11: 6.01 | I11: 1.86 | J11: 0.83 | K11: 350.32 | L11: 22.24 | M11: 97.99 | N11: 41.5 | O11: 0 | P11: 0.67 | Q11: 9.18
A12: 10/10/2025 04:00 | B12: 11.17 | C12: 14.07 | D12: 15.68 | E12: 6.92 | F12: 2.1 | G12: 25.51 | H12: 9 | I12: 1.96 | J12: 0.2 | K12: 354.13 | L12: 21.76 | M12: 98.06 | N12: 41.2 | O12: 0 | P12: 0.94 | Q12: 9.18
A13: 10/10/2025 05:00 | B13: 15.14 | C13: 13.48 | D13: 18.46 | E13: 6.91 | F13: 2.1 | G13: 76.42 | H13: 7.45 | I13: 2.1 | J13: 0.06 | K13: 355.95 | L13: 21.65 | M13: 98.09 | N13: 41.2 | O13: 0 | P13: 0.93 | Q13: 9.21
A14: 10/10/2025 06:00 | B14: 18.04 | C14: 13.52 | D14: 20.21 | E14: 6.59 | F14: 2.1 | G14: 52.22 | H14: 6.37 | I14: 2.13 | J14: 0.12 | K14: 353.25 | L14: 21.61 | M14: 98.17 | N14: 44.9 | O14: 0 | P14: 0.84 | Q14: 9.22
A15: 10/10/2025 07:00 | B15: 24.85 | C15: 10.82 | D15: 25.58 | E15: 6.28 | F15: 2.13 | G15: 43.91 | H15: 5.67 | I15: 2.1 | J15: 0.32 | K15: 337.12 | L15: 23.03 | M15: 98.15 | N15: 127.6 | O15: 0 | P15: 0.93 | Q15: 9.24
A16: 10/10/2025 08:00 | B16: 21.48 | C16: 10.35 | D16: 22.15 | E16: 6.45 | F16: 3.08 | G16: 44.93 | H16: 11.84 | I16: 2.16 | J16: 0.48 | K16: 341.22 | L16: 24.13 | M16: 98.06 | N16: 136.5 | O16: 0 | P16: 0.76 | Q16: 9.3
A17: 10/10/2025 09:00 | B17: 23.76 | C17: 11.65 | D17: 25.09 | E17: 5.94 | F17: 6.46 | G17: 46.65 | H17: 10.1 | I17: 2.17 | J17: 0.64 | K17: 133.72 | L17: 24.84 | M17: 98.13 | N17: 259.1 | O17: 0 | P17: 0.62 | Q17: 9.35
A18: 10/10/2025 10:00 | B18: 18.31 | C18: 11.73 | D18: 20.81 | E18: 6.55 | F18: 9.45 | G18: 22.53 | H18: 8.22 | I18: 2.24 | J18: 0.97 | K18: 138.95 | L18: 26.24 | M18: 97.99 | N18: 464.9 | O18: 0 | P18: 0.56 | Q18: 9.35
A19: 10/10/2025 11:00 | B19: 16.78 | C19: 12.87 | D19: 19.79 | E19: 6.51 | F19: 8.05 | G19: 26.82 | H19: 6.91 | I19: 2.06 | J19: 0.67 | K19: 132.28 | L19: 28.03 | M19: 96.85 | N19: 427.6 | O19: 0 | P19: 0.58 | Q19: 9.31
A20: 10/10/2025 12:00 | B20: 17.11 | C20: 15.23 | D20: 21.68 | E20: 6.48 | F20: 12.76 | G20: 23.6 | H20: 9.5 | I20: 1.99 | J20: 0.11 | K20: 352.85 | L20: 28.48 | M20: 89.37 | N20: 415.7 | O20: 0 | P20: 0.6 | Q20: 9.27
... A32: 10/10/2025 24:00 | B32: 16.03 | C32: 13.56 | D32: 18.01 | E32: 5.52 | F32: 5.17 | G32: 35.4 | H32: 8.7 | I32: 2.24 | J32: 0.65 | K32: 337.16 | L32: 22.99 | M32: 98.42 | N32: 41.5 | O32: 0 | P32: 0.75 | Q32: 9.28
A34: Min | B34: =MIN(B9:B32) -> 7.55 | C34: =MIN(C9:C32) -> 8.27 | D34: =MIN(D9:D32) -> 14.22 | E34: =MIN(E9:E32) -> 5.19 | F34: =MIN(F9:F32) -> 2.1 | G34: =MIN(G9:G32) -> 12.29 | H34: =MIN(H9:H32) -> 5.67 | I34: =MIN(I9:I32) -> 1.66 | ... Q34: =MIN(Q9:Q32) -> 9.11
