Workbook

Sheet 01
A1: Station: | B1: IGKV RAIPUR
A2: Date: | B2: =$A$9 -> 01/03/2025 00:15 | C2: Power Off | G2: Pw.Off | J2: Link Fail | L2: Link F | N2: Maintenance | P2: Maint.
A3: Report Type: | B3: Mean | C3: Calibration | G3: Calib. | J3: Data Fail | L3: Data F | N3: Invalid | P3: Invalid
A4: Time Base: | B4: 15 Min | C4: Zero Referrence | G4: Z.Ref | J4: Warm Up | L4: Wm. Up
A7: Date & Time | B7: NO | C7: NO2 | D7: NOX | E7: SO2 | F7: O3 | G7: PM 10 | H7: PM 2.5 | I7: BENZ | J7: WS | K7: WD | L7: TEMP | M7: HUM | N7: SR | O7: RG | P7: CO | Q7: NH3
B8: ug/m3 | C8: ug/m3 | D8: ppb | E8: ug/m3 | F8: ug/m3 | G8: ug/m3 | H8: ug/m3 | I8: ug/m3 | J8: m/sec | K8: deg | L8: degreC | M8: % | N8: w/m2 | O8: mm | P8: mg/m3 | Q8: ug/m3
A9: 01/03/2025 00:15 | B9: 9.89 | C9: 22.75 | D9: 21.17 | E9: 11.27 | F9: Maint. | G9: 110.66 | H9: 35.44 | I9: 10.91 | J9: 0.14 | K9: 147.37 | L9: 22.45 | M9: 59.21 | N9: 0.9 | O9: 0 | P9: 1 | Q9: 28.19
A10: 01/03/2025 00:30 | B10: 11.08 | C10: 23.64 | D10: 22.59 | E10: 10.77 | F10: Maint. | G10: 110.66 | H10: 35.44 | I10: 11.1 | J10: 0.23 | K10: 196.07 | L10: 22.23 | M10: 62.29 | N10: 1.2 | O10: 0 | P10: 1.02 | Q10: 28.26
A11: 01/03/2025 00:45 | B11: 12.14 | C11: 24.44 | D11: 23.86 | E11: 11.5 | F11: Maint. | G11: 110.29 | H11: 33.62 | I11: 11.36 | J11: 0.22 | K11: 187.39 | L11: 21.79 | M11: 63.5 | N11: 1.3 | O11: 0 | P11: 1.04 | Q11: 28.31
A12: 01/03/2025 01:00 | B12: 12.63 | C12: 25.03 | D12: 24.56 | E12: 10.89 | F12: Maint. | G12: 110.25 | H12: 33.62 | I12: 11.64 | J12: 0.26 | K12: 217.45 | L12: 21.47 | M12: 65.25 | N12: 1.3 | O12: 0 | P12: 1.05 | Q12: 28.35
A13: 01/03/2025 01:15 | B13: 12.76 | C13: 25.54 | D13: 24.93 | E13: 11 | F13: Maint. | G13: 110.25 | H13: 33.62 | I13: 11.87 | J13: 0.19 | K13: 203.53 | L13: 21.1 | M13: 66.63 | N13: 1.2 | O13: 0 | P13: 1.07 | Q13: 28.38
A14: 01/03/2025 01:30 | B14: 12.72 | C14: 25.91 | D14: 25.09 | E14: 11.13 | F14: Maint. | G14: 110.25 | H14: 33.62 | I14: 12.17 | J14: 0.2 | K14: 200.8 | L14: 21.04 | M14: 66.23 | N14: 1.1 | O14: 0 | P14: 1.08 | Q14: 28.36
A15: 01/03/2025 01:45 | B15: 12.56 | C15: 26.04 | D15: 25.03 | E15: 11.19 | F15: Maint. | G15: 106.13 | H15: 31.67 | I15: 12.4 | J15: 0.03 | K15: 220.08 | L15: 21.01 | M15: 63.87 | N15: 0.8 | O15: 0 | P15: 1.11 | Q15: 28.36
A16: 01/03/2025 02:00 | B16: 12.75 | C16: 26.11 | D16: 25.22 | E16: 11.09 | F16: Maint. | G16: 105.61 | H16: 31.67 | I16: 12.58 | J16: 0.21 | K16: 80.61 | L16: 21.65 | M16: 58.52 | N16: 0.6 | O16: 0 | P16: 1.12 | Q16: 28.36
A17: 01/03/2025 02:15 | B17: 14.08 | C17: 26.81 | D17: 26.65 | E17: 8.24 | F17: Maint. | G17: 105.61 | H17: 31.67 | I17: 12.77 | J17: 0.15 | K17: 126.85 | L17: 21.95 | M17: 57.54 | N17: 0.7 | O17: 0 | P17: 1.14 | Q17: 28.42
A18: 01/03/2025 02:30 | B18: 15.6 | C18: 27.34 | D18: 28.15 | E18: 9.41 | F18: Maint. | G18: 105.61 | H18: 31.67 | I18: 13.05 | J18: 0.22 | K18: 173.54 | L18: 21.43 | M18: 64.72 | N18: 1.2 | O18: 0 | P18: 1.15 | Q18: 28.45
A19: 01/03/2025 02:45 | B19: 16.49 | C19: 27.74 | D19: 29.06 | E19: 9.38 | F19: Maint. | G19: 109.09 | H19: 33.52 | I19: 13.43 | J19: 0.22 | K19: 190.4 | L19: 21.02 | M19: 66.22 | N19: 1.2 | O19: 0 | P19: 1.17 | Q19: 28.5
A20: 01/03/2025 03:00 | B20: 16.7 | C20: 27.96 | D20: 29.35 | E20: 9.3 | F20: Maint. | G20: 109.53 | H20: 33.52 | I20: 13.8 | J20: 0.27 | K20: 221.12 | L20: 20.24 | M20: 69.18 | N20: 1.6 | O20: 0 | P20: 1.18 | Q20: 28.52
... A104: 01/03/2025 24:00 | B104: 7.43 | C104: 23.71 | D104: 19.7 | E104: 10.95 | F104: Maint. | G104: 79.6 | H104: 26.11 | I104: 13.66 | J104: 0.21 | K104: 169.08 | L104: 23.39 | M104: 60.74 | N104: 1 | O104: 0 | P104: 1.08 | Q104: 28.13
A106: Min | B106: =MIN(B9:B104) -> 3.85 | C106: =MIN(C9:C104) -> 17.86 | D106: =MIN(D9:D104) -> 13.91 | E106: =MIN(E9:E104) -> 8.24 | F106: =MIN(F9:F104) -> 0 | G106: =MIN(G9:G104) -> 47.64 | H106: =MIN(H9:H104) -> 22.8 | I106: =MIN(I9:I104) -> 5.31 | ... Q106: =MIN(Q9:Q104) -> 27.97
A107: Max | B107: =MAX(B9:B104) -> 16.7 | C107: =MAX(C9:C104) -> 27.96 | D107: =MAX(D9:D104) -> 29.35 | E107: =MAX(E9:E104) -> 27.7 | F107: =MAX(F9:F104) -> 0 | G107: =MAX(G9:G104) -> 110.66 | H107: =MAX(H9:H104) -> 44.51 | I107: =MAX(I9:I104) -> 14.63 | ... Q107: =MAX(Q9:Q104) -> 28.52
A108: Avg | B108: =AVERAGE(B9:B104) -> 8.1027083 | C108: =AVERAGE(C9:C104) -> 22.413333 | D108: =AVERAGE(D9:D104) -> 19.558854 | E108: =AVERAGE(E9:E104) -> 12.022083 | F108: =AVERAGE(F9:F104) -> #DIV/0! | G108: =AVERAGE(G9:G104) -> 77.591875 | H108: =AVERAGE(H9:H104) -> 32.487292 | I108: =AVERAGE(I9:I104) -> 10.869792 | ... Q108: =AVERAGE(Q9:Q104) -> 28.172396
A109: Stdev | B109: =STDEV(B9:B104) -> 4.4935595 | C109: =STDEV(C9:C104) -> 2.7270245 | D109: =STDEV(D9:D104) -> 4.8294735 | E109: =STDEV(E9:E104) -> 3.7151978 | F109: =STDEV(F9:F104) -> #DIV/0! | G109: =STDEV(G9:G104) -> 18.532137 | H109: =STDEV(H9:H104) -> 5.2827607 | I109: =STDEV(I9:I104) -> 3.0299814 | ... Q109: =STDEV(Q9:Q104) -> 0.18424095
A110: Num | B110: =COUNT(B9:B104) -> 96 | C110: =COUNT(C9:C104) -> 96 | D110: =COUNT(D9:D104) -> 96 | E110: =COUNT(E9:E104) -> 96 | F110: =COUNT(F9:F104)+96 -> 96 | G110: =COUNT(G9:G104) -> 96 | H110: =COUNT(H9:H104) -> 96 | I110: =COUNT(I9:I104) -> 96 | J110: =COUNT(J9:J104) -> 96 | K110: =COUNT(K9:K104) -> 96 | L110: =COUNT(L9:L104) -> 96 | M110: =COUNT(M9:M104) -> 96 | N110: =COUNT(N9:N104) -> 96 | ... Q110: =COUNT(Q9:Q104) -> 96
A111: DCR | B111: =IF(B110>=87,">90%",IF(B110<=87,"<90%")) -> >90% | C111: =IF(C110>=87,">90%",IF(C110<=87,"<90%")) -> >90% | D111: =IF(D110>=87,">90%",IF(D110<=87,"<90%")) -> >90% | E111: =IF(E110>=87,">90%",IF(E110<=87,"<90%")) -> >90% | F111: =IF(F110>=87,">90%",IF(F110<=87,"<90%")) -> >90% | G111: =IF(G110>=87,">90%",IF(G110<=87,"<90%")) -> >90% | H111: =IF(H110>=87,">90%",IF(H110<=87,"<90%")) -> >90% | I111: =IF(I110>=87,">90%",IF(I110<=87,"<90%")) -> >90% | ... Q111: =IF(Q110>=87,">90%",IF(Q110<=87,"<90%")) -> >90%
A112: Status | B112: =IF(B110>=87,"OK",IF(B110<=87,"LESS")) -> OK | C112: =IF(C110>=87,"OK",IF(C110<=87,"LESS")) -> OK | D112: =IF(D110>=87,"OK",IF(D110<=87,"LESS")) -> OK | E112: =IF(E110>=87,"OK",IF(E110<=87,"LESS")) -> OK | F112: =IF(F110>=87,"OK",IF(F110<=87,"LESS")) -> OK | G112: =IF(G110>=87,"OK",IF(G110<=87,"LESS")) -> OK | H112: =IF(H110>=87,"OK",IF(H110<=87,"LESS")) -> OK | I112: =IF(I110>=87,"OK",IF(I110<=87,"LESS")) -> OK | ... Q112: =IF(Q110>=87,"OK",IF(Q110<=87,"LESS")) -> OK
A115: Done by | B115: AKASH
A117: Comment

Sheet 02
A1: Station: | B1: IGKV RAIPUR
A2: Date: | B2: =$A$9 -> 02/03/2025 00:15 | C2: Power Off | G2: Pw.Off | J2: Link Fail | L2: Link F | N2: Maintenance | P2: Maint.
A3: Report Type: | B3: Mean | C3: Calibration | G3: Calib. | J3: Data Fail | L3: Data F | N3: Invalid | P3: Invalid
A4: Time Base: | B4: 15 Min | C4: Zero Referrence | G4: Z.Ref | J4: Warm Up | L4: Wm. Up
A7: Date & Time | B7: NO | C7: NO2 | D7: NOX | E7: SO2 | F7: O3 | G7: PM 10 | H7: PM 2.5 | I7: BENZ | J7: WS | K7: WD | L7: TEMP | M7: HUM | N7: SR | O7: RG | P7: CO | Q7: NH3
B8: ug/m3 | C8: ug/m3 | D8: ppb | E8: ug/m3 | F8: ug/m3 | G8: ug/m3 | H8: ug/m3 | I8: ug/m3 | J8: m/sec | K8: deg | L8: degreC | M8: % | N8: w/m2 | O8: mm | P8: mg/m3 | Q8: ug/m3
A9: 02/03/2025 00:15 | B9: 7.76 | C9: 24.15 | D9: 20.19 | E9: 10.72 | F9: Maint. | G9: 79.6 | H9: 26.11 | I9: 13.89 | J9: 0.26 | K9: 169.11 | L9: 23.39 | M9: 62.87 | N9: 1 | O9: 0 | P9: 1.09 | Q9: 28.14
A10: 02/03/2025 00:30 | B10: 8.13 | C10: 24.26 | D10: 20.55 | E10: 10.96 | F10: Maint. | G10: 79.6 | H10: 26.11 | I10: 14.03 | J10: 0.27 | K10: 162.37 | L10: 23.1 | M10: 64.53 | N10: 1.2 | O10: 0 | P10: 1.1 | Q10: 28.15
A11: 02/03/2025 00:45 | B11: 8.23 | C11: 24.14 | D11: 20.56 | E11: 11 | F11: Maint. | G11: 78.25 | H11: 28.21 | I11: 14.16 | J11: 0.24 | K11: 192.02 | L11: 22.72 | M11: 66.88 | N11: 1.4 | O11: 0 | P11: 1.12 | Q11: 28.19
A12: 02/03/2025 01:00 | B12: 8.5 | C12: 21.71 | D12: 19.51 | E12: 10.78 | F12: Maint. | G12: 78.08 | H12: 28.21 | I12: 14.27 | J12: 0.18 | K12: 209.46 | L12: 21.92 | M12: 68.15 | N12: 1.6 | O12: 0 | P12: 1.16 | Q12: 28.24
A13: 02/03/2025 01:15 | B13: 8.72 | C13: 20.85 | D13: 19.24 | E13: 10.62 | F13: Maint. | G13: 78.08 | H13: 28.21 | I13: 14.36 | J13: 0.21 | K13: 203.6 | L13: 21.86 | M13: 66.69 | N13: 1.2 | O13: 0 | P13: 1.15 | Q13: 28.23
A14: 02/03/2025 01:30 | B14: 8.86 | C14: 20.65 | D14: 19.25 | E14: 10.23 | F14: Maint. | G14: 78.08 | H14: 28.21 | I14: 14.41 | J14: 0.13 | K14: 155.31 | L14: 21.9 | M14: 66.64 | N14: 1 | O14: 0 | P14: 1.16 | Q14: 28.22
A15: 02/03/2025 01:45 | B15: 9.1 | C15: 20.87 | D15: 19.55 | E15: 10.74 | F15: Maint. | G15: 73.32 | H15: 25.41 | I15: 14.36 | J15: 0.14 | K15: 173.19 | L15: 21.89 | M15: 69.86 | N15: 1 | O15: 0 | P15: 1.14 | Q15: 28.24
A16: 02/03/2025 02:00 | B16: 9.31 | C16: 21.23 | D16: 19.9 | E16: 10.35 | F16: Maint. | G16: 72.73 | H16: 25.41 | I16: 14.24 | J16: 0.14 | K16: 159.92 | L16: 21.87 | M16: 70.5 | N16: 0.9 | O16: 0 | P16: 1.15 | Q16: 28.24
A17: 02/03/2025 02:15 | B17: 9.55 | C17: 21.33 | D17: 20.16 | E17: 8.93 | F17: Maint. | G17: 72.73 | H17: 25.41 | I17: 14.19 | J17: 0.17 | K17: 179.05 | L17: 21.64 | M17: 72.3 | N17: 1.1 | O17: 0 | P17: 1.16 | Q17: 28.25
A18: 02/03/2025 02:30 | B18: 9.8 | C18: 21 | D18: 20.18 | E18: 10.86 | F18: Maint. | G18: 72.73 | H18: 25.41 | I18: 14.21 | J18: 0.14 | K18: 163.16 | L18: 21.51 | M18: 71.59 | N18: 1 | O18: 0 | P18: 1.17 | Q18: 28.27
A19: 02/03/2025 02:45 | B19: 10.05 | C19: 20.84 | D19: 20.3 | E19: 10.21 | F19: Maint. | G19: 75.64 | H19: 23.56 | I19: 14.25 | J19: 0.21 | K19: 187.88 | L19: 21.25 | M19: 73.67 | N19: 1.2 | O19: 0 | P19: 1.16 | Q19: 28.25
A20: 02/03/2025 03:00 | B20: 10.26 | C20: 20.62 | D20: 20.35 | E20: 10.61 | F20: Maint. | G20: 76 | H20: 23.56 | I20: 14.32 | J20: 0.17 | K20: 210.41 | L20: 20.71 | M20: 73.07 | N20: 1.4 | O20: 0 | P20: 1.17 | Q20: 28.28
... A104: 02/03/2025 24:00 | B104: 6.63 | C104: 18.43 | D104: 16.29 | E104: 8.91 | F104: Maint. | G104: 69.19 | H104: 27.62 | I104: 10.75 | J104: 0.14 | K104: 194.92 | L104: 23.89 | M104: 64.7 | N104: 1.2 | O104: 0 | P104: 0.87 | Q104: 28.13
A106: Min | B106: =MIN(B9:B104) -> 3.64 | C106: =MIN(C9:C104) -> 16.99 | D106: =MIN(D9:D104) -> 13.26 | E106: =MIN(E9:E104) -> 8.75 | F106: =MIN(F9:F104) -> 0 | G106: =MIN(G9:G104) -> 50.38 | H106: =MIN(H9:H104) -> 20.21 | I106: =MIN(I9:I104) -> 7.04 | ... Q106: =MIN(Q9:Q104) -> 27.96
A107: Max | B107: =MAX(B9:B104) -> 13.64 | C107: =MAX(C9:C104) -> 24.57 | D107: =MAX(D9:D104) -> 23.31 | E107: =MAX(E9:E104) -> 21.19 | F107: =MAX(F9:F104) -> 0 | G107: =MAX(G9:G104) -> 79.6 | H107: =MAX(H9:H104) -> 36.92 | I107: =MAX(I9:I104) -> 14.41 | ... Q107: =MAX(Q9:Q104) -> 28.42
A108: Avg | B108: =AVERAGE(B9:B104) -> 6.754375 | C108: =AVERAGE(C9:C104) -> 20.168021 | D108: =AVERAGE(D9:D104) -> 17.304479 | E108: =AVERAGE(E9:E104) -> 12.074167 | F108: =AVERAGE(F9:F104) -> #DIV/0! | G108: =AVERAGE(G9:G104) -> 63.185625 | H108: =AVERAGE(H9:H104) -> 26.826458 | I108: =AVERAGE(I9:I104) -> 11.192813 | ... Q108: =AVERAGE(Q9:Q104) -> 28.122708
A109: Stdev | B109: =STDEV(B9:B104) -> 3.3550834 | C109: =STDEV(C9:C104) -> 2.1101876 | D109: =STDEV(D9:D104) -> 3.3291225 | E109: =STDEV(E9:E104) -> 2.7489671 | F109: =STDEV(F9:F104) -> #DIV/0! | G109: =STDEV(G9:G104) -> 8.6211606 | H109: =STDEV(H9:H104) -> 3.7566802 | I109: =STDEV(I9:I104) -> 2.7288265 | ... Q109: =STDEV(Q9:Q104) -> 0.14117163
A110: Num | B110: =COUNT(B9:B104) -> 96 | C110: =COUNT(C9:C104) -> 96 | D110: =COUNT(D9:D104) -> 96 | E110: =COUNT(E9:E104) -> 96 | F110: =COUNT(F9:F104) -> 0 | G110: =COUNT(G9:G104) -> 96 | H110: =COUNT(H9:H104) -> 96 | I110: =COUNT(I9:I104) -> 96 | ... Q110: =COUNT(Q9:Q104) -> 96
A111: DCR | B111: =IF(B110>=87,">90%",IF(B110<=87,"<90%")) -> >90% | C111: =IF(C110>=87,">90%",IF(C110<=87,"<90%")) -> >90% | D111: =IF(D110>=87,">90%",IF(D110<=87,"<90%")) -> >90% | E111: =IF(E110>=87,">90%",IF(E110<=87,"<90%")) -> >90% | F111: =IF(F110>=87,">90%",IF(F110<=87,"<90%")) -> <90% | G111: =IF(G110>=87,">90%",IF(G110<=87,"<90%")) -> >90% | H111: =IF(H110>=87,">90%",IF(H110<=87,"<90%")) -> >90% | I111: =IF(I110>=87,">90%",IF(I110<=87,"<90%")) -> >90% | ... Q111: =IF(Q110>=87,">90%",IF(Q110<=87,"<90%")) -> >90%
A112: Status | B112: =IF(B110>=87,"OK",IF(B110<=87,"LESS")) -> OK | C112: =IF(C110>=87,"OK",IF(C110<=87,"LESS")) -> OK | D112: =IF(D110>=87,"OK",IF(D110<=87,"LESS")) -> OK | E112: =IF(E110>=87,"OK",IF(E110<=87,"LESS")) -> OK | F112: =IF(F110>=87,"OK",IF(F110<=87,"LESS")) -> LESS | G112: =IF(G110>=87,"OK",IF(G110<=87,"LESS")) -> OK | H112: =IF(H110>=87,"OK",IF(H110<=87,"LESS")) -> OK | I112: =IF(I110>=87,"OK",IF(I110<=87,"LESS")) -> OK | ... Q112: =IF(Q110>=87,"OK",IF(Q110<=87,"LESS")) -> OK
A115: Done by | B115: AKASH
A117: Comment

Sheet 03
A1: Station: | B1: IGKV RAIPUR
A2: Date: | B2: =$A$9 -> 03/03/2025 00:15 | C2: Power Off | G2: Pw.Off | J2: Link Fail | L2: Link F | N2: Maintenance | P2: Maint.
A3: Report Type: | B3: Mean | C3: Calibration | G3: Calib. | J3: Data Fail | L3: Data F | N3: Invalid | P3: Invalid
A4: Time Base: | B4: 15 Min | C4: Zero Referrence | G4: Z.Ref | J4: Warm Up | L4: Wm. Up
A7: Date & Time | B7: NO | C7: NO2 | D7: NOX | E7: SO2 | F7: O3 | G7: PM 10 | H7: PM 2.5 | I7: BENZ | J7: WS | K7: WD | L7: TEMP | M7: HUM | N7: SR | O7: RG | P7: CO | Q7: NH3
B8: ug/m3 | C8: ug/m3 | D8: ppb | E8: ug/m3 | F8: ug/m3 | G8: ug/m3 | H8: ug/m3 | I8: ug/m3 | J8: m/sec | K8: deg | L8: degreC | M8: % | N8: w/m2 | O8: mm | P8: mg/m3 | Q8: ug/m3
A9: 03/03/2025 00:15 | B9: 6.75 | C9: 17.45 | D9: 15.88 | E9: 9.44 | F9: Maint. | G9: 69.19 | H9: 27.62 | I9: 10.81 | J9: 0.21 | K9: 20.85 | L9: 24.4 | M9: 58.58 | N9: 0.4 | O9: 0 | P9: 0.87 | Q9: 28.13
A10: 03/03/2025 00:30 | B10: 7 | C10: 18.12 | D10: 16.43 | E10: 9.53 | F10: Maint. | G10: 69.19 | H10: 27.62 | I10: 10.85 | J10: 0.15 | K10: 169.82 | L10: 25.09 | M10: 55.99 | N10: 0.8 | O10: 0 | P10: 0.88 | Q10: 28.14
A11: 03/03/2025 00:45 | B11: 7.49 | C11: 18.95 | D11: 17.26 | E11: 9.95 | F11: Maint. | G11: 67.55 | H11: 24.04 | I11: 10.84 | J11: 0.14 | K11: 106.29 | L11: 24.94 | M11: 57 | N11: 1.2 | O11: 0 | P11: 0.89 | Q11: 28.16
A12: 03/03/2025 01:00 | B12: 8.35 | C12: 19.98 | D12: 18.48 | E12: 10.18 | F12: Maint. | G12: 67.35 | H12: 24.04 | I12: 10.93 | J12: 0.07 | K12: 184 | L12: 25.23 | M12: 55.71 | N12: 0.9 | O12: 0 | P12: 0.93 | Q12: 28.18
A13: 03/03/2025 01:15 | B13: 9.24 | C13: 20.84 | D13: 19.65 | E13: 9.76 | F13: Maint. | G13: 67.35 | H13: 24.04 | I13: 11.29 | J13: 0.17 | K13: 170.46 | L13: 24.43 | M13: 63.84 | N13: 1.8 | O13: 0 | P13: 0.9 | Q13: 28.22
A14: 03/03/2025 01:30 | B14: 9.59 | C14: 21.67 | D14: 20.36 | E14: 9.73 | F14: Maint. | G14: 67.35 | H14: 24.04 | I14: 11.56 | J14: 0.18 | K14: 173.17 | L14: 24.47 | M14: 60.73 | N14: 1.2 | O14: 0 | P14: 0.88 | Q14: 28.2
A15: 03/03/2025 01:45 | B15: 9.83 | C15: 22.26 | D15: 20.86 | E15: 9.58 | F15: Maint. | G15: 71.12 | H15: 25.83 | I15: 11.47 | J15: 0.27 | K15: 201.95 | L15: 24.19 | M15: 65.59 | N15: 1.8 | O15: 0 | P15: 0.89 | Q15: 28.25
A16: 03/03/2025 02:00 | B16: 9.89 | C16: 22.64 | D16: 21.11 | E16: 9.94 | F16: Maint. | G16: 71.59 | H16: 25.83 | I16: 11.44 | J16: 0.17 | K16: 173.63 | L16: 23.67 | M16: 65.79 | N16: 1.6 | O16: 0 | P16: 0.9 | Q16: 28.25
A17: 03/03/2025 02:15 | B17: 9.84 | C17: 22.83 | D17: 21.17 | E17: 8.8 | F17: Maint. | G17: 71.59 | H17: 25.83 | I17: 11.59 | J17: 0.18 | K17: 175.53 | L17: 23.46 | M17: 68.39 | N17: 1.6 | O17: 0 | P17: 0.88 | Q17: 28.25
A18: 03/03/2025 02:30 | B18: 9.75 | C18: 22.9 | D18: 21.13 | E18: 10.42 | F18: Maint. | G18: 71.59 | H18: 25.83 | I18: 11.71 | J18: 0.18 | K18: 177.75 | L18: 23.18 | M18: 67.11 | N18: 1.3 | O18: 0 | P18: 0.89 | Q18: 28.23
A19: 03/03/2025 02:45 | B19: 9.61 | C19: 22.75 | D19: 20.94 | E19: 10.49 | F19: Maint. | G19: 68.51 | H19: 25.44 | I19: 11.8 | J19: 0.16 | K19: 187.67 | L19: 22.93 | M19: 68.83 | N19: 1.3 | O19: 0 | P19: 0.89 | Q19: 28.22
A20: 03/03/2025 03:00 | B20: 9.47 | C20: 22.72 | D20: 20.82 | E20: 10.04 | F20: Maint. | G20: 68.12 | H20: 25.44 | I20: 11.82 | J20: 0.17 | K20: 169.79 | L20: 22.89 | M20: 66.69 | N20: 1.1 | O20: 0 | P20: 0.88 | Q20: 28.23
... A104: 03/03/2025 24:00 | B104: 25.23 | C104: 25.67 | D104: 35 | E104: 7.96 | F104: Maint. | G104: 128.3 | H104: 41.28 | I104: 13.27 | J104: 0.22 | K104: 180.9 | L104: 23.46 | M104: 59.55 | N104: 1.2 | O104: 0 | P104: 1.22 | Q104: 28.97
A106: Min | B106: =MIN(B9:B104) -> 4.11 | C106: =MIN(C9:C104) -> 2.1 | D106: =MIN(D9:D104) -> 9.19 | E106: =MIN(E9:E104) -> 3.57 | F106: =MIN(F9:F104) -> 0 | G106: =MIN(G9:G104) -> 0 | H106: =MIN(H9:H104) -> 0 | I106: =MIN(I9:I104) -> 2.96 | ... Q106: =MIN(Q9:Q104) -> 27.97
A107: Max | B107: =MAX(B9:B104) -> 209.3 | C107: =MAX(C9:C104) -> 31.6 | D107: =MAX(D9:D104) -> 232.63 | E107: =MAX(E9:E104) -> 279.49 | F107: =MAX(F9:F104) -> 0 | G107: =MAX(G9:G104) -> 128.3 | H107: =MAX(H9:H104) -> 78.94 | I107: =MAX(I9:I104) -> 20.35 | ... Q107: =MAX(Q9:Q104) -> 28.97
A108: Avg | B108: =AVERAGE(B9:B104) -> 13.095 | C108: =AVERAGE(C9:C104) -> 21.596458 | D108: =AVERAGE(D9:D104) -> 23.868333 | E108: =AVERAGE(E9:E104) -> 20.080208 | F108: =AVERAGE(F9:F104) -> #DIV/0! | G108: =AVERAGE(G9:G104) -> 71.222813 | H108: =AVERAGE(H9:H104) -> 30.182917 | I108: =AVERAGE(I9:I104) -> 10.508333 | ... Q108: =AVERAGE(Q9:Q104) -> 28.213437
A109: Stdev | B109: =STDEV(B9:B104) -> 24.586766 | C109: =STDEV(C9:C104) -> 4.0279594 | D109: =STDEV(D9:D104) -> 24.758 | E109: =STDEV(E9:E104) -> 47.691165 | F109: =STDEV(F9:F104) -> #DIV/0! | G109: =STDEV(G9:G104) -> 28.278831 | H109: =STDEV(H9:H104) -> 16.85671 | I109: =STDEV(I9:I104) -> 3.5368599 | ... Q109: =STDEV(Q9:Q104) -> 0.18429283
A110: Num | B110: =COUNT(B9:B104) -> 96 | C110: =COUNT(C9:C104) -> 96 | D110: =COUNT(D9:D104) -> 96 | E110: =COUNT(E9:E104) -> 96 | F110: =COUNT(F9:F104)+96 -> 96 | G110: =COUNT(G9:G104) -> 96 | H110: =COUNT(H9:H104) -> 96 | I110: =COUNT(I9:I104) -> 96 | J110: =COUNT(J9:J104) -> 96 | K110: =COUNT(K9:K104) -> 96 | L110: =COUNT(L9:L104) -> 96 | M110: =COUNT(M9:M104) -> 96 | N110: =COUNT(N9:N104) -> 96 | ... Q110: =COUNT(Q9:Q104) -> 96
A111: DCR | B111: =IF(B110>=87,">90%",IF(B110<=87,"<90%")) -> >90% | C111: =IF(C110>=87,">90%",IF(C110<=87,"<90%")) -> >90% | D111: =IF(D110>=87,">90%",IF(D110<=87,"<90%")) -> >90% | E111: =IF(E110>=87,">90%",IF(E110<=87,"<90%")) -> >90% | F111: =IF(F110>=87,">90%",IF(F110<=87,"<90%")) -> >90% | G111: =IF(G110>=87,">90%",IF(G110<=87,"<90%")) -> >90% | H111: =IF(H110>=87,">90%",IF(H110<=87,"<90%")) -> >90% | I111: =IF(I110>=87,">90%",IF(I110<=87,"<90%")) -> >90% | ... Q111: =IF(Q110>=87,">90%",IF(Q110<=87,"<90%")) -> >90%
A112: Status | B112: =IF(B110>=87,"OK",IF(B110<=87,"LESS")) -> OK | C112: =IF(C110>=87,"OK",IF(C110<=87,"LESS")) -> OK | D112: =IF(D110>=87,"OK",IF(D110<=87,"LESS")) -> OK | E112: =IF(E110>=87,"OK",IF(E110<=87,"LESS")) -> OK | F112: =IF(F110>=87,"OK",IF(F110<=87,"LESS")) -> OK | G112: =IF(G110>=87,"OK",IF(G110<=87,"LESS")) -> OK | H112: =IF(H110>=87,"OK",IF(H110<=87,"LESS")) -> OK | I112: =IF(I110>=87,"OK",IF(I110<=87,"LESS")) -> OK | ... Q112: =IF(Q110>=87,"OK",IF(Q110<=87,"LESS")) -> OK
A115: Done by | B115: AKASH
A117: Comment

Sheet 04
A1: Station: | B1: IGKV RAIPUR
A2: Date: | B2: =$A$9 -> 04/03/2025 00:15 | C2: Power Off | G2: Pw.Off | J2: Link Fail | L2: Link F | N2: Maintenance | P2: Maint.
A3: Report Type: | B3: Mean | C3: Calibration | G3: Calib. | J3: Data Fail | L3: Data F | N3: Invalid | P3: Invalid
A4: Time Base: | B4: 15 Min | C4: Zero Referrence | G4: Z.Ref | J4: Warm Up | L4: Wm. Up
A7: Date & Time | B7: NO | C7: NO2 | D7: NOX | E7: SO2 | F7: O3 | G7: PM 10 | H7: PM 2.5 | I7: BENZ | J7: WS | K7: WD | L7: TEMP | M7: HUM | N7: SR | O7: RG | P7: CO | Q7: NH3
B8: ug/m3 | C8: ug/m3 | D8: ppb | E8: ug/m3 | F8: ug/m3 | G8: ug/m3 | H8: ug/m3 | I8: ug/m3 | J8: m/sec | K8: deg | L8: degreC | M8: % | N8: w/m2 | O8: mm | P8: mg/m3 | Q8: ug/m3
A9: 04/03/2025 00:15 | B9: 25.39 | C9: 24.87 | D9: 34.7 | E9: 8.13 | F9: Invalid | G9: 131.94 | H9: 44.23 | I9: 13.61 | J9: 0.24 | K9: 163.97 | L9: 23.07 | M9: 59.97 | N9: 1 | O9: 0 | P9: 1.24 | Q9: 28.97
A10: 04/03/2025 00:30 | B10: 25.72 | C10: 25.42 | D10: 35.26 | E10: 8.24 | F10: Invalid | G10: 132.25 | H10: 44.23 | I10: 13.89 | J10: 0.15 | K10: 111.17 | L10: 23.11 | M10: 57.92 | N10: 0.8 | O10: 0 | P10: 1.25 | Q10: 28.97
A11: 04/03/2025 00:45 | B11: 26.6 | C11: 25.78 | D11: 36.15 | E11: 8.06 | F11: Invalid | G11: 132.25 | H11: 44.23 | I11: 14.15 | J11: 0.2 | K11: 119.07 | L11: 23.3 | M11: 54.91 | N11: 0.7 | O11: 0 | P11: 1.26 | Q11: 28.99
A12: 04/03/2025 01:00 | B12: 27.18 | C12: 25.73 | D12: 36.59 | E12: 8.01 | F12: Invalid | G12: 132.25 | H12: 44.23 | I12: 14.31 | J12: 0.09 | K12: 114.86 | L12: 23.15 | M12: 54.36 | N12: 0.8 | O12: 0 | P12: 1.26 | Q12: 29.04
A13: 04/03/2025 01:15 | B13: 27.3 | C13: 25.64 | D13: 36.64 | E13: 7.78 | F13: Invalid | G13: 121.66 | H13: 41.27 | I13: 14.39 | J13: 0.16 | K13: 124.51 | L13: 23.08 | M13: 53.77 | N13: 0.8 | O13: 0 | P13: 1.25 | Q13: 29.05
A14: 04/03/2025 01:30 | B14: 27.21 | C14: 25.46 | D14: 36.47 | E14: 8.01 | F14: Invalid | G14: 120.76 | H14: 41.27 | I14: 14.44 | J14: 0.35 | K14: 68.21 | L14: 23.25 | M14: 50.57 | N14: 0.4 | O14: 0 | P14: 1.25 | Q14: 29.02
A15: 04/03/2025 01:45 | B15: 27.28 | C15: 25.46 | D15: 36.53 | E15: 7.76 | F15: Invalid | G15: 120.76 | H15: 41.27 | I15: 14.41 | J15: 0.02 | K15: 353.27 | L15: 23.3 | M15: 50.65 | N15: 0.8 | O15: 0 | P15: 1.23 | Q15: 29.04
A16: 04/03/2025 02:00 | B16: 27.34 | C16: 25.53 | D16: 36.61 | E16: 7.97 | F16: Invalid | G16: 120.76 | H16: 41.27 | I16: 14.32 | J16: 0.22 | K16: 161.58 | L16: 22.6 | M16: 55.93 | N16: 1.1 | O16: 0 | P16: 1.23 | Q16: 29.03
A17: 04/03/2025 02:15 | B17: 27.54 | C17: 24.97 | D17: 36.48 | E17: 6.72 | F17: Invalid | G17: 109.63 | H17: 38.06 | I17: 14.24 | J17: 0.17 | K17: 155.13 | L17: 21.91 | M17: 57.41 | N17: 1.1 | O17: 0 | P17: 1.22 | Q17: 29.03
A18: 04/03/2025 02:30 | B18: 27.85 | C18: 24.84 | D18: 36.66 | E18: 8.4 | F18: Invalid | G18: 108.54 | H18: 38.06 | I18: 14.15 | J18: 0.28 | K18: 165.89 | L18: 21.48 | M18: 62.58 | N18: 1 | O18: 0 | P18: 1.22 | Q18: 29.06
A19: 04/03/2025 02:45 | B19: 27.96 | C19: 24.44 | D19: 36.54 | E19: 8.62 | F19: Invalid | G19: 108.54 | H19: 38.06 | I19: 14.09 | J19: 0.17 | K19: 143.39 | L19: 21.17 | M19: 61.36 | N19: 1 | O19: 0 | P19: 1.21 | Q19: 29.04
A20: 04/03/2025 03:00 | B20: 28.04 | C20: 24.3 | D20: 36.53 | E20: 8.53 | F20: Invalid | G20: 108.54 | H20: 38.06 | I20: 14.04 | J20: 0.06 | K20: 185.24 | L20: 21.06 | M20: 62.33 | N20: 0.8 | O20: 0 | P20: 1.2 | Q20: 29.05
... A104: 04/03/2025 24:00 | B104: 7.29 | C104: 18.95 | D104: 17.1 | E104: 9.4 | F104: Invalid | G104: 81.95 | H104: 26.39 | I104: 8.6 | J104: 0.5 | K104: 21.89 | L104: 26.8 | M104: 38.29 | N104: 1.3 | O104: 0 | P104: 0.65 | Q104: 28.17
A106: Min | B106: =MIN(B9:B104) -> 3.38 | C106: =MIN(C9:C104) -> 16.04 | D106: =MIN(D9:D104) -> 12.44 | E106: =MIN(E9:E104) -> 6.72 | F106: =MIN(F9:F104) -> 0 | G106: =MIN(G9:G104) -> 50.5 | H106: =MIN(H9:H104) -> 16.54 | I106: =MIN(I9:I104) -> 6.24 | ... Q106: =MIN(Q9:Q104) -> 27.98
A107: Max | B107: =MAX(B9:B104) -> 28.27 | C107: =MAX(C9:C104) -> 25.78 | D107: =MAX(D9:D104) -> 36.66 | E107: =MAX(E9:E104) -> 15.07 | F107: =MAX(F9:F104) -> 0 | G107: =MAX(G9:G104) -> 132.25 | H107: =MAX(H9:H104) -> 44.23 | I107: =MAX(I9:I104) -> 14.44 | ... Q107: =MAX(Q9:Q104) -> 29.08
A108: Avg | B108: =AVERAGE(B9:B104) -> 12.548958 | C108: =AVERAGE(C9:C104) -> 21.190417 | D108: =AVERAGE(D9:D104) -> 22.48625 | E108: =AVERAGE(E9:E104) -> 8.8714583 | F108: =AVERAGE(F9:F104) -> #DIV/0! | G108: =AVERAGE(G9:G104) -> 80.352812 | H108: =AVERAGE(H9:H104) -> 26.25125 | I108: =AVERAGE(I9:I104) -> 10.235625 | ... Q108: =AVERAGE(Q9:Q104) -> 28.393646
A109: Stdev | B109: =STDEV(B9:B104) -> 10.119706 | C109: =STDEV(C9:C104) -> 2.5546795 | D109: =STDEV(D9:D104) -> 9.0130336 | E109: =STDEV(E9:E104) -> 1.2460675 | F109: =STDEV(F9:F104) -> #DIV/0! | G109: =STDEV(G9:G104) -> 20.529874 | H109: =STDEV(H9:H104) -> 7.2283805 | I109: =STDEV(I9:I104) -> 2.6533565 | ... Q109: =STDEV(Q9:Q104) -> 0.43670084
A110: Num | B110: =COUNT(B9:B104) -> 96 | C110: =COUNT(C9:C104) -> 96 | D110: =COUNT(D9:D104) -> 96 | E110: =COUNT(E9:E104) -> 96 | F110: =COUNT(F9:F104) -> 0 | G110: =COUNT(G9:G104) -> 96 | H110: =COUNT(H9:H104) -> 96 | I110: =COUNT(I9:I104) -> 96 | ... Q110: =COUNT(Q9:Q104) -> 96
A111: DCR | B111: =IF(B110>=87,">90%",IF(B110<=87,"<90%")) -> >90% | C111: =IF(C110>=87,">90%",IF(C110<=87,"<90%")) -> >90% | D111: =IF(D110>=87,">90%",IF(D110<=87,"<90%")) -> >90% | E111: =IF(E110>=87,">90%",IF(E110<=87,"<90%")) -> >90% | F111: =IF(F110>=87,">90%",IF(F110<=87,"<90%")) -> <90% | G111: =IF(G110>=87,">90%",IF(G110<=87,"<90%")) -> >90% | H111: =IF(H110>=87,">90%",IF(H110<=87,"<90%")) -> >90% | I111: =IF(I110>=87,">90%",IF(I110<=87,"<90%")) -> >90% | ... Q111: =IF(Q110>=87,">90%",IF(Q110<=87,"<90%")) -> >90%
A112: Status | B112: =IF(B110>=87,"OK",IF(B110<=87,"LESS")) -> OK | C112: =IF(C110>=87,"OK",IF(C110<=87,"LESS")) -> OK | D112: =IF(D110>=87,"OK",IF(D110<=87,"LESS")) -> OK | E112: =IF(E110>=87,"OK",IF(E110<=87,"LESS")) -> OK | F112: =IF(F110>=87,"OK",IF(F110<=87,"LESS")) -> LESS | G112: =IF(G110>=87,"OK",IF(G110<=87,"LESS")) -> OK | H112: =IF(H110>=87,"OK",IF(H110<=87,"LESS")) -> OK | I112: =IF(I110>=87,"OK",IF(I110<=87,"LESS")) -> OK | ... Q112: =IF(Q110>=87,"OK",IF(Q110<=87,"LESS")) -> OK
A115: Done by | B115: AKASH
A117: Comment

Sheet 05
A1: Station: | B1: IGKV RAIPUR
A2: Date: | B2: =$A$9 -> 05/03/2025 00:15 | C2: Power Off | G2: Pw.Off | J2: Link Fail | L2: Link F | N2: Maintenance | P2: Maint.
A3: Report Type: | B3: Mean | C3: Calibration | G3: Calib. | J3: Data Fail | L3: Data F | N3: Invalid | P3: Invalid
A4: Time Base: | B4: 15 Min | C4: Zero Referrence | G4: Z.Ref | J4: Warm Up | L4: Wm. Up
A7: Date & Time | B7: NO | C7: NO2 | D7: NOX | E7: SO2 | F7: O3 | G7: PM 10 | H7: PM 2.5 | I7: BENZ | J7: WS | K7: WD | L7: TEMP | M7: HUM | N7: SR | O7: RG | P7: CO | Q7: NH3
B8: ug/m3 | C8: ug/m3 | D8: ppb | E8: ug/m3 | F8: ug/m3 | G8: ug/m3 | H8: ug/m3 | I8: ug/m3 | J8: m/sec | K8: deg | L8: degreC | M8: % | N8: w/m2 | O8: mm | P8: mg/m3 | Q8: ug/m3
A9: 05/03/2025 00:15 | B9: 7.76 | C9: 18.97 | D9: 17.48 | E9: 9.18 | F9: Invalid | G9: 76.59 | H9: 26.21 | I9: 8.56 | J9: 0.28 | K9: 2.65 | L9: 26.42 | M9: 39.62 | N9: 1.3 | O9: 0 | P9: 0.65 | Q9: 28.18
A10: 05/03/2025 00:30 | B10: 8.04 | C10: 19.15 | D10: 17.8 | E10: 8.96 | F10: Invalid | G10: 76.07 | H10: 26.21 | I10: 8.47 | J10: 0.22 | K10: 2.19 | L10: 26.06 | M10: 40.99 | N10: 1.2 | O10: 0 | P10: 0.65 | Q10: 28.18
A11: 05/03/2025 00:45 | B11: 8.39 | C11: 19.32 | D11: 18.17 | E11: 9.04 | F11: Invalid | G11: 76.07 | H11: 26.21 | I11: 8.47 | J11: 0.27 | K11: 11.31 | L11: 25.75 | M11: 42.03 | N11: 1 | O11: 0 | P11: 0.66 | Q11: 28.2
A12: 05/03/2025 01:00 | B12: 8.9 | C12: 19.28 | D12: 18.56 | E12: 11.76 | F12: Invalid | G12: 76.07 | H12: 26.21 | I12: 8.55 | J12: 0.46 | K12: 30.66 | L12: 25.61 | M12: 42.22 | N12: 0.8 | O12: 0 | P12: 0.67 | Q12: 28.21
A13: 05/03/2025 01:15 | B13: 9.14 | C13: 19.09 | D13: 18.66 | E13: 12.68 | F13: Invalid | G13: 84.6 | H13: 28.6 | I13: 8.64 | J13: 0.86 | K13: 26.35 | L13: 25.63 | M13: 41.68 | N13: 0.7 | O13: 0 | P13: 0.68 | Q13: 28.21
A14: 05/03/2025 01:30 | B14: 9.49 | C14: 19.12 | D14: 18.95 | E14: 13.94 | F14: Invalid | G14: 85.43 | H14: 28.6 | I14: 8.7 | J14: 0.67 | K14: 43.63 | L14: 25.44 | M14: 42.46 | N14: 1.1 | O14: 0 | P14: 0.67 | Q14: 28.24
A15: 05/03/2025 01:45 | B15: 9.88 | C15: 19.01 | D15: 19.21 | E15: 10.07 | F15: Invalid | G15: 85.43 | H15: 28.6 | I15: 8.71 | J15: 0.63 | K15: 45.71 | L15: 25.1 | M15: 43.73 | N15: 1.2 | O15: 0 | P15: 0.67 | Q15: 28.25
A16: 05/03/2025 02:00 | B16: 10.33 | C16: 19.05 | D16: 19.59 | E16: 9 | F16: Invalid | G16: 85.43 | H16: 28.6 | I16: 8.67 | J16: 0.54 | K16: 45.44 | L16: 24.71 | M16: 45.09 | N16: 1.1 | O16: 0 | P16: 0.66 | Q16: 28.28
A17: 05/03/2025 02:15 | B17: 10.49 | C17: 18.81 | D17: 19.59 | E17: 8.13 | F17: Invalid | G17: 87.37 | H17: 27.42 | I17: 8.47 | J17: 0.55 | K17: 43.51 | L17: 24.43 | M17: 46.2 | N17: 1 | O17: 0 | P17: 0.65 | Q17: 28.28
A18: 05/03/2025 02:30 | B18: 10.72 | C18: 18.59 | D18: 19.66 | E18: 9.41 | F18: Invalid | G18: 87.56 | H18: 27.42 | I18: 8.17 | J18: 0.81 | K18: 53.88 | L18: 24.15 | M18: 47.26 | N18: 1 | O18: 0 | P18: 0.65 | Q18: 28.29
A19: 05/03/2025 02:45 | B19: 10.69 | C19: 18.6 | D19: 19.64 | E19: 8.89 | F19: Invalid | G19: 87.56 | H19: 27.42 | I19: 8.19 | J19: 0.83 | K19: 53.54 | L19: 23.89 | M19: 48.39 | N19: 1.1 | O19: 0 | P19: 0.64 | Q19: 28.29
A20: 05/03/2025 03:00 | B20: 10.24 | C20: 18.81 | D20: 19.39 | E20: 8.75 | F20: Invalid | G20: 87.56 | H20: 27.42 | I20: 8.2 | J20: 1 | K20: 31.3 | L20: 23.68 | M20: 48.17 | N20: 0.8 | O20: 0 | P20: 0.64 | Q20: 28.28
... A104: 05/03/2025 24:00 | B104: 15.43 | C104: 18.88 | D104: 23.59 | E104: 8.44 | F104: Invalid | G104: 66.73 | H104: 21.43 | I104: 6.31 | J104: 0.36 | K104: 348.61 | L104: 22.05 | M104: 20.23 | N104: 0.4 | O104: 0 | P104: 0.63 | Q104: 28.29
A106: Min | B106: =MIN(B9:B104) -> 4.12 | C106: =MIN(C9:C104) -> 16.39 | D106: =MIN(D9:D104) -> 14.13 | E106: =MIN(E9:E104) -> 7.24 | F106: =MIN(F9:F104) -> 0 | G106: =MIN(G9:G104) -> 55.95 | H106: =MIN(H9:H104) -> 12.99 | I106: =MIN(I9:I104) -> 4.75 | ... Q106: =MIN(Q9:Q104) -> 28
A107: Max | B107: =MAX(B9:B104) -> 16.32 | C107: =MAX(C9:C104) -> 22.5 | D107: =MAX(D9:D104) -> 25.48 | E107: =MAX(E9:E104) -> 13.94 | F107: =MAX(F9:F104) -> 0 | G107: =MAX(G9:G104) -> 112.81 | H107: =MAX(H9:H104) -> 31.69 | I107: =MAX(I9:I104) -> 9.27 | ... Q107: =MAX(Q9:Q104) -> 28.54
A108: Avg | B108: =AVERAGE(B9:B104) -> 9.6215625 | C108: =AVERAGE(C9:C104) -> 19.787292 | D108: =AVERAGE(D9:D104) -> 19.405625 | E108: =AVERAGE(E9:E104) -> 9.0085417 | F108: =AVERAGE(F9:F104) -> #DIV/0! | G108: =AVERAGE(G9:G104) -> 81.115521 | H108: =AVERAGE(H9:H104) -> 23.595417 | I108: =AVERAGE(I9:I104) -> 7.0302083 | ... Q108: =AVERAGE(Q9:Q104) -> 28.226875
A109: Stdev | B109: =STDEV(B9:B104) -> 3.7201503 | C109: =STDEV(C9:C104) -> 1.5218752 | D109: =STDEV(D9:D104) -> 3.2125274 | E109: =STDEV(E9:E104) -> 1.1415308 | F109: =STDEV(F9:F104) -> #DIV/0! | G109: =STDEV(G9:G104) -> 15.992337 | H109: =STDEV(H9:H104) -> 4.8005114 | I109: =STDEV(I9:I104) -> 1.3179761 | ... Q109: =STDEV(Q9:Q104) -> 0.15020906
A110: Num | B110: =COUNT(B9:B104) -> 96 | C110: =COUNT(C9:C104) -> 96 | D110: =COUNT(D9:D104) -> 96 | E110: =COUNT(E9:E104) -> 96 | F110: =COUNT(F9:F104) -> 0 | G110: =COUNT(G9:G104) -> 96 | H110: =COUNT(H9:H104) -> 96 | I110: =COUNT(I9:I104) -> 96 | ... Q110: =COUNT(Q9:Q104) -> 96
A111: DCR | B111: =IF(B110>=87,">90%",IF(B110<=87,"<90%")) -> >90% | C111: =IF(C110>=87,">90%",IF(C110<=87,"<90%")) -> >90% | D111: =IF(D110>=87,">90%",IF(D110<=87,"<90%")) -> >90% | E111: =IF(E110>=87,">90%",IF(E110<=87,"<90%")) -> >90% | F111: =IF(F110>=87,">90%",IF(F110<=87,"<90%")) -> <90% | G111: =IF(G110>=87,">90%",IF(G110<=87,"<90%")) -> >90% | H111: =IF(H110>=87,">90%",IF(H110<=87,"<90%")) -> >90% | I111: =IF(I110>=87,">90%",IF(I110<=87,"<90%")) -> >90% | ... Q111: =IF(Q110>=87,">90%",IF(Q110<=87,"<90%")) -> >90%
A112: Status | B112: =IF(B110>=87,"OK",IF(B110<=87,"LESS")) -> OK | C112: =IF(C110>=87,"OK",IF(C110<=87,"LESS")) -> OK | D112: =IF(D110>=87,"OK",IF(D110<=87,"LESS")) -> OK | E112: =IF(E110>=87,"OK",IF(E110<=87,"LESS")) -> OK | F112: =IF(F110>=87,"OK",IF(F110<=87,"LESS")) -> LESS | G112: =IF(G110>=87,"OK",IF(G110<=87,"LESS")) -> OK | H112: =IF(H110>=87,"OK",IF(H110<=87,"LESS")) -> OK | I112: =IF(I110>=87,"OK",IF(I110<=87,"LESS")) -> OK | ... Q112: =IF(Q110>=87,"OK",IF(Q110<=87,"LESS")) -> OK
A115: Done by | B115: AKASH
A117: Comment

Sheet 06
A1: Station: | B1: IGKV RAIPUR
A2: Date: | B2: =$A$9 -> 06/03/2025 00:15 | C2: Power Off | G2: Pw.Off | J2: Link Fail | L2: Link F | N2: Maintenance | P2: Maint.
A3: Report Type: | B3: Mean | C3: Calibration | G3: Calib. | J3: Data Fail | L3: Data F | N3: Invalid | P3: Invalid
A4: Time Base: | B4: 15 Min | C4: Zero Referrence | G4: Z.Ref | J4: Warm Up | L4: Wm. Up
A7: Date & Time | B7: NO | C7: NO2 | D7: NOX | E7: SO2 | F7: O3 | G7: PM 10 | H7: PM 2.5 | I7: BENZ | J7: WS | K7: WD | L7: TEMP | M7: HUM | N7: SR | O7: RG | P7: CO | Q7: NH3
B8: ug/m3 | C8: ug/m3 | D8: ppb | E8: ug/m3 | F8: ug/m3 | G8: ug/m3 | H8: ug/m3 | I8: ug/m3 | J8: m/sec | K8: deg | L8: degreC | M8: % | N8: w/m2 | O8: mm | P8: mg/m3 | Q8: ug/m3
A9: 06/03/2025 00:15 | B9: 9.36 | C9: 18.53 | D9: 18.54 | E9: 8.18 | F9: Invalid | G9: 65.13 | H9: 19.17 | I9: 6.26 | J9: 0.23 | K9: 358.33 | L9: 21.72 | M9: 20.58 | N9: 0.5 | O9: 0 | P9: 0.61 | Q9: 28.27
A10: 06/03/2025 00:30 | B10: 9.14 | C10: 18.19 | D10: 18.18 | E10: 7.92 | F10: Invalid | G10: 64.97 | H10: 19.17 | I10: 6.2 | J10: 0.34 | K10: 338.08 | L10: 21.35 | M10: 21.11 | N10: 0.4 | O10: 0 | P10: 0.6 | Q10: 28.26
A11: 06/03/2025 00:45 | B11: 8.88 | C11: 17.8 | D11: 17.77 | E11: 7.83 | F11: Invalid | G11: 64.97 | H11: 19.17 | I11: 6.14 | J11: 0.31 | K11: 302.83 | L11: 21.21 | M11: 21.61 | N11: 0.3 | O11: 0 | P11: 0.6 | Q11: 28.24
A12: 06/03/2025 01:00 | B12: 8.68 | C12: 17.63 | D12: 17.52 | E12: 8.05 | F12: Invalid | G12: 64.97 | H12: 19.17 | I12: 6.1 | J12: 0.26 | K12: 24.3 | L12: 20.85 | M12: 22.14 | N12: 0.5 | O12: 0 | P12: 0.59 | Q12: 28.22
A13: 06/03/2025 01:15 | B13: 8.96 | C13: 16.96 | D13: 17.4 | E13: 7.94 | F13: Invalid | G13: 55.82 | H13: 19.09 | I13: 6.04 | J13: 0.46 | K13: 22.97 | L13: 20.67 | M13: 21.86 | N13: 0.3 | O13: 0 | P13: 0.58 | Q13: 28.19
A14: 06/03/2025 01:30 | B14: 9.01 | C14: 16.55 | D14: 17.22 | E14: 8.32 | F14: Invalid | G14: 54.92 | H14: 19.09 | I14: 6 | J14: 0.61 | K14: 34.89 | L14: 20.59 | M14: 21.49 | N14: 0.2 | O14: 0 | P14: 0.58 | Q14: 28.19
A15: 06/03/2025 01:45 | B15: 9.43 | C15: 16.14 | D15: 17.35 | E15: 8.53 | F15: Invalid | G15: 54.92 | H15: 19.09 | I15: 5.99 | J15: 0.62 | K15: 49.2 | L15: 20.27 | M15: 22.96 | N15: 0.6 | O15: 0 | P15: 0.59 | Q15: 28.17
A16: 06/03/2025 02:00 | B16: 9.73 | C16: 15.81 | D16: 17.42 | E16: 8.22 | F16: Invalid | G16: 54.92 | H16: 19.09 | I16: 5.96 | J16: 0.34 | K16: 14.61 | L16: 19.9 | M16: 24.07 | N16: 0.6 | O16: 0 | P16: 0.59 | Q16: 28.17
A17: 06/03/2025 02:15 | B17: 10.54 | C17: 15.09 | D17: 17.69 | E17: 8.13 | F17: Invalid | G17: 53.51 | H17: 17.76 | I17: 5.94 | J17: 0.55 | K17: 35.59 | L17: 19.74 | M17: 24.22 | N17: 0.3 | O17: 0 | P17: 0.59 | Q17: 28.16
A18: 06/03/2025 02:30 | B18: 10.31 | C18: 15.05 | D18: 17.49 | E18: 9.48 | F18: Invalid | G18: 53.37 | H18: 17.76 | I18: 5.92 | J18: 0.35 | K18: 9.34 | L18: 19.66 | M18: 24.3 | N18: 0.4 | O18: 0 | P18: 0.6 | Q18: 28.12
A19: 06/03/2025 02:45 | B19: 8.68 | C19: 15.34 | D19: 16.32 | E19: 9.74 | F19: Invalid | G19: 53.37 | H19: 17.76 | I19: 5.92 | J19: 0.05 | K19: 228.02 | L19: 19.43 | M19: 25.49 | N19: 0.6 | O19: 0 | P19: 0.6 | Q19: 28.12
A20: 06/03/2025 03:00 | B20: 6.5 | C20: 16.16 | D20: 15 | E20: 9.88 | F20: Invalid | G20: 53.37 | H20: 17.76 | I20: 5.95 | J20: 0.21 | K20: 203.4 | L20: 18.97 | M20: 27.37 | N20: 0.6 | O20: 0 | P20: 0.61 | Q20: 28.11
... A104: 06/03/2025 24:00 | B104: 4.03 | C104: 17.64 | D104: 13.8 | E104: 9.04 | F104: Invalid | G104: 86.63 | H104: 22.32 | I104: 9.51 | J104: 0.22 | K104: 178.93 | L104: 18.43 | M104: 51.18 | N104: 0.6 | O104: 0 | P104: 0.81 | Q104: 28.19
A106: Min | B106: =MIN(B9:B104) -> 2 | C106: =MIN(C9:C104) -> 11.18 | D106: =MIN(D9:D104) -> 11.89 | E106: =MIN(E9:E104) -> 7.57 | F106: =MIN(F9:F104) -> 0 | G106: =MIN(G9:G104) -> 40.43 | H106: =MIN(H9:H104) -> 10.49 | I106: =MIN(I9:I104) -> 5.61 | ... Q106: =MIN(Q9:Q104) -> 27.99
A107: Max | B107: =MAX(B9:B104) -> 16.23 | C107: =MAX(C9:C104) -> 18.59 | D107: =MAX(D9:D104) -> 23.51 | E107: =MAX(E9:E104) -> 14.97 | F107: =MAX(F9:F104) -> 0 | G107: =MAX(G9:G104) -> 93.43 | H107: =MAX(H9:H104) -> 30.7 | I107: =MAX(I9:I104) -> 10.28 | ... Q107: =MAX(Q9:Q104) -> 28.41
A108: Avg | B108: =AVERAGE(B9:B104) -> 9.4038542 | C108: =AVERAGE(C9:C104) -> 15.507812 | D108: =AVERAGE(D9:D104) -> 16.994688 | E108: =AVERAGE(E9:E104) -> 9.0748958 | F108: =AVERAGE(F9:F104) -> #DIV/0! | G108: =AVERAGE(G9:G104) -> 61.637188 | H108: =AVERAGE(H9:H104) -> 18.385 | I108: =AVERAGE(I9:I104) -> 7.0647917 | ... Q108: =AVERAGE(Q9:Q104) -> 28.144583
A109: Stdev | B109: =STDEV(B9:B104) -> 3.4087622 | C109: =STDEV(C9:C104) -> 2.1678999 | D109: =STDEV(D9:D104) -> 2.6895364 | E109: =STDEV(E9:E104) -> 1.2442888 | F109: =STDEV(F9:F104) -> #DIV/0! | G109: =STDEV(G9:G104) -> 15.027073 | H109: =STDEV(H9:H104) -> 4.8351311 | I109: =STDEV(I9:I104) -> 1.2807703 | ... Q109: =STDEV(Q9:Q104) -> 0.10556033
A110: Num | B110: =COUNT(B9:B104) -> 96 | C110: =COUNT(C9:C104) -> 96 | D110: =COUNT(D9:D104) -> 96 | E110: =COUNT(E9:E104) -> 96 | F110: =COUNT(F9:F104) -> 0 | G110: =COUNT(G9:G104) -> 96 | H110: =COUNT(H9:H104) -> 96 | I110: =COUNT(I9:I104) -> 96 | ... Q110: =COUNT(Q9:Q104) -> 96
A111: DCR | B111: =IF(B110>=87,">90%",IF(B110<=87,"<90%")) -> >90% | C111: =IF(C110>=87,">90%",IF(C110<=87,"<90%")) -> >90% | D111: =IF(D110>=87,">90%",IF(D110<=87,"<90%")) -> >90% | E111: =IF(E110>=87,">90%",IF(E110<=87,"<90%")) -> >90% | F111: =IF(F110>=87,">90%",IF(F110<=87,"<90%")) -> <90% | G111: =IF(G110>=87,">90%",IF(G110<=87,"<90%")) -> >90% | H111: =IF(H110>=87,">90%",IF(H110<=87,"<90%")) -> >90% | I111: =IF(I110>=87,">90%",IF(I110<=87,"<90%")) -> >90% | ... Q111: =IF(Q110>=87,">90%",IF(Q110<=87,"<90%")) -> >90%
A112: Status | B112: =IF(B110>=87,"OK",IF(B110<=87,"LESS")) -> OK | C112: =IF(C110>=87,"OK",IF(C110<=87,"LESS")) -> OK | D112: =IF(D110>=87,"OK",IF(D110<=87,"LESS")) -> OK | E112: =IF(E110>=87,"OK",IF(E110<=87,"LESS")) -> OK | F112: =IF(F110>=87,"OK",IF(F110<=87,"LESS")) -> LESS | G112: =IF(G110>=87,"OK",IF(G110<=87,"LESS")) -> OK | H112: =IF(H110>=87,"OK",IF(H110<=87,"LESS")) -> OK | I112: =IF(I110>=87,"OK",IF(I110<=87,"LESS")) -> OK | ... Q112: =IF(Q110>=87,"OK",IF(Q110<=87,"LESS")) -> OK
A115: Done by | B115: AKASH
A117: Comment

Sheet 07
A1: Station: | B1: IGKV RAIPUR
A2: Date: | B2: =$A$9 -> 07/03/2025 00:15 | C2: Power Off | G2: Pw.Off | J2: Link Fail | L2: Link F | N2: Maintenance | P2: Maint.
A3: Report Type: | B3: Mean | C3: Calibration | G3: Calib. | J3: Data Fail | L3: Data F | N3: Invalid | P3: Invalid
A4: Time Base: | B4: 15 Min | C4: Zero Referrence | G4: Z.Ref | J4: Warm Up | L4: Wm. Up
A7: Date & Time | B7: NO | C7: NO2 | D7: NOX | E7: SO2 | F7: O3 | G7: PM 10 | H7: PM 2.5 | I7: BENZ | J7: WS | K7: WD | L7: TEMP | M7: HUM | N7: SR | O7: RG | P7: CO | Q7: NH3
B8: ug/m3 | C8: ug/m3 | D8: ppb | E8: ug/m3 | F8: ug/m3 | G8: ug/m3 | H8: ug/m3 | I8: ug/m3 | J8: m/sec | K8: deg | L8: degreC | M8: % | N8: w/m2 | O8: mm | P8: mg/m3 | Q8: ug/m3
A9: 07/03/2025 00:15 | B9: 8.3 | C9: 18.15 | D9: 17.49 | E9: 9.23 | F9: Invalid | G9: 84.62 | H9: 25.93 | I9: 9.63 | J9: 0.19 | K9: 154.37 | L9: 17.89 | M9: 54.45 | N9: 0.9 | O9: 0 | P9: 0.82 | Q9: 28.2
A10: 07/03/2025 00:30 | B10: 9.55 | C10: 17.02 | D10: 17.9 | E10: 9.23 | F10: Invalid | G10: 84.45 | H10: 25.93 | I10: 9.74 | J10: 0.14 | K10: 156.15 | L10: 17.6 | M10: 53.42 | N10: 0.6 | O10: 0 | P10: 0.84 | Q10: 28.21
A11: 07/03/2025 00:45 | B11: 10.39 | C11: 16.3 | D11: 18.2 | E11: 8.98 | F11: Invalid | G11: 84.45 | H11: 25.93 | I11: 9.89 | J11: 0.19 | K11: 166.24 | L11: 17.74 | M11: 52.54 | N11: 0.5 | O11: 0 | P11: 0.85 | Q11: 28.2
A12: 07/03/2025 01:00 | B12: 8.61 | C12: 18.12 | D12: 17.73 | E12: 9.16 | F12: Invalid | G12: 84.45 | H12: 25.93 | I12: 10 | J12: 0.2 | K12: 174.11 | L12: 17.59 | M12: 54.09 | N12: 0.6 | O12: 0 | P12: 0.86 | Q12: 28.22
A13: 07/03/2025 01:15 | B13: 7.8 | C13: 19.87 | D13: 17.99 | E13: 9.01 | F13: Invalid | G13: 83.96 | H13: 24.11 | I13: 10.12 | J13: 0.25 | K13: 177.07 | L13: 17.15 | M13: 57.33 | N13: 0.7 | O13: 0 | P13: 0.86 | Q13: 28.24
A14: 07/03/2025 01:30 | B14: 9.49 | C14: 19.09 | D14: 18.93 | E14: 9.1 | F14: Invalid | G14: 83.92 | H14: 24.11 | I14: 10.25 | J14: 0.2 | K14: 169.15 | L14: 16.81 | M14: 58.36 | N14: 0.7 | O14: 0 | P14: 0.88 | Q14: 28.27
A15: 07/03/2025 01:45 | B15: 8.81 | C15: 19.99 | D15: 18.86 | E15: 9.27 | F15: Invalid | G15: 83.92 | H15: 24.11 | I15: 10.38 | J15: 0.23 | K15: 193.88 | L15: 16.6 | M15: 59.61 | N15: 0.7 | O15: 0 | P15: 0.89 | Q15: 28.31
A16: 07/03/2025 02:00 | B16: 9.28 | C16: 19.72 | D16: 19.09 | E16: 9.06 | F16: Invalid | G16: 83.92 | H16: 24.11 | I16: 10.45 | J16: 0.16 | K16: 202.72 | L16: 16.23 | M16: 58.46 | N16: 0.7 | O16: 0 | P16: 0.9 | Q16: 28.32
A17: 07/03/2025 02:15 | B17: 10.33 | C17: 18.86 | D17: 19.49 | E17: 7.52 | F17: Invalid | G17: 73.78 | H17: 27.19 | I17: 10.56 | J17: 0.14 | K17: 198.87 | L17: 16.09 | M17: 58.8 | N17: 0.6 | O17: 0 | P17: 0.92 | Q17: 28.3
A18: 07/03/2025 02:30 | B18: 9.59 | C18: 19.44 | D18: 19.2 | E18: 8.31 | F18: Invalid | G18: 72.8 | H18: 27.19 | I18: 10.98 | J18: 0.16 | K18: 166.84 | L18: 15.63 | M18: 62.7 | N18: 0.7 | O18: 0 | P18: 0.94 | Q18: 28.3
A19: 07/03/2025 02:45 | B19: 9.22 | C19: 19.69 | D19: 19.04 | E19: 8.67 | F19: Invalid | G19: 72.8 | H19: 27.19 | I19: 13.15 | J19: 0.18 | K19: 166.34 | L19: 15.45 | M19: 63.14 | N19: 0.6 | O19: 0 | P19: 0.97 | Q19: 28.31
A20: 07/03/2025 03:00 | B20: 9.05 | C20: 19.76 | D20: 18.93 | E20: 8.51 | F20: Invalid | G20: 72.8 | H20: 27.19 | I20: 17.13 | J20: 0.16 | K20: 152.5 | L20: 15.6 | M20: 62.43 | N20: 0.6 | O20: 0 | P20: 0.99 | Q20: 28.3
... A104: 07/03/2025 24:00 | B104: 12.78 | C104: 12.7 | D104: 18.24 | E104: 8.86 | F104: Invalid | G104: 77.94 | H104: 23.47 | I104: 9.28 | J104: 0.17 | K104: 143.41 | L104: 20.19 | M104: 45.4 | N104: 0.6 | O104: 0 | P104: 0.74 | Q104: 28.08
A106: Min | B106: =MIN(B9:B104) -> 4.83 | C106: =MIN(C9:C104) -> 10.13 | D106: =MIN(D9:D104) -> 13.18 | E106: =MIN(E9:E104) -> 7.52 | F106: =MIN(F9:F104) -> 0 | G106: =MIN(G9:G104) -> 36.38 | H106: =MIN(H9:H104) -> 12.43 | I106: =MIN(I9:I104) -> 6.6 | ... Q106: =MIN(Q9:Q104) -> 27.97
A107: Max | B107: =MAX(B9:B104) -> 25.02 | C107: =MAX(C9:C104) -> 22.88 | D107: =MAX(D9:D104) -> 32.37 | E107: =MAX(E9:E104) -> 11.63 | F107: =MAX(F9:F104) -> 0 | G107: =MAX(G9:G104) -> 103.71 | H107: =MAX(H9:H104) -> 34.98 | I107: =MAX(I9:I104) -> 26.44 | ... Q107: =MAX(Q9:Q104) -> 28.93
A108: Avg | B108: =AVERAGE(B9:B104) -> 15.155104 | C108: =AVERAGE(C9:C104) -> 16.788646 | D108: =AVERAGE(D9:D104) -> 22.275938 | E108: =AVERAGE(E9:E104) -> 8.9660417 | F108: =AVERAGE(F9:F104) -> #DIV/0! | G108: =AVERAGE(G9:G104) -> 75.21625 | H108: =AVERAGE(H9:H104) -> 24.07625 | I108: =AVERAGE(I9:I104) -> 13.794375 | ... Q108: =AVERAGE(Q9:Q104) -> 28.32875
A109: Stdev | B109: =STDEV(B9:B104) -> 5.1189495 | C109: =STDEV(C9:C104) -> 3.7651383 | D109: =STDEV(D9:D104) -> 5.468627 | E109: =STDEV(E9:E104) -> 0.69157102 | F109: =STDEV(F9:F104) -> #DIV/0! | G109: =STDEV(G9:G104) -> 19.182285 | H109: =STDEV(H9:H104) -> 7.2213985 | I109: =STDEV(I9:I104) -> 6.5694907 | ... Q109: =STDEV(Q9:Q104) -> 0.31610208
A110: Num | B110: =COUNT(B9:B104) -> 96 | C110: =COUNT(C9:C104) -> 96 | D110: =COUNT(D9:D104) -> 96 | E110: =COUNT(E9:E104) -> 96 | F110: =COUNT(F9:F104) -> 0 | G110: =COUNT(G9:G104) -> 96 | H110: =COUNT(H9:H104) -> 96 | I110: =COUNT(I9:I104) -> 96 | ... Q110: =COUNT(Q9:Q104) -> 96
A111: DCR | B111: =IF(B110>=87,">90%",IF(B110<=87,"<90%")) -> >90% | C111: =IF(C110>=87,">90%",IF(C110<=87,"<90%")) -> >90% | D111: =IF(D110>=87,">90%",IF(D110<=87,"<90%")) -> >90% | E111: =IF(E110>=87,">90%",IF(E110<=87,"<90%")) -> >90% | F111: =IF(F110>=87,">90%",IF(F110<=87,"<90%")) -> <90% | G111: =IF(G110>=87,">90%",IF(G110<=87,"<90%")) -> >90% | H111: =IF(H110>=87,">90%",IF(H110<=87,"<90%")) -> >90% | I111: =IF(I110>=87,">90%",IF(I110<=87,"<90%")) -> >90% | ... Q111: =IF(Q110>=87,">90%",IF(Q110<=87,"<90%")) -> >90%
A112: Status | B112: =IF(B110>=87,"OK",IF(B110<=87,"LESS")) -> OK | C112: =IF(C110>=87,"OK",IF(C110<=87,"LESS")) -> OK | D112: =IF(D110>=87,"OK",IF(D110<=87,"LESS")) -> OK | E112: =IF(E110>=87,"OK",IF(E110<=87,"LESS")) -> OK | F112: =IF(F110>=87,"OK",IF(F110<=87,"LESS")) -> LESS | G112: =IF(G110>=87,"OK",IF(G110<=87,"LESS")) -> OK | H112: =IF(H110>=87,"OK",IF(H110<=87,"LESS")) -> OK | I112: =IF(I110>=87,"OK",IF(I110<=87,"LESS")) -> OK | ... Q112: =IF(Q110>=87,"OK",IF(Q110<=87,"LESS")) -> OK
A115: Done by | B115: AKASH
A117: Comment

Sheet 08
A1: Station: | B1: IGKV RAIPUR
A2: Date: | B2: =$A$9 -> 08/03/2025 00:15 | C2: Power Off | G2: Pw.Off | J2: Link Fail | L2: Link F | N2: Maintenance | P2: Maint.
A3: Report Type: | B3: Mean | C3: Calibration | G3: Calib. | J3: Data Fail | L3: Data F | N3: Invalid | P3: Invalid
A4: Time Base: | B4: 15 Min | C4: Zero Referrence | G4: Z.Ref | J4: Warm Up | L4: Wm. Up
A7: Date & Time | B7: NO | C7: NO2 | D7: NOX | E7: SO2 | F7: O3 | G7: PM 10 | H7: PM 2.5 | I7: BENZ | J7: WS | K7: WD | L7: TEMP | M7: HUM | N7: SR | O7: RG | P7: CO | Q7: NH3
B8: ug/m3 | C8: ug/m3 | D8: ppb | E8: ug/m3 | F8: ug/m3 | G8: ug/m3 | H8: ug/m3 | I8: ug/m3 | J8: m/sec | K8: deg | L8: degreC | M8: % | N8: w/m2 | O8: mm | P8: mg/m3 | Q8: ug/m3
A9: 08/03/2025 00:15 | B9: 5.37 | C9: 12.13 | D9: 11.99 | E9: 8.89 | F9: 0 | G9: 75.24 | H9: 21.82 | I9: 9.36 | J9: 0.18 | K9: 168.47 | L9: 20.09 | M9: 45.91 | N9: 0.6 | O9: 0 | P9: 0.75 | Q9: 28.04
A10: 08/03/2025 00:30 | B10: 4.26 | C10: 12.19 | D10: 11.13 | E10: 8.72 | F10: 0 | G10: 74.98 | H10: 21.82 | I10: 9.39 | J10: 0.14 | K10: 185.48 | L10: 19.92 | M10: 44.68 | N10: 0.6 | O10: 0 | P10: 0.76 | Q10: 28.05
A11: 08/03/2025 00:45 | B11: 4.42 | C11: 12.14 | D11: 11.24 | E11: 8.91 | F11: 0 | G11: 74.98 | H11: 21.82 | I11: 9.4 | J11: 0.17 | K11: 165.42 | L11: 20.13 | M11: 43.85 | N11: 0.4 | O11: 0 | P11: 0.76 | Q11: 28.04
A12: 08/03/2025 01:00 | B12: 4.02 | C12: 12.15 | D12: 10.92 | E12: 8.89 | F12: 0 | G12: 74.98 | H12: 21.82 | I12: 9.51 | J12: 0.18 | K12: 164.53 | L12: 19.73 | M12: 45.19 | N12: 0.8 | O12: 0 | P12: 0.76 | Q12: 28.05
A13: 08/03/2025 01:15 | B13: 3.84 | C13: 12 | D13: 10.7 | E13: 8.78 | F13: 0 | G13: 64.9 | H13: 24.48 | I13: 9.68 | J13: 0.17 | K13: 180.7 | L13: 19.65 | M13: 47.41 | N13: 0.7 | O13: 0 | P13: 0.77 | Q13: 28.04
A14: 08/03/2025 01:30 | B14: 4.34 | C14: 11.91 | D14: 11.06 | E14: 8.99 | F14: 0 | G14: 64.05 | H14: 24.48 | I14: 9.66 | J14: 0.24 | K14: 163.97 | L14: 19.53 | M14: 47.79 | N14: 0.6 | O14: 0 | P14: 0.77 | Q14: 28.02
A15: 08/03/2025 01:45 | B15: 2.45 | C15: 11.27 | D15: 9.2 | E15: 8.45 | F15: 0 | G15: 64.05 | H15: 24.48 | I15: 9.62 | J15: 0.24 | K15: 161.52 | L15: 19.47 | M15: 48.52 | N15: 0.6 | O15: 0 | P15: 0.77 | Q15: 28.02
A16: 08/03/2025 02:00 | B16: 2.25 | C16: 11.45 | D16: 9.14 | E16: 9.03 | F16: 0 | G16: 64.05 | H16: 24.48 | I16: 9.44 | J16: 0.24 | K16: 187.23 | L16: 19.09 | M16: 51.91 | N16: 0.8 | O16: 0 | P16: 0.77 | Q16: 28.02
A17: 08/03/2025 02:15 | B17: 2.18 | C17: 11.03 | D17: 8.86 | E17: 7.01 | F17: 0 | G17: 60.72 | H17: 26.66 | I17: 9.32 | J17: 0.22 | K17: 184.58 | L17: 18.6 | M17: 49.72 | N17: 0.9 | O17: 0 | P17: 0.77 | Q17: 28.02
A18: 08/03/2025 02:30 | B18: 2 | C18: 9.64 | D18: 7.99 | E18: 7.86 | F18: 0 | G18: 60.39 | H18: 26.66 | I18: 9.35 | J18: 0.27 | K18: 168.05 | L18: 18.53 | M18: 51.55 | N18: 0.7 | O18: 0 | P18: 0.78 | Q18: 28.04
A19: 08/03/2025 02:45 | B19: 3.39 | C19: 11.59 | D19: 10.13 | E19: 7.89 | F19: 0 | G19: 60.39 | H19: 26.66 | I19: 9.22 | J19: 0.24 | K19: 170.52 | L19: 18.36 | M19: 51.87 | N19: 0.8 | O19: 0 | P19: 0.78 | Q19: 28.04
A20: 08/03/2025 03:00 | B20: 2.53 | C20: 11.49 | D20: 9.38 | E20: 7.86 | F20: 0 | G20: 60.39 | H20: 26.66 | I20: 9.37 | J20: 0.26 | K20: 166.1 | L20: 18.16 | M20: 52.92 | N20: 0.8 | O20: 0 | P20: 0.78 | Q20: 28.04
... A104: 08/03/2025 24:00 | B104: 5.28 | C104: 23.83 | D104: 18.04 | E104: 8.49 | F104: 0 | G104: 113.27 | H104: 27.31 | I104: 8.21 | J104: 0.24 | K104: 146.54 | L104: 21.9 | M104: 50.88 | N104: 0.8 | O104: 0 | P104: 0.77 | Q104: 28.5
A106: Min | B106: =MIN(B9:B104) -> 2 | C106: =MIN(C9:C104) -> 5.8 | D106: =MIN(D9:D104) -> 5.98 | E106: =MIN(E9:E104) -> 7.01 | F106: =MIN(F9:F104) -> 0 | G106: =MIN(G9:G104) -> 37.69 | H106: =MIN(H9:H104) -> 12.78 | I106: =MIN(I9:I104) -> 5.6 | ... Q106: =MIN(Q9:Q104) -> 27.99
A107: Max | B107: =MAX(B9:B104) -> 11.13 | C107: =MAX(C9:C104) -> 23.83 | D107: =MAX(D9:D104) -> 20.36 | E107: =MAX(E9:E104) -> 16.72 | F107: =MAX(F9:F104) -> 0 | G107: =MAX(G9:G104) -> 115.12 | H107: =MAX(H9:H104) -> 46.09 | I107: =MAX(I9:I104) -> 13.01 | ... Q107: =MAX(Q9:Q104) -> 28.69
A108: Avg | B108: =AVERAGE(B9:B104) -> 4.4308333 | C108: =AVERAGE(C9:C104) -> 13.52625 | D108: =AVERAGE(D9:D104) -> 11.970729 | E108: =AVERAGE(E9:E104) -> 9.4219792 | F108: =AVERAGE(F9:F104) -> 0 | G108: =AVERAGE(G9:G104) -> 73.479896 | H108: =AVERAGE(H9:H104) -> 26.451667 | I108: =AVERAGE(I9:I104) -> 9.046875 | ... Q108: =AVERAGE(Q9:Q104) -> 28.146563
A109: Stdev | B109: =STDEV(B9:B104) -> 2.8442254 | C109: =STDEV(C9:C104) -> 4.070737 | D109: =STDEV(D9:D104) -> 3.9547603 | E109: =STDEV(E9:E104) -> 1.8042486 | F109: =STDEV(F9:F104) -> 0 | G109: =STDEV(G9:G104) -> 22.088572 | H109: =STDEV(H9:H104) -> 8.3986133 | I109: =STDEV(I9:I104) -> 2.0346609 | ... Q109: =STDEV(Q9:Q104) -> 0.20177543
A110: Num | B110: =COUNT(B9:B104) -> 96 | C110: =COUNT(C9:C104) -> 96 | D110: =COUNT(D9:D104) -> 96 | E110: =COUNT(E9:E104) -> 96 | F110: =COUNT(F9:F104) -> 96 | G110: =COUNT(G9:G104) -> 96 | H110: =COUNT(H9:H104) -> 96 | I110: =COUNT(I9:I104) -> 96 | ... Q110: =COUNT(Q9:Q104) -> 96
A111: DCR | B111: =IF(B110>=87,">90%",IF(B110<=87,"<90%")) -> >90% | C111: =IF(C110>=87,">90%",IF(C110<=87,"<90%")) -> >90% | D111: =IF(D110>=87,">90%",IF(D110<=87,"<90%")) -> >90% | E111: =IF(E110>=87,">90%",IF(E110<=87,"<90%")) -> >90% | F111: =IF(F110>=87,">90%",IF(F110<=87,"<90%")) -> >90% | G111: =IF(G110>=87,">90%",IF(G110<=87,"<90%")) -> >90% | H111: =IF(H110>=87,">90%",IF(H110<=87,"<90%")) -> >90% | I111: =IF(I110>=87,">90%",IF(I110<=87,"<90%")) -> >90% | ... Q111: =IF(Q110>=87,">90%",IF(Q110<=87,"<90%")) -> >90%
A112: Status | B112: =IF(B110>=87,"OK",IF(B110<=87,"LESS")) -> OK | C112: =IF(C110>=87,"OK",IF(C110<=87,"LESS")) -> OK | D112: =IF(D110>=87,"OK",IF(D110<=87,"LESS")) -> OK | E112: =IF(E110>=87,"OK",IF(E110<=87,"LESS")) -> OK | F112: =IF(F110>=87,"OK",IF(F110<=87,"LESS")) -> OK | G112: =IF(G110>=87,"OK",IF(G110<=87,"LESS")) -> OK | H112: =IF(H110>=87,"OK",IF(H110<=87,"LESS")) -> OK | I112: =IF(I110>=87,"OK",IF(I110<=87,"LESS")) -> OK | ... Q112: =IF(Q110>=87,"OK",IF(Q110<=87,"LESS")) -> OK
A115: Done by | B115: AKASH
A117: Comment

Sheet 09
A1: Station: | B1: IGKV RAIPUR
A2: Date: | B2: =$A$9 -> 09/03/2025 00:15 | C2: Power Off | G2: Pw.Off | J2: Link Fail | L2: Link F | N2: Maintenance | P2: Maint.
A3: Report Type: | B3: Mean | C3: Calibration | G3: Calib. | J3: Data Fail | L3: Data F | N3: Invalid | P3: Invalid
A4: Time Base: | B4: 15 Min | C4: Zero Referrence | G4: Z.Ref | J4: Warm Up | L4: Wm. Up
A7: Date & Time | B7: NO | C7: NO2 | D7: NOX | E7: SO2 | F7: O3 | G7: PM 10 | H7: PM 2.5 | I7: BENZ | J7: WS | K7: WD | L7: TEMP | M7: HUM | N7: SR | O7: RG | P7: CO | Q7: NH3
B8: ug/m3 | C8: ug/m3 | D8: ppb | E8: ug/m3 | F8: ug/m3 | G8: ug/m3 | H8: ug/m3 | I8: ug/m3 | J8: m/sec | K8: deg | L8: degreC | M8: % | N8: w/m2 | O8: mm | P8: mg/m3 | Q8: ug/m3
A9: 09/03/2025 00:15 | B9: 17.7 | C9: 25.05 | D9: 28.63 | E9: 8.86 | F9: Invalid | G9: 134.48 | H9: 36.5 | I9: 8.35 | J9: 0.24 | K9: 179.62 | L9: 21.45 | M9: 54.1 | N9: 1 | O9: 0 | P9: 0.78 | Q9: 28.58
A10: 09/03/2025 00:30 | B10: 18.56 | C10: 25.15 | D10: 29.38 | E10: 8.54 | F10: Invalid | G10: 136.26 | H10: 36.5 | I10: 8.44 | J10: 0.13 | K10: 186.64 | L10: 20.99 | M10: 52.06 | N10: 0.9 | O10: 0 | P10: 0.8 | Q10: 28.63
A11: 09/03/2025 00:45 | B11: 18.67 | C11: 24.89 | D11: 29.33 | E11: 8.58 | F11: Invalid | G11: 136.26 | H11: 36.5 | I11: 8.51 | J11: 0.24 | K11: 180.88 | L11: 20.92 | M11: 53.09 | N11: 0.9 | O11: 0 | P11: 0.81 | Q11: 28.65
A12: 09/03/2025 01:00 | B12: 18.64 | C12: 24.5 | D12: 29.09 | E12: 8.47 | F12: Invalid | G12: 136.26 | H12: 36.5 | I12: 8.6 | J12: 0.18 | K12: 185.39 | L12: 20.04 | M12: 57.23 | N12: 1.3 | O12: 0 | P12: 0.81 | Q12: 28.62
A13: 09/03/2025 01:15 | B13: 18.39 | C13: 24.03 | D13: 28.66 | E13: 8.63 | F13: Invalid | G13: 116.79 | H13: 34.85 | I13: 8.63 | J13: 0.16 | K13: 23.06 | L13: 20.12 | M13: 54.15 | N13: 0.6 | O13: 0 | P13: 0.82 | Q13: 28.61
A14: 09/03/2025 01:30 | B14: 18.5 | C14: 23.67 | D14: 28.55 | E14: 8.55 | F14: Invalid | G14: 115.15 | H14: 34.85 | I14: 8.66 | J14: 0.71 | K14: 26.38 | L14: 22.21 | M14: 40.01 | N14: 0 | O14: 0 | P14: 0.82 | Q14: 28.61
A15: 09/03/2025 01:45 | B15: 19 | C15: 23.92 | D15: 29.08 | E15: 8.8 | F15: Invalid | G15: 115.15 | H15: 34.85 | I15: 8.69 | J15: 0.32 | K15: 72.85 | L15: 22.89 | M15: 36.78 | N15: 0.6 | O15: 0 | P15: 0.83 | Q15: 28.62
A16: 09/03/2025 02:00 | B16: 19.56 | C16: 23.6 | D16: 29.36 | E16: 8.76 | F16: Invalid | G16: 115.15 | H16: 34.85 | I16: 8.74 | J16: 0.18 | K16: 123.42 | L16: 22.28 | M16: 40.05 | N16: 1.2 | O16: 0 | P16: 0.83 | Q16: 28.62
A17: 09/03/2025 02:15 | B17: 19.58 | C17: 23.73 | D17: 29.46 | E17: 6.88 | F17: Invalid | G17: 100.84 | H17: 33.82 | I17: 8.81 | J17: 0.25 | K17: 85.55 | L17: 22.06 | M17: 38.55 | N17: 0.9 | O17: 0 | P17: 0.84 | Q17: 28.61
A18: 09/03/2025 02:30 | B18: 19.52 | C18: 23.77 | D18: 29.43 | E18: 8.31 | F18: Invalid | G18: 99.45 | H18: 33.82 | I18: 8.83 | J18: 0.09 | K18: 187.81 | L18: 21.91 | M18: 41.6 | N18: 1 | O18: 0 | P18: 0.84 | Q18: 28.66
A19: 09/03/2025 02:45 | B19: 20.5 | C19: 22.95 | D19: 29.78 | E19: 7.98 | F19: Invalid | G19: 99.45 | H19: 33.82 | I19: 8.87 | J19: 0.17 | K19: 178.99 | L19: 20.73 | M19: 49.61 | N19: 1.6 | O19: 0 | P19: 0.84 | Q19: 28.64
A20: 09/03/2025 03:00 | B20: 22.31 | C20: 21.18 | D20: 30.31 | E20: 7.99 | F20: Invalid | G20: 99.45 | H20: 33.82 | I20: 8.92 | J20: 0.21 | K20: 185.97 | L20: 20.19 | M20: 49.37 | N20: 1.2 | O20: 0 | P20: 0.84 | Q20: 28.64
... A104: 09/03/2025 24:00 | B104: 5.7 | C104: 21.63 | D104: 17.23 | E104: 8.66 | F104: Invalid | G104: 92.51 | H104: 31.5 | I104: 8.11 | J104: 0.71 | K104: 69.23 | L104: 26.18 | M104: 34.52 | N104: 0.1 | O104: 0 | P104: 0.78 | Q104: 28.08
A106: Min | B106: =MIN(B9:B104) -> 4.24 | C106: =MIN(C9:C104) -> 13.23 | D106: =MIN(D9:D104) -> 13.99 | E106: =MIN(E9:E104) -> 6.88 | F106: =MIN(F9:F104) -> 0 | G106: =MIN(G9:G104) -> 47.91 | H106: =MIN(H9:H104) -> 22.58 | I106: =MIN(I9:I104) -> 6.93 | ... Q106: =MIN(Q9:Q104) -> 27.98
A107: Max | B107: =MAX(B9:B104) -> 27.13 | C107: =MAX(C9:C104) -> 30.97 | D107: =MAX(D9:D104) -> 35.1 | E107: =MAX(E9:E104) -> 26.6 | F107: =MAX(F9:F104) -> 0 | G107: =MAX(G9:G104) -> 136.26 | H107: =MAX(H9:H104) -> 44.59 | I107: =MAX(I9:I104) -> 11.64 | ... Q107: =MAX(Q9:Q104) -> 28.96
A108: Avg | B108: =AVERAGE(B9:B104) -> 12.339583 | C108: =AVERAGE(C9:C104) -> 22.587917 | D108: =AVERAGE(D9:D104) -> 23.048333 | E108: =AVERAGE(E9:E104) -> 9.9853125 | F108: =AVERAGE(F9:F104) -> #DIV/0! | G108: =AVERAGE(G9:G104) -> 92.290417 | H108: =AVERAGE(H9:H104) -> 33.09 | I108: =AVERAGE(I9:I104) -> 8.9134375 | ... Q108: =AVERAGE(Q9:Q104) -> 28.306771
A109: Stdev | B109: =STDEV(B9:B104) -> 7.9937623 | C109: =STDEV(C9:C104) -> 3.7680094 | D109: =STDEV(D9:D104) -> 6.6845953 | E109: =STDEV(E9:E104) -> 2.9291759 | F109: =STDEV(F9:F104) -> #DIV/0! | G109: =STDEV(G9:G104) -> 23.900946 | H109: =STDEV(H9:H104) -> 5.4570314 | I109: =STDEV(I9:I104) -> 1.2448199 | ... Q109: =STDEV(Q9:Q104) -> 0.33396342
A110: Num | B110: =COUNT(B9:B104) -> 96 | C110: =COUNT(C9:C104) -> 96 | D110: =COUNT(D9:D104) -> 96 | E110: =COUNT(E9:E104) -> 96 | F110: =COUNT(F9:F104) -> 0 | G110: =COUNT(G9:G104) -> 96 | H110: =COUNT(H9:H104) -> 96 | I110: =COUNT(I9:I104) -> 96 | ... Q110: =COUNT(Q9:Q104) -> 96
A111: DCR | B111: =IF(B110>=87,">90%",IF(B110<=87,"<90%")) -> >90% | C111: =IF(C110>=87,">90%",IF(C110<=87,"<90%")) -> >90% | D111: =IF(D110>=87,">90%",IF(D110<=87,"<90%")) -> >90% | E111: =IF(E110>=87,">90%",IF(E110<=87,"<90%")) -> >90% | F111: =IF(F110>=87,">90%",IF(F110<=87,"<90%")) -> <90% | G111: =IF(G110>=87,">90%",IF(G110<=87,"<90%")) -> >90% | H111: =IF(H110>=87,">90%",IF(H110<=87,"<90%")) -> >90% | I111: =IF(I110>=87,">90%",IF(I110<=87,"<90%")) -> >90% | ... Q111: =IF(Q110>=87,">90%",IF(Q110<=87,"<90%")) -> >90%
A112: Status | B112: =IF(B110>=87,"OK",IF(B110<=87,"LESS")) -> OK | C112: =IF(C110>=87,"OK",IF(C110<=87,"LESS")) -> OK | D112: =IF(D110>=87,"OK",IF(D110<=87,"LESS")) -> OK | E112: =IF(E110>=87,"OK",IF(E110<=87,"LESS")) -> OK | F112: =IF(F110>=87,"OK",IF(F110<=87,"LESS")) -> LESS | G112: =IF(G110>=87,"OK",IF(G110<=87,"LESS")) -> OK | H112: =IF(H110>=87,"OK",IF(H110<=87,"LESS")) -> OK | I112: =IF(I110>=87,"OK",IF(I110<=87,"LESS")) -> OK | ... Q112: =IF(Q110>=87,"OK",IF(Q110<=87,"LESS")) -> OK
A115: Done by | B115: AKASH
A117: Comment

Sheet 10
A1: Station: | B1: IGKV RAIPUR
A2: Date: | B2: =$A$9 -> 10/03/2025 00:15 | C2: Power Off | G2: Pw.Off | J2: Link Fail | L2: Link F | N2: Maintenance | P2: Maint.
A3: Report Type: | B3: Mean | C3: Calibration | G3: Calib. | J3: Data Fail | L3: Data F | N3: Invalid | P3: Invalid
A4: Time Base: | B4: 15 Min | C4: Zero Referrence | G4: Z.Ref | J4: Warm Up | L4: Wm. Up
A7: Date & Time | B7: NO | C7: NO2 | D7: NOX | E7: SO2 | F7: O3 | G7: PM 10 | H7: PM 2.5 | I7: BENZ | J7: WS | K7: WD | L7: TEMP | M7: HUM | N7: SR | O7: RG | P7: CO | Q7: NH3
B8: ug/m3 | C8: ug/m3 | D8: ppb | E8: ug/m3 | F8: ug/m3 | G8: ug/m3 | H8: ug/m3 | I8: ug/m3 | J8: m/sec | K8: deg | L8: degreC | M8: % | N8: w/m2 | O8: mm | P8: mg/m3 | Q8: ug/m3
A9: 10/03/2025 00:15 | B9: 5.35 | C9: 21.39 | D9: 16.81 | E9: 8.64 | F9: Invalid | G9: 88.68 | H9: 35.09 | I9: 8.14 | J9: 0.71 | K9: 58.25 | L9: 26.07 | M9: 35.32 | N9: 0.6 | O9: 0 | P9: 0.77 | Q9: 28.06
A10: 10/03/2025 00:30 | B10: 5.59 | C10: 21.58 | D10: 17.11 | E10: 8.19 | F10: Invalid | G10: 88.36 | H10: 35.09 | I10: 8.14 | J10: 0.55 | K10: 54.35 | L10: 25.64 | M10: 37.77 | N10: 1 | O10: 0 | P10: 0.78 | Q10: 28.07
A11: 10/03/2025 00:45 | B11: 5.93 | C11: 22.55 | D11: 17.89 | E11: 8.32 | F11: Invalid | G11: 88.36 | H11: 35.09 | I11: 8.13 | J11: 0.52 | K11: 31.63 | L11: 25.28 | M11: 39.17 | N11: 0.9 | O11: 0 | P11: 0.78 | Q11: 28.06
A12: 10/03/2025 01:00 | B12: 5.9 | C12: 22.8 | D12: 18 | E12: 8.2 | F12: Invalid | G12: 88.36 | H12: 35.09 | I12: 8.27 | J12: 0.49 | K12: 35.16 | L12: 24.81 | M12: 40.56 | N12: 1.2 | O12: 0 | P12: 0.77 | Q12: 28.09
A13: 10/03/2025 01:15 | B13: 5.58 | C13: 23.25 | D13: 17.97 | E13: 8.35 | F13: Invalid | G13: 91.17 | H13: 37.44 | I13: 8.46 | J13: 0.42 | K13: 19.94 | L13: 24.28 | M13: 42.3 | N13: 1.3 | O13: 0 | P13: 0.75 | Q13: 28.1
A14: 10/03/2025 01:30 | B14: 5.68 | C14: 23.45 | D14: 18.16 | E14: 7.88 | F14: Invalid | G14: 91.4 | H14: 37.44 | I14: 8.44 | J14: 0.7 | K14: 29.78 | L14: 23.88 | M14: 41.24 | N14: 1 | O14: 0 | P14: 0.76 | Q14: 28.09
A15: 10/03/2025 01:45 | B15: 5.99 | C15: 23.22 | D15: 18.29 | E15: 8.39 | F15: Invalid | G15: 91.4 | H15: 37.44 | I15: 8.45 | J15: 0.77 | K15: 40.37 | L15: 24.03 | M15: 39.84 | N15: 0.8 | O15: 0 | P15: 0.77 | Q15: 28.08
A16: 10/03/2025 02:00 | B16: 5.77 | C16: 23.29 | D16: 18.14 | E16: 8.67 | F16: Invalid | G16: 91.4 | H16: 37.44 | I16: 8.38 | J16: 0.78 | K16: 54.05 | L16: 24.02 | M16: 39.27 | N16: 0.7 | O16: 0 | P16: 0.78 | Q16: 28.09
A17: 10/03/2025 02:15 | B17: 5.39 | C17: 24.1 | D17: 18.27 | E17: 8.15 | F17: Invalid | G17: 101.68 | H17: 36.06 | I17: 8.29 | J17: 0.69 | K17: 39.08 | L17: 24.23 | M17: 37.46 | N17: 0.5 | O17: 0 | P17: 0.78 | Q17: 28.08
A18: 10/03/2025 02:30 | B18: 5.3 | C18: 24.2 | D18: 18.25 | E18: 10.54 | F18: Invalid | G18: 102.68 | H18: 36.06 | I18: 8.32 | J18: 0.64 | K18: 43.09 | L18: 24.26 | M18: 36.54 | N18: 0.7 | O18: 0 | P18: 0.78 | Q18: 28.07
A19: 10/03/2025 02:45 | B19: 5.14 | C19: 24.16 | D19: 18.1 | E19: 10.3 | F19: Invalid | G19: 102.68 | H19: 36.06 | I19: 8.32 | J19: 0.18 | K19: 56.96 | L19: 24 | M19: 38.07 | N19: 1.2 | O19: 0 | P19: 0.78 | Q19: 28.08
A20: 10/03/2025 03:00 | B20: 4.99 | C20: 24.08 | D20: 17.93 | E20: 9.97 | F20: Invalid | G20: 102.68 | H20: 36.06 | I20: 8.3 | J20: 0.22 | K20: 165.61 | L20: 23.23 | M20: 43.33 | N20: 1.5 | O20: 0 | P20: 0.78 | Q20: 28.07
... A104: 10/03/2025 24:00 | B104: 22.16 | C104: 30.85 | D104: 35.24 | E104: 9.16 | F104: Invalid | G104: 146.85 | H104: 46.09 | I104: 17.87 | J104: 0.18 | K104: 225.23 | L104: 22.85 | M104: 50.73 | N104: 1.2 | O104: 0 | P104: 1.37 | Q104: 28.74
