Workbook

Sheet 01
A1: Station: | B1: BHATAGAON ,RAIPUR
A2: Date: | B2: =$A$9 -> 01-12-2022 01:00 | D2: Power Off | G2: Pw.Off | L2: Link Fail | N2: Link F | P2: Maintenance | R2: Maint.
A3: Report Type: | B3: Mean | D3: Calibration | G3: Calib. | L3: Data Fail | N3: Data F | P3: Invalid | R3: Invalid
A4: Time Base: | B4: 01 Hour | D4: Zero Referrence | G4: Z.Ref | L4: Warm Up | N4: Wm. Up
A7: Date & Time | B7: NO_BHATAGAON | C7: NO2_BHATAGAON | D7: NOX_BHATAGAON | E7: SO2_BHATAGAON | F7: O3_BHATAGAON | G7: PM10_BHATAGAON | H7: PM2_5_BHATAGAON | I7: BENZ_BHATAGAON | J7: WS_BHATAGAON | K7: WD_BHATAGAON | L7: TEMP_BHATAGAON | M7: HUM BHATAGAON | N7: SR_BHATAGAON | O7: RG_BHATAGAON | P7: CO_BHATAGAON | Q7: NH3_BHATAGAON
B8: ug/m3 | C8: ug/m3 | D8: ug/m3 | E8: ug/m3 | F8: ug/m3 | G8: mg/m3 | H8: ug/m3 | I8: ug/m3 | J8: m/sec | K8: deg | L8: degreC | M8: % | N8: w/m2 | O8: mm | P8: ug/m3 | Q8: ug/m3
A9: 01-12-2022 01:00 | B9: 93.87 | C9: 136.52 | D9: 150.61 | E9: 5.15 | F9: 0.77 | G9: 223.96 | H9: 66.47 | I9: 1.54 | J9: 0.2 | K9: 294.27 | L9: 18.08 | M9: 91 | N9: Maint. | O9: 0 | P9: 3.84 | Q9: 151.77
A10: 01-12-2022 02:00 | B10: 88.51 | C10: 131.68 | D10: 143.65 | E10: 5.04 | F10: 0.63 | G10: 185.45 | H10: 63.78 | I10: 1.53 | J10: 0.48 | K10: 294.61 | L10: 17.88 | M10: 92 | N10: Maint. | O10: 0 | P10: 3.5 | Q10: 149.59
A11: 01-12-2022 03:00 | B11: 68.64 | C11: 116.89 | D11: 119.55 | E11: 4.65 | F11: 0.66 | G11: 193.63 | H11: 73.84 | I11: 1.42 | J11: 0.38 | K11: 278.93 | L11: 17.62 | M11: 89 | N11: Maint. | O11: 0 | P11: 3.19 | Q11: 141.7
A12: 01-12-2022 04:00 | B12: 51.32 | C12: 104.72 | D12: 98.95 | E12: 4.84 | F12: 0.74 | G12: 193.63 | H12: 73.84 | I12: 1.2 | J12: 0.24 | K12: 270.74 | L12: 17.54 | M12: 68 | N12: Maint. | O12: 0 | P12: 2.85 | Q12: 132.05
A13: 01-12-2022 05:00 | B13: 37.72 | C13: 95.78 | D13: 83.11 | E13: 5.63 | F13: 0.72 | G13: 165.87 | H13: 71.59 | I13: 1 | J13: 0.3 | K13: 294.54 | L13: 17.12 | M13: 96 | N13: Maint. | O13: 0 | P13: 2.56 | Q13: 128.32
A14: 01-12-2022 06:00 | B14: 31.34 | C14: 90.89 | D14: 75.29 | E14: 5.39 | F14: 0.81 | G14: 151.27 | H14: 66.09 | I14: 0.84 | J14: 0.22 | K14: 297.26 | L14: 17.12 | M14: 66 | N14: Maint. | O14: 0 | P14: 2.36 | Q14: 124.02
A15: 01-12-2022 07:00 | B15: 38.29 | C15: 92.64 | D15: 81.84 | E15: 5.12 | F15: 0.72 | G15: 116.33 | H15: 59.78 | I15: 0.72 | J15: 0.23 | K15: 294.47 | L15: 16.68 | M15: 86 | N15: Maint. | O15: 0 | P15: 2.08 | Q15: 121.25
A16: 01-12-2022 08:00 | B16: 44.94 | C16: 100.72 | D16: 91.15 | E16: 5.06 | F16: 0.75 | G16: 107.39 | H16: 49.12 | I16: 0.65 | J16: 0.86 | K16: 282.52 | L16: 21.58 | M16: 87 | N16: 76 | O16: 0 | P16: 2.02 | Q16: 124.61
A17: 01-12-2022 09:00 | B17: 43.07 | C17: 102.7 | D17: 90.72 | E17: 5.07 | F17: 0.78 | G17: 107.39 | H17: 49.12 | I17: 0.64 | J17: 0.69 | K17: 200.89 | L17: 24.04 | M17: 85 | N17: 182 | O17: 0 | P17: 1.9 | Q17: 124.87
A18: 01-12-2022 10:00 | B18: 35.12 | C18: 100.65 | D18: 83.71 | E18: 5.19 | F18: 0.97 | G18: 81.79 | H18: 44.49 | I18: 0.61 | J18: 1.52 | K18: 202.37 | L18: 25.2 | M18: 67 | N18: 243.7 | O18: 0 | P18: 1.74 | Q18: 123.88
A19: 01-12-2022 11:00 | B19: 21.72 | C19: 93.09 | D19: 68.31 | E19: 5.04 | F19: 2 | G19: 80.96 | H19: 42.27 | I19: 0.58 | J19: 1.45 | K19: 177.79 | L19: 26.84 | M19: 71 | N19: 289.2 | O19: 0 | P19: 1.58 | Q19: 115.79
A20: 01-12-2022 12:00 | B20: 13.22 | C20: 89.58 | D20: 60.04 | E20: 5.21 | F20: 2.1 | G20: 80.54 | H20: 40.69 | I20: 0.54 | J20: 1.14 | K20: 175.97 | L20: 28.02 | M20: 93 | N20: 291.8 | O20: 0 | P20: 1.4 | Q20: 116.32
A21: 01-12-2022 13:00 | B21: 6.89 | C21: 83.61 | D21: 51.67 | E21: 6.11 | F21: 2.52 | G21: 72.28 | H21: 40.25 | I21: 0.51 | J21: 0.7 | K21: 172.6 | L21: 30.98 | M21: 82 | N21: 284.3 | O21: 0 | P21: 1.27 | Q21: 119.78
A22: 01-12-2022 14:00 | B22: 3.47 | C22: 80.95 | D22: 47.46 | E22: 5.94 | F22: 4.69 | G22: 72.28 | H22: 40.25 | I22: 0.51 | J22: 1.06 | K22: 137.35 | L22: 31.66 | M22: 93 | N22: 257.5 | O22: 0 | P22: 1.2 | Q22: 116.06
A23: 01-12-2022 15:00 | B23: 2 | C23: 77.98 | D23: 44.43 | E23: 18.28 | F23: 18.57 | G23: 67.03 | H23: 37.75 | I23: 0.45 | J23: 0.71 | K23: 141.05 | L23: 29.67 | M23: 66 | N23: 171.6 | O23: 0 | P23: 1.1 | Q23: 107.64
A24: 01-12-2022 16:00 | B24: 2.36 | C24: 85.59 | D24: 49.08 | E24: 22.82 | F24: 21.21 | G24: 75.95 | H24: 35.99 | I24: 0.33 | J24: 2.53 | K24: 146.78 | L24: 29.53 | M24: 92 | N24: 66.6 | O24: 0 | P24: 1.14 | Q24: 98.15
A25: 01-12-2022 17:00 | B25: 4.2 | C25: 108.54 | D25: 63.27 | E25: 10.59 | F25: 16.85 | G25: 75.95 | H25: 35.99 | I25: 0.32 | J25: 0.71 | K25: 215.22 | L25: 84.46 | M25: 99 | N25: Maint. | O25: 0 | P25: 1.6 | Q25: 95.18
A26: 01-12-2022 18:00 | B26: 12.63 | C26: 129.08 | D26: 76.82 | E26: 4.58 | F26: 2.05 | G26: 99.78 | H26: 41.7 | I26: 0.38 | J26: 0.22 | K26: 222.39 | L26: 25.1 | M26: 77 | N26: Maint. | O26: 0 | P26: 1.88 | Q26: 94.11
A27: 01-12-2022 19:00 | B27: 26.69 | C27: 119.99 | D27: 87.02 | E27: 4.3 | F27: 0.71 | G27: 164.12 | H27: 44.86 | I27: 0.56 | J27: 0.2 | K27: Maint. | L27: 22.65 | M27: 69 | N27: Maint. | O27: 0 | P27: 2.29 | Q27: 113.96
A28: 01-12-2022 20:00 | B28: 37.95 | C28: 117.24 | D28: 93.9 | E28: 4.54 | F28: 0.82 | G28: 179.79 | H28: 49.46 | I28: 0.86 | J28: 0.28 | K28: Maint. | L28: 22.39 | M28: 41 | N28: Maint. | O28: 0 | P28: 2.73 | Q28: 125.51
A29: 01-12-2022 21:00 | B29: 37.46 | C29: 112.05 | D29: 90.78 | E29: 4.15 | F29: 0.72 | G29: 179.79 | H29: 49.46 | I29: 1.03 | J29: 0.31 | K29: Maint. | L29: 22.49 | M29: 20 | N29: Maint. | O29: 0 | P29: 2.83 | Q29: 123.97
A30: 01-12-2022 22:00 | B30: 32.71 | C30: 110.85 | D30: 87.41 | E30: 4.05 | F30: 0.66 | G30: 135.25 | H30: 52.09 | I30: 1.07 | J30: 0.24 | K30: Maint. | L30: 21.55 | M30: 46 | N30: Maint. | O30: 0 | P30: 2.84 | Q30: 127.25
A31: 01-12-2022 23:00 | B31: 37.49 | C31: 111.08 | D31: 91.37 | E31: 4.42 | F31: 0.63 | G31: 135.25 | H31: 52.09 | I31: 1.11 | J31: 0.19 | K31: Maint. | L31: 20.31 | M31: 86 | N31: Maint. | O31: 0 | P31: 2.9 | Q31: 132.61
A32: 01-12-2022 24:00 | B32: 63.64 | C32: 118.63 | D32: 116.51 | E32: 4.6 | F32: 0.66 | G32: 173.9 | H32: 52.01 | I32: 1.21 | J32: 0.18 | K32: Maint. | L32: 18.92 | M32: 82 | N32: Maint. | O32: 0 | P32: 3.01 | Q32: 139.78
A34: Min | B34: =MIN(B9:B32) -> 2 | C34: =MIN(C9:C32) -> 77.98 | D34: =MIN(D9:D32) -> 44.43 | E34: =MIN(E9:E32) -> 4.05 | F34: =MIN(F9:F32) -> 0.63 | G34: =MIN(G9:G32) -> 67.03 | H34: =MIN(H9:H32) -> 35.99 | I34: =MIN(I9:I32) -> 0.32 | ... Q34: =MIN(Q9:Q32) -> 94.11
A35: Max | B35: =MAX(B9:B32) -> 93.87 | C35: =MAX(C9:C32) -> 136.52 | D35: =MAX(D9:D32) -> 150.61 | E35: =MAX(E9:E32) -> 22.82 | F35: =MAX(F9:F32) -> 21.21 | G35: =MAX(G9:G32) -> 223.96 | H35: =MAX(H9:H32) -> 73.84 | I35: =MAX(I9:I32) -> 1.54 | ... Q35: =MAX(Q9:Q32) -> 151.77
A36: Avg | B36: =AVERAGE(B9:B32) -> 34.802083 | C36: =AVERAGE(C9:C32) -> 104.64375 | D36: =AVERAGE(D9:D32) -> 85.277083 | E36: =AVERAGE(E9:E32) -> 6.4904167 | F36: =AVERAGE(F9:F32) -> 3.4058333 | G36: =AVERAGE(G9:G32) -> 129.9825 | H36: =AVERAGE(H9:H32) -> 51.374167 | I36: =AVERAGE(I9:I32) -> 0.81708333 | ... Q36: =AVERAGE(Q9:Q32) -> 122.84042
A37: Stdev | B37: =STDEV(B9:B32) -> 25.431562 | C37: =STDEV(C9:C32) -> 16.310959 | D37: =STDEV(D9:D32) -> 27.476427 | E37: =STDEV(E9:E32) -> 4.5577821 | F37: =STDEV(F9:F32) -> 6.0789672 | G37: =STDEV(G9:G32) -> 49.172977 | H37: =STDEV(H9:H32) -> 12.145745 | I37: =STDEV(I9:I32) -> 0.37507656 | ... Q37: =STDEV(Q9:Q32) -> 14.89545
A38: Num | B38: =COUNT(B9:B32) -> 24 | C38: =COUNT(C9:C32) -> 24 | D38: =COUNT(D9:D32) -> 24 | E38: =COUNT(E9:E32) -> 24 | F38: =COUNT(F9:F32) -> 24 | G38: =COUNT(G9:G32) -> 24 | H38: 24 | I38: =COUNT(I9:I32) -> 24 | J38: =COUNT(J9:J32) -> 24 | K38: =COUNT(K9:K32)+6 -> 24 | L38: =COUNT(L9:L32) -> 24 | M38: =COUNT(M9:M32) -> 24 | N38: =COUNT(N9:N32)+15 -> 24 | O38: =COUNT(O9:O32) -> 24 | P38: =COUNT(P9:P32) -> 24 | Q38: =COUNT(Q9:Q32) -> 24
A39: DCR | B39: =IF(B38>=22,">90%",IF(B38<=22,"<90%")) -> >90% | C39: =IF(C38>=22,">90%",IF(C38<=22,"<90%")) -> >90% | D39: =IF(D38>=22,">90%",IF(D38<=22,"<90%")) -> >90% | E39: =IF(E38>=22,">90%",IF(E38<=22,"<90%")) -> >90% | F39: =IF(F38>=22,">90%",IF(F38<=22,"<90%")) -> >90% | G39: =IF(G38>=22,">90%",IF(G38<=22,"<90%")) -> >90% | H39: =IF(H38>=22,">90%",IF(H38<=22,"<90%")) -> >90% | I39: =IF(I38>=22,">90%",IF(I38<=22,"<90%")) -> >90% | ... Q39: =IF(Q38>=22,">90%",IF(Q38<=22,"<90%")) -> >90%
A40: Status | B40: =IF(B38>=22,"OK",IF(B38<=22,"LESS")) -> OK | C40: =IF(C38>=22,"OK",IF(C38<=22,"LESS")) -> OK | D40: =IF(D38>=22,"OK",IF(D38<=22,"LESS")) -> OK | E40: =IF(E38>=22,"OK",IF(E38<=22,"LESS")) -> OK | F40: =IF(F38>=22,"OK",IF(F38<=22,"LESS")) -> OK | G40: =IF(G38>=22,"OK",IF(G38<=22,"LESS")) -> OK | H40: =IF(H38>=22,"OK",IF(H38<=22,"LESS")) -> OK | I40: =IF(I38>=22,"OK",IF(I38<=22,"LESS")) -> OK | ... Q40: =IF(Q38>=22,"OK",IF(Q38<=22,"LESS")) -> OK
A43: Done by | B43: RAHUL
A45: Comment

Sheet 02
A1: Station: | B1: BHATAGAON RAIPUR
A2: Date: | B2: =$A$9 -> 02-12-2022 01:00 | D2: Power Off | G2: Pw.Off | L2: Link Fail | N2: Link F | P2: Maintenance | R2: Maint.
A3: Report Type: | B3: Mean | D3: Calibration | G3: Calib. | L3: Data Fail | N3: Data F | P3: Invalid | R3: Invalid
A4: Time Base: | B4: 01 Hour | D4: Zero Referrence | G4: Z.Ref | L4: Warm Up | N4: Wm. Up
A7: Date & Time | B7: NO_BHATAGAON | C7: NO2_BHATAGAON | D7: NOX_BHATAGAON | E7: SO2_BHATAGAON | F7: O3_BHATAGAON | G7: PM10_BHATAGAON | H7: PM2_5_BHATAGAON | I7: BENZ_BHATAGAON | J7: WS_BHATAGAON | K7: WD_BHATAGAON | L7: TEMP_BHATAGAON | M7: HUM BHATAGAON | N7: SR_BHATAGAON | O7: RG_BHATAGAON | P7: CO_BHATAGAON | Q7: NH3_BHATAGAON
B8: ug/m3 | C8: ug/m3 | D8: ug/m3 | E8: ug/m3 | F8: ug/m3 | G8: mg/m3 | H8: ug/m3 | I8: ug/m3 | J8: m/sec | K8: deg | L8: degreC | M8: % | N8: w/m2 | O8: mm | P8: ug/m3 | Q8: ug/m3
A9: 02-12-2022 01:00 | B9: 64.2 | C9: 118.58 | D9: 116.92 | E9: 4.38 | F9: 0.65 | G9: 173.9 | H9: 50.66 | I9: 1.21 | J9: 0.24 | K9: Maint. | L9: 18.54 | M9: Maint. | N9: Maint. | O9: 0 | P9: 2.96 | Q9: 139.46
A10: 02-12-2022 02:00 | B10: 56.76 | C10: 111.99 | D10: 107.32 | E10: 4.67 | F10: 0.58 | G10: 118.66 | H10: 49.8 | I10: 1.16 | J10: 0.32 | K10: Maint. | L10: 18.59 | M10: Maint. | N10: Maint. | O10: 0 | P10: 2.75 | Q10: 137.74
A11: 02-12-2022 03:00 | B11: 50.39 | C11: 106.25 | D11: 99.05 | E11: 4.92 | F11: 0.5 | G11: 118.66 | H11: 48.65 | I11: Maint. | J11: 0.14 | K11: Maint. | L11: 17.48 | M11: Maint. | N11: Maint. | O11: 0 | P11: 2.66 | Q11: 136.31
A12: 02-12-2022 04:00 | B12: 44.3 | C12: 97.21 | D12: 89.18 | E12: 4.24 | F12: 0.55 | G12: 146.05 | H12: 50.47 | I12: Maint. | J12: 0.15 | K12: Maint. | L12: 17.04 | M12: Maint. | N12: Maint. | O12: 0 | P12: 2.5 | Q12: 133.27
A13: 02-12-2022 05:00 | B13: 39.71 | C13: 90.78 | D13: 81.94 | E13: 4.4 | F13: 0.68 | G13: 171.95 | H13: 53.79 | I13: Maint. | J13: 0.27 | K13: Maint. | L13: 17.44 | M13: Maint. | N13: Maint. | O13: 0 | P13: 2.4 | Q13: 129.39
A14: 02-12-2022 06:00 | B14: 34.36 | C14: 89.21 | D14: 76.78 | E14: 4.36 | F14: 0.54 | G14: 171.95 | H14: 53.79 | I14: Maint. | J14: 0.53 | K14: Maint. | L14: 17.46 | M14: Maint. | N14: Maint. | O14: 0 | P14: 2.36 | Q14: 127.48
A15: 02-12-2022 07:00 | B15: 28.17 | C15: 86.09 | D15: 70.1 | E15: 4.07 | F15: 0.64 | G15: 142.19 | H15: 52.78 | I15: Maint. | J15: 0.4 | K15: Maint. | L15: 17.51 | M15: Maint. | N15: Maint. | O15: 0 | P15: 2.14 | Q15: 123.04
A16: 02-12-2022 08:00 | B16: 24.44 | C16: 82.78 | D16: 65.27 | E16: 4.53 | F16: 0.81 | G16: 106.91 | H16: 49.95 | I16: Maint. | J16: 1.14 | K16: Maint. | L16: 19.83 | M16: Maint. | N16: 47.9 | O16: 0 | P16: 1.9 | Q16: 119.98
A17: 02-12-2022 09:00 | B17: 23.38 | C17: 83.85 | D17: 64.16 | E17: 4.88 | F17: 0.84 | G17: 100.87 | H17: 47.92 | I17: Maint. | J17: 1.16 | K17: Maint. | L17: 23.37 | M17: Maint. | N17: 150.1 | O17: 0 | P17: 1.79 | Q17: 120.53
A18: 02-12-2022 10:00 | B18: 18.75 | C18: 84.08 | D18: 61.44 | E18: 4.98 | F18: 1.12 | G18: 102.58 | H18: 44.36 | I18: Maint. | J18: 1.38 | K18: Maint. | L18: 24.15 | M18: Maint. | N18: 219.5 | O18: 0 | P18: 1.64 | Q18: 119.65
A19: 02-12-2022 11:00 | B19: 11.53 | C19: 80.5 | D19: 53.49 | E19: 4.86 | F19: 1.28 | G19: 102.58 | H19: 42.48 | I19: Maint. | J19: 1.07 | K19: Maint. | L19: 26.9 | M19: Maint. | N19: 258.5 | O19: 0 | P19: 1.45 | Q19: 116.61
A20: 02-12-2022 12:00 | B20: 6.2 | C20: 77.84 | D20: 47.93 | E20: 8.52 | F20: 9.78 | G20: 91.78 | H20: 41.23 | I20: 0.42 | J20: 0.99 | K20: Maint. | L20: 29.5 | M20: Maint. | N20: 266.7 | O20: 0 | P20: 1.32 | Q20: 111.06
A21: 02-12-2022 13:00 | B21: 6.76 | C21: 80.63 | D21: 47.45 | E21: 18.6 | F21: 20.13 | G21: 73.21 | H21: 39.03 | I21: 0.36 | J21: 0.92 | K21: Maint. | L21: 31.82 | M21: Maint. | N21: 260.4 | O21: 0 | P21: 1.01 | Q21: 71.89
A22: 02-12-2022 14:00 | B22: 3.18 | C22: 74.62 | D22: 43.55 | E22: 15.75 | F22: 20.44 | G22: 72.15 | H22: 39.7 | I22: 0.24 | J22: 1.1 | K22: Maint. | L22: 34.11 | M22: Maint. | N22: 223.4 | O22: 0 | P22: 0.99 | Q22: 70.71
A23: 02-12-2022 15:00 | B23: 2.84 | C23: 88.97 | D23: 51.38 | E23: 13.05 | F23: 22.38 | G23: 73.58 | H23: 39.7 | I23: 0.25 | J23: 0.93 | K23: Maint. | L23: 32.68 | M23: Maint. | N23: 298.5 | O23: 0 | P23: 1.12 | Q23: 73.12
A24: 02-12-2022 16:00 | B24: 5.06 | C24: 113.32 | D24: 66.6 | E24: 16.21 | F24: 37.73 | G24: 73.58 | H24: 37.59 | I24: 0.25 | J24: 0.45 | K24: 145.1 | L24: 30.18 | M24: Maint. | N24: 213.5 | O24: 0 | P24: 1.39 | Q24: 74.02
A25: 02-12-2022 17:00 | B25: 9.33 | C25: 65.47 | D25: 41.64 | E25: 17.66 | F25: 32.27 | G25: 73.03 | H25: 35.65 | I25: 0.29 | J25: 0.37 | K25: 213.11 | L25: 28.22 | M25: Maint. | N25: 76.8 | O25: 0 | P25: 1.9 | Q25: 55.22
A26: 02-12-2022 18:00 | B26: 8.97 | C26: 67.21 | D26: 41.64 | E26: 8.83 | F26: 5.37 | G26: 99.9 | H26: 37.59 | I26: 0.48 | J26: 0.21 | K26: 218.94 | L26: 25.54 | M26: Maint. | N26: 39 | O26: 0 | P26: 2.14 | Q26: 40.4
A27: 02-12-2022 19:00 | B27: 28.34 | C27: 55.32 | D27: 48.39 | E27: 3.73 | F27: 0.86 | G27: 167.96 | H27: 40.86 | I27: 0.68 | J27: 0.15 | K27: 231.49 | L27: 24.34 | M27: Maint. | N27: 34.7 | O27: 0 | P27: 2.79 | Q27: 43.31
A28: 02-12-2022 20:00 | B28: 35.41 | C28: 43.01 | D28: 52.13 | E28: 4.72 | F28: 1 | G28: 183.51 | H28: 50.01 | I28: 0.95 | J28: 0.26 | K28: 204.6 | L28: 24.05 | M28: Maint. | N28: 34.4 | O28: 0 | P28: 3.05 | Q28: 47.33
A29: 02-12-2022 21:00 | B29: 42.92 | C29: 37.65 | D29: 52.07 | E29: 5.53 | F29: 0.68 | G29: 201.65 | H29: 61.14 | I29: 1.14 | J29: 0.24 | K29: 212.12 | L29: 23.63 | M29: Maint. | N29: 34.6 | O29: 0 | P29: 3.31 | Q29: 51.9
A30: 02-12-2022 22:00 | B30: 41.84 | C30: 33.75 | D30: 50.64 | E30: 5.22 | F30: 0.83 | G30: 201.65 | H30: 61.14 | I30: 1.27 | J30: 0.15 | K30: 243.48 | L30: 22.57 | M30: Maint. | N30: 34.8 | O30: 0 | P30: 3.32 | Q30: 52.15
A31: 02-12-2022 23:00 | B31: 64.8 | C31: 29.73 | D31: 61.46 | E31: 5.45 | F31: 0.65 | G31: 187.77 | H31: 60.38 | I31: 1.34 | J31: 0.17 | K31: 262.94 | L31: 21.19 | M31: Maint. | N31: 34.7 | O31: 0 | P31: 3.57 | Q31: 52.29
A32: 02-12-2022 24:00 | B32: 78.8 | C32: 14.8 | D32: 66.57 | E32: 5.11 | F32: 0.8 | G32: 187.77 | H32: 60.38 | I32: 1.46 | J32: 0.15 | K32: 274.42 | L32: 20.24 | M32: Maint. | N32: 34.7 | O32: 0 | P32: 3.61 | Q32: 54.74
A34: Min | B34: =MIN(B9:B32) -> 2.84 | C34: =MIN(C9:C32) -> 14.8 | D34: =MIN(D9:D32) -> 41.64 | E34: =MIN(E9:E32) -> 3.73 | F34: =MIN(F9:F32) -> 0.5 | G34: =MIN(G9:G32) -> 72.15 | H34: =MIN(H9:H32) -> 35.65 | I34: =MIN(I9:I32) -> 0.24 | ... Q34: =MIN(Q9:Q32) -> 40.4
A35: Max | B35: =MAX(B9:B32) -> 78.8 | C35: =MAX(C9:C32) -> 118.58 | D35: =MAX(D9:D32) -> 116.92 | E35: =MAX(E9:E32) -> 18.6 | F35: =MAX(F9:F32) -> 37.73 | G35: =MAX(G9:G32) -> 201.65 | H35: =MAX(H9:H32) -> 61.14 | I35: =MAX(I9:I32) -> 1.46 | ... Q35: =MAX(Q9:Q32) -> 139.46
A36: Avg | B36: =AVERAGE(B9:B32) -> 30.435 | C36: =AVERAGE(C9:C32) -> 75.568333 | D36: =AVERAGE(D9:D32) -> 64.879167 | E36: =AVERAGE(E9:E32) -> 7.4445833 | F36: =AVERAGE(F9:F32) -> 6.7129167 | G36: =AVERAGE(G9:G32) -> 130.99333 | H36: =AVERAGE(H9:H32) -> 47.877083 | I36: =AVERAGE(I9:I32) -> 0.76666667 | ... Q36: =AVERAGE(Q9:Q32) -> 91.733333
A37: Stdev | B37: =STDEV(B9:B32) -> 22.014982 | C37: =STDEV(C9:C32) -> 27.655249 | D37: =STDEV(D9:D32) -> 20.848231 | E37: =STDEV(E9:E32) -> 4.8458974 | F37: =STDEV(F9:F32) -> 11.116832 | G37: =STDEV(G9:G32) -> 46.047675 | H37: =STDEV(H9:H32) -> 8.0598363 | I37: =STDEV(I9:I32) -> 0.46296662 | ... Q37: =STDEV(Q9:Q32) -> 36.736544
A38: Num | B38: =COUNT(B9:B32) -> 24 | C38: =COUNT(C9:C32) -> 24 | D38: =COUNT(D9:D32) -> 24 | E38: =COUNT(E9:E32) -> 24 | F38: 24 | G38: =COUNT(G9:G32) -> 24 | H38: =COUNT(H9:H32) -> 24 | I38: =COUNT(I9:I32)+9 -> 24 | J38: =COUNT(J9:J32) -> 24 | K38: =COUNT(K9:K32)+15 -> 24 | L38: =COUNT(L9:L32) -> 24 | M38: =COUNT(M9:M32)+24 -> 24 | N38: =COUNT(N9:N32)+7 -> 24 | O38: =COUNT(O9:O32) -> 24 | P38: =COUNT(P9:P32) -> 24 | Q38: =COUNT(Q9:Q32) -> 24
A39: DCR | B39: =IF(B38>=22,">90%",IF(B38<=22,"<90%")) -> >90% | C39: =IF(C38>=22,">90%",IF(C38<=22,"<90%")) -> >90% | D39: =IF(D38>=22,">90%",IF(D38<=22,"<90%")) -> >90% | E39: =IF(E38>=22,">90%",IF(E38<=22,"<90%")) -> >90% | F39: =IF(F38>=22,">90%",IF(F38<=22,"<90%")) -> >90% | G39: =IF(G38>=22,">90%",IF(G38<=22,"<90%")) -> >90% | H39: =IF(H38>=22,">90%",IF(H38<=22,"<90%")) -> >90% | I39: =IF(I38>=22,">90%",IF(I38<=22,"<90%")) -> >90% | ... Q39: =IF(Q38>=22,">90%",IF(Q38<=22,"<90%")) -> >90%
A40: Status | B40: =IF(B38>=22,"OK",IF(B38<=22,"LESS")) -> OK | C40: =IF(C38>=22,"OK",IF(C38<=22,"LESS")) -> OK | D40: =IF(D38>=22,"OK",IF(D38<=22,"LESS")) -> OK | E40: =IF(E38>=22,"OK",IF(E38<=22,"LESS")) -> OK | F40: =IF(F38>=22,"OK",IF(F38<=22,"LESS")) -> OK | G40: =IF(G38>=22,"OK",IF(G38<=22,"LESS")) -> OK | H40: =IF(H38>=22,"OK",IF(H38<=22,"LESS")) -> OK | I40: =IF(I38>=22,"OK",IF(I38<=22,"LESS")) -> OK | ... Q40: =IF(Q38>=22,"OK",IF(Q38<=22,"LESS")) -> OK
A43: Done by | B43: RAHUL
A45: Comment

Sheet 03
A1: Station: | B1: BHATAGAON RAIPUR
A2: Date: | B2: =$A$9 -> 03-12-2022 01:00 | D2: Power Off | G2: Pw.Off | L2: Link Fail | N2: Link F | P2: Maintenance | R2: Maint.
A3: Report Type: | B3: Mean | D3: Calibration | G3: Calib. | L3: Data Fail | N3: Data F | P3: Invalid | R3: Invalid
A4: Time Base: | B4: 01 Hour | D4: Zero Referrence | G4: Z.Ref | L4: Warm Up | N4: Wm. Up
A7: Date & Time | B7: NO_BHATAGAON | C7: NO2_BHATAGAON | D7: NOX_BHATAGAON | E7: SO2_BHATAGAON | F7: O3_BHATAGAON | G7: PM10_BHATAGAON | H7: PM2_5_BHATAGAON | I7: BENZ_BHATAGAON | J7: WS_BHATAGAON | K7: WD_BHATAGAON | L7: TEMP_BHATAGAON | M7: HUM BHATAGAON | N7: SR_BHATAGAON | O7: RG_BHATAGAON | P7: CO_BHATAGAON | Q7: NH3_BHATAGAON
B8: ug/m3 | C8: ug/m3 | D8: ug/m3 | E8: ug/m3 | F8: ug/m3 | G8: mg/m3 | H8: ug/m3 | I8: ug/m3 | J8: m/sec | K8: deg | L8: degreC | M8: % | N8: w/m2 | O8: mm | P8: ug/m3 | Q8: ug/m3
A9: 03-12-2022 01:00 | B9: 80.2 | C9: 4.79 | D9: 66.72 | E9: 5.75 | F9: 0.56 | G9: 159.52 | H9: 57.55 | I9: 1.48 | J9: 0.21 | K9: 285.13 | L9: 20.07 | M9: 36 | N9: 34.6 | O9: 0 | P9: 3.56 | Q9: 56.32
A10: 03-12-2022 02:00 | B10: 76.05 | C10: 4.06 | D10: 62.9 | E10: 5.55 | F10: 0.74 | G10: 148.53 | H10: 57.5 | I10: 1.44 | J10: 0.26 | K10: 302.17 | L10: 19.24 | M10: 45 | N10: 34.6 | O10: 0 | P10: 3.26 | Q10: 54.75
A11: 03-12-2022 03:00 | B11: 69.02 | C11: 5.47 | D11: 57.95 | E11: 5.43 | F11: 0.75 | G11: 166.15 | H11: 61.54 | I11: 1.32 | J11: 0.14 | K11: 298.31 | L11: 19.03 | M11: 39 | N11: 34.6 | O11: 0 | P11: 3.04 | Q11: 53.24
A12: 03-12-2022 04:00 | B12: 62.89 | C12: 8.82 | D12: 54.02 | E12: 5.48 | F12: 1.04 | G12: 190.32 | H12: 69.1 | I12: 1.25 | J12: 0.19 | K12: 300.65 | L12: 18.68 | M12: 23 | N12: 34.6 | O12: 0 | P12: 2.87 | Q12: 53.38
A13: 03-12-2022 05:00 | B13: 54.45 | C13: 13.61 | D13: 48.85 | E13: 5.9 | F13: 0.47 | G13: 196.8 | H13: 70.7 | I13: 1.17 | J13: 0.14 | K13: 296.62 | L13: 18.82 | M13: 19 | N13: 34.6 | O13: 0 | P13: 2.69 | Q13: 54.05
A14: 03-12-2022 06:00 | B14: 61.1 | C14: 13.02 | D14: 53.48 | E14: 5.35 | F14: 0.74 | G14: 216.64 | H14: 72.51 | I14: 1.02 | J14: 0.17 | K14: 305.36 | L14: 18.31 | M14: 33 | N14: 34.6 | O14: 0 | P14: 2.53 | Q14: 52.32
A15: 03-12-2022 07:00 | B15: 59.14 | C15: 10.2 | D15: 52.14 | E15: 5.78 | F15: 0.67 | G15: 216.64 | H15: 72.51 | I15: 0.92 | J15: 0.22 | K15: 288.62 | L15: 18.52 | M15: 27 | N15: 55.8 | O15: 0 | P15: 2.44 | Q15: 52.02
A16: 03-12-2022 08:00 | B16: 60.78 | C16: 7.94 | D16: 52.86 | E16: 5.78 | F16: 0.61 | G16: 169.44 | H16: 71.89 | I16: Maint. | J16: 0.78 | K16: 274.64 | L16: 20.58 | M16: 12 | N16: 157.4 | O16: 0 | P16: 2.36 | Q16: 53.17
A17: 03-12-2022 09:00 | B17: 53.39 | C17: 19.92 | D17: 49.12 | E17: 4.95 | F17: 0.92 | G17: 161.84 | H17: 71.89 | I17: Maint. | J17: 1.03 | K17: 235.45 | L17: 23.35 | M17: 15 | N17: 285.4 | O17: 0 | P17: 2.26 | Q17: 52.22
A18: 03-12-2022 10:00 | B18: 37.94 | C18: 32.61 | D18: 43.24 | E18: 5.22 | F18: 0.92 | G18: 126.63 | H18: 63.98 | I18: Maint. | J18: 0.94 | K18: 191.58 | L18: 28.68 | M18: 46 | N18: 367.3 | O18: 0 | P18: 2.03 | Q18: 50.66
A19: 03-12-2022 11:00 | B19: 25.64 | C19: 39.16 | D19: 39.08 | E19: 5.06 | F19: 1.33 | G19: 113.82 | H19: 63.98 | I19: Maint. | J19: 1 | K19: 186.98 | L19: 31.2 | M19: 37 | N19: 393.2 | O19: 0 | P19: 1.95 | Q19: 51.37
A20: 03-12-2022 12:00 | B20: 14.53 | C20: 48.33 | D20: 34.62 | E20: 5.34 | F20: 1.58 | G20: 105.19 | H20: 63.16 | I20: Maint. | J20: 0.9 | K20: 142.14 | L20: 32.46 | M20: 40 | N20: 411.3 | O20: 0 | P20: 1.9 | Q20: 52.6
A21: 03-12-2022 13:00 | B21: 4.97 | C21: 48.83 | D21: 30.93 | E21: 5.08 | F21: 2.91 | G21: 93.01 | H21: 60.54 | I21: 0.68 | J21: 0.64 | K21: 135.33 | L21: 32.18 | M21: 29 | N21: 410.1 | O21: 0 | P21: 1.76 | Q21: 50.08
A22: 03-12-2022 14:00 | B22: 4.07 | C22: 46.16 | D22: 27.81 | E22: 9.11 | F22: 5.62 | G22: 99.81 | H22: 54.97 | I22: 0.59 | J22: 0.77 | K22: 147.5 | L22: 32 | M22: 39 | N22: 327.9 | O22: 0 | P22: 1.63 | Q22: 50.56
A23: 03-12-2022 15:00 | B23: 4.16 | C23: 43.39 | D23: 27.28 | E23: 5.73 | F23: 4.02 | G23: 99.81 | H23: 54.97 | I23: 0.57 | J23: 0.93 | K23: 126.61 | L23: 32.21 | M23: 41 | N23: 338.6 | O23: 0 | P23: 1.58 | Q23: 51.82
A24: 03-12-2022 16:00 | B24: 2.6 | C24: 44.3 | D24: 26.39 | E24: 4.7 | F24: 3.77 | G24: 80.84 | H24: 54.93 | I24: 0.56 | J24: 0.99 | K24: 143.58 | L24: 31.33 | M24: 44 | N24: 201.6 | O24: 0 | P24: 1.49 | Q24: 51.69
A25: 03-12-2022 17:00 | B25: 5.28 | C25: 44.63 | D25: 28.39 | E25: 7 | F25: 7.46 | G25: 80.69 | H25: 49.09 | I25: 0.5 | J25: 0.83 | K25: 165.74 | L25: 28.5 | M25: 43 | N25: 78 | O25: 0 | P25: 1.55 | Q25: 49.63
A26: 03-12-2022 18:00 | B26: 15.6 | C26: 47.92 | D26: 37.71 | E26: 6.65 | F26: 4.44 | G26: 99.48 | H26: 43.88 | I26: 0.55 | J26: 0.45 | K26: 204.44 | L26: 25.93 | M26: 30 | N26: 38.7 | O26: 0 | P26: 1.98 | Q26: 51.08
A27: 03-12-2022 19:00 | B27: 22.8 | C27: 42.19 | D27: 39.9 | E27: 5.35 | F27: 1.11 | G27: 138.87 | H27: 48.81 | I27: 0.74 | J27: 0.1 | K27: 235.08 | L27: 23.52 | M27: 39 | N27: 34.6 | O27: 0 | P27: 2.18 | Q27: 54.69
A28: 03-12-2022 20:00 | B28: 47.69 | C28: 37.53 | D28: 54.05 | E28: 4.42 | F28: 0.9 | G28: 244.77 | H28: 53.87 | I28: 1 | J28: 0.09 | K28: 258.98 | L28: 21.82 | M28: 55 | N28: 34.6 | O28: 0 | P28: 2.82 | Q28: 54.92
A29: 03-12-2022 21:00 | B29: 83.72 | C29: 25.24 | D29: 70.15 | E29: 4.76 | F29: 0.73 | G29: 244.77 | H29: 62.91 | I29: 1.35 | J29: 0.18 | K29: 274.73 | L29: 21.17 | M29: 39 | N29: 34.5 | O29: 0 | P29: 3.66 | Q29: 56.95
A30: 03-12-2022 22:00 | B30: 121.69 | C30: Invalid | D30: 88.43 | E30: 5.56 | F30: 0.64 | G30: 231.68 | H30: 66.39 | I30: 1.71 | J30: 0.17 | K30: 273.9 | L30: 20.47 | M30: 37 | N30: 34.4 | O30: 0 | P30: 4.34 | Q30: 61.27
A31: 03-12-2022 23:00 | B31: 125.4 | C31: Invalid | D31: 90.08 | E31: 5.83 | F31: 0.65 | G31: 186.41 | H31: 66.39 | I31: 1.84 | J31: 0.2 | K31: 290.23 | L31: 20.18 | M31: 32 | N31: 34.6 | O31: 0 | P31: 4.42 | Q31: 62.46
A32: 03-12-2022 24:00 | B32: 145.17 | C32: Invalid | D32: 97.24 | E32: 5.75 | F32: 0.62 | G32: 209.5 | H32: 68.62 | I32: 1.79 | J32: 0.27 | K32: 299.26 | L32: 19.12 | M32: 23 | N32: 34.4 | O32: 0 | P32: 4.33 | Q32: 59.5
A34: Min | B34: =MIN(B9:B32) -> 2.6 | C34: =MIN(C9:C32) -> 4.06 | D34: =MIN(D9:D32) -> 26.39 | E34: =MIN(E9:E32) -> 4.42 | F34: =MIN(F9:F32) -> 0.47 | G34: =MIN(G9:G32) -> 80.69 | H34: =MIN(H9:H32) -> 43.88 | I34: =MIN(I9:I32) -> 0.5 | ... Q34: =MIN(Q9:Q32) -> 49.63
A35: Max | B35: =MAX(B9:B32) -> 145.17 | C35: =MAX(C9:C32) -> 48.83 | D35: =MAX(D9:D32) -> 97.24 | E35: =MAX(E9:E32) -> 9.11 | F35: =MAX(F9:F32) -> 7.46 | G35: =MAX(G9:G32) -> 244.77 | H35: =MAX(H9:H32) -> 72.51 | I35: =MAX(I9:I32) -> 1.84 | ... Q35: =MAX(Q9:Q32) -> 62.46
A36: Avg | B36: =AVERAGE(B9:B32) -> 51.595 | C36: =AVERAGE(C9:C32) -> 28.005714 | D36: =AVERAGE(D9:D32) -> 51.389167 | E36: =AVERAGE(E9:E32) -> 5.6470833 | F36: =AVERAGE(F9:F32) -> 1.8 | G36: =AVERAGE(G9:G32) -> 157.54833 | H36: =AVERAGE(H9:H32) -> 61.736667 | I36: =AVERAGE(I9:I32) -> 1.0778947 | ... Q36: =AVERAGE(Q9:Q32) -> 53.78125
A37: Stdev | B37: =STDEV(B9:B32) -> 40.562059 | C37: =STDEV(C9:C32) -> 17.323083 | D37: =STDEV(D9:D32) -> 20.10248 | E37: =STDEV(E9:E32) -> 0.92960711 | F37: =STDEV(F9:F32) -> 1.8867432 | G37: =STDEV(G9:G32) -> 53.614725 | H37: =STDEV(H9:H32) -> 8.2347649 | I37: =STDEV(I9:I32) -> 0.44936472 | ... Q37: =STDEV(Q9:Q32) -> 3.4007983
A38: Num | B38: =COUNT(B9:B32) -> 24 | C38: =COUNT(C9:C32) -> 21 | D38: =COUNT(D9:D32) -> 24 | E38: 24 | F38: 24 | G38: =COUNT(G9:G32) -> 24 | H38: =COUNT(H9:H32) -> 24 | I38: =COUNT(I9:I32)+5 -> 24 | J38: =COUNT(J9:J32) -> 24 | K38: =COUNT(K9:K32) -> 24 | L38: =COUNT(L9:L32) -> 24 | M38: =COUNT(M9:M32) -> 24 | N38: =COUNT(N9:N32) -> 24 | O38: =COUNT(O9:O32) -> 24 | P38: =COUNT(P9:P32) -> 24 | Q38: =COUNT(Q9:Q32) -> 24
A39: DCR | B39: =IF(B38>=22,">90%",IF(B38<=22,"<90%")) -> >90% | C39: =IF(C38>=22,">90%",IF(C38<=22,"<90%")) -> <90% | D39: =IF(D38>=22,">90%",IF(D38<=22,"<90%")) -> >90% | E39: =IF(E38>=22,">90%",IF(E38<=22,"<90%")) -> >90% | F39: =IF(F38>=22,">90%",IF(F38<=22,"<90%")) -> >90% | G39: =IF(G38>=22,">90%",IF(G38<=22,"<90%")) -> >90% | H39: =IF(H38>=22,">90%",IF(H38<=22,"<90%")) -> >90% | I39: =IF(I38>=22,">90%",IF(I38<=22,"<90%")) -> >90% | ... Q39: =IF(Q38>=22,">90%",IF(Q38<=22,"<90%")) -> >90%
A40: Status | B40: =IF(B38>=22,"OK",IF(B38<=22,"LESS")) -> OK | C40: =IF(C38>=22,"OK",IF(C38<=22,"LESS")) -> LESS | D40: =IF(D38>=22,"OK",IF(D38<=22,"LESS")) -> OK | E40: =IF(E38>=22,"OK",IF(E38<=22,"LESS")) -> OK | F40: =IF(F38>=22,"OK",IF(F38<=22,"LESS")) -> OK | G40: =IF(G38>=22,"OK",IF(G38<=22,"LESS")) -> OK | H40: =IF(H38>=22,"OK",IF(H38<=22,"LESS")) -> OK | I40: =IF(I38>=22,"OK",IF(I38<=22,"LESS")) -> OK | ... Q40: =IF(Q38>=22,"OK",IF(Q38<=22,"LESS")) -> OK
A43: Done by | B43: RAHUL
A45: Comment

Sheet 04
A1: Station: | B1: BHATAGAON RAIPUR
A2: Date: | B2: =$A$9 -> 04-12-2022 01:00 | D2: Power Off | G2: Pw.Off | L2: Link Fail | N2: Link F | P2: Maintenance | R2: Maint.
A3: Report Type: | B3: Mean | D3: Calibration | G3: Calib. | L3: Data Fail | N3: Data F | P3: Invalid | R3: Invalid
A4: Time Base: | B4: 01 Hour | D4: Zero Referrence | G4: Z.Ref | L4: Warm Up | N4: Wm. Up
A7: Date & Time | B7: NO_BHATAGAON | C7: NO2_BHATAGAON | D7: NOX_BHATAGAON | E7: SO2_BHATAGAON | F7: O3_BHATAGAON | G7: PM10_BHATAGAON | H7: PM2_5_BHATAGAON | I7: BENZ_BHATAGAON | J7: WS_BHATAGAON | K7: WD_BHATAGAON | L7: TEMP_BHATAGAON | M7: HUM BHATAGAON | N7: SR_BHATAGAON | O7: RG_BHATAGAON | P7: CO_BHATAGAON | Q7: NH3_BHATAGAON
B8: ug/m3 | C8: ug/m3 | D8: ug/m3 | E8: ug/m3 | F8: ug/m3 | G8: mg/m3 | H8: ug/m3 | I8: ug/m3 | J8: m/sec | K8: deg | L8: degreC | M8: % | N8: w/m2 | O8: mm | P8: ug/m3 | Q8: ug/m3
A9: 04-12-2022 01:00 | B9: 147.09 | C9: Invalid | D9: 97.89 | E9: 5.08 | F9: 0.64 | G9: 209.5 | H9: 68.92 | I9: 1.75 | J9: 0.46 | K9: 297.77 | L9: 19.22 | M9: Maint. | N9: 34.5 | O9: 0 | P9: 4.29 | Q9: 60.26
A10: 04-12-2022 02:00 | B10: 128.15 | C10: Invalid | D10: 87.42 | E10: 5.14 | F10: 0.66 | G10: 172.7 | H10: 69.08 | I10: 1.71 | J10: 0.34 | K10: 277.43 | L10: 19.46 | M10: Maint. | N10: 34.3 | O10: 0 | P10: 3.75 | Q10: 59.47
A11: 04-12-2022 03:00 | B11: 95.65 | C11: 2.15 | D11: 71.94 | E11: 4.71 | F11: 0.61 | G11: 218.92 | H11: 75.89 | I11: 1.53 | J11: 0.23 | K11: 298.98 | L11: 18.77 | M11: Maint. | N11: 34.8 | O11: 0 | P11: 3.5 | Q11: 57.16
A12: 04-12-2022 04:00 | B12: 70.3 | C12: 7.16 | D12: 59.09 | E12: 4.09 | F12: 0.6 | G12: 218.92 | H12: 75.89 | I12: 1.25 | J12: 0.17 | K12: 311.29 | L12: 18.01 | M12: Maint. | N12: 34.6 | O12: 0 | P12: 3.45 | Q12: 53.57
A13: 04-12-2022 05:00 | B13: 59.18 | C13: 6.91 | D13: 51.15 | E13: 4.11 | F13: 0.55 | G13: 173.51 | H13: 75.19 | I13: Maint. | J13: 0.19 | K13: 319.04 | L13: 17 | M13: Maint. | N13: 34.6 | O13: 0 | P13: 3.18 | Q13: 52.51
A14: 04-12-2022 06:00 | B14: 56.68 | C14: 6.79 | D14: 48.79 | E14: 3.7 | F14: 0.59 | G14: 151.13 | H14: 66.14 | I14: Maint. | J14: 0.23 | K14: 324.67 | L14: 16.76 | M14: 32 | N14: 34.5 | O14: 0 | P14: 2.79 | Q14: 52.44
A15: 04-12-2022 07:00 | B15: 68.12 | C15: 5.49 | D15: 55.71 | E15: 3.97 | F15: 0.72 | G15: 167.01 | H15: 65 | I15: Maint. | J15: 0.16 | K15: 321.62 | L15: 17.4 | M15: 21 | N15: 54.1 | O15: 0 | P15: 2.59 | Q15: 51.3
A16: 04-12-2022 08:00 | B16: 67.56 | C16: 11.51 | D16: 55.57 | E16: 3.85 | F16: 0.76 | G16: 167.01 | H16: 65 | I16: Maint. | J16: 0.53 | K16: 292.69 | L16: 20.91 | M16: 25 | N16: 169.7 | O16: 0 | P16: 2.52 | Q16: 51.32
A17: 04-12-2022 09:00 | B17: 58.34 | C17: 14.56 | D17: 53.28 | E17: 4.76 | F17: 0.68 | G17: 113.71 | H17: 64.83 | I17: Maint. | J17: 1.24 | K17: 248.29 | L17: 23.22 | M17: 21 | N17: 312.2 | O17: 0 | P17: 2.36 | Q17: 52.32
A18: 04-12-2022 10:00 | B18: 42.26 | C18: 33.16 | D18: 43.92 | E18: 4.92 | F18: 1.52 | G18: 99.66 | H18: 57.27 | I18: 0.61 | J18: 21.17 | K18: 217.43 | L18: 24.53 | M18: 37 | N18: 385 | O18: 0 | P18: 2.08 | Q18: 50.91
A19: 04-12-2022 11:00 | B19: 10.79 | C19: 43.04 | D19: 29.47 | E19: 6.16 | F19: 5.11 | G19: 91.09 | H19: 54.92 | I19: 0.51 | J19: 7.08 | K19: 359.52 | L19: 29.73 | M19: 50 | N19: 428.9 | O19: 0 | P19: 1.63 | Q19: 41.91
A20: 04-12-2022 12:00 | B20: 6.21 | C20: 45.53 | D20: 29.01 | E20: 4.14 | F20: 3.44 | G20: 103.59 | H20: 49.52 | I20: 0.41 | J20: 0.85 | K20: 329.19 | L20: Maint. | M20: 44 | N20: 440.8 | O20: 0 | P20: 1.43 | Q20: 42.51
A21: 04-12-2022 13:00 | B21: 3.86 | C21: 48.69 | D21: 29.45 | E21: 5.3 | F21: 3.49 | G21: 103.59 | H21: 49.52 | I21: 0.44 | J21: 0.8 | K21: 350.99 | L21: Maint. | M21: 35 | N21: 400.5 | O21: 0 | P21: 1.39 | Q21: 47.53
A22: 04-12-2022 14:00 | B22: 3.2 | C22: 47.98 | D22: 29.04 | E22: 6.49 | F22: 4.95 | G22: 88.21 | H22: 47.45 | I22: 0.44 | J22: 1.34 | K22: 340.6 | L22: Maint. | M22: 30 | N22: 381.2 | O22: 0 | P22: 1.32 | Q22: 45.65
A23: 04-12-2022 15:00 | B23: 4.51 | C23: 42.71 | D23: 26.42 | E23: 6.82 | F23: 8.96 | G23: 88.21 | H23: 46.8 | I23: 0.38 | J23: 1.07 | K23: 350.61 | L23: Maint. | M23: 30 | N23: 317.4 | O23: 0 | P23: 1.23 | Q23: 44.19
A24: 04-12-2022 16:00 | B24: 5.66 | C24: 41.18 | D24: 26.77 | E24: 8.31 | F24: 12.26 | G24: 79.56 | H24: 45.38 | I24: 0.38 | J24: 0.83 | K24: 350.53 | L24: Maint. | M24: 35 | N24: 201.4 | O24: 0 | P24: 1.25 | Q24: 47.46
A25: 04-12-2022 17:00 | B25: 4.92 | C25: 45.96 | D25: 29.29 | E25: 5.18 | F25: 3.52 | G25: 98.44 | H25: 42.67 | I25: 0.43 | J25: 0.78 | K25: 348.21 | L25: 28.37 | M25: 41 | N25: 66 | O25: 0 | P25: 1.43 | Q25: 48.78
A26: 04-12-2022 18:00 | B26: 8.12 | C26: 48.76 | D26: 33.42 | E26: 4.74 | F26: 3.16 | G26: 116 | H26: 44.2 | I26: 0.47 | J26: 0.13 | K26: 135.52 | L26: 25.76 | M26: 56 | N26: 28.5 | O26: 0 | P26: 1.66 | Q26: 48.79
A27: 04-12-2022 19:00 | B27: 19.3 | C27: 44.01 | D27: 37.97 | E27: 4.58 | F27: 0.86 | G27: 139.98 | H27: 44.47 | I27: 0.65 | J27: 0.11 | K27: 333.42 | L27: 22.66 | M27: 64 | N27: 24.5 | O27: 0 | P27: 1.94 | Q27: 49.73
A28: 04-12-2022 20:00 | B28: 45.89 | C28: 34.53 | D28: 50.68 | E28: 5.49 | F28: 0.73 | G28: 167.55 | H28: 47.91 | I28: 0.89 | J28: 0.12 | K28: 331.29 | L28: 21.89 | M28: 69 | N28: 24.4 | O28: 0 | P28: 2.73 | Q28: 54.65
A29: 04-12-2022 21:00 | B29: 83.1 | C29: 19.32 | D29: 70.91 | E29: 5.25 | F29: 0.75 | G29: 187.75 | H29: 52.5 | I29: 1.18 | J29: 0.11 | K29: 321.66 | L29: 20.79 | M29: 71 | N29: 24.5 | O29: 0 | P29: 3.58 | Q29: 55.83
A30: 04-12-2022 22:00 | B30: 129.44 | C30: Invalid | D30: 92.89 | E30: 5.66 | F30: 0.86 | G30: 191.23 | H30: 55.43 | I30: 1.44 | J30: 0.07 | K30: 306.52 | L30: 19.96 | M30: 74 | N30: 24.5 | O30: 0 | P30: 4.03 | Q30: 57.47
A31: 04-12-2022 23:00 | B31: 166.91 | C31: Invalid | D31: 110.16 | E31: 6.29 | F31: 0.79 | G31: 195.5 | H31: 58.32 | I31: 1.61 | J31: 0.16 | K31: 329.85 | L31: 19.53 | M31: 78 | N31: 24.3 | O31: 0 | P31: 4.29 | Q31: 60.53
A32: 04-12-2022 24:00 | B32: 179.87 | C32: Invalid | D32: 115.88 | E32: 6.31 | F32: 0.82 | G32: 195.5 | H32: 58.32 | I32: 1.73 | J32: 0.15 | K32: 358.89 | L32: 20.53 | M32: 74 | N32: 24.2 | O32: 0 | P32: 4.39 | Q32: 63.46
A34: Min | B34: =MIN(B9:B32) -> 3.2 | C34: =MIN(C9:C32) -> 2.15 | D34: =MIN(D9:D32) -> 26.42 | E34: =MIN(E9:E32) -> 3.7 | F34: =MIN(F9:F32) -> 0.55 | G34: =MIN(G9:G32) -> 79.56 | H34: =MIN(H9:H32) -> 42.67 | I34: =MIN(I9:I32) -> 0.38 | ... Q34: =MIN(Q9:Q32) -> 41.91
A35: Max | B35: =MAX(B9:B32) -> 179.87 | C35: =MAX(C9:C32) -> 48.76 | D35: =MAX(D9:D32) -> 115.88 | E35: =MAX(E9:E32) -> 8.31 | F35: =MAX(F9:F32) -> 12.26 | G35: =MAX(G9:G32) -> 218.92 | H35: =MAX(H9:H32) -> 75.89 | I35: =MAX(I9:I32) -> 1.75 | ... Q35: =MAX(Q9:Q32) -> 63.46
A36: Avg | B36: =AVERAGE(B9:B32) -> 61.04625 | C36: =AVERAGE(C9:C32) -> 28.917895 | D36: =AVERAGE(D9:D32) -> 55.671667 | E36: =AVERAGE(E9:E32) -> 5.2104167 | F36: =AVERAGE(F9:F32) -> 2.37625 | G36: =AVERAGE(G9:G32) -> 147.42792 | H36: =AVERAGE(H9:H32) -> 57.525833 | I36: =AVERAGE(I9:I32) -> 0.93736842 | ... Q36: =AVERAGE(Q9:Q32) -> 52.072917
A37: Stdev | B37: =STDEV(B9:B32) -> 55.361261 | C37: =STDEV(C9:C32) -> 18.021237 | D37: =STDEV(D9:D32) -> 27.587262 | E37: =STDEV(E9:E32) -> 1.1006657 | F37: =STDEV(F9:F32) -> 2.9638676 | G37: =STDEV(G9:G32) -> 46.739208 | H37: =STDEV(H9:H32) -> 10.795229 | I37: =STDEV(I9:I32) -> 0.54483272 | ... Q37: =STDEV(Q9:Q32) -> 5.7897867
A38: Num | B38: =COUNT(B9:B32) -> 24 | C38: =COUNT(C9:C32) -> 19 | D38: =COUNT(D9:D32) -> 24 | E38: =COUNT(E9:E32) -> 24 | F38: 24 | G38: 24 | H38: 24 | I38: =COUNT(I9:I32)+5 -> 24 | J38: =COUNT(J9:J32) -> 24 | K38: =COUNT(K9:K32) -> 24 | L38: =COUNT(L9:L32)+5 -> 24 | M38: =COUNT(M9:M32)+5 -> 24 | N38: =COUNT(N9:N32) -> 24 | O38: =COUNT(O9:O32) -> 24 | P38: =COUNT(P9:P32) -> 24 | Q38: =COUNT(Q9:Q32) -> 24
A39: DCR | B39: =IF(B38>=22,">90%",IF(B38<=22,"<90%")) -> >90% | C39: =IF(C38>=22,">90%",IF(C38<=22,"<90%")) -> <90% | D39: =IF(D38>=22,">90%",IF(D38<=22,"<90%")) -> >90% | E39: =IF(E38>=22,">90%",IF(E38<=22,"<90%")) -> >90% | F39: =IF(F38>=22,">90%",IF(F38<=22,"<90%")) -> >90% | G39: =IF(G38>=22,">90%",IF(G38<=22,"<90%")) -> >90% | H39: =IF(H38>=22,">90%",IF(H38<=22,"<90%")) -> >90% | I39: =IF(I38>=22,">90%",IF(I38<=22,"<90%")) -> >90% | ... Q39: =IF(Q38>=22,">90%",IF(Q38<=22,"<90%")) -> >90%
A40: Status | B40: =IF(B38>=22,"OK",IF(B38<=22,"LESS")) -> OK | C40: =IF(C38>=22,"OK",IF(C38<=22,"LESS")) -> LESS | D40: =IF(D38>=22,"OK",IF(D38<=22,"LESS")) -> OK | E40: =IF(E38>=22,"OK",IF(E38<=22,"LESS")) -> OK | F40: =IF(F38>=22,"OK",IF(F38<=22,"LESS")) -> OK | G40: =IF(G38>=22,"OK",IF(G38<=22,"LESS")) -> OK | H40: =IF(H38>=22,"OK",IF(H38<=22,"LESS")) -> OK | I40: =IF(I38>=22,"OK",IF(I38<=22,"LESS")) -> OK | ... Q40: =IF(Q38>=22,"OK",IF(Q38<=22,"LESS")) -> OK
A43: Done by | B43: RAHUL
A45: Comment

Sheet 05
A1: Station: | B1: BHATAGAON RAIPUR
A2: Date: | B2: =$A$9 -> 05-12-2022 01:00 | D2: Power Off | G2: Pw.Off | L2: Link Fail | N2: Link F | P2: Maintenance | R2: Maint.
A3: Report Type: | B3: Mean | D3: Calibration | G3: Calib. | L3: Data Fail | N3: Data F | P3: Invalid | R3: Invalid
A4: Time Base: | B4: 01 Hour | D4: Zero Referrence | G4: Z.Ref | L4: Warm Up | N4: Wm. Up
A7: Date & Time | B7: NO_BHATAGAON | C7: NO2_BHATAGAON | D7: NOX_BHATAGAON | E7: SO2_BHATAGAON | F7: O3_BHATAGAON | G7: PM10_BHATAGAON | H7: PM2_5_BHATAGAON | I7: BENZ_BHATAGAON | J7: WS_BHATAGAON | K7: WD_BHATAGAON | L7: TEMP_BHATAGAON | M7: HUM BHATAGAON | N7: SR_BHATAGAON | O7: RG_BHATAGAON | P7: CO_BHATAGAON | Q7: NH3_BHATAGAON
B8: ug/m3 | C8: ug/m3 | D8: ug/m3 | E8: ug/m3 | F8: ug/m3 | G8: mg/m3 | H8: ug/m3 | I8: ug/m3 | J8: m/sec | K8: deg | L8: degreC | M8: % | N8: w/m2 | O8: mm | P8: ug/m3 | Q8: ug/m3
A9: 05-12-2022 01:00 | B9: 142.91 | C9: Invalid | D9: 97.61 | E9: 4.85 | F9: 0.71 | G9: 172.84 | H9: 57.31 | I9: 1.6 | J9: 0.17 | K9: 283.63 | L9: 19.9 | M9: 75 | N9: 24.6 | O9: 0 | P9: 3.71 | Q9: 59.86
A10: 05-12-2022 02:00 | B10: 104.92 | C10: Invalid | D10: 76.52 | E10: 4.26 | F10: 0.73 | G10: 155.42 | H10: 51.06 | I10: 1.27 | J10: 0.18 | K10: 262.04 | L10: 18.03 | M10: 82 | N10: 24.4 | O10: 0 | P10: 3.03 | Q10: 53.98
A11: 05-12-2022 03:00 | B11: 81.77 | C11: Invalid | D11: 61.87 | E11: 4.41 | F11: 0.75 | G11: 155.42 | H11: 49.26 | I11: 1.12 | J11: 0.13 | K11: 298.44 | L11: 17.43 | M11: 87 | N11: 24.6 | O11: 0 | P11: 2.74 | Q11: 53.77
A12: 05-12-2022 04:00 | B12: 68.29 | C12: Invalid | D12: 53.32 | E12: 4.06 | F12: 1.35 | G12: 112.38 | H12: 50.89 | I12: 1.01 | J12: 0.08 | K12: 145.88 | L12: 16.67 | M12: 89 | N12: 24.4 | O12: 0 | P12: 2.45 | Q12: 53.32
A13: 05-12-2022 05:00 | B13: 59.46 | C13: 4.21 | D13: 48.04 | E13: 5.29 | F13: 1.03 | G13: 107.72 | H13: 50.89 | I13: 0.88 | J13: 0.13 | K13: 333.52 | L13: 16.65 | M13: 86 | N13: 24.2 | O13: 0 | P13: 2.22 | Q13: 51.01
A14: 05-12-2022 06:00 | B14: 52.7 | C14: 6.52 | D14: 44.68 | E14: 5.44 | F14: 1.06 | G14: 113.63 | H14: 49.82 | I14: 0.81 | J14: 0.11 | K14: 319.21 | L14: 16.44 | M14: 85 | N14: 24.2 | O14: 0 | P14: 2.01 | Q14: 48.43
A15: 05-12-2022 07:00 | B15: 54.24 | C15: 6.41 | D15: 45.95 | E15: 5.1 | F15: 0.72 | G15: 113.63 | H15: 48.04 | I15: 0.76 | J15: 0.17 | K15: 92.01 | L15: 17.5 | M15: 81 | N15: 45.8 | O15: 0 | P15: 1.92 | Q15: 50.17
A16: 05-12-2022 08:00 | B16: 49.92 | C16: 17.15 | D16: 46.76 | E16: 5.1 | F16: 0.8 | G16: 110.95 | H16: 48.04 | I16: 0.69 | J16: 0.88 | K16: 356.46 | L16: 21.74 | M16: 71 | N16: 180.5 | O16: 0 | P16: 1.82 | Q16: 49.17
A17: 05-12-2022 09:00 | B17: 45.73 | C17: 24.8 | D17: 47.87 | E17: 3.95 | F17: 1 | G17: 106.28 | H17: 46.65 | I17: 0.6 | J17: 0.86 | K17: 351.44 | L17: 25.97 | M17: 53 | N17: 307 | O17: 0 | P17: 1.82 | Q17: 45.73
A18: 05-12-2022 10:00 | B18: 35.12 | C18: 28.98 | D18: 42.86 | E18: 4.64 | F18: 1.03 | G18: 100.72 | H18: 44.63 | I18: 0.59 | J18: 1.12 | K18: 357.3 | L18: 26.51 | M18: 45 | N18: 398 | O18: 0 | P18: 1.73 | Q18: 47.47
A19: 05-12-2022 11:00 | B19: 32.81 | C19: 35.15 | D19: 43.7 | E19: 5.64 | F19: 2.16 | G19: 87.9 | H19: 41.65 | I19: 0.57 | J19: 1.27 | K19: 350.69 | L19: 28.33 | M19: 44 | N19: 457 | O19: 0 | P19: 1.56 | Q19: 47.98
A20: 05-12-2022 12:00 | B20: 25.83 | C20: 50.61 | D20: 43.47 | E20: 7.37 | F20: 5.89 | G20: 77.59 | H20: 37.62 | I20: 0.48 | J20: 0.81 | K20: 354.34 | L20: 29.91 | M20: 40 | N20: 451.1 | O20: 0 | P20: 1.38 | Q20: 43.85
A21: 05-12-2022 13:00 | B21: 6.22 | C21: 48.86 | D21: 31.72 | E21: 11.95 | F21: 8.39 | G21: 77.59 | H21: 37.31 | I21: 0.32 | J21: 1.14 | K21: 356.65 | L21: 31.62 | M21: 37 | N21: 436.8 | O21: 0 | P21: 1.16 | Q21: 37.06
A22: 05-12-2022 14:00 | B22: 4.71 | C22: 45.67 | D22: 28.01 | E22: 14.45 | F22: 12.22 | G22: 84.38 | H22: 39.4 | I22: 0.33 | J22: 1.42 | K22: 358.13 | L22: 31.8 | M22: 31 | N22: 365.6 | O22: 0 | P22: 1.19 | Q22: 39.51
A23: 05-12-2022 15:00 | B23: 3.69 | C23: 45.31 | D23: 26.95 | E23: 5.05 | F23: 5.65 | G23: 84.38 | H23: 39.4 | I23: 0.3 | J23: 1.09 | K23: 352.55 | L23: 32.17 | M23: 25 | N23: 330.8 | O23: 0 | P23: 1.2 | Q23: 37.09
A24: 05-12-2022 16:00 | B24: 8.98 | C24: 41.89 | D24: 29.81 | E24: 12.12 | F24: 11.03 | G24: 71.21 | H24: 37.08 | I24: 0.27 | J24: 0.8 | K24: 358.29 | L24: 30.45 | M24: 25 | N24: 221.6 | O24: 0 | P24: 1.24 | Q24: 38.27
... A32: 05-12-2022 24:00 | B32: 89.42 | C32: 0.64 | D32: 71.69 | E32: 4.09 | F32: 0.73 | G32: 111.62 | H32: 45.41 | I32: 1.36 | J32: 0.09 | K32: 343.58 | L32: 19.54 | M32: 63 | N32: 24.6 | O32: 0 | P32: 3.19 | Q32: 52.4
A34: Min | B34: =MIN(B9:B32) -> 3.69 | C34: =MIN(C9:C32) -> 0.52 | D34: =MIN(D9:D32) -> 26.95 | E34: =MIN(E9:E32) -> 3.77 | F34: =MIN(F9:F32) -> 0.71 | G34: =MIN(G9:G32) -> 70.47 | H34: =MIN(H9:H32) -> 36.44 | I34: =MIN(I9:I32) -> 0.27 | ... Q34: =MIN(Q9:Q32) -> 37.06
A35: Max | B35: =MAX(B9:B32) -> 142.91 | C35: =MAX(C9:C32) -> 50.61 | D35: =MAX(D9:D32) -> 97.61 | E35: =MAX(E9:E32) -> 14.45 | F35: =MAX(F9:F32) -> 14.12 | G35: =MAX(G9:G32) -> 193.99 | H35: =MAX(H9:H32) -> 57.31 | I35: =MAX(I9:I32) -> 1.6 | ... Q35: =MAX(Q9:Q32) -> 59.86
A36: Avg | B36: =AVERAGE(B9:B32) -> 54.084583 | C36: =AVERAGE(C9:C32) -> 25.714 | D36: =AVERAGE(D9:D32) -> 52.212917 | E36: =AVERAGE(E9:E32) -> 5.9845833 | F36: =AVERAGE(F9:F32) -> 3.1025 | G36: =AVERAGE(G9:G32) -> 114.35458 | H36: =AVERAGE(H9:H32) -> 45.126667 | I36: =AVERAGE(I9:I32) -> 0.81708333 | ... Q36: =AVERAGE(Q9:Q32) -> 48.170417
A37: Stdev | B37: =STDEV(B9:B32) -> 38.533037 | C37: =STDEV(C9:C32) -> 18.179833 | D37: =STDEV(D9:D32) -> 19.604161 | E37: =STDEV(E9:E32) -> 3.0679876 | F37: =STDEV(F9:F32) -> 4.1426207 | G37: =STDEV(G9:G32) -> 36.136866 | H37: =STDEV(H9:H32) -> 5.8166737 | I37: =STDEV(I9:I32) -> 0.41701297 | ... Q37: =STDEV(Q9:Q32) -> 6.2135067
A38: Num | B38: =COUNT(B9:B32) -> 24 | C38: =COUNT(C9:C32) -> 20 | D38: =COUNT(D9:D32) -> 24 | E38: =COUNT(E9:E32) -> 24 | F38: =COUNT(F9:F32) -> 24 | G38: =COUNT(G9:G32) -> 24 | H38: =COUNT(H9:H32) -> 24 | I38: =COUNT(I9:I32) -> 24 | ... Q38: =COUNT(Q9:Q32) -> 24
A39: DCR | B39: =IF(B38>=22,">90%",IF(B38<=22,"<90%")) -> >90% | C39: =IF(C38>=22,">90%",IF(C38<=22,"<90%")) -> <90% | D39: =IF(D38>=22,">90%",IF(D38<=22,"<90%")) -> >90% | E39: =IF(E38>=22,">90%",IF(E38<=22,"<90%")) -> >90% | F39: =IF(F38>=22,">90%",IF(F38<=22,"<90%")) -> >90% | G39: =IF(G38>=22,">90%",IF(G38<=22,"<90%")) -> >90% | H39: =IF(H38>=22,">90%",IF(H38<=22,"<90%")) -> >90% | I39: =IF(I38>=22,">90%",IF(I38<=22,"<90%")) -> >90% | ... Q39: =IF(Q38>=22,">90%",IF(Q38<=22,"<90%")) -> >90%
A40: Status | B40: =IF(B38>=22,"OK",IF(B38<=22,"LESS")) -> OK | C40: =IF(C38>=22,"OK",IF(C38<=22,"LESS")) -> LESS | D40: =IF(D38>=22,"OK",IF(D38<=22,"LESS")) -> OK | E40: =IF(E38>=22,"OK",IF(E38<=22,"LESS")) -> OK | F40: =IF(F38>=22,"OK",IF(F38<=22,"LESS")) -> OK | G40: =IF(G38>=22,"OK",IF(G38<=22,"LESS")) -> OK | H40: =IF(H38>=22,"OK",IF(H38<=22,"LESS")) -> OK | I40: =IF(I38>=22,"OK",IF(I38<=22,"LESS")) -> OK | ... Q40: =IF(Q38>=22,"OK",IF(Q38<=22,"LESS")) -> OK
A43: Done by | B43: RAHUL
A45: Comment

Sheet 06
A1: Station: | B1: BHATAGAON RAIPUR
A2: Date: | B2: =$A$9 -> 06-12-2022 01:00 | D2: Power Off | G2: Pw.Off | L2: Link Fail | N2: Link F | P2: Maintenance | R2: Maint.
A3: Report Type: | B3: Mean | D3: Calibration | G3: Calib. | L3: Data Fail | N3: Data F | P3: Invalid | R3: Invalid
A4: Time Base: | B4: 01 Hour | D4: Zero Referrence | G4: Z.Ref | L4: Warm Up | N4: Wm. Up
A7: Date & Time | B7: NO_BHATAGAON | C7: NO2_BHATAGAON | D7: NOX_BHATAGAON | E7: SO2_BHATAGAON | F7: O3_BHATAGAON | G7: PM10_BHATAGAON | H7: PM2_5_BHATAGAON | I7: BENZ_BHATAGAON | J7: WS_BHATAGAON | K7: WD_BHATAGAON | L7: TEMP_BHATAGAON | M7: HUM BHATAGAON | N7: SR_BHATAGAON | O7: RG_BHATAGAON | P7: CO_BHATAGAON | Q7: NH3_BHATAGAON
B8: ug/m3 | C8: ug/m3 | D8: ug/m3 | E8: ug/m3 | F8: ug/m3 | G8: mg/m3 | H8: ug/m3 | I8: ug/m3 | J8: m/sec | K8: deg | L8: degreC | M8: % | N8: w/m2 | O8: mm | P8: ug/m3 | Q8: ug/m3
A9: 06-12-2022 01:00 | B9: 79.64 | C9: 7.33 | D9: 64.9 | E9: 4.79 | F9: 0.8 | G9: 111.62 | H9: 43.45 | I9: 1.28 | J9: 0.13 | K9: 321.82 | L9: 18.79 | M9: 71 | N9: 24.6 | O9: 0 | P9: 2.88 | Q9: 52.88
A10: 06-12-2022 02:00 | B10: 61.43 | C10: 11.56 | D10: 54.01 | E10: 4.51 | F10: 0.83 | G10: 95.64 | H10: 39.68 | I10: 1.09 | J10: 0.15 | K10: 308.06 | L10: 17.34 | M10: 75 | N10: 24.5 | O10: 0 | P10: 2.36 | Q10: 50.89
A11: 06-12-2022 03:00 | B11: 50.26 | C11: 18.02 | D11: 47.18 | E11: 4.33 | F11: 0.9 | G11: 95.64 | H11: 36.45 | I11: 0.89 | J11: 0.39 | K11: 67.12 | L11: 19.03 | M11: 61 | N11: 24.1 | O11: 0 | P11: 2.09 | Q11: 47.88
A12: 06-12-2022 04:00 | B12: 33.95 | C12: 25 | D12: 37.81 | E12: 4.76 | F12: 0.99 | G12: 69.28 | H12: 34.68 | I12: 0.79 | J12: 0.61 | K12: 356.7 | L12: 18.73 | M12: 60 | N12: 24.2 | O12: 0 | P12: 1.71 | Q12: 47.26
A13: 06-12-2022 05:00 | B13: 22.54 | C13: 30.43 | D13: 32.71 | E13: 3.69 | F13: 0.97 | G13: 72.47 | H13: 28.62 | I13: 0.69 | J13: 0.62 | K13: 352.74 | L13: 18.45 | M13: 61 | N13: 24.3 | O13: 0 | P13: 1.4 | Q13: 46.81
A14: 06-12-2022 06:00 | B14: 14.84 | C14: 31.21 | D14: 29.03 | E14: 3.47 | F14: 0.87 | G14: 72.47 | H14: 27.29 | I14: 0.55 | J14: 0.24 | K14: 88.17 | L14: 17.68 | M14: 64 | N14: 24.4 | O14: 0 | P14: 1.19 | Q14: 44.86
A15: 06-12-2022 07:00 | B15: 22.01 | C15: 30.74 | D15: 32.11 | E15: 3.53 | F15: 0.79 | G15: 88.18 | H15: 29.93 | I15: 0.5 | J15: 0.08 | K15: 314.5 | L15: 17.2 | M15: 72 | N15: 44.2 | O15: 0 | P15: 1.23 | Q15: 43.86
A16: 06-12-2022 08:00 | B16: 32.69 | C16: 23.95 | D16: 37.35 | E16: 4.29 | F16: 0.75 | G16: 116.91 | H16: 34.37 | I16: 0.5 | J16: 0.57 | K16: 235.26 | L16: 20.99 | M16: 72 | N16: 222 | O16: 0 | P16: 1.35 | Q16: 45.99
A17: 06-12-2022 09:00 | B17: 30.73 | C17: 27.48 | D17: 36.82 | E17: 3.64 | F17: 0.88 | G17: 116.91 | H17: 34.37 | I17: 0.5 | J17: 1.37 | K17: 115.42 | L17: 22.07 | M17: 50 | N17: 356.2 | O17: 0 | P17: 1.33 | Q17: 45.4
A18: 06-12-2022 10:00 | B18: 22.33 | C18: 30.61 | D18: 33.6 | E18: 4.29 | F18: 1.12 | G18: 69.47 | H18: 28.63 | I18: 0.47 | J18: 1.21 | K18: 111.61 | L18: 24.79 | M18: 46 | N18: 416.1 | O18: 0 | P18: 1.2 | Q18: 44.39
A19: 06-12-2022 11:00 | B19: 15.55 | C19: 35.25 | D19: 29.71 | E19: 4.11 | F19: 2.45 | G19: 63.76 | H19: 28.63 | I19: 0.46 | J19: 1.16 | K19: 113.9 | L19: 26.41 | M19: 39 | N19: 469.2 | O19: 0 | P19: 1.1 | Q19: 44.84
A20: 06-12-2022 12:00 | B20: 5.41 | C20: 36.06 | D20: 23.69 | E20: 3.89 | F20: 5.41 | G20: 58.99 | H20: 26.25 | I20: 0.42 | J20: 0.71 | K20: 85.41 | L20: 29.38 | M20: 33 | N20: 466.5 | O20: 0 | P20: 0.95 | Q20: 43.31
... A28: 06-12-2022 20:00 | B28: 79.61 | C28: 20.88 | D28: 67.06 | E28: 4.33 | F28: 0.72 | G28: 172.61 | H28: 36.4 | I28: 0.87 | J28: 0.15 | K28: 339.89 | L28: 20.75 | M28: 61 | N28: 24.4 | O28: 0 | P28: 2.64 | Q28: 46.79
A29: 06-12-2022 21:00 | B29: 96.72 | C29: Invalid | D29: 75.07 | E29: 4.38 | F29: 0.71 | G29: 172.61 | H29: 36.4 | I29: 1.24 | J29: 0.28 | K29: 59.11 | L29: 21.42 | M29: 62 | N29: 23.7 | O29: 0 | P29: 3.1 | Q29: 49.88
A30: 06-12-2022 22:00 | B30: 93.32 | C30: Invalid | D30: 72.08 | E30: 4.33 | F30: 1.19 | G30: 131.19 | H30: 35.8 | I30: 1.3 | J30: 0.23 | K30: 72.06 | L30: 21.47 | M30: 53 | N30: 24.4 | O30: 0 | P30: 3.14 | Q30: 52.35
A31: 06-12-2022 23:00 | B31: 93.28 | C31: 1.83 | D31: 71.88 | E31: 4.56 | F31: 0.98 | G31: 104.22 | H31: 36.88 | I31: 1.38 | J31: 0.32 | K31: 85.8 | L31: 20.52 | M31: 53 | N31: 24.2 | O31: 0 | P31: 3.14 | Q31: 52.16
A32: 06-12-2022 24:00 | B32: 74.26 | C32: 9.24 | D32: 61.85 | E32: 4.13 | F32: 2.21 | G32: 155.87 | H32: 36.88 | I32: 1.23 | J32: 0.3 | K32: 83.01 | L32: 19.92 | M32: 55 | N32: 24.2 | O32: 0 | P32: 2.79 | Q32: 49.58
A34: Min | B34: =MIN(B9:B32) -> 4.97 | C34: =MIN(C9:C32) -> 1.83 | D34: =MIN(D9:D32) -> 23.3 | E34: =MIN(E9:E32) -> 3.47 | F34: =MIN(F9:F32) -> 0.71 | G34: =MIN(G9:G32) -> 55.74 | H34: =MIN(H9:H32) -> 26.25 | I34: =MIN(I9:I32) -> 0.28 | ... Q34: =MIN(Q9:Q32) -> 36.37
A35: Max | B35: =MAX(B9:B32) -> 96.72 | C35: =MAX(C9:C32) -> 45.58 | D35: =MAX(D9:D32) -> 75.07 | E35: =MAX(E9:E32) -> 9.2 | F35: =MAX(F9:F32) -> 17.87 | G35: =MAX(G9:G32) -> 172.61 | H35: =MAX(H9:H32) -> 43.45 | I35: =MAX(I9:I32) -> 1.38 | ... Q35: =MAX(Q9:Q32) -> 52.88
A36: Avg | B36: =AVERAGE(B9:B32) -> 38.945 | C36: =AVERAGE(C9:C32) -> 28.057273 | D36: =AVERAGE(D9:D32) -> 42.9675 | E36: =AVERAGE(E9:E32) -> 4.8733333 | F36: =AVERAGE(F9:F32) -> 3.2033333 | G36: =AVERAGE(G9:G32) -> 95.846667 | H36: =AVERAGE(H9:H32) -> 32.700833 | I36: =AVERAGE(I9:I32) -> 0.69083333 | ... Q36: =AVERAGE(Q9:Q32) -> 45.019583
A37: Stdev | B37: =STDEV(B9:B32) -> 31.72466 | C37: =STDEV(C9:C32) -> 12.162555 | D37: =STDEV(D9:D32) -> 17.324118 | E37: =STDEV(E9:E32) -> 1.6463548 | F37: =STDEV(F9:F32) -> 4.2457361 | G37: =STDEV(G9:G32) -> 39.05513 | H37: =STDEV(H9:H32) -> 4.6220078 | I37: =STDEV(I9:I32) -> 0.37481493 | ... Q37: =STDEV(Q9:Q32) -> 5.1475612
A38: Num | B38: =COUNT(B9:B32) -> 24 | C38: =COUNT(C9:C32) -> 22 | D38: =COUNT(D9:D32) -> 24 | E38: =COUNT(E9:E32) -> 24 | F38: =COUNT(F9:F32) -> 24 | G38: =COUNT(G9:G32) -> 24 | H38: =COUNT(H9:H32) -> 24 | I38: 24 | J38: =COUNT(J9:J32) -> 24 | K38: =COUNT(K9:K32) -> 24 | L38: =COUNT(L9:L32) -> 24 | M38: =COUNT(M9:M32) -> 24 | N38: =COUNT(N9:N32) -> 24 | O38: =COUNT(O9:O32) -> 24 | P38: =COUNT(P9:P32) -> 24 | Q38: =COUNT(Q9:Q32) -> 24
A39: DCR | B39: =IF(B38>=22,">90%",IF(B38<=22,"<90%")) -> >90% | C39: =IF(C38>=22,">90%",IF(C38<=22,"<90%")) -> >90% | D39: =IF(D38>=22,">90%",IF(D38<=22,"<90%")) -> >90% | E39: =IF(E38>=22,">90%",IF(E38<=22,"<90%")) -> >90% | F39: =IF(F38>=22,">90%",IF(F38<=22,"<90%")) -> >90% | G39: =IF(G38>=22,">90%",IF(G38<=22,"<90%")) -> >90% | H39: =IF(H38>=22,">90%",IF(H38<=22,"<90%")) -> >90% | I39: =IF(I38>=22,">90%",IF(I38<=22,"<90%")) -> >90% | ... Q39: =IF(Q38>=22,">90%",IF(Q38<=22,"<90%")) -> >90%
A40: Status | B40: =IF(B38>=22,"OK",IF(B38<=22,"LESS")) -> OK | C40: =IF(C38>=22,"OK",IF(C38<=22,"LESS")) -> OK | D40: =IF(D38>=22,"OK",IF(D38<=22,"LESS")) -> OK | E40: =IF(E38>=22,"OK",IF(E38<=22,"LESS")) -> OK | F40: =IF(F38>=22,"OK",IF(F38<=22,"LESS")) -> OK | G40: =IF(G38>=22,"OK",IF(G38<=22,"LESS")) -> OK | H40: =IF(H38>=22,"OK",IF(H38<=22,"LESS")) -> OK | I40: =IF(I38>=22,"OK",IF(I38<=22,"LESS")) -> OK | ... Q40: =IF(Q38>=22,"OK",IF(Q38<=22,"LESS")) -> OK
A43: Done by | B43: RAHUL
A45: Comment

Sheet 07
A1: Station: | B1: BHATAGAON RAIPUR
A2: Date: | B2: =$A$9 -> 07-12-2022 01:00 | D2: Power Off | G2: Pw.Off | L2: Link Fail | N2: Link F | P2: Maintenance | R2: Maint.
A3: Report Type: | B3: Mean | D3: Calibration | G3: Calib. | L3: Data Fail | N3: Data F | P3: Invalid | R3: Invalid
A4: Time Base: | B4: 01 Hour | D4: Zero Referrence | G4: Z.Ref | L4: Warm Up | N4: Wm. Up
A7: Date & Time | B7: NO_BHATAGAON | C7: NO2_BHATAGAON | D7: NOX_BHATAGAON | E7: SO2_BHATAGAON | F7: O3_BHATAGAON | G7: PM10_BHATAGAON | H7: PM2_5_BHATAGAON | I7: BENZ_BHATAGAON | J7: WS_BHATAGAON | K7: WD_BHATAGAON | L7: TEMP_BHATAGAON | M7: HUM BHATAGAON | N7: SR_BHATAGAON | O7: RG_BHATAGAON | P7: CO_BHATAGAON | Q7: NH3_BHATAGAON
B8: ug/m3 | C8: ug/m3 | D8: ug/m3 | E8: ug/m3 | F8: ug/m3 | G8: mg/m3 | H8: ug/m3 | I8: ug/m3 | J8: m/sec | K8: deg | L8: degreC | M8: % | N8: w/m2 | O8: mm | P8: ug/m3 | Q8: ug/m3
A9: 07-12-2022 01:00 | B9: 60.21 | C9: 11.77 | D9: 53.31 | E9: 4.81 | F9: 1.2 | G9: 155.87 | H9: 33.7 | I9: 1.05 | J9: 0.14 | K9: 237.61 | L9: 19.36 | M9: 61 | N9: 24.4 | O9: 0 | P9: 2.49 | Q9: 47.86
A10: 07-12-2022 02:00 | B10: 46.93 | C10: 16.18 | D10: 44.67 | E10: 4.41 | F10: 0.69 | G10: 69.59 | H10: 30.05 | I10: 0.98 | J10: 0.13 | K10: 335.07 | L10: 18.1 | M10: 69 | N10: 24.5 | O10: 0 | P10: 1.98 | Q10: 48.74
A11: 07-12-2022 03:00 | B11: 33.78 | C11: 18.69 | D11: 36.69 | E11: 4.1 | F11: 0.67 | G11: 96.08 | H11: 26.86 | I11: 0.83 | J11: 0.14 | K11: 317.07 | L11: 16.98 | M11: 77 | N11: 24.3 | O11: 0 | P11: 1.73 | Q11: 46.96
A12: 07-12-2022 04:00 | B12: 29.76 | C12: 18.4 | D12: 33.36 | E12: 4.22 | F12: 0.7 | G12: 104.98 | H12: 28.59 | I12: 0.71 | J12: 0.13 | K12: 334.94 | L12: 15.72 | M12: 80 | N12: 24.3 | O12: 0 | P12: 1.51 | Q12: 43.94
A13: 07-12-2022 05:00 | B13: 29.26 | C13: 19.71 | D13: 32.72 | E13: 4.14 | F13: 0.8 | G13: 104.98 | H13: 28.84 | I13: 0.68 | J13: 0.9 | K13: 26.7 | L13: 17.05 | M13: 69 | N13: 24.1 | O13: 0 | P13: 1.37 | Q13: 45.29
A14: 07-12-2022 06:00 | B14: 25.76 | C14: 23.66 | D14: 32.12 | E14: 4.67 | F14: 0.68 | G14: 117.72 | H14: 32.41 | I14: 0.63 | J14: 1.33 | K14: 12.74 | L14: 17.19 | M14: 69 | N14: 24.1 | O14: 0 | P14: 1.36 | Q14: 45.12
A15: 07-12-2022 07:00 | B15: 21.05 | C15: 24.54 | D15: 30.41 | E15: 4 | F15: 0.81 | G15: 117.72 | H15: 32.41 | I15: 0.52 | J15: 0.76 | K15: 357.47 | L15: 16.66 | M15: 74 | N15: 47.4 | O15: 0 | P15: 1.24 | Q15: 43
A16: 07-12-2022 08:00 | B16: 23.37 | C16: 23.84 | D16: 31.76 | E16: 4.55 | F16: 1.08 | G16: 123.45 | H16: 35.13 | I16: Maint. | J16: 0.88 | K16: 104.35 | L16: 19.14 | M16: 72 | N16: 156.6 | O16: 0 | P16: 1.34 | Q16: 41.67
A17: 07-12-2022 09:00 | B17: 22.96 | C17: 28.94 | D17: 34.09 | E17: 5.46 | F17: 0.86 | G17: 123.45 | H17: 35.9 | I17: Maint. | J17: 1.53 | K17: 20.45 | L17: 23.41 | M17: 55 | N17: 299.7 | O17: 0 | P17: 1.36 | Q17: 43.24
A18: 07-12-2022 10:00 | B18: 21.91 | C18: 36.31 | D18: 34.72 | E18: 5.34 | F18: 1.78 | G18: 125.02 | H18: 35.92 | I18: Maint. | J18: 1.45 | K18: 52.04 | L18: 24.65 | M18: 43 | N18: 389 | O18: 0 | P18: 1.35 | Q18: 42.42
A19: 07-12-2022 11:00 | B19: 13.08 | C19: 39 | D19: 31.38 | E19: 5.7 | F19: 2.28 | G19: 125.02 | H19: 36.6 | I19: Maint. | J19: 1.29 | K19: 25.12 | L19: 26.26 | M19: 37 | N19: 444.8 | O19: 0 | P19: 1.25 | Q19: 39.99
A20: 07-12-2022 12:00 | B20: 7.95 | C20: 40.28 | D20: 28.36 | E20: 5.47 | F20: 2.61 | G20: 74.63 | H20: 36.6 | I20: Maint. | J20: 1.36 | K20: 77.95 | L20: 27.18 | M20: 31 | N20: 480.4 | O20: 0 | P20: 1.17 | Q20: 40.31
A21: 07-12-2022 13:00 | B21: 5.51 | C21: 38.98 | D21: 25.93 | E21: 4.87 | F21: 2.27 | G21: 74.63 | H21: 37.1 | I21: 0.42 | J21: 1.21 | K21: 99.71 | L21: 27.58 | M21: 25 | N21: 478.2 | O21: 0 | P21: 1.09 | Q21: 41.45
A22: 07-12-2022 14:00 | B22: 3.86 | C22: 37.22 | D22: 23.64 | E22: 4.9 | F22: 3.12 | G22: 33.76 | H22: 37.1 | I22: 0.38 | J22: 1.44 | K22: 120.74 | L22: 26.13 | M22: 27 | N22: 430.3 | O22: 0 | P22: 0.96 | Q22: 40.75
A23: 07-12-2022 15:00 | B23: 5.01 | C23: 33.08 | D23: 22.12 | E23: 5.17 | F23: 3.95 | G23: 45.6 | H23: 35.09 | I23: 0.35 | J23: 0.74 | K23: 113.53 | L23: 27.14 | M23: 24 | N23: 351.7 | O23: 0 | P23: 0.88 | Q23: 39.79
A24: 07-12-2022 16:00 | B24: 4.76 | C24: 37.65 | D24: 24.31 | E24: 6.16 | F24: 4.09 | G24: 75.21 | H24: 31.45 | I24: 0.35 | J24: 1.18 | K24: 13.95 | L24: 27.56 | M24: 25 | N24: 231.2 | O24: 0 | P24: 0.96 | Q24: 41.94
A25: 07-12-2022 17:00 | B25: 5.6 | C25: 41.12 | D25: 27.18 | E25: 4.35 | F25: 2.32 | G25: 75.21 | H25: 31.58 | I25: 0.34 | J25: 1.06 | K25: 358.52 | L25: 24.91 | M25: 42 | N25: 60.7 | O25: 0 | P25: 1.12 | Q25: 41.37
A26: 07-12-2022 18:00 | B26: 14.23 | C26: 43.68 | D26: 34.35 | E26: 4.46 | F26: 1.32 | G26: 108.87 | H26: 32.09 | I26: 0.4 | J26: 0.46 | K26: 52.81 | L26: 22.69 | M26: 47 | N26: 27.1 | O26: 0 | P26: 1.35 | Q26: 40.43
A27: 07-12-2022 19:00 | B27: 24.96 | C27: 41.28 | D27: 40.39 | E27: 4.36 | F27: 0.77 | G27: 113.67 | H27: 33.99 | I27: 0.52 | J27: 0.25 | K27: 352.68 | L27: 21.56 | M27: 54 | N27: 24.5 | O27: 0 | P27: 1.75 | Q27: 43.44
A28: 07-12-2022 20:00 | B28: 62.47 | C28: 34.6 | D28: 60.87 | E28: 4.56 | F28: 0.77 | G28: 158.69 | H28: 37.59 | I28: 0.76 | J28: 0.16 | K28: 357.54 | L28: 18.71 | M28: 63 | N28: 24.4 | O28: 0 | P28: 2.57 | Q28: 47
A29: 07-12-2022 21:00 | B29: 110.28 | C29: 10.57 | D29: 86.24 | E29: 4.74 | F29: 0.76 | G29: 185.74 | H29: 47.72 | I29: 1.18 | J29: 0.1 | K29: 336.45 | L29: 18.37 | M29: 62 | N29: 24.1 | O29: 0 | P29: 3.8 | Q29: 49.35
A30: 07-12-2022 22:00 | B30: 130.53 | C30: Invalid | D30: 95.09 | E30: 5.62 | F30: 0.85 | G30: 199.4 | H30: 56.26 | I30: 1.76 | J30: 0.21 | K30: 80.34 | L30: 19.28 | M30: 62 | N30: 24.4 | O30: 0 | P30: 4.38 | Q30: 50.83
A31: 07-12-2022 23:00 | B31: 129.82 | C31: Invalid | D31: 93.67 | E31: 5.54 | F31: 0.8 | G31: 199.4 | H31: 56.26 | I31: 1.88 | J31: 0.3 | K31: 77.63 | L31: 18.54 | M31: 55 | N31: 24.1 | O31: 0 | P31: 4.4 | Q31: 51.8
A32: 07-12-2022 24:00 | B32: 112.29 | C32: Invalid | D32: 83.26 | E32: 5.1 | F32: 0.75 | G32: 183.02 | H32: 54.97 | I32: 1.82 | J32: 0.84 | K32: 62.84 | L32: 18.52 | M32: 49 | N32: 24 | O32: 0 | P32: 3.99 | Q32: 51.02
A34: Min | B34: =MIN(B9:B32) -> 3.86 | C34: =MIN(C9:C32) -> 10.57 | D34: =MIN(D9:D32) -> 22.12 | E34: =MIN(E9:E32) -> 4 | F34: =MIN(F9:F32) -> 0.67 | G34: =MIN(G9:G32) -> 33.76 | H34: =MIN(H9:H32) -> 26.86 | I34: =MIN(I9:I32) -> 0.34 | ... Q34: =MIN(Q9:Q32) -> 39.79
A35: Max | B35: =MAX(B9:B32) -> 130.53 | C35: =MAX(C9:C32) -> 43.68 | D35: =MAX(D9:D32) -> 95.09 | E35: =MAX(E9:E32) -> 6.16 | F35: =MAX(F9:F32) -> 4.09 | G35: =MAX(G9:G32) -> 199.4 | H35: =MAX(H9:H32) -> 56.26 | I35: =MAX(I9:I32) -> 1.88 | ... Q35: =MAX(Q9:Q32) -> 51.8
A36: Avg | B36: =AVERAGE(B9:B32) -> 39.389167 | C36: =AVERAGE(C9:C32) -> 29.5 | D36: =AVERAGE(D9:D32) -> 43.36 | E36: =AVERAGE(E9:E32) -> 4.8625 | F36: =AVERAGE(F9:F32) -> 1.4970833 | G36: =AVERAGE(G9:G32) -> 116.32125 | H36: =AVERAGE(H9:H32) -> 36.842083 | I36: =AVERAGE(I9:I32) -> 0.81894737 | ... Q36: =AVERAGE(Q9:Q32) -> 44.487917
A37: Stdev | B37: =STDEV(B9:B32) -> 40.584401 | C37: =STDEV(C9:C32) -> 10.62898 | D37: =STDEV(D9:D32) -> 22.954615 | E37: =STDEV(E9:E32) -> 0.58645026 | F37: =STDEV(F9:F32) -> 1.0619772 | G37: =STDEV(G9:G32) -> 45.814231 | H37: =STDEV(H9:H32) -> 8.403298 | I37: =STDEV(I9:I32) -> 0.50930121 | ... Q37: =STDEV(Q9:Q32) -> 3.8217706
A38: Num | B38: =COUNT(B9:B32) -> 24 | C38: =COUNT(C9:C32) -> 21 | D38: =COUNT(D9:D32) -> 24 | E38: =COUNT(E9:E32) -> 24 | F38: =COUNT(F9:F32) -> 24 | G38: =COUNT(G9:G32) -> 24 | H38: =COUNT(H9:H32) -> 24 | I38: =COUNT(I9:I32)+5 -> 24 | J38: =COUNT(J9:J32) -> 24 | K38: =COUNT(K9:K32) -> 24 | L38: =COUNT(L9:L32) -> 24 | M38: =COUNT(M9:M32) -> 24 | N38: =COUNT(N9:N32) -> 24 | O38: =COUNT(O9:O32) -> 24 | P38: =COUNT(P9:P32) -> 24 | Q38: =COUNT(Q9:Q32) -> 24
A39: DCR | B39: =IF(B38>=22,">90%",IF(B38<=22,"<90%")) -> >90% | C39: =IF(C38>=22,">90%",IF(C38<=22,"<90%")) -> <90% | D39: =IF(D38>=22,">90%",IF(D38<=22,"<90%")) -> >90% | E39: =IF(E38>=22,">90%",IF(E38<=22,"<90%")) -> >90% | F39: =IF(F38>=22,">90%",IF(F38<=22,"<90%")) -> >90% | G39: =IF(G38>=22,">90%",IF(G38<=22,"<90%")) -> >90% | H39: =IF(H38>=22,">90%",IF(H38<=22,"<90%")) -> >90% | I39: =IF(I38>=22,">90%",IF(I38<=22,"<90%")) -> >90% | ... Q39: =IF(Q38>=22,">90%",IF(Q38<=22,"<90%")) -> >90%
A40: Status | B40: =IF(B38>=22,"OK",IF(B38<=22,"LESS")) -> OK | C40: =IF(C38>=22,"OK",IF(C38<=22,"LESS")) -> LESS | D40: =IF(D38>=22,"OK",IF(D38<=22,"LESS")) -> OK | E40: =IF(E38>=22,"OK",IF(E38<=22,"LESS")) -> OK | F40: =IF(F38>=22,"OK",IF(F38<=22,"LESS")) -> OK | G40: =IF(G38>=22,"OK",IF(G38<=22,"LESS")) -> OK | H40: =IF(H38>=22,"OK",IF(H38<=22,"LESS")) -> OK | I40: =IF(I38>=22,"OK",IF(I38<=22,"LESS")) -> OK | ... Q40: =IF(Q38>=22,"OK",IF(Q38<=22,"LESS")) -> OK
A43: Done by | B43: RAHUL
A45: Comment

Sheet 08
A1: Station: | B1: BHATAGAON RAIPUR
A2: Date: | B2: =$A$9 -> 08-12-2022 01:00 | D2: Power Off | G2: Pw.Off | L2: Link Fail | N2: Link F | P2: Maintenance | R2: Maint.
A3: Report Type: | B3: Mean | D3: Calibration | G3: Calib. | L3: Data Fail | N3: Data F | P3: Invalid | R3: Invalid
A4: Time Base: | B4: 01 Hour | D4: Zero Referrence | G4: Z.Ref | L4: Warm Up | N4: Wm. Up
A7: Date & Time | B7: NO_BHATAGAON | C7: NO2_BHATAGAON | D7: NOX_BHATAGAON | E7: SO2_BHATAGAON | F7: O3_BHATAGAON | G7: PM10_BHATAGAON | H7: PM2_5_BHATAGAON | I7: BENZ_BHATAGAON | J7: WS_BHATAGAON | K7: WD_BHATAGAON | L7: TEMP_BHATAGAON | M7: HUM BHATAGAON | N7: SR_BHATAGAON | O7: RG_BHATAGAON | P7: CO_BHATAGAON | Q7: NH3_BHATAGAON
B8: ug/m3 | C8: ug/m3 | D8: ug/m3 | E8: ug/m3 | F8: ug/m3 | G8: mg/m3 | H8: ug/m3 | I8: ug/m3 | J8: m/sec | K8: deg | L8: degreC | M8: % | N8: w/m2 | O8: mm | P8: ug/m3 | Q8: ug/m3
A9: 08-12-2022 01:00 | B9: 77.65 | C9: 12.11 | D9: 64.29 | E9: 5.45 | F9: 0.8 | G9: 86.94 | H9: 47.05 | I9: 1.33 | J9: 0.92 | K9: 110.44 | L9: 18.27 | M9: 53 | N9: 24.6 | O9: 0 | P9: 3.13 | Q9: 46.97
A10: 08-12-2022 02:00 | B10: 52.99 | C10: 18.27 | D10: 50.23 | E10: 5.4 | F10: 0.76 | G10: 100.2 | H10: 38.26 | I10: 1.04 | J10: 0.6 | K10: 131.79 | L10: 17.33 | M10: 59 | N10: 24.6 | O10: 0 | P10: 2.61 | Q10: 42.99
A11: 08-12-2022 03:00 | B11: 37.65 | C11: 27.65 | D11: 41.06 | E11: 5.37 | F11: 0.79 | G11: 100.2 | H11: 35.66 | I11: 0.89 | J11: 1.33 | K11: 13.97 | L11: 17.25 | M11: 56 | N11: 24.5 | O11: 0 | P11: 2.37 | Q11: 42.98
