Workbook

Sheet 01
A1: Station: | B1: BHATAGAON RAIPPUR
A2: Date: | B2: =$A$9 -> 01-12-2022 00:15 | D2: Power Off | G2: Pw.Off | L2: Link Fail | N2: Link F | P2: Maintenance | R2: Maint.
A3: Report Type: | B3: Mean | D3: Calibration | G3: Calib. | L3: Data Fail | N3: Data F | P3: Invalid | R3: Invalid
A4: Time Base: | B4: 15 Min | D4: Zero Referrence | G4: Z.Ref | L4: Warm Up | N4: Wm. Up
A7: Date & Time | B7: NO_BHATAGAON | C7: NO2__BHATAGAON | D7: NOX_BHATAGAON | E7: SO2__BHATAGAON | F7: O3__BHATAGAON | G7: PM10__BHATAGAON | H7: PM2_5__BHATAGAON | I7: BENZ__BHATAGAON | J7: WS__BHATAGAON | K7: WD__BHATAGAON | L7: TEMP__BHATAGAON | M7: HUM__BHATAGAON | N7: SR__BHATAGAON | O7: RG__BHATAGAON | P7: CO__BHATAGAON | Q7: NH3__BHATAGAON
B8: ug/m3 | C8: ug/m3 | D8: ug/m3 | E8: ug/m3 | F8: ug/m3 | G8: ug/m3 | H8: ug/m3 | I8: ug/m3 | J8: m/sec | K8: deg | L8: degreC | M8: % | N8: w/m2 | O8: mm | P8: mg/m3 | Q8: ug/m3
A9: 01-12-2022 00:15 | B9: 93.75 | C9: 135.96 | D9: 150.21 | E9: 4.45 | F9: 0.73 | G9: 223.96 | H9: 66.47 | I9: 1.51 | J9: 0.13 | K9: 285.14 | L9: 18.08 | M9: 91 | N9: Maint. | O9: 0 | P9: 3.84 | Q9: 150.04
A10: 01-12-2022 00:30 | B10: 93.87 | C10: 136.52 | D10: 150.61 | E10: 5.15 | F10: 0.77 | G10: 223.96 | H10: 66.47 | I10: 1.52 | J10: 0.2 | K10: 286.32 | L10: 17.81 | M10: 70 | N10: Maint. | O10: 0 | P10: 3.81 | Q10: 151.77
A11: 01-12-2022 00:45 | B11: 92.21 | C11: 135.25 | D11: 148.58 | E11: 4.9 | F11: 0.54 | G11: 204.59 | H11: 65.15 | I11: 1.54 | J11: 0.13 | K11: 293.2 | L11: 17.56 | M11: 89 | N11: Maint. | O11: 0 | P11: 3.79 | Q11: 151.7
A12: 01-12-2022 01:00 | B12: 90.23 | C12: 133.48 | D12: 146.02 | E12: 4.93 | F12: 0.57 | G12: 162.17 | H12: 61.05 | I12: 1.53 | J12: 0.12 | K12: 294.27 | L12: 17.48 | M12: 83 | N12: Maint. | O12: 0 | P12: 3.76 | Q12: 150.71
A13: 01-12-2022 01:15 | B13: 88.51 | C13: 131.68 | D13: 143.65 | E13: 4.73 | F13: 0.61 | G13: 162.17 | H13: 61.05 | I13: 1.53 | J13: 0.48 | K13: 294.61 | L13: 17.5 | M13: 79 | N13: Maint. | O13: 0 | P13: 3.4 | Q13: 149.59
A14: 01-12-2022 01:30 | B14: 85.07 | C14: 129.13 | D14: 139.48 | E14: 4.79 | F14: 0.54 | G14: 162.17 | H14: 61.05 | I14: 1.52 | J14: 0.44 | K14: 273.83 | L14: 17.88 | M14: 92 | N14: Maint. | O14: 0 | P14: 3.5 | Q14: 147.78
A15: 01-12-2022 01:45 | B15: 79.78 | C15: 125.97 | D15: 133.49 | E15: 4.89 | F15: 0.56 | G15: 169.23 | H15: 61.69 | I15: 1.52 | J15: 0.23 | K15: 271.01 | L15: 17.85 | M15: 92 | N15: Maint. | O15: 0 | P15: 3.39 | Q15: 145.66
A16: 01-12-2022 02:00 | B16: 74.03 | C16: 121.9 | D16: 126.64 | E16: 5.04 | F16: 0.63 | G16: 185.45 | H16: 63.78 | I16: 1.47 | J16: 0.13 | K16: 273.5 | L16: 17.65 | M16: 76 | N16: Maint. | O16: 0 | P16: 3.28 | Q16: 143.5
A17: 01-12-2022 02:15 | B17: 68.64 | C17: 116.89 | D17: 119.55 | E17: 4.65 | F17: 0.51 | G17: 185.45 | H17: 63.78 | I17: 1.42 | J17: 0.16 | K17: 273.75 | L17: 17.62 | M17: 72 | N17: Maint. | O17: 0 | P17: 3.19 | Q17: 141.7
A18: 01-12-2022 02:30 | B18: 63.92 | C18: 113.85 | D18: 114.09 | E18: 4.22 | F18: 0.5 | G18: 185.45 | H18: 63.78 | I18: 1.36 | J18: 0.2 | K18: 275.7 | L18: 17.52 | M18: 71 | N18: Maint. | O18: 0 | P18: 3.1 | Q18: 138.75
A19: 01-12-2022 02:45 | B19: 59.53 | C19: 110.54 | D19: 108.74 | E19: 4.29 | F19: 0.64 | G19: 187.93 | H19: 66.13 | I19: 1.3 | J19: 0.11 | K19: 277.5 | L19: 17.26 | M19: 86 | N19: Maint. | O19: 0 | P19: 3.02 | Q19: 135.4
A20: 01-12-2022 03:00 | B20: 55.38 | C20: 107.61 | D20: 103.8 | E20: 4.59 | F20: 0.66 | G20: 193.63 | H20: 73.84 | I20: 1.25 | J20: 0.38 | K20: 278.93 | L20: 17.14 | M20: 89 | N20: Maint. | O20: 0 | P20: 2.94 | Q20: 133.69
... A37: 01-12-2022 07:15 | B37: 41.4 | C37: 93.82 | D37: 84.98 | E37: 4.9 | F37: 0.6 | G37: 97.6 | H37: 48.54 | I37: 0.65 | J37: 0.16 | K37: 282.52 | L37: 17.2 | M37: 52 | N37: Maint. | O37: 0 | P37: 1.94 | Q37: 122.04
A38: 01-12-2022 07:30 | B38: 43.13 | C38: 96.08 | D38: 87.61 | E38: 4.85 | F38: 0.75 | G38: 97.6 | H38: 48.54 | I38: 0.64 | J38: 0.16 | K38: 268.65 | L38: 18.08 | M38: 64 | N38: 4.3 | O38: 0 | P38: 2.02 | Q38: 122.82
A39: 01-12-2022 07:45 | B39: 44.94 | C39: 98.78 | D39: 90.55 | E39: 5.06 | F39: 0.75 | G39: 99.18 | H39: 48.68 | I39: 0.64 | J39: 0.86 | K39: 243.05 | L39: 19.64 | M39: 87 | N39: 41 | O39: 0 | P39: 2 | Q39: 124.61
A40: 01-12-2022 08:00 | B40: 44.35 | C40: 100.72 | D40: 91.15 | E40: 2.42 | F40: 0.6 | G40: 107.39 | H40: 49.12 | I40: 0.63 | J40: 0.66 | K40: 221.37 | L40: 21.58 | M40: 87 | N40: 76 | O40: 0 | P40: 1.94 | Q40: 124.51
A41: 01-12-2022 08:15 | B41: 43.07 | C41: 101.81 | D41: 90.72 | E41: 4.61 | F41: 0.63 | G41: 107.39 | H41: 49.12 | I41: 0.64 | J41: 0.67 | K41: 200.89 | L41: 23.04 | M41: 84 | N41: 105.4 | O41: 0 | P41: 1.9 | Q41: 124.87
A42: 01-12-2022 08:30 | B42: 41.46 | C42: 102.66 | D42: 89.9 | E42: 4.5 | F42: 0.54 | G42: 107.39 | H42: 49.12 | I42: 0.63 | J42: 0.67 | K42: 194.69 | L42: 23.78 | M42: 85 | N42: 136.5 | O42: 0 | P42: 1.85 | Q42: 124.29
A43: 01-12-2022 08:45 | B43: 39.29 | C43: 102.7 | D43: 88.18 | E43: 5.07 | F43: 0.78 | G43: 99.37 | H43: 48.04 | I43: 0.62 | J43: 0.69 | K43: 190.2 | L43: 24.04 | M43: 65 | N43: 160.7 | O43: 0 | P43: 1.8 | Q43: 123.11
A44: 01-12-2022 09:00 | B44: 37.33 | C44: 102.12 | D44: 86.29 | E44: 4.6 | F44: 0.68 | G44: 81.79 | H44: 44.49 | I44: 0.62 | J44: 0.62 | K44: 200.52 | L44: 23.46 | M44: 68 | N44: 182 | O44: 0 | P44: 1.77 | Q44: 122.04
A45: 01-12-2022 09:15 | B45: 35.12 | C45: 100.65 | D45: 83.71 | E45: 4.78 | F45: 0.75 | G45: 81.79 | H45: 44.49 | I45: 0.61 | J45: 0.75 | K45: 180.94 | L45: 25.2 | M45: 67 | N45: 199.6 | O45: 0 | P45: 1.74 | Q45: 123.88
A46: 01-12-2022 09:30 | B46: 32.4 | C46: 98.92 | D46: 80.57 | E46: 5.19 | F46: 0.84 | G46: 81.79 | H46: 44.49 | I46: 0.61 | J46: 1.52 | K46: 202.37 | L46: 22.89 | M46: 33 | N46: 224.8 | O46: 0 | P46: 1.71 | Q46: 122.32
A47: 01-12-2022 09:45 | B47: 28.63 | C47: 96.07 | D47: 75.97 | E47: 4.88 | F47: 0.75 | G47: 81.53 | H47: 43.97 | I47: 0.61 | J47: 0.82 | K47: 199.21 | L47: 23.45 | M47: 47 | N47: 232 | O47: 0 | P47: 1.66 | Q47: 118.88
A48: 01-12-2022 10:00 | B48: 25.1 | C48: 93.84 | D48: 71.91 | E48: 4.5 | F48: 0.97 | G48: 80.96 | H48: 42.27 | I48: 0.6 | J48: 0.93 | K48: 194.19 | L48: 24.12 | M48: 44 | N48: 243.7 | O48: 0 | P48: 1.61 | Q48: 116.83
A49: 01-12-2022 10:15 | B49: 21.72 | C49: 92.21 | D49: 68.31 | E49: 4.45 | F49: 1.09 | G49: 80.96 | H49: 42.27 | I49: 0.58 | J49: 0.89 | K49: 177.79 | L49: 25.77 | M49: 71 | N49: 254.8 | O49: 0 | P49: 1.58 | Q49: 115.79
... A71: 01-12-2022 15:45 | B71: 2.36 | C71: 84.03 | D71: 48.26 | E71: 10.35 | F71: 5.85 | G71: 63.84 | H71: 35.07 | I71: 0.28 | J71: 0.97 | K71: 124.64 | L71: 28.54 | M71: 87 | N71: 4 | O71: 0 | P71: 1.1 | Q71: 98.15
A72: 01-12-2022 16:00 | B72: 2.29 | C72: 85.59 | D72: 49.08 | E72: 5.5 | F72: 11.21 | G72: 75.95 | H72: 35.99 | I72: 0.3 | J72: 2.53 | K72: 146.78 | L72: 13.22 | M72: 92 | N72: Maint. | O72: 0 | P72: 1.14 | Q72: 0
A73: 01-12-2022 16:15 | B73: 2.59 | C73: 88.85 | D73: 51.11 | E73: 7.56 | F73: 7.83 | G73: 75.95 | H73: 35.99 | I73: 0.32 | J73: 0.71 | K73: 148.75 | L73: 84.46 | M73: 99 | N73: Maint. | O73: 0 | P73: 1.18 | Q73: 95.18
A74: 01-12-2022 16:30 | B74: 2.93 | C74: 93.65 | D74: 54.03 | E74: 5.18 | F74: 4.11 | G74: 75.95 | H74: 35.99 | I74: 0.31 | J74: 0.44 | K74: 121.21 | L74: 9.69 | M74: 87 | N74: Maint. | O74: 0 | P74: 1.27 | Q74: 93.12
A75: 01-12-2022 16:45 | B75: 3.55 | C75: 89.41 | D75: 52.19 | E75: 10.19 | F75: 16.85 | G75: 74.38 | H75: 35.9 | I75: 0.3 | J75: 0.61 | K75: 201.72 | L75: 26.63 | M75: 82 | N75: Maint. | O75: 0 | P75: 1.48 | Q75: 81.84
A76: 01-12-2022 17:00 | B76: 4.2 | C76: 108.54 | D76: 63.27 | E76: 10.59 | F76: 8.97 | G76: 70.95 | H76: 35.61 | I76: 0.3 | J76: 0.44 | K76: 215.22 | L76: 25.87 | M76: 79 | N76: Maint. | O76: 0 | P76: 1.6 | Q76: 77.93
A77: 01-12-2022 17:15 | B77: 4.97 | C77: 129.08 | D77: 75.22 | E77: 4.58 | F77: 2.05 | G77: 70.95 | H77: 35.61 | I77: 0.3 | J77: 0.22 | K77: 222.39 | L77: 25.1 | M77: 77 | N77: Maint. | O77: 0 | P77: 1.65 | Q77: 85.06
A78: 01-12-2022 17:30 | B78: 7.42 | C78: 126.21 | D78: 75.6 | E78: 3.67 | F78: 0.95 | G78: 70.95 | H78: 35.61 | I78: 0.32 | J78: 0.08 | K78: 67.62 | L78: 24.24 | M78: 48 | N78: Maint. | O78: 0 | P78: 1.69 | Q78: 88.12
A79: 01-12-2022 17:45 | B79: 9.97 | C79: 123.26 | D79: 76.02 | E79: 3.48 | F79: 0.54 | G79: 79.99 | H79: 37.1 | I79: 0.35 | J79: 0.12 | K79: Maint. | L79: 23.64 | M79: 47 | N79: Maint. | O79: 0 | P79: 1.8 | Q79: 91.17
...

Sheet 02
A1: Station: | B1: BHATAGAON RAIPUR
A2: Date: | B2: =$A$9 -> 02-12-2022 00:15 | D2: Power Off | G2: Pw.Off | L2: Link Fail | N2: Link F | P2: Maintenance | R2: Maint.
A3: Report Type: | B3: Mean | D3: Calibration | G3: Calib. | L3: Data Fail | N3: Data F | P3: Invalid | R3: Invalid
A4: Time Base: | B4: 15 Min | D4: Zero Referrence | G4: Z.Ref | L4: Warm Up | N4: Wm. Up
A7: Date & Time | B7: NO_BHATAGAON | C7: NO2__BHATAGAON | D7: NOX_BHATAGAON | E7: SO2__BHATAGAON | F7: O3__BHATAGAON | G7: PM10__BHATAGAON | H7: PM2_5__BHATAGAON | I7: BENZ__BHATAGAON | J7: WS__BHATAGAON | K7: WD__BHATAGAON | L7: TEMP__BHATAGAON | M7: HUM__BHATAGAON | N7: SR__BHATAGAON | O7: RG__BHATAGAON | P7: CO__BHATAGAON | Q7: NH3__BHATAGAON
B8: ug/m3 | C8: ug/m3 | D8: ug/m3 | E8: ug/m3 | F8: ug/m3 | G8: ug/m3 | H8: ug/m3 | I8: ug/m3 | J8: m/sec | K8: deg | L8: degreC | M8: % | N8: w/m2 | O8: mm | P8: mg/m3 | Q8: ug/m3
A9: 02-12-2022 00:15 | B9: 64.2 | C9: 118.58 | D9: 116.92 | E9: 4.19 | F9: 0.65 | G9: 173.9 | H9: 50.66 | I9: 1.21 | J9: 0.24 | K9: Maint. | L9: 18.51 | M9: Maint. | N9: Maint. | O9: 0 | P9: 2.96 | Q9: 139.38
A10: 02-12-2022 00:30 | B10: 62.38 | C10: 117.08 | D10: 114.64 | E10: 4.38 | F10: 0.6 | G10: 173.9 | H10: 50.66 | I10: 1.2 | J10: 0.16 | K10: Maint. | L10: 18.54 | M10: Maint. | N10: Maint. | O10: 0 | P10: 2.92 | Q10: 139.46
A11: 02-12-2022 00:45 | B11: 60.7 | C11: 115.47 | D11: 112.41 | E11: 3.83 | F11: 0.59 | G11: 156.29 | H11: 50.45 | I11: 1.19 | J11: 0.11 | K11: Maint. | L11: 18.51 | M11: Maint. | N11: Maint. | O11: 0 | P11: 2.89 | Q11: 138.99
A12: 02-12-2022 01:00 | B12: 58.76 | C12: 113.49 | D12: 109.76 | E12: 4.19 | F12: 0.55 | G12: 117.71 | H12: 49.8 | I12: 1.18 | J12: 0.11 | K12: Maint. | L12: 18.14 | M12: Maint. | N12: Maint. | O12: 0 | P12: 2.85 | Q12: 138.07
A13: 02-12-2022 01:15 | B13: 56.76 | C13: 111.99 | D13: 107.32 | E13: 4.15 | F13: 0.46 | G13: 117.71 | H13: 49.8 | I13: 1.16 | J13: 0.13 | K13: Maint. | L13: 17.89 | M13: Maint. | N13: Maint. | O13: 0 | P13: 2.71 | Q13: 137.63
A14: 02-12-2022 01:30 | B14: 55.02 | C14: 110.95 | D14: 105.35 | E14: 4.5 | F14: 0.58 | G14: 117.71 | H14: 49.8 | I14: 1.15 | J14: 0.21 | K14: Maint. | L14: 17.79 | M14: Maint. | N14: Maint. | O14: 0 | P14: 2.75 | Q14: 137.52
A15: 02-12-2022 01:45 | B15: 53.43 | C15: 109.97 | D15: 103.54 | E15: 4.67 | F15: 0.5 | G15: 118 | H15: 49.33 | I15: Maint. | J15: 0.32 | K15: Maint. | L15: 18.59 | M15: Maint. | N15: Maint. | O15: 0 | P15: 2.73 | Q15: 137.74
A16: 02-12-2022 02:00 | B16: 51.65 | C16: 108 | D16: 101.02 | E16: 4.19 | F16: 0.39 | G16: 118.66 | H16: 47.8 | I16: Maint. | J16: 0.22 | K16: Maint. | L16: 17.93 | M16: Maint. | N16: Maint. | O16: 0 | P16: 2.69 | Q16: 137.3
A17: 02-12-2022 02:15 | B17: 50.39 | C17: 106.25 | D17: 99.05 | E17: 4.25 | F17: 0.48 | G17: 118.66 | H17: 47.8 | I17: Maint. | J17: 0.13 | K17: Maint. | L17: 17.42 | M17: Maint. | N17: Maint. | O17: 0 | P17: 2.66 | Q17: 136.31
A18: 02-12-2022 02:30 | B18: 49.19 | C18: 104.16 | D18: 96.93 | E18: 4.36 | F18: 0.5 | G18: 118.66 | H18: 47.8 | I18: Maint. | J18: 0.13 | K18: Maint. | L18: 17.41 | M18: Maint. | N18: Maint. | O18: 0 | P18: 2.62 | Q18: 135.16
A19: 02-12-2022 02:45 | B19: 47.47 | C19: 102.05 | D19: 94.39 | E19: 4.92 | F19: 0.33 | G19: 116.15 | H19: 48 | I19: Maint. | J19: 0.14 | K19: Maint. | L19: 17.48 | M19: Maint. | N19: Maint. | O19: 0 | P19: 2.58 | Q19: 134.59
A20: 02-12-2022 03:00 | B20: 45.59 | C20: 99.55 | D20: 91.49 | E20: 4.81 | F20: 0.4 | G20: 110.4 | H20: 48.65 | I20: Maint. | J20: 0.13 | K20: Maint. | L20: 17.16 | M20: Maint. | N20: Maint. | O20: 0 | P20: 2.53 | Q20: 132.74
A21: 02-12-2022 03:15 | B21: 44.3 | C21: 97.21 | D21: 89.18 | E21: 4.09 | F21: 0.44 | G21: 110.4 | H21: 48.65 | I21: Maint. | J21: 0.15 | K21: Maint. | L21: 17.02 | M21: Maint. | N21: Maint. | O21: 0 | P21: 2.5 | Q21: 133.27
A22: 02-12-2022 03:30 | B22: 43.88 | C22: 94.7 | D22: 87.45 | E22: 3.57 | F22: 0.51 | G22: 110.4 | H22: 48.65 | I22: Maint. | J22: 0.08 | K22: Maint. | L22: 16.94 | M22: Maint. | N22: Maint. | O22: 0 | P22: 2.48 | Q22: 131.34
A23: 02-12-2022 03:45 | B23: 42.65 | C23: 93.28 | D23: 85.68 | E23: 4.24 | F23: 0.5 | G23: 116.76 | H23: 49.08 | I23: Maint. | J23: 0.13 | K23: Maint. | L23: 16.99 | M23: Maint. | N23: Maint. | O23: 0 | P23: 2.45 | Q23: 130.28
A24: 02-12-2022 04:00 | B24: 40.96 | C24: 91.87 | D24: 83.54 | E24: 1.94 | F24: 0.55 | G24: 146.05 | H24: 50.47 | I24: Maint. | J24: 0.11 | K24: Maint. | L24: 17.04 | M24: Maint. | N24: Maint. | O24: 0 | P24: 2.42 | Q24: 128.24
A25: 02-12-2022 04:15 | B25: 39.71 | C25: 90.78 | D25: 81.94 | E25: 3.89 | F25: 0.68 | G25: 146.05 | H25: 50.47 | I25: Maint. | J25: 0.12 | K25: Maint. | L25: 16.87 | M25: Maint. | N25: Maint. | O25: 0 | P25: 2.4 | Q25: 128.98
A26: 02-12-2022 04:30 | B26: 39.14 | C26: 90.31 | D26: 81.23 | E26: 3.92 | F26: 0.65 | G26: 146.05 | H26: 50.47 | I26: Maint. | J26: 0.1 | K26: Maint. | L26: 17.11 | M26: Maint. | N26: Maint. | O26: 0 | P26: 2.39 | Q26: 129.39
... A37: 02-12-2022 07:15 | B37: 24.35 | C37: 82.2 | D37: 64.9 | E37: 4 | F37: 0.53 | G37: 106.91 | H37: 49.95 | I37: Maint. | J37: 0.46 | K37: Maint. | L37: 17.97 | M37: Maint. | N37: Maint. | O37: 0 | P37: 1.88 | Q37: 119.98
A38: 02-12-2022 07:30 | B38: 24.28 | C38: 82.43 | D38: 64.97 | E38: 4.53 | F38: 0.51 | G38: 106.91 | H38: 49.95 | I38: Maint. | J38: 0.45 | K38: Maint. | L38: 18.46 | M38: Maint. | N38: 0.2 | O38: 0 | P38: 1.9 | Q38: 119.75
A39: 02-12-2022 07:45 | B39: 24.44 | C39: 82.76 | D39: 65.27 | E39: 4.26 | F39: 0.57 | G39: 105.75 | H39: 49.48 | I39: Maint. | J39: 0.64 | K39: Maint. | L39: 19.19 | M39: Maint. | N39: 18 | O39: 0 | P39: 1.86 | Q39: 119.67
A40: 02-12-2022 08:00 | B40: 24.3 | C40: 82.78 | D40: 65.17 | E40: 1.78 | F40: 0.81 | G40: 100.87 | H40: 47.92 | I40: Maint. | J40: 1.14 | K40: Maint. | L40: 19.83 | M40: Maint. | N40: 47.9 | O40: 0 | P40: 1.83 | Q40: 119.41
A41: 02-12-2022 08:15 | B41: 23.38 | C41: 82.28 | D41: 64.16 | E41: 3.79 | F41: 0.82 | G41: 100.87 | H41: 47.92 | I41: Maint. | J41: 0.65 | K41: Maint. | L41: 20.67 | M41: Maint. | N41: 73.8 | O41: 0 | P41: 1.79 | Q41: 120.08
A42: 02-12-2022 08:30 | B42: 22.54 | C42: 83.06 | D42: 63.91 | E42: 4.24 | F42: 0.84 | G42: 100.87 | H42: 47.92 | I42: Maint. | J42: 0.69 | K42: Maint. | L42: 21.99 | M42: Maint. | N42: 103.2 | O42: 0 | P42: 1.76 | Q42: 119.81
A43: 02-12-2022 08:45 | B43: 21.58 | C43: 83.85 | D43: 63.58 | E43: 4.21 | F43: 0.8 | G43: 98.77 | H43: 47.05 | I43: Maint. | J43: 1.16 | K43: Maint. | L43: 21.86 | M43: Maint. | N43: 129.8 | O43: 0 | P43: 1.72 | Q43: 120.53
A44: 02-12-2022 09:00 | B44: 20.1 | C44: 83.36 | D44: 62.12 | E44: 4.88 | F44: 0.84 | G44: 94.18 | H44: 44.36 | I44: Maint. | J44: 0.75 | K44: Maint. | L44: 23.37 | M44: Maint. | N44: 150.1 | O44: 0 | P44: 1.68 | Q44: 120.2
A45: 02-12-2022 09:15 | B45: 18.75 | C45: 84.08 | D45: 61.44 | E45: 4.47 | F45: 0.73 | G45: 94.18 | H45: 44.36 | I45: Maint. | J45: 0.96 | K45: Maint. | L45: 23.15 | M45: Maint. | N45: 170 | O45: 0 | P45: 1.64 | Q45: 119.65
A46: 02-12-2022 09:30 | B46: 17.07 | C46: 83.59 | D46: 59.82 | E46: 4.91 | F46: 1.12 | G46: 94.18 | H46: 44.36 | I46: Maint. | J46: 0.81 | K46: Maint. | L46: 24.15 | M46: Maint. | N46: 185.8 | O46: 0 | P46: 1.59 | Q46: 118.75
A47: 02-12-2022 09:45 | B47: 15.03 | C47: 83.27 | D47: 58.01 | E47: 4.98 | F47: 1.12 | G47: 96.81 | H47: 43.92 | I47: Maint. | J47: 1.32 | K47: Maint. | L47: 23.9 | M47: Maint. | N47: 205.3 | O47: 0 | P47: 1.55 | Q47: 117.55
A48: 02-12-2022 10:00 | B48: 13.03 | C48: 81.65 | D48: 55.51 | E48: 4.27 | F48: 1.09 | G48: 102.58 | H48: 42.48 | I48: Maint. | J48: 1.38 | K48: Maint. | L48: 23.99 | M48: Maint. | N48: 219.5 | O48: 0 | P48: 1.51 | Q48: 116.41
A49: 02-12-2022 10:15 | B49: 11.53 | C49: 80.17 | D49: 53.49 | E49: 4.86 | F49: 0.9 | G49: 102.58 | H49: 42.48 | I49: Maint. | J49: 0.94 | K49: Maint. | L49: 25.16 | M49: Maint. | N49: 232.6 | O49: 0 | P49: 1.45 | Q49: 116.61
... A53: 02-12-2022 11:15 | B53: 6.2 | C53: 77.84 | D53: 47.93 | E53: 4.11 | F53: 1.54 | G53: 91.78 | H53: 41.23 | I53: Maint. | J53: 0.99 | K53: Maint. | L53: 26.9 | M53: Maint. | N53: 261.2 | O53: 0 | P53: 1.32 | Q53: 111.06
A54: 02-12-2022 11:30 | B54: 3.71 | C54: 77.64 | D54: 45.83 | E54: 6.65 | F54: 8.06 | G54: 91.78 | H54: 41.23 | I54: Maint. | J54: 0.96 | K54: 96.91 | L54: 27.12 | M54: Maint. | N54: 266.7 | O54: 0 | P54: 1.18 | Q54: 96.16
A55: 02-12-2022 11:45 | B55: 2.03 | C55: 73.57 | D55: 42.23 | E55: 7.17 | F55: 6.84 | G55: 88.75 | H55: 40.69 | I55: 0.13 | J55: 0.64 | K55: 132.98 | L55: 28.38 | M55: Maint. | N55: 262.1 | O55: 0 | P55: 1.08 | Q55: 83.34
...

Sheet 03
A1: Station: | B1: BHATAGAON RAIPUR
A2: Date: | B2: =$A$9 -> 03-12-2022 00:15 | D2: Power Off | G2: Pw.Off | L2: Link Fail | N2: Link F | P2: Maintenance | R2: Maint.
A3: Report Type: | B3: Mean | D3: Calibration | G3: Calib. | L3: Data Fail | N3: Data F | P3: Invalid | R3: Invalid
A4: Time Base: | B4: 15 Min | D4: Zero Referrence | G4: Z.Ref | L4: Warm Up | N4: Wm. Up
A7: Date & Time | B7: NO_BHATAGAON | C7: NO2__BHATAGAON | D7: NOX_BHATAGAON | E7: SO2__BHATAGAON | F7: O3__BHATAGAON | G7: PM10__BHATAGAON | H7: PM2_5__BHATAGAON | I7: BENZ__BHATAGAON | J7: WS__BHATAGAON | K7: WD__BHATAGAON | L7: TEMP__BHATAGAON | M7: HUM__BHATAGAON | N7: SR__BHATAGAON | O7: RG__BHATAGAON | P7: CO__BHATAGAON | Q7: NH3__BHATAGAON
B8: ug/m3 | C8: ug/m3 | D8: ug/m3 | E8: ug/m3 | F8: ug/m3 | G8: ug/m3 | H8: ug/m3 | I8: ug/m3 | J8: m/sec | K8: deg | L8: degreC | M8: % | N8: w/m2 | O8: mm | P8: mg/m3 | Q8: ug/m3
A9: 03-12-2022 00:15 | B9: 79.9 | C9: 4.79 | D9: 66.72 | E9: 4.99 | F9: 0.45 | G9: 159.52 | H9: 57.55 | I9: 1.47 | J9: 0.16 | K9: 271.43 | L9: 19.74 | M9: Invalid | N9: 34.4 | O9: 0 | P9: 3.56 | Q9: 55.25
A10: 03-12-2022 00:30 | B10: 80.2 | C10: 3.44 | D10: 66.21 | E10: 5.23 | F10: 0.45 | G10: 159.52 | H10: 57.55 | I10: 1.48 | J10: 0.21 | K10: 275.14 | L10: 20.07 | M10: Invalid | N10: 34.1 | O10: 0 | P10: 3.52 | Q10: 56.23
A11: 03-12-2022 00:45 | B11: 79.36 | C11: 0.23 | D11: 63.77 | E11: 5.27 | F11: 0.54 | G11: 154.89 | H11: 57.23 | I11: 1.48 | J11: 0.16 | K11: 283.62 | L11: 19.69 | M11: Invalid | N11: 34.6 | O11: 0 | P11: 3.45 | Q11: 56.32
A12: 03-12-2022 01:00 | B12: 77.67 | C12: 1.56 | D12: 63.15 | E12: 5.75 | F12: 0.56 | G12: 144.98 | H12: 56.24 | I12: 1.47 | J12: 0.16 | K12: 285.13 | L12: 19.62 | M12: Invalid | N12: 34.6 | O12: 0 | P12: 3.39 | Q12: 55.24
A13: 03-12-2022 01:15 | B13: 76.05 | C13: 3.47 | D13: 62.9 | E13: 5.32 | F13: 0.61 | G13: 144.98 | H13: 56.24 | I13: 1.44 | J13: 0.11 | K13: 293.54 | L13: 19.24 | M13: Invalid | N13: 34.6 | O13: 0 | P13: 3.22 | Q13: 54.75
A14: 03-12-2022 01:30 | B14: 75.47 | C14: 3.24 | D14: 62.31 | E14: 5.53 | F14: 0.66 | G14: 144.98 | H14: 56.24 | I14: 1.41 | J14: 0.14 | K14: 302.17 | L14: 18.98 | M14: Invalid | N14: 34.6 | O14: 0 | P14: 3.26 | Q14: 54.06
A15: 03-12-2022 01:45 | B15: 73.82 | C15: 3.35 | D15: 61.05 | E15: 5.55 | F15: 0.74 | G15: 146.06 | H15: 56.53 | I15: 1.38 | J15: 0.13 | K15: 300.34 | L15: 18.94 | M15: Invalid | N15: 34.5 | O15: 0 | P15: 3.19 | Q15: 53.59
A16: 03-12-2022 02:00 | B16: 71.08 | C16: 4.06 | D16: 59.24 | E16: 5.08 | F16: 0.71 | G16: 148.53 | H16: 57.5 | I16: 1.34 | J16: 0.26 | K16: 299.76 | L16: 19.02 | M16: Invalid | N16: 34.2 | O16: 0 | P16: 3.11 | Q16: 53.13
A17: 03-12-2022 02:15 | B17: 69.02 | C17: 4.71 | D17: 57.95 | E17: 5.09 | F17: 0.75 | G17: 148.53 | H17: 57.5 | I17: 1.32 | J17: 0.12 | K17: 298.31 | L17: 19.03 | M17: Invalid | N17: 34.5 | O17: 0 | P17: 3.04 | Q17: 52.6
A18: 03-12-2022 02:30 | B18: 68.45 | C18: 4.54 | D18: 57.39 | E18: 5.1 | F18: 0.65 | G18: 148.53 | H18: 57.5 | I18: 1.28 | J18: 0.14 | K18: 295.15 | L18: 18.92 | M18: Invalid | N18: 34.5 | O18: 0 | P18: 3 | Q18: 52.61
A19: 03-12-2022 02:45 | B19: 67.64 | C19: 4.66 | D19: 56.82 | E19: 5.43 | F19: 0.54 | G19: 153.87 | H19: 58.44 | I19: 1.27 | J19: 0.09 | K19: 286.44 | L19: 18.91 | M19: Invalid | N19: 34.6 | O19: 0 | P19: 2.96 | Q19: 53.16
A20: 03-12-2022 03:00 | B20: 65.57 | C20: 5.47 | D20: 55.6 | E20: 5.33 | F20: 0.59 | G20: 166.15 | H20: 61.54 | I20: 1.26 | J20: 0.1 | K20: 285.44 | L20: 18.82 | M20: Invalid | N20: 34.6 | O20: 0 | P20: 2.91 | Q20: 53.24
... A33: 03-12-2022 06:15 | B33: 58.31 | C33: 9.38 | D33: 51.93 | E33: 5.19 | F33: 0.46 | G33: 216.64 | H33: 72.51 | I33: 0.92 | J33: 0.17 | K33: 270.56 | L33: 18.52 | M33: Invalid | N33: 34.7 | O33: 0 | P33: 2.44 | Q33: 51.57
A34: 03-12-2022 06:30 | B34: 56.2 | C34: 10.2 | D34: 50.7 | E34: 5.78 | F34: 0.46 | G34: 216.64 | H34: 72.51 | I34: Maint. | J34: 0.22 | K34: 287.66 | L34: 18.1 | M34: Invalid | N34: 37.2 | O34: 0 | P34: 2.4 | Q34: 51.85
A35: 03-12-2022 06:45 | B35: 56.46 | C35: 9.99 | D35: 50.79 | E35: 5.16 | F35: 0.48 | G35: 202.34 | H35: 71.64 | I35: Maint. | J35: 0.19 | K35: 288.62 | L35: 18.13 | M35: Invalid | N35: 44.4 | O35: 0 | P35: 2.37 | Q35: 52.02
A36: 03-12-2022 07:00 | B36: 59.14 | C36: 8.53 | D36: 52.14 | E36: 5.71 | F36: 0.67 | G36: 169.44 | H36: 68.79 | I36: Maint. | J36: 0.15 | K36: 288.59 | L36: 18.21 | M36: Invalid | N36: 55.8 | O36: 0 | P36: 2.36 | Q36: 51.82
A37: 03-12-2022 07:15 | B37: 60.78 | C37: 7.46 | D37: 52.86 | E37: 5.64 | F37: 0.5 | G37: 169.44 | H37: 68.79 | I37: Maint. | J37: 0.31 | K37: 274.64 | L37: 18.87 | M37: Invalid | N37: 68.9 | O37: 0 | P37: 2.33 | Q37: 52.61
A38: 03-12-2022 07:30 | B38: 60.43 | C38: 7.64 | D38: 52.67 | E38: 5.61 | F38: 0.53 | G38: 169.44 | H38: 68.79 | I38: Maint. | J38: 0.48 | K38: 266.11 | L38: 19.43 | M38: Invalid | N38: 88.7 | O38: 0 | P38: 2.36 | Q38: 52.85
A39: 03-12-2022 07:45 | B39: 58.64 | C39: 7.64 | D39: 51.24 | E39: 5.78 | F39: 0.6 | G39: 168.08 | H39: 69.51 | I39: Maint. | J39: 0.78 | K39: 258.2 | L39: 19.86 | M39: Invalid | N39: 122.2 | O39: 0 | P39: 2.33 | Q39: 53.17
A40: 03-12-2022 08:00 | B40: 55.77 | C40: 7.94 | D40: 49.1 | E40: 2.3 | F40: 0.61 | G40: 161.84 | H40: 71.89 | I40: Maint. | J40: 0.49 | K40: 252.75 | L40: 20.58 | M40: Invalid | N40: 157.4 | O40: 0 | P40: 2.27 | Q40: 52.58
A41: 03-12-2022 08:15 | B41: 53.39 | C41: 11.43 | D41: 49.12 | E41: 4.51 | F41: 0.78 | G41: 161.84 | H41: 71.89 | I41: Maint. | J41: 0.59 | K41: 235.45 | L41: 21.9 | M41: Invalid | N41: 189.6 | O41: 0 | P41: 2.26 | Q41: 52.22
A42: 03-12-2022 08:30 | B42: 51.04 | C42: 13.79 | D42: 48.54 | E42: 4.92 | F42: 0.88 | G42: 161.84 | H42: 71.89 | I42: Maint. | J42: 1.03 | K42: 235.23 | L42: 21.6 | M42: Invalid | N42: 224.5 | O42: 0 | P42: 2.21 | Q42: 52.16
A43: 03-12-2022 08:45 | B43: 46.53 | C43: 16.76 | D43: 46.57 | E43: 4.95 | F43: 0.91 | G43: 150.8 | H43: 69.79 | I43: Maint. | J43: 0.56 | K43: 219.01 | L43: 22.96 | M43: Invalid | N43: 255.8 | O43: 0 | P43: 2.14 | Q43: 51.54
A44: 03-12-2022 09:00 | B44: 42.29 | C44: 19.92 | D44: 44.9 | E44: 4.74 | F44: 0.92 | G44: 126.63 | H44: 62.9 | I44: Maint. | J44: 0.75 | K44: 214.92 | L44: 23.35 | M44: Invalid | N44: 285.4 | O44: 0 | P44: 2.09 | Q44: 50.96
A45: 03-12-2022 09:15 | B45: 37.94 | C45: 23.22 | D45: 43.24 | E45: 5.04 | F45: 0.92 | G45: 126.63 | H45: 62.9 | I45: Maint. | J45: 0.61 | K45: 191.58 | L45: 25.22 | M45: Invalid | N45: 308.1 | O45: 0 | P45: 2.03 | Q45: 50.66
... A56: 03-12-2022 12:00 | B56: 6.47 | C56: 48.33 | D56: 31.86 | E56: 2.79 | F56: 1.58 | G56: 93.01 | H56: 60.54 | I56: Maint. | J56: 0.56 | K56: 131.78 | L56: 32.46 | M56: Invalid | N56: 411.3 | O56: 0 | P56: 1.81 | Q56: 49.9
A57: 03-12-2022 12:15 | B57: 4.97 | C57: 48.83 | D57: 30.93 | E57: 4.34 | F57: 2.18 | G57: 93.01 | H57: 60.54 | I57: 0.5 | J57: 0.64 | K57: 132.43 | L57: 32.18 | M57: Invalid | N57: 410.1 | O57: 0 | P57: 1.76 | Q57: 50.08
A58: 03-12-2022 12:30 | B58: 4.09 | C58: 48.75 | D58: 30.19 | E58: 5.08 | F58: 2.91 | G58: 93.01 | H58: 60.54 | I58: 0.68 | J58: 0.55 | K58: 135.33 | L58: 31.36 | M58: Invalid | N58: 404.5 | O58: 0 | P58: 1.73 | Q58: 49.24
A59: 03-12-2022 12:45 | B59: 3.62 | C59: 48.42 | D59: 29.62 | E59: 4.11 | F59: 2.78 | G59: 89.95 | H59: 58.96 | I59: 0.64 | J59: 0.59 | K59: 134.29 | L59: 31.41 | M59: Invalid | N59: 398.1 | O59: 0 | P59: 1.68 | Q59: 48.86
A60: 03-12-2022 13:00 | B60: 3.11 | C60: 47.76 | D60: 28.85 | E60: 4.23 | F60: 2.81 | G60: 83.25 | H60: 54.07 | I60: 0.61 | J60: 0.24 | K60: 133.32 | L60: 31.16 | M60: Invalid | N60: 365.9 | O60: 0 | P60: 1.66 | Q60: 48.47
A61: 03-12-2022 13:15 | B61: 2.92 | C61: 46.16 | D61: 27.81 | E61: 9.11 | F61: 5.44 | G61: 83.25 | H61: 54.07 | I61: 0.59 | J61: 0.36 | K61: 139.22 | L61: 30.21 | M61: Invalid | N61: 327.9 | O61: 0 | P61: 1.52 | Q61: 48.83
A62: 03-12-2022 13:30 | B62: 3.26 | C62: 44.52 | D62: 27.18 | E62: 8.28 | F62: 3.95 | G62: 83.25 | H62: 54.07 | I62: 0.59 | J62: 0.77 | K62: 147.5 | L62: 29.51 | M62: Invalid | N62: 302.8 | O62: 0 | P62: 1.63 | Q62: 49.52
A63: 03-12-2022 13:45 | B63: 3.94 | C63: 43.73 | D63: 27.3 | E63: 7.14 | F63: 5.62 | G63: 88.44 | H63: 54.28 | I63: 0.57 | J63: 0.69 | K63: 137.29 | L63: 31.29 | M63: Invalid | N63: 291.1 | O63: 0 | P63: 1.62 | Q63: 50.22
A64: 03-12-2022 14:00 | B64: 4.07 | C64: 43.8 | D64: 27.44 | E64: 6.13 | F64: 3.84 | G64: 99.81 | H64: 54.97 | I64: 0.55 | J64: 0.6 | K64: 133.36 | L64: 32 | M64: Invalid | N64: 317.7 | O64: 0 | P64: 1.61 | Q64: 50.56
...

Sheet 04
A1: Station: | B1: BHATAGAON RAIPUR
A2: Date: | B2: =$A$9 -> 04-12-2022 00:15 | D2: Power Off | G2: Pw.Off | L2: Link Fail | N2: Link F | P2: Maintenance | R2: Maint.
A3: Report Type: | B3: Mean | D3: Calibration | G3: Calib. | L3: Data Fail | N3: Data F | P3: Invalid | R3: Invalid
A4: Time Base: | B4: 15 Min | D4: Zero Referrence | G4: Z.Ref | L4: Warm Up | N4: Wm. Up
A7: Date & Time | B7: NO_BHATAGAON | C7: NO2__BHATAGAON | D7: NOX_BHATAGAON | E7: SO2__BHATAGAON | F7: O3__BHATAGAON | G7: PM10__BHATAGAON | H7: PM2_5__BHATAGAON | I7: BENZ__BHATAGAON | J7: WS__BHATAGAON | K7: WD__BHATAGAON | L7: TEMP__BHATAGAON | M7: HUM__BHATAGAON | N7: SR__BHATAGAON | O7: RG__BHATAGAON | P7: CO__BHATAGAON | Q7: NH3__BHATAGAON
B8: ug/m3 | C8: ug/m3 | D8: ug/m3 | E8: ug/m3 | F8: ug/m3 | G8: ug/m3 | H8: ug/m3 | I8: ug/m3 | J8: m/sec | K8: deg | L8: degreC | M8: % | N8: w/m2 | O8: mm | P8: mg/m3 | Q8: ug/m3
A9: 04-12-2022 00:15 | B9: 147.09 | C9: Invalid | D9: 97.89 | E9: 4.64 | F9: 0.51 | G9: 209.5 | H9: 68.62 | I9: 1.75 | J9: 0.46 | K9: 297.77 | L9: 19.09 | M9: 25 | N9: 33.5 | O9: 0 | P9: 4.29 | Q9: 60.26
A10: 04-12-2022 00:30 | B10: 144.31 | C10: Invalid | D10: 96.1 | E10: 5.02 | F10: 0.5 | G10: 209.5 | H10: 68.62 | I10: 1.75 | J10: 0.35 | K10: 283.01 | L10: 19.2 | M10: 40 | N10: 33.9 | O10: 0 | P10: 4.23 | Q10: 60.26
A11: 04-12-2022 00:45 | B11: 139.05 | C11: Invalid | D11: 93.3 | E11: 4.61 | F11: 0.64 | G11: 197.96 | H11: 68.69 | I11: 1.75 | J11: 0.13 | K11: 276.59 | L11: 19.22 | M11: Maint. | N11: 34.4 | O11: 0 | P11: 4.14 | Q11: 60.08
A12: 04-12-2022 01:00 | B12: 133.85 | C12: Invalid | D12: 90.45 | E12: 5.08 | F12: 0.57 | G12: 172.7 | H12: 68.92 | I12: 1.74 | J12: 0.13 | K12: 272.53 | L12: 19.17 | M12: Maint. | N12: 34.5 | O12: 0 | P12: 4.04 | Q12: 59.38
A13: 04-12-2022 01:15 | B13: 128.15 | C13: Invalid | D13: 87.42 | E13: 5.14 | F13: 0.63 | G13: 172.7 | H13: 68.92 | I13: 1.71 | J13: 0.19 | K13: 277.43 | L13: 18.89 | M13: Maint. | N13: 34.2 | O13: 0 | P13: 3.65 | Q13: 59.47
A14: 04-12-2022 01:30 | B14: 120.96 | C14: Invalid | D14: 83.82 | E14: 4.68 | F14: 0.57 | G14: 172.7 | H14: 68.92 | I14: 1.68 | J14: 0.34 | K14: 260.55 | L14: 19.36 | M14: Maint. | N14: 33.6 | O14: 0 | P14: 3.75 | Q14: 59.06
A15: 04-12-2022 01:45 | B15: 112.8 | C15: Invalid | D15: 78.93 | E15: 4.76 | F15: 0.65 | G15: 171.23 | H15: 68.96 | I15: 1.65 | J15: 0.32 | K15: 259.3 | L15: 19.46 | M15: Maint. | N15: 34.1 | O15: 0 | P15: 3.64 | Q15: 59.24
A16: 04-12-2022 02:00 | B16: 104.11 | C16: Invalid | D16: 75.52 | E16: 4.65 | F16: 0.66 | G16: 167.84 | H16: 69.08 | I16: 1.6 | J16: 0.21 | K16: 263.19 | L16: 19.27 | M16: Maint. | N16: 34.3 | O16: 0 | P16: 3.55 | Q16: 58.01
A17: 04-12-2022 02:15 | B17: 95.65 | C17: Invalid | D17: 71.94 | E17: 4.71 | F17: 0.57 | G17: 167.84 | H17: 69.08 | I17: 1.53 | J17: 0.1 | K17: 276.21 | L17: 18.77 | M17: Maint. | N17: 34.8 | O17: 0 | P17: 3.5 | Q17: 57.16
A18: 04-12-2022 02:30 | B18: 87.99 | C18: Invalid | D18: 68.34 | E18: 4.66 | F18: 0.58 | G18: 167.84 | H18: 69.08 | I18: 1.45 | J18: 0.1 | K18: 287.95 | L18: 18.29 | M18: Maint. | N18: 34.6 | O18: 0 | P18: 3.47 | Q18: 56.03
A19: 04-12-2022 02:45 | B19: 81.45 | C19: Invalid | D19: 64.95 | E19: 4.25 | F19: 0.53 | G19: 183.32 | H19: 70.67 | I19: 1.37 | J19: 0.14 | K19: 298.17 | L19: 17.86 | M19: Maint. | N19: 34.6 | O19: 0 | P19: 3.43 | Q19: 55.15
A20: 04-12-2022 03:00 | B20: 75.79 | C20: 2.15 | D20: 61.96 | E20: 4 | F20: 0.61 | G20: 218.92 | H20: 75.89 | I20: 1.31 | J20: 0.23 | K20: 298.98 | L20: 18.06 | M20: 12 | N20: 33.9 | O20: 0 | P20: 3.42 | Q20: 54.46
A21: 04-12-2022 03:15 | B21: 70.3 | C21: 4.91 | D21: 59.09 | E21: 3.84 | F21: 0.54 | G21: 218.92 | H21: 75.89 | I21: 1.25 | J21: 0.17 | K21: 300.28 | L21: 18.01 | M21: 28 | N21: 34.6 | O21: 0 | P21: 3.44 | Q21: 53.57
A22: 04-12-2022 03:30 | B22: 66.11 | C22: 6.36 | D22: 56.52 | E22: 4.09 | F22: 0.6 | G22: 218.92 | H22: 75.89 | I22: 1.2 | J22: 0.15 | K22: 308.15 | L22: 17.57 | M22: 29 | N22: 34.4 | O22: 0 | P22: 3.45 | Q22: 52.83
A23: 04-12-2022 03:45 | B23: 63.41 | C23: 6.92 | D23: 54.67 | E23: 4.01 | F23: 0.43 | G23: 210.81 | H23: 75.72 | I23: 1.15 | J23: 0.15 | K23: 306.2 | L23: 17.66 | M23: 21 | N23: 34.4 | O23: 0 | P23: 3.39 | Q23: 52.82
A24: 04-12-2022 04:00 | B24: 60.95 | C24: 7.16 | D24: 52.82 | E24: 1.48 | F24: 0.35 | G24: 173.51 | H24: 75.19 | I24: 1.12 | J24: 0.11 | K24: 311.29 | L24: 17.4 | M24: 29 | N24: 34.5 | O24: 0 | P24: 3.29 | Q24: 52.39
A25: 04-12-2022 04:15 | B25: 59.18 | C25: 6.68 | D25: 51.15 | E25: 3.67 | F25: 0.55 | G25: 173.51 | H25: 75.19 | I25: Maint. | J25: 0.08 | K25: 315.61 | L25: 17 | M25: 37 | N25: 34.6 | O25: 0 | P25: 3.18 | Q25: 52.51
A26: 04-12-2022 04:30 | B26: 57.76 | C26: 6.41 | D26: 49.85 | E26: 3.83 | F26: 0.48 | G26: 173.51 | H26: 75.19 | I26: Maint. | J26: 0.13 | K26: 319.04 | L26: 16.73 | M26: 2 | N26: 34.4 | O26: 0 | P26: 3.07 | Q26: 52.3
A27: 04-12-2022 04:45 | B27: 55.86 | C27: 6.58 | D27: 48.43 | E27: 4.11 | F27: 0.24 | G27: 161.17 | H27: 73.08 | I27: Maint. | J27: 0.14 | K27: 318.91 | L27: 16.75 | M27: 27 | N27: 34.3 | O27: 0 | P27: 2.96 | Q27: 52.28
A28: 04-12-2022 05:00 | B28: 54.51 | C28: 6.91 | D28: 47.52 | E28: 3.87 | F28: 0.43 | G28: 134.13 | H28: 66.14 | I28: Maint. | J28: 0.19 | K28: 317.46 | L28: 16.77 | M28: 28 | N28: 34.3 | O28: 0 | P28: 2.86 | Q28: 51.97
A29: 04-12-2022 05:15 | B29: 55.49 | C29: 6.02 | D29: 47.82 | E29: 3.7 | F29: 0.38 | G29: 134.13 | H29: 66.14 | I29: Maint. | J29: 0.15 | K29: 324.67 | L29: 16.53 | M29: 31 | N29: 34.5 | O29: 0 | P29: 2.79 | Q29: 52.42
A30: 04-12-2022 05:30 | B30: 56.68 | C30: 5.45 | D30: 48.46 | E30: 3.61 | F30: 0.59 | G30: 134.13 | H30: 66.14 | I30: Maint. | J30: 0.06 | K30: 323.92 | L30: 16.52 | M30: 21 | N30: 34.5 | O30: 0 | P30: 2.72 | Q30: 52.44
A31: 04-12-2022 05:45 | B31: 56.12 | C31: 6.3 | D31: 48.48 | E31: 3.55 | F31: 0.59 | G31: 139.16 | H31: 65.81 | I31: Maint. | J31: 0.13 | K31: 318.97 | L31: 16.7 | M31: 24 | N31: 34.2 | O31: 0 | P31: 2.66 | Q31: 51.83
A32: 04-12-2022 06:00 | B32: 56.17 | C32: 6.79 | D32: 48.79 | E32: 3.38 | F32: 0.36 | G32: 151.13 | H32: 64.81 | I32: Maint. | J32: 0.23 | K32: 319.51 | L32: 16.76 | M32: 32 | N32: 34.2 | O32: 0 | P32: 2.61 | Q32: 51.46
A33: 04-12-2022 06:15 | B33: 59.38 | C33: 5.49 | D33: 50.65 | E33: 3.64 | F33: 0.72 | G33: 151.13 | H33: 64.81 | I33: Maint. | J33: 0.07 | K33: 321.62 | L33: 16.57 | M33: Maint. | N33: 34.9 | O33: 0 | P33: 2.59 | Q33: 51.3
A34: 04-12-2022 06:30 | B34: 62.79 | C34: 4.21 | D34: 52.68 | E34: 3.45 | F34: 0.67 | G34: 151.13 | H34: 64.81 | I34: Maint. | J34: 0.16 | K34: 319.8 | L34: 16.72 | M34: Maint. | N34: 36.7 | O34: 0 | P34: 2.57 | Q34: 51.21
A35: 04-12-2022 06:45 | B35: 65.59 | C35: 3.07 | D35: 54.29 | E35: 3.97 | F35: 0.64 | G35: 156.11 | H35: 64.86 | I35: Maint. | J35: 0.15 | K35: 307.12 | L35: 17.12 | M35: Maint. | N35: 43.5 | O35: 0 | P35: 2.56 | Q35: 51
A36: 04-12-2022 07:00 | B36: 68.12 | C36: 1.95 | D36: 55.71 | E36: 3.52 | F36: 0.66 | G36: 167.01 | H36: 65 | I36: Maint. | J36: 0.09 | K36: 301.89 | L36: 17.4 | M36: Maint. | N36: 54.1 | O36: 0 | P36: 2.54 | Q36: 50.54
A37: 04-12-2022 07:15 | B37: 67.56 | C37: 2.52 | D37: 55.57 | E37: 3.09 | F37: 0.62 | G37: 167.01 | H37: 65 | I37: Maint. | J37: 0.1 | K37: 292.69 | L37: 17.86 | M37: Maint. | N37: 67.7 | O37: 0 | P37: 2.48 | Q37: 50.61
A38: 04-12-2022 07:30 | B38: 65.91 | C38: 3.72 | D38: 54.9 | E38: 3.85 | F38: 0.76 | G38: 167.01 | H38: 65 | I38: Maint. | J38: 0.43 | K38: 277.38 | L38: 18.67 | M38: Maint. | N38: 88.2 | O38: 0 | P38: 2.52 | Q38: 51.32
A39: 04-12-2022 07:45 | B39: 62.9 | C39: 6.92 | D39: 54.25 | E39: 3.82 | F39: 0.45 | G39: 157.49 | H39: 64.96 | I39: Maint. | J39: 0.48 | K39: 270.33 | L39: 19.36 | M39: Maint. | N39: 127.7 | O39: 0 | P39: 2.46 | Q39: 51.07
A40: 04-12-2022 08:00 | B40: 60.29 | C40: 11.51 | D40: 54.7 | E40: 2.36 | F40: 0.59 | G40: 113.71 | H40: 64.83 | I40: Maint. | J40: 0.53 | K40: 251.99 | L40: 20.91 | M40: Maint. | N40: 169.7 | O40: 0 | P40: 2.41 | Q40: 50.53
A41: 04-12-2022 08:15 | B41: 58.34 | C41: 11.78 | D41: 53.28 | E41: 3.93 | F41: 0.62 | G41: 113.71 | H41: 64.83 | I41: Maint. | J41: 0.71 | K41: 248.29 | L41: 21.2 | M41: Maint. | N41: 204.8 | O41: 0 | P41: 2.36 | Q41: 51.17
A42: 04-12-2022 08:30 | B42: 55.48 | C42: 11.39 | D42: 50.78 | E42: 4.51 | F42: 0.63 | G42: 113.71 | H42: 64.83 | I42: Maint. | J42: 0.83 | K42: 244.11 | L42: 21.35 | M42: Maint. | N42: 241.8 | O42: 0 | P42: 2.3 | Q42: 51.65
...

Sheet 05
A1: Station: | B1: BHATAGAON RAIPUR
A2: Date: | B2: =$A$9 -> 05-12-2022 00:15 | D2: Power Off | G2: Pw.Off | L2: Link Fail | N2: Link F | P2: Maintenance | R2: Maint.
A3: Report Type: | B3: Mean | D3: Calibration | G3: Calib. | L3: Data Fail | N3: Data F | P3: Invalid | R3: Invalid
A4: Time Base: | B4: 15 Min | D4: Zero Referrence | G4: Z.Ref | L4: Warm Up | N4: Wm. Up
A7: Date & Time | B7: NO_BHATAGAON | C7: NO2__BHATAGAON | D7: NOX_BHATAGAON | E7: SO2__BHATAGAON | F7: O3__BHATAGAON | G7: PM10__BHATAGAON | H7: PM2_5__BHATAGAON | I7: BENZ__BHATAGAON | J7: WS__BHATAGAON | K7: WD__BHATAGAON | L7: TEMP__BHATAGAON | M7: HUM__BHATAGAON | N7: SR__BHATAGAON | O7: RG__BHATAGAON | P7: CO__BHATAGAON | Q7: NH3__BHATAGAON
B8: ug/m3 | C8: ug/m3 | D8: ug/m3 | E8: ug/m3 | F8: ug/m3 | G8: ug/m3 | H8: ug/m3 | I8: ug/m3 | J8: m/sec | K8: deg | L8: degreC | M8: % | N8: w/m2 | O8: mm | P8: mg/m3 | Q8: ug/m3
A9: 05-12-2022 00:15 | B9: 142.91 | C9: Invalid | D9: 97.61 | E9: 4.64 | F9: 0.66 | G9: 172.84 | H9: 57.31 | I9: 1.6 | J9: 0.13 | K9: 246.73 | L9: 19.9 | M9: 63 | N9: 24.5 | O9: 0 | P9: 3.71 | Q9: 59.86
A10: 05-12-2022 00:30 | B10: 130.62 | C10: Invalid | D10: 91.09 | E10: 4.85 | F10: 0.68 | G10: 172.84 | H10: 57.31 | I10: 1.51 | J10: 0.12 | K10: 283.63 | L10: 19.49 | M10: 66 | N10: 24.6 | O10: 0 | P10: 3.53 | Q10: 58.75
A11: 05-12-2022 00:45 | B11: 120.4 | C11: Invalid | D11: 85.64 | E11: 4.58 | F11: 0.63 | G11: 172.84 | H11: 55.85 | I11: 1.42 | J11: 0.17 | K11: 243.07 | L11: 18.71 | M11: 71 | N11: 24.6 | O11: 0 | P11: 3.36 | Q11: 57.14
A12: 05-12-2022 01:00 | B12: 111.18 | C12: Invalid | D12: 80.33 | E12: 3.93 | F12: 0.71 | G12: 557.25 | H12: 51.06 | I12: 1.34 | J12: 0.09 | K12: 258.59 | L12: 18.32 | M12: 75 | N12: 24.6 | O12: 0 | P12: 3.24 | Q12: 55.1
A13: 05-12-2022 01:15 | B13: 104.92 | C13: Invalid | D13: 76.52 | E13: 4.26 | F13: 0.71 | G13: 557.25 | H13: 51.06 | I13: 1.27 | J13: 0.11 | K13: 254.45 | L13: 18.02 | M13: 78 | N13: 24.4 | O13: 0 | P13: 3.02 | Q13: 53.98
A14: 05-12-2022 01:30 | B14: 98.48 | C14: Invalid | D14: 72.4 | E14: 4.2 | F14: 0.72 | G14: 557.25 | H14: 51.06 | I14: 1.23 | J14: 0.18 | K14: 218.77 | L14: 18.03 | M14: 79 | N14: 24.1 | O14: 0 | P14: 3.03 | Q14: 53.45
A15: 05-12-2022 01:45 | B15: 92.16 | C15: Invalid | D15: 68.3 | E15: 3.83 | F15: 0.73 | G15: 155.42 | H15: 50.61 | I15: 1.19 | J15: 0.16 | K15: 236.11 | L15: 18.02 | M15: 80 | N15: 24.1 | O15: 0 | P15: 2.92 | Q15: 53.19
A16: 05-12-2022 02:00 | B16: 86.68 | C16: Invalid | D16: 64.82 | E16: 4.08 | F16: 0.67 | G16: 155.42 | H16: 49.14 | I16: 1.16 | J16: 0.1 | K16: 262.04 | L16: 17.6 | M16: 82 | N16: 24.3 | O16: 0 | P16: 2.82 | Q16: 52.92
A17: 05-12-2022 02:15 | B17: 81.77 | C17: Invalid | D17: 61.87 | E17: 4.07 | F17: 0.65 | G17: 155.42 | H17: 49.14 | I17: 1.12 | J17: 0.13 | K17: 298.44 | L17: 17.43 | M17: 82 | N17: 24.2 | O17: 0 | P17: 2.74 | Q17: 52.74
A18: 05-12-2022 02:30 | B18: 78.44 | C18: Invalid | D18: 59.83 | E18: 4.41 | F18: 0.52 | G18: 155.42 | H18: 49.14 | I18: 1.09 | J18: 0.04 | K18: 288.66 | L18: 16.93 | M18: 85 | N18: 24.6 | O18: 0 | P18: 2.66 | Q18: 52.38
A19: 05-12-2022 02:45 | B19: 75.54 | C19: Invalid | D19: 57.88 | E19: 4.32 | F19: 0.55 | G19: 142.38 | H19: 49.17 | I19: 1.06 | J19: 0.08 | K19: 274.8 | L19: 16.74 | M19: 87 | N19: 24.4 | O19: 0 | P19: 2.59 | Q19: 53.32
A20: 05-12-2022 03:00 | B20: 71.92 | C20: Invalid | D20: 55.49 | E20: 4.23 | F20: 0.75 | G20: 112.38 | H20: 49.26 | I20: 1.04 | J20: 0.09 | K20: 258.54 | L20: 16.74 | M20: 87 | N20: 24.2 | O20: 0 | P20: 2.52 | Q20: 53.77
... A24: 05-12-2022 04:00 | B24: 62.46 | C24: Invalid | D24: 49.64 | E24: 3.12 | F24: 0.68 | G24: 107.72 | H24: 50.89 | I24: 0.91 | J24: 0.01 | K24: 88.27 | L24: 16.49 | M24: 87 | N24: 24.4 | O24: 0 | P24: 2.29 | Q24: 51.24
A25: 05-12-2022 04:15 | B25: 59.46 | C25: 0.65 | D25: 48.04 | E25: 4.84 | F25: 1.03 | G25: 107.72 | H25: 50.89 | I25: 0.88 | J25: 0.04 | K25: 275.74 | L25: 16.49 | M25: 84 | N25: 24.2 | O25: 0 | P25: 2.22 | Q25: 51.01
A26: 05-12-2022 04:30 | B26: 56.89 | C26: 2.12 | D26: 46.79 | E26: 4.72 | F26: 0.73 | G26: 107.72 | H26: 50.89 | I26: 0.87 | J26: 0.13 | K26: 333.52 | L26: 16.42 | M26: 86 | N26: 24.1 | O26: 0 | P26: 2.16 | Q26: 49.59
A27: 05-12-2022 04:45 | B27: 55.63 | C27: 3.04 | D27: 46.29 | E27: 4.97 | F27: 0.88 | G27: 104.82 | H27: 50.64 | I27: 0.84 | J27: 0.02 | K27: 316.81 | L27: 16.65 | M27: 80 | N27: 23.8 | O27: 0 | P27: 2.13 | Q27: 48.7
A28: 05-12-2022 05:00 | B28: 53.39 | C28: 4.21 | D28: 45.14 | E28: 5.29 | F28: 0.97 | G28: 98.14 | H28: 49.82 | I28: 0.83 | J28: 0.07 | K28: 228.96 | L28: 16.49 | M28: 81 | N28: 23.9 | O28: 0 | P28: 2.07 | Q28: 48.66
A29: 05-12-2022 05:15 | B29: 50.76 | C29: 5.59 | D29: 43.79 | E29: 4.87 | F29: 1.06 | G29: 98.14 | H29: 49.82 | I29: 0.81 | J29: 0.08 | K29: 270.34 | L29: 16.44 | M29: 82 | N29: 23.9 | O29: 0 | P29: 2.01 | Q29: 48.26
A30: 05-12-2022 05:30 | B30: 48.74 | C30: 6.52 | D30: 42.68 | E30: 4.97 | F30: 0.67 | G30: 98.14 | H30: 49.82 | I30: 0.79 | J30: 0.11 | K30: 306.37 | L30: 16.32 | M30: 83 | N30: 24.1 | O30: 0 | P30: 1.97 | Q30: 48.26
A31: 05-12-2022 05:45 | B31: 49.81 | C31: 5.86 | D31: 43.18 | E31: 5.1 | F31: 0.5 | G31: 102.99 | H31: 48.94 | I31: 0.78 | J31: 0.1 | K31: 319.21 | L31: 16.02 | M31: 85 | N31: 24.2 | O31: 0 | P31: 1.95 | Q31: 48.43
A32: 05-12-2022 06:00 | B32: 52.7 | C32: 4.39 | D32: 44.68 | E32: 5.44 | F32: 0.64 | G32: 113.63 | H32: 46.04 | I32: 0.77 | J32: 0.06 | K32: 307.09 | L32: 15.95 | M32: 85 | N32: 24.2 | O32: 0 | P32: 1.94 | Q32: 48.31
A33: 05-12-2022 06:15 | B33: 53.78 | C33: 4.21 | D33: 45.45 | E33: 5.1 | F33: 0.66 | G33: 113.63 | H33: 46.04 | I33: 0.76 | J33: 0.08 | K33: 39.98 | L33: 16.13 | M33: 81 | N33: 24.2 | O33: 0 | P33: 1.92 | Q33: 48.88
A34: 05-12-2022 06:30 | B34: 54.24 | C34: 4.44 | D34: 45.95 | E34: 5.05 | F34: 0.64 | G34: 113.63 | H34: 46.04 | I34: 0.76 | J34: 0.12 | K34: 63.64 | L34: 16.89 | M34: 76 | N34: 26.3 | O34: 0 | P34: 1.91 | Q34: 50.17
A35: 05-12-2022 06:45 | B35: 53.43 | C35: 5.13 | D35: 45.68 | E35: 5.02 | F35: 0.72 | G35: 112.79 | H35: 46.51 | I35: 0.74 | J35: 0.16 | K35: 70.67 | L35: 17.32 | M35: 73 | N35: 33.8 | O35: 0 | P35: 1.91 | Q35: 50.08
A36: 05-12-2022 07:00 | B36: 52.27 | C36: 6.41 | D36: 45.45 | E36: 4.98 | F36: 0.72 | G36: 110.95 | H36: 48.04 | I36: 0.72 | J36: 0.17 | K36: 92.01 | L36: 17.5 | M36: 71 | N36: 45.8 | O36: 0 | P36: 1.87 | Q36: 49.53
... A93: 05-12-2022 21:15 | B93: 89.46 | C93: 3.14 | D93: 73.48 | E93: 4.16 | F93: 0.69 | G93: 193.99 | H93: 50.35 | I93: 1.38 | J93: 0.15 | K93: 354.09 | L93: 20.35 | M93: 57 | N93: 24.1 | O93: 0 | P93: 3.25 | Q93: 54.23
A94: 05-12-2022 21:30 | B94: 97.17 | C94: Invalid | D94: 77.57 | E94: 3.58 | F94: 0.81 | G94: 193.99 | H94: 50.35 | I94: 1.36 | J94: 0.09 | K94: 347.04 | L94: 20.23 | M94: 56 | N94: 24.4 | O94: 0 | P94: 3.39 | Q94: 54.38
A95: 05-12-2022 21:45 | B95: 100.73 | C95: Invalid | D95: 79.4 | E95: 3.75 | F95: 0.66 | G95: 175.38 | H95: 49.68 | I95: 1.39 | J95: 0.19 | K95: 353.14 | L95: 19.95 | M95: 58 | N95: 24.2 | O95: 0 | P95: 3.4 | Q95: 54.44
A96: 05-12-2022 22:00 | B96: 104.35 | C96: Invalid | D96: 81.35 | E96: 3.86 | F96: 0.7 | G96: 134.63 | H96: 47.62 | I96: 1.41 | J96: 0.12 | K96: 32.84 | L96: 19.8 | M96: 57 | N96: 24 | O96: 0 | P96: 3.47 | Q96: 54.16
A97: 05-12-2022 22:15 | B97: 103.78 | C97: Invalid | D97: 81.16 | E97: 4 | F97: 0.83 | G97: 134.63 | H97: 47.62 | I97: 1.41 | J97: 0.18 | K97: 29.22 | L97: 20.37 | M97: 53 | N97: 23.9 | O97: 0 | P97: 3.43 | Q97: 54.04
A98: 05-12-2022 22:30 | B98: 97.76 | C98: Invalid | D98: 78.33 | E98: 3.98 | F98: 0.81 | G98: 134.63 | H98: 47.62 | I98: 1.42 | J98: 0.04 | K98: 355.94 | L98: 20.06 | M98: 55 | N98: 24.5 | O98: 0 | P98: 3.37 | Q98: 53.56
A99: 05-12-2022 22:45 | B99: 94.67 | C99: Invalid | D99: 75.8 | E99: 3.77 | F99: 0.86 | G99: 126.34 | H99: 47.08 | I99: 1.39 | J99: 0.05 | K99: 297.12 | L99: 19.73 | M99: 57 | N99: 24.4 | O99: 0 | P99: 3.3 | Q99: 53.12
A100: 05-12-2022 23:00 | B100: 90.93 | C100: Invalid | D100: 73.21 | E100: 4.15 | F100: 0.77 | G100: 108.59 | H100: 45.41 | I100: 1.39 | J100: 0.16 | K100: 346.27 | L100: 19.53 | M100: 58 | N100: 24.1 | O100: 0 | P100: 3.24 | Q100: 52.7
A101: 05-12-2022 23:15 | B101: 89.42 | C101: Invalid | D101: 71.69 | E101: 4.09 | F101: 0.73 | G101: 108.59 | H101: 45.41 | I101: 1.36 | J101: 0.09 | K101: 343.58 | L101: 19.54 | M101: 58 | N101: 24.3 | O101: 0 | P101: 3.19 | Q101: 52.4
...

Sheet 06
A1: Station: | B1: BHATAGAON RAIPUR
A2: Date: | B2: =$A$9 -> 06-12-2022 00:15 | D2: Power Off | G2: Pw.Off | L2: Link Fail | N2: Link F | P2: Maintenance | R2: Maint.
A3: Report Type: | B3: Mean | D3: Calibration | G3: Calib. | L3: Data Fail | N3: Data F | P3: Invalid | R3: Invalid
A4: Time Base: | B4: 15 Min | D4: Zero Referrence | G4: Z.Ref | L4: Warm Up | N4: Wm. Up
A7: Date & Time | B7: NO_BHATAGAON | C7: NO2__BHATAGAON | D7: NOX_BHATAGAON | E7: SO2__BHATAGAON | F7: O3__BHATAGAON | G7: PM10__BHATAGAON | H7: PM2_5__BHATAGAON | I7: BENZ__BHATAGAON | J7: WS__BHATAGAON | K7: WD__BHATAGAON | L7: TEMP__BHATAGAON | M7: HUM__BHATAGAON | N7: SR__BHATAGAON | O7: RG__BHATAGAON | P7: CO__BHATAGAON | Q7: NH3__BHATAGAON
B8: ug/m3 | C8: ug/m3 | D8: ug/m3 | E8: ug/m3 | F8: ug/m3 | G8: ug/m3 | H8: ug/m3 | I8: ug/m3 | J8: m/sec | K8: deg | L8: degreC | M8: % | N8: w/m2 | O8: mm | P8: mg/m3 | Q8: ug/m3
A9: 06-12-2022 00:15 | B9: 79.64 | C9: 1.88 | D9: 64.9 | E9: 4.57 | F9: 0.72 | G9: 111.62 | H9: 43.45 | I9: 1.28 | J9: 0.09 | K9: 256.17 | L9: 18.79 | M9: 62 | N9: 24.5 | O9: 0 | P9: 2.88 | Q9: 52.88
A10: 06-12-2022 00:30 | B10: 74.21 | C10: 3.87 | D10: 61.65 | E10: 4.77 | F10: 0.8 | G10: 111.62 | H10: 43.45 | I10: 1.26 | J10: 0.13 | K10: 321.82 | L10: 18.17 | M10: 68 | N10: 24.6 | O10: 0 | P10: 2.75 | Q10: 52.85
A11: 06-12-2022 00:45 | B11: 69.58 | C11: 5.6 | D11: 58.89 | E11: 4.46 | F11: 0.72 | G11: 102.97 | H11: 42.57 | I11: 1.2 | J11: 0.07 | K11: 298.14 | L11: 17.62 | M11: 69 | N11: 24.6 | O11: 0 | P11: 2.65 | Q11: 52.02
A12: 06-12-2022 01:00 | B12: 65.12 | C12: 7.33 | D12: 56.26 | E12: 4.79 | F12: 0.51 | G12: 84.01 | H12: 39.68 | I12: 1.14 | J12: 0.11 | K12: 289.32 | L12: 17.39 | M12: 71 | N12: 24.4 | O12: 0 | P12: 2.54 | Q12: 51.23
A13: 06-12-2022 01:15 | B13: 61.43 | C13: 8.6 | D13: 54.01 | E13: 4.39 | F13: 0.61 | G13: 84.01 | H13: 39.68 | I13: 1.09 | J13: 0.07 | K13: 282.46 | L13: 17.34 | M13: 72 | N13: 24.3 | O13: 0 | P13: 2.36 | Q13: 50.89
A14: 06-12-2022 01:30 | B14: 58.03 | C14: 9.95 | D14: 52.03 | E14: 4.16 | F14: 0.72 | G14: 84.01 | H14: 39.68 | I14: 1.04 | J14: 0.06 | K14: 245.58 | L14: 17.1 | M14: 72 | N14: 24.5 | O14: 0 | P14: 2.34 | Q14: 50.21
A15: 06-12-2022 01:45 | B15: 55.16 | C15: 11.11 | D15: 50.37 | E15: 4.51 | F15: 0.6 | G15: 87.53 | H15: 38.93 | I15: 0.97 | J15: 0.13 | K15: 308.06 | L15: 17.04 | M15: 75 | N15: 24.3 | O15: 0 | P15: 2.26 | Q15: 49.38
A16: 06-12-2022 02:00 | B16: 53.19 | C16: 11.56 | D16: 49.03 | E16: 4.23 | F16: 0.83 | G16: 95.64 | H16: 36.45 | I16: 0.92 | J16: 0.15 | K16: 43.8 | L16: 17.24 | M16: 70 | N16: 23.6 | O16: 0 | P16: 2.18 | Q16: 48.02
A17: 06-12-2022 02:15 | B17: 50.26 | C17: 12.45 | D17: 47.18 | E17: 4.25 | F17: 0.9 | G17: 95.64 | H17: 36.45 | I17: 0.89 | J17: 0.26 | K17: 54.2 | L17: 18.49 | M17: 61 | N17: 23.1 | O17: 0 | P17: 2.09 | Q17: 47.88
A18: 06-12-2022 02:30 | B18: 46.87 | C18: 14.17 | D18: 45.41 | E18: 4.19 | F18: 0.88 | G18: 95.64 | H18: 36.45 | I18: 0.86 | J18: 0.39 | K18: 67.12 | L18: 18.93 | M18: 58 | N18: 23.1 | O18: 0 | P18: 2 | Q18: 47.86
A19: 06-12-2022 02:45 | B19: 42.84 | C19: 16.06 | D19: 43.22 | E19: 4.33 | F19: 0.84 | G19: 87.65 | H19: 36.04 | I19: 0.84 | J19: 0.23 | K19: 19.38 | L19: 19.03 | M19: 58 | N19: 23.8 | O19: 0 | P19: 1.9 | Q19: 47.67
A20: 06-12-2022 03:00 | B20: 38.64 | C20: 18.02 | D20: 40.93 | E20: 4.19 | F20: 0.81 | G20: 69.28 | H20: 34.68 | I20: 0.81 | J20: 0.25 | K20: 33.44 | L20: 18.79 | M20: 58 | N20: 24.1 | O20: 0 | P20: 1.81 | Q20: 47.41
... A88: 06-12-2022 20:00 | B88: 79.61 | C88: 5.82 | D88: 67.06 | E88: 1.62 | F88: 0.59 | G88: 172.61 | H88: 36.4 | I88: 0.87 | J88: 0.04 | K88: 307.71 | L88: 19.99 | M88: 61 | N88: 24.4 | O88: 0 | P88: 2.64 | Q88: 46.37
A89: 06-12-2022 20:15 | B89: 91.38 | C89: Invalid | D89: 73.1 | E89: 3.81 | F89: 0.63 | G89: 172.61 | H89: 36.4 | I89: 0.98 | J89: 0.23 | K89: 16.2 | L89: 19.89 | M89: 62 | N89: 23.7 | O89: 0 | P89: 2.85 | Q89: 47.32
A90: 06-12-2022 20:30 | B90: 96.72 | C90: Invalid | D90: 75.07 | E90: 4.25 | F90: 0.6 | G90: 172.61 | H90: 36.4 | I90: 1.06 | J90: 0.2 | K90: 54.13 | L90: 20.9 | M90: 50 | N90: 23.1 | O90: 0 | P90: 3.04 | Q90: 48.45
A91: 06-12-2022 20:45 | B91: 94.13 | C91: Invalid | D91: 74.61 | E91: 4.23 | F91: 0.58 | G91: 159.63 | H91: 36.15 | I91: 1.16 | J91: 0.27 | K91: 59.11 | L91: 21.37 | M91: 47 | N91: 23.5 | O91: 0 | P91: 3.09 | Q91: 49.4
A92: 06-12-2022 21:00 | B92: 92.15 | C92: Invalid | D92: 73.06 | E92: 4.38 | F92: 0.71 | G92: 131.19 | H92: 35.38 | I92: 1.24 | J92: 0.28 | K92: 54.64 | L92: 21.42 | M92: 46 | N92: 23.6 | O92: 0 | P92: 3.1 | Q92: 49.88
A93: 06-12-2022 21:15 | B93: 92.52 | C93: Invalid | D93: 72.08 | E93: 4.01 | F93: 0.7 | G93: 131.19 | H93: 35.38 | I93: 1.27 | J93: 0.23 | K93: 59.83 | L93: 21.47 | M93: 46 | N93: 23.9 | O93: 0 | P93: 3.09 | Q93: 50.29
A94: 06-12-2022 21:30 | B94: 91.44 | C94: Invalid | D94: 71.34 | E94: 4.28 | F94: 0.66 | G94: 131.19 | H94: 35.38 | I94: 1.29 | J94: 0.18 | K94: 72.06 | L94: 21.28 | M94: 47 | N94: 24.2 | O94: 0 | P94: 3.08 | Q94: 50.57
A95: 06-12-2022 21:45 | B95: 90.93 | C95: Invalid | D95: 70.48 | E95: 4.32 | F95: 1.19 | G95: 122.73 | H95: 35.48 | I95: 1.28 | J95: 0.09 | K95: 63.82 | L95: 20.85 | M95: 50 | N95: 24.4 | O95: 0 | P95: 3.09 | Q95: 51.75
A96: 06-12-2022 22:00 | B96: 93.32 | C96: Invalid | D96: 71.78 | E96: 4.33 | F96: 0.49 | G96: 104.22 | H96: 35.8 | I96: 1.3 | J96: 0.13 | K96: 56.84 | L96: 20.34 | M96: 53 | N96: 24.2 | O96: 0 | P96: 3.14 | Q96: 52.35
A97: 06-12-2022 22:15 | B97: 93.28 | C97: Invalid | D97: 71.88 | E97: 4.56 | F97: 0.72 | G97: 104.22 | H97: 35.8 | I97: 1.31 | J97: 0.21 | K97: 47.4 | L97: 20.52 | M97: 51 | N97: 23.8 | O97: 0 | P97: 3.14 | Q97: 52.16
A98: 06-12-2022 22:30 | B98: 89.41 | C98: Invalid | D98: 69.97 | E98: 4.2 | F98: 0.07 | G98: 104.22 | H98: 35.8 | I98: 1.32 | J98: 0.17 | K98: 85.8 | L98: 20.17 | M98: 53 | N98: 23.9 | O98: 0 | P98: 3.09 | Q98: 51.62
A99: 06-12-2022 22:45 | B99: 84.52 | C99: Invalid | D99: 67.36 | E99: 3.85 | F99: 0.48 | G99: 80.59 | H99: 36.07 | I99: 1.3 | J99: 0.32 | K99: 82.74 | L99: 20.52 | M99: 52 | N99: 23.5 | O99: 0 | P99: 3 | Q99: 50.95
A100: 06-12-2022 23:00 | B100: 79.02 | C100: 1.83 | D100: 64.38 | E100: 3.56 | F100: 0.98 | G100: 26.25 | H100: 36.88 | I100: 1.38 | J100: 0.26 | K100: 38.81 | L100: 20.32 | M100: 52 | N100: 24.2 | O100: 0 | P100: 2.9 | Q100: 50.2
A101: 06-12-2022 23:15 | B101: 74.26 | C101: 4.17 | D101: 61.85 | E101: 4.02 | F101: 2.21 | G101: 26.25 | H101: 36.88 | I101: 1.23 | J101: 0.22 | K101: 52.65 | L101: 19.91 | M101: 53 | N101: 24.2 | O101: 0 | P101: 2.79 | Q101: 49.58
A102: 06-12-2022 23:30 | B102: 69.7 | C102: 5.9 | D102: 59.15 | E102: 3.99 | F102: 0.55 | G102: 26.25 | H102: 36.88 | I102: 1.18 | J102: 0.3 | K102: 74.12 | L102: 19.92 | M102: 53 | N102: 24.1 | O102: 0 | P102: 2.71 | Q102: 48.08
A103: 06-12-2022 23:45 | B103: 65.64 | C103: 7.84 | D103: 56.97 | E103: 4.13 | F103: 0.6 | G103: 49.4 | H103: 36.1 | I103: 1.13 | J103: 0.21 | K103: 83.01 | L103: 19.73 | M103: 54 | N103: 24.2 | O103: 0 | P103: 2.62 | Q103: 47.68
A104: 06-12-2022 24:00 | B104: 61.81 | C104: 9.24 | D104: 54.67 | E104: 2.48 | F104: 0.58 | G104: 155.87 | H104: 33.7 | I104: 1.09 | J104: 0.17 | K104: 68.03 | L104: 19.55 | M104: 55 | N104: 24.2 | O104: 0 | P104: 2.56 | Q104: 47.69
A106: Min | B106: =MIN(B9:B104) -> 3.49 | C106: =MIN(C9:C104) -> 1.83 | D106: =MIN(D9:D104) -> 21.83 | E106: =MIN(E9:E104) -> 1.4 | F106: =MIN(F9:F104) -> 0.07 | G106: =MIN(G9:G104) -> 26.25 | H106: =MIN(H9:H104) -> 23.95 | I106: =MIN(I9:I104) -> 0.25 | ... Q106: =MIN(Q9:Q104) -> 34.83
A107: Max | B107: =MAX(B9:B104) -> 96.72 | C107: =MAX(C9:C104) -> 45.58 | D107: =MAX(D9:D104) -> 75.07 | E107: =MAX(E9:E104) -> 9.2 | F107: =MAX(F9:F104) -> 17.87 | G107: =MAX(G9:G104) -> 172.61 | H107: =MAX(H9:H104) -> 43.45 | I107: =MAX(I9:I104) -> 1.38 | ... Q107: =MAX(Q9:Q104) -> 52.88
A108: Avg | B108: =AVERAGE(B9:B104) -> 34.735104 | C108: =AVERAGE(C9:C104) -> 26.471529 | D108: =AVERAGE(D9:D104) -> 40.591667 | E108: =AVERAGE(E9:E104) -> 4.2402083 | F108: =AVERAGE(F9:F104) -> 2.2934375 | G108: =AVERAGE(G9:G104) -> 81.866875 | H108: =AVERAGE(H9:H104) -> 31.453438 | I108: =AVERAGE(I9:I104) -> 0.65114583 | ... Q108: =AVERAGE(Q9:Q104) -> 44.155208
A109: Stdev | B109: =STDEV(B9:B104) -> 29.745537 | C109: =STDEV(C9:C104) -> 11.26895 | D109: =STDEV(D9:D104) -> 16.366181 | E109: =STDEV(E9:E104) -> 1.4067416 | F109: =STDEV(F9:F104) -> 3.0181227 | G109: =STDEV(G9:G104) -> 35.499232 | H109: =STDEV(H9:H104) -> 4.7875934 | I109: =STDEV(I9:I104) -> 0.35019354 | ... Q109: =STDEV(Q9:Q104) -> 5.2140846
A110: Num | B110: =COUNT(B9:B104)+1 -> 97 | C110: =COUNT(C9:C104)+1 -> 86 | D110: =COUNT(D9:D104) -> 96 | E110: =COUNT(E9:E104) -> 96 | F110: =COUNT(F9:F104) -> 96 | G110: =COUNT(G9:G104) -> 96 | H110: =COUNT(H9:H104) -> 96 | I110: =COUNT(I9:I104) -> 96 | J110: =COUNT(J9:J104) -> 96 | K110: =COUNT(K9:K104) -> 96 | ... Q110: =COUNT(Q9:Q104) -> 96
...

Sheet 07
A1: Station: | B1: BHATAGAON RAIPUR
A2: Date: | B2: =$A$9 -> 07-12-2022 00:15 | D2: Power Off | G2: Pw.Off | L2: Link Fail | N2: Link F | P2: Maintenance | R2: Maint.
A3: Report Type: | B3: Mean | D3: Calibration | G3: Calib. | L3: Data Fail | N3: Data F | P3: Invalid | R3: Invalid
A4: Time Base: | B4: 15 Min | D4: Zero Referrence | G4: Z.Ref | L4: Warm Up | N4: Wm. Up
A7: Date & Time | B7: NO_BHATAGAON | C7: NO2__BHATAGAON | D7: NOX_BHATAGAON | E7: SO2__BHATAGAON | F7: O3__BHATAGAON | G7: PM10__BHATAGAON | H7: PM2_5__BHATAGAON | I7: BENZ__BHATAGAON | J7: WS__BHATAGAON | K7: WD__BHATAGAON | L7: TEMP__BHATAGAON | M7: HUM__BHATAGAON | N7: SR__BHATAGAON | O7: RG__BHATAGAON | P7: CO__BHATAGAON | Q7: NH3__BHATAGAON
B8: ug/m3 | C8: ug/m3 | D8: ug/m3 | E8: ug/m3 | F8: ug/m3 | G8: ug/m3 | H8: ug/m3 | I8: ug/m3 | J8: m/sec | K8: deg | L8: degreC | M8: % | N8: w/m2 | O8: mm | P8: mg/m3 | Q8: ug/m3
A9: 07-12-2022 00:15 | B9: 60.21 | C9: 9.11 | D9: 53.31 | E9: 4.04 | F9: 0.74 | G9: 155.87 | H9: 33.7 | I9: 1.05 | J9: 0.14 | K9: 99.59 | L9: 19.36 | M9: 57 | N9: 24.3 | O9: 0 | P9: 2.49 | Q9: 47.85
A10: 07-12-2022 00:30 | B10: 56.34 | C10: 9.39 | D10: 50.36 | E10: 4.49 | F10: 1.2 | G10: 155.87 | H10: 33.7 | I10: 1.05 | J10: 0.13 | K10: 134.15 | L10: 19.21 | M10: 57 | N10: 24.1 | O10: 0 | P10: 2.4 | Q10: 47.86
A11: 07-12-2022 00:45 | B11: 53.16 | C11: 10.85 | D11: 48.62 | E11: 4.2 | F11: 0.82 | G11: 122.73 | H11: 32.85 | I11: 1.02 | J11: 0.14 | K11: 90.56 | L11: 19.1 | M11: 58 | N11: 24.1 | O11: 0 | P11: 2.31 | Q11: 47.71
A12: 07-12-2022 01:00 | B12: 50.19 | C12: 11.77 | D12: 46.74 | E12: 4.81 | F12: 0.56 | G12: 50.13 | H12: 30.05 | I12: 1.01 | J12: 0.06 | K12: 237.61 | L12: 18.62 | M12: 61 | N12: 24.4 | O12: 0 | P12: 2.23 | Q12: 47.5
A13: 07-12-2022 01:15 | B13: 46.93 | C13: 12.75 | D13: 44.67 | E13: 4.35 | F13: 0.33 | G13: 50.13 | H13: 30.05 | I13: 0.98 | J13: 0.13 | K13: 265.7 | L13: 18.1 | M13: 63 | N13: 24.4 | O13: 0 | P13: 1.95 | Q13: 47.9
A14: 07-12-2022 01:30 | B14: 43.13 | C14: 14.02 | D14: 42.32 | E14: 4.41 | F14: 0.56 | G14: 50.13 | H14: 30.05 | I14: 0.96 | J14: 0.04 | K14: 335.07 | L14: 17.81 | M14: 65 | N14: 24.5 | O14: 0 | P14: 1.98 | Q14: 48.74
A15: 07-12-2022 01:45 | B15: 40.08 | C15: 15.16 | D15: 40.51 | E15: 3.61 | F15: 0.66 | G15: 56.03 | H15: 29.14 | I15: 0.93 | J15: 0.02 | K15: 300.71 | L15: 17.39 | M15: 68 | N15: 24.5 | O15: 0 | P15: 1.89 | Q15: 48.1
A16: 07-12-2022 02:00 | B16: 37.07 | C16: 16.18 | D16: 38.65 | E16: 4.13 | F16: 0.69 | G16: 69.59 | H16: 26.13 | I16: 0.88 | J16: 0.12 | K16: 257.64 | L16: 17.15 | M16: 69 | N16: 24.2 | O16: 0 | P16: 1.81 | Q16: 47.36
A17: 07-12-2022 02:15 | B17: 33.78 | C17: 17.39 | D17: 36.69 | E17: 4.1 | F17: 0.67 | G17: 69.59 | H17: 26.13 | I17: 0.83 | J17: 0.03 | K17: 267.25 | L17: 16.98 | M17: 70 | N17: 24.2 | O17: 0 | P17: 1.73 | Q17: 46.96
A18: 07-12-2022 02:30 | B18: 31.19 | C18: 18.24 | D18: 35.08 | E18: 3.65 | F18: 0.34 | G18: 69.59 | H18: 26.13 | I18: 0.8 | J18: 0.12 | K18: 313.07 | L18: 16.54 | M18: 74 | N18: 24.3 | O18: 0 | P18: 1.64 | Q18: 46.42
A19: 07-12-2022 02:45 | B19: 29.93 | C19: 18.67 | D19: 34.31 | E19: 3.74 | F19: 0.45 | G19: 77.9 | H19: 26.3 | I19: 0.77 | J19: 0.12 | K19: 279.28 | L19: 16.29 | M19: 76 | N19: 24.2 | O19: 0 | P19: 1.58 | Q19: 45.77
A20: 07-12-2022 03:00 | B20: 29 | C20: 18.69 | D20: 33.57 | E20: 3.57 | F20: 0.5 | G20: 96.08 | H20: 26.86 | I20: 0.73 | J20: 0.14 | K20: 317.07 | L20: 16.14 | M20: 77 | N20: 24.3 | O20: 0 | P20: 1.54 | Q20: 44.59
... A36: 07-12-2022 07:00 | B36: 20.88 | C36: 24.35 | D36: 30.18 | E36: 3.95 | F36: 0.81 | G36: 67.21 | H36: 30.72 | I36: 0.46 | J36: 0.06 | K36: 108.64 | L36: 15.9 | M36: 74 | N36: 47.4 | O36: 0 | P36: 1.2 | Q36: 40.85
A37: 07-12-2022 07:15 | B37: 21.62 | C37: 23.84 | D37: 30.5 | E37: 4.02 | F37: 0.76 | G37: 67.21 | H37: 30.72 | I37: Maint. | J37: 0.38 | K37: 104.35 | L37: 16.35 | M37: 72 | N37: 63.3 | O37: 0 | P37: 1.18 | Q37: 41.23
A38: 07-12-2022 07:30 | B38: 22.5 | C38: 23.24 | D38: 30.87 | E38: 3.76 | F38: 0.64 | G38: 67.21 | H38: 30.72 | I38: Maint. | J38: 0.18 | K38: 71.85 | L38: 16.98 | M38: 69 | N38: 76.9 | O38: 0 | P38: 1.28 | Q38: 41.38
A39: 07-12-2022 07:45 | B39: 23.27 | C39: 22.86 | D39: 31.28 | E39: 4.55 | F39: 0.61 | G39: 77.25 | H39: 31.75 | I39: Maint. | J39: 0.75 | K39: 14.17 | L39: 17.72 | M39: 65 | N39: 119.5 | O39: 0 | P39: 1.32 | Q39: 41.67
A40: 07-12-2022 08:00 | B40: 23.37 | C40: 23.59 | D40: 31.76 | E40: 2.95 | F40: 1.08 | G40: 123.45 | H40: 35.13 | I40: Maint. | J40: 0.88 | K40: 16.73 | L40: 19.14 | M40: 58 | N40: 156.6 | O40: 0 | P40: 1.34 | Q40: 41.56
A41: 07-12-2022 08:15 | B41: 22.96 | C41: 24.78 | D41: 32.09 | E41: 5.4 | F41: 0.71 | G41: 123.45 | H41: 35.13 | I41: Maint. | J41: 1.04 | K41: 10.84 | L41: 19.96 | M41: 55 | N41: 146.7 | O41: 0 | P41: 1.35 | Q41: 41.86
A42: 07-12-2022 08:30 | B42: 22.85 | C42: 26.11 | D42: 32.74 | E42: 5.46 | F42: 0.71 | G42: 123.45 | H42: 35.13 | I42: Maint. | J42: 0.62 | K42: 20.45 | L42: 19.95 | M42: 55 | N42: 230.8 | O42: 0 | P42: 1.36 | Q42: 42.77
A43: 07-12-2022 08:45 | B43: 22.84 | C43: 27.35 | D43: 33.41 | E43: 5.43 | F43: 0.86 | G43: 99.49 | H43: 35.31 | I43: Maint. | J43: 1.31 | K43: 11.77 | L43: 21.7 | M43: 50 | N43: 299.7 | O43: 0 | P43: 1.36 | Q43: 43.24
A44: 07-12-2022 09:00 | B44: 22.59 | C44: 28.94 | D44: 34.09 | E44: 5.24 | F44: 0.84 | G44: 44.4 | H44: 35.9 | I44: Maint. | J44: 1.53 | K44: 10.98 | L44: 23.41 | M44: 45 | N44: 291.5 | O44: 0 | P44: 1.36 | Q44: 42.83
A45: 07-12-2022 09:15 | B45: 21.91 | C45: 30.91 | D45: 34.63 | E45: 5.25 | F45: 0.82 | G45: 44.4 | H45: 35.9 | I45: Maint. | J45: 1.45 | K45: 7.29 | L45: 24.2 | M45: 43 | N45: 349.4 | O45: 0 | P45: 1.35 | Q45: 42.42
A46: 07-12-2022 09:30 | B46: 20.86 | C46: 32.6 | D46: 34.72 | E46: 5.34 | F46: 0.97 | G46: 44.4 | H46: 35.9 | I46: Maint. | J46: 0.61 | K46: 28.43 | L46: 24.65 | M46: 42 | N46: 378.1 | O46: 0 | P46: 1.33 | Q46: 41.95
A47: 07-12-2022 09:45 | B47: 18.81 | C47: 34.21 | D47: 33.97 | E47: 5.17 | F47: 1.52 | G47: 68.83 | H47: 35.91 | I47: Maint. | J47: 1.09 | K47: 30.64 | L47: 23.61 | M47: 42 | N47: 389 | O47: 0 | P47: 1.31 | Q47: 41.65
A48: 07-12-2022 10:00 | B48: 15.61 | C48: 36.31 | D48: 32.56 | E48: 5.13 | F48: 1.78 | G48: 125.02 | H48: 35.92 | I48: Maint. | J48: 0.95 | K48: 52.04 | L48: 24.22 | M48: 39 | N48: 380.9 | O48: 0 | P48: 1.28 | Q48: 41.13
... A56: 07-12-2022 12:00 | B56: 6.27 | C56: 39.26 | D56: 26.7 | E56: 2.66 | F56: 2.49 | G56: 74.63 | H56: 35.24 | I56: Maint. | J56: 0.78 | K56: 77.44 | L56: 26.8 | M56: 25 | N56: 423.8 | O56: 0 | P56: 1.1 | Q56: 40.31
A57: 07-12-2022 12:15 | B57: 5.51 | C57: 38.98 | D57: 25.93 | E57: 4.87 | F57: 2.27 | G57: 74.63 | H57: 35.24 | I57: 0.08 | J57: 1.21 | K57: 12.76 | L57: 27.12 | M57: 23 | N57: 456.2 | O57: 0 | P57: 1.09 | Q57: 41.37
A58: 07-12-2022 12:30 | B58: 4.85 | C58: 38.93 | D58: 25.37 | E58: 4.5 | F58: 2.19 | G58: 74.63 | H58: 35.24 | I58: 0.42 | J58: 0.71 | K58: 20.86 | L58: 27.58 | M58: 24 | N58: 467.4 | O58: 0 | P58: 1.06 | Q58: 41.45
A59: 07-12-2022 12:45 | B59: 4.35 | C59: 38.56 | D59: 24.77 | E59: 4.16 | F59: 2.11 | G59: 61.82 | H59: 35.67 | I59: 0.41 | J59: 1.11 | K59: 99.71 | L59: 26.79 | M59: 24 | N59: 478.2 | O59: 0 | P59: 1.03 | Q59: 41.3
A60: 07-12-2022 13:00 | B60: 3.87 | C60: 37.59 | D60: 23.84 | E60: 4.27 | F60: 2.09 | G60: 33.76 | H60: 37.1 | I60: 0.39 | J60: 0.49 | K60: 68.9 | L60: 26.74 | M60: 25 | N60: 419 | O60: 0 | P60: 1 | Q60: 40.84
A61: 07-12-2022 13:15 | B61: 3.86 | C61: 37.22 | D61: 23.64 | E61: 4.47 | F61: 2.12 | G61: 33.76 | H61: 37.1 | I61: 0.38 | J61: 1.08 | K61: 114.81 | L61: 26.13 | M61: 27 | N61: 430.3 | O61: 0 | P61: 0.94 | Q61: 40.71
A62: 07-12-2022 13:30 | B62: 3.68 | C62: 36.6 | D62: 23.15 | E62: 4.72 | F62: 2.26 | G62: 33.76 | H62: 37.1 | I62: 0.37 | J62: 1.08 | K62: 108.78 | L62: 25.92 | M62: 27 | N62: 418.2 | O62: 0 | P62: 0.96 | Q62: 40.75
A63: 07-12-2022 13:45 | B63: 3.5 | C63: 35.45 | D63: 22.37 | E63: 4.9 | F63: 2.3 | G63: 27.86 | H63: 36.63 | I63: 0.37 | J63: 1.44 | K63: 120.74 | L63: 25.59 | M63: 26 | N63: 394.8 | O63: 0 | P63: 0.93 | Q63: 39.94
A64: 07-12-2022 14:00 | B64: 3.29 | C64: 34.15 | D64: 21.48 | E64: 4.9 | F64: 3.12 | G64: 14.92 | H64: 35.09 | I64: 0.36 | J64: 0.98 | K64: 103.74 | L64: 25.97 | M64: 25 | N64: 377.2 | O64: 0 | P64: 0.89 | Q64: 39.11
...

Sheet 08
A1: Station: | B1: BHATAGAON RAIPUR
A2: Date: | B2: =$A$9 -> 08-12-2022 00:15 | D2: Power Off | G2: Pw.Off | L2: Link Fail | N2: Link F | P2: Maintenance | R2: Maint.
A3: Report Type: | B3: Mean | D3: Calibration | G3: Calib. | L3: Data Fail | N3: Data F | P3: Invalid | R3: Invalid
A4: Time Base: | B4: 15 Min | D4: Zero Referrence | G4: Z.Ref | L4: Warm Up | N4: Wm. Up
