Workbook

Sheet 01
A1: Station: | B1: IGKV RAIPUR
A2: Date: | B2: =$A$9 -> 01/09/2023 00:15 | C2: Power Off | G2: Pw.Off | J2: Link Fail | L2: Link F | N2: Maintenance | P2: Maint.
A3: Report Type: | B3: Mean | C3: Calibration | G3: Calib. | J3: Data Fail | L3: Data F | N3: Invalid | P3: Invalid
A4: Time Base: | B4: 15 Min | C4: Zero Referrence | G4: Z.Ref | J4: Warm Up | L4: Wm. Up
A7: Date & Time | B7: NO | C7: NO2 | D7: NOX | E7: SO2 | F7: O3 | G7: PM 10 | H7: PM 2.5 | I7: BENZ | J7: WS | K7: WD | L7: TEMP | M7: HUM | N7: SR | O7: RG | P7: CO | Q7: NH3
B8: ug/m3 | C8: ug/m3 | D8: ppb | E8: ug/m3 | F8: ug/m3 | G8: ug/m3 | H8: ug/m3 | I8: ug/m3 | J8: m/sec | K8: deg | L8: degreC | M8: % | N8: w/m2 | O8: mm | P8: mg/m3 | Q8: ug/m3
A9: 01/09/2023 00:15 | B9: 8.57 | C9: 14.33 | D9: 15.71 | E9: 7.41 | F9: 5.27 | G9: 55.21 | H9: 17.87 | I9: 17.78 | J9: 0.09 | K9: 201.91 | L9: 27.52 | M9: 97.26 | N9: 0 | O9: 0 | P9: 0.76 | Q9: 4.67
A10: 01/09/2023 00:30 | B10: 9.51 | C10: 15.6 | D10: 17.13 | E10: 7.96 | F10: 5.34 | G10: 55.21 | H10: 17.87 | I10: 17.02 | J10: 0.25 | K10: 256.91 | L10: 27.48 | M10: 96.37 | N10: 0 | O10: 0 | P10: 0.76 | Q10: 4.65
A11: 01/09/2023 00:45 | B11: 9.93 | C11: 17.74 | D11: 18.59 | E11: 9.13 | F11: 5.47 | G11: 55.21 | H11: 17.87 | I11: 17.72 | J11: 0.21 | K11: 202.97 | L11: 27.59 | M11: 91.05 | N11: 0 | O11: 0 | P11: 0.78 | Q11: 4.71
A12: 01/09/2023 01:00 | B12: 9.52 | C12: 15.88 | D12: 17.28 | E12: 8.24 | F12: 5.97 | G12: 51.89 | H12: 18.1 | I12: 19 | J12: 0.25 | K12: 171.32 | L12: 27.52 | M12: 94.37 | N12: 0 | O12: 0 | P12: 0.76 | Q12: 4.7
A13: 01/09/2023 01:15 | B13: 9.49 | C13: 14.47 | D13: 16.52 | E13: 7.99 | F13: 6.87 | G13: 51.74 | H13: 18.1 | I13: 18.2 | J13: 0.16 | K13: 188.5 | L13: 27.1 | M13: 95.87 | N13: 0 | O13: 0 | P13: 0.72 | Q13: 4.69
A14: 01/09/2023 01:30 | B14: 10.59 | C14: 16.24 | D14: 18.33 | E14: 8.47 | F14: 6.54 | G14: 51.74 | H14: 18.1 | I14: 16.99 | J14: 0.12 | K14: 203.46 | L14: 27.13 | M14: 93.12 | N14: 0 | O14: 0 | P14: 0.75 | Q14: 4.65
A15: 01/09/2023 01:45 | B15: 10.73 | C15: 16.21 | D15: 18.42 | E15: 8.5 | F15: 6.15 | G15: 51.74 | H15: 18.1 | I15: 17.24 | J15: 0.29 | K15: 172.43 | L15: 27.15 | M15: 95.51 | N15: 0 | O15: 0 | P15: 0.76 | Q15: 4.69
A16: 01/09/2023 02:00 | B16: 10 | C16: 14.63 | D16: 17.01 | E16: 8.21 | F16: 7.02 | G16: 49.99 | H16: 18.48 | I16: 18.93 | J16: 0.14 | K16: 206 | L16: 26.86 | M16: 95.55 | N16: 0 | O16: 0 | P16: 0.72 | Q16: 4.69
A17: 01/09/2023 02:15 | B17: 10.04 | C17: 13.78 | D17: 16.6 | E17: 6.76 | F17: 7.14 | G17: 49.88 | H17: 18.48 | I17: 17.69 | J17: 0.24 | K17: 180.62 | L17: 26.8 | M17: 96.96 | N17: 0 | O17: 0 | P17: 0.71 | Q17: 4.66
A18: 01/09/2023 02:30 | B18: 9.99 | C18: 13.19 | D18: 16.25 | E18: 8.09 | F18: 6.63 | G18: 49.88 | H18: 18.48 | I18: 16.28 | J18: 0.13 | K18: 200.93 | L18: 26.67 | M18: 97.99 | N18: 0 | O18: 0 | P18: 0.7 | Q18: 4.64
A19: 01/09/2023 02:45 | B19: 9.69 | C19: 13.11 | D19: 15.97 | E19: 7.96 | F19: 6.51 | G19: 49.88 | H19: 18.48 | I19: 16.01 | J19: 0.13 | K19: 162.79 | L19: 26.69 | M19: 97.21 | N19: 0 | O19: 0 | P19: 0.7 | Q19: 4.61
A20: 01/09/2023 03:00 | B20: 10.36 | C20: 15.01 | D20: 17.5 | E20: 8.27 | F20: 5.48 | G20: 47.38 | H20: 20.73 | I20: 15.53 | J20: 0.11 | K20: 186.06 | L20: 26.57 | M20: 98.01 | N20: 0 | O20: 0 | P20: 0.72 | Q20: 4.67
... A104: 01/09/2023 24:00 | B104: 9.93 | C104: 14.6 | D104: 16.95 | E104: 7.24 | F104: 8.18 | G104: 57.5 | H104: 16.82 | I104: 7.16 | J104: 0.15 | K104: 241.83 | L104: 27.73 | M104: 88.61 | N104: 0 | O104: 0 | P104: 0.77 | Q104: 4.71
A106: Min | B106: =MIN(B9:B104) -> 5.11 | C106: =MIN(C9:C104) -> 11.2 | D106: =MIN(D9:D104) -> 11.5 | E106: =MIN(E9:E104) -> 6.76 | F106: =MIN(F9:F104) -> 4.21 | G106: =MIN(G9:G104) -> 35.58 | H106: =MIN(H9:H104) -> 12.73 | I106: =MIN(I9:I104) -> 5.22 | ... Q106: =MIN(Q9:Q104) -> 4.13
A107: Max | B107: =MAX(B9:B104) -> 13.75 | C107: =MAX(C9:C104) -> 23.71 | D107: =MAX(D9:D104) -> 24.76 | E107: =MAX(E9:E104) -> 16.91 | F107: =MAX(F9:F104) -> 24.01 | G107: =MAX(G9:G104) -> 71.96 | H107: =MAX(H9:H104) -> 20.73 | I107: =MAX(I9:I104) -> 19 | ... Q107: =MAX(Q9:Q104) -> 4.79
A108: Avg | B108: =AVERAGE(B9:B104) -> 9.0527083 | C108: =AVERAGE(C9:C104) -> 16.393333 | D108: =AVERAGE(D9:D104) -> 17.175521 | E108: =AVERAGE(E9:E104) -> 9.6008333 | F108: =AVERAGE(F9:F104) -> 9.663125 | G108: =AVERAGE(G9:G104) -> 51.05125 | H108: =AVERAGE(H9:H104) -> 16.960313 | I108: =AVERAGE(I9:I104) -> 10.180521 | ... Q108: =AVERAGE(Q9:Q104) -> 4.5230208
A109: Stdev | B109: =STDEV(B9:B104) -> 2.6107 | C109: =STDEV(C9:C104) -> 2.7522143 | D109: =STDEV(D9:D104) -> 2.8443968 | E109: =STDEV(E9:E104) -> 2.2980677 | F109: =STDEV(F9:F104) -> 5.6893101 | G109: =STDEV(G9:G104) -> 9.7827489 | H109: =STDEV(H9:H104) -> 1.729759 | I109: =STDEV(I9:I104) -> 3.8960129 | ... Q109: =STDEV(Q9:Q104) -> 0.21697984
A110: Num | B110: =COUNT(B9:B104) -> 96 | C110: =COUNT(C9:C104) -> 96 | D110: =COUNT(D9:D104) -> 96 | E110: =COUNT(E9:E104) -> 96 | F110: =COUNT(F9:F104) -> 96 | G110: =COUNT(G9:G104) -> 96 | H110: =COUNT(H9:H104) -> 96 | I110: =COUNT(I9:I104) -> 96 | ... Q110: =COUNT(Q9:Q104) -> 96
A111: DCR | B111: =IF(B110>=87,">90%",IF(B110<=87,"<90%")) -> >90% | C111: =IF(C110>=87,">90%",IF(C110<=87,"<90%")) -> >90% | D111: =IF(D110>=87,">90%",IF(D110<=87,"<90%")) -> >90% | E111: =IF(E110>=87,">90%",IF(E110<=87,"<90%")) -> >90% | F111: =IF(F110>=87,">90%",IF(F110<=87,"<90%")) -> >90% | G111: =IF(G110>=87,">90%",IF(G110<=87,"<90%")) -> >90% | H111: =IF(H110>=87,">90%",IF(H110<=87,"<90%")) -> >90% | I111: =IF(I110>=87,">90%",IF(I110<=87,"<90%")) -> >90% | ... Q111: =IF(Q110>=87,">90%",IF(Q110<=87,"<90%")) -> >90%
A112: Status | B112: =IF(B110>=87,"OK",IF(B110<=87,"LESS")) -> OK | C112: =IF(C110>=87,"OK",IF(C110<=87,"LESS")) -> OK | D112: =IF(D110>=87,"OK",IF(D110<=87,"LESS")) -> OK | E112: =IF(E110>=87,"OK",IF(E110<=87,"LESS")) -> OK | F112: =IF(F110>=87,"OK",IF(F110<=87,"LESS")) -> OK | G112: =IF(G110>=87,"OK",IF(G110<=87,"LESS")) -> OK | H112: =IF(H110>=87,"OK",IF(H110<=87,"LESS")) -> OK | I112: =IF(I110>=87,"OK",IF(I110<=87,"LESS")) -> OK | ... Q112: =IF(Q110>=87,"OK",IF(Q110<=87,"LESS")) -> OK
A115: Done by | B115: AKASH
A117: Comment

Sheet 02
A1: Station: | B1: IGKV RAIPUR
A2: Date: | B2: =$A$9 -> 02/09/2023 00:15 | C2: Power Off | G2: Pw.Off | J2: Link Fail | L2: Link F | N2: Maintenance | P2: Maint.
A3: Report Type: | B3: Mean | C3: Calibration | G3: Calib. | J3: Data Fail | L3: Data F | N3: Invalid | P3: Invalid
A4: Time Base: | B4: 15 Min | C4: Zero Referrence | G4: Z.Ref | J4: Warm Up | L4: Wm. Up
A7: Date & Time | B7: NO | C7: NO2 | D7: NOX | E7: SO2 | F7: O3 | G7: PM 10 | H7: PM 2.5 | I7: BENZ | J7: WS | K7: WD | L7: TEMP | M7: HUM | N7: SR | O7: RG | P7: CO | Q7: NH3
B8: ug/m3 | C8: ug/m3 | D8: ppb | E8: ug/m3 | F8: ug/m3 | G8: ug/m3 | H8: ug/m3 | I8: ug/m3 | J8: m/sec | K8: deg | L8: degreC | M8: % | N8: w/m2 | O8: mm | P8: mg/m3 | Q8: ug/m3
A9: 02/09/2023 00:15 | B9: 9.73 | C9: 14.53 | D9: 16.74 | E9: 6.62 | F9: 7.9 | G9: 56.86 | H9: 16.82 | I9: 6.73 | J9: 0.13 | K9: 183.08 | L9: 27.69 | M9: 88.04 | N9: 0 | O9: 0 | P9: 0.75 | Q9: 4.69
A10: 02/09/2023 00:30 | B10: 9.25 | C10: 14.06 | D10: 16.11 | E10: 6.85 | F10: 8.02 | G10: 56.86 | H10: 16.82 | I10: 6.56 | J10: 0.11 | K10: 197.61 | L10: 27.57 | M10: 88.52 | N10: 0 | O10: 0 | P10: 0.74 | Q10: 4.7
A11: 02/09/2023 00:45 | B11: 9.18 | C11: 14 | D11: 16.03 | E11: 7.11 | F11: 7.52 | G11: 56.86 | H11: 16.82 | I11: 6.57 | J11: 0.12 | K11: 187.6 | L11: 27.55 | M11: 88.61 | N11: 0 | O11: 0 | P11: 0.76 | Q11: 4.69
A12: 02/09/2023 01:00 | B12: 9.81 | C12: 14.93 | D12: 17.01 | E12: 7.36 | F12: 6.55 | G12: 51.16 | H12: 16 | I12: 6.63 | J12: 0.11 | K12: 173.83 | L12: 27.5 | M12: 89.32 | N12: 0 | O12: 0 | P12: 0.79 | Q12: 4.69
A13: 02/09/2023 01:15 | B13: 10.59 | C13: 17.09 | D13: 18.77 | E13: 7.7 | F13: 5.67 | G13: 50.9 | H13: 16 | I13: 6.97 | J13: 0.12 | K13: 224.91 | L13: 27.35 | M13: 89.94 | N13: 0 | O13: 0 | P13: 0.81 | Q13: 4.79
A14: 02/09/2023 01:30 | B14: 11.16 | C14: 16.72 | D14: 19.04 | E14: 7.65 | F14: 5.9 | G14: 50.9 | H14: 16 | I14: 7.33 | J14: 0.13 | K14: 226.12 | L14: 27.34 | M14: 90.91 | N14: 0 | O14: 0 | P14: 0.82 | Q14: 4.75
A15: 02/09/2023 01:45 | B15: 10.92 | C15: 15.65 | D15: 18.28 | E15: 7.46 | F15: 5.95 | G15: 50.9 | H15: 16 | I15: 7.54 | J15: 0.13 | K15: 191.75 | L15: 27.31 | M15: 92.07 | N15: 0 | O15: 0 | P15: 0.82 | Q15: 4.74
A16: 02/09/2023 02:00 | B16: 10.41 | C16: 14.13 | D16: 17.09 | E16: 6.95 | F16: 6.44 | G16: 46.68 | H16: 14.39 | I16: 7.59 | J16: 0.11 | K16: 188.36 | L16: 27.31 | M16: 90.57 | N16: 0 | O16: 0 | P16: 0.81 | Q16: 4.74
A17: 02/09/2023 02:15 | B17: 10.41 | C17: 13.65 | D17: 16.83 | E17: 6.24 | F17: 6.9 | G17: 46.44 | H17: 14.39 | I17: 7.66 | J17: 0.14 | K17: 159.67 | L17: 27.21 | M17: 91.93 | N17: 0 | O17: 0 | P17: 0.76 | Q17: 4.69
A18: 02/09/2023 02:30 | B18: 10.11 | C18: 12.9 | D18: 16.2 | E18: 7.2 | F18: 7.52 | G18: 46.44 | H18: 14.39 | I18: 7.67 | J18: 0.06 | K18: 202.04 | L18: 27.14 | M18: 91.84 | N18: 0 | O18: 0 | P18: 0.71 | Q18: 4.64
A19: 02/09/2023 02:45 | B19: 9.76 | C19: 12.32 | D19: 15.61 | E19: 7.19 | F19: 8.01 | G19: 46.44 | H19: 14.39 | I19: 7.18 | J19: 0.13 | K19: 183.23 | L19: 27.24 | M19: 91.61 | N19: 0 | O19: 0 | P19: 0.68 | Q19: 4.64
A20: 02/09/2023 03:00 | B20: 9.33 | C20: 11.42 | D20: 14.8 | E20: 7.16 | F20: 8.52 | G20: 38.66 | H20: 15.1 | I20: 6.63 | J20: 0.17 | K20: 176.42 | L20: 27.05 | M20: 91.93 | N20: 0 | O20: 0 | P20: 0.65 | Q20: 4.65
... A104: 02/09/2023 24:00 | B104: 7.97 | C104: 15.26 | D104: 15.71 | E104: 5.97 | F104: 6.57 | G104: 17.27 | H104: 6.33 | I104: 4.28 | J104: 0.25 | K104: 270.48 | L104: 25.28 | M104: 94.25 | N104: 0 | O104: 0 | P104: 0.48 | Q104: 4.36
A106: Min | B106: =MIN(B9:B104) -> 6.61 | C106: =MIN(C9:C104) -> 11.42 | D106: =MIN(D9:D104) -> 13.22 | E106: =MIN(E9:E104) -> 5.43 | F106: =MIN(F9:F104) -> 3.99 | G106: =MIN(G9:G104) -> 10.29 | H106: =MIN(H9:H104) -> 4.2 | I106: =MIN(I9:I104) -> 3.8 | ... Q106: =MIN(Q9:Q104) -> 4.35
A107: Max | B107: =MAX(B9:B104) -> 16.29 | C107: =MAX(C9:C104) -> 22.61 | D107: =MAX(D9:D104) -> 25.52 | E107: =MAX(E9:E104) -> 52.61 | F107: =MAX(F9:F104) -> 21.26 | G107: =MAX(G9:G104) -> 101.8 | H107: =MAX(H9:H104) -> 27.66 | I107: =MAX(I9:I104) -> 7.67 | ... Q107: =MAX(Q9:Q104) -> 5.11
A108: Avg | B108: =AVERAGE(B9:B104) -> 10.46125 | C108: =AVERAGE(C9:C104) -> 17.144479 | D108: =AVERAGE(D9:D104) -> 18.697917 | E108: =AVERAGE(E9:E104) -> 10.790938 | F108: =AVERAGE(F9:F104) -> 9.1430208 | G108: =AVERAGE(G9:G104) -> 51.311979 | H108: =AVERAGE(H9:H104) -> 16.058646 | I108: =AVERAGE(I9:I104) -> 5.8125 | ... Q108: =AVERAGE(Q9:Q104) -> 4.6569792
A109: Stdev | B109: =STDEV(B9:B104) -> 2.7251998 | C109: =STDEV(C9:C104) -> 2.883362 | D109: =STDEV(D9:D104) -> 3.0606934 | E109: =STDEV(E9:E104) -> 8.6403381 | F109: =STDEV(F9:F104) -> 4.298195 | G109: =STDEV(G9:G104) -> 25.401201 | H109: =STDEV(H9:H104) -> 6.5267104 | I109: =STDEV(I9:I104) -> 1.1391363 | ... Q109: =STDEV(Q9:Q104) -> 0.23127618
A110: Num | B110: =COUNT(B9:B104) -> 96 | C110: =COUNT(C9:C104) -> 96 | D110: =COUNT(D9:D104) -> 96 | E110: =COUNT(E9:E104) -> 96 | F110: =COUNT(F9:F104) -> 96 | G110: =COUNT(G9:G104) -> 96 | H110: =COUNT(H9:H104) -> 96 | I110: =COUNT(I9:I104) -> 96 | ... Q110: =COUNT(Q9:Q104) -> 96
A111: DCR | B111: =IF(B110>=87,">90%",IF(B110<=87,"<90%")) -> >90% | C111: =IF(C110>=87,">90%",IF(C110<=87,"<90%")) -> >90% | D111: =IF(D110>=87,">90%",IF(D110<=87,"<90%")) -> >90% | E111: =IF(E110>=87,">90%",IF(E110<=87,"<90%")) -> >90% | F111: =IF(F110>=87,">90%",IF(F110<=87,"<90%")) -> >90% | G111: =IF(G110>=87,">90%",IF(G110<=87,"<90%")) -> >90% | H111: =IF(H110>=87,">90%",IF(H110<=87,"<90%")) -> >90% | I111: =IF(I110>=87,">90%",IF(I110<=87,"<90%")) -> >90% | ... Q111: =IF(Q110>=87,">90%",IF(Q110<=87,"<90%")) -> >90%
A112: Status | B112: =IF(B110>=87,"OK",IF(B110<=87,"LESS")) -> OK | C112: =IF(C110>=87,"OK",IF(C110<=87,"LESS")) -> OK | D112: =IF(D110>=87,"OK",IF(D110<=87,"LESS")) -> OK | E112: =IF(E110>=87,"OK",IF(E110<=87,"LESS")) -> OK | F112: =IF(F110>=87,"OK",IF(F110<=87,"LESS")) -> OK | G112: =IF(G110>=87,"OK",IF(G110<=87,"LESS")) -> OK | H112: =IF(H110>=87,"OK",IF(H110<=87,"LESS")) -> OK | I112: =IF(I110>=87,"OK",IF(I110<=87,"LESS")) -> OK | ... Q112: =IF(Q110>=87,"OK",IF(Q110<=87,"LESS")) -> OK
A115: Done by | B115: AKASH
A117: Comment

Sheet 03
A1: Station: | B1: IGKV RAIPUR
A2: Date: | B2: =$A$9 -> 03/09/2023 00:15 | C2: Power Off | G2: Pw.Off | J2: Link Fail | L2: Link F | N2: Maintenance | P2: Maint.
A3: Report Type: | B3: Mean | C3: Calibration | G3: Calib. | J3: Data Fail | L3: Data F | N3: Invalid | P3: Invalid
A4: Time Base: | B4: 15 Min | C4: Zero Referrence | G4: Z.Ref | J4: Warm Up | L4: Wm. Up
A7: Date & Time | B7: NO | C7: NO2 | D7: NOX | E7: SO2 | F7: O3 | G7: PM 10 | H7: PM 2.5 | I7: BENZ | J7: WS | K7: WD | L7: TEMP | M7: HUM | N7: SR | O7: RG | P7: CO | Q7: NH3
B8: ug/m3 | C8: ug/m3 | D8: ppb | E8: ug/m3 | F8: ug/m3 | G8: ug/m3 | H8: ug/m3 | I8: ug/m3 | J8: m/sec | K8: deg | L8: degreC | M8: % | N8: w/m2 | O8: mm | P8: mg/m3 | Q8: ug/m3
A9: 03/09/2023 00:15 | B9: 8.75 | C9: 16.93 | D9: 17.21 | E9: 6.6 | F9: 5.05 | G9: 17.54 | H9: 6.33 | I9: 4.12 | J9: 0.27 | K9: 262.05 | L9: 25.28 | M9: 93.7 | N9: 0 | O9: 0 | P9: 0.5 | Q9: 4.4
A10: 03/09/2023 00:30 | B10: 8.87 | C10: 15.53 | D10: 16.57 | E10: 6.69 | F10: 6.06 | G10: 17.54 | H10: 6.33 | I10: 4.19 | J10: 0.31 | K10: 249.16 | L10: 25.34 | M10: 92.78 | N10: 0 | O10: 0 | P10: 0.49 | Q10: 4.37
A11: 03/09/2023 00:45 | B11: 8.51 | C11: 14.55 | D11: 15.77 | E11: 6.29 | F11: 7.23 | G11: 17.54 | H11: 6.33 | I11: 4.31 | J11: 0.36 | K11: 263.03 | L11: 25.38 | M11: 92.94 | N11: 0 | O11: 0 | P11: 0.46 | Q11: 4.33
A12: 03/09/2023 01:00 | B12: 8.46 | C12: 15.67 | D12: 16.32 | E12: 6.34 | F12: 5.77 | G12: 13.25 | H12: 6.46 | I12: 4.18 | J12: 0.28 | K12: 240.91 | L12: 25.3 | M12: 93.31 | N12: 0 | O12: 0 | P12: 0.47 | Q12: 4.35
A13: 03/09/2023 01:15 | B13: 8.84 | C13: 17.34 | D13: 17.5 | E13: 7.05 | F13: 4.41 | G13: 12.99 | H13: 6.46 | I13: 4.07 | J13: 0.3 | K13: 256.55 | L13: 25.33 | M13: 94.18 | N13: 0 | O13: 0 | P13: 0.48 | Q13: 4.41
A14: 03/09/2023 01:30 | B14: 9.1 | C14: 16.33 | D14: 17.18 | E14: 6.65 | F14: 5.04 | G14: 12.99 | H14: 6.46 | I14: 4.21 | J14: 0.16 | K14: 220.42 | L14: 25.26 | M14: 94.45 | N14: 0 | O14: 0 | P14: 0.48 | Q14: 4.38
A15: 03/09/2023 01:45 | B15: 9.16 | C15: 16.39 | D15: 17.26 | E15: 6.69 | F15: 4.87 | G15: 12.99 | H15: 6.46 | I15: 4.32 | J15: 0.19 | K15: 243.28 | L15: 25.24 | M15: 94.24 | N15: 0 | O15: 0 | P15: 0.5 | Q15: 4.39
A16: 03/09/2023 02:00 | B16: 9.02 | C16: 15.19 | D16: 16.52 | E16: 6.25 | F16: 6.36 | G16: 11.44 | H16: 4.58 | I16: 4.21 | J16: 0.18 | K16: 226.36 | L16: 25.25 | M16: 93.9 | N16: 0 | O16: 0 | P16: 0.47 | Q16: 4.38
A17: 03/09/2023 02:15 | B17: 8.89 | C17: 14.77 | D17: 16.2 | E17: 6.76 | F17: 6.2 | G17: 11.34 | H17: 4.58 | I17: 4.21 | J17: 0.11 | K17: 220.14 | L17: 25.2 | M17: 94.69 | N17: 0 | O17: 0 | P17: 0.43 | Q17: 4.36
A18: 03/09/2023 02:30 | B18: 8.85 | C18: 14.9 | D18: 16.23 | E18: 8.49 | F18: 5.7 | G18: 11.34 | H18: 4.58 | I18: 4.04 | J18: 0.13 | K18: 156.43 | L18: 25.21 | M18: 94.75 | N18: 0 | O18: 0 | P18: 0.44 | Q18: 4.34
A19: 03/09/2023 02:45 | B19: 9.22 | C19: 16.77 | D19: 17.51 | E19: 8.65 | F19: 4.19 | G19: 11.34 | H19: 4.58 | I19: 3.99 | J19: 0.08 | K19: 174.56 | L19: 25.14 | M19: 95.1 | N19: 0 | O19: 0 | P19: 0.48 | Q19: 4.42
A20: 03/09/2023 03:00 | B20: 9.39 | C20: 15.7 | D20: 17.09 | E20: 8.71 | F20: 5.18 | G20: 12.89 | H20: 3.26 | I20: 4.04 | J20: 0.07 | K20: 201.37 | L20: 25.1 | M20: 95.6 | N20: 0 | O20: 0 | P20: 0.46 | Q20: 4.41
... A104: 03/09/2023 24:00 | B104: 8.7 | C104: 16.32 | D104: 16.85 | E104: 8.08 | F104: 4.96 | G104: 13.03 | H104: 4.4 | I104: 5.13 | J104: 0.29 | K104: 304.88 | L104: 25.46 | M104: 92.15 | N104: 0 | O104: 0 | P104: 0.64 | Q104: 4.35
A106: Min | B106: =MIN(B9:B104) -> 7.19 | C106: =MIN(C9:C104) -> 13.63 | D106: =MIN(D9:D104) -> 15.76 | E106: =MIN(E9:E104) -> 6.15 | F106: =MIN(F9:F104) -> 3.99 | G106: =MIN(G9:G104) -> 10.2 | H106: =MIN(H9:H104) -> 3.13 | I106: =MIN(I9:I104) -> 3.62 | ... Q106: =MIN(Q9:Q104) -> 4.33
A107: Max | B107: =MAX(B9:B104) -> 11.28 | C107: =MAX(C9:C104) -> 20.02 | D107: =MAX(D9:D104) -> 20.28 | E107: =MAX(E9:E104) -> 9.35 | F107: =MAX(F9:F104) -> 7.43 | G107: =MAX(G9:G104) -> 33.21 | H107: =MAX(H9:H104) -> 13.09 | I107: =MAX(I9:I104) -> 6.28 | ... Q107: =MAX(Q9:Q104) -> 4.65
A108: Avg | B108: =AVERAGE(B9:B104) -> 9.1660417 | C108: =AVERAGE(C9:C104) -> 16.950417 | D108: =AVERAGE(D9:D104) -> 17.556875 | E108: =AVERAGE(E9:E104) -> 8.0164583 | F108: =AVERAGE(F9:F104) -> 5.52875 | G108: =AVERAGE(G9:G104) -> 17.096979 | H108: =AVERAGE(H9:H104) -> 6.28875 | I108: =AVERAGE(I9:I104) -> 4.8973958 | ... Q108: =AVERAGE(Q9:Q104) -> 4.44375
A109: Stdev | B109: =STDEV(B9:B104) -> 1.0462982 | C109: =STDEV(C9:C104) -> 1.6387838 | D109: =STDEV(D9:D104) -> 0.99016353 | E109: =STDEV(E9:E104) -> 0.84039838 | F109: =STDEV(F9:F104) -> 0.86469252 | G109: =STDEV(G9:G104) -> 6.2914375 | H109: =STDEV(H9:H104) -> 2.5319097 | I109: =STDEV(I9:I104) -> 0.79550083 | ... Q109: =STDEV(Q9:Q104) -> 0.074427641
A110: Num | B110: =COUNT(B9:B104) -> 96 | C110: =COUNT(C9:C104) -> 96 | D110: =COUNT(D9:D104) -> 96 | E110: =COUNT(E9:E104) -> 96 | F110: =COUNT(F9:F104) -> 96 | G110: =COUNT(G9:G104) -> 96 | H110: =COUNT(H9:H104) -> 96 | I110: =COUNT(I9:I104) -> 96 | ... Q110: =COUNT(Q9:Q104) -> 96
A111: DCR | B111: =IF(B110>=87,">90%",IF(B110<=87,"<90%")) -> >90% | C111: =IF(C110>=87,">90%",IF(C110<=87,"<90%")) -> >90% | D111: =IF(D110>=87,">90%",IF(D110<=87,"<90%")) -> >90% | E111: =IF(E110>=87,">90%",IF(E110<=87,"<90%")) -> >90% | F111: =IF(F110>=87,">90%",IF(F110<=87,"<90%")) -> >90% | G111: =IF(G110>=87,">90%",IF(G110<=87,"<90%")) -> >90% | H111: =IF(H110>=87,">90%",IF(H110<=87,"<90%")) -> >90% | I111: =IF(I110>=87,">90%",IF(I110<=87,"<90%")) -> >90% | ... Q111: =IF(Q110>=87,">90%",IF(Q110<=87,"<90%")) -> >90%
A112: Status | B112: =IF(B110>=87,"OK",IF(B110<=87,"LESS")) -> OK | C112: =IF(C110>=87,"OK",IF(C110<=87,"LESS")) -> OK | D112: =IF(D110>=87,"OK",IF(D110<=87,"LESS")) -> OK | E112: =IF(E110>=87,"OK",IF(E110<=87,"LESS")) -> OK | F112: =IF(F110>=87,"OK",IF(F110<=87,"LESS")) -> OK | G112: =IF(G110>=87,"OK",IF(G110<=87,"LESS")) -> OK | H112: =IF(H110>=87,"OK",IF(H110<=87,"LESS")) -> OK | I112: =IF(I110>=87,"OK",IF(I110<=87,"LESS")) -> OK | ... Q112: =IF(Q110>=87,"OK",IF(Q110<=87,"LESS")) -> OK
A115: Done by | B115: AKASH
A117: Comment

Sheet 04
A1: Station: | B1: IGKV RAIPUR
A2: Date: | B2: =$A$9 -> 04/09/2023 00:15 | C2: Power Off | G2: Pw.Off | J2: Link Fail | L2: Link F | N2: Maintenance | P2: Maint.
A3: Report Type: | B3: Mean | C3: Calibration | G3: Calib. | J3: Data Fail | L3: Data F | N3: Invalid | P3: Invalid
A4: Time Base: | B4: 15 Min | C4: Zero Referrence | G4: Z.Ref | J4: Warm Up | L4: Wm. Up
A7: Date & Time | B7: NO | C7: NO2 | D7: NOX | E7: SO2 | F7: O3 | G7: PM 10 | H7: PM 2.5 | I7: BENZ | J7: WS | K7: WD | L7: TEMP | M7: HUM | N7: SR | O7: RG | P7: CO | Q7: NH3
B8: ug/m3 | C8: ug/m3 | D8: ppb | E8: ug/m3 | F8: ug/m3 | G8: ug/m3 | H8: ug/m3 | I8: ug/m3 | J8: m/sec | K8: deg | L8: degreC | M8: % | N8: w/m2 | O8: mm | P8: mg/m3 | Q8: ug/m3
A9: 04/09/2023 00:15 | B9: 8.59 | C9: 17 | D9: 17.12 | E9: 8.81 | F9: 4.39 | G9: 12.91 | H9: 4.4 | I9: 5.04 | J9: 0.26 | K9: 306.07 | L9: 25.52 | M9: 91.78 | N9: 0 | O9: 0 | P9: 0.66 | Q9: 4.43
A10: 04/09/2023 00:30 | B10: 8.62 | C10: 16.34 | D10: 16.8 | E10: 8.65 | F10: 5.34 | G10: 12.91 | H10: 4.4 | I10: 5.11 | J10: 0.29 | K10: 39.69 | L10: 25.33 | M10: 92.66 | N10: 0 | O10: 0.8 | P10: 0.64 | Q10: 4.43
A11: 04/09/2023 00:45 | B11: 8.26 | C11: 16.1 | D11: 16.39 | E11: 8.2 | F11: 5.94 | G11: 12.91 | H11: 4.4 | I11: 5.1 | J11: 0.24 | K11: 138.92 | L11: 23.95 | M11: 97.79 | N11: 0 | O11: 1.8 | P11: 0.62 | Q11: 4.36
A12: 04/09/2023 01:00 | B12: 7.81 | C12: 18.03 | D12: 17.03 | E12: 8.7 | F12: 4.55 | G12: 11.98 | H12: 4.06 | I12: 5 | J12: 0.27 | K12: 128.05 | L12: 23.43 | M12: 98.75 | N12: 0 | O12: 1.2 | P12: 0.64 | Q12: 4.39
A13: 04/09/2023 01:15 | B13: 7.35 | C13: 17.48 | D13: 16.38 | E13: 8.36 | F13: 4.93 | G13: 11.94 | H13: 4.06 | I13: 4.94 | J13: 0.04 | K13: 198.84 | L13: 23.31 | M13: 99.82 | N13: 0 | O13: 1.6 | P13: 0.62 | Q13: 4.35
A14: 04/09/2023 01:30 | B14: 7.09 | C14: 16.72 | D14: 15.77 | E14: 8.49 | F14: 5.02 | G14: 11.94 | H14: 4.06 | I14: 4.97 | J14: 0.41 | K14: 254.53 | L14: 23.2 | M14: 99.86 | N14: 0 | O14: 1 | P14: 0.6 | Q14: 4.3
A15: 04/09/2023 01:45 | B15: 6.97 | C15: 17.73 | D15: 16.2 | E15: 8.22 | F15: 4.23 | G15: 11.94 | H15: 4.06 | I15: 4.81 | J15: 0.26 | K15: 251.57 | L15: 23.21 | M15: 100.02 | N15: 0 | O15: 0.6 | P15: 0.62 | Q15: 4.33
A16: 04/09/2023 02:00 | B16: 6.98 | C16: 16.98 | D16: 15.82 | E16: 8.48 | F16: 4.78 | G16: 8.92 | H16: 2.95 | I16: 4.72 | J16: 0.11 | K16: 208.95 | L16: 23.2 | M16: 100.41 | N16: 0 | O16: 0.8 | P16: 0.6 | Q16: 4.31
A17: 04/09/2023 02:15 | B17: 6.88 | C17: 16.81 | D17: 15.64 | E17: 5.47 | F17: 4.71 | G17: 8.74 | H17: 2.95 | I17: 4.75 | J17: 0.56 | K17: 265.74 | L17: 23.18 | M17: 100.65 | N17: 0 | O17: 0.2 | P17: 0.58 | Q17: 4.27
A18: 04/09/2023 02:30 | B18: 6.88 | C18: 18.07 | D18: 16.31 | E18: 6.86 | F18: 3.9 | G18: 8.74 | H18: 2.95 | I18: 4.66 | J18: 0.61 | K18: 268.16 | L18: 23.15 | M18: 100.74 | N18: 0 | O18: 0.4 | P18: 0.6 | Q18: 4.32
A19: 04/09/2023 02:45 | B19: 6.84 | C19: 17.07 | D19: 15.75 | E19: 6.81 | F19: 4.78 | G19: 8.74 | H19: 2.95 | I19: 4.64 | J19: 0.64 | K19: 268.8 | L19: 23.25 | M19: 100.61 | N19: 0 | O19: 0 | P19: 0.59 | Q19: 4.3
A20: 04/09/2023 03:00 | B20: 6.65 | C20: 17.1 | D20: 15.62 | E20: 6.34 | F20: 5.28 | G20: 6.48 | H20: 2.25 | I20: 4.69 | J20: 0.61 | K20: 270.58 | L20: 23.35 | M20: 100.66 | N20: 0 | O20: 0 | P20: 0.58 | Q20: 4.28
... A104: 04/09/2023 24:00 | B104: 10.31 | C104: 21.1 | D104: 20.64 | E104: 6.47 | F104: 4.27 | G104: 24.34 | H104: 11.35 | I104: 6.53 | J104: 0.34 | K104: 44.65 | L104: 23.48 | M104: 96.66 | N104: 0 | O104: 0 | P104: 0.92 | Q104: 4.69
A106: Min | B106: =MIN(B9:B104) -> 4.16 | C106: =MIN(C9:C104) -> 14.72 | D106: =MIN(D9:D104) -> 12.38 | E106: =MIN(E9:E104) -> 5.47 | F106: =MIN(F9:F104) -> 3.59 | G106: =MIN(G9:G104) -> 3.62 | H106: =MIN(H9:H104) -> 1.6 | I106: =MIN(I9:I104) -> 4.37 | ... Q106: =MIN(Q9:Q104) -> 4.17
A107: Max | B107: =MAX(B9:B104) -> 12.36 | C107: =MAX(C9:C104) -> 21.63 | D107: =MAX(D9:D104) -> 21.48 | E107: =MAX(E9:E104) -> 11.38 | F107: =MAX(F9:F104) -> 17.76 | G107: =MAX(G9:G104) -> 40.39 | H107: =MAX(H9:H104) -> 16.13 | I107: =MAX(I9:I104) -> 8.4 | ... Q107: =MAX(Q9:Q104) -> 4.8
A108: Avg | B108: =AVERAGE(B9:B104) -> 8.2954167 | C108: =AVERAGE(C9:C104) -> 18.194792 | D108: =AVERAGE(D9:D104) -> 17.509479 | E108: =AVERAGE(E9:E104) -> 7.9597917 | F108: =AVERAGE(F9:F104) -> 5.9163542 | G108: =AVERAGE(G9:G104) -> 26.102187 | H108: =AVERAGE(H9:H104) -> 9.2986458 | I108: =AVERAGE(I9:I104) -> 5.7428125 | ... Q108: =AVERAGE(Q9:Q104) -> 4.4620833
A109: Stdev | B109: =STDEV(B9:B104) -> 2.400464 | C109: =STDEV(C9:C104) -> 1.4323966 | D109: =STDEV(D9:D104) -> 2.4436919 | E109: =STDEV(E9:E104) -> 1.1864152 | F109: =STDEV(F9:F104) -> 2.8374418 | G109: =STDEV(G9:G104) -> 11.263878 | H109: =STDEV(H9:H104) -> 4.579857 | I109: =STDEV(I9:I104) -> 1.0455406 | ... Q109: =STDEV(Q9:Q104) -> 0.19157473
A110: Num | B110: =COUNT(B9:B104) -> 96 | C110: =COUNT(C9:C104) -> 96 | D110: =COUNT(D9:D104) -> 96 | E110: =COUNT(E9:E104) -> 96 | F110: =COUNT(F9:F104) -> 96 | G110: =COUNT(G9:G104) -> 96 | H110: =COUNT(H9:H104) -> 96 | I110: =COUNT(I9:I104) -> 96 | ... Q110: =COUNT(Q9:Q104) -> 96
A111: DCR | B111: =IF(B110>=87,">90%",IF(B110<=87,"<90%")) -> >90% | C111: =IF(C110>=87,">90%",IF(C110<=87,"<90%")) -> >90% | D111: =IF(D110>=87,">90%",IF(D110<=87,"<90%")) -> >90% | E111: =IF(E110>=87,">90%",IF(E110<=87,"<90%")) -> >90% | F111: =IF(F110>=87,">90%",IF(F110<=87,"<90%")) -> >90% | G111: =IF(G110>=87,">90%",IF(G110<=87,"<90%")) -> >90% | H111: =IF(H110>=87,">90%",IF(H110<=87,"<90%")) -> >90% | I111: =IF(I110>=87,">90%",IF(I110<=87,"<90%")) -> >90% | ... Q111: =IF(Q110>=87,">90%",IF(Q110<=87,"<90%")) -> >90%
A112: Status | B112: =IF(B110>=87,"OK",IF(B110<=87,"LESS")) -> OK | C112: =IF(C110>=87,"OK",IF(C110<=87,"LESS")) -> OK | D112: =IF(D110>=87,"OK",IF(D110<=87,"LESS")) -> OK | E112: =IF(E110>=87,"OK",IF(E110<=87,"LESS")) -> OK | F112: =IF(F110>=87,"OK",IF(F110<=87,"LESS")) -> OK | G112: =IF(G110>=87,"OK",IF(G110<=87,"LESS")) -> OK | H112: =IF(H110>=87,"OK",IF(H110<=87,"LESS")) -> OK | I112: =IF(I110>=87,"OK",IF(I110<=87,"LESS")) -> OK | ... Q112: =IF(Q110>=87,"OK",IF(Q110<=87,"LESS")) -> OK
A115: Done by | B115: AKASH
A117: Comment

Sheet 05
A1: Station: | B1: IGKV RAIPUR
A2: Date: | B2: =$A$9 -> 05/09/2023 00:15 | C2: Power Off | G2: Pw.Off | J2: Link Fail | L2: Link F | N2: Maintenance | P2: Maint.
A3: Report Type: | B3: Mean | C3: Calibration | G3: Calib. | J3: Data Fail | L3: Data F | N3: Invalid | P3: Invalid
A4: Time Base: | B4: 15 Min | C4: Zero Referrence | G4: Z.Ref | J4: Warm Up | L4: Wm. Up
A7: Date & Time | B7: NO | C7: NO2 | D7: NOX | E7: SO2 | F7: O3 | G7: PM 10 | H7: PM 2.5 | I7: BENZ | J7: WS | K7: WD | L7: TEMP | M7: HUM | N7: SR | O7: RG | P7: CO | Q7: NH3
B8: ug/m3 | C8: ug/m3 | D8: ppb | E8: ug/m3 | F8: ug/m3 | G8: ug/m3 | H8: ug/m3 | I8: ug/m3 | J8: m/sec | K8: deg | L8: degreC | M8: % | N8: w/m2 | O8: mm | P8: mg/m3 | Q8: ug/m3
A9: 05/09/2023 00:15 | B9: 11.25 | C9: 21.78 | D9: 21.75 | E9: 7.03 | F9: 3.97 | G9: 24.14 | H9: 11.35 | I9: 6.47 | J9: 0.28 | K9: 56.48 | L9: 23.47 | M9: 97.02 | N9: 0 | O9: 0 | P9: 0.91 | Q9: 4.71
A10: 05/09/2023 00:30 | B10: 11.47 | C10: 20.57 | D10: 21.29 | E10: 7.01 | F10: 4.58 | G10: 24.14 | H10: 11.35 | I10: 6.43 | J10: 0.18 | K10: 74.47 | L10: 23.57 | M10: 97.42 | N10: 0 | O10: 0 | P10: 0.89 | Q10: 4.67
A11: 05/09/2023 00:45 | B11: 11.48 | C11: 20.6 | D11: 21.32 | E11: 6.57 | F11: 4.39 | G11: 24.14 | H11: 11.35 | I11: 6.37 | J11: 0.06 | K11: 165 | L11: 23.74 | M11: 98.27 | N11: 0 | O11: 0 | P11: 0.88 | Q11: 4.67
A12: 05/09/2023 01:00 | B12: 11.74 | C12: 21.28 | D12: 21.88 | E12: 7.07 | F12: 3.79 | G12: 26.73 | H12: 8.31 | I12: 6.25 | J12: 0.11 | K12: 288.59 | L12: 23.76 | M12: 98.25 | N12: 0 | O12: 0 | P12: 0.89 | Q12: 4.73
A13: 05/09/2023 01:15 | B13: 11.92 | C13: 20.2 | D13: 21.46 | E13: 6.65 | F13: 4.43 | G13: 26.89 | H13: 8.31 | I13: 6.17 | J13: 0.08 | K13: 309.79 | L13: 23.75 | M13: 97.87 | N13: 0 | O13: 0 | P13: 0.86 | Q13: 4.72
A14: 05/09/2023 01:30 | B14: 11.79 | C14: 20.24 | D14: 21.38 | E14: 6.7 | F14: 4.37 | G14: 26.89 | H14: 8.31 | I14: 6.16 | J14: 0.1 | K14: 213.21 | L14: 23.81 | M14: 97.55 | N14: 0 | O14: 0 | P14: 0.85 | Q14: 4.68
A15: 05/09/2023 01:45 | B15: 11.8 | C15: 20.98 | D15: 21.77 | E15: 6.97 | F15: 3.98 | G15: 26.89 | H15: 8.31 | I15: 6.07 | J15: 0.09 | K15: 324 | L15: 23.87 | M15: 97.68 | N15: 0 | O15: 0.4 | P15: 0.86 | Q15: 4.74
A16: 05/09/2023 02:00 | B16: 11.87 | C16: 19.88 | D16: 21.25 | E16: 6.76 | F16: 4.8 | G16: 21.09 | H16: 6.06 | I16: 5.95 | J16: 0.08 | K16: 313.37 | L16: 23.84 | M16: 97.84 | N16: 0 | O16: 0 | P16: 0.83 | Q16: 4.67
A17: 05/09/2023 02:15 | B17: 11.97 | C17: 20.1 | D17: 21.45 | E17: 8.01 | F17: 4.41 | G17: 20.75 | H17: 6.06 | I17: 5.9 | J17: 0.23 | K17: 269.12 | L17: 23.78 | M17: 97.97 | N17: 0 | O17: 0.2 | P17: 0.83 | Q17: 4.65
A18: 05/09/2023 02:30 | B18: 12.15 | C18: 20.81 | D18: 21.97 | E18: 9.44 | F18: 3.95 | G18: 20.75 | H18: 6.06 | I18: 5.73 | J18: 0.26 | K18: 297.18 | L18: 23.77 | M18: 98.1 | N18: 0 | O18: 0 | P18: 0.84 | Q18: 4.71
A19: 05/09/2023 02:45 | B19: 12.22 | C19: 19.54 | D19: 21.36 | E19: 8.79 | F19: 4.95 | G19: 20.75 | H19: 6.06 | I19: 5.76 | J19: 0.22 | K19: 310.78 | L19: 23.73 | M19: 98.15 | N19: 0 | O19: 0 | P19: 0.8 | Q19: 4.69
A20: 05/09/2023 03:00 | B20: 12.06 | C20: 20.22 | D20: 21.58 | E20: 9.58 | F20: 4.71 | G20: 20.52 | H20: 4.65 | I20: 5.73 | J20: 0.19 | K20: 288.07 | L20: 23.74 | M20: 98.16 | N20: 0 | O20: 0 | P20: 0.8 | Q20: 4.69
... A104: 05/09/2023 24:00 | B104: 15.76 | C104: 19.67 | D104: 24.27 | E104: 6.89 | F104: 5.91 | G104: 35.12 | H104: 14.69 | I104: 4.48 | J104: 0.2 | K104: 61.89 | L104: 25.48 | M104: 94.22 | N104: 0 | O104: 0 | P104: 0.7 | Q104: 5.89
A106: Min | B106: =MIN(B9:B104) -> 2 | C106: =MIN(C9:C104) -> 12.45 | D106: =MIN(D9:D104) -> 9.85 | E106: =MIN(E9:E104) -> 5.96 | F106: =MIN(F9:F104) -> 3.77 | G106: =MIN(G9:G104) -> 20.51 | H106: =MIN(H9:H104) -> 4.65 | I106: =MIN(I9:I104) -> 3.38 | ... Q106: =MIN(Q9:Q104) -> 4.04
A107: Max | B107: =MAX(B9:B104) -> 18.62 | C107: =MAX(C9:C104) -> 23.58 | D107: =MAX(D9:D104) -> 28.39 | E107: =MAX(E9:E104) -> 17.7 | F107: =MAX(F9:F104) -> 19.29 | G107: =MAX(G9:G104) -> 71.24 | H107: =MAX(H9:H104) -> 21.78 | I107: =MAX(I9:I104) -> 7.07 | ... Q107: =MAX(Q9:Q104) -> 5.96
A108: Avg | B108: =AVERAGE(B9:B104) -> 11.741563 | C108: =AVERAGE(C9:C104) -> 19.435104 | D108: =AVERAGE(D9:D104) -> 20.920521 | E108: =AVERAGE(E9:E104) -> 8.4407292 | F108: =AVERAGE(F9:F104) -> 7.094375 | G108: =AVERAGE(G9:G104) -> 41.527708 | H108: =AVERAGE(H9:H104) -> 15.932292 | I108: =AVERAGE(I9:I104) -> 5.1390625 | ... Q108: =AVERAGE(Q9:Q104) -> 5.07375
A109: Stdev | B109: =STDEV(B9:B104) -> 5.0633803 | C109: =STDEV(C9:C104) -> 2.7723723 | D109: =STDEV(D9:D104) -> 5.355882 | E109: =STDEV(E9:E104) -> 2.1809275 | F109: =STDEV(F9:F104) -> 3.0977696 | G109: =STDEV(G9:G104) -> 13.165339 | H109: =STDEV(H9:H104) -> 4.8763747 | I109: =STDEV(I9:I104) -> 1.1898537 | ... Q109: =STDEV(Q9:Q104) -> 0.50522585
A110: Num | B110: =COUNT(B9:B104) -> 96 | C110: =COUNT(C9:C104) -> 96 | D110: =COUNT(D9:D104) -> 96 | E110: =COUNT(E9:E104) -> 96 | F110: =COUNT(F9:F104) -> 96 | G110: =COUNT(G9:G104) -> 96 | H110: =COUNT(H9:H104) -> 96 | I110: =COUNT(I9:I104) -> 96 | ... Q110: =COUNT(Q9:Q104) -> 96
A111: DCR | B111: =IF(B110>=87,">90%",IF(B110<=87,"<90%")) -> >90% | C111: =IF(C110>=87,">90%",IF(C110<=87,"<90%")) -> >90% | D111: =IF(D110>=87,">90%",IF(D110<=87,"<90%")) -> >90% | E111: =IF(E110>=87,">90%",IF(E110<=87,"<90%")) -> >90% | F111: =IF(F110>=87,">90%",IF(F110<=87,"<90%")) -> >90% | G111: =IF(G110>=87,">90%",IF(G110<=87,"<90%")) -> >90% | H111: =IF(H110>=87,">90%",IF(H110<=87,"<90%")) -> >90% | I111: =IF(I110>=87,">90%",IF(I110<=87,"<90%")) -> >90% | ... Q111: =IF(Q110>=87,">90%",IF(Q110<=87,"<90%")) -> >90%
A112: Status | B112: =IF(B110>=87,"OK",IF(B110<=87,"LESS")) -> OK | C112: =IF(C110>=87,"OK",IF(C110<=87,"LESS")) -> OK | D112: =IF(D110>=87,"OK",IF(D110<=87,"LESS")) -> OK | E112: =IF(E110>=87,"OK",IF(E110<=87,"LESS")) -> OK | F112: =IF(F110>=87,"OK",IF(F110<=87,"LESS")) -> OK | G112: =IF(G110>=87,"OK",IF(G110<=87,"LESS")) -> OK | H112: =IF(H110>=87,"OK",IF(H110<=87,"LESS")) -> OK | I112: =IF(I110>=87,"OK",IF(I110<=87,"LESS")) -> OK | ... Q112: =IF(Q110>=87,"OK",IF(Q110<=87,"LESS")) -> OK
A115: Done by | B115: AKASH
A117: Comment

Sheet 06
A1: Station: | B1: IGKV RAIPUR
A2: Date: | B2: =$A$9 -> 06/09/2023 00:15 | C2: Power Off | G2: Pw.Off | J2: Link Fail | L2: Link F | N2: Maintenance | P2: Maint.
A3: Report Type: | B3: Mean | C3: Calibration | G3: Calib. | J3: Data Fail | L3: Data F | N3: Invalid | P3: Invalid
A4: Time Base: | B4: 15 Min | C4: Zero Referrence | G4: Z.Ref | J4: Warm Up | L4: Wm. Up
A7: Date & Time | B7: NO | C7: NO2 | D7: NOX | E7: SO2 | F7: O3 | G7: PM 10 | H7: PM 2.5 | I7: BENZ | J7: WS | K7: WD | L7: TEMP | M7: HUM | N7: SR | O7: RG | P7: CO | Q7: NH3
B8: ug/m3 | C8: ug/m3 | D8: ppb | E8: ug/m3 | F8: ug/m3 | G8: ug/m3 | H8: ug/m3 | I8: ug/m3 | J8: m/sec | K8: deg | L8: degreC | M8: % | N8: w/m2 | O8: mm | P8: mg/m3 | Q8: ug/m3
A9: 06/09/2023 00:15 | B9: 13.58 | C9: 18.29 | D9: 21.8 | E9: 6.28 | F9: 6.07 | G9: 34.52 | H9: 14.69 | I9: 4.53 | J9: 0.12 | K9: 123.95 | L9: 25.48 | M9: 93.71 | N9: 0 | O9: 0 | P9: 0.67 | Q9: 5.87
A10: 06/09/2023 00:30 | B10: 13.84 | C10: 18.43 | D10: 22.08 | E10: 6.2 | F10: 5.7 | G10: 34.52 | H10: 14.69 | I10: 4.36 | J10: 0.21 | K10: 69.54 | L10: 25.27 | M10: 93.43 | N10: 0 | O10: 0 | P10: 0.66 | Q10: 5.84
A11: 06/09/2023 00:45 | B11: 14.08 | C11: 20.69 | D11: 23.46 | E11: 6.71 | F11: 4.25 | G11: 34.52 | H11: 14.69 | I11: 4.33 | J11: 0.4 | K11: 56.79 | L11: 25.2 | M11: 93.77 | N11: 0 | O11: 0 | P11: 0.69 | Q11: 5.91
A12: 06/09/2023 01:00 | B12: 13.95 | C12: 19.86 | D12: 22.92 | E12: 6.8 | F12: 5.67 | G12: 31.32 | H12: 12.03 | I12: 4.35 | J12: 0.35 | K12: 49.49 | L12: 25.23 | M12: 93.81 | N12: 0 | O12: 0 | P12: 0.68 | Q12: 5.94
A13: 06/09/2023 01:15 | B13: 13.9 | C13: 18.09 | D13: 21.95 | E13: 6.62 | F13: 7.13 | G13: 31.13 | H13: 12.03 | I13: 4.46 | J13: 0.31 | K13: 49.07 | L13: 25.14 | M13: 94.12 | N13: 0 | O13: 0 | P13: 0.63 | Q13: 5.87
A14: 06/09/2023 01:30 | B14: 13.8 | C14: 17.81 | D14: 21.72 | E14: 6.4 | F14: 6.79 | G14: 31.13 | H14: 12.03 | I14: 4.26 | J14: 0.23 | K14: 74.86 | L14: 25.23 | M14: 93.53 | N14: 0 | O14: 0 | P14: 0.64 | Q14: 5.82
A15: 06/09/2023 01:45 | B15: 14.07 | C15: 20.03 | D15: 23.1 | E15: 7.14 | F15: 4.6 | G15: 31.13 | H15: 12.03 | I15: 4.2 | J15: 0.14 | K15: 129.91 | L15: 25.28 | M15: 94.35 | N15: 0 | O15: 0 | P15: 0.67 | Q15: 5.88
A16: 06/09/2023 02:00 | B16: 14.18 | C16: 19.23 | D16: 22.77 | E16: 6.67 | F16: 5.14 | G16: 25.21 | H16: 11.11 | I16: 4.18 | J16: 0.17 | K16: 174.18 | L16: 25.28 | M16: 94.56 | N16: 0 | O16: 0 | P16: 0.66 | Q16: 5.88
A17: 06/09/2023 02:15 | B17: 13.76 | C17: 17.68 | D17: 21.62 | E17: 6.37 | F17: 6.86 | G17: 24.86 | H17: 11.11 | I17: 4.32 | J17: 0.07 | K17: 240.49 | L17: 25.18 | M17: 95.49 | N17: 0 | O17: 0 | P17: 0.63 | Q17: 5.83
A18: 06/09/2023 02:30 | B18: 13.3 | C18: 16.78 | D18: 20.79 | E18: 7.92 | F18: 6.82 | G18: 24.86 | H18: 11.11 | I18: 4.18 | J18: 0.22 | K18: 265.62 | L18: 25.27 | M18: 95.4 | N18: 0 | O18: 0 | P18: 0.6 | Q18: 5.8
A19: 06/09/2023 02:45 | B19: 13.24 | C19: 17.78 | D19: 21.26 | E19: 7.46 | F19: 5.82 | G19: 24.86 | H19: 11.11 | I19: 4.04 | J19: 0.19 | K19: 257.85 | L19: 25.39 | M19: 95.18 | N19: 0 | O19: 0 | P19: 0.61 | Q19: 5.74
A20: 06/09/2023 03:00 | B20: 13.61 | C20: 19.23 | D20: 22.31 | E20: 7.96 | F20: 4.85 | G20: 20.12 | H20: 11.19 | I20: 4 | J20: 0.12 | K20: 200.14 | L20: 25.13 | M20: 93.56 | N20: 0 | O20: 0.2 | P20: 0.64 | Q20: 5.82
... A104: 06/09/2023 24:00 | B104: 13.6 | C104: 17.01 | D104: 21.15 | E104: 7.1 | F104: 5.2 | G104: 21.07 | H104: 8.17 | I104: 4.19 | J104: 0.06 | K104: 329.97 | L104: 24.34 | M104: 99.27 | N104: 0 | O104: 1.8 | P104: 0.58 | Q104: 5.7
A106: Min | B106: =MIN(B9:B104) -> 11.8 | C106: =MIN(C9:C104) -> 13.86 | D106: =MIN(D9:D104) -> 18.14 | E106: =MIN(E9:E104) -> 6.2 | F106: =MIN(F9:F104) -> 4.25 | G106: =MIN(G9:G104) -> 13.27 | H106: =MIN(H9:H104) -> 4.76 | I106: =MIN(I9:I104) -> 3.4 | ... Q106: =MIN(Q9:Q104) -> 5.63
A107: Max | B107: =MAX(B9:B104) -> 17.58 | C107: =MAX(C9:C104) -> 22.18 | D107: =MAX(D9:D104) -> 27.04 | E107: =MAX(E9:E104) -> 9.51 | F107: =MAX(F9:F104) -> 9.95 | G107: =MAX(G9:G104) -> 34.88 | H107: =MAX(H9:H104) -> 14.69 | I107: =MAX(I9:I104) -> 4.53 | ... Q107: =MAX(Q9:Q104) -> 5.94
A108: Avg | B108: =AVERAGE(B9:B104) -> 13.492708 | C108: =AVERAGE(C9:C104) -> 17.658125 | D108: =AVERAGE(D9:D104) -> 21.3975 | E108: =AVERAGE(E9:E104) -> 7.7060417 | F108: =AVERAGE(F9:F104) -> 6.2534375 | G108: =AVERAGE(G9:G104) -> 23.864479 | H108: =AVERAGE(H9:H104) -> 8.35875 | I108: =AVERAGE(I9:I104) -> 3.8685417 | ... Q108: =AVERAGE(Q9:Q104) -> 5.7560417
A109: Stdev | B109: =STDEV(B9:B104) -> 0.92759733 | C109: =STDEV(C9:C104) -> 1.3125983 | D109: =STDEV(D9:D104) -> 1.2583506 | E109: =STDEV(E9:E104) -> 0.61498049 | F109: =STDEV(F9:F104) -> 1.2658559 | G109: =STDEV(G9:G104) -> 7.2517388 | H109: =STDEV(H9:H104) -> 2.403611 | I109: =STDEV(I9:I104) -> 0.27923572 | ... Q109: =STDEV(Q9:Q104) -> 0.071000062
A110: Num | B110: =COUNT(B9:B104) -> 96 | C110: =COUNT(C9:C104) -> 96 | D110: =COUNT(D9:D104) -> 96 | E110: =COUNT(E9:E104) -> 96 | F110: =COUNT(F9:F104) -> 96 | G110: =COUNT(G9:G104) -> 96 | H110: =COUNT(H9:H104) -> 96 | I110: =COUNT(I9:I104) -> 96 | ... Q110: =COUNT(Q9:Q104) -> 96
A111: DCR | B111: =IF(B110>=87,">90%",IF(B110<=87,"<90%")) -> >90% | C111: =IF(C110>=87,">90%",IF(C110<=87,"<90%")) -> >90% | D111: =IF(D110>=87,">90%",IF(D110<=87,"<90%")) -> >90% | E111: =IF(E110>=87,">90%",IF(E110<=87,"<90%")) -> >90% | F111: =IF(F110>=87,">90%",IF(F110<=87,"<90%")) -> >90% | G111: =IF(G110>=87,">90%",IF(G110<=87,"<90%")) -> >90% | H111: =IF(H110>=87,">90%",IF(H110<=87,"<90%")) -> >90% | I111: =IF(I110>=87,">90%",IF(I110<=87,"<90%")) -> >90% | ... Q111: =IF(Q110>=87,">90%",IF(Q110<=87,"<90%")) -> >90%
A112: Status | B112: =IF(B110>=87,"OK",IF(B110<=87,"LESS")) -> OK | C112: =IF(C110>=87,"OK",IF(C110<=87,"LESS")) -> OK | D112: =IF(D110>=87,"OK",IF(D110<=87,"LESS")) -> OK | E112: =IF(E110>=87,"OK",IF(E110<=87,"LESS")) -> OK | F112: =IF(F110>=87,"OK",IF(F110<=87,"LESS")) -> OK | G112: =IF(G110>=87,"OK",IF(G110<=87,"LESS")) -> OK | H112: =IF(H110>=87,"OK",IF(H110<=87,"LESS")) -> OK | I112: =IF(I110>=87,"OK",IF(I110<=87,"LESS")) -> OK | ... Q112: =IF(Q110>=87,"OK",IF(Q110<=87,"LESS")) -> OK
A115: Done by | B115: AKASH
A117: Comment

Sheet 07
A1: Station: | B1: IGKV RAIPUR
A2: Date: | B2: =$A$9 -> 07/09/2023 00:15 | C2: Power Off | G2: Pw.Off | J2: Link Fail | L2: Link F | N2: Maintenance | P2: Maint.
A3: Report Type: | B3: Mean | C3: Calibration | G3: Calib. | J3: Data Fail | L3: Data F | N3: Invalid | P3: Invalid
A4: Time Base: | B4: 15 Min | C4: Zero Referrence | G4: Z.Ref | J4: Warm Up | L4: Wm. Up
A7: Date & Time | B7: NO | C7: NO2 | D7: NOX | E7: SO2 | F7: O3 | G7: PM 10 | H7: PM 2.5 | I7: BENZ | J7: WS | K7: WD | L7: TEMP | M7: HUM | N7: SR | O7: RG | P7: CO | Q7: NH3
B8: ug/m3 | C8: ug/m3 | D8: ppb | E8: ug/m3 | F8: ug/m3 | G8: ug/m3 | H8: ug/m3 | I8: ug/m3 | J8: m/sec | K8: deg | L8: degreC | M8: % | N8: w/m2 | O8: mm | P8: mg/m3 | Q8: ug/m3
A9: 07/09/2023 00:15 | B9: 11.66 | C9: 19.82 | D9: 21.05 | E9: 7.29 | F9: 4.08 | G9: 20.61 | H9: 8.17 | I9: 4.17 | J9: 0.12 | K9: 93.4 | L9: 24.35 | M9: 99.49 | N9: 0 | O9: 1.8 | P9: 0.61 | Q9: 5.75
A10: 07/09/2023 00:30 | B10: 12.08 | C10: 17.64 | D10: 20.25 | E10: 7.16 | F10: 4.86 | G10: 20.61 | H10: 8.17 | I10: 4.14 | J10: 0.12 | K10: 123.72 | L10: 24.5 | M10: 99.91 | N10: 0 | O10: 0.6 | P10: 0.6 | Q10: 5.76
A11: 07/09/2023 00:45 | B11: 12 | C11: 16.61 | D11: 19.65 | E11: 7.14 | F11: 5.46 | G11: 20.61 | H11: 8.17 | I11: 4.21 | J11: 0.17 | K11: 133.81 | L11: 24.38 | M11: 100.05 | N11: 0 | O11: 1.8 | P11: 0.57 | Q11: 5.73
A12: 07/09/2023 01:00 | B12: 12.1 | C12: 18.26 | D12: 20.59 | E12: 7.79 | F12: 4.25 | G12: 15.78 | H12: 5.86 | I12: 4.1 | J12: 0.11 | K12: 141.05 | L12: 24.24 | M12: 100.13 | N12: 0 | O12: 1.8 | P12: 0.6 | Q12: 5.79
A13: 07/09/2023 01:15 | B13: 12.24 | C13: 17.67 | D13: 20.4 | E13: 7.63 | F13: 4.65 | G13: 15.55 | H13: 5.86 | I13: 4.06 | J13: 0.1 | K13: 169.68 | L13: 24.24 | M13: 100.22 | N13: 0 | O13: 0.4 | P13: 0.58 | Q13: 5.78
A14: 07/09/2023 01:30 | B14: 12.23 | C14: 16.78 | D14: 19.92 | E14: 6.95 | F14: 5.1 | G14: 15.55 | H14: 5.86 | I14: 4.17 | J14: 0.21 | K14: 246.16 | L14: 24.17 | M14: 99.91 | N14: 0 | O14: 0.2 | P14: 0.57 | Q14: 5.69
A15: 07/09/2023 01:45 | B15: 12.12 | C15: 17.85 | D15: 20.4 | E15: 6.96 | F15: 4.14 | G15: 15.55 | H15: 5.86 | I15: 4.08 | J15: 0.12 | K15: 244.87 | L15: 24.28 | M15: 99.89 | N15: 0 | O15: 0.2 | P15: 0.59 | Q15: 5.73
A16: 07/09/2023 02:00 | B16: 12.18 | C16: 16.98 | D16: 19.99 | E16: 7.11 | F16: 4.55 | G16: 11.49 | H16: 4.51 | I16: 4.03 | J16: 0.1 | K16: 241.43 | L16: 24.42 | M16: 99.66 | N16: 0 | O16: 0.4 | P16: 0.57 | Q16: 5.75
A17: 07/09/2023 02:15 | B17: 12.14 | C17: 15.99 | D17: 19.44 | E17: 6.47 | F17: 5.06 | G17: 11.25 | H17: 4.51 | I17: 4.07 | J17: 0.08 | K17: 201.62 | L17: 24.46 | M17: 99.58 | N17: 0 | O17: 0 | P17: 0.53 | Q17: 5.69
A18: 07/09/2023 02:30 | B18: 12.05 | C18: 15.75 | D18: 19.25 | E18: 7.71 | F18: 4.9 | G18: 11.25 | H18: 4.51 | I18: 3.95 | J18: 0.09 | K18: 141.96 | L18: 24.51 | M18: 99.6 | N18: 0 | O18: 0.2 | P18: 0.53 | Q18: 5.66
A19: 07/09/2023 02:45 | B19: 12.05 | C19: 17.46 | D19: 20.13 | E19: 8.53 | F19: 3.96 | G19: 11.25 | H19: 4.51 | I19: 3.88 | J19: 0.11 | K19: 46.57 | L19: 24.58 | M19: 99.65 | N19: 0 | O19: 0.2 | P19: 0.56 | Q19: 5.72
A20: 07/09/2023 03:00 | B20: 11.94 | C20: 16.02 | D20: 19.3 | E20: 8.41 | F20: 5.02 | G20: 8.42 | H20: 3.36 | I20: 3.89 | J20: 0.08 | K20: 198.53 | L20: 24.56 | M20: 99.7 | N20: 0 | O20: 0 | P20: 0.54 | Q20: 5.72
... A104: 07/09/2023 24:00 | B104: 9.15 | C104: 14.61 | D104: 16.32 | E104: 7.26 | F104: 5.92 | G104: 5.46 | H104: 2.15 | I104: 3.37 | J104: 0.12 | K104: 189.68 | L104: 25.39 | M104: 98.22 | N104: 0 | O104: 0 | P104: 0.47 | Q104: 5.47
A106: Min | B106: =MIN(B9:B104) -> 7.67 | C106: =MIN(C9:C104) -> 12.99 | D106: =MIN(D9:D104) -> 14.57 | E106: =MIN(E9:E104) -> 5.99 | F106: =MIN(F9:F104) -> 3.91 | G106: =MIN(G9:G104) -> 3.17 | H106: =MIN(H9:H104) -> 0.95 | I106: =MIN(I9:I104) -> 3.15 | ... Q106: =MIN(Q9:Q104) -> 5.34
A107: Max | B107: =MAX(B9:B104) -> 12.84 | C107: =MAX(C9:C104) -> 19.82 | D107: =MAX(D9:D104) -> 21.05 | E107: =MAX(E9:E104) -> 9.04 | F107: =MAX(F9:F104) -> 7.85 | G107: =MAX(G9:G104) -> 20.61 | H107: =MAX(H9:H104) -> 8.17 | I107: =MAX(I9:I104) -> 4.21 | ... Q107: =MAX(Q9:Q104) -> 5.8
A108: Avg | B108: =AVERAGE(B9:B104) -> 10.547396 | C108: =AVERAGE(C9:C104) -> 15.93375 | D108: =AVERAGE(D9:D104) -> 18.134688 | E108: =AVERAGE(E9:E104) -> 7.7176042 | F108: =AVERAGE(F9:F104) -> 5.4536458 | G108: =AVERAGE(G9:G104) -> 7.1947917 | H108: =AVERAGE(H9:H104) -> 2.3279167 | I108: =AVERAGE(I9:I104) -> 3.5977083 | ... Q108: =AVERAGE(Q9:Q104) -> 5.5995833
A109: Stdev | B109: =STDEV(B9:B104) -> 1.7127775 | C109: =STDEV(C9:C104) -> 1.2398262 | D109: =STDEV(D9:D104) -> 1.8706458 | E109: =STDEV(E9:E104) -> 0.68438639 | F109: =STDEV(F9:F104) -> 0.93043523 | G109: =STDEV(G9:G104) -> 3.532775 | H109: =STDEV(H9:H104) -> 1.5296452 | I109: =STDEV(I9:I104) -> 0.25301749 | ... Q109: =STDEV(Q9:Q104) -> 0.14387068
A110: Num | B110: =COUNT(B9:B104) -> 96 | C110: =COUNT(C9:C104) -> 96 | D110: =COUNT(D9:D104) -> 96 | E110: =COUNT(E9:E104) -> 96 | F110: =COUNT(F9:F104) -> 96 | G110: =COUNT(G9:G104) -> 96 | H110: =COUNT(H9:H104) -> 96 | I110: =COUNT(I9:I104) -> 96 | ... Q110: =COUNT(Q9:Q104) -> 96
A111: DCR | B111: =IF(B110>=87,">90%",IF(B110<=87,"<90%")) -> >90% | C111: =IF(C110>=87,">90%",IF(C110<=87,"<90%")) -> >90% | D111: =IF(D110>=87,">90%",IF(D110<=87,"<90%")) -> >90% | E111: =IF(E110>=87,">90%",IF(E110<=87,"<90%")) -> >90% | F111: =IF(F110>=87,">90%",IF(F110<=87,"<90%")) -> >90% | G111: =IF(G110>=87,">90%",IF(G110<=87,"<90%")) -> >90% | H111: =IF(H110>=87,">90%",IF(H110<=87,"<90%")) -> >90% | I111: =IF(I110>=87,">90%",IF(I110<=87,"<90%")) -> >90% | ... Q111: =IF(Q110>=87,">90%",IF(Q110<=87,"<90%")) -> >90%
A112: Status | B112: =IF(B110>=87,"OK",IF(B110<=87,"LESS")) -> OK | C112: =IF(C110>=87,"OK",IF(C110<=87,"LESS")) -> OK | D112: =IF(D110>=87,"OK",IF(D110<=87,"LESS")) -> OK | E112: =IF(E110>=87,"OK",IF(E110<=87,"LESS")) -> OK | F112: =IF(F110>=87,"OK",IF(F110<=87,"LESS")) -> OK | G112: =IF(G110>=87,"OK",IF(G110<=87,"LESS")) -> OK | H112: =IF(H110>=87,"OK",IF(H110<=87,"LESS")) -> OK | I112: =IF(I110>=87,"OK",IF(I110<=87,"LESS")) -> OK | ... Q112: =IF(Q110>=87,"OK",IF(Q110<=87,"LESS")) -> OK
A115: Done by | B115: AKASH
A117: Comment

Sheet 08
A1: Station: | B1: IGKV RAIPUR
A2: Date: | B2: =$A$9 -> 08/09/2023 00:15 | C2: Power Off | G2: Pw.Off | J2: Link Fail | L2: Link F | N2: Maintenance | P2: Maint.
A3: Report Type: | B3: Mean | C3: Calibration | G3: Calib. | J3: Data Fail | L3: Data F | N3: Invalid | P3: Invalid
A4: Time Base: | B4: 15 Min | C4: Zero Referrence | G4: Z.Ref | J4: Warm Up | L4: Wm. Up
A7: Date & Time | B7: NO | C7: NO2 | D7: NOX | E7: SO2 | F7: O3 | G7: PM 10 | H7: PM 2.5 | I7: BENZ | J7: WS | K7: WD | L7: TEMP | M7: HUM | N7: SR | O7: RG | P7: CO | Q7: NH3
B8: ug/m3 | C8: ug/m3 | D8: ppb | E8: ug/m3 | F8: ug/m3 | G8: ug/m3 | H8: ug/m3 | I8: ug/m3 | J8: m/sec | K8: deg | L8: degreC | M8: % | N8: w/m2 | O8: mm | P8: mg/m3 | Q8: ug/m3
A9: 08/09/2023 00:15 | B9: 10.45 | C9: 15.52 | D9: 17.84 | E9: 7.66 | F9: 4.54 | G9: 5.51 | H9: 2.15 | I9: 3.29 | J9: 0.48 | K9: 259.79 | L9: 25.15 | M9: 97.82 | N9: 0 | O9: 0 | P9: 0.49 | Q9: 5.54
A10: 08/09/2023 00:30 | B10: 10.12 | C10: 15.72 | D10: 17.68 | E10: 7.18 | F10: 5 | G10: 5.51 | H10: 2.15 | I10: 3.32 | J10: 0.14 | K10: 181.25 | L10: 25.05 | M10: 97.25 | N10: 0 | O10: 0 | P10: 0.47 | Q10: 5.48
A11: 08/09/2023 00:45 | B11: 9.75 | C11: 14.45 | D11: 16.72 | E11: 7.12 | F11: 6 | G11: 5.51 | H11: 2.15 | I11: 3.46 | J11: 0.1 | K11: 224.97 | L11: 25.02 | M11: 97.57 | N11: 0 | O11: 0 | P11: 0.45 | Q11: 5.48
A12: 08/09/2023 01:00 | B12: 9.64 | C12: 14.38 | D12: 16.59 | E12: 6.59 | F12: 5.84 | G12: 7.77 | H12: 2.07 | I12: 3.36 | J12: 0.1 | K12: 230.35 | L12: 25.02 | M12: 97.91 | N12: 0 | O12: 0.2 | P12: 0.44 | Q12: 5.49
A13: 08/09/2023 01:15 | B13: 10.15 | C13: 16.49 | D13: 18.11 | E13: 7.4 | F13: 4.1 | G13: 7.9 | H13: 2.07 | I13: 3.21 | J13: 0.13 | K13: 239.83 | L13: 25.07 | M13: 98.13 | N13: 0 | O13: 0 | P13: 0.47 | Q13: 5.53
A14: 08/09/2023 01:30 | B14: 10.48 | C14: 15.76 | D14: 17.99 | E14: 7.95 | F14: 4.61 | G14: 7.9 | H14: 2.07 | I14: 3.27 | J14: 0.13 | K14: 242.84 | L14: 25.11 | M14: 98.21 | N14: 0 | O14: 0 | P14: 0.48 | Q14: 5.52
A15: 08/09/2023 01:45 | B15: 10.5 | C15: 16.26 | D15: 18.26 | E15: 6.97 | F15: 4.35 | G15: 7.9 | H15: 2.07 | I15: 3.44 | J15: 0.14 | K15: 232.55 | L15: 25.15 | M15: 98.32 | N15: 0 | O15: 0 | P15: 0.49 | Q15: 5.54
A16: 08/09/2023 02:00 | B16: 10.38 | C16: 15.26 | D16: 17.65 | E16: 7.52 | F16: 5.16 | G16: 5.97 | H16: 1.45 | I16: 3.39 | J16: 0.04 | K16: 213.56 | L16: 25.05 | M16: 98.27 | N16: 0 | O16: 0 | P16: 0.46 | Q16: 5.53
A17: 08/09/2023 02:15 | B17: 10.35 | C17: 14.73 | D17: 17.35 | E17: 6.21 | F17: 5.21 | G17: 5.85 | H17: 1.45 | I17: 3.4 | J17: 0.09 | K17: 180.64 | L17: 25.05 | M17: 98.25 | N17: 0 | O17: 0 | P17: 0.45 | Q17: 5.49
A18: 08/09/2023 02:30 | B18: 10.13 | C18: 14.18 | D18: 16.89 | E18: 7.05 | F18: 5.42 | G18: 5.85 | H18: 1.45 | I18: 3.26 | J18: 0.1 | K18: 244.83 | L18: 24.97 | M18: 98.27 | N18: 0 | O18: 0 | P18: 0.43 | Q18: 5.49
A19: 08/09/2023 02:45 | B19: 10.36 | C19: 16.14 | D19: 18.1 | E19: 7.46 | F19: 4.21 | G19: 5.85 | H19: 1.45 | I19: 3.21 | J19: 0.09 | K19: 263.07 | L19: 24.91 | M19: 98.23 | N19: 0 | O19: 0 | P19: 0.46 | Q19: 5.48
A20: 08/09/2023 03:00 | B20: 10.72 | C20: 16.7 | D20: 18.68 | E20: 7.91 | F20: 4.05 | G20: 4.28 | H20: 1.51 | I20: 3.17 | J20: 0.09 | K20: 232.96 | L20: 24.83 | M20: 98.01 | N20: 0 | O20: 0 | P20: 0.47 | Q20: 5.54
... A51: 08/09/2023 10:45 | B51: 11.27 | C51: 15.19 | D51: 18.32 | E51: 7.22 | F51: 5.1 | G51: 4.24 | H51: 1.05 | I51: 3.27 | J51: -0.1 | K51: -0.08 | L51: 28.16 | M51: 85.38 | N51: 188.6 | O51: 0 | P51: 0.43 | Q51: 5.53
A52: 08/09/2023 11:00 | B52: Data F | C52: Data F | D52: Data F | E52: Data F | F52: Data F | G52: Data F | H52: Data F | I52: Data F | J52: Data F | K52: Data F | L52: Data F | M52: Data F | N52: Data F | O52: Data F | P52: Data F | Q52: Data F
A53: 08/09/2023 11:15 | B53: 10.16 | C53: 15.41 | D53: 17.55 | E53: 6.95 | F53: 4.49 | G53: Calib. | H53: Calib. | I53: 3.25 | J53: 0.06 | K53: 244.75 | L53: 27.11 | M53: 90.66 | N53: 106.8 | O53: 0 | P53: 0.45 | Q53: 5.52
A54: 08/09/2023 11:30 | B54: 9.86 | C54: 15.4 | D54: 17.3 | E54: 7.21 | F54: 4.58 | G54: Calib. | H54: Calib. | I54: 3.22 | J54: 0.29 | K54: 251.96 | L54: 26.67 | M54: 93.26 | N54: 102.5 | O54: 0.4 | P54: 0.46 | Q54: 5.59
A55: 08/09/2023 11:45 | B55: 9.45 | C55: 14.38 | D55: 16.44 | E55: 6.65 | F55: 5.15 | G55: Calib. | H55: Calib. | I55: 3.24 | J55: 0.16 | K55: 224.32 | L55: 26.47 | M55: 95.13 | N55: 122.2 | O55: 0.2 | P55: 0.43 | Q55: 5.59
A56: 08/09/2023 12:00 | B56: 9.04 | C56: 14.09 | D56: 15.96 | E56: 7.04 | F56: 8.08 | G56: Calib. | H56: Calib. | I56: 3.18 | J56: 0.19 | K56: 235.82 | L56: 26.65 | M56: 94.84 | N56: 131.3 | O56: 0 | P56: 0.43 | Q56: 5.62
A57: 08/09/2023 12:15 | B57: 9.12 | C57: 14.37 | D57: 16.18 | E57: 7.09 | F57: 6.6 | G57: Calib. | H57: Calib. | I57: 3.08 | J57: 0.47 | K57: 257.87 | L57: 26.74 | M57: 93.61 | N57: 152.3 | O57: 0 | P57: 0.42 | Q57: 5.6
A58: 08/09/2023 12:30 | B58: 9.19 | C58: 14.79 | D58: 16.45 | E58: 6.52 | F58: 5.78 | G58: Calib. | H58: Calib. | I58: 3.06 | J58: 0.24 | K58: 226.31 | L58: 27.04 | M58: 92.65 | N58: 135.1 | O58: 0 | P58: 0.42 | Q58: 5.56
A59: 08/09/2023 12:45 | B59: 9.07 | C59: 15.13 | D59: 16.53 | E59: 6.96 | F59: 5.53 | G59: Calib. | H59: Calib. | I59: 3.12 | J59: 0.71 | K59: 258.38 | L59: 26.83 | M59: 90.72 | N59: 173.7 | O59: 0 | P59: 0.44 | Q59: 5.54
A60: 08/09/2023 13:00 | B60: 8.94 | C60: 15.98 | D60: 16.87 | E60: 7.39 | F60: 5.32 | G60: Calib. | H60: Calib. | I60: 3.13 | J60: 0.63 | K60: 258.77 | L60: 27.09 | M60: 89.57 | N60: 232.4 | O60: 0 | P60: 0.45 | Q60: 5.6
A61: 08/09/2023 13:15 | B61: 8.85 | C61: 15.79 | D61: 16.7 | E61: 6.86 | F61: 5.65 | G61: Calib. | H61: Calib. | I61: 3.13 | J61: 0.7 | K61: 265.64 | L61: 27.58 | M61: 87.31 | N61: 228.8 | O61: 0 | P61: 0.44 | Q61: 5.58
A62: 08/09/2023 13:30 | B62: 8.54 | C62: 16.22 | D62: 16.68 | E62: 6.66 | F62: 5.61 | G62: Calib. | H62: Calib. | I62: 3.13 | J62: 0.7 | K62: 259.31 | L62: 27.9 | M62: 85.51 | N62: 257.6 | O62: 0 | P62: 0.45 | Q62: 5.57
A63: 08/09/2023 13:45 | B63: 8.28 | C63: 16.41 | D63: 16.57 | E63: 6.55 | F63: 5.39 | G63: Calib. | H63: Calib. | I63: 3.11 | J63: 0.53 | K63: 252.17 | L63: 27.8 | M63: 85.8 | N63: 245.9 | O63: 0 | P63: 0.45 | Q63: 5.57
A64: 08/09/2023 14:00 | B64: 7.97 | C64: 16.33 | D64: 16.28 | E64: 6.23 | F64: 5.52 | G64: 0.27 | H64: 0.02 | I64: 3.09 | J64: 0.62 | K64: 257.43 | L64: 27.43 | M64: 86.88 | N64: 77.3 | O64: 0 | P64: 0.45 | Q64: 5.58
A65: 08/09/2023 14:15 | B65: 7.91 | C65: 16.58 | D65: 16.35 | E65: 6.24 | F65: 5.12 | G65: 0.27 | H65: 0.02 | I65: 3.05 | J65: 0.87 | K65: 260.53 | L65: 27.22 | M65: 86.62 | N65: 196.6 | O65: 0 | P65: 0.42 | Q65: 5.59
A66: 08/09/2023 14:30 | B66: 7.7 | C66: 16.49 | D66: 16.14 | E66: 6.17 | F66: 5.12 | G66: 0.27 | H66: 0.02 | I66: 3.04 | J66: 0.74 | K66: 258.85 | L66: 27.41 | M66: 85.87 | N66: 179.8 | O66: 0 | P66: 0.44 | Q66: 5.55
A67: 08/09/2023 14:45 | B67: 7.69 | C67: 16.34 | D67: 16.05 | E67: 6.06 | F67: 5.22 | G67: 0.27 | H67: 0.02 | I67: 3.05 | J67: 0.56 | K67: 250.51 | L67: 27.49 | M67: 85.54 | N67: 158.9 | O67: 0 | P67: 0.44 | Q67: 5.54
A68: 08/09/2023 15:00 | B68: 7.12 | C68: 16.1 | D68: 15.47 | E68: 6.17 | F68: 5.84 | G68: 2.08 | H68: 0.06 | I68: 3 | J68: 0.47 | K68: 246.6 | L68: 27.23 | M68: 85.87 | N68: 105.1 | O68: 0 | P68: 0.44 | Q68: 5.48
A69: 08/09/2023 15:15 | B69: 6.97 | C69: 16.24 | D69: 15.42 | E69: 6.05 | F69: 5.51 | G69: 3.59 | H69: 0.08 | I69: 2.94 | J69: 0.42 | K69: 256.44 | L69: 27.17 | M69: 86.03 | N69: 141.4 | O69: 0 | P69: 0.44 | Q69: 5.49
A70: 08/09/2023 15:30 | B70: 6.91 | C70: 16.58 | D70: 15.56 | E70: 6.13 | F70: 5.32 | G70: 3.59 | H70: 0.08 | I70: 2.86 | J70: 0.39 | K70: 244.27 | L70: 27.29 | M70: 86.07 | N70: 128.6 | O70: 0 | P70: 0.43 | Q70: 5.46
A71: 08/09/2023 15:45 | B71: 7.01 | C71: 16.68 | D71: 15.69 | E71: 5.78 | F71: 4.98 | G71: 3.59 | H71: 0.08 | I71: 2.88 | J71: 0.43 | K71: 254.2 | L71: 27.47 | M71: 85.45 | N71: 176.7 | O71: 0 | P71: 0.43 | Q71: 5.46
A72: 08/09/2023 16:00 | B72: 7.08 | C72: 17.33 | D72: 16.08 | E72: 5.78 | F72: 4.68 | G72: 4.35 | H72: 0.78 | I72: 2.85 | J72: 0.41 | K72: 252.24 | L72: 27.64 | M72: 84.19 | N72: 137.3 | O72: 0 | P72: 0.43 | Q72: 5.47
...

Sheet 09
A1: Station: | B1: IGKV RAIPUR
A2: Date: | B2: =$A$9 -> 09/09/2023 00:15 | C2: Power Off | G2: Pw.Off | J2: Link Fail | L2: Link F | N2: Maintenance | P2: Maint.
A3: Report Type: | B3: Mean | C3: Calibration | G3: Calib. | J3: Data Fail | L3: Data F | N3: Invalid | P3: Invalid
A4: Time Base: | B4: 15 Min | C4: Zero Referrence | G4: Z.Ref | J4: Warm Up | L4: Wm. Up
A7: Date & Time | B7: NO | C7: NO2 | D7: NOX | E7: SO2 | F7: O3 | G7: PM 10 | H7: PM 2.5 | I7: BENZ | J7: WS | K7: WD | L7: TEMP | M7: HUM | N7: SR | O7: RG | P7: CO | Q7: NH3
B8: ug/m3 | C8: ug/m3 | D8: ppb | E8: ug/m3 | F8: ug/m3 | G8: ug/m3 | H8: ug/m3 | I8: ug/m3 | J8: m/sec | K8: deg | L8: degreC | M8: % | N8: w/m2 | O8: mm | P8: mg/m3 | Q8: ug/m3
A9: 09/09/2023 00:15 | B9: 10.69 | C9: 18.61 | D9: 19.65 | E9: 9.65 | F9: 4.19 | G9: 6.75 | H9: 4.55 | I9: 2.82 | J9: 0.2 | K9: 258.97 | L9: 25.42 | M9: 89.89 | N9: 0 | O9: 0 | P9: 0.42 | Q9: 5.57
A10: 09/09/2023 00:30 | B10: 10.82 | C10: 17.44 | D10: 19.14 | E10: 10.2 | F10: 4.36 | G10: 6.75 | H10: 4.55 | I10: 2.82 | J10: 0.16 | K10: 246.43 | L10: 25.39 | M10: 90.39 | N10: 0 | O10: 0 | P10: 0.42 | Q10: 5.57
A11: 09/09/2023 00:45 | B11: 10.65 | C11: 16.21 | D11: 18.36 | E11: 9.32 | F11: 5.19 | G11: 6.75 | H11: 4.55 | I11: 3 | J11: 0.14 | K11: 233.59 | L11: 25.42 | M11: 90.57 | N11: 0 | O11: 0 | P11: 0.41 | Q11: 5.56
A12: 09/09/2023 01:00 | B12: 10.28 | C12: 15.61 | D12: 17.76 | E12: 9.07 | F12: 5.69 | G12: 7.93 | H12: 3.67 | I12: 2.93 | J12: 0.11 | K12: 255.16 | L12: 25.33 | M12: 91.72 | N12: 0 | O12: 0 | P12: 0.4 | Q12: 5.53
A13: 09/09/2023 01:15 | B13: 10.8 | C13: 17.97 | D13: 19.4 | E13: 10.41 | F13: 4.12 | G13: 8.92 | H13: 3.35 | I13: 0.03 | J13: 0.12 | K13: 249.33 | L13: 25.26 | M13: 92.32 | N13: 0 | O13: 0 | P13: 0.42 | Q13: 5.59
A14: 09/09/2023 01:30 | B14: 11.06 | C14: 17.54 | D14: 19.39 | E14: 9.31 | F14: 4.39 | G14: 8.92 | H14: 3.35 | I14: 1.21 | J14: 0.16 | K14: 262.86 | L14: 25.21 | M14: 92.59 | N14: 0 | O14: 0 | P14: 0.42 | Q14: 5.58
A15: 09/09/2023 01:45 | B15: 11.28 | C15: 17.64 | D15: 19.62 | E15: 9.34 | F15: 4.3 | G15: 8.92 | H15: 3.35 | I15: 2.95 | J15: 0.1 | K15: 253.26 | L15: 25.24 | M15: 92.57 | N15: 0 | O15: 0 | P15: 0.44 | Q15: 5.59
A16: 09/09/2023 02:00 | B16: 11.25 | C16: 15.99 | D16: 18.73 | E16: 8.99 | F16: 5.24 | G16: 7.5 | H16: 2.72 | I16: 2.94 | J16: 0.11 | K16: 266.47 | L16: 25.2 | M16: 93.31 | N16: 0 | O16: 0 | P16: 0.41 | Q16: 5.57
A17: 09/09/2023 02:15 | B17: 11.16 | C17: 15.29 | D17: 18.29 | E17: 6.8 | F17: 5.24 | G17: 6.46 | H17: 2.52 | I17: 2.98 | J17: 0.09 | K17: 249.15 | L17: 25.21 | M17: 93.72 | N17: 0 | O17: 0 | P17: 0.39 | Q17: 5.56
A18: 09/09/2023 02:30 | B18: 11.12 | C18: 14.77 | D18: 17.98 | E18: 8.02 | F18: 5.19 | G18: 6.46 | H18: 2.52 | I18: 2.87 | J18: 0.13 | K18: 263.09 | L18: 25.22 | M18: 94.17 | N18: 0 | O18: 0 | P18: 0.37 | Q18: 5.55
A19: 09/09/2023 02:45 | B19: 11.16 | C19: 15.74 | D19: 18.52 | E19: 8.18 | F19: 4.62 | G19: 6.46 | H19: 2.52 | I19: 2.8 | J19: 0.13 | K19: 266.67 | L19: 25.22 | M19: 94.36 | N19: 0 | O19: 0 | P19: 0.39 | Q19: 5.52
A20: 09/09/2023 03:00 | B20: 11.52 | C20: 17.34 | D20: 19.65 | E20: 8.09 | F20: 3.97 | G20: 7.23 | H20: 2.05 | I20: 2.81 | J20: 0.1 | K20: 274.01 | L20: 25.29 | M20: 94.05 | N20: 0 | O20: 0 | P20: 0.43 | Q20: 5.6
... A104: 09/09/2023 24:00 | B104: 9.22 | C104: 12.59 | D104: 15.32 | E104: 7.28 | F104: 7.42 | G104: 9.53 | H104: 3.25 | I104: 2.86 | J104: 0.06 | K104: 206.17 | L104: 26 | M104: 89.72 | N104: 0 | O104: 0 | P104: 0.33 | Q104: 5.35
A106: Min | B106: =MIN(B9:B104) -> 7.83 | C106: =MIN(C9:C104) -> 11.82 | D106: =MIN(D9:D104) -> 13.9 | E106: =MIN(E9:E104) -> 6.43 | F106: =MIN(F9:F104) -> 3.93 | G106: =MIN(G9:G104) -> 4.62 | H106: =MIN(H9:H104) -> 1.16 | I106: =MIN(I9:I104) -> 0.03 | ... Q106: =MIN(Q9:Q104) -> 5.25
A107: Max | B107: =MAX(B9:B104) -> 12.86 | C107: =MAX(C9:C104) -> 18.61 | D107: =MAX(D9:D104) -> 21.21 | E107: =MAX(E9:E104) -> 10.41 | F107: =MAX(F9:F104) -> 11.2 | G107: =MAX(G9:G104) -> 12.58 | H107: =MAX(H9:H104) -> 4.55 | I107: =MAX(I9:I104) -> 3 | ... Q107: =MAX(Q9:Q104) -> 5.7
A108: Avg | B108: =AVERAGE(B9:B104) -> 10.194896 | C108: =AVERAGE(C9:C104) -> 14.905 | D108: =AVERAGE(D9:D104) -> 17.314479 | E108: =AVERAGE(E9:E104) -> 7.87 | F108: =AVERAGE(F9:F104) -> 5.9655208 | G108: =AVERAGE(G9:G104) -> 7.7122917 | H108: =AVERAGE(H9:H104) -> 2.5229167 | I108: =AVERAGE(I9:I104) -> 2.7494792 | ... Q108: =AVERAGE(Q9:Q104) -> 5.441875
A109: Stdev | B109: =STDEV(B9:B104) -> 1.5079215 | C109: =STDEV(C9:C104) -> 1.5435366 | D109: =STDEV(D9:D104) -> 1.8954382 | E109: =STDEV(E9:E104) -> 0.68422065 | F109: =STDEV(F9:F104) -> 1.6911042 | G109: =STDEV(G9:G104) -> 2.0014234 | H109: =STDEV(H9:H104) -> 0.90957007 | I109: =STDEV(I9:I104) -> 0.34785469 | ... Q109: =STDEV(Q9:Q104) -> 0.14279402
A110: Num | B110: =COUNT(B9:B104) -> 96 | C110: =COUNT(C9:C104) -> 96 | D110: =COUNT(D9:D104) -> 96 | E110: =COUNT(E9:E104) -> 96 | F110: =COUNT(F9:F104) -> 96 | G110: =COUNT(G9:G104) -> 96 | H110: =COUNT(H9:H104) -> 96 | I110: =COUNT(I9:I104) -> 96 | ... Q110: =COUNT(Q9:Q104) -> 96
A111: DCR | B111: =IF(B110>=87,">90%",IF(B110<=87,"<90%")) -> >90% | C111: =IF(C110>=87,">90%",IF(C110<=87,"<90%")) -> >90% | D111: =IF(D110>=87,">90%",IF(D110<=87,"<90%")) -> >90% | E111: =IF(E110>=87,">90%",IF(E110<=87,"<90%")) -> >90% | F111: =IF(F110>=87,">90%",IF(F110<=87,"<90%")) -> >90% | G111: =IF(G110>=87,">90%",IF(G110<=87,"<90%")) -> >90% | H111: =IF(H110>=87,">90%",IF(H110<=87,"<90%")) -> >90% | I111: =IF(I110>=87,">90%",IF(I110<=87,"<90%")) -> >90% | ... Q111: =IF(Q110>=87,">90%",IF(Q110<=87,"<90%")) -> >90%
A112: Status | B112: =IF(B110>=87,"OK",IF(B110<=87,"LESS")) -> OK | C112: =IF(C110>=87,"OK",IF(C110<=87,"LESS")) -> OK | D112: =IF(D110>=87,"OK",IF(D110<=87,"LESS")) -> OK | E112: =IF(E110>=87,"OK",IF(E110<=87,"LESS")) -> OK | F112: =IF(F110>=87,"OK",IF(F110<=87,"LESS")) -> OK | G112: =IF(G110>=87,"OK",IF(G110<=87,"LESS")) -> OK | H112: =IF(H110>=87,"OK",IF(H110<=87,"LESS")) -> OK | I112: =IF(I110>=87,"OK",IF(I110<=87,"LESS")) -> OK | ... Q112: =IF(Q110>=87,"OK",IF(Q110<=87,"LESS")) -> OK
A115: Done by | B115: AKASH
A117: Comment

Sheet 10
A1: Station: | B1: IGKV RAIPUR
A2: Date: | B2: =$A$9 -> 10/09/2023 00:15 | C2: Power Off | G2: Pw.Off | J2: Link Fail | L2: Link F | N2: Maintenance | P2: Maint.
A3: Report Type: | B3: Mean | C3: Calibration | G3: Calib. | J3: Data Fail | L3: Data F | N3: Invalid | P3: Invalid
A4: Time Base: | B4: 15 Min | C4: Zero Referrence | G4: Z.Ref | J4: Warm Up | L4: Wm. Up
A7: Date & Time | B7: NO | C7: NO2 | D7: NOX | E7: SO2 | F7: O3 | G7: PM 10 | H7: PM 2.5 | I7: BENZ | J7: WS | K7: WD | L7: TEMP | M7: HUM | N7: SR | O7: RG | P7: CO | Q7: NH3
B8: ug/m3 | C8: ug/m3 | D8: ppb | E8: ug/m3 | F8: ug/m3 | G8: ug/m3 | H8: ug/m3 | I8: ug/m3 | J8: m/sec | K8: deg | L8: degreC | M8: % | N8: w/m2 | O8: mm | P8: mg/m3 | Q8: ug/m3
A9: 10/09/2023 00:15 | B9: 9.8 | C9: 15.82 | D9: 17.47 | E9: 7.7 | F9: 5.18 | G9: 8.31 | H9: 3.68 | I9: 2.76 | J9: 0.09 | K9: 141.94 | L9: 25.97 | M9: 89.94 | N9: 0 | O9: 0 | P9: 0.35 | Q9: 5.39
A10: 10/09/2023 00:30 | B10: 9.83 | C10: 15.22 | D10: 17.19 | E10: 7.94 | F10: 5.02 | G10: 8.31 | H10: 3.68 | I10: 2.56 | J10: 0.08 | K10: 170.94 | L10: 25.85 | M10: 90.25 | N10: 0 | O10: 0 | P10: 0.36 | Q10: 5.41
A11: 10/09/2023 00:45 | B11: 9.69 | C11: 14.08 | D11: 16.48 | E11: 7.56 | F11: 5.89 | G11: 8.31 | H11: 3.68 | I11: 2.97 | J11: 0.07 | K11: 192.13 | L11: 25.81 | M11: 90.35 | N11: 0 | O11: 0 | P11: 0.34 | Q11: 5.4
A12: 10/09/2023 01:00 | B12: 9.31 | C12: 12.59 | D12: 15.39 | E12: 7.23 | F12: 6.95 | G12: 7.78 | H12: 2.96 | I12: 2.9 | J12: 0.11 | K12: 167.23 | L12: 25.81 | M12: 91.4 | N12: 0 | O12: 0 | P12: 0.32 | Q12: 5.37
A13: 10/09/2023 01:15 | B13: 9.19 | C13: 12.33 | D13: 15.16 | E13: 7.31 | F13: 6.93 | G13: 7.39 | H13: 2.73 | I13: 2.73 | J13: 0.07 | K13: 219.26 | L13: 25.73 | M13: 91.71 | N13: 0 | O13: 0 | P13: 0.31 | Q13: 5.36
A14: 10/09/2023 01:30 | B14: 9.6 | C14: 15.25 | D14: 17.02 | E14: 7.64 | F14: 4.81 | G14: 7.39 | H14: 2.73 | I14: 2.63 | J14: 0.07 | K14: 174.09 | L14: 25.66 | M14: 92.95 | N14: 0 | O14: 0 | P14: 0.35 | Q14: 5.38
A15: 10/09/2023 01:45 | B15: 10.08 | C15: 16.26 | D15: 17.93 | E15: 8 | F15: 4.27 | G15: 7.39 | H15: 2.73 | I15: 2.63 | J15: 0.09 | K15: 196.23 | L15: 25.61 | M15: 93.36 | N15: 0 | O15: 0 | P15: 0.38 | Q15: 5.45
A16: 10/09/2023 02:00 | B16: 10.25 | C16: 14.72 | D16: 17.26 | E16: 7.83 | F16: 5.32 | G16: 7.74 | H16: 3.85 | I16: 2.97 | J16: 0.11 | K16: 221.87 | L16: 25.64 | M16: 92.75 | N16: 0 | O16: 0 | P16: 0.37 | Q16: 5.45
