Workbook

Sheet 01
A1: Station: | B1: IGKV RAIPUR
A2: Date: | B2: =$A$9 -> 01/04/2023 00:15 | C2: Power Off | G2: Pw.Off | J2: Link Fail | L2: Link F | N2: Maintenance | P2: Maint.
A3: Report Type: | B3: Mean | C3: Calibration | G3: Calib. | J3: Data Fail | L3: Data F | N3: Invalid | P3: Invalid
A4: Time Base: | B4: 15 Min | C4: Zero Referrence | G4: Z.Ref | J4: Warm Up | L4: Wm. Up
A7: Date & Time | B7: NO_IGKV | C7: NO2__IGKV | D7: NOX_IGKV | E7: SO2__IGKV | F7: O3__IGKV | G7: PM10_IGKV | H7: PM2.5_IGKV | I7: BENZ_IGKV | J7: WS_IGKV | K7: WD_IGKV | L7: TEMP_IGKV | M7: HUM_IGKV | N7: SR_IGKV | O7: RG_IGKV | P7: CO_IGKV | Q7: NH3_IGKV
B8: ug/m3 | C8: ug/m3 | D8: ug/m3 | E8: ug/m3 | F8: ug/m3 | G8: ug/m3 | H8: ug/m3 | I8: ug/m3 | J8: m/sec | K8: deg | L8: degreC | M8: % | N8: w/m2 | O8: mm | P8: mg/m3 | Q8: ug/m3
A9: 01/04/2023 00:15 | B9: 26.95 | C9: 59.83 | D9: 53.74 | E9: 7.25 | F9: 3.2 | G9: 29.01 | H9: 5.48 | I9: 4.79 | J9: 0.1 | K9: 278.88 | L9: 23.46 | M9: 75.12 | N9: 0 | O9: 0 | P9: 0.61 | Q9: 7.05
A10: 01/04/2023 00:30 | B10: 28.11 | C10: 68.72 | D10: 59.32 | E10: 7.63 | F10: 2.62 | G10: 28.14 | H10: 5.48 | I10: 4.76 | J10: 0.12 | K10: 11.88 | L10: 23.54 | M10: 73.23 | N10: 0 | O10: 0 | P10: 0.62 | Q10: 7.26
A11: 01/04/2023 00:45 | B11: 29.71 | C11: 65.98 | D11: 59.17 | E11: 7.58 | F11: 2.95 | G11: 28.14 | H11: 5.48 | I11: 4.73 | J11: 0.23 | K11: 110.08 | L11: 23.39 | M11: 75.43 | N11: 0 | O11: 0 | P11: 0.61 | Q11: 7.3
A12: 45017.042 | B12: 30.78 | C12: 65.98 | D12: 60.03 | E12: 7.62 | F12: 2.9 | G12: 28.14 | H12: 5.48 | I12: 4.76 | J12: 0.17 | K12: 163.23 | L12: 23.03 | M12: 78.06 | N12: 0 | O12: 0 | P12: 0.61 | Q12: 7.34
A13: 01/04/2023 01:15 | B13: 31.57 | C13: 68.41 | D13: 61.94 | E13: 7.89 | F13: 2.7 | G13: 27.47 | H13: 7.59 | I13: 4.74 | J13: 0.18 | K13: 170.93 | L13: 22.67 | M13: 81.18 | N13: 0 | O13: 0 | P13: 0.62 | Q13: 7.43
A14: 01/04/2023 01:30 | B14: 32.56 | C14: 67.4 | D14: 62.2 | E14: 7.88 | F14: 2.81 | G14: 27.3 | H14: 7.59 | I14: 4.79 | J14: 0.2 | K14: 45.52 | L14: 22.46 | M14: 80.33 | N14: 0 | O14: 0 | P14: 0.62 | Q14: 7.51
A15: 01/04/2023 01:45 | B15: 33.84 | C15: 64.05 | D15: 61.47 | E15: 7.76 | F15: 3.04 | G15: 27.3 | H15: 7.59 | I15: 4.77 | J15: 0.4 | K15: 23.39 | L15: 22.72 | M15: 77.06 | N15: 0 | O15: 0 | P15: 0.6 | Q15: 7.5
A16: 01/04/2023 02:00 | B16: 34.75 | C16: 67.14 | D16: 63.82 | E16: 7.11 | F16: 2.67 | G16: 27.3 | H16: 7.59 | I16: 4.73 | J16: 0.31 | K16: 46.43 | L16: 22.79 | M16: 76.8 | N16: 0 | O16: 0 | P16: 0.62 | Q16: 7.58
A17: 01/04/2023 02:15 | B17: 36.19 | C17: 63.47 | D17: 63.05 | E17: 5.07 | F17: 3.11 | G17: 29.32 | H17: 13.53 | I17: 4.74 | J17: 0.2 | K17: 56.35 | L17: 22.81 | M17: 77.3 | N17: 0 | O17: 0 | P17: 0.6 | Q17: 7.53
A18: 01/04/2023 02:30 | B18: 37.05 | C18: 66.98 | D18: 65.58 | E18: 7.65 | F18: 2.8 | G18: 29.87 | H18: 13.53 | I18: 4.75 | J18: 0.6 | K18: 48.4 | L18: 22.69 | M18: 77.63 | N18: 0 | O18: 0 | P18: 0.61 | Q18: 7.7
A19: 01/04/2023 02:45 | B19: 37.76 | C19: 64.9 | D19: 65.06 | E19: 8.14 | F19: 2.98 | G19: 29.87 | H19: 13.53 | I19: 4.77 | J19: 0.82 | K19: 57.56 | L19: 22.42 | M19: 81.59 | N19: 0 | O19: 0 | P19: 0.6 | Q19: 7.67
A20: 01/04/2023 03:00 | B20: 38.39 | C20: 65.95 | D20: 66.12 | E20: 8.32 | F20: 2.89 | G20: 29.87 | H20: 13.53 | I20: 4.87 | J20: 0.59 | K20: 15.42 | L20: 22.28 | M20: 83.68 | N20: 0 | O20: 0 | P20: 0.61 | Q20: 7.75
A21: 01/04/2023 03:15 | B21: 39.07 | C21: 65.75 | D21: 66.56 | E21: 8.72 | F21: 2.93 | G21: 32.04 | H21: 12.61 | I21: 4.86 | J21: 0.88 | K21: 26.99 | L21: 22.18 | M21: 84.55 | N21: 0 | O21: 0 | P21: 0.61 | Q21: 7.83
A22: 01/04/2023 03:30 | B22: 39.75 | C22: 65.79 | D22: 67.12 | E22: 8.21 | F22: 2.88 | G22: 32.62 | H22: 12.61 | I22: 4.88 | J22: 1.04 | K22: 35.18 | L22: 22.17 | M22: 84.46 | N22: 0 | O22: 0 | P22: 0.6 | Q22: 7.87
A23: 01/04/2023 03:45 | B23: 40.3 | C23: 63.37 | D23: 66.3 | E23: 8.3 | F23: 3.01 | G23: 32.62 | H23: 12.61 | I23: 4.9 | J23: 0.94 | K23: 38.02 | L23: 22.2 | M23: 83.8 | N23: 0 | O23: 0 | P23: 0.58 | Q23: 7.81
A24: 01/04/2023 04:00 | B24: 40.42 | C24: 66.12 | D24: 67.83 | E24: 8.57 | F24: 2.76 | G24: 32.62 | H24: 12.61 | I24: 4.85 | J24: 1.25 | K24: 28.38 | L24: 22.18 | M24: 82.4 | N24: 0 | O24: 0 | P24: 0.59 | Q24: 7.96
... A55: 01/04/2023 11:45 | B55: 19.01 | C55: 63.01 | D55: 49.03 | E55: 7.41 | F55: 4.09 | G55: 12.52 | H55: 21.75 | I55: 3.67 | J55: 0.67 | K55: 248.16 | L55: 30.28 | M55: 44.85 | N55: 860.2 | O55: 0 | P55: 0.44 | Q55: 6.51
A56: 01/04/2023 12:00 | B56: 12.62 | C56: 47.29 | D56: 35.7 | E56: 8 | F56: 22.61 | G56: Calib. | H56: Calib. | I56: 3.69 | J56: 0.57 | K56: 290.53 | L56: 30.65 | M56: 42.8 | N56: 882.3 | O56: 0 | P56: 0.44 | Q56: 6.4
A57: 01/04/2023 12:15 | B57: 6.92 | C57: 40.57 | D57: 27.62 | E57: 7.1 | F57: 22.7 | G57: Calib. | H57: Calib. | I57: 3.68 | J57: 0.36 | K57: 220.29 | L57: 31.08 | M57: 41.17 | N57: 885.4 | O57: 0 | P57: 0.41 | Q57: 5.81
A58: 01/04/2023 12:30 | B58: 4.53 | C58: 45.39 | D58: 28.22 | E58: 6.96 | F58: 16.77 | G58: Calib. | H58: Calib. | I58: 3.48 | J58: 0.48 | K58: 284.8 | L58: 31.38 | M58: 38.68 | N58: 885.2 | O58: 0 | P58: 0.42 | Q58: 5.56
A59: 01/04/2023 12:45 | B59: 4.26 | C59: 43.88 | D59: 27.22 | E59: 7.26 | F59: 24.23 | G59: Calib. | H59: Calib. | I59: 3.3 | J59: 0.21 | K59: 335.78 | L59: 31.82 | M59: 35.63 | N59: 873.7 | O59: 0 | P59: 0.43 | Q59: 5.66
A60: 01/04/2023 13:00 | B60: 4.4 | C60: 37.02 | D60: 23.75 | E60: 7.48 | F60: 33.56 | G60: Calib. | H60: Calib. | I60: 3.26 | J60: 0.82 | K60: 305.86 | L60: 32.3 | M60: 34.63 | N60: 888.2 | O60: 0 | P60: 0.42 | Q60: 5.38
A61: 01/04/2023 13:15 | B61: 4.03 | C61: 35.79 | D61: 22.8 | E61: 7.31 | F61: 26.17 | G61: Calib. | H61: Calib. | I61: 3.17 | J61: 0.45 | K61: 276.48 | L61: 32.68 | M61: 32.28 | N61: 869.8 | O61: 0 | P61: 0.41 | Q61: 5.15
A62: 01/04/2023 13:30 | B62: 3.73 | C62: 33.7 | D62: 21.47 | E62: 7.21 | F62: 34.7 | G62: Calib. | H62: Calib. | I62: 3.01 | J62: 0.36 | K62: 248.47 | L62: 32.96 | M62: 31.4 | N62: 833.1 | O62: 0 | P62: 0.39 | Q62: 4.99
A63: 01/04/2023 13:45 | B63: 3.18 | C63: 33.37 | D63: 20.86 | E63: 6.34 | F63: 20.65 | G63: Calib. | H63: Calib. | I63: 2.91 | J63: 0.55 | K63: 212.94 | L63: 33.42 | M63: 31.29 | N63: 784.3 | O63: 0 | P63: 0.39 | Q63: 4.92
A64: 01/04/2023 14:00 | B64: 3.21 | C64: 33.27 | D64: 20.83 | E64: 6.78 | F64: 27.93 | G64: Calib. | H64: Calib. | I64: 2.76 | J64: 0.58 | K64: 211.49 | L64: 34.19 | M64: 28.12 | N64: 792.4 | O64: 0 | P64: 0.38 | Q64: 5
A65: 01/04/2023 14:15 | B65: 3.2 | C65: 34.74 | D65: 21.59 | E65: 6.8 | F65: 32.1 | G65: Calib. | H65: Calib. | I65: 2.71 | J65: 0.74 | K65: 257.8 | L65: 33.66 | M65: 29.51 | N65: 776.7 | O65: 0 | P65: 0.36 | Q65: 4.97
A66: 01/04/2023 14:30 | B66: 3.28 | C66: 33.48 | D66: 21 | E66: 7.2 | F66: 31.1 | G66: Calib. | H66: Calib. | I66: 2.59 | J66: 1.07 | K66: 275.55 | L66: 33.18 | M66: 30.69 | N66: 699.7 | O66: 0 | P66: 0.39 | Q66: 4.99
A67: 01/04/2023 14:45 | B67: 3.3 | C67: 36.02 | D67: 22.34 | E67: 6.72 | F67: 14.38 | G67: 17.49 | H67: Calib. | I67: 2.5 | J67: 0.8 | K67: 269.8 | L67: 33.25 | M67: 31.52 | N67: 660.4 | O67: 0 | P67: 0.4 | Q67: 5.03
A68: 01/04/2023 15:00 | B68: 3.61 | C68: 42.36 | D68: 25.9 | E68: 6.5 | F68: 9.99 | G68: 17.49 | H68: Calib. | I68: 2.49 | J68: 0.56 | K68: 297.15 | L68: 34.15 | M68: 29.89 | N68: 631.2 | O68: 0 | P68: 0.42 | Q68: 5.16
A69: 01/04/2023 15:15 | B69: 4.05 | C69: 43.93 | D69: 27.07 | E69: 5.92 | F69: 8.58 | G69: 17.49 | H69: Calib. | I69: 2.7 | J69: 0.5 | K69: 232.42 | L69: 33.88 | M69: 31.06 | N69: 572.9 | O69: 0 | P69: 0.43 | Q69: 5.24
A70: 01/04/2023 15:30 | B70: 4.45 | C70: 48.14 | D70: 29.59 | E70: 6.21 | F70: 8.18 | G70: 17.55 | H70: Calib. | I70: 2.87 | J70: 0.54 | K70: 249.17 | L70: 33.84 | M70: 31.61 | N70: 525.1 | O70: 0 | P70: 0.44 | Q70: 5.35
A71: 01/04/2023 15:45 | B71: 4.8 | C71: 50.72 | D71: 31.22 | E71: 6.05 | F71: 7.44 | G71: 20.05 | H71: Calib. | I71: 3.05 | J71: 0.71 | K71: 250.6 | L71: 33.52 | M71: 32.25 | N71: 473.8 | O71: 0 | P71: 0.47 | Q71: 5.5
A72: 01/04/2023 16:00 | B72: 4.95 | C72: 51.06 | D72: 31.52 | E72: 6.38 | F72: 8.65 | G72: 20.05 | H72: Calib. | I72: 3.27 | J72: 0.63 | K72: 244.84 | L72: 33.21 | M72: 32.69 | N72: 408.1 | O72: 0 | P72: 0.49 | Q72: 5.54
...

Sheet 02
A1: Station: | B1: IGKV RAIPUR
A2: Date: | B2: =$A$9 -> 02/04/2023 00:15 | C2: Power Off | G2: Pw.Off | J2: Link Fail | L2: Link F | N2: Maintenance | P2: Maint.
A3: Report Type: | B3: Mean | C3: Calibration | G3: Calib. | J3: Data Fail | L3: Data F | N3: Invalid | P3: Invalid
A4: Time Base: | B4: 15 Min | C4: Zero Referrence | G4: Z.Ref | J4: Warm Up | L4: Wm. Up
A7: Date & Time | B7: NO_IGKV | C7: NO2__IGKV | D7: NOX_IGKV | E7: SO2__IGKV | F7: O3__IGKV | G7: PM10_IGKV | H7: PM2.5_IGKV | I7: BENZ_IGKV | J7: WS_IGKV | K7: WD_IGKV | L7: TEMP_IGKV | M7: HUM_IGKV | N7: SR_IGKV | O7: RG_IGKV | P7: CO_IGKV | Q7: NH3_IGKV
B8: ug/m3 | C8: ug/m3 | D8: ug/m3 | E8: ug/m3 | F8: ug/m3 | G8: ug/m3 | H8: ug/m3 | I8: ug/m3 | J8: m/sec | K8: deg | L8: degreC | M8: % | N8: w/m2 | O8: mm | P8: mg/m3 | Q8: ug/m3
A9: 02/04/2023 00:15 | B9: 39.23 | C9: 70.25 | D9: 69.03 | E9: 7.95 | F9: 3.74 | G9: 54.59 | H9: 28.69 | I9: 6.76 | J9: 0.3 | K9: 188.08 | L9: 23.38 | M9: 72.3 | N9: 0 | O9: 0 | P9: 0.74 | Q9: 8.35
A10: 02/04/2023 00:30 | B10: 39.35 | C10: 68.99 | D10: 68.48 | E10: 8.12 | F10: 3.76 | G10: 54.58 | H10: 28.39 | I10: 6.82 | J10: 0.15 | K10: 149.93 | L10: 22.8 | M10: 73.1 | N10: 0 | O10: 0 | P10: 0.74 | Q10: 8.33
A11: 02/04/2023 00:45 | B11: 39.45 | C11: 69.21 | D11: 68.67 | E11: 7.78 | F11: 3.64 | G11: 53.98 | H11: 18.82 | I11: 6.86 | J11: 0.13 | K11: 190.64 | L11: 22.84 | M11: 72.08 | N11: 0 | O11: 0 | P11: 0.74 | Q11: 8.33
A12: 02/04/2023 01:00 | B12: 39.36 | C12: 68.54 | D12: 68.24 | E12: 7.78 | F12: 3.75 | G12: 53.98 | H12: 18.82 | I12: 6.88 | J12: 0.12 | K12: 206.64 | L12: 22.76 | M12: 71.64 | N12: 0 | O12: 0 | P12: 0.74 | Q12: 8.33
A13: 02/04/2023 01:15 | B13: 39.19 | C13: 68.23 | D13: 67.95 | E13: 7.82 | F13: 3.7 | G13: 53.98 | H13: 18.82 | I13: 6.94 | J13: 0.23 | K13: 168.29 | L13: 22.88 | M13: 74.99 | N13: 0 | O13: 0 | P13: 0.74 | Q13: 8.32
A14: 02/04/2023 01:30 | B14: 38.89 | C14: 67.26 | D14: 67.2 | E14: 7.82 | F14: 3.73 | G14: 53.85 | H14: 18.74 | I14: 7.02 | J14: 0.17 | K14: 125.96 | L14: 22.66 | M14: 73.28 | N14: 0 | O14: 0 | P14: 0.74 | Q14: 8.3
A15: 02/04/2023 01:45 | B15: 39.65 | C15: 68.24 | D15: 68.32 | E15: 7.74 | F15: 3.63 | G15: 48.25 | H15: 13.13 | I15: 7.01 | J15: 0.2 | K15: 81.63 | L15: 23.03 | M15: 70.58 | N15: 0 | O15: 0 | P15: 0.74 | Q15: 8.32
A16: 02/04/2023 02:00 | B16: 42.96 | C16: 67.94 | D16: 70.83 | E16: 7.79 | F16: 3.72 | G16: 48.25 | H16: 13.13 | I16: 7.03 | J16: 0.21 | K16: 165.75 | L16: 23.02 | M16: 72 | N16: 0 | O16: 0 | P16: 0.74 | Q16: 8.49
A17: 02/04/2023 02:15 | B17: 45.13 | C17: 68.56 | D17: 72.89 | E17: 5.51 | F17: 3.67 | G17: 48.25 | H17: 13.13 | I17: 7.06 | J17: 0.19 | K17: 211.01 | L17: 22.56 | M17: 75.71 | N17: 0 | O17: 0 | P17: 0.73 | Q17: 8.66
A18: 02/04/2023 02:30 | B18: 45.88 | C18: 68.2 | D18: 73.3 | E18: 7.85 | F18: 3.8 | G18: 48.24 | H18: 13.21 | I18: 7.07 | J18: 0.19 | K18: 168.06 | L18: 22.49 | M18: 75.56 | N18: 0 | O18: 0 | P18: 0.73 | Q18: 8.73
A19: 02/04/2023 02:45 | B19: 46.13 | C19: 68.67 | D19: 73.75 | E19: 8.35 | F19: 3.47 | G19: 48.03 | H19: 18.15 | I19: 7.06 | J19: 0.28 | K19: 182.22 | L19: 22.33 | M19: 77.22 | N19: 0 | O19: 0 | P19: 0.73 | Q19: 8.75
A20: 02/04/2023 03:00 | B20: 45.85 | C20: 68.53 | D20: 73.45 | E20: 8.22 | F20: 3.48 | G20: 48.03 | H20: 18.15 | I20: 7.04 | J20: 0.15 | K20: 179.81 | L20: 21.85 | M20: 78.69 | N20: 0 | O20: 0 | P20: 0.73 | Q20: 8.75
... A57: 02/04/2023 12:15 | B57: 11.99 | C57: 63.64 | D57: 43.74 | E57: 9.46 | F57: 12.55 | G57: 40.16 | H57: 17.51 | I57: 6.83 | J57: 1.18 | K57: 304 | L57: 34.41 | M57: 22.78 | N57: 884.6 | O57: 0 | P57: 0.6 | Q57: 6.76
A58: 02/04/2023 12:30 | B58: 11.23 | C58: 61.55 | D58: 42.04 | E58: 9.31 | F58: 11.38 | G58: 40.15 | H58: 17.28 | I58: 6.67 | J58: Invalid | K58: 0.49 | L58: 34.55 | M58: 22.47 | N58: 876.2 | O58: 0 | P58: 0.58 | Q58: 6.67
A59: 02/04/2023 12:45 | B59: Pw.Off | C59: Pw.Off | D59: Pw.Off | E59: Pw.Off | F59: Pw.Off | G59: Pw.Off | H59: Pw.Off | I59: Pw.Off | J59: Pw.Off | K59: Pw.Off | L59: Pw.Off | M59: Pw.Off | N59: Pw.Off | O59: Pw.Off | P59: Pw.Off | Q59: Pw.Off
A60: 02/04/2023 13:00 | B60: Pw.Off | C60: Pw.Off | D60: Pw.Off | E60: Pw.Off | F60: Pw.Off | G60: Pw.Off | H60: Pw.Off | I60: Pw.Off | J60: Pw.Off | K60: Pw.Off | L60: Pw.Off | M60: Pw.Off | N60: Pw.Off | O60: Pw.Off | P60: Pw.Off | Q60: Pw.Off
A61: 02/04/2023 13:15 | B61: Pw.Off | C61: Pw.Off | D61: Pw.Off | E61: Pw.Off | F61: Pw.Off | G61: Pw.Off | H61: Pw.Off | I61: Pw.Off | J61: Pw.Off | K61: Pw.Off | L61: Pw.Off | M61: Pw.Off | N61: Pw.Off | O61: Pw.Off | P61: Pw.Off | Q61: Pw.Off
A62: 02/04/2023 13:30 | B62: Pw.Off | C62: Pw.Off | D62: Pw.Off | E62: Pw.Off | F62: Pw.Off | G62: Pw.Off | H62: Pw.Off | I62: Pw.Off | J62: Pw.Off | K62: Pw.Off | L62: Pw.Off | M62: Pw.Off | N62: Pw.Off | O62: Pw.Off | P62: Pw.Off | Q62: Pw.Off
A63: 02/04/2023 13:45 | B63: Wm. Up | C63: Wm. Up | D63: Wm. Up | E63: Maint. | F63: Wm. Up | G63: Maint. | H63: Maint. | I63: Wm. Up | J63: 1.8 | K63: 286.99 | L63: 34.92 | M63: 19.25 | N63: 764.6 | O63: 0 | P63: 0.62 | Q63: Wm. Up
A64: 02/04/2023 14:00 | B64: 12.38 | C64: 49.76 | D64: 36.8 | E64: Maint. | F64: 9.52 | G64: Maint. | H64: Maint. | I64: Wm. Up | J64: 1.7 | K64: 300.24 | L64: 35.08 | M64: 19.43 | N64: 767.8 | O64: 0 | P64: 0.59 | Q64: Wm. Up
A65: 02/04/2023 14:15 | B65: 10.93 | C65: 49.73 | D65: 35.62 | E65: Maint. | F65: 9.81 | G65: Maint. | H65: Maint. | I65: 5.79 | J65: 1.59 | K65: 297.68 | L65: 34.91 | M65: 19.6 | N65: 658.9 | O65: 0 | P65: 0.56 | Q65: 5.24
A66: 02/04/2023 14:30 | B66: 9.63 | C66: 50.68 | D66: 35.07 | E66: Maint. | F66: 10.75 | G66: 15.98 | H66: 14.58 | I66: 5.86 | J66: 1 | K66: 264.08 | L66: 34.83 | M66: 19.78 | N66: 401.6 | O66: 0 | P66: 0.56 | Q66: 4.79
A67: 02/04/2023 14:45 | B67: 8.92 | C67: 53.03 | D67: 35.74 | E67: Maint. | F67: 10.04 | G67: 15.98 | H67: 14.58 | I67: 5.63 | J67: 1.31 | K67: 267.49 | L67: 34.72 | M67: 20.1 | N67: 445.7 | O67: 0 | P67: 0.53 | Q67: 4.15
A68: 02/04/2023 15:00 | B68: 7.99 | C68: 54.43 | D68: 35.72 | E68: Maint. | F68: 11.53 | G68: 15.98 | H68: 14.58 | I68: 5.54 | J68: 0.78 | K68: 235.64 | L68: 33.77 | M68: 22.29 | N68: 159 | O68: 0 | P68: 0.5 | Q68: 4.22
A69: 02/04/2023 15:15 | B69: 7.37 | C69: 56.1 | D69: 36.09 | E69: Maint. | F69: 12.67 | G69: 15.98 | H69: 14.58 | I69: 5.44 | J69: 0.81 | K69: 249.27 | L69: 34.19 | M69: 22.73 | N69: 462.6 | O69: 0 | P69: 0.49 | Q69: 4.86
A70: 02/04/2023 15:30 | B70: 6.3 | C70: 52.88 | D70: 33.55 | E70: Maint. | F70: 16.07 | G70: 16.54 | H70: 14.2 | I70: 5.26 | J70: 0.62 | K70: 235.7 | L70: 35.24 | M70: 21.81 | N70: 521.4 | O70: 0 | P70: 0.47 | Q70: 5
A71: 02/04/2023 15:45 | B71: 6.37 | C71: 71.04 | D71: 45.09 | E71: Maint. | F71: 10.78 | G71: 40.99 | H71: 1.93 | I71: 5.09 | J71: 0.72 | K71: 246.68 | L71: 35.34 | M71: 21.19 | N71: 392.5 | O71: 0 | P71: 0.47 | Q71: 4.9
A72: 02/04/2023 16:00 | B72: 5.86 | C72: 62.99 | D72: 38.49 | E72: Maint. | F72: 16 | G72: 40.99 | H72: 1.93 | I72: 4.97 | J72: 0.65 | K72: 264.5 | L72: 35.21 | M72: 21.11 | N72: 368.4 | O72: 0 | P72: 0.47 | Q72: 5
A73: 02/04/2023 16:15 | B73: 5.84 | C73: 59.36 | D73: 36.57 | E73: Maint. | F73: 14.62 | G73: 40.99 | H73: 1.93 | I73: 4.84 | J73: 0.72 | K73: 242.24 | L73: 35.28 | M73: 21.67 | N73: 371 | O73: 0 | P73: 0.46 | Q73: 5
A74: 02/04/2023 16:30 | B74: 5.89 | C74: 58.56 | D74: 36.2 | E74: Maint. | F74: 15.76 | G74: 40.67 | H74: 2.18 | I74: 4.81 | J74: 0.85 | K74: 246.96 | L74: 35.14 | M74: 20.81 | N74: 256.1 | O74: 0 | P74: 0.44 | Q74: 5
A75: 02/04/2023 16:45 | B75: 5.54 | C75: 62.43 | D75: 37.93 | E75: Maint. | F75: 18.54 | G75: 26.5 | H75: 10.18 | I75: 4.81 | J75: 0.52 | K75: 263.37 | L75: 34.59 | M75: 22.08 | N75: 132.4 | O75: 0 | P75: 0.43 | Q75: 5
A76: 02/04/2023 17:00 | B76: 4.98 | C76: 59.43 | D76: 35.92 | E76: Maint. | F76: 23.77 | G76: 26.5 | H76: 10.18 | I76: 4.69 | J76: 1 | K76: 61.01 | L76: 34.58 | M76: 21.92 | N76: 136.5 | O76: 0 | P76: 0.42 | Q76: 5
A77: 02/04/2023 17:15 | B77: 5.98 | C77: 58.37 | D77: 36.16 | E77: Maint. | F77: 18.14 | G77: 26.5 | H77: 10.18 | I77: 4.36 | J77: 0.8 | K77: 23.16 | L77: 34.03 | M77: 20.89 | N77: 90.3 | O77: 0 | P77: 0.42 | Q77: 5
... A80: 02/04/2023 18:00 | B80: 12.4 | C80: 64.91 | D80: 44.73 | E80: Maint. | F80: 14.61 | G80: 28.07 | H80: 19.4 | I80: 4.18 | J80: 0.54 | K80: 44.05 | L80: 32.69 | M80: 23.66 | N80: 9.7 | O80: 0 | P80: 0.49 | Q80: 5
...

Sheet 03
A1: Station: | B1: IGKV RAIPUR
A2: Date: | B2: =$A$9 -> 03/04/2023 00:15 | C2: Power Off | G2: Pw.Off | J2: Link Fail | L2: Link F | N2: Maintenance | P2: Maint.
A3: Report Type: | B3: Mean | C3: Calibration | G3: Calib. | J3: Data Fail | L3: Data F | N3: Invalid | P3: Invalid
A4: Time Base: | B4: 15 Min | C4: Zero Referrence | G4: Z.Ref | J4: Warm Up | L4: Wm. Up
A7: Date & Time | B7: NO_IGKV | C7: NO2__IGKV | D7: NOX_IGKV | E7: SO2__IGKV | F7: O3__IGKV | G7: PM10_IGKV | H7: PM2.5_IGKV | I7: BENZ_IGKV | J7: WS_IGKV | K7: WD_IGKV | L7: TEMP_IGKV | M7: HUM_IGKV | N7: SR_IGKV | O7: RG_IGKV | P7: CO_IGKV | Q7: NH3_IGKV
B8: ug/m3 | C8: ug/m3 | D8: ug/m3 | E8: ug/m3 | F8: ug/m3 | G8: ug/m3 | H8: ug/m3 | I8: ug/m3 | J8: m/sec | K8: deg | L8: degreC | M8: % | N8: w/m2 | O8: mm | P8: mg/m3 | Q8: ug/m3
A9: 03/04/2023 00:15 | B9: 53.25 | C9: 70.41 | D9: 80.36 | E9: 7.08 | F9: 3.87 | G9: 114.59 | H9: 37.12 | I9: 8.08 | J9: 0.25 | K9: 76.51 | L9: 25.24 | M9: 50.46 | N9: 0 | O9: 0 | P9: 0.91 | Q9: 4.55
A10: 03/04/2023 00:30 | B10: 54.49 | C10: 72.14 | D10: 82.27 | E10: 7.09 | F10: 3.86 | G10: 114.82 | H10: 37.16 | I10: 8.21 | J10: 0.24 | K10: 137.54 | L10: 24.43 | M10: 59.7 | N10: 0 | O10: 0 | P10: 0.93 | Q10: 4.74
A11: 03/04/2023 00:45 | B11: 55.72 | C11: 72.45 | D11: 83.41 | E11: 7.32 | F11: 3.62 | G11: 125 | H11: 38.58 | I11: 8.37 | J11: 0.2 | K11: 95.45 | L11: 23.93 | M11: 59.08 | N11: 0 | O11: 0 | P11: 0.94 | Q11: 4.9
A12: 03/04/2023 01:00 | B12: 56.9 | C12: 71.54 | D12: 83.88 | E12: 7.04 | F12: 3.7 | G12: 125 | H12: 38.58 | I12: 8.51 | J12: 0.25 | K12: 152.02 | L12: 23.76 | M12: 62.05 | N12: 0 | O12: 0 | P12: 0.95 | Q12: 4.94
A13: 03/04/2023 01:15 | B13: 57.54 | C13: 72.09 | D13: 84.68 | E13: 7.41 | F13: 3.85 | G13: 125 | H13: 38.58 | I13: 8.6 | J13: 0.21 | K13: 152.17 | L13: 22.95 | M13: 64.95 | N13: 0 | O13: 0 | P13: 0.96 | Q13: 4.94
A14: 03/04/2023 01:30 | B14: 58.33 | C14: 70.55 | D14: 84.51 | E14: 7.2 | F14: 3.76 | G14: 124.38 | H14: 38.39 | I14: 8.68 | J14: 0.1 | K14: 129.03 | L14: 22.97 | M14: 62.15 | N14: 0 | O14: 0 | P14: 0.96 | Q14: 4.94
A15: 03/04/2023 01:45 | B15: 60.12 | C15: 70.68 | D15: 86.01 | E15: 7.39 | F15: 3.66 | G15: 97.13 | H15: 26.22 | I15: 8.75 | J15: 0.19 | K15: 168.56 | L15: 22.73 | M15: 67.47 | N15: 0 | O15: 0 | P15: 0.96 | Q15: 5.04
A16: 03/04/2023 02:00 | B16: 61.49 | C16: 70.94 | D16: 87.25 | E16: 7.95 | F16: 3.71 | G16: 97.13 | H16: 26.22 | I16: 8.78 | J16: 0.18 | K16: 143.48 | L16: 22.5 | M16: 64.91 | N16: 0 | O16: 0 | P16: 0.97 | Q16: 5.13
A17: 03/04/2023 02:15 | B17: 63.02 | C17: 70.43 | D17: 88.21 | E17: 4.51 | F17: 3.73 | G17: 97.13 | H17: 26.22 | I17: 8.81 | J17: 0.26 | K17: 162.16 | L17: 22.1 | M17: 70.28 | N17: 0 | O17: 0 | P17: 0.98 | Q17: 5.2
A18: 03/04/2023 02:30 | B18: 63.38 | C18: 69.97 | D18: 88.26 | E18: 8.36 | F18: 3.68 | G18: 96.79 | H18: 26.4 | I18: 8.86 | J18: 0.31 | K18: 187.82 | L18: 21.4 | M18: 73.09 | N18: 0 | O18: 0 | P18: 0.98 | Q18: 5.25
A19: 03/04/2023 02:45 | B19: 63.12 | C19: 69.7 | D19: 87.9 | E19: 8.85 | F19: 3.8 | G19: 81.69 | H19: 32.13 | I19: 8.91 | J19: 0.15 | K19: 183.6 | L19: 21.18 | M19: 71.35 | N19: 0 | O19: 0 | P19: 0.98 | Q19: 5.2
A20: 03/04/2023 03:00 | B20: 62.4 | C20: 69.39 | D20: 87.17 | E20: 8.72 | F20: 3.59 | G20: 81.69 | H20: 32.13 | I20: 8.95 | J20: 0.15 | K20: 126.99 | L20: 21.27 | M20: 70.92 | N20: 0 | O20: 0 | P20: 0.98 | Q20: 5.14
... A104: 03/04/2023 24:00 | B104: 17.22 | C104: 64.1 | D104: 48.17 | E104: 9.24 | F104: 5.08 | G104: 44.36 | H104: 20.85 | I104: 5.78 | J104: 0.1 | K104: 129.92 | L104: 25.54 | M104: 60.71 | N104: 0 | O104: 0 | P104: 0.71 | Q104: 5
A106: Min | B106: =MIN(B9:B104) -> 4.87 | C106: =MIN(C9:C104) -> 50.53 | D106: =MIN(D9:D104) -> 31.5 | E106: =MIN(E9:E104) -> 4.51 | F106: =MIN(F9:F104) -> 3.59 | G106: =MIN(G9:G104) -> 29.38 | H106: =MIN(H9:H104) -> 15.31 | I106: =MIN(I9:I104) -> 4.35 | ... Q106: =MIN(Q9:Q104) -> 4.55
A107: Max | B107: =MAX(B9:B104) -> 67.68 | C107: =MAX(C9:C104) -> 75 | D107: =MAX(D9:D104) -> 93.02 | E107: =MAX(E9:E104) -> 10.7 | F107: =MAX(F9:F104) -> 22.92 | G107: =MAX(G9:G104) -> 125 | H107: =MAX(H9:H104) -> 42.07 | I107: =MAX(I9:I104) -> 9.76 | ... Q107: =MAX(Q9:Q104) -> 5.8
A108: Avg | B108: =AVERAGE(B9:B104) -> 31.26125 | C108: =AVERAGE(C9:C104) -> 64.935729 | D108: =AVERAGE(D9:D104) -> 59.869479 | E108: =AVERAGE(E9:E104) -> 8.684375 | F108: =AVERAGE(F9:F104) -> 8.8619792 | G108: =AVERAGE(G9:G104) -> 66.194688 | H108: =AVERAGE(H9:H104) -> 25.687604 | I108: =AVERAGE(I9:I104) -> 7.226875 | ... Q108: =AVERAGE(Q9:Q104) -> 5.0828125
A109: Stdev | B109: =STDEV(B9:B104) -> 25.064382 | C109: =STDEV(C9:C104) -> 7.1878912 | D109: =STDEV(D9:D104) -> 23.255599 | E109: =STDEV(E9:E104) -> 1.1161992 | F109: =STDEV(F9:F104) -> 5.7082429 | G109: =STDEV(G9:G104) -> 28.876608 | H109: =STDEV(H9:H104) -> 8.1664485 | I109: =STDEV(I9:I104) -> 1.8209236 | ... Q109: =STDEV(Q9:Q104) -> 0.2325452
A110: Num | B110: =COUNT(B9:B104) -> 96 | C110: =COUNT(C9:C104) -> 96 | D110: =COUNT(D9:D104) -> 96 | E110: =COUNT(E9:E104) -> 96 | F110: =COUNT(F9:F104) -> 96 | G110: =COUNT(G9:G104) -> 96 | H110: =COUNT(H9:H104) -> 96 | I110: =COUNT(I9:I104) -> 96 | ... Q110: =COUNT(Q9:Q104) -> 96
A111: DCR | B111: =IF(B110>=87,">90%",IF(B110<=87,"<90%")) -> >90% | C111: =IF(C110>=87,">90%",IF(C110<=87,"<90%")) -> >90% | D111: =IF(D110>=87,">90%",IF(D110<=87,"<90%")) -> >90% | E111: =IF(E110>=87,">90%",IF(E110<=87,"<90%")) -> >90% | F111: =IF(F110>=87,">90%",IF(F110<=87,"<90%")) -> >90% | G111: =IF(G110>=87,">90%",IF(G110<=87,"<90%")) -> >90% | H111: =IF(H110>=87,">90%",IF(H110<=87,"<90%")) -> >90% | I111: =IF(I110>=87,">90%",IF(I110<=87,"<90%")) -> >90% | ... Q111: =IF(Q110>=87,">90%",IF(Q110<=87,"<90%")) -> >90%
A112: Status | B112: =IF(B110>=87,"OK",IF(B110<=87,"LESS")) -> OK | C112: =IF(C110>=87,"OK",IF(C110<=87,"LESS")) -> OK | D112: =IF(D110>=87,"OK",IF(D110<=87,"LESS")) -> OK | E112: =IF(E110>=87,"OK",IF(E110<=87,"LESS")) -> OK | F112: =IF(F110>=87,"OK",IF(F110<=87,"LESS")) -> OK | G112: =IF(G110>=87,"OK",IF(G110<=87,"LESS")) -> OK | H112: =IF(H110>=87,"OK",IF(H110<=87,"LESS")) -> OK | I112: =IF(I110>=87,"OK",IF(I110<=87,"LESS")) -> OK | ... Q112: =IF(Q110>=87,"OK",IF(Q110<=87,"LESS")) -> OK
A115: Done by | B115: AKASH
A117: Comment

Sheet 04
A1: Station: | B1: IGKV RAIPUR
A2: Date: | B2: =$A$9 -> 04/04/2023 00:15 | C2: Power Off | G2: Pw.Off | J2: Link Fail | L2: Link F | N2: Maintenance | P2: Maint.
A3: Report Type: | B3: Mean | C3: Calibration | G3: Calib. | J3: Data Fail | L3: Data F | N3: Invalid | P3: Invalid
A4: Time Base: | B4: 15 Min | C4: Zero Referrence | G4: Z.Ref | J4: Warm Up | L4: Wm. Up
A7: Date & Time | B7: NO_IGKV | C7: NO2__IGKV | D7: NOX_IGKV | E7: SO2__IGKV | F7: O3__IGKV | G7: PM10_IGKV | H7: PM2.5_IGKV | I7: BENZ_IGKV | J7: WS_IGKV | K7: WD_IGKV | L7: TEMP_IGKV | M7: HUM_IGKV | N7: SR_IGKV | O7: RG_IGKV | P7: CO_IGKV | Q7: NH3_IGKV
B8: ug/m3 | C8: ug/m3 | D8: ug/m3 | E8: ug/m3 | F8: ug/m3 | G8: ug/m3 | H8: ug/m3 | I8: ug/m3 | J8: m/sec | K8: deg | L8: degreC | M8: % | N8: w/m2 | O8: mm | P8: mg/m3 | Q8: ug/m3
A9: 04/04/2023 00:15 | B9: 18.11 | C9: 67.15 | D9: 50.48 | E9: 9.51 | F9: 4.5 | G9: 44.36 | H9: 20.85 | I9: 5.8 | J9: 0.1 | K9: 140.92 | L9: 25.76 | M9: 59.23 | N9: 0 | O9: 0 | P9: 0.71 | Q9: 5
A10: 04/04/2023 00:30 | B10: 17.9 | C10: 67.1 | D10: 50.28 | E10: 8.84 | F10: 4.29 | G10: 44.3 | H10: 20.9 | I10: 5.82 | J10: 0.09 | K10: 171.6 | L10: 25.74 | M10: 59.44 | N10: 0 | O10: 0 | P10: 0.71 | Q10: 5
A11: 04/04/2023 00:45 | B11: 17.8 | C11: 67.59 | D11: 50.46 | E11: 9.15 | F11: 4.39 | G11: 42.07 | H11: 22.43 | I11: 5.79 | J11: 0.08 | K11: 198.57 | L11: 25.57 | M11: 60.47 | N11: 0 | O11: 0 | P11: 0.72 | Q11: 5
A12: 04/04/2023 01:00 | B12: 17.73 | C12: 67.75 | D12: 50.48 | E12: 8.91 | F12: 4.26 | G12: 42.07 | H12: 22.43 | I12: 5.73 | J12: 0.15 | K12: 146.68 | L12: 25.61 | M12: 60.71 | N12: 0 | O12: 0 | P12: 0.71 | Q12: 5
A13: 04/04/2023 01:15 | B13: 17.54 | C13: 67.84 | D13: 50.38 | E13: 9.19 | F13: 4.22 | G13: 42.07 | H13: 22.43 | I13: 5.68 | J13: 0.15 | K13: 137.05 | L13: 25.59 | M13: 61.61 | N13: 0 | O13: 0 | P13: 0.71 | Q13: 5
A14: 04/04/2023 01:30 | B14: 17.4 | C14: 68.08 | D14: 50.4 | E14: 8.76 | F14: 4.31 | G14: 42.03 | H14: 22.34 | I14: 5.66 | J14: 0.14 | K14: 160.38 | L14: 25.41 | M14: 62.21 | N14: 0 | O14: 0 | P14: 0.7 | Q14: 5
A15: 04/04/2023 01:45 | B15: 17.25 | C15: 68.32 | D15: 50.4 | E15: 9.01 | F15: 4.36 | G15: 40.08 | H15: 19.55 | I15: 5.62 | J15: 0.18 | K15: 177.51 | L15: 25.54 | M15: 61.64 | N15: 0 | O15: 0 | P15: 0.7 | Q15: 5
A16: 04/04/2023 02:00 | B16: 17.11 | C16: 68.49 | D16: 50.38 | E16: 8.85 | F16: 3.64 | G16: 40.08 | H16: 19.55 | I16: 5.52 | J16: 0.19 | K16: 141.71 | L16: 25.54 | M16: 62.54 | N16: 0 | O16: 0 | P16: 0.69 | Q16: 5
A17: 04/04/2023 02:15 | B17: 16.93 | C17: 68.78 | D17: 50.39 | E17: 5.01 | F17: 2.68 | G17: 40.08 | H17: 19.55 | I17: 5.46 | J17: 0.14 | K17: 151.88 | L17: 25.17 | M17: 64.22 | N17: 0 | O17: 0 | P17: 0.69 | Q17: 5
A18: 04/04/2023 02:30 | B18: 16.93 | C18: 68.47 | D18: 50.22 | E18: 7.34 | F18: 3.88 | G18: 40.01 | H18: 19.56 | I18: 5.42 | J18: 0.21 | K18: 154.5 | L18: 24.99 | M18: 66.12 | N18: 0 | O18: 0 | P18: 0.68 | Q18: 5
A19: 04/04/2023 02:45 | B19: 17.05 | C19: 68.67 | D19: 50.42 | E19: 7.4 | F19: 3.87 | G19: 37.04 | H19: 19.95 | I19: 5.34 | J19: 0.22 | K19: 154.27 | L19: 24.75 | M19: 67.41 | N19: 0 | O19: 0 | P19: 0.68 | Q19: 5
A20: 04/04/2023 03:00 | B20: 17.15 | C20: 68.46 | D20: 50.39 | E20: 7.41 | F20: 3.81 | G20: 37.04 | H20: 19.95 | I20: 5.25 | J20: 0.12 | K20: 152.44 | L20: 24.41 | M20: 69.78 | N20: 0 | O20: 0 | P20: 0.68 | Q20: 5
... A104: 04/04/2023 24:00 | B104: 16.96 | C104: 70.92 | D104: 51.53 | E104: 7.82 | F104: 3.92 | G104: 42.58 | H104: 19.6 | I104: 4.68 | J104: 0.19 | K104: 176.73 | L104: 25.49 | M104: 61.42 | N104: 0 | O104: 0 | P104: 0.62 | Q104: 5
A106: Min | B106: =MIN(B9:B104) -> 5.91 | C106: =MIN(C9:C104) -> 47.78 | D106: =MIN(D9:D104) -> 30.57 | E106: =MIN(E9:E104) -> 5.01 | F106: =MIN(F9:F104) -> 2.68 | G106: =MIN(G9:G104) -> 34.43 | H106: =MIN(H9:H104) -> 13.05 | I106: =MIN(I9:I104) -> 3.71 | ... Q106: =MIN(Q9:Q104) -> 5
A107: Max | B107: =MAX(B9:B104) -> 26.01 | C107: =MAX(C9:C104) -> 73.96 | D107: =MAX(D9:D104) -> 57.04 | E107: =MAX(E9:E104) -> 14.15 | F107: =MAX(F9:F104) -> 27.67 | G107: =MAX(G9:G104) -> 48.23 | H107: =MAX(H9:H104) -> 22.43 | I107: =MAX(I9:I104) -> 5.82 | ... Q107: =MAX(Q9:Q104) -> 5
A108: Avg | B108: =AVERAGE(B9:B104) -> 14.169063 | C108: =AVERAGE(C9:C104) -> 64.089271 | D108: =AVERAGE(D9:D104) -> 45.720833 | E108: =AVERAGE(E9:E104) -> 8.5075 | F108: =AVERAGE(F9:F104) -> 7.5665625 | G108: =AVERAGE(G9:G104) -> 38.733542 | H108: =AVERAGE(H9:H104) -> 18.758125 | I108: =AVERAGE(I9:I104) -> 4.6035417 | ... Q108: =AVERAGE(Q9:Q104) -> 5
A109: Stdev | B109: =STDEV(B9:B104) -> 6.3163719 | C109: =STDEV(C9:C104) -> 6.8371661 | D109: =STDEV(D9:D104) -> 7.5927863 | E109: =STDEV(E9:E104) -> 1.5003515 | F109: =STDEV(F9:F104) -> 5.0743451 | G109: =STDEV(G9:G104) -> 2.9820805 | H109: =STDEV(H9:H104) -> 2.227734 | I109: =STDEV(I9:I104) -> 0.56905643 | ... Q109: =STDEV(Q9:Q104) -> 0
A110: Num | B110: =COUNT(B9:B104) -> 96 | C110: =COUNT(C9:C104) -> 96 | D110: =COUNT(D9:D104) -> 96 | E110: =COUNT(E9:E104) -> 96 | F110: =COUNT(F9:F104) -> 96 | G110: =COUNT(G9:G104) -> 96 | H110: =COUNT(H9:H104) -> 96 | I110: =COUNT(I9:I104) -> 96 | ... Q110: =COUNT(Q9:Q104) -> 96
A111: DCR | B111: =IF(B110>=87,">90%",IF(B110<=87,"<90%")) -> >90% | C111: =IF(C110>=87,">90%",IF(C110<=87,"<90%")) -> >90% | D111: =IF(D110>=87,">90%",IF(D110<=87,"<90%")) -> >90% | E111: =IF(E110>=87,">90%",IF(E110<=87,"<90%")) -> >90% | F111: =IF(F110>=87,">90%",IF(F110<=87,"<90%")) -> >90% | G111: =IF(G110>=87,">90%",IF(G110<=87,"<90%")) -> >90% | H111: =IF(H110>=87,">90%",IF(H110<=87,"<90%")) -> >90% | I111: =IF(I110>=87,">90%",IF(I110<=87,"<90%")) -> >90% | ... Q111: =IF(Q110>=87,">90%",IF(Q110<=87,"<90%")) -> >90%
A112: Status | B112: =IF(B110>=87,"OK",IF(B110<=87,"LESS")) -> OK | C112: =IF(C110>=87,"OK",IF(C110<=87,"LESS")) -> OK | D112: =IF(D110>=87,"OK",IF(D110<=87,"LESS")) -> OK | E112: =IF(E110>=87,"OK",IF(E110<=87,"LESS")) -> OK | F112: =IF(F110>=87,"OK",IF(F110<=87,"LESS")) -> OK | G112: =IF(G110>=87,"OK",IF(G110<=87,"LESS")) -> OK | H112: =IF(H110>=87,"OK",IF(H110<=87,"LESS")) -> OK | I112: =IF(I110>=87,"OK",IF(I110<=87,"LESS")) -> OK | ... Q112: =IF(Q110>=87,"OK",IF(Q110<=87,"LESS")) -> OK
A115: Done by | B115: AKASH
A117: Comment

Sheet 05
A1: Station: | B1: IGKV RAIPUR
A2: Date: | B2: =$A$9 -> 05/04/2023 00:15 | C2: Power Off | G2: Pw.Off | J2: Link Fail | L2: Link F | N2: Maintenance | P2: Maint.
A3: Report Type: | B3: Mean | C3: Calibration | G3: Calib. | J3: Data Fail | L3: Data F | N3: Invalid | P3: Invalid
A4: Time Base: | B4: 15 Min | C4: Zero Referrence | G4: Z.Ref | J4: Warm Up | L4: Wm. Up
A7: Date & Time | B7: NO_IGKV | C7: NO2__IGKV | D7: NOX_IGKV | E7: SO2__IGKV | F7: O3__IGKV | G7: PM10_IGKV | H7: PM2.5_IGKV | I7: BENZ_IGKV | J7: WS_IGKV | K7: WD_IGKV | L7: TEMP_IGKV | M7: HUM_IGKV | N7: SR_IGKV | O7: RG_IGKV | P7: CO_IGKV | Q7: NH3_IGKV
B8: ug/m3 | C8: ug/m3 | D8: ug/m3 | E8: ug/m3 | F8: ug/m3 | G8: ug/m3 | H8: ug/m3 | I8: ug/m3 | J8: m/sec | K8: deg | L8: degreC | M8: % | N8: w/m2 | O8: mm | P8: mg/m3 | Q8: ug/m3
A9: 05/04/2023 00:15 | B9: 16.84 | C9: 71.58 | D9: 51.78 | E9: 7.54 | F9: 3.86 | G9: 42.58 | H9: 19.6 | I9: 4.66 | J9: 0.19 | K9: 186.5 | L9: 25.27 | M9: 62.83 | N9: 0 | O9: 0 | P9: 0.62 | Q9: 5
A10: 05/04/2023 00:30 | B10: 17.02 | C10: 70.22 | D10: 51.21 | E10: 7.47 | F10: 4.11 | G10: 42.63 | H10: 19.56 | I10: 4.68 | J10: 0.03 | K10: 303.94 | L10: 25.23 | M10: 61.39 | N10: 0 | O10: 0 | P10: 0.62 | Q10: 5
A11: 05/04/2023 00:45 | B11: 17.38 | C11: 61.39 | D11: 46.89 | E11: 7.45 | F11: 5.25 | G11: 44.92 | H11: 18.2 | I11: 4.67 | J11: 0.32 | K11: 200.88 | L11: 25.7 | M11: 58.65 | N11: 0 | O11: 0 | P11: 0.6 | Q11: 5
A12: 05/04/2023 01:00 | B12: 18.09 | C12: 65.04 | D12: 49.36 | E12: 7.81 | F12: 5.43 | G12: 44.92 | H12: 18.2 | I12: 4.67 | J12: 0.17 | K12: 181.26 | L12: 25.53 | M12: 59.46 | N12: 0 | O12: 0 | P12: 0.58 | Q12: 5
A13: 05/04/2023 01:15 | B13: 18.52 | C13: 65.49 | D13: 49.95 | E13: 7.73 | F13: 4.21 | G13: 44.92 | H13: 18.2 | I13: 4.68 | J13: 0.17 | K13: 165.74 | L13: 25.36 | M13: 60.46 | N13: 0 | O13: 0 | P13: 0.58 | Q13: 5
A14: 05/04/2023 01:30 | B14: 18.8 | C14: 66.83 | D14: 50.87 | E14: 7.14 | F14: 3.99 | G14: 44.75 | H14: 18.17 | I14: 4.68 | J14: 0.15 | K14: 165.32 | L14: 25.2 | M14: 61.73 | N14: 0 | O14: 0 | P14: 0.58 | Q14: 5
A15: 05/04/2023 01:45 | B15: 19.14 | C15: 66.79 | D15: 51.12 | E15: 7.9 | F15: 4.02 | G15: 36.9 | H15: 16.11 | I15: 4.65 | J15: 0.25 | K15: 185.67 | L15: 25.09 | M15: 62.15 | N15: 0 | O15: 0 | P15: 0.58 | Q15: 5
A16: 05/04/2023 02:00 | B16: 19.45 | C16: 66.34 | D16: 51.13 | E16: 8.06 | F16: 4.04 | G16: 36.9 | H16: 16.11 | I16: 4.63 | J16: 0.21 | K16: 168.63 | L16: 25.02 | M16: 62.9 | N16: 0 | O16: 0 | P16: 0.58 | Q16: 5
A17: 05/04/2023 02:15 | B17: 19.76 | C17: 65.89 | D17: 51.15 | E17: 5.46 | F17: 4.05 | G17: 36.9 | H17: 16.11 | I17: 4.64 | J17: 0.22 | K17: 117.15 | L17: 24.62 | M17: 64.72 | N17: 0 | O17: 0 | P17: 0.58 | Q17: 5
A18: 05/04/2023 02:30 | B18: 19.7 | C18: 65.56 | D18: 50.93 | E18: 8.21 | F18: 4.17 | G18: 36.87 | H18: 16.1 | I18: 4.65 | J18: 0.1 | K18: 143.63 | L18: 24.54 | M18: 64.69 | N18: 0 | O18: 0 | P18: 0.57 | Q18: 5
A19: 05/04/2023 02:45 | B19: 20.23 | C19: 65.59 | D19: 51.36 | E19: 8.22 | F19: 4.31 | G19: 35.91 | H19: 15.86 | I19: 4.65 | J19: 0.16 | K19: 125.61 | L19: 24.45 | M19: 65.33 | N19: 0 | O19: 0 | P19: 0.58 | Q19: 5
A20: 05/04/2023 03:00 | B20: 21.55 | C20: 66.23 | D20: 52.75 | E20: 8.28 | F20: 3.84 | G20: 35.91 | H20: 15.86 | I20: 4.65 | J20: 0.14 | K20: 153.25 | L20: 24.29 | M20: 65.99 | N20: 0 | O20: 0 | P20: 0.58 | Q20: 5
... A104: 05/04/2023 24:00 | B104: 23.48 | C104: 67.58 | D104: 55.02 | E104: 8.78 | F104: 3.75 | G104: 80.69 | H104: 26.12 | I104: 5.99 | J104: 0.19 | K104: 119.08 | L104: 25.01 | M104: 62.7 | N104: 0 | O104: 0 | P104: 0.73 | Q104: 5
A106: Min | B106: =MIN(B9:B104) -> 5.18 | C106: =MIN(C9:C104) -> 53.76 | D106: =MIN(D9:D104) -> 33.23 | E106: =MIN(E9:E104) -> 5.46 | F106: =MIN(F9:F104) -> 3.56 | G106: =MIN(G9:G104) -> 34.56 | H106: =MIN(H9:H104) -> 13.81 | I106: =MIN(I9:I104) -> 4.63 | ... Q106: =MIN(Q9:Q104) -> 4.95
A107: Max | B107: =MAX(B9:B104) -> 31.35 | C107: =MAX(C9:C104) -> 73.66 | D107: =MAX(D9:D104) -> 63.36 | E107: =MAX(E9:E104) -> 31.8 | F107: =MAX(F9:F104) -> 36.24 | G107: =MAX(G9:G104) -> 84.88 | H107: =MAX(H9:H104) -> 27.13 | I107: =MAX(I9:I104) -> 11.59 | ... Q107: =MAX(Q9:Q104) -> 5
A108: Avg | B108: =AVERAGE(B9:B104) -> 16.771354 | C108: =AVERAGE(C9:C104) -> 65.164896 | D108: =AVERAGE(D9:D104) -> 48.370104 | E108: =AVERAGE(E9:E104) -> 11.613021 | F108: =AVERAGE(F9:F104) -> 10.703542 | G108: =AVERAGE(G9:G104) -> 59.03375 | H108: =AVERAGE(H9:H104) -> 21.508125 | I108: =AVERAGE(I9:I104) -> 6.7227083 | ... Q108: =AVERAGE(Q9:Q104) -> 4.9988542
A109: Stdev | B109: =STDEV(B9:B104) -> 8.3763687 | C109: =STDEV(C9:C104) -> 4.5534537 | D109: =STDEV(D9:D104) -> 8.669441 | E109: =STDEV(E9:E104) -> 5.105038 | F109: =STDEV(F9:F104) -> 8.4909231 | G109: =STDEV(G9:G104) -> 14.728836 | H109: =STDEV(H9:H104) -> 3.6151588 | I109: =STDEV(I9:I104) -> 2.1681651 | ... Q109: =STDEV(Q9:Q104) -> 0.0066284541
A110: Num | B110: =COUNT(B9:B104) -> 96 | C110: =COUNT(C9:C104) -> 96 | D110: =COUNT(D9:D104) -> 96 | E110: =COUNT(E9:E104) -> 96 | F110: =COUNT(F9:F104) -> 96 | G110: =COUNT(G9:G104) -> 96 | H110: =COUNT(H9:H104) -> 96 | I110: =COUNT(I9:I104) -> 96 | ... Q110: =COUNT(Q9:Q104) -> 96
A111: DCR | B111: =IF(B110>=87,">90%",IF(B110<=87,"<90%")) -> >90% | C111: =IF(C110>=87,">90%",IF(C110<=87,"<90%")) -> >90% | D111: =IF(D110>=87,">90%",IF(D110<=87,"<90%")) -> >90% | E111: =IF(E110>=87,">90%",IF(E110<=87,"<90%")) -> >90% | F111: =IF(F110>=87,">90%",IF(F110<=87,"<90%")) -> >90% | G111: =IF(G110>=87,">90%",IF(G110<=87,"<90%")) -> >90% | H111: =IF(H110>=87,">90%",IF(H110<=87,"<90%")) -> >90% | I111: =IF(I110>=87,">90%",IF(I110<=87,"<90%")) -> >90% | ... Q111: =IF(Q110>=87,">90%",IF(Q110<=87,"<90%")) -> >90%
A112: Status | B112: =IF(B110>=87,"OK",IF(B110<=87,"LESS")) -> OK | C112: =IF(C110>=87,"OK",IF(C110<=87,"LESS")) -> OK | D112: =IF(D110>=87,"OK",IF(D110<=87,"LESS")) -> OK | E112: =IF(E110>=87,"OK",IF(E110<=87,"LESS")) -> OK | F112: =IF(F110>=87,"OK",IF(F110<=87,"LESS")) -> OK | G112: =IF(G110>=87,"OK",IF(G110<=87,"LESS")) -> OK | H112: =IF(H110>=87,"OK",IF(H110<=87,"LESS")) -> OK | I112: =IF(I110>=87,"OK",IF(I110<=87,"LESS")) -> OK | ... Q112: =IF(Q110>=87,"OK",IF(Q110<=87,"LESS")) -> OK
A115: Done by | B115: AKASH
A117: Comment

Sheet 06
A1: Station: | B1: IGKV RAIPUR
A2: Date: | B2: =$A$9 -> 06/04/2023 00:15 | C2: Power Off | G2: Pw.Off | J2: Link Fail | L2: Link F | N2: Maintenance | P2: Maint.
A3: Report Type: | B3: Mean | C3: Calibration | G3: Calib. | J3: Data Fail | L3: Data F | N3: Invalid | P3: Invalid
A4: Time Base: | B4: 15 Min | C4: Zero Referrence | G4: Z.Ref | J4: Warm Up | L4: Wm. Up
A7: Date & Time | B7: NO_IGKV | C7: NO2__IGKV | D7: NOX_IGKV | E7: SO2__IGKV | F7: O3__IGKV | G7: PM10_IGKV | H7: PM2.5_IGKV | I7: BENZ_IGKV | J7: WS_IGKV | K7: WD_IGKV | L7: TEMP_IGKV | M7: HUM_IGKV | N7: SR_IGKV | O7: RG_IGKV | P7: CO_IGKV | Q7: NH3_IGKV
B8: ug/m3 | C8: ug/m3 | D8: ug/m3 | E8: ug/m3 | F8: ug/m3 | G8: ug/m3 | H8: ug/m3 | I8: ug/m3 | J8: m/sec | K8: deg | L8: degreC | M8: % | N8: w/m2 | O8: mm | P8: mg/m3 | Q8: ug/m3
A9: 06/04/2023 00:15 | B9: 24 | C9: 67.81 | D9: 55.55 | E9: 8.79 | F9: 4.02 | G9: 80.69 | H9: 26.12 | I9: 6.04 | J9: 0.19 | K9: 154.15 | L9: 25.22 | M9: 61.75 | N9: 0 | O9: 0 | P9: 0.73 | Q9: 5
A10: 06/04/2023 00:30 | B10: 24.29 | C10: 67.65 | D10: 55.7 | E10: 8.61 | F10: 3.82 | G10: 80.86 | H10: 26.15 | I10: 6.08 | J10: 0.23 | K10: 159.31 | L10: 24.96 | M10: 63.93 | N10: 0 | O10: 0 | P10: 0.73 | Q10: 5
A11: 06/04/2023 00:45 | B11: 24.54 | C11: 67.5 | D11: 55.82 | E11: 8.71 | F11: 4.08 | G11: 88.54 | H11: 27.12 | I11: 6.11 | J11: 0.15 | K11: 181.94 | L11: 24.63 | M11: 63.42 | N11: 0 | O11: 0 | P11: 0.74 | Q11: 5
A12: 06/04/2023 01:00 | B12: 24.91 | C12: 68.06 | D12: 56.41 | E12: 9.07 | F12: 3.87 | G12: 88.54 | H12: 27.12 | I12: 6.17 | J12: 0.07 | K12: 137.35 | L12: 24.44 | M12: 63.56 | N12: 0 | O12: 0 | P12: 0.73 | Q12: 5
A13: 06/04/2023 01:15 | B13: 25.2 | C13: 70.07 | D13: 57.7 | E13: 8.64 | F13: 3.73 | G13: 88.54 | H13: 27.12 | I13: 6.22 | J13: 0.14 | K13: 149.79 | L13: 24.79 | M13: 60.86 | N13: 0 | O13: 0 | P13: 0.75 | Q13: 5
A14: 06/04/2023 01:30 | B14: 25.65 | C14: 70.12 | D14: 58.07 | E14: 8.47 | F14: 3.75 | G14: 88.27 | H14: 26.99 | I14: 6.27 | J14: 0.17 | K14: 179.74 | L14: 24.81 | M14: 61.89 | N14: 0 | O14: 0 | P14: 0.76 | Q14: 5
A15: 06/04/2023 01:45 | B15: 25.4 | C15: 70.09 | D15: 57.87 | E15: 8.23 | F15: 3.78 | G15: 76.4 | H15: 22.74 | I15: 6.28 | J15: 0.06 | K15: 204.95 | L15: 24.46 | M15: 63.71 | N15: 0 | O15: 0 | P15: 0.75 | Q15: 5
A16: 06/04/2023 02:00 | B16: 26.05 | C16: 70.37 | D16: 58.53 | E16: 8.35 | F16: 3.77 | G16: 76.4 | H16: 22.74 | I16: 6.25 | J16: 0.2 | K16: 21.99 | L16: 24.39 | M16: 63.46 | N16: 0 | O16: 0 | P16: 0.74 | Q16: 5
A17: 06/04/2023 02:15 | B17: 27.55 | C17: 70.5 | D17: 59.8 | E17: 5.43 | F17: 3.86 | G17: 76.4 | H17: 22.74 | I17: 6.21 | J17: 0.07 | K17: 136.33 | L17: 24.65 | M17: 61.8 | N17: 0 | O17: 0 | P17: 0.74 | Q17: 5
A18: 06/04/2023 02:30 | B18: 28.78 | C18: 70.99 | D18: 61.04 | E18: 7.7 | F18: 3.66 | G18: 76.31 | H18: 22.76 | I18: 6.19 | J18: 0.13 | K18: 149.34 | L18: 24.51 | M18: 64.06 | N18: 0 | O18: 0 | P18: 0.74 | Q18: 5
A19: 06/04/2023 02:45 | B19: 30.02 | C19: 71.59 | D19: 62.35 | E19: 7.7 | F19: 3.63 | G19: 72.08 | H19: 23.66 | I19: 6.16 | J19: 0.25 | K19: 154.26 | L19: 24.32 | M19: 67.05 | N19: 0 | O19: 0 | P19: 0.73 | Q19: 5
A20: 06/04/2023 03:00 | B20: 30.93 | C20: 71.75 | D20: 63.16 | E20: 7.9 | F20: 3.66 | G20: 72.08 | H20: 23.66 | I20: 6.12 | J20: 0.43 | K20: 155.16 | L20: 23.97 | M20: 66.2 | N20: 0 | O20: 0 | P20: 0.73 | Q20: 5
... A104: 06/04/2023 24:00 | B104: 15.1 | C104: 69.01 | D104: 49.04 | E104: 7.09 | F104: 3.97 | G104: 34.74 | H104: 19.34 | I104: 5.83 | J104: 0.21 | K104: 199.56 | L104: 25.51 | M104: 68.39 | N104: 0 | O104: 0 | P104: 0.73 | Q104: 5
A106: Min | B106: =MIN(B9:B104) -> 8.63 | C106: =MIN(C9:C104) -> 57.66 | D106: =MIN(D9:D104) -> 39.11 | E106: =MIN(E9:E104) -> 5.43 | F106: =MIN(F9:F104) -> 3.58 | G106: =MIN(G9:G104) -> 34.74 | H106: =MIN(H9:H104) -> 19.34 | I106: =MIN(I9:I104) -> 5.08 | ... Q106: =MIN(Q9:Q104) -> 5
A107: Max | B107: =MAX(B9:B104) -> 36.75 | C107: =MAX(C9:C104) -> 79.73 | D107: =MAX(D9:D104) -> 66.83 | E107: =MAX(E9:E104) -> 37.65 | F107: =MAX(F9:F104) -> 32.86 | G107: =MAX(G9:G104) -> 174.56 | H107: =MAX(H9:H104) -> 46.04 | I107: =MAX(I9:I104) -> 8.01 | ... Q107: =MAX(Q9:Q104) -> 5
A108: Avg | B108: =AVERAGE(B9:B104) -> 21.774167 | C108: =AVERAGE(C9:C104) -> 68.479792 | D108: =AVERAGE(D9:D104) -> 54.13125 | E108: =AVERAGE(E9:E104) -> 13.105625 | F108: =AVERAGE(F9:F104) -> 8.9991667 | G108: =AVERAGE(G9:G104) -> 85.507292 | H108: =AVERAGE(H9:H104) -> 28.969062 | I108: =AVERAGE(I9:I104) -> 6.4816667 | ... Q108: =AVERAGE(Q9:Q104) -> 5
A109: Stdev | B109: =STDEV(B9:B104) -> 9.330095 | C109: =STDEV(C9:C104) -> 4.4621984 | D109: =STDEV(D9:D104) -> 8.0167714 | E109: =STDEV(E9:E104) -> 6.9591451 | F109: =STDEV(F9:F104) -> 6.9797835 | G109: =STDEV(G9:G104) -> 35.909245 | H109: =STDEV(H9:H104) -> 7.5519616 | I109: =STDEV(I9:I104) -> 0.68969202 | ... Q109: =STDEV(Q9:Q104) -> 0
A110: Num | B110: =COUNT(B9:B104) -> 96 | C110: =COUNT(C9:C104) -> 96 | D110: =COUNT(D9:D104) -> 96 | E110: =COUNT(E9:E104) -> 96 | F110: =COUNT(F9:F104) -> 96 | G110: =COUNT(G9:G104) -> 96 | H110: =COUNT(H9:H104) -> 96 | I110: =COUNT(I9:I104) -> 96 | ... Q110: =COUNT(Q9:Q104) -> 96
A111: DCR | B111: =IF(B110>=87,">90%",IF(B110<=87,"<90%")) -> >90% | C111: =IF(C110>=87,">90%",IF(C110<=87,"<90%")) -> >90% | D111: =IF(D110>=87,">90%",IF(D110<=87,"<90%")) -> >90% | E111: =IF(E110>=87,">90%",IF(E110<=87,"<90%")) -> >90% | F111: =IF(F110>=87,">90%",IF(F110<=87,"<90%")) -> >90% | G111: =IF(G110>=87,">90%",IF(G110<=87,"<90%")) -> >90% | H111: =IF(H110>=87,">90%",IF(H110<=87,"<90%")) -> >90% | I111: =IF(I110>=87,">90%",IF(I110<=87,"<90%")) -> >90% | ... Q111: =IF(Q110>=87,">90%",IF(Q110<=87,"<90%")) -> >90%
A112: Status | B112: =IF(B110>=87,"OK",IF(B110<=87,"LESS")) -> OK | C112: =IF(C110>=87,"OK",IF(C110<=87,"LESS")) -> OK | D112: =IF(D110>=87,"OK",IF(D110<=87,"LESS")) -> OK | E112: =IF(E110>=87,"OK",IF(E110<=87,"LESS")) -> OK | F112: =IF(F110>=87,"OK",IF(F110<=87,"LESS")) -> OK | G112: =IF(G110>=87,"OK",IF(G110<=87,"LESS")) -> OK | H112: =IF(H110>=87,"OK",IF(H110<=87,"LESS")) -> OK | I112: =IF(I110>=87,"OK",IF(I110<=87,"LESS")) -> OK | ... Q112: =IF(Q110>=87,"OK",IF(Q110<=87,"LESS")) -> OK
A115: Done by | B115: AKASH
A117: Comment

Sheet 07
A1: Station: | B1: IGKV RAIPUR
A2: Date: | B2: =$A$9 -> 07/04/2023 00:15 | C2: Power Off | G2: Pw.Off | J2: Link Fail | L2: Link F | N2: Maintenance | P2: Maint.
A3: Report Type: | B3: Mean | C3: Calibration | G3: Calib. | J3: Data Fail | L3: Data F | N3: Invalid | P3: Invalid
A4: Time Base: | B4: 15 Min | C4: Zero Referrence | G4: Z.Ref | J4: Warm Up | L4: Wm. Up
A7: Date & Time | B7: NO_IGKV | C7: NO2__IGKV | D7: NOX_IGKV | E7: SO2__IGKV | F7: O3__IGKV | G7: PM10_IGKV | H7: PM2.5_IGKV | I7: BENZ_IGKV | J7: WS_IGKV | K7: WD_IGKV | L7: TEMP_IGKV | M7: HUM_IGKV | N7: SR_IGKV | O7: RG_IGKV | P7: CO_IGKV | Q7: NH3_IGKV
B8: ug/m3 | C8: ug/m3 | D8: ug/m3 | E8: ug/m3 | F8: ug/m3 | G8: ug/m3 | H8: ug/m3 | I8: ug/m3 | J8: m/sec | K8: deg | L8: degreC | M8: % | N8: w/m2 | O8: mm | P8: mg/m3 | Q8: ug/m3
A9: 07/04/2023 00:15 | B9: 15.28 | C9: 70.69 | D9: 50.06 | E9: 6.79 | F9: 3.8 | G9: 34.74 | H9: 19.34 | I9: 5.73 | J9: 0.14 | K9: 208.14 | L9: 25.26 | M9: 69.61 | N9: 0 | O9: 0 | P9: 0.72 | Q9: 5
A10: 07/04/2023 00:30 | B10: 15.16 | C10: 69.3 | D10: 49.24 | E10: 6.57 | F10: 3.72 | G10: 34.61 | H10: 19.36 | I10: 5.6 | J10: 0.16 | K10: 182.18 | L10: 25.31 | M10: 69.42 | N10: 0 | O10: 0 | P10: 0.7 | Q10: 5
A11: 07/04/2023 00:45 | B11: 15.27 | C11: 69.7 | D11: 49.54 | E11: 7.31 | F11: 3.76 | G11: 28.58 | H11: 20 | I11: 5.44 | J11: 0.2 | K11: 155.83 | L11: 25.08 | M11: 70.56 | N11: 0 | O11: 0 | P11: 0.69 | Q11: 5
A12: 07/04/2023 01:00 | B12: 15.49 | C12: 69.35 | D12: 49.53 | E12: 6.59 | F12: 3.77 | G12: 28.58 | H12: 20 | I12: 5.31 | J12: 0.17 | K12: 173.57 | L12: 24.74 | M12: 72.11 | N12: 0 | O12: 0 | P12: 0.67 | Q12: 5
A13: 07/04/2023 01:15 | B13: 15.64 | C13: 69.19 | D13: 49.56 | E13: 7.06 | F13: 3.89 | G13: 28.58 | H13: 20 | I13: 5.24 | J13: 0.19 | K13: 182.49 | L13: 24.73 | M13: 72.07 | N13: 0 | O13: 0 | P13: 0.66 | Q13: 5
A14: 07/04/2023 01:30 | B14: 15.76 | C14: 68.97 | D14: 49.55 | E14: 6.95 | F14: 3.81 | G14: 28.62 | H14: 19.94 | I14: 5.19 | J14: 0.25 | K14: 222.29 | L14: 24.57 | M14: 72.52 | N14: 0 | O14: 0 | P14: 0.65 | Q14: 5
A15: 07/04/2023 01:45 | B15: 15.99 | C15: 66.1 | D15: 48.23 | E15: 6.88 | F15: 4.23 | G15: 30.29 | H15: 17.98 | I15: 5.09 | J15: 0.11 | K15: 208.98 | L15: 24.62 | M15: 71.4 | N15: 0 | O15: 0 | P15: 0.64 | Q15: 5
A16: 07/04/2023 02:00 | B16: 16.59 | C16: 59.54 | D16: 45.29 | E16: 6.27 | F16: 4.4 | G16: 30.29 | H16: 17.98 | I16: 4.96 | J16: 0.36 | K16: 245.4 | L16: 24.52 | M16: 71.4 | N16: 0 | O16: 0 | P16: 0.61 | Q16: 5
A17: 07/04/2023 02:15 | B17: 16.95 | C17: 63.46 | D17: 47.62 | E17: 4.98 | F17: 4.07 | G17: 30.29 | H17: 17.98 | I17: 4.87 | J17: 0.31 | K17: 245.09 | L17: 24.47 | M17: 71.58 | N17: 0 | O17: 0 | P17: 0.6 | Q17: 5
A18: 07/04/2023 02:30 | B18: 17.4 | C18: 65.58 | D18: 49.09 | E18: 8.45 | F18: 3.87 | G18: 30 | H18: 17.87 | I18: 4.84 | J18: 0.13 | K18: 160.83 | L18: 24.41 | M18: 72.21 | N18: 0 | O18: 0 | P18: 0.59 | Q18: 5
A19: 07/04/2023 02:45 | B19: 17.91 | C19: 66.56 | D19: 50.01 | E19: 8.6 | F19: 3.69 | G19: 17.19 | H19: 14.25 | I19: 4.78 | J19: 0.15 | K19: 123.99 | L19: 24.11 | M19: 73.59 | N19: 0 | O19: 0 | P19: 0.59 | Q19: 5
A20: 07/04/2023 03:00 | B20: 18.39 | C20: 67.53 | D20: 50.9 | E20: 8.94 | F20: 3.61 | G20: 17.19 | H20: 14.25 | I20: 4.71 | J20: 0.1 | K20: 165.19 | L20: 23.76 | M20: 75.4 | N20: 0 | O20: 0 | P20: 0.59 | Q20: 5
... A104: 07/04/2023 24:00 | B104: 9.58 | C104: 62.69 | D104: 41.31 | E104: 7.16 | F104: 6.44 | G104: 33.79 | H104: 10.53 | I104: 3.27 | J104: 0.96 | K104: 60.01 | L104: 25.52 | M104: 48.55 | N104: 0 | O104: 0 | P104: 0.47 | Q104: 5
A106: Min | B106: =MIN(B9:B104) -> 5.18 | C106: =MIN(C9:C104) -> 50 | D106: =MIN(D9:D104) -> 31.35 | E106: =MIN(E9:E104) -> 4.98 | F106: =MIN(F9:F104) -> 3.48 | G106: =MIN(G9:G104) -> 17.19 | H106: =MIN(H9:H104) -> 10.53 | I106: =MIN(I9:I104) -> 3.27 | ... Q106: =MIN(Q9:Q104) -> 5
A107: Max | B107: =MAX(B9:B104) -> 29.66 | C107: =MAX(C9:C104) -> 72.92 | D107: =MAX(D9:D104) -> 60.7 | E107: =MAX(E9:E104) -> 16.43 | F107: =MAX(F9:F104) -> 42.11 | G107: =MAX(G9:G104) -> 74.87 | H107: =MAX(H9:H104) -> 24.1 | I107: =MAX(I9:I104) -> 5.73 | ... Q107: =MAX(Q9:Q104) -> 5
A108: Avg | B108: =AVERAGE(B9:B104) -> 13.755104 | C108: =AVERAGE(C9:C104) -> 62.655208 | D108: =AVERAGE(D9:D104) -> 44.639896 | E108: =AVERAGE(E9:E104) -> 9.435625 | F108: =AVERAGE(F9:F104) -> 12.146875 | G108: =AVERAGE(G9:G104) -> 41.494167 | H108: =AVERAGE(H9:H104) -> 17.153854 | I108: =AVERAGE(I9:I104) -> 4.3023958 | ... Q108: =AVERAGE(Q9:Q104) -> 5
A109: Stdev | B109: =STDEV(B9:B104) -> 8.4164993 | C109: =STDEV(C9:C104) -> 6.3610883 | D109: =STDEV(D9:D104) -> 9.6362495 | E109: =STDEV(E9:E104) -> 2.5399444 | F109: =STDEV(F9:F104) -> 10.752311 | G109: =STDEV(G9:G104) -> 12.207539 | H109: =STDEV(H9:H104) -> 2.4298587 | I109: =STDEV(I9:I104) -> 0.49604063 | ... Q109: =STDEV(Q9:Q104) -> 0
A110: Num | B110: =COUNT(B9:B104) -> 96 | C110: =COUNT(C9:C104) -> 96 | D110: =COUNT(D9:D104) -> 96 | E110: =COUNT(E9:E104) -> 96 | F110: =COUNT(F9:F104) -> 96 | G110: =COUNT(G9:G104) -> 96 | H110: =COUNT(H9:H104) -> 96 | I110: =COUNT(I9:I104) -> 96 | ... Q110: =COUNT(Q9:Q104) -> 96
A111: DCR | B111: =IF(B110>=87,">90%",IF(B110<=87,"<90%")) -> >90% | C111: =IF(C110>=87,">90%",IF(C110<=87,"<90%")) -> >90% | D111: =IF(D110>=87,">90%",IF(D110<=87,"<90%")) -> >90% | E111: =IF(E110>=87,">90%",IF(E110<=87,"<90%")) -> >90% | F111: =IF(F110>=87,">90%",IF(F110<=87,"<90%")) -> >90% | G111: =IF(G110>=87,">90%",IF(G110<=87,"<90%")) -> >90% | H111: =IF(H110>=87,">90%",IF(H110<=87,"<90%")) -> >90% | I111: =IF(I110>=87,">90%",IF(I110<=87,"<90%")) -> >90% | ... Q111: =IF(Q110>=87,">90%",IF(Q110<=87,"<90%")) -> >90%
A112: Status | B112: =IF(B110>=87,"OK",IF(B110<=87,"LESS")) -> OK | C112: =IF(C110>=87,"OK",IF(C110<=87,"LESS")) -> OK | D112: =IF(D110>=87,"OK",IF(D110<=87,"LESS")) -> OK | E112: =IF(E110>=87,"OK",IF(E110<=87,"LESS")) -> OK | F112: =IF(F110>=87,"OK",IF(F110<=87,"LESS")) -> OK | G112: =IF(G110>=87,"OK",IF(G110<=87,"LESS")) -> OK | H112: =IF(H110>=87,"OK",IF(H110<=87,"LESS")) -> OK | I112: =IF(I110>=87,"OK",IF(I110<=87,"LESS")) -> OK | ... Q112: =IF(Q110>=87,"OK",IF(Q110<=87,"LESS")) -> OK
A115: Done by | B115: AKASH
A117: Comment

Sheet 08
A1: Station: | B1: IGKV RAIPUR
A2: Date: | B2: =$A$9 -> 08/04/2023 00:15 | C2: Power Off | G2: Pw.Off | J2: Link Fail | L2: Link F | N2: Maintenance | P2: Maint.
A3: Report Type: | B3: Mean | C3: Calibration | G3: Calib. | J3: Data Fail | L3: Data F | N3: Invalid | P3: Invalid
A4: Time Base: | B4: 15 Min | C4: Zero Referrence | G4: Z.Ref | J4: Warm Up | L4: Wm. Up
A7: Date & Time | B7: NO_IGKV | C7: NO2__IGKV | D7: NOX_IGKV | E7: SO2__IGKV | F7: O3__IGKV | G7: PM10_IGKV | H7: PM2.5_IGKV | I7: BENZ_IGKV | J7: WS_IGKV | K7: WD_IGKV | L7: TEMP_IGKV | M7: HUM_IGKV | N7: SR_IGKV | O7: RG_IGKV | P7: CO_IGKV | Q7: NH3_IGKV
B8: ug/m3 | C8: ug/m3 | D8: ug/m3 | E8: ug/m3 | F8: ug/m3 | G8: ug/m3 | H8: ug/m3 | I8: ug/m3 | J8: m/sec | K8: deg | L8: degreC | M8: % | N8: w/m2 | O8: mm | P8: mg/m3 | Q8: ug/m3
A9: 08/04/2023 00:15 | B9: 10.33 | C9: 61.89 | D9: 41.5 | E9: 6.85 | F9: 5.77 | G9: 33.79 | H9: 10.53 | I9: 3.27 | J9: 1.06 | K9: 60.81 | L9: 25.7 | M9: 47.24 | N9: 0 | O9: 0 | P9: 0.47 | Q9: 5
A10: 08/04/2023 00:30 | B10: 10.51 | C10: 65.02 | D10: 43.27 | E10: 6.93 | F10: 5.37 | G10: 33.78 | H10: 10.55 | I10: 3.28 | J10: 0.88 | K10: 56.18 | L10: 25.8 | M10: 46.62 | N10: 0 | O10: 0 | P10: 0.47 | Q10: 5
A11: 08/04/2023 00:45 | B11: 11.06 | C11: 66.17 | D11: 44.31 | E11: 7.33 | F11: 5.66 | G11: 33.56 | H11: 11.35 | I11: 3.28 | J11: 0.88 | K11: 63.44 | L11: 25.91 | M11: 45.88 | N11: 0 | O11: 0 | P11: 0.47 | Q11: 5
A12: 45024.042 | B12: 11.49 | C12: 66.13 | D12: 44.64 | E12: 7.25 | F12: 5.87 | G12: 33.56 | H12: 11.35 | I12: 3.32 | J12: 1.01 | K12: 61.58 | L12: 26.15 | M12: 44.56 | N12: 0 | O12: 0 | P12: 0.46 | Q12: 5
A13: 08/04/2023 01:15 | B13: 11.7 | C13: 65.91 | D13: 44.69 | E13: 7.28 | F13: 5.99 | G13: 33.56 | H13: 11.35 | I13: 3.36 | J13: 0.58 | K13: 74.68 | L13: 26.38 | M13: 43.58 | N13: 0 | O13: 0 | P13: 0.46 | Q13: 5
A14: 08/04/2023 01:30 | B14: 11.63 | C14: 64.58 | D14: 43.94 | E14: 7.01 | F14: 5.21 | G14: 33.72 | H14: 11.29 | I14: 3.43 | J14: 0.29 | K14: 99.91 | L14: 26.39 | M14: 43.95 | N14: 0 | O14: 0 | P14: 0.46 | Q14: 5
A15: 08/04/2023 01:45 | B15: 11.99 | C15: 66 | D15: 44.97 | E15: 6.76 | F15: 4.48 | G15: 40.68 | H15: 9.51 | I15: 3.46 | J15: 0.2 | K15: 136.71 | L15: 26.38 | M15: 43.94 | N15: 0 | O15: 0 | P15: 0.46 | Q15: 5
A16: 08/04/2023 02:00 | B16: 12.15 | C16: 66.78 | D16: 45.51 | E16: 7.11 | F16: 4.37 | G16: 40.68 | H16: 9.51 | I16: 3.44 | J16: 0.36 | K16: 259.45 | L16: 26.23 | M16: 44.99 | N16: 0 | O16: 0 | P16: 0.46 | Q16: 5
A17: 08/04/2023 02:15 | B17: 12.28 | C17: 68.19 | D17: 46.35 | E17: 5.14 | F17: 4.33 | G17: 40.68 | H17: 9.51 | I17: 3.44 | J17: 0.26 | K17: 222.99 | L17: 25.91 | M17: 46.82 | N17: 0 | O17: 0 | P17: 0.46 | Q17: 5
A18: 08/04/2023 02:30 | B18: 12.09 | C18: 68.57 | D18: 46.4 | E18: 7.23 | F18: 4.53 | G18: 40.5 | H18: 9.52 | I18: 3.46 | J18: 0.09 | K18: 267.34 | L18: 25.95 | M18: 46.3 | N18: 0 | O18: 0 | P18: 0.47 | Q18: 5
A19: 08/04/2023 02:45 | B19: 12.17 | C19: 69.25 | D19: 46.82 | E19: 7.97 | F19: 4.25 | G19: 32.62 | H19: 9.89 | I19: 3.44 | J19: 0.22 | K19: 159.69 | L19: 25.87 | M19: 48.32 | N19: 0 | O19: 0 | P19: 0.48 | Q19: 5
A20: 08/04/2023 03:00 | B20: 12.33 | C20: 69.2 | D20: 46.91 | E20: 7.73 | F20: 4.29 | G20: 32.62 | H20: 9.89 | I20: 3.42 | J20: 0.22 | K20: 218.41 | L20: 25.2 | M20: 51.34 | N20: 0 | O20: 0 | P20: 0.47 | Q20: 5
A21: 08/04/2023 03:15 | B21: 12.51 | C21: 69 | D21: 46.96 | E21: 7.46 | F21: 4.31 | G21: 32.62 | H21: 9.89 | I21: 3.42 | J21: 0.28 | K21: 242.99 | L21: 25 | M21: 52.41 | N21: 0 | O21: 0 | P21: 0.47 | Q21: 5
A22: 08/04/2023 03:30 | B22: 12.76 | C22: 68.8 | D22: 47.05 | E22: 7.43 | F22: 4.25 | G22: 32.61 | H22: 9.97 | I22: 3.39 | J22: 0.46 | K22: 245.75 | L22: 24.78 | M22: 53.88 | N22: 0 | O22: 0 | P22: 0.47 | Q22: 5
A23: 08/04/2023 03:45 | B23: 12.76 | C23: 69.2 | D23: 47.26 | E23: 7.45 | F23: 4.41 | G23: 32.19 | H23: 12.61 | I23: 3.37 | J23: 0.3 | K23: 229.76 | L23: 24.86 | M23: 54.22 | N23: 0 | O23: 0 | P23: 0.47 | Q23: 5
A24: 08/04/2023 04:00 | B24: 12.64 | C24: 69.2 | D24: 47.16 | E24: 7.11 | F24: 4.3 | G24: 32.19 | H24: 12.61 | I24: 3.35 | J24: 0.38 | K24: 242.07 | L24: 24.54 | M24: 55.16 | N24: 0 | O24: 0 | P24: 0.47 | Q24: 5
... A57: 08/04/2023 12:15 | B57: 15.79 | C57: 64.73 | D57: 47.36 | E57: 8.84 | F57: 8.16 | G57: 56.82 | H57: 21.62 | I57: 6.68 | J57: 1.32 | K57: 334.42 | L57: 30.32 | M57: 35.95 | N57: 779.5 | O57: 0 | P57: 0.71 | Q57: 5
A58: 08/04/2023 12:30 | B58: Calib. | C58: Calib. | D58: Calib. | E58: Calib. | F58: Calib. | G58: Calib. | H58: Calib. | I58: 6.54 | J58: 1.16 | K58: 3.19 | L58: 30.59 | M58: 35.65 | N58: 558.3 | O58: 0 | P58: 0.62 | Q58: 5
A59: 08/04/2023 12:45 | B59: Calib. | C59: Calib. | D59: Calib. | E59: Calib. | F59: 21.22 | G59: Calib. | H59: Calib. | I59: 6.31 | J59: 1.17 | K59: 1.4 | L59: 30.7 | M59: 35.38 | N59: 474.8 | O59: 0 | P59: 0.65 | Q59: 5
A60: 08/04/2023 13:00 | B60: Calib. | C60: Calib. | D60: Calib. | E60: Calib. | F60: 22.62 | G60: Calib. | H60: Calib. | I60: 7.48 | J60: 1.33 | K60: 1.57 | L60: 30.39 | M60: 35.15 | N60: 440.8 | O60: 0 | P60: 0.63 | Q60: 5
A61: 08/04/2023 13:15 | B61: 12.96 | C61: 43.35 | D61: 34.4 | E61: Calib. | F61: 22.76 | G61: Calib. | H61: Calib. | I61: 10.89 | J61: 1.18 | K61: 318.6 | L61: 31.01 | M61: 34.87 | N61: 751.1 | O61: 0 | P61: 0.61 | Q61: Maint.
A62: 08/04/2023 13:30 | B62: 15.68 | C62: 40.11 | D62: 34.88 | E62: Calib. | F62: 24.82 | G62: Calib. | H62: Calib. | I62: 14.98 | J62: 1.6 | K62: 24.1 | L62: 31.08 | M62: 34.34 | N62: 505 | O62: 0 | P62: 0.78 | Q62: Maint.
A63: 08/04/2023 13:45 | B63: 7.99 | C63: 47.97 | D63: 32.82 | E63: Calib. | F63: 20.38 | G63: 80.35 | H63: 13.83 | I63: 19.12 | J63: 1.02 | K63: 9.93 | L63: 31.33 | M63: 32.28 | N63: 631.4 | O63: 0 | P63: 0.8 | Q63: Maint.
A64: 08/04/2023 14:00 | B64: 7.48 | C64: 44.05 | D64: 30.36 | E64: Calib. | F64: 20.92 | G64: 80.35 | H64: 13.83 | I64: 24.99 | J64: 1.96 | K64: 30.76 | L64: 31.81 | M64: 30.36 | N64: 608.6 | O64: 0 | P64: 0.73 | Q64: 2.54
A65: 08/04/2023 14:15 | B65: 6.16 | C65: 47.53 | D65: 31.13 | E65: 8.21 | F65: 19.64 | G65: 80.35 | H65: 13.83 | I65: 32.59 | J65: 1.92 | K65: 33.34 | L65: 31.46 | M65: 30.35 | N65: 461.5 | O65: 0 | P65: 0.59 | Q65: 4.7
A66: 08/04/2023 14:30 | B66: 5.26 | C66: 48.44 | D66: 30.88 | E66: 9.89 | F66: 24.75 | G66: 80.35 | H66: 13.83 | I66: 41.5 | J66: 2.13 | K66: 36.4 | L66: 31.52 | M66: 30.47 | N66: 444.3 | O66: 0 | P66: 0.55 | Q66: 4.78
A67: 08/04/2023 14:45 | B67: 4.53 | C67: 50.19 | D67: 31.2 | E67: 9.17 | F67: 16.33 | G67: 75.36 | H67: 13.24 | I67: 41.02 | J67: 2.22 | K67: 33.2 | L67: 31.28 | M67: 30.39 | N67: 391.2 | O67: 0 | P67: 0.53 | Q67: 4.78
A68: 08/04/2023 15:00 | B68: 4.83 | C68: 53.97 | D68: 33.42 | E68: 8.22 | F68: 12.31 | G68: 63.06 | H68: 12.31 | I68: 32.47 | J68: 1.94 | K68: 29.06 | L68: 30.83 | M68: 31.24 | N68: 247 | O68: 0 | P68: 0.53 | Q68: 4.84
A69: 08/04/2023 15:15 | B69: 5.3 | C69: 57.09 | D69: 35.43 | E69: 7.68 | F69: 11.13 | G69: 63.06 | H69: 12.31 | I69: 27.66 | J69: 2.29 | K69: 36.2 | L69: 30.26 | M69: 31.35 | N69: 201.2 | O69: 0 | P69: 0.52 | Q69: 4.91
A70: 08/04/2023 15:30 | B70: 5.86 | C70: 59.04 | D70: 36.9 | E70: 7.93 | F70: 11.66 | G70: 63.06 | H70: 12.31 | I70: 26.09 | J70: 2.09 | K70: 36.34 | L70: 30.28 | M70: 30.88 | N70: 331.6 | O70: 0 | P70: 0.5 | Q70: 4.99
A71: 08/04/2023 15:45 | B71: 6.16 | C71: 59.8 | D71: 37.53 | E71: 9.13 | F71: 11.68 | G71: 61.9 | H71: 13.15 | I71: 24.61 | J71: 2.25 | K71: 38.64 | L71: 30.59 | M71: 29.91 | N71: 339 | O71: 0 | P71: 0.49 | Q71: 5.06
A72: 08/04/2023 16:00 | B72: 6.51 | C72: 61.23 | D72: 38.57 | E72: 9.21 | F72: 11.34 | G72: 59.03 | H72: 14.49 | I72: 22.84 | J72: 2.31 | K72: 36.79 | L72: 30.22 | M72: 30.26 | N72: 189.6 | O72: 0 | P72: 0.5 | Q72: 5.1
A73: 08/04/2023 16:15 | B73: 6.46 | C73: 60.58 | D73: 38.18 | E73: 8.62 | F73: 9.32 | G73: 59.03 | H73: 14.49 | I73: 21.54 | J73: 2.2 | K73: 36.8 | L73: 29.81 | M73: 31.62 | N73: 109.5 | O73: 0 | P73: 0.49 | Q73: 5.16
A74: 08/04/2023 16:30 | B74: 6.58 | C74: 62.59 | D74: 39.33 | E74: 8.76 | F74: 9.58 | G74: 59.03 | H74: 14.49 | I74: 20.56 | J74: 1.9 | K74: 45.95 | L74: 29.64 | M74: 32.69 | N74: 163.1 | O74: 0 | P74: 0.48 | Q74: 5.18
...

Sheet 09
A1: Station: | B1: IGKV RAIPUR
A2: Date: | B2: =$A$9 -> 09/04/2023 00:15 | C2: Power Off | G2: Pw.Off | J2: Link Fail | L2: Link F | N2: Maintenance | P2: Maint.
A3: Report Type: | B3: Mean | C3: Calibration | G3: Calib. | J3: Data Fail | L3: Data F | N3: Invalid | P3: Invalid
A4: Time Base: | B4: 15 Min | C4: Zero Referrence | G4: Z.Ref | J4: Warm Up | L4: Wm. Up
A7: Date & Time | B7: NO_IGKV | C7: NO2__IGKV | D7: NOX_IGKV | E7: SO2__IGKV | F7: O3__IGKV | G7: PM10_IGKV | H7: PM2.5_IGKV | I7: BENZ_IGKV | J7: WS_IGKV | K7: WD_IGKV | L7: TEMP_IGKV | M7: HUM_IGKV | N7: SR_IGKV | O7: RG_IGKV | P7: CO_IGKV | Q7: NH3_IGKV
B8: ug/m3 | C8: ug/m3 | D8: ug/m3 | E8: ug/m3 | F8: ug/m3 | G8: ug/m3 | H8: ug/m3 | I8: ug/m3 | J8: m/sec | K8: deg | L8: degreC | M8: % | N8: w/m2 | O8: mm | P8: mg/m3 | Q8: ug/m3
A9: 09/04/2023 00:15 | B9: 32.19 | C9: 72.36 | D9: 64.98 | E9: 8.15 | F9: 3.82 | G9: 108.91 | H9: 30.6 | I9: 10.41 | J9: 0.29 | K9: 172.66 | L9: 24.96 | M9: 57.21 | N9: 0 | O9: 0 | P9: 0.84 | Q9: 6.93
A10: 09/04/2023 00:30 | B10: 31.88 | C10: 72.09 | D10: 64.58 | E10: 8.16 | F10: 3.74 | G10: 108.91 | H10: 30.6 | I10: 10.34 | J10: 0.1 | K10: 172.27 | L10: 24.81 | M10: 57.68 | N10: 0 | O10: 0 | P10: 0.85 | Q10: 6.93
A11: 09/04/2023 00:45 | B11: 32.46 | C11: 72.04 | D11: 65.02 | E11: 8.55 | F11: 3.79 | G11: 108.42 | H11: 30.85 | I11: 10.28 | J11: 0.2 | K11: 102 | L11: 24.84 | M11: 57.1 | N11: 0 | O11: 0 | P11: 0.86 | Q11: 6.95
A12: 09/04/2023 01:00 | B12: 34.25 | C12: 72.32 | D12: 66.6 | E12: 8.51 | F12: 3.8 | G12: 107.23 | H12: 31.81 | I12: 10.2 | J12: 0.15 | K12: 236.62 | L12: 24.6 | M12: 60.48 | N12: 0 | O12: 0 | P12: 0.88 | Q12: 7.05
A13: 09/04/2023 01:15 | B13: 36.55 | C13: 72.61 | D13: 68.6 | E13: 8.16 | F13: 3.75 | G13: 107.23 | H13: 31.81 | I13: 10.13 | J13: 0.25 | K13: 37.67 | L13: 24.63 | M13: 58.46 | N13: 0 | O13: 0 | P13: 0.9 | Q13: 7.17
A14: 09/04/2023 01:30 | B14: 39.1 | C14: 73.01 | D14: 70.85 | E14: 8.36 | F14: 3.64 | G14: 107.23 | H14: 31.81 | I14: 10.14 | J14: 0.17 | K14: 15.77 | L14: 24.72 | M14: 58.89 | N14: 0 | O14: 0 | P14: 0.94 | Q14: 7.3
A15: 09/04/2023 01:45 | B15: 40.98 | C15: 73.15 | D15: 72.43 | E15: 8.55 | F15: 3.64 | G15: 109.58 | H15: 33.04 | I15: 10.15 | J15: 0.21 | K15: 16.02 | L15: 24.78 | M15: 58.7 | N15: 0 | O15: 0 | P15: 0.97 | Q15: 7.46
A16: 09/04/2023 02:00 | B16: 42.43 | C16: 73.36 | D16: 73.71 | E16: 8.45 | F16: 3.59 | G16: 115.38 | H16: 34.99 | I16: 10.13 | J16: 0.52 | K16: 60.93 | L16: 24.67 | M16: 58.56 | N16: 0 | O16: 0 | P16: 1 | Q16: 7.56
A17: 09/04/2023 02:15 | B17: 43.54 | C17: 73.5 | D17: 74.67 | E17: 7.6 | F17: 3.63 | G17: 115.38 | H17: 34.99 | I17: 10.13 | J17: 0.2 | K17: 94.47 | L17: 24.89 | M17: 57.45 | N17: 0 | O17: 0 | P17: 1.04 | Q17: 7.6
A18: 09/04/2023 02:30 | B18: 43.98 | C18: 73.65 | D18: 75.1 | E18: 9 | F18: 3.63 | G18: 115.38 | H18: 34.99 | I18: 10.18 | J18: 0.11 | K18: 221.11 | L18: 24.7 | M18: 60.08 | N18: 0 | O18: 0 | P18: 1.06 | Q18: 7.69
A19: 09/04/2023 02:45 | B19: 44.42 | C19: 71.54 | D19: 74.35 | E19: 8.91 | F19: 3.82 | G19: 119.52 | H19: 35.9 | I19: 10.3 | J19: 0.54 | K19: 16.58 | L19: 24.26 | M19: 61.36 | N19: 0 | O19: 0 | P19: 1.07 | Q19: 7.64
A20: 09/04/2023 03:00 | B20: 45.04 | C20: 69.28 | D20: 73.67 | E20: 8.95 | F20: 3.83 | G20: 129.74 | H20: 37.41 | I20: 10.38 | J20: 0.65 | K20: 30.71 | L20: 24.14 | M20: 61.22 | N20: 0 | O20: 0 | P20: 1.06 | Q20: 7.52
... A104: 09/04/2023 24:00 | B104: 17.48 | C104: 68.62 | D104: 51.22 | E104: 7.08 | F104: 4.27 | G104: 46.52 | H104: 17.41 | I104: 4.69 | J104: 0.22 | K104: 169.4 | L104: 25.42 | M104: 53.71 | N104: 0 | O104: 0 | P104: 0.63 | Q104: 5.73
A106: Min | B106: =MIN(B9:B104) -> 4.84 | C106: =MIN(C9:C104) -> 47.04 | D106: =MIN(D9:D104) -> 29.81 | E106: =MIN(E9:E104) -> 7.08 | F106: =MIN(F9:F104) -> 3.52 | G106: =MIN(G9:G104) -> 33.8 | H106: =MIN(H9:H104) -> 16.69 | I106: =MIN(I9:I104) -> 4.21 | ... Q106: =MIN(Q9:Q104) -> 4.63
A107: Max | B107: =MAX(B9:B104) -> 45.32 | C107: =MAX(C9:C104) -> 76.65 | D107: =MAX(D9:D104) -> 75.1 | E107: =MAX(E9:E104) -> 18.75 | F107: =MAX(F9:F104) -> 46.18 | G107: =MAX(G9:G104) -> 129.74 | H107: =MAX(H9:H104) -> 37.41 | I107: =MAX(I9:I104) -> 10.41 | ... Q107: =MAX(Q9:Q104) -> 7.69
