Workbook

Sheet 01
A1: Station: | B1: BHATAGAON ,RAIPUR
A2: Date: | B2: =$A$9 -> 01-02-2023 01:00 | D2: Power Off | G2: Pw.Off | L2: Link Fail | N2: Link F | P2: Maintenance | R2: Maint.
A3: Report Type: | B3: Mean | D3: Calibration | G3: Calib. | L3: Data Fail | N3: Data F | P3: Invalid | R3: Invalid
A4: Time Base: | B4: 01 Hour | D4: Zero Referrence | G4: Z.Ref | L4: Warm Up | N4: Wm. Up
A7: Date & Time | B7: NO_BHATAGAON | C7: NO2_BHATAGAON | D7: NOX_BHATAGAON | E7: SO2_BHATAGAON | F7: O3_BHATAGAON | G7: PM10_BHATAGAON | H7: PM2_5_BHATAGAON | I7: BENZ_BHATAGAON | J7: WS_BHATAGAON | K7: WD_BHATAGAON | L7: TEMP_BHATAGAON | M7: HUM BHATAGAON | N7: SR_BHATAGAON | O7: RG_BHATAGAON | P7: CO_BHATAGAON | Q7: NH3_BHATAGAON
B8: ug/m3 | C8: ug/m3 | D8: ppb | E8: ug/m3 | F8: ug/m3 | G8: mg/m3 | H8: ug/m3 | I8: ug/m3 | J8: m/sec | K8: deg | L8: degreC | M8: % | N8: w/m2 | O8: mm | P8: ug/m3 | Q8: ug/m3
A9: 01-02-2023 01:00 | B9: 11.08 | C9: 85.63 | D9: 56.55 | E9: 8.31 | F9: 8.74 | G9: 79.02 | H9: 46.65 | I9: Maint. | J9: 1.75 | K9: 14.08 | L9: 21.97 | M9: 55 | N9: 4.6 | O9: 0 | P9: 1.3 | Q9: 30.33
A10: 01-02-2023 02:00 | B10: 2.94 | C10: 77.5 | D10: 45.54 | E10: 5.93 | F10: 6.93 | G10: 49.8 | H10: 34.88 | I10: Maint. | J10: 1.49 | K10: 11.53 | L10: 21.36 | M10: 58 | N10: 4.6 | O10: 0 | P10: 0.91 | Q10: 29.21
A11: 01-02-2023 03:00 | B11: 1.59 | C11: 70.25 | D11: 40.12 | E11: 5.52 | F11: 6.48 | G11: 49.8 | H11: 22.18 | I11: Maint. | J11: 1.28 | K11: 13.12 | L11: 20.51 | M11: 61 | N11: 4.6 | O11: 0 | P11: 0.71 | Q11: 27.93
A12: 01-02-2023 04:00 | B12: 2.08 | C12: 67.21 | D12: 38.99 | E12: 5.96 | F12: 5.67 | G12: 31.75 | H12: 20.32 | I12: Maint. | J12: 1.33 | K12: 12.24 | L12: 19.62 | M12: 62 | N12: 4.4 | O12: 0 | P12: 0.58 | Q12: 26.88
A13: 01-02-2023 05:00 | B13: 2.19 | C13: 66.41 | D13: 38.74 | E13: 6.45 | F13: 5.49 | G13: 31.75 | H13: 16.17 | I13: Maint. | J13: 1.14 | K13: 12.41 | L13: 19.3 | M13: 62 | N13: 4.4 | O13: 0 | P13: 0.51 | Q13: 28.57
A14: 01-02-2023 06:00 | B14: 3.21 | C14: 70.64 | D14: 41.98 | E14: 6.52 | F14: 5.82 | G14: 29.91 | H14: 16.17 | I14: Maint. | J14: 1.11 | K14: 45.93 | L14: 19.18 | M14: 57 | N14: 4.4 | O14: 0 | P14: 0.46 | Q14: 28.49
A15: 01-02-2023 07:00 | B15: 6.34 | C15: 73.69 | D15: 46.17 | E15: 8.09 | F15: 5.56 | G15: 42.92 | H15: 13.65 | I15: Maint. | J15: 1.35 | K15: 26.56 | L15: 18.92 | M15: 56 | N15: 17.8 | O15: 0 | P15: 0.44 | Q15: 27.48
A16: 01-02-2023 08:00 | B16: 8.86 | C16: 77.72 | D16: 50.41 | E16: 6.44 | F16: 4.79 | G16: 42.92 | H16: 18.23 | I16: Maint. | J16: 0.93 | K16: 41.37 | L16: 20.34 | M16: 55 | N16: 142.8 | O16: 0 | P16: 0.55 | Q16: 26.47
A17: 01-02-2023 09:00 | B17: 9.16 | C17: 82.32 | D17: 53.19 | E17: 5.79 | F17: 4.12 | G17: 48.27 | H17: 18.23 | I17: Maint. | J17: 0.8 | K17: 65.41 | L17: 23.28 | M17: 48 | N17: 361.9 | O17: 0 | P17: 0.59 | Q17: 28.85
A18: 01-02-2023 10:00 | B18: 9.92 | C18: 86.04 | D18: 55.19 | E18: 6.05 | F18: 5.2 | G18: 48.27 | H18: 16.57 | I18: Maint. | J18: 1.44 | K18: 19.41 | L18: 28.15 | M18: 39 | N18: 485.9 | O18: 0 | P18: 0.66 | Q18: 28.98
A19: 01-02-2023 11:00 | B19: 10.55 | C19: 87.08 | D19: 56.5 | E19: 7.27 | F19: 4.98 | G19: 41.19 | H19: 16.73 | I19: Maint. | J19: 1.14 | K19: 90.75 | L19: 28.46 | M19: 38 | N19: 568.8 | O19: 0 | P19: 0.68 | Q19: 28.1
A20: 01-02-2023 12:00 | B20: 11.32 | C20: 88.54 | D20: 57.77 | E20: 9.29 | F20: 5.77 | G20: 39.65 | H20: 17.75 | I20: Maint. | J20: 1.22 | K20: 98.2 | L20: 29.43 | M20: 32 | N20: 654.4 | O20: 0 | P20: 0.69 | Q20: 30.5
... A32: 01-02-2023 24:00 | B32: 133.98 | C32: 147.76 | D32: 189.4 | E32: 8.43 | F32: 3.58 | G32: 183.92 | H32: 68.24 | I32: Maint. | J32: 0.29 | K32: 102.35 | L32: 21.09 | M32: 47 | N32: 4.4 | O32: 0 | P32: 2.91 | Q32: 44.65
A34: Min | B34: =MIN(B9:B32) -> 1.59 | C34: =MIN(C9:C32) -> 66.41 | D34: =MIN(D9:D32) -> 38.74 | E34: =MIN(E9:E32) -> 5.36 | F34: =MIN(F9:F32) -> 3.58 | G34: =MIN(G9:G32) -> 29.91 | H34: =MIN(H9:H32) -> 13.65 | I34: =MIN(I9:I32) -> 0 | ... Q34: =MIN(Q9:Q32) -> 26.47
A35: Max | B35: =MAX(B9:B32) -> 151.1 | C35: =MAX(C9:C32) -> 154.41 | D35: =MAX(D9:D32) -> 206.08 | E35: =MAX(E9:E32) -> 13.05 | F35: =MAX(F9:F32) -> 14.5 | G35: =MAX(G9:G32) -> 192.56 | H35: =MAX(H9:H32) -> 68.24 | I35: =MAX(I9:I32) -> 0 | ... Q35: =MAX(Q9:Q32) -> 46.2
A36: Avg | B36: =AVERAGE(B9:B32) -> 33.240833 | C36: =AVERAGE(C9:C32) -> 95.963333 | D36: =AVERAGE(D9:D32) -> 79.75375 | E36: =AVERAGE(E9:E32) -> 7.5125 | F36: =AVERAGE(F9:F32) -> 6.3558333 | G36: =AVERAGE(G9:G32) -> 73.115417 | H36: =AVERAGE(H9:H32) -> 28.015417 | I36: =AVERAGE(I9:I32) -> #DIV/0! | ... Q36: =AVERAGE(Q9:Q32) -> 32.029167
A37: Stdev | B37: =STDEV(B9:B32) -> 50.964093 | C37: =STDEV(C9:C32) -> 28.292896 | D37: =STDEV(D9:D32) -> 56.07079 | E37: =STDEV(E9:E32) -> 1.8473677 | F37: =STDEV(F9:F32) -> 2.8762565 | G37: =STDEV(G9:G32) -> 51.868725 | H37: =STDEV(H9:H32) -> 17.270841 | I37: =STDEV(I9:I32) -> #DIV/0! | ... Q37: =STDEV(Q9:Q32) -> 6.007124
A38: Num | B38: =COUNT(B9:B32) -> 24 | C38: =COUNT(C9:C32) -> 24 | D38: =COUNT(D9:D32) -> 24 | E38: =COUNT(E9:E32) -> 24 | F38: =COUNT(F9:F32) -> 24 | G38: =COUNT(G9:G32) -> 24 | H38: 24 | I38: =COUNT(I9:I32)+24 -> 24 | J38: =COUNT(J9:J32) -> 24 | K38: =COUNT(K9:K32) -> 24 | L38: =COUNT(L9:L32) -> 24 | M38: =COUNT(M9:M32) -> 24 | N38: =COUNT(N9:N32) -> 24 | O38: =COUNT(O9:O32) -> 24 | P38: =COUNT(P9:P32) -> 24 | Q38: =COUNT(Q9:Q32) -> 24
A39: DCR | B39: =IF(B38>=22,">90%",IF(B38<=22,"<90%")) -> >90% | C39: =IF(C38>=22,">90%",IF(C38<=22,"<90%")) -> >90% | D39: =IF(D38>=22,">90%",IF(D38<=22,"<90%")) -> >90% | E39: =IF(E38>=22,">90%",IF(E38<=22,"<90%")) -> >90% | F39: =IF(F38>=22,">90%",IF(F38<=22,"<90%")) -> >90% | G39: =IF(G38>=22,">90%",IF(G38<=22,"<90%")) -> >90% | H39: =IF(H38>=22,">90%",IF(H38<=22,"<90%")) -> >90% | I39: =IF(I38>=22,">90%",IF(I38<=22,"<90%")) -> >90% | ... Q39: =IF(Q38>=22,">90%",IF(Q38<=22,"<90%")) -> >90%
A40: Status | B40: =IF(B38>=22,"OK",IF(B38<=22,"LESS")) -> OK | C40: =IF(C38>=22,"OK",IF(C38<=22,"LESS")) -> OK | D40: =IF(D38>=22,"OK",IF(D38<=22,"LESS")) -> OK | E40: =IF(E38>=22,"OK",IF(E38<=22,"LESS")) -> OK | F40: =IF(F38>=22,"OK",IF(F38<=22,"LESS")) -> OK | G40: =IF(G38>=22,"OK",IF(G38<=22,"LESS")) -> OK | H40: =IF(H38>=22,"OK",IF(H38<=22,"LESS")) -> OK | I40: =IF(I38>=22,"OK",IF(I38<=22,"LESS")) -> OK | ... Q40: =IF(Q38>=22,"OK",IF(Q38<=22,"LESS")) -> OK
A43: Done by | B43: RAHUL
A45: Comment

Sheet 02
A1: Station: | B1: BHATAGAON RAIPUR
A2: Date: | B2: =$A$9 -> 02-02-2023 01:00 | D2: Power Off | G2: Pw.Off | L2: Link Fail | N2: Link F | P2: Maintenance | R2: Maint.
A3: Report Type: | B3: Mean | D3: Calibration | G3: Calib. | L3: Data Fail | N3: Data F | P3: Invalid | R3: Invalid
A4: Time Base: | B4: 01 Hour | D4: Zero Referrence | G4: Z.Ref | L4: Warm Up | N4: Wm. Up
A7: Date & Time | B7: NO_BHATAGAON | C7: NO2_BHATAGAON | D7: NOX_BHATAGAON | E7: SO2_BHATAGAON | F7: O3_BHATAGAON | G7: PM10_BHATAGAON | H7: PM2_5_BHATAGAON | I7: BENZ_BHATAGAON | J7: WS_BHATAGAON | K7: WD_BHATAGAON | L7: TEMP_BHATAGAON | M7: HUM BHATAGAON | N7: SR_BHATAGAON | O7: RG_BHATAGAON | P7: CO_BHATAGAON | Q7: NH3_BHATAGAON
B8: ug/m3 | C8: ug/m3 | D8: ppb | E8: ug/m3 | F8: ug/m3 | G8: mg/m3 | H8: ug/m3 | I8: ug/m3 | J8: m/sec | K8: deg | L8: degreC | M8: % | N8: w/m2 | O8: mm | P8: ug/m3 | Q8: ug/m3
A9: 02-02-2023 01:00 | B9: 103.42 | C9: 133.39 | D9: 156.96 | E9: 7.86 | F9: 3.99 | G9: 142.37 | H9: 68.24 | I9: Maint. | J9: 0.48 | K9: 96.56 | L9: 20.47 | M9: 39 | N9: 4.1 | O9: 0 | P9: 2.62 | Q9: 41.45
A10: 02-02-2023 02:00 | B10: 84.23 | C10: 120.73 | D10: 134.58 | E10: 6.96 | F10: 4.32 | G10: 142.37 | H10: 58.37 | I10: Maint. | J10: 0.57 | K10: 69.39 | L10: 19.64 | M10: 35 | N10: 4.3 | O10: 0 | P10: 2.19 | Q10: 38.85
A11: 02-02-2023 03:00 | B11: 66.21 | C11: 107.9 | D11: 113.06 | E11: 8.08 | F11: 3.76 | G11: 87.04 | H11: 49.99 | I11: Maint. | J11: 1.17 | K11: 21.84 | L11: 18.73 | M11: 40 | N11: 4.2 | O11: 0 | P11: 1.88 | Q11: 38.09
A12: 02-02-2023 04:00 | B12: 43.67 | C12: 96.91 | D12: 88.92 | E12: 15.74 | F12: 3.8 | G12: 102.69 | H12: 41.31 | I12: Maint. | J12: 1.12 | K12: 28.2 | L12: 18.19 | M12: 42 | N12: 4.6 | O12: 0 | P12: 1.54 | Q12: 33.48
A13: 02-02-2023 05:00 | B13: 37.53 | C13: 93.82 | D13: 82.28 | E13: 9.82 | F13: 3.71 | G13: 135.74 | H13: 47.03 | I13: Maint. | J13: 0.38 | K13: 92.52 | L13: 16.87 | M13: 44 | N13: 4.5 | O13: 0 | P13: 1.34 | Q13: 29.7
A14: 02-02-2023 06:00 | B14: 37.41 | C14: 90.64 | D14: 79.87 | E14: 9.85 | F14: 3.63 | G14: 135.74 | H14: 53.78 | I14: Maint. | J14: 0.76 | K14: 351.72 | L14: 15.76 | M14: 54 | N14: 4.4 | O14: 0 | P14: 1.26 | Q14: 30.82
A15: 02-02-2023 07:00 | B15: 43.33 | C15: 91.95 | D15: 85.91 | E15: 9.74 | F15: 3.65 | G15: 141.75 | H15: 53.78 | I15: Maint. | J15: 0.5 | K15: 69.98 | L15: 14.88 | M15: 52 | N15: 19.1 | O15: 0 | P15: 1.28 | Q15: 31.04
A16: 02-02-2023 08:00 | B16: 45.33 | C16: 92.85 | D16: 88 | E16: 7.66 | F16: 3.67 | G16: 141.75 | H16: 52.68 | I16: Maint. | J16: 0.65 | K16: 91.56 | L16: 19.24 | M16: 51 | N16: 255.2 | O16: 0 | P16: 1.48 | Q16: 30.09
A17: 02-02-2023 09:00 | B17: 41.99 | C17: 92.07 | D17: 84.9 | E17: 9.06 | F17: 4.65 | G17: 128.3 | H17: 52.68 | I17: Maint. | J17: 0.99 | K17: 100.42 | L17: 22.62 | M17: 33 | N17: 447.4 | O17: 0 | P17: 1.43 | Q17: 28.6
A18: 02-02-2023 10:00 | B18: 31.17 | C18: 92.58 | D18: 74.93 | E18: 7.97 | F18: 4.07 | G18: 77.45 | H18: 46.78 | I18: Maint. | J18: 1.05 | K18: 38.03 | L18: 26.85 | M18: 27 | N18: 557.7 | O18: 0 | P18: 1.21 | Q18: 28.73
A19: 02-02-2023 11:00 | B19: 25.03 | C19: 96.17 | D19: 72.23 | E19: 9 | F19: 4.35 | G19: 47.3 | H19: 33.59 | I19: Maint. | J19: 1.32 | K19: 87.11 | L19: 28.37 | M19: 23 | N19: 629.4 | O19: 0 | P19: 1.06 | Q19: 28.1
A20: 02-02-2023 12:00 | B20: 21.35 | C20: 95.36 | D20: 70.16 | E20: 7.73 | F20: 5.45 | G20: 43.15 | H20: 29.4 | I20: Maint. | J20: 0.88 | K20: 101.36 | L20: 30.04 | M20: 22 | N20: 735 | O20: 0 | P20: 0.95 | Q20: 26.71
... A32: 02-02-2023 24:00 | B32: 256.28 | C32: 198.56 | D32: 315.13 | E32: 9.28 | F32: 3.66 | G32: 221.16 | H32: 78.34 | I32: Maint. | J32: 0.07 | K32: 335.78 | L32: 16.7 | M32: 68 | N32: 4.2 | O32: 0 | P32: 4.42 | Q32: 50.88
A34: Min | B34: =MIN(B9:B32) -> 7.42 | C34: =MIN(C9:C32) -> 89.8 | D34: =MIN(D9:D32) -> 55.92 | E34: =MIN(E9:E32) -> 6.59 | F34: =MIN(F9:F32) -> 3.63 | G34: =MIN(G9:G32) -> 37.47 | H34: =MIN(H9:H32) -> 18.92 | I34: =MIN(I9:I32) -> 0 | ... Q34: =MIN(Q9:Q32) -> 26.66
A35: Max | B35: =MAX(B9:B32) -> 256.28 | C35: =MAX(C9:C32) -> 198.56 | D35: =MAX(D9:D32) -> 315.13 | E35: =MAX(E9:E32) -> 15.74 | F35: =MAX(F9:F32) -> 9.06 | G35: =MAX(G9:G32) -> 221.16 | H35: =MAX(H9:H32) -> 78.34 | I35: =MAX(I9:I32) -> 0 | ... Q35: =MAX(Q9:Q32) -> 50.88
A36: Avg | B36: =AVERAGE(B9:B32) -> 63.366667 | C36: =AVERAGE(C9:C32) -> 113.1275 | D36: =AVERAGE(D9:D32) -> 113.34833 | E36: =AVERAGE(E9:E32) -> 8.7641667 | F36: =AVERAGE(F9:F32) -> 4.5125 | G36: =AVERAGE(G9:G32) -> 109.29583 | H36: =AVERAGE(H9:H32) -> 42.223333 | I36: =AVERAGE(I9:I32) -> #DIV/0! | ... Q36: =AVERAGE(Q9:Q32) -> 33.277083
A37: Stdev | B37: =STDEV(B9:B32) -> 69.000874 | C37: =STDEV(C9:C32) -> 32.713644 | D37: =STDEV(D9:D32) -> 73.143687 | E37: =STDEV(E9:E32) -> 1.867132 | F37: =STDEV(F9:F32) -> 1.4178467 | G37: =STDEV(G9:G32) -> 58.371079 | H37: =STDEV(H9:H32) -> 18.277816 | I37: =STDEV(I9:I32) -> #DIV/0! | ... Q37: =STDEV(Q9:Q32) -> 6.6351439
A38: Num | B38: =COUNT(B9:B32) -> 24 | C38: =COUNT(C9:C32) -> 24 | D38: =COUNT(D9:D32) -> 24 | E38: =COUNT(E9:E32) -> 24 | F38: 24 | G38: =COUNT(G9:G32) -> 24 | H38: =COUNT(H9:H32) -> 24 | I38: =COUNT(I9:I32)+24 -> 24 | J38: =COUNT(J9:J32) -> 24 | K38: =COUNT(K9:K32) -> 24 | L38: =COUNT(L9:L32) -> 24 | M38: =COUNT(M9:M32) -> 24 | N38: =COUNT(N9:N32) -> 24 | O38: =COUNT(O9:O32) -> 24 | P38: =COUNT(P9:P32) -> 24 | Q38: =COUNT(Q9:Q32) -> 24
A39: DCR | B39: =IF(B38>=22,">90%",IF(B38<=22,"<90%")) -> >90% | C39: =IF(C38>=22,">90%",IF(C38<=22,"<90%")) -> >90% | D39: =IF(D38>=22,">90%",IF(D38<=22,"<90%")) -> >90% | E39: =IF(E38>=22,">90%",IF(E38<=22,"<90%")) -> >90% | F39: =IF(F38>=22,">90%",IF(F38<=22,"<90%")) -> >90% | G39: =IF(G38>=22,">90%",IF(G38<=22,"<90%")) -> >90% | H39: =IF(H38>=22,">90%",IF(H38<=22,"<90%")) -> >90% | I39: =IF(I38>=22,">90%",IF(I38<=22,"<90%")) -> >90% | ... Q39: =IF(Q38>=22,">90%",IF(Q38<=22,"<90%")) -> >90%
A40: Status | B40: =IF(B38>=22,"OK",IF(B38<=22,"LESS")) -> OK | C40: =IF(C38>=22,"OK",IF(C38<=22,"LESS")) -> OK | D40: =IF(D38>=22,"OK",IF(D38<=22,"LESS")) -> OK | E40: =IF(E38>=22,"OK",IF(E38<=22,"LESS")) -> OK | F40: =IF(F38>=22,"OK",IF(F38<=22,"LESS")) -> OK | G40: =IF(G38>=22,"OK",IF(G38<=22,"LESS")) -> OK | H40: =IF(H38>=22,"OK",IF(H38<=22,"LESS")) -> OK | I40: =IF(I38>=22,"OK",IF(I38<=22,"LESS")) -> OK | ... Q40: =IF(Q38>=22,"OK",IF(Q38<=22,"LESS")) -> OK
A43: Done by | B43: RAHUL
A45: Comment

Sheet 03
A1: Station: | B1: BHATAGAON RAIPUR
A2: Date: | B2: =$A$9 -> 03-02-2023 01:00 | D2: Power Off | G2: Pw.Off | L2: Link Fail | N2: Link F | P2: Maintenance | R2: Maint.
A3: Report Type: | B3: Mean | D3: Calibration | G3: Calib. | L3: Data Fail | N3: Data F | P3: Invalid | R3: Invalid
A4: Time Base: | B4: 01 Hour | D4: Zero Referrence | G4: Z.Ref | L4: Warm Up | N4: Wm. Up
A7: Date & Time | B7: NO_BHATAGAON | C7: NO2_BHATAGAON | D7: NOX_BHATAGAON | E7: SO2_BHATAGAON | F7: O3_BHATAGAON | G7: PM10_BHATAGAON | H7: PM2_5_BHATAGAON | I7: BENZ_BHATAGAON | J7: WS_BHATAGAON | K7: WD_BHATAGAON | L7: TEMP_BHATAGAON | M7: HUM BHATAGAON | N7: SR_BHATAGAON | O7: RG_BHATAGAON | P7: CO_BHATAGAON | Q7: NH3_BHATAGAON
B8: ug/m3 | C8: ug/m3 | D8: ppb | E8: ug/m3 | F8: ug/m3 | G8: mg/m3 | H8: ug/m3 | I8: ug/m3 | J8: m/sec | K8: deg | L8: degreC | M8: % | N8: w/m2 | O8: mm | P8: ug/m3 | Q8: ug/m3
A9: 03-02-2023 01:00 | B9: 262.58 | C9: 198.8 | D9: 320.53 | E9: 9.68 | F9: 3.6 | G9: 220.5 | H9: 79.73 | I9: Maint. | J9: 0.08 | K9: 353.57 | L9: 16.44 | M9: 71 | N9: 4.4 | O9: 0 | P9: 4.85 | Q9: 50.82
A10: 03-02-2023 02:00 | B10: 249.09 | C10: 188.76 | D10: 304.34 | E10: 10.47 | F10: 3.54 | G10: 184.77 | H10: 93.02 | I10: Maint. | J10: 0.2 | K10: 260.14 | L10: 17.14 | M10: 53 | N10: 4.2 | O10: 0 | P10: 4.42 | Q10: 49.64
A11: 03-02-2023 03:00 | B11: 208.25 | C11: 167.01 | D11: 259.59 | E11: 9.75 | F11: 3.65 | G11: 217.01 | H11: 98.38 | I11: Maint. | J11: 0.46 | K11: 100.11 | L11: 16.35 | M11: 49 | N11: 4.2 | O11: 0 | P11: 4.01 | Q11: 44.81
A12: 03-02-2023 04:00 | B12: 163 | C12: 145.8 | D12: 211.59 | E12: 9 | F12: 3.8 | G12: 217.01 | H12: 98.38 | I12: Maint. | J12: 0.34 | K12: 87.43 | L12: 16.34 | M12: 49 | N12: 4.3 | O12: 0 | P12: 3.36 | Q12: 42.2
A13: 03-02-2023 05:00 | B13: 118.68 | C13: 128.63 | D13: 166.58 | E13: 8.5 | F13: 3.52 | G13: 186.16 | H13: 85.41 | I13: Maint. | J13: 0.17 | K13: 255.66 | L13: 16.09 | M13: 50 | N13: 4.2 | O13: 0 | P13: 2.69 | Q13: 37.88
A14: 03-02-2023 06:00 | B14: 86.18 | C14: 116.22 | D14: 133.66 | E14: 7.56 | F14: 3.59 | G14: 105.17 | H14: 67.04 | I14: Maint. | J14: 0.14 | K14: 309.18 | L14: 14.65 | M14: 67 | N14: 4.6 | O14: 0 | P14: 2.09 | Q14: 33.06
A15: 03-02-2023 07:00 | B15: 76.79 | C15: 109.2 | D15: 122.25 | E15: 7.62 | F15: 3.56 | G15: 88.16 | H15: 43.47 | I15: Maint. | J15: 0.17 | K15: 307.63 | L15: 14.6 | M15: 62 | N15: 19.4 | O15: 0 | P15: 1.75 | Q15: 32.53
A16: 03-02-2023 08:00 | B16: 72.59 | C16: 111.28 | D16: 119.5 | E16: 7.84 | F16: 3.54 | G16: 91.42 | H16: 44.8 | I16: Maint. | J16: 0.44 | K16: 68.83 | L16: 19.73 | M16: 57 | N16: 246.8 | O16: 0 | P16: 1.73 | Q16: 32.55
A17: 03-02-2023 09:00 | B17: 68.36 | C17: 112.4 | D17: 117.26 | E17: 7.48 | F17: 4.25 | G17: 103.96 | H17: 48.9 | I17: Maint. | J17: 0.94 | K17: 77.82 | L17: 23.75 | M17: 36 | N17: 437.2 | O17: 0 | P17: 1.7 | Q17: 31.65
A18: 03-02-2023 10:00 | B18: 47.08 | C18: 104 | D18: 95.56 | E18: 7.21 | F18: 5.81 | G18: 103.96 | H18: 48.9 | I18: Maint. | J18: 1.31 | K18: 50.4 | L18: 26.75 | M18: 29 | N18: 553.4 | O18: 0 | P18: 1.42 | Q18: 28.48
A19: 03-02-2023 11:00 | B19: 31.82 | C19: 102.56 | D19: 82.53 | E19: 6.47 | F19: 5.96 | G19: 80.09 | H19: 32.99 | I19: Maint. | J19: 1.24 | K19: 89.5 | L19: 28.96 | M19: 21 | N19: 632.1 | O19: 0 | P19: 1.23 | Q19: 27.5
A20: 03-02-2023 12:00 | B20: 4.13 | C20: 60.78 | D20: 37.27 | E20: 12.69 | F20: 50.65 | G20: 50.09 | H20: 31.05 | I20: 0.26 | J20: 1.26 | K20: 108.58 | L20: 28.89 | M20: 15 | N20: 733.7 | O20: 0 | P20: 0.5 | Q20: 11.17
A21: 03-02-2023 13:00 | B21: 3.62 | C21: 32.61 | D21: 19.66 | E21: 16.03 | F21: 48.06 | G21: 26.25 | H21: 19.06 | I21: 0.45 | J21: 1.4 | K21: 118.57 | L21: 30.54 | M21: 15 | N21: 736.3 | O21: 0 | P21: 0.27 | Q21: 6.29
A22: 03-02-2023 14:00 | B22: 5.89 | C22: 54.62 | D22: 33.15 | E22: 10.15 | F22: 7.74 | G22: 39.97 | H22: 17.97 | I22: 0.49 | J22: 1.26 | K22: 64.47 | L22: 33.74 | M22: 12 | N22: 610.5 | O22: 0 | P22: 0.4 | Q22: 13.19
A23: 03-02-2023 15:00 | B23: 5.41 | C23: 71.72 | D23: 42.25 | E23: 9.34 | F23: 7.14 | G23: 50.11 | H23: 18.27 | I23: 0.52 | J23: 1.3 | K23: 344.25 | L23: 33.64 | M23: 11 | N23: 493.9 | O23: 0 | P23: 0.54 | Q23: 17.74
A24: 03-02-2023 16:00 | B24: 7.28 | C24: 78.05 | D24: 46.92 | E24: 16.54 | F24: 11.06 | G24: 57.53 | H24: 18.27 | I24: 0.55 | J24: 1.25 | K24: 13.57 | L24: 32.44 | M24: 13 | N24: 171.1 | O24: 0 | P24: 0.62 | Q24: 18.55
A25: 03-02-2023 17:00 | B25: 15.65 | C25: 84.03 | D25: 57.73 | E25: 17.01 | F25: 10.3 | G25: 57.53 | H25: 18.39 | I25: 0.56 | J25: 1.42 | K25: 16.21 | L25: 29.92 | M25: 13 | N25: 122.9 | O25: 0 | P25: 0.75 | Q25: 19.74
A26: 03-02-2023 18:00 | B26: 17.63 | C26: 92.66 | D26: 64.08 | E26: 16.61 | F26: 8.34 | G26: 66.16 | H26: 18.39 | I26: 0.6 | J26: 0.71 | K26: 70.18 | L26: 27.14 | M26: 17 | N26: 27.1 | O26: 0 | P26: 0.94 | Q26: 24.61
A27: 03-02-2023 19:00 | B27: 43.75 | C27: 109.14 | D27: 94.13 | E27: 7.43 | F27: 3.66 | G27: 76.15 | H27: 19.27 | I27: 0.65 | J27: 0.28 | K27: 293.39 | L27: 24.51 | M27: 34 | N27: 4.9 | O27: 0 | P27: 1.43 | Q27: 26.4
A28: 03-02-2023 20:00 | B28: 90.37 | C28: 130.54 | D28: 143.32 | E28: 6.97 | F28: 3.71 | G28: 183.94 | H28: 36.59 | I28: 0.95 | J28: 0.07 | K28: 305.68 | L28: 20.4 | M28: 40 | N28: 4.3 | O28: 0 | P28: 1.93 | Q28: 29.09
A29: 03-02-2023 21:00 | B29: 138.51 | C29: 150.83 | D29: 193.13 | E29: 8.47 | F29: 3.62 | G29: 237.76 | H29: 52.4 | I29: 1.22 | J29: 0.14 | K29: 327.32 | L29: 18.92 | M29: 47 | N29: 4 | O29: 0 | P29: 2.53 | Q29: 37.15
A30: 03-02-2023 22:00 | B30: 252.7 | C30: 204.37 | D30: 314.24 | E30: 9.32 | F30: 3.64 | G30: 237.76 | H30: 68.77 | I30: 1.54 | J30: 0.14 | K30: 249.31 | L30: 18.03 | M30: 56 | N30: 4.3 | O30: 0 | P30: 3.63 | Q30: 47.68
A31: 03-02-2023 23:00 | B31: 343.77 | C31: 243.94 | D31: 408.86 | E31: 10.49 | F31: 3.79 | G31: 235.24 | H31: 87.34 | I31: 1.97 | J31: 0.08 | K31: 331.17 | L31: 17.4 | M31: 58 | N31: 4.1 | O31: 0 | P31: 4.56 | Q31: 54.72
A32: 03-02-2023 24:00 | B32: 352.68 | C32: 244.11 | D32: 415.9 | E32: 10.56 | F32: 3.6 | G32: Invalid | H32: 98.46 | I32: 2.19 | J32: 0.2 | K32: 301.36 | L32: 17.46 | M32: 63 | N32: 4.1 | O32: 0 | P32: 4.81 | Q32: 55.83
A34: Min | B34: =MIN(B9:B32) -> 3.62 | C34: =MIN(C9:C32) -> 32.61 | D34: =MIN(D9:D32) -> 19.66 | E34: =MIN(E9:E32) -> 6.47 | F34: =MIN(F9:F32) -> 3.52 | G34: =MIN(G9:G32) -> 26.25 | H34: =MIN(H9:H32) -> 17.97 | I34: =MIN(I9:I32) -> 0.26 | ... Q34: =MIN(Q9:Q32) -> 6.29
A35: Max | B35: =MAX(B9:B32) -> 352.68 | C35: =MAX(C9:C32) -> 244.11 | D35: =MAX(D9:D32) -> 415.9 | E35: =MAX(E9:E32) -> 17.01 | F35: =MAX(F9:F32) -> 50.65 | G35: =MAX(G9:G32) -> 237.76 | H35: =MAX(H9:H32) -> 98.46 | I35: =MAX(I9:I32) -> 2.19 | ... Q35: =MAX(Q9:Q32) -> 55.83
A36: Avg | B36: =AVERAGE(B9:B32) -> 111.07542 | C36: =AVERAGE(C9:C32) -> 126.7525 | D36: =AVERAGE(D9:D32) -> 158.50125 | E36: =AVERAGE(E9:E32) -> 10.132917 | F36: =AVERAGE(F9:F32) -> 8.7554167 | G36: =AVERAGE(G9:G32) -> 126.81304 | H36: =AVERAGE(H9:H32) -> 51.885417 | I36: =AVERAGE(I9:I32) -> 0.91923077 | ... Q36: =AVERAGE(Q9:Q32) -> 32.22
A37: Stdev | B37: =STDEV(B9:B32) -> 110.68801 | C37: =STDEV(C9:C32) -> 56.810471 | D37: =STDEV(D9:D32) -> 119.59979 | E37: =STDEV(E9:E32) -> 3.2630507 | F37: =STDEV(F9:F32) -> 12.711143 | G37: =STDEV(G9:G32) -> 74.857621 | H37: =STDEV(H9:H32) -> 30.083475 | I37: =STDEV(I9:I32) -> 0.62141588 | ... Q37: =STDEV(Q9:Q32) -> 13.887029
A38: Num | B38: =COUNT(B9:B32) -> 24 | C38: =COUNT(C9:C32) -> 24 | D38: =COUNT(D9:D32) -> 24 | E38: 24 | F38: 24 | G38: =COUNT(G9:G32) -> 23 | H38: =COUNT(H9:H32) -> 24 | I38: =COUNT(I9:I32)+11 -> 24 | J38: =COUNT(J9:J32) -> 24 | K38: =COUNT(K9:K32) -> 24 | L38: =COUNT(L9:L32) -> 24 | M38: =COUNT(M9:M32) -> 24 | N38: =COUNT(N9:N32) -> 24 | O38: =COUNT(O9:O32) -> 24 | P38: =COUNT(P9:P32) -> 24 | Q38: =COUNT(Q9:Q32) -> 24
A39: DCR | B39: =IF(B38>=22,">90%",IF(B38<=22,"<90%")) -> >90% | C39: =IF(C38>=22,">90%",IF(C38<=22,"<90%")) -> >90% | D39: =IF(D38>=22,">90%",IF(D38<=22,"<90%")) -> >90% | E39: =IF(E38>=22,">90%",IF(E38<=22,"<90%")) -> >90% | F39: =IF(F38>=22,">90%",IF(F38<=22,"<90%")) -> >90% | G39: =IF(G38>=22,">90%",IF(G38<=22,"<90%")) -> >90% | H39: =IF(H38>=22,">90%",IF(H38<=22,"<90%")) -> >90% | I39: =IF(I38>=22,">90%",IF(I38<=22,"<90%")) -> >90% | ... Q39: =IF(Q38>=22,">90%",IF(Q38<=22,"<90%")) -> >90%
A40: Status | B40: =IF(B38>=22,"OK",IF(B38<=22,"LESS")) -> OK | C40: =IF(C38>=22,"OK",IF(C38<=22,"LESS")) -> OK | D40: =IF(D38>=22,"OK",IF(D38<=22,"LESS")) -> OK | E40: =IF(E38>=22,"OK",IF(E38<=22,"LESS")) -> OK | F40: =IF(F38>=22,"OK",IF(F38<=22,"LESS")) -> OK | G40: =IF(G38>=22,"OK",IF(G38<=22,"LESS")) -> OK | H40: =IF(H38>=22,"OK",IF(H38<=22,"LESS")) -> OK | I40: =IF(I38>=22,"OK",IF(I38<=22,"LESS")) -> OK | ... Q40: =IF(Q38>=22,"OK",IF(Q38<=22,"LESS")) -> OK
A43: Done by | B43: RAHUL
A45: Comment

Sheet 04
A1: Station: | B1: BHATAGAON RAIPUR
A2: Date: | B2: =$A$9 -> 04-02-2023 01:00 | D2: Power Off | G2: Pw.Off | L2: Link Fail | N2: Link F | P2: Maintenance | R2: Maint.
A3: Report Type: | B3: Mean | D3: Calibration | G3: Calib. | L3: Data Fail | N3: Data F | P3: Invalid | R3: Invalid
A4: Time Base: | B4: 01 Hour | D4: Zero Referrence | G4: Z.Ref | L4: Warm Up | N4: Wm. Up
A7: Date & Time | B7: NO_BHATAGAON | C7: NO2_BHATAGAON | D7: NOX_BHATAGAON | E7: SO2_BHATAGAON | F7: O3_BHATAGAON | G7: PM10_BHATAGAON | H7: PM2_5_BHATAGAON | I7: BENZ_BHATAGAON | J7: WS_BHATAGAON | K7: WD_BHATAGAON | L7: TEMP_BHATAGAON | M7: HUM BHATAGAON | N7: SR_BHATAGAON | O7: RG_BHATAGAON | P7: CO_BHATAGAON | Q7: NH3_BHATAGAON
B8: ug/m3 | C8: ug/m3 | D8: ppb | E8: ug/m3 | F8: ug/m3 | G8: mg/m3 | H8: ug/m3 | I8: ug/m3 | J8: m/sec | K8: deg | L8: degreC | M8: % | N8: w/m2 | O8: mm | P8: ug/m3 | Q8: ug/m3
A9: 04-02-2023 01:00 | B9: 319.33 | C9: 222 | D9: 377.41 | E9: 9.51 | F9: 3.78 | G9: 237.38 | H9: 98.46 | I9: 2.23 | J9: 0.12 | K9: 343.77 | L9: 16.81 | M9: 66 | N9: 4.2 | O9: 0 | P9: 4.49 | Q9: 54.24
A10: 04-02-2023 02:00 | B10: 267.27 | C10: 192.78 | D10: 319.54 | E10: 8.77 | F10: 3.57 | G10: 237.38 | H10: 92.44 | I10: 1.99 | J10: 0.12 | K10: 307.82 | L10: 15.95 | M10: 64 | N10: 4.3 | O10: 0 | P10: 3.56 | Q10: 50.11
A11: 04-02-2023 03:00 | B11: 209.52 | C11: 166.19 | D11: 258.55 | E11: 8.45 | F11: 3.48 | G11: 236.7 | H11: 84.81 | I11: 1.71 | J11: 0.13 | K11: 348.86 | L11: 15.43 | M11: 63 | N11: 4.2 | O11: 0 | P11: 3.12 | Q11: 44.61
A12: 04-02-2023 04:00 | B12: 176.45 | C12: 149.59 | D12: 222.86 | E12: 8.03 | F12: 3.58 | G12: 161.84 | H12: 76.54 | I12: 1.54 | J12: 0.19 | K12: 334.13 | L12: 14.81 | M12: 66 | N12: 4.4 | O12: 0 | P12: 2.8 | Q12: 40.28
A13: 04-02-2023 05:00 | B13: 148.94 | C13: 134.74 | D13: 192.61 | E13: 8.78 | F13: 3.52 | G13: 216.97 | H13: 79.84 | I13: 1.43 | J13: 0.17 | K13: 346.26 | L13: 15.51 | M13: 57 | N13: 4 | O13: 0 | P13: 2.61 | Q13: 38.45
A14: 04-02-2023 06:00 | B14: 123.72 | C14: 124.61 | D14: 166.79 | E14: 8.96 | F14: 3.57 | G14: 216.97 | H14: 79.84 | I14: 1.24 | J14: 0.27 | K14: 298.74 | L14: 15.16 | M14: 75 | N14: 4.6 | O14: 0 | P14: 2.36 | Q14: 36.72
A15: 04-02-2023 07:00 | B15: 106.68 | C15: 112.22 | D15: 146.29 | E15: 7.04 | F15: 3.48 | G15: 194.16 | H15: 75.14 | I15: Maint. | J15: 0.26 | K15: 296.92 | L15: 13.59 | M15: 74 | N15: 19 | O15: 0 | P15: 2.12 | Q15: 33.3
A16: 04-02-2023 08:00 | B16: 109.42 | C16: 116.75 | D16: 150.99 | E16: 7.48 | F16: 3.63 | G16: 194.16 | H16: 70.86 | I16: Maint. | J16: 0.22 | K16: 349.45 | L16: 19.11 | M16: 71 | N16: 221.2 | O16: 0 | P16: 2.15 | Q16: 34.34
A17: 04-02-2023 09:00 | B17: 114.83 | C17: 134.43 | D17: 162.02 | E17: 8.02 | F17: 3.69 | G17: 199.2 | H17: 81.79 | I17: Maint. | J17: 0.91 | K17: 112.81 | L17: 24.56 | M17: 46 | N17: 417.8 | O17: 0 | P17: 2.23 | Q17: 35.4
A18: 04-02-2023 10:00 | B18: 101.06 | C18: 133.14 | D18: 153.33 | E18: 7.82 | F18: 3.83 | G18: 199.2 | H18: 81.79 | I18: Maint. | J18: 0.95 | K18: 112.38 | L18: 25.73 | M18: 30 | N18: 523 | O18: 0 | P18: 2.07 | Q18: 35.03
A19: 04-02-2023 11:00 | B19: 74.27 | C19: 122.51 | D19: 125.98 | E19: 7.07 | F19: 3.99 | G19: 75.78 | H19: 63.1 | I19: Maint. | J19: 1.3 | K19: 110.45 | L19: 26.82 | M19: 27 | N19: 575.9 | O19: 0 | P19: 1.78 | Q19: 33.31
A20: 04-02-2023 12:00 | B20: 55.05 | C20: 117.04 | D20: 106.51 | E20: 7.64 | F20: 3.9 | G20: 59.68 | H20: 47.8 | I20: Maint. | J20: 0.9 | K20: 355.91 | L20: 34.33 | M20: 21 | N20: 679.5 | O20: 0 | P20: 1.45 | Q20: 33.11
A21: 04-02-2023 13:00 | B21: 39.39 | C21: 117.49 | D21: 95.24 | E21: 7.06 | F21: 4.11 | G21: 59.68 | H21: 37.91 | I21: 0.07 | J21: 0.44 | K21: 346.86 | L21: 33.2 | M21: 16 | N21: 708.2 | O21: 0 | P21: 1.21 | Q21: 32.18
A22: 04-02-2023 14:00 | B22: 24.17 | C22: 114.26 | D22: 81.25 | E22: 8.47 | F22: 8.33 | G22: 52.78 | H22: 29.4 | I22: 0.74 | J22: 0.58 | K22: 341.99 | L22: 32.06 | M22: 16 | N22: 549.8 | O22: 0 | P22: 1.1 | Q22: 30.39
A23: 04-02-2023 15:00 | B23: 14.41 | C23: 104.66 | D23: 67.53 | E23: 10.07 | F23: 9.95 | G23: 62.1 | H23: 26.31 | I23: 0.69 | J23: 0.87 | K23: 357.23 | L23: 33.86 | M23: 17 | N23: 461 | O23: 0 | P23: 1.03 | Q23: 31.69
A24: 04-02-2023 16:00 | B24: 9.67 | C24: 100.99 | D24: 62.3 | E24: 5.9 | F24: 6.5 | G24: 62.1 | H24: 26.31 | I24: 0.69 | J24: 1 | K24: 358.78 | L24: 33.97 | M24: 12 | N24: 163.4 | O24: 0 | P24: 0.95 | Q24: 31.99
A25: 04-02-2023 17:00 | B25: 9.08 | C25: 95.85 | D25: 56.8 | E25: 7.85 | F25: 9.33 | G25: 33.41 | H25: 20.55 | I25: 0.63 | J25: 1.04 | K25: 349.23 | L25: 30.13 | M25: 15 | N25: 129.1 | O25: 0 | P25: 0.82 | Q25: 30.13
A26: 04-02-2023 18:00 | B26: 18.59 | C26: 99.89 | D26: 68.85 | E26: 7.92 | F26: 8.85 | G26: 35.01 | H26: 15.21 | I26: 0.61 | J26: 0.95 | K26: 357.27 | L26: 27.83 | M26: 21 | N26: 28.6 | O26: 0 | P26: 0.99 | Q26: 29.22
A27: 04-02-2023 19:00 | B27: 34.75 | C27: 111.13 | D27: 88 | E27: 7.02 | F27: 4.2 | G27: 78.7 | H27: 22.01 | I27: 0.68 | J27: 0.11 | K27: 357.05 | L27: 23.87 | M27: 33 | N27: 4.7 | O27: 0 | P27: 1.1 | Q27: 34
A28: 04-02-2023 20:00 | B28: 88.1 | C28: 139.78 | D28: 146.6 | E28: 6.99 | F28: 3.84 | G28: 156.16 | H28: 29.96 | I28: 0.89 | J28: 0.04 | K28: 355.74 | L28: 21.22 | M28: 41 | N28: 4.6 | O28: 0 | P28: 1.62 | Q28: 37.59
A29: 04-02-2023 21:00 | B29: 158.73 | C29: 170.76 | D29: 220.34 | E29: 8.37 | F29: 3.51 | G29: 212.61 | H29: 51.41 | I29: 1.25 | J29: 0.13 | K29: 338.71 | L29: 19.93 | M29: 50 | N29: 4.3 | O29: 0 | P29: 2.5 | Q29: 39.61
A30: 04-02-2023 22:00 | B30: 217.92 | C30: 193.54 | D30: 280.37 | E30: 9.43 | F30: 3.6 | G30: 212.61 | H30: 70.07 | I30: 1.57 | J30: 0.06 | K30: 278.4 | L30: 18.78 | M30: 51 | N30: 4.4 | O30: 0 | P30: 3.14 | Q30: 45.87
A31: 04-02-2023 23:00 | B31: 245.95 | C31: 203.5 | D31: 307.8 | E31: 9.96 | F31: 3.71 | G31: 213.1 | H31: 73.82 | I31: 1.78 | J31: 0.16 | K31: 325.43 | L31: 18.54 | M31: 52 | N31: 4.2 | O31: 0 | P31: 3.64 | Q31: 51.52
A32: 04-02-2023 24:00 | B32: 246.04 | C32: 201.93 | D32: 307.56 | E32: 10.22 | F32: 4.11 | G32: 213.1 | H32: 73.82 | I32: 1.89 | J32: 0.15 | K32: 352.18 | L32: 17.66 | M32: 59 | N32: 4.6 | O32: 0 | P32: 3.75 | Q32: 50.7
A34: Min | B34: =MIN(B9:B32) -> 9.08 | C34: =MIN(C9:C32) -> 95.85 | D34: =MIN(D9:D32) -> 56.8 | E34: =MIN(E9:E32) -> 5.9 | F34: =MIN(F9:F32) -> 3.48 | G34: =MIN(G9:G32) -> 33.41 | H34: =MIN(H9:H32) -> 15.21 | I34: =MIN(I9:I32) -> 0.07 | ... Q34: =MIN(Q9:Q32) -> 29.22
A35: Max | B35: =MAX(B9:B32) -> 319.33 | C35: =MAX(C9:C32) -> 222 | D35: =MAX(D9:D32) -> 377.41 | E35: =MAX(E9:E32) -> 10.22 | F35: =MAX(F9:F32) -> 9.95 | G35: =MAX(G9:G32) -> 237.38 | H35: =MAX(H9:H32) -> 98.46 | I35: =MAX(I9:I32) -> 2.23 | ... Q35: =MAX(Q9:Q32) -> 54.24
A36: Avg | B36: =AVERAGE(B9:B32) -> 121.38917 | C36: =AVERAGE(C9:C32) -> 140.82417 | D36: =AVERAGE(D9:D32) -> 173.56333 | E36: =AVERAGE(E9:E32) -> 8.20125 | F36: =AVERAGE(F9:F32) -> 4.7525 | G36: =AVERAGE(G9:G32) -> 150.86583 | H36: =AVERAGE(H9:H32) -> 58.71625 | I36: =AVERAGE(I9:I32) -> 1.2016667 | ... Q36: =AVERAGE(Q9:Q32) -> 38.074583
A37: Stdev | B37: =STDEV(B9:B32) -> 91.633599 | C37: =STDEV(C9:C32) -> 37.7469 | D37: =STDEV(D9:D32) -> 93.710102 | E37: =STDEV(E9:E32) -> 1.1153916 | F37: =STDEV(F9:F32) -> 2.0950713 | G37: =STDEV(G9:G32) -> 76.638745 | H37: =STDEV(H9:H32) -> 26.195897 | I37: =STDEV(I9:I32) -> 0.59976711 | ... Q37: =STDEV(Q9:Q32) -> 7.4876298
A38: Num | B38: =COUNT(B9:B32) -> 24 | C38: =COUNT(C9:C32) -> 24 | D38: =COUNT(D9:D32) -> 24 | E38: =COUNT(E9:E32) -> 24 | F38: =COUNT(F9:F32) -> 24 | G38: =COUNT(G9:G32) -> 24 | H38: =COUNT(H9:H32) -> 24 | I38: =COUNT(I9:I32)+6 -> 24 | J38: =COUNT(J9:J32) -> 24 | K38: =COUNT(K9:K32) -> 24 | L38: =COUNT(L9:L32) -> 24 | M38: =COUNT(M9:M32) -> 24 | N38: =COUNT(N9:N32) -> 24 | O38: =COUNT(O9:O32) -> 24 | P38: =COUNT(P9:P32) -> 24 | Q38: =COUNT(Q9:Q32) -> 24
A39: DCR | B39: =IF(B38>=22,">90%",IF(B38<=22,"<90%")) -> >90% | C39: =IF(C38>=22,">90%",IF(C38<=22,"<90%")) -> >90% | D39: =IF(D38>=22,">90%",IF(D38<=22,"<90%")) -> >90% | E39: =IF(E38>=22,">90%",IF(E38<=22,"<90%")) -> >90% | F39: =IF(F38>=22,">90%",IF(F38<=22,"<90%")) -> >90% | G39: =IF(G38>=22,">90%",IF(G38<=22,"<90%")) -> >90% | H39: =IF(H38>=22,">90%",IF(H38<=22,"<90%")) -> >90% | I39: =IF(I38>=22,">90%",IF(I38<=22,"<90%")) -> >90% | ... Q39: =IF(Q38>=22,">90%",IF(Q38<=22,"<90%")) -> >90%
A40: Status | B40: =IF(B38>=22,"OK",IF(B38<=22,"LESS")) -> OK | C40: =IF(C38>=22,"OK",IF(C38<=22,"LESS")) -> OK | D40: =IF(D38>=22,"OK",IF(D38<=22,"LESS")) -> OK | E40: =IF(E38>=22,"OK",IF(E38<=22,"LESS")) -> OK | F40: =IF(F38>=22,"OK",IF(F38<=22,"LESS")) -> OK | G40: =IF(G38>=22,"OK",IF(G38<=22,"LESS")) -> OK | H40: =IF(H38>=22,"OK",IF(H38<=22,"LESS")) -> OK | I40: =IF(I38>=22,"OK",IF(I38<=22,"LESS")) -> OK | ... Q40: =IF(Q38>=22,"OK",IF(Q38<=22,"LESS")) -> OK
A43: Done by | B43: RAHUL
A45: Comment

Sheet 05
A1: Station: | B1: BHATAGAON RAIPUR
A2: Date: | B2: =$A$9 -> 05-02-2023 01:00 | D2: Power Off | G2: Pw.Off | L2: Link Fail | N2: Link F | P2: Maintenance | R2: Maint.
A3: Report Type: | B3: Mean | D3: Calibration | G3: Calib. | L3: Data Fail | N3: Data F | P3: Invalid | R3: Invalid
A4: Time Base: | B4: 01 Hour | D4: Zero Referrence | G4: Z.Ref | L4: Warm Up | N4: Wm. Up
A7: Date & Time | B7: NO_BHATAGAON | C7: NO2_BHATAGAON | D7: NOX_BHATAGAON | E7: SO2_BHATAGAON | F7: O3_BHATAGAON | G7: PM10_BHATAGAON | H7: PM2_5_BHATAGAON | I7: BENZ_BHATAGAON | J7: WS_BHATAGAON | K7: WD_BHATAGAON | L7: TEMP_BHATAGAON | M7: HUM BHATAGAON | N7: SR_BHATAGAON | O7: RG_BHATAGAON | P7: CO_BHATAGAON | Q7: NH3_BHATAGAON
B8: ug/m3 | C8: ug/m3 | D8: ppb | E8: ug/m3 | F8: ug/m3 | G8: mg/m3 | H8: ug/m3 | I8: ug/m3 | J8: m/sec | K8: deg | L8: degreC | M8: % | N8: w/m2 | O8: mm | P8: ug/m3 | Q8: ug/m3
A9: 05-02-2023 01:00 | B9: 223.18 | C9: 186.06 | D9: 280.47 | E9: 8.42 | F9: 3.63 | G9: 164.07 | H9: 68.93 | I9: 1.86 | J9: 0.13 | K9: 350.93 | L9: 17.07 | M9: 57 | N9: 4.4 | O9: 0 | P9: 3.54 | Q9: 47.07
A10: 05-02-2023 02:00 | B10: 181.42 | C10: 162.57 | D10: 234.01 | E10: 8.14 | F10: 3.65 | G10: 115.21 | H10: 61.41 | I10: 1.69 | J10: 0.16 | K10: 342.49 | L10: 16.15 | M10: 58 | N10: 4.3 | O10: 0 | P10: 2.83 | Q10: 42.92
A11: 05-02-2023 03:00 | B11: 149.08 | C11: 144.76 | D11: 198.26 | E11: 7.71 | F11: 3.68 | G11: 113.47 | H11: 53.73 | I11: 1.49 | J11: 0.16 | K11: 349.17 | L11: 16.76 | M11: 56 | N11: 4 | O11: 0 | P11: 2.55 | Q11: 41.33
A12: 05-02-2023 04:00 | B12: 114.69 | C12: 130.37 | D12: 162.73 | E12: 7.31 | F12: 3.86 | G12: 113.47 | H12: 55.47 | I12: 1.29 | J12: 0.17 | K12: 327.24 | L12: 15.89 | M12: 63 | N12: 4.6 | O12: 0 | P12: 2.19 | Q12: 37.66
A13: 05-02-2023 05:00 | B13: 96.55 | C13: 121.64 | D13: 143.37 | E13: 6.58 | F13: 3.55 | G13: 111.93 | H13: 55.47 | I13: 1.13 | J13: 0.19 | K13: 346.12 | L13: 14.51 | M13: 65 | N13: 4.3 | O13: 0 | P13: 1.95 | Q13: 33.92
A14: 05-02-2023 06:00 | B14: 90.65 | C14: 114.1 | D14: 134.48 | E14: 6.75 | F14: 4.04 | G14: 116.85 | H14: 55.15 | I14: 1 | J14: 0.21 | K14: 276.97 | L14: 14.18 | M14: 70 | N14: 4 | O14: 0 | P14: 1.82 | Q14: 33.85
A15: 05-02-2023 07:00 | B15: 90.27 | C15: 111.63 | D15: 132.81 | E15: 6.46 | F15: 3.64 | G15: 116.85 | H15: 49.13 | I15: 0.93 | J15: 0.24 | K15: 325.07 | L15: 13.81 | M15: 78 | N15: 19.5 | O15: 0 | P15: 1.67 | Q15: 33.42
A16: 05-02-2023 08:00 | B16: 109.39 | C16: 120.51 | D16: 153.04 | E16: 6.62 | F16: 4.02 | G16: 139.01 | H16: 51.85 | I16: Maint. | J16: 0.49 | K16: 325.64 | L16: 17.59 | M16: 79 | N16: 223.8 | O16: 0 | P16: 1.77 | Q16: 33.6
A17: 05-02-2023 09:00 | B17: 100.57 | C17: 119.29 | D17: 144.61 | E17: 7.2 | F17: 3.54 | G17: 139.01 | H17: 57.34 | I17: Maint. | J17: 0.97 | K17: 172.41 | L17: 21.7 | M17: 55 | N17: 376.3 | O17: 0 | P17: 1.76 | Q17: 34.09
A18: 05-02-2023 10:00 | B18: 78.41 | C18: 126.1 | D18: 127.73 | E18: 6.92 | F18: 3.7 | G18: 126.59 | H18: 57.34 | I18: Maint. | J18: 0.6 | K18: 170.14 | L18: 28.56 | M18: 45 | N18: 502.2 | O18: 0 | P18: 1.69 | Q18: 34.08
A19: 05-02-2023 11:00 | B19: 51.72 | C19: 127.57 | D19: 110.69 | E19: 7.32 | F19: 3.86 | G19: 102.52 | H19: 55.33 | I19: Maint. | J19: 1.14 | K19: 124.41 | L19: 27.74 | M19: 26 | N19: 576.9 | O19: 0 | P19: 1.55 | Q19: 32.61
A20: 05-02-2023 12:00 | B20: 36.47 | C20: 119.55 | D20: 94.03 | E20: 6.39 | F20: 4.72 | G20: 83.5 | H20: 46.8 | I20: Maint. | J20: 1.02 | K20: 137.74 | L20: 29.4 | M20: 20 | N20: 671.8 | O20: 0 | P20: 1.37 | Q20: 31.58
A21: 05-02-2023 13:00 | B21: 26.87 | C21: 109.12 | D21: 80.58 | E21: 6.86 | F21: 4.65 | G21: 69.17 | H21: 44.85 | I21: Maint. | J21: 0.98 | K21: 150.22 | L21: 33.29 | M21: 16 | N21: 686.9 | O21: 0 | P21: 1.17 | Q21: 32.62
A22: 05-02-2023 14:00 | B22: 15.06 | C22: 106.72 | D22: 69.78 | E22: 6.8 | F22: 6.7 | G22: 41.52 | H22: 33.84 | I22: Maint. | J22: 0.71 | K22: 342.33 | L22: 33.98 | M22: 12 | N22: 601.4 | O22: 0 | P22: 1.05 | Q22: 32.19
A23: 05-02-2023 15:00 | B23: 8.5 | C23: 94.22 | D23: 56.16 | E23: 11.57 | F23: 15.39 | G23: 41.01 | H23: 27.19 | I23: Maint. | J23: 0.47 | K23: 338.74 | L23: 32.74 | M23: 13 | N23: 463.1 | O23: 0 | P23: 0.94 | Q23: 30.05
A24: 05-02-2023 16:00 | B24: 10.19 | C24: 95.43 | D24: 59.33 | E24: 17.78 | F24: 22.08 | G24: 44.33 | H24: 21.15 | I24: Maint. | J24: 0.85 | K24: 359.65 | L24: 32.79 | M24: 13 | N24: 161.5 | O24: 0 | P24: 0.9 | Q24: 31.46
A25: 05-02-2023 17:00 | B25: 8.46 | C25: 98.3 | D25: 59.51 | E25: 13.75 | F25: 10.94 | G25: 44.6 | H25: 21.15 | I25: Maint. | J25: 0.32 | K25: 331.36 | L25: 30.55 | M25: 16 | N25: 103.9 | O25: 0 | P25: 0.91 | Q25: 32.43
A26: 05-02-2023 18:00 | B26: 12.51 | C26: 110.89 | D26: 70.04 | E26: 19.61 | F26: 20.9 | G26: 44.6 | H26: 21.01 | I26: Maint. | J26: 0.17 | K26: 269.47 | L26: 28.44 | M26: 27 | N26: 30.5 | O26: 0 | P26: 0.93 | Q26: 31.58
A27: 05-02-2023 19:00 | B27: 32.91 | C27: 120.64 | D27: 91.78 | E27: 10.51 | F27: 4.19 | G27: 71.17 | H27: 29.9 | I27: Maint. | J27: 0.19 | K27: 189.64 | L27: 24.32 | M27: 39 | N27: 4.8 | O27: 0 | P27: 1.36 | Q27: 31.29
... A32: 05-02-2023 24:00 | B32: 192.51 | C32: 188.98 | D32: 257.48 | E32: 8.16 | F32: 4.36 | G32: 190.46 | H32: 68.12 | I32: Maint. | J32: 0.12 | K32: 348.06 | L32: 18.59 | M32: 60 | N32: 4.1 | O32: 0 | P32: 3.28 | Q32: 48.51
A34: Min | B34: =MIN(B9:B32) -> 8.46 | C34: =MIN(C9:C32) -> 94.22 | D34: =MIN(D9:D32) -> 56.16 | E34: =MIN(E9:E32) -> 6.39 | F34: =MIN(F9:F32) -> 3.43 | G34: =MIN(G9:G32) -> 41.01 | H34: =MIN(H9:H32) -> 21.01 | I34: =MIN(I9:I32) -> 0.93 | ... Q34: =MIN(Q9:Q32) -> 30.05
A35: Max | B35: =MAX(B9:B32) -> 223.18 | C35: =MAX(C9:C32) -> 188.98 | D35: =MAX(D9:D32) -> 280.47 | E35: =MAX(E9:E32) -> 19.61 | F35: =MAX(F9:F32) -> 22.08 | G35: =MAX(G9:G32) -> 212.69 | H35: =MAX(H9:H32) -> 68.93 | I35: =MAX(I9:I32) -> 1.86 | ... Q35: =MAX(Q9:Q32) -> 48.51
A36: Avg | B36: =AVERAGE(B9:B32) -> 87.799167 | C36: =AVERAGE(C9:C32) -> 131.27542 | D36: =AVERAGE(D9:D32) -> 141.4025 | E36: =AVERAGE(E9:E32) -> 8.7191667 | F36: =AVERAGE(F9:F32) -> 6.2391667 | G36: =AVERAGE(G9:G32) -> 117.54833 | H36: =AVERAGE(H9:H32) -> 48.73625 | I36: =AVERAGE(I9:I32) -> 1.3414286 | ... Q36: =AVERAGE(Q9:Q32) -> 36.331667
A37: Stdev | B37: =STDEV(B9:B32) -> 64.7789 | C37: =STDEV(C9:C32) -> 28.980763 | D37: =STDEV(D9:D32) -> 66.804223 | E37: =STDEV(E9:E32) -> 3.554709 | F37: =STDEV(F9:F32) -> 5.4376089 | G37: =STDEV(G9:G32) -> 57.052536 | H37: =STDEV(H9:H32) -> 15.320073 | I37: =STDEV(I9:I32) -> 0.35253504 | ... Q37: =STDEV(Q9:Q32) -> 5.5305725
A38: Num | B38: =COUNT(B9:B32) -> 24 | C38: =COUNT(C9:C32) -> 24 | D38: =COUNT(D9:D32) -> 24 | E38: =COUNT(E9:E32) -> 24 | F38: =COUNT(F9:F32) -> 24 | G38: =COUNT(G9:G32) -> 24 | H38: =COUNT(H9:H32) -> 24 | I38: =COUNT(I9:I32)+17 -> 24 | J38: =COUNT(J9:J32) -> 24 | K38: =COUNT(K9:K32) -> 24 | L38: =COUNT(L9:L32) -> 24 | M38: =COUNT(M9:M32) -> 24 | N38: =COUNT(N9:N32) -> 24 | O38: =COUNT(O9:O32) -> 24 | P38: =COUNT(P9:P32) -> 24 | Q38: =COUNT(Q9:Q32) -> 24
A39: DCR | B39: =IF(B38>=22,">90%",IF(B38<=22,"<90%")) -> >90% | C39: =IF(C38>=22,">90%",IF(C38<=22,"<90%")) -> >90% | D39: =IF(D38>=22,">90%",IF(D38<=22,"<90%")) -> >90% | E39: =IF(E38>=22,">90%",IF(E38<=22,"<90%")) -> >90% | F39: =IF(F38>=22,">90%",IF(F38<=22,"<90%")) -> >90% | G39: =IF(G38>=22,">90%",IF(G38<=22,"<90%")) -> >90% | H39: =IF(H38>=22,">90%",IF(H38<=22,"<90%")) -> >90% | I39: =IF(I38>=22,">90%",IF(I38<=22,"<90%")) -> >90% | ... Q39: =IF(Q38>=22,">90%",IF(Q38<=22,"<90%")) -> >90%
A40: Status | B40: =IF(B38>=22,"OK",IF(B38<=22,"LESS")) -> OK | C40: =IF(C38>=22,"OK",IF(C38<=22,"LESS")) -> OK | D40: =IF(D38>=22,"OK",IF(D38<=22,"LESS")) -> OK | E40: =IF(E38>=22,"OK",IF(E38<=22,"LESS")) -> OK | F40: =IF(F38>=22,"OK",IF(F38<=22,"LESS")) -> OK | G40: =IF(G38>=22,"OK",IF(G38<=22,"LESS")) -> OK | H40: =IF(H38>=22,"OK",IF(H38<=22,"LESS")) -> OK | I40: =IF(I38>=22,"OK",IF(I38<=22,"LESS")) -> OK | ... Q40: =IF(Q38>=22,"OK",IF(Q38<=22,"LESS")) -> OK
A43: Done by | B43: RAHUL
A45: Comment

Sheet 06
A1: Station: | B1: BHATAGAON RAIPUR
A2: Date: | B2: =$A$9 -> 06-02-2023 01:00 | D2: Power Off | G2: Pw.Off | L2: Link Fail | N2: Link F | P2: Maintenance | R2: Maint.
A3: Report Type: | B3: Mean | D3: Calibration | G3: Calib. | L3: Data Fail | N3: Data F | P3: Invalid | R3: Invalid
A4: Time Base: | B4: 01 Hour | D4: Zero Referrence | G4: Z.Ref | L4: Warm Up | N4: Wm. Up
A7: Date & Time | B7: NO_BHATAGAON | C7: NO2_BHATAGAON | D7: NOX_BHATAGAON | E7: SO2_BHATAGAON | F7: O3_BHATAGAON | G7: PM10_BHATAGAON | H7: PM2_5_BHATAGAON | I7: BENZ_BHATAGAON | J7: WS_BHATAGAON | K7: WD_BHATAGAON | L7: TEMP_BHATAGAON | M7: HUM BHATAGAON | N7: SR_BHATAGAON | O7: RG_BHATAGAON | P7: CO_BHATAGAON | Q7: NH3_BHATAGAON
B8: ug/m3 | C8: ug/m3 | D8: ppb | E8: ug/m3 | F8: ug/m3 | G8: mg/m3 | H8: ug/m3 | I8: ug/m3 | J8: m/sec | K8: deg | L8: degreC | M8: % | N8: w/m2 | O8: mm | P8: ug/m3 | Q8: ug/m3
A9: 06-02-2023 01:00 | B9: 171.66 | C9: 178.92 | D9: 235.21 | E9: 8.43 | F9: 3.59 | G9: 190.46 | H9: 68.12 | I9: Maint. | J9: 0.15 | K9: 335.58 | L9: 18.4 | M9: 57 | N9: 4.3 | O9: 0 | P9: 3.1 | Q9: 46.42
A10: 06-02-2023 02:00 | B10: 138.76 | C10: 161.73 | D10: 199.34 | E10: 8.12 | F10: 3.48 | G10: 109.73 | H10: 59.04 | I10: Maint. | J10: 0.15 | K10: 330.26 | L10: 17.2 | M10: 62 | N10: 4.6 | O10: 0 | P10: 2.64 | Q10: 41.63
A11: 06-02-2023 03:00 | B11: 124.56 | C11: 150.05 | D11: 181.51 | E11: 7.95 | F11: 3.54 | G11: 108.43 | H11: 54.9 | I11: Maint. | J11: 0.33 | K11: 323.91 | L11: 17.59 | M11: 66 | N11: 4.7 | O11: 0 | P11: 2.53 | Q11: 39.76
A12: 06-02-2023 04:00 | B12: 96.52 | C12: 130.16 | D12: 148.05 | E12: 7.71 | F12: 3.8 | G12: 101.49 | H12: 54.8 | I12: Maint. | J12: 0.11 | K12: 304.8 | L12: 15.82 | M12: 70 | N12: 4.4 | O12: 0 | P12: 2.16 | Q12: 37.97
A13: 06-02-2023 05:00 | B13: 71.78 | C13: 115.89 | D13: 120.33 | E13: 6.49 | F13: 3.44 | G13: 88.71 | H13: 46.51 | I13: Maint. | J13: 0.12 | K13: 338.63 | L13: 15.39 | M13: 70 | N13: 4.5 | O13: 0 | P13: 1.86 | Q13: 34.64
A14: 06-02-2023 06:00 | B14: 76.38 | C14: 116 | D14: 124.08 | E14: 6.49 | F14: 3.5 | G14: 107.33 | H14: 46.51 | I14: Maint. | J14: 0.15 | K14: 356.83 | L14: 15.41 | M14: 70 | N14: 4.4 | O14: 0 | P14: 1.84 | Q14: 32.88
A15: 06-02-2023 07:00 | B15: 118.78 | C15: 135.76 | D15: 168.98 | E15: 6.97 | F15: 3.51 | G15: 180.11 | H15: 54.36 | I15: Maint. | J15: 0.12 | K15: 297.39 | L15: 15.06 | M15: 76 | N15: 21.2 | O15: 0 | P15: 2 | Q15: 37.11
A16: 06-02-2023 08:00 | B16: 148.96 | C16: 154.01 | D16: 203.26 | E16: 7.81 | F16: 3.55 | G16: 209.21 | H16: 67.77 | I16: Maint. | J16: 0.63 | K16: 257.79 | L16: 19.08 | M16: 73 | N16: 185.2 | O16: 0 | P16: 2.1 | Q16: 40.03
A17: 06-02-2023 09:00 | B17: 130.42 | C17: 145.61 | D17: 183.76 | E17: 8.09 | F17: 3.87 | G17: 209.21 | H17: 67.77 | I17: Maint. | J17: 0.52 | K17: 203.35 | L17: 24.09 | M17: 43 | N17: 357 | O17: 0 | P17: 2.03 | Q17: 37.92
A18: 06-02-2023 10:00 | B18: 103.1 | C18: 144.65 | D18: 158.97 | E18: 7.96 | F18: 3.84 | G18: 137.11 | H18: 66.55 | I18: Maint. | J18: 0.45 | K18: 160.28 | L18: 29.95 | M18: 32 | N18: 420.6 | O18: 0 | P18: 2.02 | Q18: 37.61
A19: 06-02-2023 11:00 | B19: 75.56 | C19: 166.61 | D19: 144.05 | E19: 25.45 | F19: 53.24 | G19: 150.85 | H19: 70.75 | I19: 0.43 | J19: 0.58 | K19: 359.05 | L19: 32.14 | M19: 27 | N19: 475.4 | O19: 0 | P19: 2.81 | Q19: 37.63
A20: 06-02-2023 12:00 | B20: 2.86 | C20: 110.57 | D20: 62.13 | E20: 15.92 | F20: 45.73 | G20: 152.02 | H20: 72.47 | I20: 0.83 | J20: 0.43 | K20: 52.18 | L20: 32.73 | M20: 23 | N20: 528.6 | O20: 0 | P20: 2.41 | Q20: 13.34
A21: 06-02-2023 13:00 | B21: 4.18 | C21: 83.52 | D21: 48.25 | E21: 32.21 | F21: 48.42 | G21: 154.55 | H21: 72.47 | I21: 0.73 | J21: 0.39 | K21: 143.87 | L21: 32.72 | M21: 20 | N21: 449.4 | O21: 0 | P21: 2.22 | Q21: 15.5
A22: 06-02-2023 14:00 | B22: 3.71 | C22: 75.12 | D22: 43.12 | E22: 19.66 | F22: 18.16 | G22: 154.55 | H22: 72.15 | I22: 0.7 | J22: 0.74 | K22: 350.79 | L22: 33.65 | M22: 16 | N22: 420.2 | O22: 0 | P22: 2 | Q22: 20.74
A23: 06-02-2023 15:00 | B23: 4.09 | C23: 70.46 | D23: 40.37 | E23: 8.14 | F23: 11.34 | G23: 147.66 | H23: 69.28 | I23: 0.71 | J23: 0.93 | K23: 348.3 | L23: 34.58 | M23: 14 | N23: 399.8 | O23: 0 | P23: 1.6 | Q23: 19.99
A24: 06-02-2023 16:00 | B24: 8.61 | C24: 66.61 | D24: 41.59 | E24: 7.79 | F24: 14.71 | G24: 70.11 | H24: 55.09 | I24: Maint. | J24: 1.1 | K24: 353.59 | L24: 34.17 | M24: 15 | N24: 183.9 | O24: 0 | P24: 1.22 | Q24: 20.6
A25: 06-02-2023 17:00 | B25: 10.67 | C25: 68.28 | D25: 45.05 | E25: 11.84 | F25: 22.11 | G25: 56.09 | H25: 45.45 | I25: Maint. | J25: 0.51 | K25: 340.4 | L25: 31.35 | M25: 19 | N25: 87.3 | O25: 0 | P25: 1.12 | Q25: 24.09
A26: 06-02-2023 18:00 | B26: 12.55 | C26: 80.09 | D26: 52.56 | E26: 6.45 | F26: 6.98 | G26: 50.65 | H26: 33.58 | I26: Maint. | J26: 0.7 | K26: 286.59 | L26: 28.74 | M26: 28 | N26: 30.8 | O26: 0 | P26: 1.21 | Q26: 28.84
A27: 06-02-2023 19:00 | B27: 38.75 | C27: 91.53 | D27: 80.4 | E27: 6.24 | F27: 3.51 | G27: 118.88 | H27: 34.76 | I27: Maint. | J27: 0.22 | K27: 136.23 | L27: 24.77 | M27: 43 | N27: 5 | O27: 0 | P27: 1.47 | Q27: 30.22
A28: 06-02-2023 20:00 | B28: 62.08 | C28: 89.67 | D28: 97.28 | E28: 6.22 | F28: 3.87 | G28: 149.66 | H28: 45.15 | I28: Maint. | J28: 0.1 | K28: 351.16 | L28: 22.65 | M28: 48 | N28: 4.6 | O28: 0 | P28: 1.62 | Q28: 32.6
A29: 06-02-2023 21:00 | B29: 74.14 | C29: 86.5 | D29: 105.9 | E29: 6.18 | F29: 3.66 | G29: 167.23 | H29: 50.08 | I29: Maint. | J29: 0.22 | K29: 355.87 | L29: 22.29 | M29: 55 | N29: 4.6 | O29: 0 | P29: 2.03 | Q29: 37.56
A30: 06-02-2023 22:00 | B30: 145.19 | C30: 90.86 | D30: 165.38 | E30: 6.71 | F30: 3.49 | G30: 167.23 | H30: 67.13 | I30: Maint. | J30: 0.08 | K30: 316.85 | L30: 20.15 | M30: 55 | N30: 4.6 | O30: 0 | P30: 2.83 | Q30: 43.1
A31: 06-02-2023 23:00 | B31: 199.05 | C31: 93.4 | D31: 207.95 | E31: 7.63 | F31: 3.56 | G31: 230.38 | H31: 72.37 | I31: Maint. | J31: 0.1 | K31: 325.76 | L31: 19.64 | M31: 57 | N31: 4.5 | O31: 0 | P31: 3.07 | Q31: 44.86
A32: 06-02-2023 24:00 | B32: 217.75 | C32: 88.93 | D32: 220.93 | E32: 7.56 | F32: 3.5 | G32: 246.73 | H32: 80.09 | I32: Maint. | J32: 0.1 | K32: 352.07 | L32: 19.41 | M32: 58 | N32: 4.4 | O32: 0 | P32: 3.21 | Q32: 48.67
A34: Min | B34: =MIN(B9:B32) -> 2.86 | C34: =MIN(C9:C32) -> 66.61 | D34: =MIN(D9:D32) -> 40.37 | E34: =MIN(E9:E32) -> 6.18 | F34: =MIN(F9:F32) -> 3.44 | G34: =MIN(G9:G32) -> 50.65 | H34: =MIN(H9:H32) -> 33.58 | I34: =MIN(I9:I32) -> 0.43 | ... Q34: =MIN(Q9:Q32) -> 13.34
A35: Max | B35: =MAX(B9:B32) -> 217.75 | C35: =MAX(C9:C32) -> 178.92 | D35: =MAX(D9:D32) -> 235.21 | E35: =MAX(E9:E32) -> 32.21 | F35: =MAX(F9:F32) -> 53.24 | G35: =MAX(G9:G32) -> 246.73 | H35: =MAX(H9:H32) -> 80.09 | I35: =MAX(I9:I32) -> 0.83 | ... Q35: =MAX(Q9:Q32) -> 48.67
A36: Avg | B36: =AVERAGE(B9:B32) -> 85.004583 | C36: =AVERAGE(C9:C32) -> 112.28875 | D36: =AVERAGE(D9:D32) -> 128.26875 | E36: =AVERAGE(E9:E32) -> 10.1675 | F36: =AVERAGE(F9:F32) -> 11.6 | G36: =AVERAGE(G9:G32) -> 144.09917 | H36: =AVERAGE(H9:H32) -> 59.464583 | I36: =AVERAGE(I9:I32) -> 0.68 | ... Q36: =AVERAGE(Q9:Q32) -> 33.487917
A37: Stdev | B37: =STDEV(B9:B32) -> 65.983001 | C37: =STDEV(C9:C32) -> 34.920498 | D37: =STDEV(D9:D32) -> 65.053419 | E37: =STDEV(E9:E32) -> 6.6309316 | F37: =STDEV(F9:F32) -> 15.409793 | G37: =STDEV(G9:G32) -> 52.199225 | H37: =STDEV(H9:H32) -> 12.904372 | I37: =STDEV(I9:I32) -> 0.14899664 | ... Q37: =STDEV(Q9:Q32) -> 9.8573702
A38: Num | B38: =COUNT(B9:B32) -> 24 | C38: =COUNT(C9:C32) -> 24 | D38: =COUNT(D9:D32) -> 24 | E38: =COUNT(E9:E32) -> 24 | F38: =COUNT(F9:F32) -> 24 | G38: =COUNT(G9:G32) -> 24 | H38: =COUNT(H9:H32) -> 24 | I38: =COUNT(I9:I32)+19 -> 24 | J38: =COUNT(J9:J32) -> 24 | K38: =COUNT(K9:K32) -> 24 | L38: =COUNT(L9:L32) -> 24 | M38: =COUNT(M9:M32) -> 24 | N38: =COUNT(N9:N32) -> 24 | O38: =COUNT(O9:O32) -> 24 | P38: =COUNT(P9:P32) -> 24 | Q38: =COUNT(Q9:Q32) -> 24
A39: DCR | B39: =IF(B38>=22,">90%",IF(B38<=22,"<90%")) -> >90% | C39: =IF(C38>=22,">90%",IF(C38<=22,"<90%")) -> >90% | D39: =IF(D38>=22,">90%",IF(D38<=22,"<90%")) -> >90% | E39: =IF(E38>=22,">90%",IF(E38<=22,"<90%")) -> >90% | F39: =IF(F38>=22,">90%",IF(F38<=22,"<90%")) -> >90% | G39: =IF(G38>=22,">90%",IF(G38<=22,"<90%")) -> >90% | H39: =IF(H38>=22,">90%",IF(H38<=22,"<90%")) -> >90% | I39: =IF(I38>=22,">90%",IF(I38<=22,"<90%")) -> >90% | ... Q39: =IF(Q38>=22,">90%",IF(Q38<=22,"<90%")) -> >90%
A40: Status | B40: =IF(B38>=22,"OK",IF(B38<=22,"LESS")) -> OK | C40: =IF(C38>=22,"OK",IF(C38<=22,"LESS")) -> OK | D40: =IF(D38>=22,"OK",IF(D38<=22,"LESS")) -> OK | E40: =IF(E38>=22,"OK",IF(E38<=22,"LESS")) -> OK | F40: =IF(F38>=22,"OK",IF(F38<=22,"LESS")) -> OK | G40: =IF(G38>=22,"OK",IF(G38<=22,"LESS")) -> OK | H40: =IF(H38>=22,"OK",IF(H38<=22,"LESS")) -> OK | I40: =IF(I38>=22,"OK",IF(I38<=22,"LESS")) -> OK | ... Q40: =IF(Q38>=22,"OK",IF(Q38<=22,"LESS")) -> OK
A43: Done by | B43: RAHUL
A45: Comment

Sheet 07
A1: Station: | B1: BHATAGAON RAIPUR
A2: Date: | B2: =$A$9 -> 07-02-2023 01:00 | D2: Power Off | G2: Pw.Off | L2: Link Fail | N2: Link F | P2: Maintenance | R2: Maint.
A3: Report Type: | B3: Mean | D3: Calibration | G3: Calib. | L3: Data Fail | N3: Data F | P3: Invalid | R3: Invalid
A4: Time Base: | B4: 01 Hour | D4: Zero Referrence | G4: Z.Ref | L4: Warm Up | N4: Wm. Up
A7: Date & Time | B7: NO_BHATAGAON | C7: NO2_BHATAGAON | D7: NOX_BHATAGAON | E7: SO2_BHATAGAON | F7: O3_BHATAGAON | G7: PM10_BHATAGAON | H7: PM2_5_BHATAGAON | I7: BENZ_BHATAGAON | J7: WS_BHATAGAON | K7: WD_BHATAGAON | L7: TEMP_BHATAGAON | M7: HUM BHATAGAON | N7: SR_BHATAGAON | O7: RG_BHATAGAON | P7: CO_BHATAGAON | Q7: NH3_BHATAGAON
B8: ug/m3 | C8: ug/m3 | D8: ppb | E8: ug/m3 | F8: ug/m3 | G8: mg/m3 | H8: ug/m3 | I8: ug/m3 | J8: m/sec | K8: deg | L8: degreC | M8: % | N8: w/m2 | O8: mm | P8: ug/m3 | Q8: ug/m3
A9: 07-02-2023 01:00 | B9: 208.83 | C9: 83.63 | D9: 212.43 | E9: 7.49 | F9: 3.43 | G9: 246.73 | H9: 80.09 | I9: Maint. | J9: 0.13 | K9: 335.46 | L9: 19.08 | M9: 53 | N9: 4.5 | O9: 0 | P9: 3.11 | Q9: 49.17
A10: 07-02-2023 02:00 | B10: 153.88 | C10: 80.61 | D10: 166.7 | E10: 6.87 | F10: 3.47 | G10: 135.14 | H10: 71.55 | I10: Maint. | J10: 0.15 | K10: 357.59 | L10: 18.12 | M10: 61 | N10: 4.5 | O10: 0 | P10: 2.43 | Q10: 44.43
A11: 07-02-2023 03:00 | B11: 116.11 | C11: 79.81 | D11: 135.97 | E11: 6.51 | F11: 3.46 | G11: 121.97 | H11: 60.75 | I11: Maint. | J11: 0.14 | K11: 337.41 | L11: 17.97 | M11: 59 | N11: 4.4 | O11: 0 | P11: 2.22 | Q11: 39.62
A12: 07-02-2023 04:00 | B12: 98.38 | C12: 74.27 | D12: 118.69 | E12: 6.68 | F12: 3.49 | G12: 133.71 | H12: 59.02 | I12: Maint. | J12: 0.3 | K12: 274.12 | L12: 17.28 | M12: 66 | N12: 4.4 | O12: 0 | P12: 2.02 | Q12: 37.03
A13: 07-02-2023 05:00 | B13: 77.29 | C13: 68.88 | D13: 98.81 | E13: 6.24 | F13: 3.69 | G13: 133.71 | H13: 59.02 | I13: Maint. | J13: 0.18 | K13: 316.47 | L13: 17.06 | M13: 66 | N13: 4.5 | O13: 0 | P13: 1.76 | Q13: 36.69
A14: 07-02-2023 06:00 | B14: 59.79 | C14: 68.42 | D14: 84.44 | E14: 6.06 | F14: 3.36 | G14: 85.12 | H14: 50.45 | I14: Maint. | J14: 0.12 | K14: 343.38 | L14: 15.85 | M14: 72 | N14: 4.6 | O14: 0 | P14: 1.53 | Q14: 34.57
A15: 07-02-2023 07:00 | B15: 64.66 | C15: 68.18 | D15: 87.92 | E15: 5.96 | F15: 3.43 | G15: 89.99 | H15: 42.95 | I15: Maint. | J15: 0.15 | K15: 353.19 | L15: 16.27 | M15: 74 | N15: 20.7 | O15: 0 | P15: 1.42 | Q15: 31.93
A16: 07-02-2023 08:00 | B16: 70.39 | C16: 68.38 | D16: 92.82 | E16: 6.4 | F16: 3.49 | G16: 90.88 | H16: 42.62 | I16: Maint. | J16: 0.49 | K16: 326.83 | L16: 19.07 | M16: 74 | N16: 193 | O16: 0 | P16: 1.53 | Q16: 34.52
A17: 07-02-2023 09:00 | B17: 60.2 | C17: 70.74 | D17: 84.85 | E17: 5.74 | F17: 3.49 | G17: 97.06 | H17: 43.88 | I17: Maint. | J17: 0.45 | K17: 340.02 | L17: 23.24 | M17: 56 | N17: 346.8 | O17: 0 | P17: 1.45 | Q17: 33.88
A18: 07-02-2023 10:00 | B18: 41.01 | C18: 74.29 | D18: 71.19 | E18: 5.05 | F18: 3.58 | G18: 97.06 | H18: 43.88 | I18: Maint. | J18: 0.36 | K18: 348.98 | L18: 27.42 | M18: 42 | N18: 460.1 | O18: 0 | P18: 1.35 | Q18: 30.65
A19: 07-02-2023 11:00 | B19: 32.7 | C19: 76.83 | D19: 66.29 | E19: 6.54 | F19: 5.77 | G19: 83.22 | H19: 41.14 | I19: 0.79 | J19: 0.5 | K19: 359.08 | L19: 32.85 | M19: 31 | N19: 522.9 | O19: 0 | P19: 1.35 | Q19: 32.22
A20: 07-02-2023 12:00 | B20: 24.17 | C20: 88.73 | D20: 63.06 | E20: 5.95 | F20: 4.73 | G20: 83.22 | H20: 41.14 | I20: 0.74 | J20: 0.59 | K20: 71.53 | L20: 34.53 | M20: 24 | N20: 575 | O20: 0 | P20: 1.34 | Q20: 33.96
A21: 07-02-2023 13:00 | B21: 9.83 | C21: 89.83 | D21: 56.27 | E21: 7.81 | F21: 13.18 | G21: 72.61 | H21: 37.2 | I21: 0.71 | J21: 0.7 | K21: 357.23 | L21: 34.94 | M21: 20 | N21: 579.2 | O21: 0 | P21: 1.23 | Q21: 33.27
A22: 07-02-2023 14:00 | B22: 5.25 | C22: 85.64 | D22: 50.28 | E22: 6.79 | F22: 8.44 | G22: 72.61 | H22: 36.71 | I22: 0.66 | J22: 0.64 | K22: 355.79 | L22: 34.2 | M22: 17.42 | N22: 503.2 | O22: 0 | P22: 1.05 | Q22: 29.12
A23: 07-02-2023 15:00 | B23: 3.82 | C23: 73.07 | D23: 42.2 | E23: 6.4 | F23: 10 | G23: 55.16 | H23: 33.4 | I23: Maint. | J23: 0.52 | K23: 356.07 | L23: 34.35 | M23: 17.13 | N23: 435.6 | O23: 0 | P23: 0.93 | Q23: 29.4
A24: 07-02-2023 16:00 | B24: 4 | C24: 69.89 | D24: 40.53 | E24: 6.77 | F24: 9.68 | G24: 35.54 | H24: 29.47 | I24: Maint. | J24: 0.2 | K24: 355.21 | L24: 34.29 | M24: 19.44 | N24: 170.7 | O24: 0 | P24: 0.87 | Q24: 29.76
A25: 07-02-2023 17:00 | B25: 4.04 | C25: 65.31 | D25: 38.1 | E25: 9.57 | F25: 21.24 | G25: 66.9 | H25: 27.01 | I25: Maint. | J25: 0.2 | K25: 254.19 | L25: 30.62 | M25: 22.5 | N25: 89.6 | O25: 0 | P25: 0.82 | Q25: 28.42
A26: 07-02-2023 18:00 | B26: 8.41 | C26: 69.99 | D26: 44.07 | E26: 8.71 | F26: 11.78 | G26: 66.9 | H26: 26.59 | I26: Maint. | J26: 0.13 | K26: 32.54 | L26: 29.6 | M26: 26.9 | N26: 32.7 | O26: 0 | P26: 0.88 | Q26: 27.14
A27: 07-02-2023 19:00 | B27: 13.19 | C27: 78.07 | D27: 52.47 | E27: 6.82 | F27: 5.73 | G27: 67.52 | H27: 32.47 | I27: Maint. | J27: 0.14 | K27: 322.7 | L27: 27.6 | M27: 32.44 | N27: 4.6 | O27: 0 | P27: 1.07 | Q27: 31.97
A28: 07-02-2023 20:00 | B28: 29.7 | C28: 87.73 | D28: 71.05 | E28: 6.65 | F28: 4.55 | G28: 79.41 | H28: 34.66 | I28: Maint. | J28: 0.17 | K28: 344.59 | L28: 25.29 | M28: 38.27 | N28: 4.5 | O28: 0 | P28: 1.66 | Q28: 32.49
A29: 07-02-2023 21:00 | B29: 45.6 | C29: 88.43 | D29: 82.86 | E29: 8.98 | F29: 4.26 | G29: 79.41 | H29: 40.61 | I29: Maint. | J29: 0.13 | K29: 320.59 | L29: 23.95 | M29: 46.24 | N29: 4.4 | O29: 0 | P29: 1.83 | Q29: 31.71
A30: 07-02-2023 22:00 | B30: 50.84 | C30: 86.3 | D30: 86.23 | E30: 6.68 | F30: 3.57 | G30: Data F | H30: 43.1 | I30: Maint. | J30: 0.15 | K30: 333.33 | L30: 22.51 | M30: 53.85 | N30: 4.4 | O30: 0 | P30: 1.97 | Q30: 37.67
A31: 07-02-2023 23:00 | B31: 70.32 | C31: 86.46 | D31: 102.92 | E31: 6.02 | F31: 3.55 | G31: 129.1 | H31: 44.31 | I31: Maint. | J31: 0.08 | K31: 327.93 | L31: 21.76 | M31: 55.96 | N31: 4.4 | O31: 0 | P31: 2.2 | Q31: 39.07
A32: 07-02-2023 24:00 | B32: 73.83 | C32: 87.26 | D32: 106.17 | E32: 6.27 | F32: 3.54 | G32: 150.76 | H32: 47.74 | I32: Maint. | J32: 0.09 | K32: 349.6 | L32: 20.85 | M32: 57.59 | N32: 4.6 | O32: 0 | P32: 2.21 | Q32: 39.31
A34: Min | B34: =MIN(B9:B32) -> 3.82 | C34: =MIN(C9:C32) -> 65.31 | D34: =MIN(D9:D32) -> 38.1 | E34: =MIN(E9:E32) -> 5.05 | F34: =MIN(F9:F32) -> 3.36 | G34: =MIN(G9:G32) -> 35.54 | H34: =MIN(H9:H32) -> 26.59 | I34: =MIN(I9:I32) -> 0.66 | ... Q34: =MIN(Q9:Q32) -> 27.14
A35: Max | B35: =MAX(B9:B32) -> 208.83 | C35: =MAX(C9:C32) -> 89.83 | D35: =MAX(D9:D32) -> 212.43 | E35: =MAX(E9:E32) -> 9.57 | F35: =MAX(F9:F32) -> 21.24 | G35: =MAX(G9:G32) -> 246.73 | H35: =MAX(H9:H32) -> 80.09 | I35: =MAX(I9:I32) -> 0.79 | ... Q35: =MAX(Q9:Q32) -> 49.17
A36: Avg | B36: =AVERAGE(B9:B32) -> 55.26 | C36: =AVERAGE(C9:C32) -> 77.947917 | D36: =AVERAGE(D9:D32) -> 85.68 | E36: =AVERAGE(E9:E32) -> 6.79 | F36: =AVERAGE(F9:F32) -> 6.0379167 | G36: =AVERAGE(G9:G32) -> 98.857826 | H36: =AVERAGE(H9:H32) -> 44.573333 | I36: =AVERAGE(I9:I32) -> 0.725 | ... Q36: =AVERAGE(Q9:Q32) -> 34.5
A37: Stdev | B37: =STDEV(B9:B32) -> 50.717671 | C37: =STDEV(C9:C32) -> 8.1980846 | D37: =STDEV(D9:D32) -> 41.526004 | E37: =STDEV(E9:E32) -> 1.0521448 | F37: =STDEV(F9:F32) -> 4.3769773 | G37: =STDEV(G9:G32) -> 43.515266 | H37: =STDEV(H9:H32) -> 13.363737 | I37: =STDEV(I9:I32) -> 0.054467115 | ... Q37: =STDEV(Q9:Q32) -> 5.1957265
A38: Num | B38: =COUNT(B9:B32) -> 24 | C38: =COUNT(C9:C32) -> 24 | D38: =COUNT(D9:D32) -> 24 | E38: =COUNT(E9:E32) -> 24 | F38: =COUNT(F9:F32) -> 24 | G38: =COUNT(G9:G32)+1 -> 24 | H38: =COUNT(H9:H32) -> 24 | I38: =COUNT(I9:I32)+20 -> 24 | J38: =COUNT(J9:J32) -> 24 | K38: =COUNT(K9:K32) -> 24 | L38: =COUNT(L9:L32) -> 24 | M38: =COUNT(M9:M32) -> 24 | N38: =COUNT(N9:N32) -> 24 | O38: =COUNT(O9:O32) -> 24 | P38: =COUNT(P9:P32) -> 24 | Q38: =COUNT(Q9:Q32) -> 24
A39: DCR | B39: =IF(B38>=22,">90%",IF(B38<=22,"<90%")) -> >90% | C39: =IF(C38>=22,">90%",IF(C38<=22,"<90%")) -> >90% | D39: =IF(D38>=22,">90%",IF(D38<=22,"<90%")) -> >90% | E39: =IF(E38>=22,">90%",IF(E38<=22,"<90%")) -> >90% | F39: =IF(F38>=22,">90%",IF(F38<=22,"<90%")) -> >90% | G39: =IF(G38>=22,">90%",IF(G38<=22,"<90%")) -> >90% | H39: =IF(H38>=22,">90%",IF(H38<=22,"<90%")) -> >90% | I39: =IF(I38>=22,">90%",IF(I38<=22,"<90%")) -> >90% | ... Q39: =IF(Q38>=22,">90%",IF(Q38<=22,"<90%")) -> >90%
A40: Status | B40: =IF(B38>=22,"OK",IF(B38<=22,"LESS")) -> OK | C40: =IF(C38>=22,"OK",IF(C38<=22,"LESS")) -> OK | D40: =IF(D38>=22,"OK",IF(D38<=22,"LESS")) -> OK | E40: =IF(E38>=22,"OK",IF(E38<=22,"LESS")) -> OK | F40: =IF(F38>=22,"OK",IF(F38<=22,"LESS")) -> OK | G40: =IF(G38>=22,"OK",IF(G38<=22,"LESS")) -> OK | H40: =IF(H38>=22,"OK",IF(H38<=22,"LESS")) -> OK | I40: =IF(I38>=22,"OK",IF(I38<=22,"LESS")) -> OK | ... Q40: =IF(Q38>=22,"OK",IF(Q38<=22,"LESS")) -> OK
A43: Done by | B43: RAHUL
A45: Comment

Sheet 08
A1: Station: | B1: BHATAGAON RAIPUR
A2: Date: | B2: =$A$9 -> 08-02-2023 01:00 | D2: Power Off | G2: Pw.Off | L2: Link Fail | N2: Link F | P2: Maintenance | R2: Maint.
A3: Report Type: | B3: Mean | D3: Calibration | G3: Calib. | L3: Data Fail | N3: Data F | P3: Invalid | R3: Invalid
A4: Time Base: | B4: 01 Hour | D4: Zero Referrence | G4: Z.Ref | L4: Warm Up | N4: Wm. Up
A7: Date & Time | B7: NO_BHATAGAON | C7: NO2_BHATAGAON | D7: NOX_BHATAGAON | E7: SO2_BHATAGAON | F7: O3_BHATAGAON | G7: PM10_BHATAGAON | H7: PM2_5_BHATAGAON | I7: BENZ_BHATAGAON | J7: WS_BHATAGAON | K7: WD_BHATAGAON | L7: TEMP_BHATAGAON | M7: HUM BHATAGAON | N7: SR_BHATAGAON | O7: RG_BHATAGAON | P7: CO_BHATAGAON | Q7: NH3_BHATAGAON
B8: ug/m3 | C8: ug/m3 | D8: ppb | E8: ug/m3 | F8: ug/m3 | G8: mg/m3 | H8: ug/m3 | I8: ug/m3 | J8: m/sec | K8: deg | L8: degreC | M8: % | N8: w/m2 | O8: mm | P8: ug/m3 | Q8: ug/m3
A9: 08-02-2023 01:00 | B9: 69.95 | C9: 84.4 | D9: 101.49 | E9: 6.57 | F9: 4.09 | G9: 150.76 | H9: 47.74 | I9: Maint. | J9: 0.79 | K9: 358.57 | L9: 20.44 | M9: 60.47 | N9: 4.4 | O9: 0 | P9: 2.18 | Q9: 37.52
A10: 08-02-2023 02:00 | B10: 58.91 | C10: 79.94 | D10: 90.01 | E10: 6.8 | F10: 4.14 | G10: 114.19 | H10: 45.82 | I10: Maint. | J10: 0.15 | K10: 346.27 | L10: 20.28 | M10: 58 | N10: 4.9 | O10: 0 | P10: 1.98 | Q10: 38.05
A11: 08-02-2023 03:00 | B11: 41.52 | C11: 78 | D11: 75.16 | E11: 5.3 | F11: 3.74 | G11: 75.65 | H11: 43.41 | I11: Maint. | J11: 0.62 | K11: 357.18 | L11: 19.67 | M11: 56.07 | N11: 4.7 | O11: 0 | P11: 1.76 | Q11: 36.44
A12: 08-02-2023 04:00 | B12: 25.79 | C12: 73.34 | D12: 59.97 | E12: 5.2 | F12: 4.53 | G12: 61.73 | H12: 39.49 | I12: Maint. | J12: 0.17 | K12: 341.48 | L12: 19.44 | M12: 51.28 | N12: 4.7 | O12: 0 | P12: 1.47 | Q12: 32.41
A13: 08-02-2023 05:00 | B13: 20.38 | C13: 70.11 | D13: 53.85 | E13: 6.47 | F13: 3.72 | G13: 54.1 | H13: 34.09 | I13: Maint. | J13: 0.19 | K13: 245.35 | L13: 18.71 | M13: 62.11 | N13: 4.6 | O13: 0 | P13: 1.32 | Q13: Data F
A14: 08-02-2023 06:00 | B14: 22.38 | C14: 65.44 | D14: 52.62 | E14: 5.98 | F14: 3.51 | G14: 51.54 | H14: 29.25 | I14: Maint. | J14: 0.28 | K14: 352.42 | L14: 18.09 | M14: 59.35 | N14: 4.5 | O14: 0 | P14: 1.19 | Q14: Data F
A15: 08-02-2023 07:00 | B15: 27.1 | C15: 65.41 | D15: 56.48 | E15: 6.29 | F15: 3.56 | G15: 76.58 | H15: 29.25 | I15: Maint. | J15: 0.52 | K15: 284.56 | L15: 18.52 | M15: 54.67 | N15: 20.1 | O15: 0 | P15: 1.04 | Q15: Data F
A16: 08-02-2023 08:00 | B16: 31.14 | C16: 65.11 | D16: 59.1 | E16: 7.33 | F16: 3.45 | G16: 93.8 | H16: 35.92 | I16: Maint. | J16: 0.43 | K16: 123.02 | L16: 21.89 | M16: 51.64 | N16: 180 | O16: 0 | P16: 1.08 | Q16: Data F
A17: 08-02-2023 09:00 | B17: 35.38 | C17: 65.47 | D17: 62.97 | E17: 11.97 | F17: 3.66 | G17: 131.26 | H17: 48.87 | I17: Maint. | J17: 0.74 | K17: 38.96 | L17: 28.21 | M17: 38.48 | N17: 358.6 | O17: 0 | P17: 1.26 | Q17: Data F
A18: 08-02-2023 10:00 | B18: 34.16 | C18: 69.01 | D18: 62.88 | E18: 9.76 | F18: 3.78 | G18: 131.26 | H18: 48.87 | I18: Maint. | J18: 1.58 | K18: 114.62 | L18: 28.96 | M18: 33.95 | N18: 471.7 | O18: 0 | P18: 1.27 | Q18: Data F
A19: 08-02-2023 11:00 | B19: 24.3 | C19: 68.3 | D19: 55.99 | E19: 11.1 | F19: 9.9 | G19: 89.94 | H19: 46.37 | I19: 0.58 | J19: 1.3 | K19: 123.65 | L19: 31.08 | M19: 31.08 | N19: 535.5 | O19: 0 | P19: 1.09 | Q19: Data F
A20: 08-02-2023 12:00 | B20: 11.64 | C20: 57.96 | D20: 37.17 | E20: 25.45 | F20: 20.81 | G20: Calib. | H20: Calib. | I20: 0.58 | J20: 1 | K20: 16.32 | L20: 34.66 | M20: 22.76 | N20: 564.2 | O20: 0 | P20: 0.81 | Q20: Data F
A21: 08-02-2023 13:00 | B21: 6.5 | C21: 58.52 | D21: 36.16 | E21: 6.88 | F21: 12.12 | G21: Calib. | H21: Calib. | I21: 0.56 | J21: 1.16 | K21: 359.71 | L21: 34.97 | M21: 19.46 | N21: 609.5 | O21: 0 | P21: 0.74 | Q21: Data F
A22: 08-02-2023 14:00 | B22: 4.95 | C22: 53.63 | D22: 31.96 | E22: 4.29 | F22: 9.08 | G22: 76.15 | H22: 21.43 | I22: 0.52 | J22: 1.03 | K22: 354.85 | L22: 34.98 | M22: 20.01 | N22: 554 | O22: 0 | P22: 0.64 | Q22: Data F
