Workbook

Sheet 01
A1: Station: | B1: BHATAGAON ,RAIPUR
A2: Date: | B2: =$A$9 -> 01-02-2024 01:00 | D2: Power Off | G2: Pw.Off | L2: Link Fail | N2: Link F | P2: Maintenance | R2: Maint.
A3: Report Type: | B3: Mean | D3: Calibration | G3: Calib. | L3: Data Fail | N3: Data F | P3: Invalid | R3: Invalid
A4: Time Base: | B4: 01 Hour | D4: Zero Referrence | G4: Z.Ref | L4: Warm Up | N4: Wm. Up
A7: Date & Time | B7: NO_BHATAGAON | C7: NO2_BHATAGAON | D7: NOX_BHATAGAON | E7: SO2_BHATAGAON | F7: O3_BHATAGAON | G7: PM10_BHATAGAON | H7: PM2_5_BHATAGAON | I7: BENZ_BHATAGAON | J7: WS_BHATAGAON | K7: WD_BHATAGAON | L7: TEMP_BHATAGAON | M7: HUM BHATAGAON | N7: SR_BHATAGAON | O7: RG_BHATAGAON | P7: CO_BHATAGAON | Q7: NH3_BHATAGAON
B8: ug/m3 | C8: ug/m3 | D8: ppb | E8: ug/m3 | F8: ug/m3 | G8: mg/m3 | H8: ug/m3 | I8: ug/m3 | J8: m/sec | K8: deg | L8: degreC | M8: % | N8: w/m2 | O8: mm | P8: ug/m3 | Q8: ug/m3
A9: 01-02-2024 01:00 | B9: 20.8 | C9: 61.42 | D9: 49.23 | E9: 0.3 | F9: 3.16 | G9: 101.84 | H9: 44.16 | I9: 1.56 | J9: 0.51 | K9: 305.32 | L9: 18.24 | M9: 82.79 | N9: 59.3 | O9: 0 | P9: 1.06 | Q9: 8.19
A10: 01-02-2024 02:00 | B10: 18.13 | C10: 59.97 | D10: 48.28 | E10: 0.28 | F10: 3.26 | G10: 101.84 | H10: 44.16 | I10: 1.55 | J10: 0.68 | K10: 275.33 | L10: 18.19 | M10: 78.51 | N10: 59 | O10: 0 | P10: 0.96 | Q10: 8.14
A11: 01-02-2024 03:00 | B11: 11.71 | C11: 58.38 | D11: 42.25 | E11: 0.28 | F11: 3.26 | G11: 88.97 | H11: 39.86 | I11: 1.55 | J11: 0.34 | K11: 306.2 | L11: 17.83 | M11: 81.5 | N11: 59 | O11: 0 | P11: 0.86 | Q11: 7.61
A12: 01-02-2024 04:00 | B12: 8.49 | C12: 55.3 | D12: 37.97 | E12: 0.21 | F12: 3.36 | G12: 74.36 | H12: 38.31 | I12: 1.56 | J12: 0.67 | K12: 335.14 | L12: 16.89 | M12: 89.63 | N12: 59 | O12: 0 | P12: 0.76 | Q12: 7.17
A13: 01-02-2024 05:00 | B13: 9.52 | C13: 54.5 | D13: 38.36 | E13: 0.19 | F13: 3.07 | G13: 69.53 | H13: 35.32 | I13: 1.53 | J13: 0.3 | K13: 329.68 | L13: 16.54 | M13: 91.77 | N13: 59 | O13: 0 | P13: 0.76 | Q13: 7.17
A14: 01-02-2024 06:00 | B14: 21.33 | C14: 53.57 | D14: 47.22 | E14: 0.25 | F14: 3.23 | G14: 123.09 | H14: 48.34 | I14: 1.52 | J14: 0.24 | K14: 322.75 | L14: 15.85 | M14: 96.58 | N14: 59 | O14: 0 | P14: 0.9 | Q14: 8.07
A15: 01-02-2024 07:00 | B15: 36.15 | C15: 53.32 | D15: 58.96 | E15: 0.25 | F15: 3.22 | G15: 148.13 | H15: 64.67 | I15: 1.51 | J15: 0.05 | K15: 248.72 | L15: 15.65 | M15: 98.56 | N15: 78.3 | O15: 0 | P15: 1.04 | Q15: 8.99
A16: 01-02-2024 08:00 | B16: 46.42 | C16: 53.29 | D16: 66.5 | E16: 0.29 | F16: 3.18 | G16: 179.71 | H16: 72.53 | I16: 1.54 | J16: 0.75 | K16: 251.99 | L16: 18.06 | M16: 95.81 | N16: 197.5 | O16: 0 | P16: 1.16 | Q16: 9.88
A17: 01-02-2024 09:00 | B17: 45.49 | C17: 56.1 | D17: 66.64 | E17: 0.37 | F17: 3.02 | G17: 183.19 | H17: 75.44 | I17: 1.57 | J17: 0.55 | K17: 155.04 | L17: 20.22 | M17: 77.75 | N17: 306.1 | O17: 0 | P17: 1.26 | Q17: 9.89
A18: 01-02-2024 10:00 | B18: 38.82 | C18: 62.61 | D18: 63.8 | E18: 0.35 | F18: 3.09 | G18: 183.19 | H18: 75.44 | I18: 1.55 | J18: 0.62 | K18: 346.42 | L18: 27.07 | M18: 66.32 | N18: 504.1 | O18: 0 | P18: 1.25 | Q18: 9.64
A19: 01-02-2024 11:00 | B19: 26.79 | C19: 71.53 | D19: 57.55 | E19: 0.3 | F19: 3.26 | G19: 148.47 | H19: 64.68 | I19: 1.59 | J19: 0.8 | K19: 330.94 | L19: 29.25 | M19: 42.98 | N19: 592.2 | O19: 0 | P19: 1.22 | Q19: 8.85
A20: 01-02-2024 12:00 | B20: 16.7 | C20: 74.7 | D20: 54.52 | E20: 0.29 | F20: 3.71 | G20: 122.64 | H20: 54.43 | I20: 1.55 | J20: 0.46 | K20: 339.32 | L20: 28.8 | M20: 42.64 | N20: 642.2 | O20: 0 | P20: 1.22 | Q20: 8.53
... A32: 01-02-2024 24:00 | B32: 96.25 | C32: 58.36 | D32: 110.02 | E32: 0.56 | F32: 3.06 | G32: 175.14 | H32: 57.37 | I32: 1.55 | J32: 0.2 | K32: 314.53 | L32: 18.67 | M32: 89.82 | N32: 58.3 | O32: 0 | P32: 2.07 | Q32: 13.82
A34: Min | B34: =MIN(B9:B32) -> 2.31 | C34: =MIN(C9:C32) -> 53.29 | D34: =MIN(D9:D32) -> 34.81 | E34: =MIN(E9:E32) -> 0.14 | F34: =MIN(F9:F32) -> 2.95 | G34: =MIN(G9:G32) -> 42.1 | H34: =MIN(H9:H32) -> 26.59 | I34: =MIN(I9:I32) -> 1.5 | ... Q34: =MIN(Q9:Q32) -> 6.94
A35: Max | B35: =MAX(B9:B32) -> 99.17 | C35: =MAX(C9:C32) -> 74.7 | D35: =MAX(D9:D32) -> 113.3 | E35: =MAX(E9:E32) -> 0.56 | F35: =MAX(F9:F32) -> 6.35 | G35: =MAX(G9:G32) -> 183.19 | H35: =MAX(H9:H32) -> 75.44 | I35: =MAX(I9:I32) -> 1.61 | ... Q35: =MAX(Q9:Q32) -> 13.92
A36: Avg | B36: =AVERAGE(B9:B32) -> 29.915417 | C36: =AVERAGE(C9:C32) -> 61.4925 | D36: =AVERAGE(D9:D32) -> 57.983333 | E36: =AVERAGE(E9:E32) -> 0.29833333 | F36: =AVERAGE(F9:F32) -> 3.6616667 | G36: =AVERAGE(G9:G32) -> 117.1525 | H36: =AVERAGE(H9:H32) -> 48.345833 | I36: =AVERAGE(I9:I32) -> 1.5483333 | ... Q36: =AVERAGE(Q9:Q32) -> 8.9558333
A37: Stdev | B37: =STDEV(B9:B32) -> 28.933549 | C37: =STDEV(C9:C32) -> 6.4678289 | D37: =STDEV(D9:D32) -> 22.515934 | E37: =STDEV(E9:E32) -> 0.10166726 | F37: =STDEV(F9:F32) -> 0.91929872 | G37: =STDEV(G9:G32) -> 45.182579 | H37: =STDEV(H9:H32) -> 14.542418 | I37: =STDEV(I9:I32) -> 0.027610122 | ... Q37: =STDEV(Q9:Q32) -> 2.004024
A38: Num | B38: =COUNT(B9:B32) -> 24 | C38: =COUNT(C9:C32) -> 24 | D38: =COUNT(D9:D32) -> 24 | E38: =COUNT(E9:E32) -> 24 | F38: =COUNT(F9:F32) -> 24 | G38: =COUNT(G9:G32) -> 24 | H38: =COUNT(H9:H32) -> 24 | I38: =COUNT(I9:I32) -> 24 | ... M38: =COUNT(M9:M32) -> 24 | N38: =COUNT(N9:N32)+12 -> 36 | O38: =COUNT(O9:O32) -> 24 | P38: =COUNT(P9:P32) -> 24 | Q38: =COUNT(Q9:Q32) -> 24
A39: DCR | B39: =IF(B38>=22,">90%",IF(B38<=22,"<90%")) -> >90% | C39: =IF(C38>=22,">90%",IF(C38<=22,"<90%")) -> >90% | D39: =IF(D38>=22,">90%",IF(D38<=22,"<90%")) -> >90% | E39: =IF(E38>=22,">90%",IF(E38<=22,"<90%")) -> >90% | F39: =IF(F38>=22,">90%",IF(F38<=22,"<90%")) -> >90% | G39: =IF(G38>=22,">90%",IF(G38<=22,"<90%")) -> >90% | H39: =IF(H38>=22,">90%",IF(H38<=22,"<90%")) -> >90% | I39: =IF(I38>=22,">90%",IF(I38<=22,"<90%")) -> >90% | ... Q39: =IF(Q38>=22,">90%",IF(Q38<=22,"<90%")) -> >90%
A40: Status | B40: =IF(B38>=22,"OK",IF(B38<=22,"LESS")) -> OK | C40: =IF(C38>=22,"OK",IF(C38<=22,"LESS")) -> OK | D40: =IF(D38>=22,"OK",IF(D38<=22,"LESS")) -> OK | E40: =IF(E38>=22,"OK",IF(E38<=22,"LESS")) -> OK | F40: =IF(F38>=22,"OK",IF(F38<=22,"LESS")) -> OK | G40: =IF(G38>=22,"OK",IF(G38<=22,"LESS")) -> OK | H40: =IF(H38>=22,"OK",IF(H38<=22,"LESS")) -> OK | I40: =IF(I38>=22,"OK",IF(I38<=22,"LESS")) -> OK | ... Q40: =IF(Q38>=22,"OK",IF(Q38<=22,"LESS")) -> OK
A43: Done by | B43: RAHUL
A45: Comment

Sheet 02
A1: Station: | B1: BHATAGAON RAIPUR
A2: Date: | B2: =$A$9 -> 02-02-2024 01:00 | D2: Power Off | G2: Pw.Off | L2: Link Fail | N2: Link F | P2: Maintenance | R2: Maint.
A3: Report Type: | B3: Mean | D3: Calibration | G3: Calib. | L3: Data Fail | N3: Data F | P3: Invalid | R3: Invalid
A4: Time Base: | B4: 01 Hour | D4: Zero Referrence | G4: Z.Ref | L4: Warm Up | N4: Wm. Up
A7: Date & Time | B7: NO_BHATAGAON | C7: NO2_BHATAGAON | D7: NOX_BHATAGAON | E7: SO2_BHATAGAON | F7: O3_BHATAGAON | G7: PM10_BHATAGAON | H7: PM2_5_BHATAGAON | I7: BENZ_BHATAGAON | J7: WS_BHATAGAON | K7: WD_BHATAGAON | L7: TEMP_BHATAGAON | M7: HUM BHATAGAON | N7: SR_BHATAGAON | O7: RG_BHATAGAON | P7: CO_BHATAGAON | Q7: NH3_BHATAGAON
B8: ug/m3 | C8: ug/m3 | D8: ppb | E8: ug/m3 | F8: ug/m3 | G8: mg/m3 | H8: ug/m3 | I8: ug/m3 | J8: m/sec | K8: deg | L8: degreC | M8: % | N8: w/m2 | O8: mm | P8: ug/m3 | Q8: ug/m3
A9: 02-02-2024 01:00 | B9: 93.28 | C9: 57.43 | D9: 107.15 | E9: 0.32 | F9: 3.2 | G9: 131.77 | H9: 51.49 | I9: 1.52 | J9: 0.11 | K9: 351.82 | L9: 17.72 | M9: 95.79 | N9: 58.2 | O9: 0 | P9: 1.91 | Q9: 13.59
A10: 02-02-2024 02:00 | B10: 82.15 | C10: 55.13 | D10: 95.65 | E10: 0.29 | F10: 3.21 | G10: 118.79 | H10: 45.89 | I10: 1.57 | J10: 0.13 | K10: 350.64 | L10: 17.49 | M10: 95.58 | N10: 58.3 | O10: 0 | P10: 1.54 | Q10: 12.78
A11: 02-02-2024 03:00 | B11: 72.05 | C11: 55.25 | D11: 88.92 | E11: 0.31 | F11: 3.26 | G11: 85.22 | H11: 42.07 | I11: 1.52 | J11: 0.07 | K11: 255.22 | L11: 17.56 | M11: 92.57 | N11: 58.4 | O11: 0 | P11: 1.39 | Q11: 12.4
A12: 02-02-2024 04:00 | B12: 62.69 | C12: 54.26 | D12: 80.86 | E12: 0.29 | F12: 3.24 | G12: 78.76 | H12: 35.39 | I12: 1.57 | J12: 0.17 | K12: 354.88 | L12: 17.28 | M12: 97.87 | N12: 58.6 | O12: 0 | P12: 1.22 | Q12: 11.7
A13: 02-02-2024 05:00 | B13: 57.3 | C13: 52.72 | D13: 75.69 | E13: 0.35 | F13: 3.39 | G13: 79.53 | H13: 35.39 | I13: 1.5 | J13: 0.45 | K13: 351.94 | L13: 17.82 | M13: 93.76 | N13: 58.8 | O13: 0 | P13: 1.11 | Q13: 11.31
A14: 02-02-2024 06:00 | B14: 51.34 | C14: 50.8 | D14: 69.62 | E14: 0.28 | F14: 3.43 | G14: 89.21 | H14: 36.93 | I14: 1.58 | J14: 0.27 | K14: 112.06 | L14: 18 | M14: 86.43 | N14: 59 | O14: 0 | P14: 1.03 | Q14: 10.65
A15: 02-02-2024 07:00 | B15: 43.26 | C15: 52.53 | D15: 63.92 | E15: 0.26 | F15: 3.18 | G15: 98.06 | H15: 36.93 | I15: 1.5 | J15: 0.58 | K15: 338.03 | L15: 17.51 | M15: 93.07 | N15: 62.6 | O15: 0 | P15: 0.95 | Q15: 10.03
A16: 02-02-2024 08:00 | B16: 38.72 | C16: 52.39 | D16: 60.28 | E16: 0.24 | F16: 3.39 | G16: 98.06 | H16: 36.48 | I16: 1.51 | J16: 0.91 | K16: 345.14 | L16: 18.81 | M16: 92.69 | N16: 185 | O16: 0 | P16: 0.93 | Q16: 9.51
A17: 02-02-2024 09:00 | B17: 44.39 | C17: 56.83 | D17: 67.61 | E17: 0.32 | F17: 3.28 | G17: 130.95 | H17: 40.42 | I17: 1.56 | J17: 0.97 | K17: 347.07 | L17: 23.05 | M17: 77.9 | N17: 404.2 | O17: 0 | P17: 1.05 | Q17: 10.21
A18: 02-02-2024 10:00 | B18: 44.2 | C18: 59.94 | D18: 68.16 | E18: 0.35 | F18: 3.48 | G18: 143.62 | H18: 49.09 | I18: 1.56 | J18: 0.7 | K18: 340.82 | L18: 27.3 | M18: 66.1 | N18: 549.7 | O18: 0 | P18: 1.08 | Q18: 10.32
A19: 02-02-2024 11:00 | B19: 40.75 | C19: 66.48 | D19: 67.16 | E19: 0.32 | F19: 3.25 | G19: 143.62 | H19: 49.09 | I19: 1.58 | J19: 0.57 | K19: 344.31 | L19: 29.3 | M19: 46.76 | N19: 639.3 | O19: 0 | P19: 1.1 | Q19: 10.27
A20: 02-02-2024 12:00 | B20: 32.53 | C20: 67.29 | D20: 63.78 | E20: 0.3 | F20: 3.46 | G20: 130.36 | H20: 47.5 | I20: 1.55 | J20: 0.74 | K20: 341.34 | L20: 29.04 | M20: 51.68 | N20: 667.1 | O20: 0 | P20: 1.08 | Q20: 10.03
... A32: 02-02-2024 24:00 | B32: 35.5 | C32: 56.46 | D32: 59.99 | E32: 0.22 | F32: 3.32 | G32: 70.59 | H32: 30.18 | I32: 1.52 | J32: 0.62 | K32: 350.71 | L32: 18.34 | M32: 92.22 | N32: 61.9 | O32: 0 | P32: 1.04 | Q32: 9.8
A34: Min | B34: =MIN(B9:B32) -> 2.39 | C34: =MIN(C9:C32) -> 50.8 | D34: =MIN(D9:D32) -> 36.61 | E34: =MIN(E9:E32) -> 0.18 | F34: =MIN(F9:F32) -> 3.04 | G34: =MIN(G9:G32) -> 70.11 | H34: =MIN(H9:H32) -> 30.18 | I34: =MIN(I9:I32) -> 1.5 | ... Q34: =MIN(Q9:Q32) -> 7.69
A35: Max | B35: =MAX(B9:B32) -> 93.28 | C35: =MAX(C9:C32) -> 75.76 | D35: =MAX(D9:D32) -> 107.15 | E35: =MAX(E9:E32) -> 0.41 | F35: =MAX(F9:F32) -> 4.98 | G35: =MAX(G9:G32) -> 143.62 | H35: =MAX(H9:H32) -> 51.49 | I35: =MAX(I9:I32) -> 1.62 | ... Q35: =MAX(Q9:Q32) -> 13.59
A36: Avg | B36: =AVERAGE(B9:B32) -> 36.150833 | C36: =AVERAGE(C9:C32) -> 59.514583 | D36: =AVERAGE(D9:D32) -> 61.825417 | E36: =AVERAGE(E9:E32) -> 0.27083333 | F36: =AVERAGE(F9:F32) -> 3.57625 | G36: =AVERAGE(G9:G32) -> 95.562083 | H36: =AVERAGE(H9:H32) -> 39.087083 | I36: =AVERAGE(I9:I32) -> 1.5479167 | ... Q36: =AVERAGE(Q9:Q32) -> 9.79625
A37: Stdev | B37: =STDEV(B9:B32) -> 25.845884 | C37: =STDEV(C9:C32) -> 7.0970079 | D37: =STDEV(D9:D32) -> 18.790589 | E37: =STDEV(E9:E32) -> 0.060499132 | F37: =STDEV(F9:F32) -> 0.53254771 | G37: =STDEV(G9:G32) -> 23.911092 | H37: =STDEV(H9:H32) -> 5.9181588 | I37: =STDEV(I9:I32) -> 0.032966276 | ... Q37: =STDEV(Q9:Q32) -> 1.6806257
A38: Num | B38: =COUNT(B9:B32) -> 24 | C38: =COUNT(C9:C32) -> 24 | D38: =COUNT(D9:D32) -> 24 | E38: =COUNT(E9:E32) -> 24 | F38: =COUNT(F9:F32) -> 24 | G38: =COUNT(G9:G32) -> 24 | H38: =COUNT(H9:H32) -> 24 | I38: =COUNT(I9:I32) -> 24 | ... Q38: =COUNT(Q9:Q32) -> 24
A39: DCR | B39: =IF(B38>=22,">90%",IF(B38<=22,"<90%")) -> >90% | C39: =IF(C38>=22,">90%",IF(C38<=22,"<90%")) -> >90% | D39: =IF(D38>=22,">90%",IF(D38<=22,"<90%")) -> >90% | E39: =IF(E38>=22,">90%",IF(E38<=22,"<90%")) -> >90% | F39: =IF(F38>=22,">90%",IF(F38<=22,"<90%")) -> >90% | G39: =IF(G38>=22,">90%",IF(G38<=22,"<90%")) -> >90% | H39: =IF(H38>=22,">90%",IF(H38<=22,"<90%")) -> >90% | I39: =IF(I38>=22,">90%",IF(I38<=22,"<90%")) -> >90% | ... Q39: =IF(Q38>=22,">90%",IF(Q38<=22,"<90%")) -> >90%
A40: Status | B40: =IF(B38>=22,"OK",IF(B38<=22,"LESS")) -> OK | C40: =IF(C38>=22,"OK",IF(C38<=22,"LESS")) -> OK | D40: =IF(D38>=22,"OK",IF(D38<=22,"LESS")) -> OK | E40: =IF(E38>=22,"OK",IF(E38<=22,"LESS")) -> OK | F40: =IF(F38>=22,"OK",IF(F38<=22,"LESS")) -> OK | G40: =IF(G38>=22,"OK",IF(G38<=22,"LESS")) -> OK | H40: =IF(H38>=22,"OK",IF(H38<=22,"LESS")) -> OK | I40: =IF(I38>=22,"OK",IF(I38<=22,"LESS")) -> OK | ... Q40: =IF(Q38>=22,"OK",IF(Q38<=22,"LESS")) -> OK
A43: Done by | B43: RAHUL
A45: Comment

Sheet 03
A1: Station: | B1: BHATAGAON RAIPUR
A2: Date: | B2: =$A$9 -> 03-02-2024 01:00 | D2: Power Off | G2: Pw.Off | L2: Link Fail | N2: Link F | P2: Maintenance | R2: Maint.
A3: Report Type: | B3: Mean | D3: Calibration | G3: Calib. | L3: Data Fail | N3: Data F | P3: Invalid | R3: Invalid
A4: Time Base: | B4: 01 Hour | D4: Zero Referrence | G4: Z.Ref | L4: Warm Up | N4: Wm. Up
A7: Date & Time | B7: NO_BHATAGAON | C7: NO2_BHATAGAON | D7: NOX_BHATAGAON | E7: SO2_BHATAGAON | F7: O3_BHATAGAON | G7: PM10_BHATAGAON | H7: PM2_5_BHATAGAON | I7: BENZ_BHATAGAON | J7: WS_BHATAGAON | K7: WD_BHATAGAON | L7: TEMP_BHATAGAON | M7: HUM BHATAGAON | N7: SR_BHATAGAON | O7: RG_BHATAGAON | P7: CO_BHATAGAON | Q7: NH3_BHATAGAON
B8: ug/m3 | C8: ug/m3 | D8: ppb | E8: ug/m3 | F8: ug/m3 | G8: mg/m3 | H8: ug/m3 | I8: ug/m3 | J8: m/sec | K8: deg | L8: degreC | M8: % | N8: w/m2 | O8: mm | P8: ug/m3 | Q8: ug/m3
A9: 03-02-2024 01:00 | B9: 35.17 | C9: 55.44 | D9: 58.94 | E9: 0.38 | F9: 3.18 | G9: 82.37 | H9: 34.27 | I9: 1.53 | J9: 0.12 | K9: 312.56 | L9: 17.74 | M9: 98.07 | N9: 62.2 | O9: 0 | P9: 1.03 | Q9: 9.73
A10: 03-02-2024 02:00 | B10: 38.19 | C10: 54.25 | D10: 60.18 | E10: 0.42 | F10: 3.25 | G10: 98.2 | H10: 42.31 | I10: 1.53 | J10: 0.3 | K10: 358.69 | L10: 17.61 | M10: 99.27 | N10: 62 | O10: 0 | P10: 1.03 | Q10: 9.77
A11: 03-02-2024 03:00 | B11: 33.06 | C11: 56.27 | D11: 56.93 | E11: 0.36 | F11: 3.31 | G11: 98.2 | H11: 42.31 | I11: 1.52 | J11: 0.58 | K11: 349.11 | L11: 17.78 | M11: 65.58 | N11: 62.5 | O11: 0 | P11: 0.97 | Q11: 9.52
A12: 03-02-2024 04:00 | B12: 24.76 | C12: 55.95 | D12: 51.28 | E12: 0.39 | F12: 3.07 | G12: 83.98 | H12: 41.33 | I12: 1.54 | J12: 0.26 | K12: 82.58 | L12: 16.69 | M12: 68.45 | N12: 62.6 | O12: 0 | P12: 0.87 | Q12: 8.73
A13: 03-02-2024 05:00 | B13: 24.45 | C13: 54.62 | D13: 49.62 | E13: 0.19 | F13: 3.14 | G13: 81.72 | H13: 36.95 | I13: 1.52 | J13: 0.19 | K13: 348.29 | L13: 15.83 | M13: 82.34 | N13: 62.8 | O13: 0 | P13: 0.78 | Q13: 8.21
A14: 03-02-2024 06:00 | B14: 29.83 | C14: 54.24 | D14: 54.48 | E14: 0.18 | F14: 3.24 | G14: 86.58 | H14: 34.81 | I14: 1.52 | J14: 0.13 | K14: 357.1 | L14: 15.04 | M14: 82.88 | N14: 62.5 | O14: 0 | P14: 0.76 | Q14: 8.73
A15: 03-02-2024 07:00 | B15: 46.8 | C15: 56.06 | D15: 69.11 | E15: 0.2 | F15: 3.28 | G15: 97.02 | H15: 36.96 | I15: 1.55 | J15: 0.17 | K15: 350.5 | L15: 14.26 | M15: 87.62 | N15: 85.4 | O15: 0 | P15: 0.85 | Q15: 9.73
A16: 03-02-2024 08:00 | B16: 55.69 | C16: 57.7 | D16: 77.15 | E16: 0.23 | F16: 3.25 | G16: 128.17 | H16: 45.32 | I16: 1.52 | J16: 0.64 | K16: 351.34 | L16: 19.46 | M16: 84.45 | N16: 265.6 | O16: 0 | P16: 1 | Q16: 10.77
A17: 03-02-2024 09:00 | B17: 56.71 | C17: 60.86 | D17: 78.03 | E17: 0.33 | F17: 3.3 | G17: 151.57 | H17: 52.33 | I17: 1.57 | J17: 0.51 | K17: 343.69 | L17: 23.89 | M17: 48.67 | N17: 502.6 | O17: 0 | P17: Calib. | Q17: 10.84
A18: 03-02-2024 10:00 | B18: 50.06 | C18: 63.55 | D18: 75.12 | E18: 0.33 | F18: 3.28 | G18: 151.57 | H18: 52.33 | I18: 1.57 | J18: 1.05 | K18: 114.04 | L18: 23.11 | M18: 38.72 | N18: 704.7 | O18: 0 | P18: Calib. | Q18: 10.54
A19: 03-02-2024 11:00 | B19: 34.26 | C19: 72.6 | D19: 63.18 | E19: 0.34 | F19: 4.36 | G19: 111.26 | H19: 42.3 | I19: 1.58 | J19: 1.06 | K19: 110.18 | L19: 26.06 | M19: 35.06 | N19: 792.4 | O19: 0 | P19: 0.9 | Q19: 9.48
A20: 03-02-2024 12:00 | B20: 8.35 | C20: 73.7 | D20: 48.01 | E20: 0.3 | F20: 6.08 | G20: Calib. | H20: Calib. | I20: 1.51 | J20: 0.9 | K20: 350.22 | L20: 29.33 | M20: 27.38 | N20: 839.2 | O20: 0 | P20: 0.67 | Q20: 7.88
A21: 03-02-2024 13:00 | B21: 3.8 | C21: 69.1 | D21: 41.83 | E21: 0.37 | F21: 6.07 | G21: 38.51 | H21: 38.01 | I21: 1.6 | J21: 0.61 | K21: 322.63 | L21: 30.17 | M21: 23.87 | N21: 846.9 | O21: 0 | P21: 0.53 | Q21: 7.14
A22: 03-02-2024 14:00 | B22: 4.13 | C22: 66.13 | D22: 40.28 | E22: 0.37 | F22: 4.2 | G22: 48.24 | H22: 38.87 | I22: 1.57 | J22: 0.59 | K22: 349.79 | L22: 30 | M22: 25.77 | N22: 794.6 | O22: 0 | P22: 0.49 | Q22: 7.26
A23: 03-02-2024 15:00 | B23: 5.7 | C23: 63.5 | D23: 40.07 | E23: 0.42 | F23: 4.07 | G23: 56.44 | H23: 38.87 | I23: 1.53 | J23: 1.11 | K23: 342.08 | L23: 29.2 | M23: 25.34 | N23: 596.3 | O23: 0 | P23: 0.49 | Q23: 7.49
A24: 03-02-2024 16:00 | B24: 10.54 | C24: 57.7 | D24: 40.61 | E24: 0.4 | F24: 5.19 | G24: 56.44 | H24: 37.89 | I24: 1.55 | J24: 0.82 | K24: 322.97 | L24: 28.6 | M24: 25.79 | N24: 288.4 | O24: 0 | P24: 0.48 | Q24: 7.64
A25: 03-02-2024 17:00 | B25: 6.91 | C25: 60.08 | D25: 38.94 | E25: 0.13 | F25: 4.34 | G25: 54.54 | H25: 30.6 | I25: 1.51 | J25: 1.13 | K25: 338.36 | L25: 25.7 | M25: 28.09 | N25: 117.9 | O25: 0 | P25: 0.44 | Q25: 7.42
A26: 03-02-2024 18:00 | B26: 7.8 | C26: 63.5 | D26: 41.95 | E26: 0.08 | F26: 4.01 | G26: 49.75 | H26: 21.66 | I26: 1.51 | J26: 0.57 | K26: 335.69 | L26: 24.3 | M26: 46.85 | N26: 84.7 | O26: 0 | P26: 0.49 | Q26: 7.54
A27: 03-02-2024 19:00 | B27: 19.95 | C27: 65.68 | D27: 52.89 | E27: 0.06 | F27: 3.42 | G27: 51.75 | H27: 21.27 | I27: 1.53 | J27: 0.04 | K27: 278.99 | L27: 21.5 | M27: 48.8 | N27: 59.5 | O27: 0 | P27: 0.72 | Q27: 8.13
A28: 03-02-2024 20:00 | B28: 46.31 | C28: 67.18 | D28: 74.86 | E28: 0.14 | F28: 3.23 | G28: 200.93 | H28: 27.93 | I28: 1.55 | J28: 0.08 | K28: 333.34 | L28: 19.12 | M28: 69.01 | N28: 59.2 | O28: 0 | P28: 1.04 | Q28: 10
A29: 03-02-2024 21:00 | B29: 77.79 | C29: 67.8 | D29: 100.44 | E29: 0.29 | F29: 3.28 | G29: 200.93 | H29: 31.66 | I29: 1.57 | J29: 0.2 | K29: 335.05 | L29: 18.68 | M29: 72.21 | N29: 59.5 | O29: 0 | P29: 1.54 | Q29: 12.2
A30: 03-02-2024 22:00 | B30: 143.78 | C30: 69.98 | D30: 154.57 | E30: 0.43 | F30: 3.21 | G30: 211.82 | H30: 41.88 | I30: 1.55 | J30: 0.13 | K30: 328.7 | L30: 17.55 | M30: 74.52 | N30: 59.4 | O30: 0 | P30: 2.16 | Q30: 16.07
A31: 03-02-2024 23:00 | B31: 217.62 | C31: 71.11 | D31: 214.16 | E31: 0.61 | F31: 3.12 | G31: 235.72 | H31: 55.37 | I31: 1.56 | J31: 0.13 | K31: 297.99 | L31: 17.41 | M31: 82.01 | N31: 59.8 | O31: 0 | P31: 2.76 | Q31: 21.42
A32: 03-02-2024 24:00 | B32: 232.73 | C32: 70.27 | D32: 225.47 | E32: 0.69 | F32: 3.08 | G32: 235.72 | H32: 56.54 | I32: 1.58 | J32: 0.16 | K32: 306.82 | L32: 16.77 | M32: 79.33 | N32: 60 | O32: 0 | P32: 2.92 | Q32: 23.33
A34: Min | B34: =MIN(B9:B32) -> 3.8 | C34: =MIN(C9:C32) -> 54.24 | D34: =MIN(D9:D32) -> 38.94 | E34: =MIN(E9:E32) -> 0.06 | F34: =MIN(F9:F32) -> 3.07 | G34: =MIN(G9:G32) -> 38.51 | H34: =MIN(H9:H32) -> 21.27 | I34: =MIN(I9:I32) -> 1.51 | ... Q34: =MIN(Q9:Q32) -> 7.14
A35: Max | B35: =MAX(B9:B32) -> 232.73 | C35: =MAX(C9:C32) -> 73.7 | D35: =MAX(D9:D32) -> 225.47 | E35: =MAX(E9:E32) -> 0.69 | F35: =MAX(F9:F32) -> 6.08 | G35: =MAX(G9:G32) -> 235.72 | H35: =MAX(H9:H32) -> 56.54 | I35: =MAX(I9:I32) -> 1.6 | ... Q35: =MAX(Q9:Q32) -> 23.33
A36: Avg | B36: =AVERAGE(B9:B32) -> 50.599583 | C36: =AVERAGE(C9:C32) -> 62.802917 | D36: =AVERAGE(D9:D32) -> 75.3375 | E36: =AVERAGE(E9:E32) -> 0.31833333 | F36: =AVERAGE(F9:F32) -> 3.7483333 | G36: =AVERAGE(G9:G32) -> 113.54043 | H36: =AVERAGE(H9:H32) -> 39.207391 | I36: =AVERAGE(I9:I32) -> 1.5445833 | ... Q36: =AVERAGE(Q9:Q32) -> 10.39875
A37: Stdev | B37: =STDEV(B9:B32) -> 61.774667 | C37: =STDEV(C9:C32) -> 6.4662686 | D37: =STDEV(D9:D32) -> 51.041837 | E37: =STDEV(E9:E32) -> 0.15167662 | F37: =STDEV(F9:F32) -> 0.89618839 | G37: =STDEV(G9:G32) -> 63.964309 | H37: =STDEV(H9:H32) -> 9.3639372 | I37: =STDEV(I9:I32) -> 0.025872458 | ... Q37: =STDEV(Q9:Q32) -> 4.1856373
A38: Num | B38: =COUNT(B9:B32) -> 24 | C38: =COUNT(C9:C32) -> 24 | D38: =COUNT(D9:D32) -> 24 | E38: =COUNT(E9:E32) -> 24 | F38: =COUNT(F9:F32) -> 24 | G38: =COUNT(G9:G32)+1 -> 24 | H38: =COUNT(H9:H32)+1 -> 24 | I38: =COUNT(I9:I32) -> 24 | J38: =COUNT(J9:J32) -> 24 | K38: =COUNT(K9:K32) -> 24 | L38: =COUNT(L9:L32) -> 24 | M38: =COUNT(M9:M32) -> 24 | N38: =COUNT(N9:N32) -> 24 | O38: =COUNT(O9:O32) -> 24 | P38: =COUNT(P9:P32)+2 -> 24 | Q38: =COUNT(Q9:Q32) -> 24
A39: DCR | B39: =IF(B38>=22,">90%",IF(B38<=22,"<90%")) -> >90% | C39: =IF(C38>=22,">90%",IF(C38<=22,"<90%")) -> >90% | D39: =IF(D38>=22,">90%",IF(D38<=22,"<90%")) -> >90% | E39: =IF(E38>=22,">90%",IF(E38<=22,"<90%")) -> >90% | F39: =IF(F38>=22,">90%",IF(F38<=22,"<90%")) -> >90% | G39: =IF(G38>=22,">90%",IF(G38<=22,"<90%")) -> >90% | H39: =IF(H38>=22,">90%",IF(H38<=22,"<90%")) -> >90% | I39: =IF(I38>=22,">90%",IF(I38<=22,"<90%")) -> >90% | ... Q39: =IF(Q38>=22,">90%",IF(Q38<=22,"<90%")) -> >90%
A40: Status | B40: =IF(B38>=22,"OK",IF(B38<=22,"LESS")) -> OK | C40: =IF(C38>=22,"OK",IF(C38<=22,"LESS")) -> OK | D40: =IF(D38>=22,"OK",IF(D38<=22,"LESS")) -> OK | E40: =IF(E38>=22,"OK",IF(E38<=22,"LESS")) -> OK | F40: =IF(F38>=22,"OK",IF(F38<=22,"LESS")) -> OK | G40: =IF(G38>=22,"OK",IF(G38<=22,"LESS")) -> OK | H40: =IF(H38>=22,"OK",IF(H38<=22,"LESS")) -> OK | I40: =IF(I38>=22,"OK",IF(I38<=22,"LESS")) -> OK | ... Q40: =IF(Q38>=22,"OK",IF(Q38<=22,"LESS")) -> OK
A43: Done by | B43: RAHUL
A45: Comment

Sheet 04
A1: Station: | B1: BHATAGAON RAIPUR
A2: Date: | B2: =$A$9 -> 04-02-2024 01:00 | D2: Power Off | G2: Pw.Off | L2: Link Fail | N2: Link F | P2: Maintenance | R2: Maint.
A3: Report Type: | B3: Mean | D3: Calibration | G3: Calib. | L3: Data Fail | N3: Data F | P3: Invalid | R3: Invalid
A4: Time Base: | B4: 01 Hour | D4: Zero Referrence | G4: Z.Ref | L4: Warm Up | N4: Wm. Up
A7: Date & Time | B7: NO_BHATAGAON | C7: NO2_BHATAGAON | D7: NOX_BHATAGAON | E7: SO2_BHATAGAON | F7: O3_BHATAGAON | G7: PM10_BHATAGAON | H7: PM2_5_BHATAGAON | I7: BENZ_BHATAGAON | J7: WS_BHATAGAON | K7: WD_BHATAGAON | L7: TEMP_BHATAGAON | M7: HUM BHATAGAON | N7: SR_BHATAGAON | O7: RG_BHATAGAON | P7: CO_BHATAGAON | Q7: NH3_BHATAGAON
B8: ug/m3 | C8: ug/m3 | D8: ppb | E8: ug/m3 | F8: ug/m3 | G8: mg/m3 | H8: ug/m3 | I8: ug/m3 | J8: m/sec | K8: deg | L8: degreC | M8: % | N8: w/m2 | O8: mm | P8: ug/m3 | Q8: ug/m3
A9: 04-02-2024 01:00 | B9: 226.53 | C9: 65.76 | D9: 218.6 | E9: 0.43 | F9: 3.07 | G9: 203.44 | H9: 56.54 | I9: 1.53 | J9: 0.12 | K9: 333.94 | L9: 15.61 | M9: 81.17 | N9: 60.1 | O9: 0 | P9: 2.82 | Q9: 23.08
A10: 04-02-2024 02:00 | B10: 196.7 | C10: 61.91 | D10: 192.55 | E10: 0.37 | F10: 3.07 | G10: 148.86 | H10: 52.7 | I10: 1.58 | J10: 0.1 | K10: 247.7 | L10: 15.6 | M10: 83.42 | N10: 60.1 | O10: 0 | P10: 2.23 | Q10: 21.12
A11: 04-02-2024 03:00 | B11: 172.62 | C11: 59.68 | D11: 172.01 | E11: 0.36 | F11: 3.11 | G11: 183 | H11: 59.48 | I11: 1.55 | J11: 0.16 | K11: 296.95 | L11: 14.56 | M11: 91.86 | N11: 59.8 | O11: 0 | P11: 2.16 | Q11: 19.16
A12: 04-02-2024 04:00 | B12: 161.53 | C12: 59.11 | D12: 162.8 | E12: 0.33 | F12: 3 | G12: 183 | H12: 60.09 | I12: 1.52 | J12: 0.11 | K12: 292.02 | L12: 14.38 | M12: 92.53 | N12: 59.4 | O12: 0 | P12: 2.12 | Q12: 18.5
A13: 04-02-2024 05:00 | B13: 157.11 | C13: 57.88 | D13: 158.58 | E13: 0.52 | F13: 3.36 | G13: 166.28 | H13: 60.09 | I13: 1.56 | J13: 0.16 | K13: 310.65 | L13: 14.49 | M13: 83.45 | N13: 59.7 | O13: 0 | P13: 2 | Q13: 18.21
A14: 04-02-2024 06:00 | B14: 138.71 | C14: 57.27 | D14: 143.48 | E14: 0.49 | F14: 3.06 | G14: 163.56 | H14: 58.05 | I14: 1.63 | J14: 0.18 | K14: 299.67 | L14: 13.78 | M14: 92.74 | N14: 59.7 | O14: 0 | P14: 1.81 | Q14: 14.21
A15: 04-02-2024 07:00 | B15: 148.04 | C15: 55.44 | D15: 149.96 | E15: 0.46 | F15: 3.2 | G15: 133.62 | H15: 51.65 | I15: 1.57 | J15: 0.12 | K15: 294.83 | L15: 13.82 | M15: 96.51 | N15: 82 | O15: 0 | P15: 1.61 | Q15: 16.75
A16: 04-02-2024 08:00 | B16: 157.55 | C16: 56.88 | D16: 158.09 | E16: 0.44 | F16: 3.21 | G16: 139.02 | H16: 51.65 | I16: 1.5 | J16: 0.11 | K16: 288.35 | L16: 19.22 | M16: 92.87 | N16: 276.3 | O16: 0 | P16: 1.61 | Q16: 17.59
A17: 04-02-2024 09:00 | B17: 150.44 | C17: 63.98 | D17: 153.28 | E17: 0.55 | F17: 3.35 | G17: 150.31 | H17: 51.61 | I17: 1.6 | J17: 0.81 | K17: 351.6 | L17: 22.63 | M17: 57.89 | N17: 488.7 | O17: 0 | P17: 1.57 | Q17: 17.41
A18: 04-02-2024 10:00 | B18: 123.5 | C18: 71.26 | D18: 136.11 | E18: 0.47 | F18: 3.49 | G18: 150.31 | H18: 50.99 | I18: 1.55 | J18: 0.62 | K18: 155.93 | L18: 25.22 | M18: 50.4 | N18: 684.9 | O18: 0 | P18: 1.5 | Q18: 16.17
A19: 04-02-2024 11:00 | B19: 88.2 | C19: 73.4 | D19: 111.45 | E19: 0.41 | F19: 3.18 | G19: 117.67 | H19: 48.52 | I19: 1.56 | J19: 0.53 | K19: 334.3 | L19: 27.97 | M19: 34.67 | N19: 789.8 | O19: 0 | P19: 1.29 | Q19: 14.2
A20: 04-02-2024 12:00 | B20: 62.53 | C20: 74.85 | D20: 91.72 | E20: 0.37 | F20: 3.36 | G20: 78.56 | H20: 40.54 | I20: 1.53 | J20: 0.64 | K20: 349.74 | L20: 29.31 | M20: 30.02 | N20: 838 | O20: 0 | P20: 1.1 | Q20: 12.33
... A32: 04-02-2024 24:00 | B32: 108.68 | C32: 74.75 | D32: 129.05 | E32: 0.37 | F32: 3.28 | G32: 121.26 | H32: 38.92 | I32: 1.54 | J32: 0.29 | K32: 328.96 | L32: 18.03 | M32: 65.13 | N32: 64.8 | O32: 0 | P32: 1.56 | Q32: 16.45
A34: Min | B34: =MIN(B9:B32) -> 2.75 | C34: =MIN(C9:C32) -> 54.56 | D34: =MIN(D9:D32) -> 33.49 | E34: =MIN(E9:E32) -> 0.04 | F34: =MIN(F9:F32) -> 3 | G34: =MIN(G9:G32) -> 35.2 | H34: =MIN(H9:H32) -> 21.35 | I34: =MIN(I9:I32) -> 1.48 | ... Q34: =MIN(Q9:Q32) -> 4.84
A35: Max | B35: =MAX(B9:B32) -> 226.53 | C35: =MAX(C9:C32) -> 77.05 | D35: =MAX(D9:D32) -> 218.6 | E35: =MAX(E9:E32) -> 0.55 | F35: =MAX(F9:F32) -> 4.88 | G35: =MAX(G9:G32) -> 203.44 | H35: =MAX(H9:H32) -> 60.09 | I35: =MAX(I9:I32) -> 1.63 | ... Q35: =MAX(Q9:Q32) -> 23.08
A36: Avg | B36: =AVERAGE(B9:B32) -> 96.4475 | C36: =AVERAGE(C9:C32) -> 66.275417 | D36: =AVERAGE(D9:D32) -> 114.21083 | E36: =AVERAGE(E9:E32) -> 0.32166667 | F36: =AVERAGE(F9:F32) -> 3.4420833 | G36: =AVERAGE(G9:G32) -> 120.265 | H36: =AVERAGE(H9:H32) -> 42.03875 | I36: =AVERAGE(I9:I32) -> 1.5391667 | ... Q36: =AVERAGE(Q9:Q32) -> 14.735833
A37: Stdev | B37: =STDEV(B9:B32) -> 67.994854 | C37: =STDEV(C9:C32) -> 8.0154714 | D37: =STDEV(D9:D32) -> 53.363398 | E37: =STDEV(E9:E32) -> 0.14760896 | F37: =STDEV(F9:F32) -> 0.49557151 | G37: =STDEV(G9:G32) -> 54.401294 | H37: =STDEV(H9:H32) -> 13.174608 | I37: =STDEV(I9:I32) -> 0.03682115 | ... Q37: =STDEV(Q9:Q32) -> 4.2432759
A38: Num | B38: =COUNT(B9:B32) -> 24 | C38: =COUNT(C9:C32) -> 24 | D38: =COUNT(D9:D32) -> 24 | E38: =COUNT(E9:E32) -> 24 | F38: =COUNT(F9:F32) -> 24 | G38: =COUNT(G9:G32) -> 24 | H38: =COUNT(H9:H32) -> 24 | I38: =COUNT(I9:I32) -> 24 | ... Q38: =COUNT(Q9:Q32) -> 24
A39: DCR | B39: =IF(B38>=22,">90%",IF(B38<=22,"<90%")) -> >90% | C39: =IF(C38>=22,">90%",IF(C38<=22,"<90%")) -> >90% | D39: =IF(D38>=22,">90%",IF(D38<=22,"<90%")) -> >90% | E39: =IF(E38>=22,">90%",IF(E38<=22,"<90%")) -> >90% | F39: =IF(F38>=22,">90%",IF(F38<=22,"<90%")) -> >90% | G39: =IF(G38>=22,">90%",IF(G38<=22,"<90%")) -> >90% | H39: =IF(H38>=22,">90%",IF(H38<=22,"<90%")) -> >90% | I39: =IF(I38>=22,">90%",IF(I38<=22,"<90%")) -> >90% | ... Q39: =IF(Q38>=22,">90%",IF(Q38<=22,"<90%")) -> >90%
A40: Status | B40: =IF(B38>=22,"OK",IF(B38<=22,"LESS")) -> OK | C40: =IF(C38>=22,"OK",IF(C38<=22,"LESS")) -> OK | D40: =IF(D38>=22,"OK",IF(D38<=22,"LESS")) -> OK | E40: =IF(E38>=22,"OK",IF(E38<=22,"LESS")) -> OK | F40: =IF(F38>=22,"OK",IF(F38<=22,"LESS")) -> OK | G40: =IF(G38>=22,"OK",IF(G38<=22,"LESS")) -> OK | H40: =IF(H38>=22,"OK",IF(H38<=22,"LESS")) -> OK | I40: =IF(I38>=22,"OK",IF(I38<=22,"LESS")) -> OK | ... Q40: =IF(Q38>=22,"OK",IF(Q38<=22,"LESS")) -> OK
A43: Done by | B43: RAHUL
A45: Comment

Sheet 05
A1: Station: | B1: BHATAGAON RAIPUR
A2: Date: | B2: =$A$9 -> 05-02-2024 01:00 | D2: Power Off | G2: Pw.Off | L2: Link Fail | N2: Link F | P2: Maintenance | R2: Maint.
A3: Report Type: | B3: Mean | D3: Calibration | G3: Calib. | L3: Data Fail | N3: Data F | P3: Invalid | R3: Invalid
A4: Time Base: | B4: 01 Hour | D4: Zero Referrence | G4: Z.Ref | L4: Warm Up | N4: Wm. Up
A7: Date & Time | B7: NO_BHATAGAON | C7: NO2_BHATAGAON | D7: NOX_BHATAGAON | E7: SO2_BHATAGAON | F7: O3_BHATAGAON | G7: PM10_BHATAGAON | H7: PM2_5_BHATAGAON | I7: BENZ_BHATAGAON | J7: WS_BHATAGAON | K7: WD_BHATAGAON | L7: TEMP_BHATAGAON | M7: HUM BHATAGAON | N7: SR_BHATAGAON | O7: RG_BHATAGAON | P7: CO_BHATAGAON | Q7: NH3_BHATAGAON
B8: ug/m3 | C8: ug/m3 | D8: ppb | E8: ug/m3 | F8: ug/m3 | G8: mg/m3 | H8: ug/m3 | I8: ug/m3 | J8: m/sec | K8: deg | L8: degreC | M8: % | N8: w/m2 | O8: mm | P8: ug/m3 | Q8: ug/m3
A9: 05-02-2024 01:00 | B9: 101.36 | C9: 70.68 | D9: 120.94 | E9: 0.24 | F9: 3.26 | G9: 91.14 | H9: 35.51 | I9: 1.52 | J9: 0.38 | K9: 308.56 | L9: 18.12 | M9: 67.05 | N9: 64.4 | O9: 0 | P9: 1.5 | Q9: 15.71
A10: 05-02-2024 02:00 | B10: 83.3 | C10: 66.8 | D10: 104.31 | E10: 0.23 | F10: 3.19 | G10: 91.14 | H10: 31.96 | I10: 1.54 | J10: 0.12 | K10: 332.91 | L10: 17.68 | M10: 80.53 | N10: 65 | O10: 0 | P10: 1.22 | Q10: 14.39
A11: 05-02-2024 03:00 | B11: 66.18 | C11: 62.25 | D11: 88.08 | E11: 0.19 | F11: 3.17 | G11: 55.97 | H11: 30.76 | I11: 1.58 | J11: 0.14 | K11: 282.95 | L11: 16.55 | M11: 79.34 | N11: 65 | O11: 0 | P11: 1.08 | Q11: 12.88
A12: 05-02-2024 04:00 | B12: 50.67 | C12: 58.95 | D12: 73.81 | E12: 0.13 | F12: 3.1 | G12: 48.89 | H12: 25.08 | I12: 1.52 | J12: 0.16 | K12: 355.48 | L12: 15.51 | M12: 89.36 | N12: 65.1 | O12: 0 | P12: 0.92 | Q12: 11.36
A13: 05-02-2024 05:00 | B13: 43.39 | C13: 58 | D13: 67.36 | E13: 0.17 | F13: 3.23 | G13: 48.89 | H13: 23.21 | I13: 1.55 | J13: 0.18 | K13: 301.96 | L13: 15.19 | M13: 84.97 | N13: 65 | O13: 0 | P13: 0.82 | Q13: 10.4
A14: 05-02-2024 06:00 | B14: 52.38 | C14: 58.65 | D14: 75.02 | E14: 0.18 | F14: 3.05 | G14: 80.08 | H14: 23.92 | I14: 1.53 | J14: 0.12 | K14: 305.01 | L14: 15.22 | M14: 86.87 | N14: 65 | O14: 0 | P14: 0.76 | Q14: 10.53
A15: 05-02-2024 07:00 | B15: 59.58 | C15: 60.74 | D15: 81.85 | E15: 0.24 | F15: 3.29 | G15: 82.05 | H15: 23.92 | I15: 1.54 | J15: 0.42 | K15: 211.39 | L15: 16.02 | M15: 82.75 | N15: 88.6 | O15: 0 | P15: 0.74 | Q15: 11.31
A16: 05-02-2024 08:00 | B16: 57.07 | C16: 61.58 | D16: 79.96 | E16: 0.27 | F16: 3.12 | G16: 82.05 | H16: 26.06 | I16: 1.51 | J16: 1.07 | K16: 177.16 | L16: 18.13 | M16: 79.44 | N16: 291.4 | O16: 0 | P16: 0.75 | Q16: 11.16
A17: 05-02-2024 09:00 | B17: 48.77 | C17: 62.13 | D17: 73.74 | E17: 0.22 | F17: 3.33 | G17: 59.94 | H17: 26.06 | I17: 1.51 | J17: 0.72 | K17: 213.8 | L17: 21.82 | M17: 64.37 | N17: 508 | O17: 0 | P17: 0.72 | Q17: 10.46
A18: 05-02-2024 10:00 | B18: 34.94 | C18: 64.45 | D18: 62.62 | E18: 0.18 | F18: 3.18 | G18: 48.85 | H18: 22.31 | I18: 1.5 | J18: 0.36 | K18: 343.08 | L18: 28.66 | M18: 46.73 | N18: 670.4 | O18: 0 | P18: 0.67 | Q18: 9.36
A19: 05-02-2024 11:00 | B19: 23.43 | C19: 73.07 | D19: 55.78 | E19: 0.21 | F19: 4.54 | G19: 45.02 | H19: 22.03 | I19: 1.54 | J19: 0.33 | K19: 347.15 | L19: 29.82 | M19: 43.79 | N19: 766.9 | O19: 0 | P19: 0.67 | Q19: 8.71
A20: 05-02-2024 12:00 | B20: 4.15 | C20: 69.45 | D20: 42.3 | E20: 0.23 | F20: 7.29 | G20: 70.15 | H20: 23.16 | I20: 1.52 | J20: 0.58 | K20: 343.63 | L20: 31.66 | M20: 39.98 | N20: 796.1 | O20: 0 | P20: 0.63 | Q20: 7.25
... A32: 05-02-2024 24:00 | B32: 28.61 | C32: 59.85 | D32: 56.57 | E32: 0.39 | F32: 3.29 | G32: 85.01 | H32: 28.73 | I32: 1.54 | J32: 0.14 | K32: 308.02 | L32: 21.12 | M32: 80.79 | N32: 64.8 | O32: 0 | P32: 1.05 | Q32: 8.87
A34: Min | B34: =MIN(B9:B32) -> 1.64 | C34: =MIN(C9:C32) -> 51.42 | D34: =MIN(D9:D32) -> 32.3 | E34: =MIN(E9:E32) -> 0.13 | F34: =MIN(F9:F32) -> 3.05 | G34: =MIN(G9:G32) -> 45.02 | H34: =MIN(H9:H32) -> 15.67 | I34: =MIN(I9:I32) -> 1.5 | ... Q34: =MIN(Q9:Q32) -> 5.21
A35: Max | B35: =MAX(B9:B32) -> 101.36 | C35: =MAX(C9:C32) -> 73.07 | D35: =MAX(D9:D32) -> 120.94 | E35: =MAX(E9:E32) -> 0.46 | F35: =MAX(F9:F32) -> 16.96 | G35: =MAX(G9:G32) -> 91.14 | H35: =MAX(H9:H32) -> 35.51 | I35: =MAX(I9:I32) -> 1.58 | ... Q35: =MAX(Q9:Q32) -> 15.71
A36: Avg | B36: =AVERAGE(B9:B32) -> 31.342083 | C36: =AVERAGE(C9:C32) -> 62.36125 | D36: =AVERAGE(D9:D32) -> 59.67375 | E36: =AVERAGE(E9:E32) -> 0.25 | F36: =AVERAGE(F9:F32) -> 4.9283333 | G36: =AVERAGE(G9:G32) -> 66.100417 | H36: =AVERAGE(H9:H32) -> 24.6475 | I36: =AVERAGE(I9:I32) -> 1.5325 | ... Q36: =AVERAGE(Q9:Q32) -> 8.9779167
A37: Stdev | B37: =STDEV(B9:B32) -> 28.493221 | C37: =STDEV(C9:C32) -> 5.6264896 | D37: =STDEV(D9:D32) -> 24.005484 | E37: =STDEV(E9:E32) -> 0.095507796 | F37: =STDEV(F9:F32) -> 3.1742725 | G37: =STDEV(G9:G32) -> 14.878596 | H37: =STDEV(H9:H32) -> 4.2363533 | I37: =STDEV(I9:I32) -> 0.017257639 | ... Q37: =STDEV(Q9:Q32) -> 2.8892604
A38: Num | B38: =COUNT(B9:B32) -> 24 | C38: =COUNT(C9:C32) -> 24 | D38: =COUNT(D9:D32) -> 24 | E38: =COUNT(E9:E32) -> 24 | F38: =COUNT(F9:F32) -> 24 | G38: =COUNT(G9:G32) -> 24 | H38: =COUNT(H9:H32) -> 24 | I38: =COUNT(I9:I32) -> 24 | ... Q38: =COUNT(Q9:Q32) -> 24
A39: DCR | B39: =IF(B38>=22,">90%",IF(B38<=22,"<90%")) -> >90% | C39: =IF(C38>=22,">90%",IF(C38<=22,"<90%")) -> >90% | D39: =IF(D38>=22,">90%",IF(D38<=22,"<90%")) -> >90% | E39: =IF(E38>=22,">90%",IF(E38<=22,"<90%")) -> >90% | F39: =IF(F38>=22,">90%",IF(F38<=22,"<90%")) -> >90% | G39: =IF(G38>=22,">90%",IF(G38<=22,"<90%")) -> >90% | H39: =IF(H38>=22,">90%",IF(H38<=22,"<90%")) -> >90% | I39: =IF(I38>=22,">90%",IF(I38<=22,"<90%")) -> >90% | ... Q39: =IF(Q38>=22,">90%",IF(Q38<=22,"<90%")) -> >90%
A40: Status | B40: =IF(B38>=22,"OK",IF(B38<=22,"LESS")) -> OK | C40: =IF(C38>=22,"OK",IF(C38<=22,"LESS")) -> OK | D40: =IF(D38>=22,"OK",IF(D38<=22,"LESS")) -> OK | E40: =IF(E38>=22,"OK",IF(E38<=22,"LESS")) -> OK | F40: =IF(F38>=22,"OK",IF(F38<=22,"LESS")) -> OK | G40: =IF(G38>=22,"OK",IF(G38<=22,"LESS")) -> OK | H40: =IF(H38>=22,"OK",IF(H38<=22,"LESS")) -> OK | I40: =IF(I38>=22,"OK",IF(I38<=22,"LESS")) -> OK | ... Q40: =IF(Q38>=22,"OK",IF(Q38<=22,"LESS")) -> OK
A43: Done by | B43: RAHUL
A45: Comment

Sheet 06
A1: Station: | B1: BHATAGAON RAIPUR
A2: Date: | B2: =$A$9 -> 06-02-2024 01:00 | D2: Power Off | G2: Pw.Off | L2: Link Fail | N2: Link F | P2: Maintenance | R2: Maint.
A3: Report Type: | B3: Mean | D3: Calibration | G3: Calib. | L3: Data Fail | N3: Data F | P3: Invalid | R3: Invalid
A4: Time Base: | B4: 01 Hour | D4: Zero Referrence | G4: Z.Ref | L4: Warm Up | N4: Wm. Up
A7: Date & Time | B7: NO_BHATAGAON | C7: NO2_BHATAGAON | D7: NOX_BHATAGAON | E7: SO2_BHATAGAON | F7: O3_BHATAGAON | G7: PM10_BHATAGAON | H7: PM2_5_BHATAGAON | I7: BENZ_BHATAGAON | J7: WS_BHATAGAON | K7: WD_BHATAGAON | L7: TEMP_BHATAGAON | M7: HUM BHATAGAON | N7: SR_BHATAGAON | O7: RG_BHATAGAON | P7: CO_BHATAGAON | Q7: NH3_BHATAGAON
B8: ug/m3 | C8: ug/m3 | D8: ppb | E8: ug/m3 | F8: ug/m3 | G8: mg/m3 | H8: ug/m3 | I8: ug/m3 | J8: m/sec | K8: deg | L8: degreC | M8: % | N8: w/m2 | O8: mm | P8: ug/m3 | Q8: ug/m3
A9: 06-02-2024 01:00 | B9: 23.43 | C9: 59.58 | D9: 52.32 | E9: 0.35 | F9: 3.11 | G9: 71.19 | H9: 28.73 | I9: 1.54 | J9: 0.28 | K9: 316.67 | L9: 20.28 | M9: 80.78 | N9: 64.6 | O9: 0 | P9: 0.96 | Q9: 8.39
A10: 06-02-2024 02:00 | B10: 17.14 | C10: 56.87 | D10: 45.78 | E10: 0.37 | F10: 3.28 | G10: 63.85 | H10: 25.71 | I10: 1.55 | J10: 0.08 | K10: 292.77 | L10: 19.77 | M10: 82 | N10: 64.6 | O10: 0 | P10: 0.8 | Q10: 7.94
A11: 06-02-2024 03:00 | B11: 12.04 | C11: 54.41 | D11: 40.08 | E11: 0.32 | F11: 3.57 | G11: 54.22 | H11: 23.7 | I11: 1.57 | J11: 0.16 | K11: 230.58 | L11: 19.2 | M11: 86.7 | N11: 64.7 | O11: 0 | P11: 0.71 | Q11: 7.48
A12: 06-02-2024 04:00 | B12: 13.13 | C12: 54.82 | D12: 41.36 | E12: 0.3 | F12: 3.39 | G12: 54.22 | H12: 22.75 | I12: 1.57 | J12: 0.1 | K12: 309.46 | L12: 18.54 | M12: 93.91 | N12: 64.9 | O12: 0 | P12: 0.62 | Q12: 7.6
A13: 06-02-2024 05:00 | B13: 20.55 | C13: 54.95 | D13: 47.38 | E13: 0.2 | F13: 3.2 | G13: 59.81 | H13: 23.23 | I13: 1.57 | J13: 0.16 | K13: 343.36 | L13: 17.72 | M13: 97.84 | N13: 64.7 | O13: 0 | P13: 0.61 | Q13: 8.09
A14: 06-02-2024 06:00 | B14: 24.42 | C14: 55.01 | D14: 49.88 | E14: 0.18 | F14: 3.28 | G14: 59.81 | H14: 23.23 | I14: 1.56 | J14: 0.15 | K14: 343.29 | L14: 18.11 | M14: 95.4 | N14: 64.5 | O14: 0 | P14: 0.58 | Q14: 8.51
A15: 06-02-2024 07:00 | B15: 35.42 | C15: 52.56 | D15: 57.8 | E15: 0.23 | F15: 3.32 | G15: 82.2 | H15: 28.88 | I15: 1.56 | J15: 0.12 | K15: 259.63 | L15: 18.12 | M15: 97.81 | N15: 85.4 | O15: 0 | P15: 0.65 | Q15: 8.75
A16: 06-02-2024 08:00 | B16: 62.22 | C16: 56.46 | D16: 81.7 | E16: 0.21 | F16: 3.17 | G16: 112.25 | H16: 38.75 | I16: 1.6 | J16: 0.1 | K16: 341.51 | L16: 21.39 | M16: 96.58 | N16: 220.5 | O16: 0 | P16: 0.85 | Q16: 10.77
A17: 06-02-2024 09:00 | B17: 62.06 | C17: 59.16 | D17: 81.86 | E17: 0.18 | F17: 3.27 | G17: 112.25 | H17: 38.75 | I17: 1.56 | J17: 0.17 | K17: 333.15 | L17: 23.95 | M17: 71.92 | N17: 416.3 | O17: 0 | P17: 0.87 | Q17: 10.96
A18: 06-02-2024 10:00 | B18: 45.69 | C18: 68.17 | D18: 70.52 | E18: 0.23 | F18: 3.63 | G18: 103.02 | H18: 34.28 | I18: 1.53 | J18: 0.29 | K18: 351.65 | L18: 25.73 | M18: 63.15 | N18: 610.8 | O18: 0 | P18: 0.85 | Q18: 10.29
A19: 06-02-2024 11:00 | B19: 15.36 | C19: 70.05 | D19: 51.62 | E19: 0.15 | F19: 8.49 | G19: 78.32 | H19: 33.99 | I19: 1.58 | J19: 0.36 | K19: 312.24 | L19: 27.36 | M19: 59.18 | N19: 706.3 | O19: 0 | P19: 0.69 | Q19: 8.94
A20: 06-02-2024 12:00 | B20: 2.41 | C20: 56.74 | D20: 33.89 | E20: 0.19 | F20: 9.66 | G20: 70.28 | H20: 27.21 | I20: 1.55 | J20: 0.4 | K20: 22.11 | L20: 29.01 | M20: 54.09 | N20: 761.1 | O20: 0 | P20: 0.46 | Q20: 7.48
... A32: 06-02-2024 24:00 | B32: 54.33 | C32: 60.23 | D32: 77.15 | E32: 0.2 | F32: 3.13 | G32: 111.46 | H32: 38.68 | I32: 1.53 | J32: 0.85 | K32: 348.69 | L32: 21.35 | M32: 70.51 | N32: 63.3 | O32: 0 | P32: 1.58 | Q32: 10.66
A34: Min | B34: =MIN(B9:B32) -> 1.43 | C34: =MIN(C9:C32) -> 49.49 | D34: =MIN(D9:D32) -> 29.42 | E34: =MIN(E9:E32) -> 0.1 | F34: =MIN(F9:F32) -> 3.11 | G34: =MIN(G9:G32) -> 49.62 | H34: =MIN(H9:H32) -> 21.17 | I34: =MIN(I9:I32) -> 1.5 | ... Q34: =MIN(Q9:Q32) -> 5.27
A35: Max | B35: =MAX(B9:B32) -> 66.93 | C35: =MAX(C9:C32) -> 70.05 | D35: =MAX(D9:D32) -> 87.76 | E35: =MAX(E9:E32) -> 0.37 | F35: =MAX(F9:F32) -> 19.31 | G35: =MAX(G9:G32) -> 120.03 | H35: =MAX(H9:H32) -> 38.75 | I35: =MAX(I9:I32) -> 1.6 | ... Q35: =MAX(Q9:Q32) -> 11.39
A36: Avg | B36: =AVERAGE(B9:B32) -> 24.714167 | C36: =AVERAGE(C9:C32) -> 57.444583 | D36: =AVERAGE(D9:D32) -> 51.700417 | E36: =AVERAGE(E9:E32) -> 0.22208333 | F36: =AVERAGE(F9:F32) -> 5.615 | G36: =AVERAGE(G9:G32) -> 76.87875 | H36: =AVERAGE(H9:H32) -> 28.652083 | I36: =AVERAGE(I9:I32) -> 1.5441667 | ... Q36: =AVERAGE(Q9:Q32) -> 8.2170833
A37: Stdev | B37: =STDEV(B9:B32) -> 22.816966 | C37: =STDEV(C9:C32) -> 5.1439352 | D37: =STDEV(D9:D32) -> 19.531384 | E37: =STDEV(E9:E32) -> 0.070401283 | F37: =STDEV(F9:F32) -> 4.0898953 | G37: =STDEV(G9:G32) -> 23.535925 | H37: =STDEV(H9:H32) -> 5.8622262 | I37: =STDEV(I9:I32) -> 0.025007245 | ... Q37: =STDEV(Q9:Q32) -> 1.9243033
A38: Num | B38: =COUNT(B9:B32) -> 24 | C38: =COUNT(C9:C32) -> 24 | D38: =COUNT(D9:D32) -> 24 | E38: =COUNT(E9:E32) -> 24 | F38: =COUNT(F9:F32) -> 24 | G38: =COUNT(G9:G32) -> 24 | H38: =COUNT(H9:H32) -> 24 | I38: =COUNT(I9:I32) -> 24 | ... Q38: =COUNT(Q9:Q32) -> 24
A39: DCR | B39: =IF(B38>=22,">90%",IF(B38<=22,"<90%")) -> >90% | C39: =IF(C38>=22,">90%",IF(C38<=22,"<90%")) -> >90% | D39: =IF(D38>=22,">90%",IF(D38<=22,"<90%")) -> >90% | E39: =IF(E38>=22,">90%",IF(E38<=22,"<90%")) -> >90% | F39: =IF(F38>=22,">90%",IF(F38<=22,"<90%")) -> >90% | G39: =IF(G38>=22,">90%",IF(G38<=22,"<90%")) -> >90% | H39: =IF(H38>=22,">90%",IF(H38<=22,"<90%")) -> >90% | I39: =IF(I38>=22,">90%",IF(I38<=22,"<90%")) -> >90% | ... Q39: =IF(Q38>=22,">90%",IF(Q38<=22,"<90%")) -> >90%
A40: Status | B40: =IF(B38>=22,"OK",IF(B38<=22,"LESS")) -> OK | C40: =IF(C38>=22,"OK",IF(C38<=22,"LESS")) -> OK | D40: =IF(D38>=22,"OK",IF(D38<=22,"LESS")) -> OK | E40: =IF(E38>=22,"OK",IF(E38<=22,"LESS")) -> OK | F40: =IF(F38>=22,"OK",IF(F38<=22,"LESS")) -> OK | G40: =IF(G38>=22,"OK",IF(G38<=22,"LESS")) -> OK | H40: =IF(H38>=22,"OK",IF(H38<=22,"LESS")) -> OK | I40: =IF(I38>=22,"OK",IF(I38<=22,"LESS")) -> OK | ... Q40: =IF(Q38>=22,"OK",IF(Q38<=22,"LESS")) -> OK
A43: Done by | B43: RAHUL
A45: Comment

Sheet 07
A1: Station: | B1: BHATAGAON RAIPUR
A2: Date: | B2: =$A$9 -> 07-02-2024 01:00 | D2: Power Off | G2: Pw.Off | L2: Link Fail | N2: Link F | P2: Maintenance | R2: Maint.
A3: Report Type: | B3: Mean | D3: Calibration | G3: Calib. | L3: Data Fail | N3: Data F | P3: Invalid | R3: Invalid
A4: Time Base: | B4: 01 Hour | D4: Zero Referrence | G4: Z.Ref | L4: Warm Up | N4: Wm. Up
A7: Date & Time | B7: NO_BHATAGAON | C7: NO2_BHATAGAON | D7: NOX_BHATAGAON | E7: SO2_BHATAGAON | F7: O3_BHATAGAON | G7: PM10_BHATAGAON | H7: PM2_5_BHATAGAON | I7: BENZ_BHATAGAON | J7: WS_BHATAGAON | K7: WD_BHATAGAON | L7: TEMP_BHATAGAON | M7: HUM BHATAGAON | N7: SR_BHATAGAON | O7: RG_BHATAGAON | P7: CO_BHATAGAON | Q7: NH3_BHATAGAON
B8: ug/m3 | C8: ug/m3 | D8: ppb | E8: ug/m3 | F8: ug/m3 | G8: mg/m3 | H8: ug/m3 | I8: ug/m3 | J8: m/sec | K8: deg | L8: degreC | M8: % | N8: w/m2 | O8: mm | P8: ug/m3 | Q8: ug/m3
A9: 07-02-2024 01:00 | B9: 40.33 | C9: 60.52 | D9: 66.35 | E9: 0.37 | F9: 3.36 | G9: 90.61 | H9: 33.86 | I9: 1.53 | J9: 1.06 | K9: 346.52 | L9: 19.81 | M9: 75.93 | N9: 62.9 | O9: 0 | P9: 1.27 | Q9: 9.8
A10: 07-02-2024 02:00 | B10: 28.67 | C10: 59.78 | D10: 56.63 | E10: 0.3 | F10: 3.38 | G10: 69.79 | H10: 25.93 | I10: 1.53 | J10: 0.87 | K10: 351.38 | L10: 19.02 | M10: 80.57 | N10: 63.1 | O10: 0 | P10: 0.94 | Q10: 9.11
A11: 07-02-2024 03:00 | B11: 21.14 | C11: 57.84 | D11: 49.52 | E11: 0.28 | F11: 3.25 | G11: 53.06 | H11: 24.43 | I11: 1.58 | J11: 0.29 | K11: 82.39 | L11: 18.39 | M11: 82.66 | N11: 63 | O11: 0 | P11: 0.81 | Q11: 8.43
A12: 07-02-2024 04:00 | B12: 16.54 | C12: 50.85 | D12: 41.87 | E12: 0.26 | F12: 3.36 | G12: 49.66 | H12: 23.72 | I12: 1.54 | J12: 0.28 | K12: 35 | L12: 18.04 | M12: 85.92 | N12: 63 | O12: 0 | P12: 0.68 | Q12: 7.81
A13: 07-02-2024 05:00 | B13: 14.18 | C13: 49.9 | D13: 39.41 | E13: 0.23 | F13: 3.09 | G13: 49.66 | H13: 24.38 | I13: 1.52 | J13: 0.44 | K13: 352.57 | L13: 17.9 | M13: 86.02 | N13: 63.5 | O13: 0 | P13: 0.59 | Q13: 7.42
A14: 07-02-2024 06:00 | B14: 15.45 | C14: 49.63 | D14: 40.42 | E14: 0.21 | F14: 3.07 | G14: 52.6 | H14: 24.88 | I14: 1.52 | J14: 0.5 | K14: 355.38 | L14: 17.53 | M14: 86.5 | N14: 63.6 | O14: 0 | P14: 0.51 | Q14: 7.4
A15: 07-02-2024 07:00 | B15: 20.02 | C15: 51.09 | D15: 44.9 | E15: 0.19 | F15: 3.19 | G15: 56.73 | H15: 24.88 | I15: 1.52 | J15: 0.37 | K15: 355.38 | L15: 17.53 | M15: 87.92 | N15: 84.9 | O15: 0 | P15: 0.49 | Q15: 7.76
A16: 07-02-2024 08:00 | B16: 23.53 | C16: 51.31 | D16: 47.66 | E16: 0.18 | F16: 3.23 | G16: 57.76 | H16: 24.37 | I16: 1.56 | J16: 0.91 | K16: 103.97 | L16: 18.54 | M16: 88.38 | N16: 228.6 | O16: 0 | P16: 0.46 | Q16: 8.17
A17: 07-02-2024 09:00 | B17: 27.07 | C17: 51.74 | D17: 50.91 | E17: 0.31 | F17: 3.37 | G17: 57.76 | H17: 24.13 | I17: 1.55 | J17: 0.74 | K17: 113.68 | L17: 20.65 | M17: 76.46 | N17: 430.3 | O17: 0 | P17: 0.47 | Q17: 8.49
A18: 07-02-2024 10:00 | B18: 28.66 | C18: 53.07 | D18: 52.7 | E18: 0.29 | F18: 3.23 | G18: 59.43 | H18: 25.65 | I18: 1.55 | J18: 0.83 | K18: 359.79 | L18: 26.64 | M18: 62.46 | N18: 563.3 | O18: 0 | P18: 0.5 | Q18: 8.65
A19: 07-02-2024 11:00 | B19: 28.49 | C19: 55.1 | D19: 52.08 | E19: 0.32 | F19: 3.12 | G19: 64.68 | H19: 25.65 | I19: 1.49 | J19: 0.61 | K19: 351.34 | L19: 27.46 | M19: 48.14 | N19: 705.1 | O19: 0 | P19: 0.54 | Q19: 8.5
A20: 07-02-2024 12:00 | B20: 25.06 | C20: 58.5 | D20: 50.93 | E20: 0.3 | F20: 3.22 | G20: 64.68 | H20: 25.73 | I20: 1.56 | J20: 0.74 | K20: 119.06 | L20: 26.84 | M20: 51.51 | N20: 741.5 | O20: 0 | P20: 0.56 | Q20: 8.35
... A32: 07-02-2024 24:00 | B32: 52.1 | C32: 64.95 | D32: 78.27 | E32: 0.23 | F32: 3.3 | G32: 122.43 | H32: 40.9 | I32: 1.61 | J32: 1.52 | K32: 349.77 | L32: 20.05 | M32: 60.1 | N32: 66.8 | O32: 0 | P32: 1.52 | Q32: 11.21
A34: Min | B34: =MIN(B9:B32) -> 2.8 | C34: =MIN(C9:C32) -> 49.63 | D34: =MIN(D9:D32) -> 33.84 | E34: =MIN(E9:E32) -> 0.11 | F34: =MIN(F9:F32) -> 3.07 | G34: =MIN(G9:G32) -> 49.66 | H34: =MIN(H9:H32) -> 23.72 | I34: =MIN(I9:I32) -> 1.49 | ... Q34: =MIN(Q9:Q32) -> 7.02
A35: Max | B35: =MAX(B9:B32) -> 54.95 | C35: =MAX(C9:C32) -> 68.13 | D35: =MAX(D9:D32) -> 80.75 | E35: =MAX(E9:E32) -> 0.37 | F35: =MAX(F9:F32) -> 4.56 | G35: =MAX(G9:G32) -> 122.6 | H35: =MAX(H9:H32) -> 41.18 | I35: =MAX(I9:I32) -> 1.61 | ... Q35: =MAX(Q9:Q32) -> 11.25
A36: Avg | B36: =AVERAGE(B9:B32) -> 22.005833 | C36: =AVERAGE(C9:C32) -> 58.622917 | D36: =AVERAGE(D9:D32) -> 50.295833 | E36: =AVERAGE(E9:E32) -> 0.25 | F36: =AVERAGE(F9:F32) -> 3.4758333 | G36: =AVERAGE(G9:G32) -> 74.36625 | H36: =AVERAGE(H9:H32) -> 29.259583 | I36: =AVERAGE(I9:I32) -> 1.5429167 | ... Q36: =AVERAGE(Q9:Q32) -> 8.3716667
A37: Stdev | B37: =STDEV(B9:B32) -> 15.03648 | C37: =STDEV(C9:C32) -> 5.8552188 | D37: =STDEV(D9:D32) -> 13.18074 | E37: =STDEV(E9:E32) -> 0.061219491 | F37: =STDEV(F9:F32) -> 0.44268859 | G37: =STDEV(G9:G32) -> 22.75084 | H37: =STDEV(H9:H32) -> 5.5548173 | I37: =STDEV(I9:I32) -> 0.028357833 | ... Q37: =STDEV(Q9:Q32) -> 1.2012699
A38: Num | B38: =COUNT(B9:B32) -> 24 | C38: =COUNT(C9:C32) -> 24 | D38: =COUNT(D9:D32) -> 24 | E38: =COUNT(E9:E32) -> 24 | F38: =COUNT(F9:F32) -> 24 | G38: =COUNT(G9:G32) -> 24 | H38: =COUNT(H9:H32) -> 24 | I38: =COUNT(I9:I32) -> 24 | ... Q38: =COUNT(Q9:Q32) -> 24
A39: DCR | B39: =IF(B38>=22,">90%",IF(B38<=22,"<90%")) -> >90% | C39: =IF(C38>=22,">90%",IF(C38<=22,"<90%")) -> >90% | D39: =IF(D38>=22,">90%",IF(D38<=22,"<90%")) -> >90% | E39: =IF(E38>=22,">90%",IF(E38<=22,"<90%")) -> >90% | F39: =IF(F38>=22,">90%",IF(F38<=22,"<90%")) -> >90% | G39: =IF(G38>=22,">90%",IF(G38<=22,"<90%")) -> >90% | H39: =IF(H38>=22,">90%",IF(H38<=22,"<90%")) -> >90% | I39: =IF(I38>=22,">90%",IF(I38<=22,"<90%")) -> >90% | ... Q39: =IF(Q38>=22,">90%",IF(Q38<=22,"<90%")) -> >90%
A40: Status | B40: =IF(B38>=22,"OK",IF(B38<=22,"LESS")) -> OK | C40: =IF(C38>=22,"OK",IF(C38<=22,"LESS")) -> OK | D40: =IF(D38>=22,"OK",IF(D38<=22,"LESS")) -> OK | E40: =IF(E38>=22,"OK",IF(E38<=22,"LESS")) -> OK | F40: =IF(F38>=22,"OK",IF(F38<=22,"LESS")) -> OK | G40: =IF(G38>=22,"OK",IF(G38<=22,"LESS")) -> OK | H40: =IF(H38>=22,"OK",IF(H38<=22,"LESS")) -> OK | I40: =IF(I38>=22,"OK",IF(I38<=22,"LESS")) -> OK | ... Q40: =IF(Q38>=22,"OK",IF(Q38<=22,"LESS")) -> OK
A43: Done by | B43: RAHUL
A45: Comment

Sheet 08
A1: Station: | B1: BHATAGAON RAIPUR
A2: Date: | B2: =$A$9 -> 08-02-2024 01:00 | D2: Power Off | G2: Pw.Off | L2: Link Fail | N2: Link F | P2: Maintenance | R2: Maint.
A3: Report Type: | B3: Mean | D3: Calibration | G3: Calib. | L3: Data Fail | N3: Data F | P3: Invalid | R3: Invalid
A4: Time Base: | B4: 01 Hour | D4: Zero Referrence | G4: Z.Ref | L4: Warm Up | N4: Wm. Up
A7: Date & Time | B7: NO_BHATAGAON | C7: NO2_BHATAGAON | D7: NOX_BHATAGAON | E7: SO2_BHATAGAON | F7: O3_BHATAGAON | G7: PM10_BHATAGAON | H7: PM2_5_BHATAGAON | I7: BENZ_BHATAGAON | J7: WS_BHATAGAON | K7: WD_BHATAGAON | L7: TEMP_BHATAGAON | M7: HUM BHATAGAON | N7: SR_BHATAGAON | O7: RG_BHATAGAON | P7: CO_BHATAGAON | Q7: NH3_BHATAGAON
B8: ug/m3 | C8: ug/m3 | D8: ppb | E8: ug/m3 | F8: ug/m3 | G8: mg/m3 | H8: ug/m3 | I8: ug/m3 | J8: m/sec | K8: deg | L8: degreC | M8: % | N8: w/m2 | O8: mm | P8: ug/m3 | Q8: ug/m3
A9: 08-02-2024 01:00 | B9: 36.47 | C9: 61.28 | D9: 63.71 | E9: 0.2 | F9: 3.36 | G9: 99.19 | H9: 38.99 | I9: 1.58 | J9: 0.91 | K9: 356.83 | L9: 19.05 | M9: 45.66 | N9: 66.8 | O9: 0 | P9: 1.16 | Q9: 9.85
A10: 08-02-2024 02:00 | B10: 22.58 | C10: 58.95 | D10: 51.29 | E10: 0.16 | F10: 3.4 | G10: 59.83 | H10: 28.98 | I10: 1.58 | J10: 0.96 | K10: 350.82 | L10: 18.22 | M10: 45.05 | N10: 66.7 | O10: 0 | P10: 0.85 | Q10: 8.31
A11: 08-02-2024 03:00 | B11: 15.5 | C11: 58.11 | D11: 45.15 | E11: 0.15 | F11: 3.4 | G11: 53.49 | H11: 17.1 | I11: 1.56 | J11: 0.75 | K11: 349.61 | L11: 17.58 | M11: 47.7 | N11: 67.1 | O11: 0 | P11: 0.69 | Q11: 7.43
A12: 08-02-2024 04:00 | B12: 12.71 | C12: 57.12 | D12: 42.37 | E12: 0.11 | F12: 3.36 | G12: 44.08 | H12: 9.89 | I12: 1.53 | J12: 0.3 | K12: 349.57 | L12: 16.94 | M12: 48.04 | N12: 67.2 | O12: 0 | P12: 0.56 | Q12: 6.99
A13: 08-02-2024 05:00 | B13: 11.58 | C13: 55.65 | D13: 40.33 | E13: 0.16 | F13: 3.46 | G13: 44.08 | H13: 9.89 | I13: 1.62 | J13: 1.19 | K13: 349.97 | L13: 17.09 | M13: 44.99 | N13: 67.9 | O13: 0 | P13: 0.48 | Q13: 6.88
A14: 08-02-2024 06:00 | B14: 10.08 | C14: 56.32 | D14: 39.71 | E14: 0.18 | F14: 3.6 | G14: 36.9 | H14: 6.97 | I14: 1.61 | J14: 0.97 | K14: 349.5 | L14: 16.56 | M14: 47.74 | N14: 66.8 | O14: 0 | P14: 0.4 | Q14: 6.81
A15: 08-02-2024 07:00 | B15: 10.01 | C15: 56.57 | D15: 39.88 | E15: 0.12 | F15: 3.73 | G15: 46.92 | H15: 15.58 | I15: 1.58 | J15: 0.97 | K15: 349.25 | L15: 15.83 | M15: 47.78 | N15: 90.2 | O15: 0 | P15: 0.38 | Q15: 6.75
A16: 08-02-2024 08:00 | B16: 10.27 | C16: 58.46 | D16: 41.15 | E16: 0.3 | F16: 3.63 | G16: 51.57 | H16: 19.93 | I16: 1.53 | J16: 1.1 | K16: 352.48 | L16: 18.53 | M16: 45.21 | N16: 282.9 | O16: 0 | P16: 0.44 | Q16: 6.68
A17: 08-02-2024 09:00 | B17: 14.79 | C17: 61.22 | D17: 46.29 | E17: 0.49 | F17: 3.38 | G17: 63.79 | H17: 22.69 | I17: 1.54 | J17: 1.34 | K17: 349.81 | L17: 21.54 | M17: 34.99 | N17: 445.2 | O17: 0 | P17: 0.48 | Q17: 6.15
A18: 08-02-2024 10:00 | B18: 14.79 | C18: 63.83 | D18: 47.18 | E18: 0.43 | F18: 3.5 | G18: 70.05 | H18: 26.52 | I18: 1.54 | J18: 1.35 | K18: 349.81 | L18: 23.62 | M18: 28.87 | N18: 687.7 | O18: 0 | P18: 0.5 | Q18: 11.57
A19: 08-02-2024 11:00 | B19: 11.57 | C19: 64.63 | D19: 44.89 | E19: 0.58 | F19: 4.67 | G19: 70.05 | H19: 26.52 | I19: 1.49 | J19: 1.22 | K19: 355.63 | L19: 27.4 | M19: 20.62 | N19: 776.3 | O19: 0 | P19: 0.51 | Q19: 15.86
A20: 08-02-2024 12:00 | B20: 8.37 | C20: 71.69 | D20: 46.85 | E20: 0.54 | F20: 4.33 | G20: 55.92 | H20: 24.06 | I20: 1.51 | J20: 1.26 | K20: 356.9 | L20: 28.2 | M20: 20.97 | N20: 811.5 | O20: 0 | P20: 0.56 | Q20: 14.2
... A32: 08-02-2024 24:00 | B32: 111.75 | C32: 66.38 | D32: 126.89 | E32: 0.36 | F32: 3.26 | G32: 127.23 | H32: 38.46 | I32: 1.57 | J32: 1.11 | K32: 358.44 | L32: 16.27 | M32: 59.57 | N32: 56.9 | O32: 0 | P32: 2.09 | Q32: 14.67
A34: Min | B34: =MIN(B9:B32) -> 5.21 | C34: =MIN(C9:C32) -> 55.65 | D34: =MIN(D9:D32) -> 39.32 | E34: =MIN(E9:E32) -> 0.11 | F34: =MIN(F9:F32) -> 3.13 | G34: =MIN(G9:G32) -> 36.9 | H34: =MIN(H9:H32) -> 6.97 | I34: =MIN(I9:I32) -> 1.49 | ... Q34: =MIN(Q9:Q32) -> 6.15
A35: Max | B35: =MAX(B9:B32) -> 115.83 | C35: =MAX(C9:C32) -> 71.78 | D35: =MAX(D9:D32) -> 130.14 | E35: =MAX(E9:E32) -> 0.85 | F35: =MAX(F9:F32) -> 6.85 | G35: =MAX(G9:G32) -> 132.93 | H35: =MAX(H9:H32) -> 38.99 | I35: =MAX(I9:I32) -> 1.62 | ... Q35: =MAX(Q9:Q32) -> 15.86
A36: Avg | B36: =AVERAGE(B9:B32) -> 28.302083 | C36: =AVERAGE(C9:C32) -> 63.223333 | D36: =AVERAGE(D9:D32) -> 58.10625 | E36: =AVERAGE(E9:E32) -> 0.32416667 | F36: =AVERAGE(F9:F32) -> 3.9195833 | G36: =AVERAGE(G9:G32) -> 73.33625 | H36: =AVERAGE(H9:H32) -> 22.9675 | I36: =AVERAGE(I9:I32) -> 1.56 | ... Q36: =AVERAGE(Q9:Q32) -> 9.44625
A37: Stdev | B37: =STDEV(B9:B32) -> 34.871268 | C37: =STDEV(C9:C32) -> 4.6655683 | D37: =STDEV(D9:D32) -> 28.834482 | E37: =STDEV(E9:E32) -> 0.17641149 | F37: =STDEV(F9:F32) -> 0.92736878 | G37: =STDEV(G9:G32) -> 29.153046 | H37: =STDEV(H9:H32) -> 8.697748 | I37: =STDEV(I9:I32) -> 0.033879582 | ... Q37: =STDEV(Q9:Q32) -> 3.0807478
A38: Num | B38: =COUNT(B9:B32) -> 24 | C38: =COUNT(C9:C32) -> 24 | D38: =COUNT(D9:D32) -> 24 | E38: =COUNT(E9:E32) -> 24 | F38: =COUNT(F9:F32) -> 24 | G38: =COUNT(G9:G32) -> 24 | H38: =COUNT(H9:H32) -> 24 | I38: =COUNT(I9:I32) -> 24 | ... Q38: =COUNT(Q9:Q32) -> 24
A39: DCR | B39: =IF(B38>=22,">90%",IF(B38<=22,"<90%")) -> >90% | C39: =IF(C38>=22,">90%",IF(C38<=22,"<90%")) -> >90% | D39: =IF(D38>=22,">90%",IF(D38<=22,"<90%")) -> >90% | E39: =IF(E38>=22,">90%",IF(E38<=22,"<90%")) -> >90% | F39: =IF(F38>=22,">90%",IF(F38<=22,"<90%")) -> >90% | G39: =IF(G38>=22,">90%",IF(G38<=22,"<90%")) -> >90% | H39: =IF(H38>=22,">90%",IF(H38<=22,"<90%")) -> >90% | I39: =IF(I38>=22,">90%",IF(I38<=22,"<90%")) -> >90% | ... Q39: =IF(Q38>=22,">90%",IF(Q38<=22,"<90%")) -> >90%
A40: Status | B40: =IF(B38>=22,"OK",IF(B38<=22,"LESS")) -> OK | C40: =IF(C38>=22,"OK",IF(C38<=22,"LESS")) -> OK | D40: =IF(D38>=22,"OK",IF(D38<=22,"LESS")) -> OK | E40: =IF(E38>=22,"OK",IF(E38<=22,"LESS")) -> OK | F40: =IF(F38>=22,"OK",IF(F38<=22,"LESS")) -> OK | G40: =IF(G38>=22,"OK",IF(G38<=22,"LESS")) -> OK | H40: =IF(H38>=22,"OK",IF(H38<=22,"LESS")) -> OK | I40: =IF(I38>=22,"OK",IF(I38<=22,"LESS")) -> OK | ... Q40: =IF(Q38>=22,"OK",IF(Q38<=22,"LESS")) -> OK
A43: Done by | B43: RAHUL
A45: Comment

Sheet 09
A1: Station: | B1: BHATAGAON RAIPUR
A2: Date: | B2: =$A$9 -> 09-02-2024 01:00 | D2: Power Off | G2: Pw.Off | L2: Link Fail | N2: Link F | P2: Maintenance | R2: Maint.
A3: Report Type: | B3: Mean | D3: Calibration | G3: Calib. | L3: Data Fail | N3: Data F | P3: Invalid | R3: Invalid
A4: Time Base: | B4: 01 Hour | D4: Zero Referrence | G4: Z.Ref | L4: Warm Up | N4: Wm. Up
A7: Date & Time | B7: NO_BHATAGAON | C7: NO2_BHATAGAON | D7: NOX_BHATAGAON | E7: SO2_BHATAGAON | F7: O3_BHATAGAON | G7: PM10_BHATAGAON | H7: PM2_5_BHATAGAON | I7: BENZ_BHATAGAON | J7: WS_BHATAGAON | K7: WD_BHATAGAON | L7: TEMP_BHATAGAON | M7: HUM BHATAGAON | N7: SR_BHATAGAON | O7: RG_BHATAGAON | P7: CO_BHATAGAON | Q7: NH3_BHATAGAON
B8: ug/m3 | C8: ug/m3 | D8: ppb | E8: ug/m3 | F8: ug/m3 | G8: mg/m3 | H8: ug/m3 | I8: ug/m3 | J8: m/sec | K8: deg | L8: degreC | M8: % | N8: w/m2 | O8: mm | P8: ug/m3 | Q8: ug/m3
A9: 09-02-2024 01:00 | B9: 83.63 | C9: 64.84 | D9: 103.5 | E9: 0.45 | F9: 3.2 | G9: 105.78 | H9: 35.33 | I9: 1.55 | J9: 0.87 | K9: 353.2 | L9: 16 | M9: 61.14 | N9: 57 | O9: 0 | P9: 1.73 | Q9: 13
A10: 09-02-2024 02:00 | B10: 63.18 | C10: 63.32 | D10: 86.26 | E10: 0.56 | F10: 3.35 | G10: 84.97 | H10: 32.09 | I10: 1.56 | J10: 0.98 | K10: 353.22 | L10: 15.79 | M10: 59.18 | N10: 56.7 | O10: 0 | P10: 1.26 | Q10: 11.4
A11: 09-02-2024 03:00 | B11: 50.46 | C11: 60.93 | D11: 74.73 | E11: 0.61 | F11: 3.18 | G11: 117.31 | H11: 35.11 | I11: 1.5 | J11: 0.82 | K11: 354.04 | L11: 14.95 | M11: 57.96 | N11: 56.9 | O11: 0 | P11: 1.12 | Q11: 10.23
A12: 09-02-2024 04:00 | B12: 43.18 | C12: 59.92 | D12: 68.34 | E12: 0.51 | F12: 3.09 | G12: 117.31 | H12: 35.11 | I12: 1.57 | J12: 0.35 | K12: 66 | L12: 14.38 | M12: 57.76 | N12: 57.3 | O12: 0 | P12: 1.03 | Q12: 9.65
A13: 09-02-2024 05:00 | B13: 39.81 | C13: 56.56 | D13: 63.78 | E13: 0.31 | F13: 3.24 | G13: 117.28 | H13: 36.59 | I13: 1.58 | J13: 0.18 | K13: 62.32 | L13: 13.53 | M13: 59.27 | N13: 57 | O13: 0 | P13: 0.99 | Q13: 9.1
A14: 09-02-2024 06:00 | B14: 36.22 | C14: 54.92 | D14: 60 | E14: 0.23 | F14: 3.2 | G14: 117.28 | H14: 36.59 | I14: 1.53 | J14: 0.16 | K14: 356.34 | L14: 13.21 | M14: 50.25 | N14: 56.9 | O14: 0 | P14: 0.9 | Q14: 8.76
A15: 09-02-2024 07:00 | B15: 30.29 | C15: 54.64 | D15: 54.92 | E15: 0.2 | F15: 3.36 | G15: 74.07 | H15: 33.58 | I15: 1.54 | J15: 0.2 | K15: 342.46 | L15: 12.92 | M15: 50.31 | N15: 81.2 | O15: 0 | P15: 0.76 | Q15: 8.34
A16: 09-02-2024 08:00 | B16: 30.07 | C16: 56.54 | D16: 55.81 | E16: 0.19 | F16: 3.4 | G16: 68.28 | H16: 29.16 | I16: 1.51 | J16: 1.21 | K16: 349.03 | L16: 15.83 | M16: 49.75 | N16: 336.8 | O16: 0 | P16: 0.77 | Q16: 8.16
A17: 09-02-2024 09:00 | B17: 28.23 | C17: 56.27 | D17: 54.31 | E17: 0.32 | F17: 3.44 | G17: 68.28 | H17: 25.62 | I17: 1.58 | J17: 1.25 | K17: 105.09 | L17: 18.57 | M17: 36.76 | N17: 548.8 | O17: 0 | P17: 0.72 | Q17: 8.09
A18: 09-02-2024 10:00 | B18: 23.81 | C18: 57.17 | D18: 51.29 | E18: 0.31 | F18: 3.43 | G18: 60.87 | H18: 24.25 | I18: 1.58 | J18: 1.51 | K18: 100.65 | L18: 20.52 | M18: 29.55 | N18: 719.4 | O18: 0 | P18: 0.65 | Q18: 7.72
A19: 09-02-2024 11:00 | B19: 20.64 | C19: 61.6 | D19: 48.93 | E19: 0.58 | F19: 6.26 | G19: 52 | H19: 21.28 | I19: 1.52 | J19: 1.23 | K19: 97.38 | L19: 22.75 | M19: 25.05 | N19: 820.1 | O19: 0 | P19: 0.57 | Q19: 7.55
A20: 09-02-2024 12:00 | B20: 6.7 | C20: 70.5 | D20: 44.93 | E20: 1.09 | F20: 8.22 | G20: 45.68 | H20: 20.23 | I20: 1.52 | J20: 1.13 | K20: 102.24 | L20: 24.39 | M20: 21.94 | N20: 883.4 | O20: 0 | P20: 0.47 | Q20: 6.71
... A32: 09-02-2024 24:00 | B32: 27.02 | C32: 71.08 | D32: 61.38 | E32: 0.25 | F32: 3.47 | G32: 86.47 | H32: 32.16 | I32: 1.53 | J32: 0.15 | K32: 348.48 | L32: 16.76 | M32: 43.07 | N32: 88.2 | O32: 0 | P32: 1.2 | Q32: 8.44
A34: Min | B34: =MIN(B9:B32) -> 3.8 | C34: =MIN(C9:C32) -> 54.64 | D34: =MIN(D9:D32) -> 35.55 | E34: =MIN(E9:E32) -> 0.19 | F34: =MIN(F9:F32) -> 3.09 | G34: =MIN(G9:G32) -> 44.27 | H34: =MIN(H9:H32) -> 17.16 | I34: =MIN(I9:I32) -> 1.49 | ... Q34: =MIN(Q9:Q32) -> 5.91
A35: Max | B35: =MAX(B9:B32) -> 83.63 | C35: =MAX(C9:C32) -> 72.68 | D35: =MAX(D9:D32) -> 103.5 | E35: =MAX(E9:E32) -> 1.09 | F35: =MAX(F9:F32) -> 8.22 | G35: =MAX(G9:G32) -> 117.31 | H35: =MAX(H9:H32) -> 36.59 | I35: =MAX(I9:I32) -> 1.61 | ... Q35: =MAX(Q9:Q32) -> 13
A36: Avg | B36: =AVERAGE(B9:B32) -> 26.131667 | C36: =AVERAGE(C9:C32) -> 62.515417 | D36: =AVERAGE(D9:D32) -> 55.911667 | E36: =AVERAGE(E9:E32) -> 0.3875 | F36: =AVERAGE(F9:F32) -> 3.8204167 | G36: =AVERAGE(G9:G32) -> 80.242917 | H36: =AVERAGE(H9:H32) -> 27.271667 | I36: =AVERAGE(I9:I32) -> 1.5420833 | ... Q36: =AVERAGE(Q9:Q32) -> 8.0645833
A37: Stdev | B37: =STDEV(B9:B32) -> 19.943803 | C37: =STDEV(C9:C32) -> 6.3020404 | D37: =STDEV(D9:D32) -> 16.381414 | E37: =STDEV(E9:E32) -> 0.19065676 | F37: =STDEV(F9:F32) -> 1.1624056 | G37: =STDEV(G9:G32) -> 25.400663 | H37: =STDEV(H9:H32) -> 6.9390832 | I37: =STDEV(I9:I32) -> 0.02963241 | ... Q37: =STDEV(Q9:Q32) -> 1.7505378
A38: Num | B38: =COUNT(B9:B32) -> 24 | C38: =COUNT(C9:C32) -> 24 | D38: =COUNT(D9:D32) -> 24 | E38: =COUNT(E9:E32) -> 24 | F38: =COUNT(F9:F32) -> 24 | G38: =COUNT(G9:G32) -> 24 | H38: =COUNT(H9:H32) -> 24 | I38: =COUNT(I9:I32) -> 24 | ... Q38: =COUNT(Q9:Q32) -> 24
A39: DCR | B39: =IF(B38>=22,">90%",IF(B38<=22,"<90%")) -> >90% | C39: =IF(C38>=22,">90%",IF(C38<=22,"<90%")) -> >90% | D39: =IF(D38>=22,">90%",IF(D38<=22,"<90%")) -> >90% | E39: =IF(E38>=22,">90%",IF(E38<=22,"<90%")) -> >90% | F39: =IF(F38>=22,">90%",IF(F38<=22,"<90%")) -> >90% | G39: =IF(G38>=22,">90%",IF(G38<=22,"<90%")) -> >90% | H39: =IF(H38>=22,">90%",IF(H38<=22,"<90%")) -> >90% | I39: =IF(I38>=22,">90%",IF(I38<=22,"<90%")) -> >90% | ... Q39: =IF(Q38>=22,">90%",IF(Q38<=22,"<90%")) -> >90%
A40: Status | B40: =IF(B38>=22,"OK",IF(B38<=22,"LESS")) -> OK | C40: =IF(C38>=22,"OK",IF(C38<=22,"LESS")) -> OK | D40: =IF(D38>=22,"OK",IF(D38<=22,"LESS")) -> OK | E40: =IF(E38>=22,"OK",IF(E38<=22,"LESS")) -> OK | F40: =IF(F38>=22,"OK",IF(F38<=22,"LESS")) -> OK | G40: =IF(G38>=22,"OK",IF(G38<=22,"LESS")) -> OK | H40: =IF(H38>=22,"OK",IF(H38<=22,"LESS")) -> OK | I40: =IF(I38>=22,"OK",IF(I38<=22,"LESS")) -> OK | ... Q40: =IF(Q38>=22,"OK",IF(Q38<=22,"LESS")) -> OK
A43: Done by | B43: RAHUL
A45: Comment

Sheet 10
A1: Station: | B1: BHATAGAON RAIPUR
A2: Date: | B2: =$A$9 -> 10-02-2024 01:00 | D2: Power Off | G2: Pw.Off | L2: Link Fail | N2: Link F | P2: Maintenance | R2: Maint.
A3: Report Type: | B3: Mean | D3: Calibration | G3: Calib. | L3: Data Fail | N3: Data F | P3: Invalid | R3: Invalid
A4: Time Base: | B4: 01 Hour | D4: Zero Referrence | G4: Z.Ref | L4: Warm Up | N4: Wm. Up
A7: Date & Time | B7: NO_BHATAGAON | C7: NO2_BHATAGAON | D7: NOX_BHATAGAON | E7: SO2_BHATAGAON | F7: O3_BHATAGAON | G7: PM10_BHATAGAON | H7: PM2_5_BHATAGAON | I7: BENZ_BHATAGAON | J7: WS_BHATAGAON | K7: WD_BHATAGAON | L7: TEMP_BHATAGAON | M7: HUM BHATAGAON | N7: SR_BHATAGAON | O7: RG_BHATAGAON | P7: CO_BHATAGAON | Q7: NH3_BHATAGAON
B8: ug/m3 | C8: ug/m3 | D8: ppb | E8: ug/m3 | F8: ug/m3 | G8: mg/m3 | H8: ug/m3 | I8: ug/m3 | J8: m/sec | K8: deg | L8: degreC | M8: % | N8: w/m2 | O8: mm | P8: ug/m3 | Q8: ug/m3
A9: 10-02-2024 01:00 | B9: 21.5 | C9: 70.7 | D9: 56.9 | E9: 0.13 | F9: 3.56 | G9: 76.56 | H9: 29.64 | I9: 1.53 | J9: 0.16 | K9: 316.39 | L9: 16.18 | M9: 61.64 | N9: 88.7 | O9: 0 | P9: 1.09 | Q9: 8.22
A10: 10-02-2024 02:00 | B10: 16.7 | C10: 66.7 | D10: 50.85 | E10: 0.12 | F10: 3.26 | G10: 64.53 | H10: 26.24 | I10: 1.59 | J10: 0.16 | K10: 321.19 | L10: 14.38 | M10: 62.04 | N10: 88.6 | O10: 0 | P10: 0.88 | Q10: 7.71
