Workbook

Sheet 01
A1: Station: | B1: BHATAGAON RAIPPUR
A2: Date: | B2: =$A$9 -> 01-02-2023 00:15 | D2: Power Off | G2: Pw.Off | L2: Link Fail | N2: Link F | P2: Maintenance | R2: Maint.
A3: Report Type: | B3: Mean | D3: Calibration | G3: Calib. | L3: Data Fail | N3: Data F | P3: Invalid | R3: Invalid
A4: Time Base: | B4: 15 Min | D4: Zero Referrence | G4: Z.Ref | L4: Warm Up | N4: Wm. Up
A7: Date & Time | B7: NO_BHATAGAON | C7: NO2__BHATAGAON | D7: NOX_BHATAGAON | E7: SO2__BHATAGAON | F7: O3__BHATAGAON | G7: PM10__BHATAGAON | H7: PM2_5__BHATAGAON | I7: BENZ__BHATAGAON | J7: WS__BHATAGAON | K7: WD__BHATAGAON | L7: TEMP__BHATAGAON | M7: HUM__BHATAGAON | N7: SR__BHATAGAON | O7: RG__BHATAGAON | P7: CO__BHATAGAON | Q7: NH3__BHATAGAON
B8: ug/m3 | C8: ug/m3 | D8: ppb | E8: ug/m3 | F8: ug/m3 | G8: ug/m3 | H8: ug/m3 | I8: ug/m3 | J8: m/sec | K8: deg | L8: degreC | M8: % | N8: w/m2 | O8: mm | P8: mg/m3 | Q8: ug/m3
A9: 01-02-2023 00:15 | B9: 11.08 | C9: 85.63 | D9: 56.55 | E9: 7.66 | F9: 7.91 | G9: 79.02 | H9: 46.65 | I9: Maint. | J9: 1.43 | K9: 13.81 | L9: 21.97 | M9: 54 | N9: 4.4 | O9: 0 | P9: 1.3 | Q9: 30.33
A10: 01-02-2023 00:30 | B10: 8.62 | C10: 82.5 | D10: 52.85 | E10: 8.31 | F10: 8.41 | G10: 56.77 | H10: 39.98 | I10: Maint. | J10: 1.72 | K10: 14.08 | L10: 21.85 | M10: 54 | N10: 4.3 | O10: 0 | P10: 1.2 | Q10: 29.42
A11: 01-02-2023 00:45 | B11: 6.26 | C11: 77.33 | D11: 48.11 | E11: 7.09 | F11: 8.74 | G11: 38.97 | H11: 34.88 | I11: Maint. | J11: 1.56 | K11: 13.19 | L11: 21.68 | M11: 55 | N11: 4.6 | O11: 0 | P11: 1.1 | Q11: 28.43
A12: 01-02-2023 01:00 | B12: 4.72 | C12: 77.28 | D12: 46.85 | E12: 5.98 | F12: 7.11 | G12: 38.97 | H12: 34.88 | I12: Maint. | J12: 1.75 | K12: 13.63 | L12: 21.52 | M12: 55 | N12: 4.5 | O12: 0 | P12: 1.02 | Q12: 28.94
A13: 01-02-2023 01:15 | B13: 2.94 | C13: 77.5 | D13: 45.54 | E13: 5.92 | F13: 6.42 | G13: 38.97 | H13: 34.88 | I13: Maint. | J13: 1.49 | K13: 11.53 | L13: 21.36 | M13: 56 | N13: 4.6 | O13: 0 | P13: 0.91 | Q13: 29.21
A14: 01-02-2023 01:30 | B14: 2.09 | C14: 73.96 | D14: 42.91 | E14: 5.93 | F14: 6.55 | G14: 44.99 | H14: 27.82 | I14: Maint. | J14: 1.37 | K14: 10.88 | L14: 21.14 | M14: 57 | N14: 4.6 | O14: 0 | P14: 0.87 | Q14: 28.52
A15: 01-02-2023 01:45 | B15: 1.66 | C15: 73.05 | D15: 42.06 | E15: 5.48 | F15: 6.93 | G15: 49.8 | H15: 22.18 | I15: Maint. | J15: 1.26 | K15: 11.49 | L15: 20.93 | M15: 57 | N15: 4.6 | O15: 0 | P15: 0.8 | Q15: 28.22
A16: 01-02-2023 02:00 | B16: 1.33 | C16: 70.17 | D16: 40.2 | E16: 5.3 | F16: 6.12 | G16: 49.8 | H16: 22.18 | I16: Maint. | J16: 1.11 | K16: 9.31 | L16: 20.74 | M16: 58 | N16: 4.6 | O16: 0 | P16: 0.75 | Q16: 27.97
A17: 01-02-2023 02:15 | B17: 1.17 | C17: 70.25 | D17: 40.12 | E17: 5.52 | F17: 5.66 | G17: 49.8 | H17: 22.18 | I17: Maint. | J17: 1.28 | K17: 13.12 | L17: 20.51 | M17: 58 | N17: 4.5 | O17: 0 | P17: 0.71 | Q17: 27.93
A18: 01-02-2023 02:30 | B18: 1.21 | C18: 68.63 | D18: 39.26 | E18: 4.96 | F18: 5.45 | G18: 38.75 | H18: 21.15 | I18: Maint. | J18: 1.27 | K18: 8.39 | L18: 20.33 | M18: 59 | N18: 4.6 | O18: 0 | P18: 0.66 | Q18: 27.29
A19: 01-02-2023 02:45 | B19: 1.41 | C19: 64.75 | D19: 37.28 | E19: 5.32 | F19: 6.48 | G19: 29.9 | H19: 20.32 | I19: Maint. | J19: 1.06 | K19: 10.36 | L19: 20.14 | M19: 60 | N19: 4.5 | O19: 0 | P19: 0.63 | Q19: 26.48
A20: 01-02-2023 03:00 | B20: 1.59 | C20: 65.63 | D20: 37.91 | E20: 5.14 | F20: 5.95 | G20: 29.9 | H20: 20.32 | I20: Maint. | J20: 0.88 | K20: 9.52 | L20: 19.89 | M20: 61 | N20: 4.6 | O20: 0 | P20: 0.6 | Q20: 26.08
... A30: 01-02-2023 05:30 | B30: 1.92 | C30: 66.96 | D30: 38.91 | E30: 5.86 | F30: 5.82 | G30: 18.58 | H30: 14.02 | I30: Maint. | J30: 1.11 | K30: 14.48 | L30: 19.13 | M30: 57 | N30: 4.4 | O30: 0 | P30: 0.43 | Q30: 28.23
A31: 01-02-2023 05:45 | B31: 2.24 | C31: 67.99 | D31: 39.73 | E31: 6.37 | F31: 4.97 | G31: Invalid | H31: Invalid | I31: Maint. | J31: 0.57 | K31: 45.93 | L31: 19 | M31: 56 | N31: 4.4 | O31: 0 | P31: 0.43 | Q31: 28.22
A32: 01-02-2023 06:00 | B32: 3.21 | C32: 70.64 | D32: 41.98 | E32: 6.52 | F32: 4.29 | G32: Invalid | H32: Invalid | I32: Maint. | J32: 0.81 | K32: 25.87 | L32: 18.89 | M32: 56 | N32: 4.3 | O32: 0 | P32: 0.42 | Q32: 28.35
A33: 01-02-2023 06:15 | B33: 3.86 | C33: 71.67 | D33: 43.06 | E33: 8.09 | F33: 5.56 | G33: Invalid | H33: Invalid | I33: Maint. | J33: 1.35 | K33: 20.94 | L33: 18.92 | M33: 56 | N33: 4.1 | O33: 0 | P33: 0.42 | Q33: 27.48
A34: 01-02-2023 06:30 | B34: 4.68 | C34: 72.58 | D34: 44.22 | E34: 7.98 | F34: 4.87 | G34: 28.07 | H34: 13.05 | I34: Maint. | J34: 1.13 | K34: 26.56 | L34: 18.83 | M34: 56 | N34: 5.6 | O34: 0 | P34: 0.43 | Q34: 26.41
A35: 01-02-2023 06:45 | B35: 5.53 | C35: 73.53 | D35: 45.43 | E35: 6.73 | F35: 4.34 | G35: 42.92 | H35: 13.65 | I35: Maint. | J35: 0.78 | K35: 25.31 | L35: 18.66 | M35: 56 | N35: 9.6 | O35: 0 | P35: 0.43 | Q35: 25.92
A36: 01-02-2023 07:00 | B36: 6.34 | C36: 73.69 | D36: 46.17 | E36: 6.29 | F36: 4.26 | G36: 42.92 | H36: 13.65 | I36: Maint. | J36: 0.82 | K36: 19.09 | L36: 18.63 | M36: 55 | N36: 17.8 | O36: 0 | P36: 0.44 | Q36: 26.26
A37: 01-02-2023 07:15 | B37: 7.14 | C37: 73.44 | D37: 46.68 | E37: 6.38 | F37: 4.53 | G37: 42.92 | H37: 13.65 | I37: Maint. | J37: 0.84 | K37: 17.62 | L37: 18.78 | M37: 55 | N37: 27.3 | O37: 0 | P37: 0.47 | Q37: 26.38
A38: 01-02-2023 07:30 | B38: 7.31 | C38: 75.05 | D38: 47.69 | E38: 5.9 | F38: 4.79 | G38: 39.64 | H38: 16.19 | I38: Maint. | J38: 0.93 | K38: 19.77 | L38: 19.07 | M38: 54 | N38: 51 | O38: 0 | P38: 0.51 | Q38: 26.25
A39: 01-02-2023 07:45 | B39: 7.72 | C39: 76.34 | D39: 48.74 | E39: 6.44 | F39: 4.75 | G39: 37.01 | H39: 18.23 | I39: Maint. | J39: 0.93 | K39: 20.58 | L39: 19.54 | M39: 53 | N39: 94.9 | O39: 0 | P39: 0.53 | Q39: 26.18
A40: 01-02-2023 08:00 | B40: 8.86 | C40: 77.72 | D40: 50.41 | E40: 4.12 | F40: 4.4 | G40: 37.01 | H40: 18.23 | I40: Maint. | J40: 0.75 | K40: 41.37 | L40: 20.34 | M40: 50 | N40: 142.8 | O40: 0 | P40: 0.55 | Q40: 26.47
A41: 01-02-2023 08:15 | B41: 9.03 | C41: 79.16 | D41: 51.35 | E41: 5.79 | F41: 4.12 | G41: 37.01 | H41: 18.23 | I41: Maint. | J41: 0.8 | K41: 50.52 | L41: 21.2 | M41: 48 | N41: 216.3 | O41: 0 | P41: 0.57 | Q41: 27.91
A42: 01-02-2023 08:30 | B42: 8.89 | C42: 80.42 | D42: 51.93 | E42: 5.66 | F42: 3.95 | G42: 43.27 | H42: 17.21 | I42: Maint. | J42: 0.62 | K42: 57.95 | L42: 21.8 | M42: 47 | N42: 233.5 | O42: 0 | P42: 0.58 | Q42: 28.23
A43: 01-02-2023 08:45 | B43: 9 | C43: 81.37 | D43: 52.54 | E43: 5.51 | F43: 3.93 | G43: 48.27 | H43: 16.4 | I43: Maint. | J43: 0.48 | K43: 65.41 | L43: 22.52 | M43: 46 | N43: 299.6 | O43: 0 | P43: 0.58 | Q43: 28.47
A44: 01-02-2023 09:00 | B44: 9.16 | C44: 82.32 | D44: 53.19 | E44: 5.69 | F44: 3.95 | G44: 48.27 | H44: 16.4 | I44: Maint. | J44: 0.64 | K44: 63.82 | L44: 23.28 | M44: 44 | N44: 361.9 | O44: 0 | P44: 0.59 | Q44: 28.85
A45: 01-02-2023 09:15 | B45: 9.92 | C45: 83.71 | D45: 54.56 | E45: 5.65 | F45: 4 | G45: 48.27 | H45: 16.4 | I45: Maint. | J45: 1.41 | K45: 18.25 | L45: 25.46 | M45: 39 | N45: 376 | O45: 0 | P45: 0.62 | Q45: 28.98
... A92: 01-02-2023 21:00 | B92: 118.09 | C92: 145.26 | D92: 175.28 | E92: 7.15 | F92: 3.56 | G92: 137.94 | H92: 47.3 | I92: Maint. | J92: 0.11 | K92: 276.44 | L92: 20.8 | M92: 54 | N92: 4.2 | O92: 0 | P92: 2.35 | Q92: 38.27
A93: 01-02-2023 21:15 | B93: 128.44 | C93: 148.89 | D93: 185.59 | E93: 7.13 | F93: 3.66 | G93: 137.94 | H93: 47.3 | I93: Maint. | J93: Maint. | K93: 235.57 | L93: 20.59 | M93: 57 | N93: 4.3 | O93: 0 | P93: 2.44 | Q93: 39.21
A94: 01-02-2023 21:30 | B94: 138.5 | C94: 150.03 | D94: 194.28 | E94: 6.96 | F94: 3.64 | G94: 168.29 | H94: 56.47 | I94: Maint. | J94: 0.21 | K94: 17.01 | L94: 20.22 | M94: 63 | N94: 4.2 | O94: 0 | P94: 2.55 | Q94: 40.47
A95: 01-02-2023 21:45 | B95: 149.65 | C95: 154.41 | D95: 205.63 | E95: 7.02 | F95: 3.51 | G95: 192.56 | H95: 63.81 | I95: Maint. | J95: 0.06 | K95: 357.59 | L95: 19.88 | M95: 62 | N95: 4.5 | O95: 0 | P95: 2.77 | Q95: 41.61
A96: 01-02-2023 22:00 | B96: 151.1 | C96: 153.1 | D96: 206.08 | E96: 7.14 | F96: 3.45 | G96: 192.56 | H96: 63.81 | I96: Maint. | J96: 0.13 | K96: 296.91 | L96: 20.19 | M96: 59 | N96: 3.9 | O96: 0 | P96: 2.85 | Q96: 43.57
A97: 01-02-2023 22:15 | B97: 150.31 | C97: 151.47 | D97: 204.54 | E97: 6.93 | F97: 3.5 | G97: 192.56 | H97: 63.81 | I97: Maint. | J97: 0.3 | K97: 24.63 | L97: 19.78 | M97: 63 | N97: 4 | O97: 0 | P97: 2.88 | Q97: 44.9
...

Sheet 02
A1: Station: | B1: BHATAGAON RAIPUR
A2: Date: | B2: =$A$9 -> 02-02-2023 00:15 | D2: Power Off | G2: Pw.Off | L2: Link Fail | N2: Link F | P2: Maintenance | R2: Maint.
A3: Report Type: | B3: Mean | D3: Calibration | G3: Calib. | L3: Data Fail | N3: Data F | P3: Invalid | R3: Invalid
A4: Time Base: | B4: 15 Min | D4: Zero Referrence | G4: Z.Ref | L4: Warm Up | N4: Wm. Up
A7: Date & Time | B7: NO_BHATAGAON | C7: NO2__BHATAGAON | D7: NOX_BHATAGAON | E7: SO2__BHATAGAON | F7: O3__BHATAGAON | G7: PM10__BHATAGAON | H7: PM2_5__BHATAGAON | I7: BENZ__BHATAGAON | J7: WS__BHATAGAON | K7: WD__BHATAGAON | L7: TEMP__BHATAGAON | M7: HUM__BHATAGAON | N7: SR__BHATAGAON | O7: RG__BHATAGAON | P7: CO__BHATAGAON | Q7: NH3__BHATAGAON
B8: ug/m3 | C8: ug/m3 | D8: ppb | E8: ug/m3 | F8: ug/m3 | G8: ug/m3 | H8: ug/m3 | I8: ug/m3 | J8: m/sec | K8: deg | L8: degreC | M8: % | N8: w/m2 | O8: mm | P8: mg/m3 | Q8: ug/m3
A9: 02-02-2023 00:15 | B9: 103.42 | C9: 133.39 | D9: 156.96 | E9: 7.56 | F9: 3.68 | G9: 137.82 | H9: 68.24 | I9: Maint. | J9: 0.31 | K9: 96.56 | L9: 20.47 | M9: 39 | N9: 3.9 | O9: 0 | P9: 2.62 | Q9: 41.45
A10: 02-02-2023 00:30 | B10: 98.63 | C10: 129.77 | D10: 151.13 | E10: 7.86 | F10: 3.69 | G10: 140.4 | H10: 62.76 | I10: Maint. | J10: 0.23 | K10: 50.39 | L10: 20.07 | M10: 38 | N10: 4.1 | O10: 0 | P10: 2.57 | Q10: 40.23
A11: 02-02-2023 00:45 | B11: 94.83 | C11: 127.93 | D11: 147.07 | E11: 7.29 | F11: 3.66 | G11: 142.37 | H11: 58.37 | I11: Maint. | J11: 0.48 | K11: 26.28 | L11: 19.91 | M11: 37 | N11: 3.7 | O11: 0 | P11: 2.54 | Q11: 39.51
A12: 02-02-2023 01:00 | B12: 90.13 | C12: 123.07 | D12: 140.61 | E12: 7.05 | F12: 3.99 | G12: 142.37 | H12: 58.37 | I12: Maint. | J12: 0.46 | K12: 29.29 | L12: 19.82 | M12: 36 | N12: 3.9 | O12: 0 | P12: 2.46 | Q12: 39.21
A13: 02-02-2023 01:15 | B13: 84.23 | C13: 120.73 | D13: 134.58 | E13: 6.9 | F13: 4.32 | G13: 142.37 | H13: 58.37 | I13: Maint. | J13: 0.57 | K13: 25.57 | L13: 19.64 | M13: 35 | N13: 3.7 | O13: 0 | P13: 2.19 | Q13: 38.85
A14: 02-02-2023 01:30 | B14: 79.11 | C14: 113.72 | D14: 126.62 | E14: 6.96 | F14: 4.02 | G14: 111.63 | H14: 53.72 | I14: Maint. | J14: 0.36 | K14: 34.87 | L14: 19.57 | M14: 32 | N14: 4.1 | O14: 0 | P14: 2.19 | Q14: 38.17
A15: 02-02-2023 01:45 | B15: 74.54 | C15: 111.61 | D15: 121.78 | E15: 6.89 | F15: 3.85 | G15: 87.04 | H15: 49.99 | I15: Maint. | J15: 0.31 | K15: 69.39 | L15: 19.21 | M15: 32 | N15: 4.2 | O15: 0 | P15: 2.11 | Q15: 37.6
A16: 02-02-2023 02:00 | B16: 71.69 | C16: 110.67 | D16: 118.98 | E16: 6.44 | F16: 3.56 | G16: 87.04 | H16: 49.99 | I16: Maint. | J16: 0.26 | K16: 54.58 | L16: 18.77 | M16: 34 | N16: 4.3 | O16: 0 | P16: 2 | Q16: 37.87
A17: 02-02-2023 02:15 | B17: 66.21 | C17: 107.9 | D17: 113.06 | E17: 6.42 | F17: 3.6 | G17: 87.04 | H17: 49.99 | I17: Maint. | J17: 0.88 | K17: 14.35 | L17: 18.66 | M17: 35 | N17: 3.4 | O17: 0 | P17: 1.88 | Q17: 38.09
A18: 02-02-2023 02:30 | B18: 59.53 | C18: 104.25 | D18: 105.69 | E18: 6.6 | F18: 3.73 | G18: 68.88 | H18: 41.67 | I18: Maint. | J18: 1.03 | K18: 16.55 | L18: 18.73 | M18: 33 | N18: 3.6 | O18: 0 | P18: 1.75 | Q18: 36.93
A19: 02-02-2023 02:45 | B19: 53.08 | C19: 100.73 | D19: 98.57 | E19: 7.35 | F19: 3.76 | G19: 54.35 | H19: 35.01 | I19: Maint. | J19: 1.17 | K19: 21.84 | L19: 18.56 | M19: 37 | N19: 3.9 | O19: 0 | P19: 1.65 | Q19: 35.56
A20: 02-02-2023 03:00 | B20: 47.68 | C20: 98.43 | D20: 92.97 | E20: 8.08 | F20: 3.57 | G20: 54.35 | H20: 35.01 | I20: Maint. | J20: 0.99 | K20: 15.12 | L20: 18.37 | M20: 40 | N20: 4.2 | O20: 0 | P20: 1.59 | Q20: 34.43
... A104: 02-02-2023 24:00 | B104: 256.28 | C104: 197.87 | D104: 315.13 | E104: 5.73 | F104: 3.65 | G104: 220.5 | H104: 78.34 | I104: Maint. | J104: 0.07 | K104: 335.78 | L104: 16.11 | M104: 68 | N104: 4.2 | O104: 0 | P104: 4.42 | Q104: 50.88
A106: Min | B106: =MIN(B9:B104) -> 6.23 | C106: =MIN(C9:C104) -> 85.24 | D106: =MIN(D9:D104) -> 52.76 | E106: =MIN(E9:E104) -> 4.3 | F106: =MIN(F9:F104) -> 3.48 | G106: =MIN(G9:G104) -> 33.09 | H106: =MIN(H9:H104) -> 17.9 | I106: =MIN(I9:I104) -> 0 | ... Q106: =MIN(Q9:Q104) -> 26.42
A107: Max | B107: =MAX(B9:B104) -> 256.28 | C107: =MAX(C9:C104) -> 198.56 | D107: =MAX(D9:D104) -> 315.13 | E107: =MAX(E9:E104) -> 15.74 | F107: =MAX(F9:F104) -> 9.06 | G107: =MAX(G9:G104) -> 221.16 | H107: =MAX(H9:H104) -> 78.34 | I107: =MAX(I9:I104) -> 0 | ... Q107: =MAX(Q9:Q104) -> 50.88
A108: Avg | B108: =AVERAGE(B9:B104) -> 57.548125 | C108: =AVERAGE(C9:C104) -> 109.65646 | D108: =AVERAGE(D9:D104) -> 107.08094 | E108: =AVERAGE(E9:E104) -> 7.8265625 | F108: =AVERAGE(F9:F104) -> 4.1801042 | G108: =AVERAGE(G9:G104) -> 98.808021 | H108: =AVERAGE(H9:H104) -> 39.066146 | I108: =AVERAGE(I9:I104) -> #DIV/0! | ... Q108: =AVERAGE(Q9:Q104) -> 32.355833
A109: Stdev | B109: =STDEV(B9:B104) -> 63.541323 | C109: =STDEV(C9:C104) -> 30.766154 | D109: =STDEV(D9:D104) -> 67.57129 | E109: =STDEV(E9:E104) -> 1.5559007 | F109: =STDEV(F9:F104) -> 0.97969006 | G109: =STDEV(G9:G104) -> 57.749373 | H109: =STDEV(H9:H104) -> 17.285832 | I109: =STDEV(I9:I104) -> #DIV/0! | ... Q109: =STDEV(Q9:Q104) -> 6.25639
A110: Num | B110: =COUNT(B9:B104) -> 96 | C110: =COUNT(C9:C104) -> 96 | D110: =COUNT(D9:D104) -> 96 | E110: =COUNT(E9:E104) -> 96 | F110: =COUNT(F9:F104) -> 96 | G110: =COUNT(G9:G104) -> 96 | H110: =COUNT(H9:H104) -> 96 | I110: =COUNT(I9:I104)+96 -> 96 | J110: =COUNT(J9:J104) -> 96 | K110: =COUNT(K9:K104) -> 96 | L110: =COUNT(L9:L104) -> 96 | M110: =COUNT(M9:M104) -> 96 | N110: =COUNT(N9:N104) -> 96 | O110: =COUNT(O9:O104) -> 96 | P110: =COUNT(P9:P104) -> 96 | Q110: =COUNT(Q9:Q104) -> 96
A111: DCR | B111: =IF(B110>=87,">90%",IF(B110<=87,"<90%")) -> >90% | C111: =IF(C110>=87,">90%",IF(C110<=87,"<90%")) -> >90% | D111: =IF(D110>=87,">90%",IF(D110<=87,"<90%")) -> >90% | E111: =IF(E110>=87,">90%",IF(E110<=87,"<90%")) -> >90% | F111: =IF(F110>=87,">90%",IF(F110<=87,"<90%")) -> >90% | G111: =IF(G110>=87,">90%",IF(G110<=87,"<90%")) -> >90% | H111: =IF(H110>=87,">90%",IF(H110<=87,"<90%")) -> >90% | I111: =IF(I110>=87,">90%",IF(I110<=87,"<90%")) -> >90% | ... Q111: =IF(Q110>=87,">90%",IF(Q110<=87,"<90%")) -> >90%
A112: Status | B112: =IF(B110>=87,"OK",IF(B110<=87,"LESS")) -> OK | C112: =IF(C110>=87,"OK",IF(C110<=87,"LESS")) -> OK | D112: =IF(D110>=87,"OK",IF(D110<=87,"LESS")) -> OK | E112: =IF(E110>=87,"OK",IF(E110<=87,"LESS")) -> OK | F112: =IF(F110>=87,"OK",IF(F110<=87,"LESS")) -> OK | G112: =IF(G110>=87,"OK",IF(G110<=87,"LESS")) -> OK | H112: =IF(H110>=87,"OK",IF(H110<=87,"LESS")) -> OK | I112: =IF(I110>=87,"OK",IF(I110<=87,"LESS")) -> OK | ... Q112: =IF(Q110>=87,"OK",IF(Q110<=87,"LESS")) -> OK
A115: Done by | B115: RK
A117: Comment

Sheet 03
A1: Station: | B1: BHATAGAON RAIPUR
A2: Date: | B2: =$A$9 -> 03-02-2023 00:15 | D2: Power Off | G2: Pw.Off | L2: Link Fail | N2: Link F | P2: Maintenance | R2: Maint.
A3: Report Type: | B3: Mean | D3: Calibration | G3: Calib. | L3: Data Fail | N3: Data F | P3: Invalid | R3: Invalid
A4: Time Base: | B4: 15 Min | D4: Zero Referrence | G4: Z.Ref | L4: Warm Up | N4: Wm. Up
A7: Date & Time | B7: NO_BHATAGAON | C7: NO2__BHATAGAON | D7: NOX_BHATAGAON | E7: SO2__BHATAGAON | F7: O3__BHATAGAON | G7: PM10__BHATAGAON | H7: PM2_5__BHATAGAON | I7: BENZ__BHATAGAON | J7: WS__BHATAGAON | K7: WD__BHATAGAON | L7: TEMP__BHATAGAON | M7: HUM__BHATAGAON | N7: SR__BHATAGAON | O7: RG__BHATAGAON | P7: CO__BHATAGAON | Q7: NH3__BHATAGAON
B8: ug/m3 | C8: ug/m3 | D8: ppb | E8: ug/m3 | F8: ug/m3 | G8: ug/m3 | H8: ug/m3 | I8: ug/m3 | J8: m/sec | K8: deg | L8: degreC | M8: % | N8: w/m2 | O8: mm | P8: mg/m3 | Q8: ug/m3
A9: 03-02-2023 00:15 | B9: 258.3 | C9: 198.29 | D9: 316.98 | E9: 9.15 | F9: 3.56 | G9: 220.5 | H9: 78.34 | I9: Maint. | J9: 0.05 | K9: 347.39 | L9: 15.85 | M9: 69 | N9: 4.4 | O9: 0 | P9: 4.56 | Q9: 50.82
A10: 03-02-2023 00:30 | B10: 260.66 | C10: 198.8 | D10: 319.16 | E10: 9.16 | F10: 3.52 | G10: 200.65 | H10: 79.11 | I10: Maint. | J10: 0.08 | K10: 324.93 | L10: 15.7 | M10: 71 | N10: 4.1 | O10: 0 | P10: 4.7 | Q10: 50.72
A11: 03-02-2023 00:45 | B11: 262.58 | C11: 198.49 | D11: 320.53 | E11: 9.37 | F11: 3.58 | G11: 184.77 | H11: 79.73 | I11: Maint. | J11: 0.02 | K11: 283.15 | L11: 15.79 | M11: 67 | N11: 4 | O11: 0 | P11: 4.82 | Q11: 50.68
A12: 03-02-2023 01:00 | B12: 260.67 | C12: 196.68 | D12: 317.99 | E12: 9.68 | F12: 3.6 | G12: 184.77 | H12: 79.73 | I12: Maint. | J12: 0.06 | K12: 353.57 | L12: 16.44 | M12: 52 | N12: 3.6 | O12: 0 | P12: 4.85 | Q12: 50.47
A13: 03-02-2023 01:15 | B13: 249.09 | C13: 188.76 | D13: 304.34 | E13: 10.47 | F13: 3.5 | G13: 184.77 | H13: 79.73 | I13: Maint. | J13: 0.14 | K13: 214.43 | L13: 16.72 | M13: 53 | N13: 3.4 | O13: 0 | P13: 4.27 | Q13: 49.64
A14: 03-02-2023 01:30 | B14: 241.99 | C14: 182.82 | D14: 295.36 | E14: 9.83 | F14: 3.53 | G14: 184.77 | H14: 87.11 | I14: Maint. | J14: 0.14 | K14: 205 | L14: 17.05 | M14: 48 | N14: 3.4 | O14: 0 | P14: 4.42 | Q14: 48.11
A15: 03-02-2023 01:45 | B15: 233.1 | C15: 178.97 | D15: 286.11 | E15: 10.06 | F15: 3.52 | G15: 254.78 | H15: 93.02 | I15: Maint. | J15: 0.2 | K15: 243.71 | L15: 17.14 | M15: 45 | N15: 3.6 | O15: 0 | P15: 4.31 | Q15: 46.93
A16: 03-02-2023 02:00 | B16: 220.79 | C16: 173.32 | D16: 273.12 | E16: 9.87 | F16: 3.54 | G16: 254.78 | H16: 93.02 | I16: Maint. | J16: 0.14 | K16: 260.14 | L16: 16.75 | M16: 47 | N16: 4.2 | O16: 0 | P16: 4.16 | Q16: 45.91
A17: 03-02-2023 02:15 | B17: 208.25 | C17: 167.01 | D17: 259.59 | E17: 9.62 | F17: 3.58 | G17: 254.78 | H17: 93.02 | I17: Maint. | J17: 0.06 | K17: 100.11 | L17: 16.13 | M17: 48 | N17: 4.2 | O17: 0 | P17: 4.01 | Q17: 44.81
A18: 03-02-2023 02:30 | B18: 195.82 | C18: 160.63 | D18: 246.1 | E18: 9.48 | F18: 3.55 | G18: 217.01 | H18: 96 | I18: Maint. | J18: 0.23 | K18: 49.8 | L18: 16.2 | M18: 49 | N18: 3.7 | O18: 0 | P18: 3.87 | Q18: 43.56
A19: 03-02-2023 02:45 | B19: 184.27 | C19: 155.88 | D19: 234.21 | E19: 9.75 | F19: 3.47 | G19: 217.01 | H19: 98.38 | I19: Maint. | J19: 0.46 | K19: 18.32 | L19: 16.35 | M19: 48 | N19: 3.1 | O19: 0 | P19: 3.73 | Q19: 42.79
A20: 03-02-2023 03:00 | B20: 172.33 | C20: 149.53 | D20: 221.13 | E20: 9.56 | F20: 3.65 | G20: 217.01 | H20: 98.38 | I20: Maint. | J20: 0.45 | K20: 21.13 | L20: 16.31 | M20: 48 | N20: 3.8 | O20: 0 | P20: 3.54 | Q20: 42.53
... A54: 03-02-2023 11:30 | B54: 2.7 | C54: 45.98 | D54: 27.95 | E54: 10.39 | F54: 34.56 | G54: 33.06 | H54: 24.39 | I54: Maint. | J54: 0.74 | K54: 78.87 | L54: 28.89 | M54: 14 | N54: 682.2 | O54: 0 | P54: 0.42 | Q54: 4.5
A55: 03-02-2023 11:45 | B55: 1.78 | C55: 41.64 | D55: 24.82 | E55: 8.65 | F55: 37.27 | G55: Invalid | H55: Invalid | I55: Maint. | J55: 1.26 | K55: 108.58 | L55: 28.3 | M55: 15 | N55: 714.8 | O55: 0 | P55: 0.41 | Q55: 3.09
A56: 03-02-2023 12:00 | B56: 0.83 | C56: 23.56 | D56: 14.08 | E56: 12.69 | F56: 50.65 | G56: Invalid | H56: Invalid | I56: Maint. | J56: 1.22 | K56: 106.41 | L56: 27.72 | M56: 15 | N56: 733.7 | O56: 0 | P56: 0.28 | Q56: 2
A57: 03-02-2023 12:15 | B57: 0.61 | C57: 18.86 | D57: 11.31 | E57: 16.03 | F57: 48.06 | G57: Invalid | H57: Invalid | I57: Maint. | J57: 1.4 | K57: 118.57 | L57: 27.82 | M57: 15 | N57: 736.3 | O57: 0 | P57: 0.24 | Q57: 0.69
A58: 03-02-2023 12:30 | B58: 3.62 | C58: 21.45 | D58: 13.6 | E58: 11.4 | F58: 23.1 | G58: 23.22 | H58: 17.36 | I58: 0.13 | J58: 1.06 | K58: 107.91 | L58: 28.5 | M58: 14 | N58: 725.8 | O58: 0 | P58: 0.24 | Q58: 1.55
A59: 03-02-2023 12:45 | B59: 3.04 | C59: 28.08 | D59: 16.74 | E59: 7.41 | F59: 10.53 | G59: 26.25 | H59: 16 | I59: 0.45 | J59: 0.62 | K59: 49.46 | L59: 29.83 | M59: 14 | N59: 694.4 | O59: 0 | P59: 0.25 | Q59: 3.98
A60: 03-02-2023 13:00 | B60: 3.56 | C60: 32.61 | D60: 19.66 | E60: 6.86 | F60: 7.18 | G60: 26.25 | H60: 16 | I60: 0.45 | J60: 0.53 | K60: 46.2 | L60: 30.54 | M60: 13 | N60: 653.7 | O60: 0 | P60: 0.27 | Q60: 6.29
A61: 03-02-2023 13:15 | B61: 5.86 | C61: 38.63 | D61: 24.83 | E61: 8.41 | F61: 7.65 | G61: 26.25 | H61: 16 | I61: 0.48 | J61: 0.87 | K61: 28.65 | L61: 31.17 | M61: 12 | N61: 610.5 | O61: 0 | P61: 0.3 | Q61: 8.64
A62: 03-02-2023 13:30 | B62: 5.89 | C62: 44.43 | D62: 28.05 | E62: 10.15 | F62: 7.74 | G62: 34.03 | H62: 17.09 | I62: 0.48 | J62: 0.68 | K62: 3.75 | L62: 33.29 | M62: 11 | N62: 580.9 | O62: 0 | P62: 0.35 | Q62: 10.21
A63: 03-02-2023 13:45 | B63: 5.14 | C63: 49.59 | D63: 30.3 | E63: 8.98 | F63: 6.29 | G63: 39.97 | H63: 17.97 | I63: 0.49 | J63: 1.26 | K63: 9.01 | L63: 33.74 | M63: 10 | N63: 543 | O63: 0 | P63: 0.37 | Q63: 11.66
A64: 03-02-2023 14:00 | B64: 5.23 | C64: 54.62 | D64: 33.15 | E64: 8.41 | F64: 6.61 | G64: 39.97 | H64: 17.97 | I64: 0.49 | J64: 0.54 | K64: 64.47 | L64: 32.67 | M64: 10 | N64: 510.1 | O64: 0 | P64: 0.4 | Q64: 13.19
A65: 03-02-2023 14:15 | B65: 5.18 | C65: 58.19 | D65: 35.08 | E65: 7.69 | F65: 5.66 | G65: 39.97 | H65: 17.97 | I65: 0.5 | J65: 1.3 | K65: 15.92 | L65: 31.8 | M65: 11 | N65: 493.9 | O65: 0 | P65: 0.42 | Q65: 15.46
A66: 03-02-2023 14:30 | B66: 5.38 | C66: 60.73 | D66: 36.65 | E66: 7.61 | F66: 6.12 | G66: 45.72 | H66: 18.13 | I66: 0.51 | J66: 1.01 | K66: 5.61 | L66: 32.78 | M66: 11 | N66: 474.5 | O66: 0 | P66: 0.46 | Q66: 16.95
A67: 03-02-2023 14:45 | B67: 5.41 | C67: 65.96 | D67: 39.55 | E67: 9.34 | F67: 7.14 | G67: 50.11 | H67: 18.27 | I67: 0.51 | J67: 0.77 | K67: 344.25 | L67: 33.27 | M67: 11 | N67: 444.2 | O67: 0 | P67: 0.53 | Q67: 17.36
A68: 03-02-2023 15:00 | B68: 4.81 | C68: 71.72 | D68: 42.25 | E68: 7.97 | F68: 6.19 | G68: 50.11 | H68: 18.27 | I68: 0.52 | J68: 1.18 | K68: 3.79 | L68: 33.64 | M68: 11 | N68: 307 | O68: 0 | P68: 0.54 | Q68: 17.74
A69: 03-02-2023 15:15 | B69: 4.95 | C69: 74.62 | D69: 43.96 | E69: 8.15 | F69: 7.07 | G69: 50.11 | H69: 18.27 | I69: 0.51 | J69: 0.98 | K69: 11.76 | L69: 32.1 | M69: 11 | N69: 171.1 | O69: 0 | P69: 0.56 | Q69: 18.4
... A104: 03-02-2023 24:00 | B104: 336.3 | C104: 232.18 | D104: 396.63 | E104: 6.58 | F104: 3.6 | G104: 252.02 | H104: 98.46 | I104: 2.19 | J104: 0.13 | K104: 257.2 | L104: 17.03 | M104: 53 | N104: 4.1 | O104: 0 | P104: 4.69 | Q104: 55.66
A106: Min | B106: =MIN(B9:B104) -> 0.61 | C106: =MIN(C9:C104) -> 18.86 | D106: =MIN(D9:D104) -> 11.31 | E106: =MIN(E9:E104) -> 4.68 | F106: =MIN(F9:F104) -> 3.42 | G106: =MIN(G9:G104) -> 23.22 | H106: =MIN(H9:H104) -> 15.15 | I106: =MIN(I9:I104) -> 0.13 | ... Q106: =MIN(Q9:Q104) -> 0.69
A107: Max | B107: =MAX(B9:B104) -> 352.68 | C107: =MAX(C9:C104) -> 244.11 | D107: =MAX(D9:D104) -> 415.9 | E107: =MAX(E9:E104) -> 17.01 | F107: =MAX(F9:F104) -> 50.65 | G107: =MAX(G9:G104) -> 294.37 | H107: =MAX(H9:H104) -> 98.46 | I107: =MAX(I9:I104) -> 2.19 | ... Q107: =MAX(Q9:Q104) -> 55.83
A108: Avg | B108: =AVERAGE(B9:B104) -> 101.45896 | C108: =AVERAGE(C9:C104) -> 120.2775 | D108: =AVERAGE(D9:D104) -> 147.37042 | E108: =AVERAGE(E9:E104) -> 8.7329167 | F108: =AVERAGE(F9:F104) -> 6.6878125 | G108: =AVERAGE(G9:G104) -> 127.59538 | H108: =AVERAGE(H9:H104) -> 48.527634 | I108: =AVERAGE(I9:I104) -> 0.92234043 | ... Q108: =AVERAGE(Q9:Q104) -> 30.646979
A109: Stdev | B109: =STDEV(B9:B104) -> 104.34094 | C109: =STDEV(C9:C104) -> 55.91222 | D109: =STDEV(D9:D104) -> 113.71017 | E109: =STDEV(E9:E104) -> 2.3443127 | F109: =STDEV(F9:F104) -> 8.3934433 | G109: =STDEV(G9:G104) -> 81.404479 | H109: =STDEV(H9:H104) -> 28.439589 | I109: =STDEV(I9:I104) -> 0.56641977 | ... Q109: =STDEV(Q9:Q104) -> 14.085703
A110: Num | B110: =COUNT(B9:B104) -> 96 | C110: =COUNT(C9:C104) -> 96 | D110: =COUNT(D9:D104) -> 96 | E110: =COUNT(E9:E104) -> 96 | F110: =COUNT(F9:F104) -> 96 | G110: =COUNT(G9:G104) -> 93 | H110: =COUNT(H9:H104) -> 93 | I110: =COUNT(I9:I104)+49 -> 96 | J110: =COUNT(J9:J104) -> 96 | K110: =COUNT(K9:K104) -> 96 | L110: =COUNT(L9:L104) -> 96 | M110: =COUNT(M9:M104) -> 96 | N110: =COUNT(N9:N104) -> 96 | O110: =COUNT(O9:O104) -> 96 | P110: =COUNT(P9:P104) -> 96 | Q110: =COUNT(Q9:Q104) -> 96
...

Sheet 04
A1: Station: | B1: BHATAGAON RAIPUR
A2: Date: | B2: =$A$9 -> 04-02-2023 00:15 | D2: Power Off | G2: Pw.Off | L2: Link Fail | N2: Link F | P2: Maintenance | R2: Maint.
A3: Report Type: | B3: Mean | D3: Calibration | G3: Calib. | L3: Data Fail | N3: Data F | P3: Invalid | R3: Invalid
A4: Time Base: | B4: 15 Min | D4: Zero Referrence | G4: Z.Ref | L4: Warm Up | N4: Wm. Up
A7: Date & Time | B7: NO_BHATAGAON | C7: NO2__BHATAGAON | D7: NOX_BHATAGAON | E7: SO2__BHATAGAON | F7: O3__BHATAGAON | G7: PM10__BHATAGAON | H7: PM2_5__BHATAGAON | I7: BENZ__BHATAGAON | J7: WS__BHATAGAON | K7: WD__BHATAGAON | L7: TEMP__BHATAGAON | M7: HUM__BHATAGAON | N7: SR__BHATAGAON | O7: RG__BHATAGAON | P7: CO__BHATAGAON | Q7: NH3__BHATAGAON
B8: ug/m3 | C8: ug/m3 | D8: ppb | E8: ug/m3 | F8: ug/m3 | G8: ug/m3 | H8: ug/m3 | I8: ug/m3 | J8: m/sec | K8: deg | L8: degreC | M8: % | N8: w/m2 | O8: mm | P8: mg/m3 | Q8: ug/m3
A9: 04-02-2023 00:15 | B9: 319.33 | C9: 222 | D9: 377.41 | E9: 9.1 | F9: 3.46 | G9: 252.02 | H9: 98.46 | I9: 2.23 | J9: 0.07 | K9: 222.27 | L9: 16.81 | M9: 59 | N9: 4.2 | O9: 0 | P9: 4.49 | Q9: 54.24
A10: 04-02-2023 00:30 | B10: 302.95 | C10: 213.37 | D10: 359.51 | E10: 9.51 | F10: 3.25 | G10: 237.38 | H10: 95.11 | I10: 2.19 | J10: 0.05 | K10: 14.88 | L10: 16.06 | M10: 64 | N10: 4.1 | O10: 0 | P10: 4.31 | Q10: 52.43
A11: 04-02-2023 00:45 | B11: 291.82 | C11: 205.9 | D11: 346.46 | E11: 9.33 | F11: 3.51 | G11: 237.38 | H11: 92.44 | I11: 2.11 | J11: 0.06 | K11: 257.6 | L11: 15.81 | M11: 66 | N11: 4.1 | O11: 0 | P11: 4.17 | Q11: 52.05
A12: 04-02-2023 01:00 | B12: 279.76 | C12: 199.68 | D12: 333.36 | E12: 9.2 | F12: 3.78 | G12: 237.38 | H12: 92.44 | I12: 2.04 | J12: 0.12 | K12: 343.77 | L12: 16.1 | M12: 63 | N12: 3.6 | O12: 0 | P12: 4.02 | Q12: 51.28
A13: 04-02-2023 01:15 | B13: 267.27 | C13: 192.78 | D13: 319.54 | E13: 8.77 | F13: 3.43 | G13: 237.38 | H13: 92.44 | I13: 1.99 | J13: 0.11 | K13: 307.82 | L13: 15.85 | M13: 64 | N13: 4.1 | O13: 0 | P13: 3.53 | Q13: 50.11
A14: 04-02-2023 01:30 | B14: 253.64 | C14: 186.62 | D14: 305.21 | E14: 8.58 | F14: 3.55 | G14: 237 | H14: 88.2 | I14: 1.92 | J14: 0.09 | K14: 104.91 | L14: 15.84 | M14: 63 | N14: 4.3 | O14: 0 | P14: 3.56 | Q14: 48.72
A15: 04-02-2023 01:45 | B15: 238.71 | C15: 179.7 | D15: 289.41 | E15: 8.38 | F15: 3.57 | G15: 236.7 | H15: 84.81 | I15: 1.84 | J15: 0.12 | K15: 76.66 | L15: 15.75 | M15: 61 | N15: 4 | O15: 0 | P15: 3.4 | Q15: 47.53
A16: 04-02-2023 02:00 | B16: 225.51 | C16: 173.38 | D16: 275.34 | E16: 8.1 | F16: 3.23 | G16: 236.7 | H16: 84.81 | I16: 1.78 | J16: 0.11 | K16: 249.61 | L16: 15.95 | M16: 60 | N16: 4.1 | O16: 0 | P16: 3.26 | Q16: 46.19
A17: 04-02-2023 02:15 | B17: 209.52 | C17: 166.19 | D17: 258.55 | E17: 8.25 | F17: 3.37 | G17: 236.7 | H17: 84.81 | I17: 1.71 | J17: 0.02 | K17: 282.3 | L17: 15.43 | M17: 62 | N17: 4.2 | O17: 0 | P17: 3.12 | Q17: 44.61
A18: 04-02-2023 02:30 | B18: 198.63 | C18: 160.04 | D18: 246.42 | E18: 7.7 | F18: 3.46 | G18: 179.4 | H18: 77.44 | I18: 1.66 | J18: 0.03 | K18: 307.75 | L18: 15.18 | M18: 63 | N18: 4 | O18: 0 | P18: 3.02 | Q18: 42.77
A19: 04-02-2023 02:45 | B19: 191.65 | C19: 156.97 | D19: 239.13 | E19: 8.45 | F19: 3.45 | G19: 133.55 | H19: 71.55 | I19: 1.62 | J19: 0.09 | K19: 280.4 | L19: 15.37 | M19: 58 | N19: 4.1 | O19: 0 | P19: 2.94 | Q19: 41.74
A20: 04-02-2023 03:00 | B20: 183.6 | C20: 152.97 | D20: 230.47 | E20: 8.12 | F20: 3.48 | G20: 133.55 | H20: 71.55 | I20: 1.57 | J20: 0.13 | K20: 348.86 | L20: 14.97 | M20: 61 | N20: 4.2 | O20: 0 | P20: 2.87 | Q20: 40.94
... A32: 04-02-2023 06:00 | B32: 109.39 | C32: 114.45 | D32: 149.7 | E32: 7.29 | F32: 3.37 | G32: 169.85 | H32: 75.14 | I32: 1.12 | J32: 0.22 | K32: 260.96 | L32: 13.58 | M32: 75 | N32: 4.3 | O32: 0 | P32: 2.17 | Q32: 34.21
A33: 04-02-2023 06:15 | B33: 106.68 | C33: 112.22 | D33: 146.29 | E33: 7.04 | F33: 3.16 | G33: 169.85 | H33: 75.14 | I33: Maint. | J33: 0.17 | K33: 284.38 | L33: 13.35 | M33: 74 | N33: 4.2 | O33: 0 | P33: 2.12 | Q33: 33.3
A34: 04-02-2023 06:30 | B34: 104.1 | C34: 110.4 | D34: 143.22 | E34: 6.78 | F34: 3.29 | G34: 183.36 | H34: 71.91 | I34: Maint. | J34: 0.26 | K34: 249.06 | L34: 13.59 | M34: 70 | N34: 4.6 | O34: 0 | P34: 2.09 | Q34: 32.64
A35: 04-02-2023 06:45 | B35: 102.14 | C35: 109.23 | D35: 141 | E35: 6.54 | F35: 3.4 | G35: 194.16 | H35: 69.32 | I35: Maint. | J35: 0.21 | K35: 263 | L35: 13.56 | M35: 69 | N35: 9.5 | O35: 0 | P35: 2.08 | Q35: 32.33
A36: 04-02-2023 07:00 | B36: 100.98 | C36: 108.77 | D36: 139.82 | E36: 7.02 | F36: 3.48 | G36: 194.16 | H36: 69.32 | I36: Maint. | J36: 0.12 | K36: 296.92 | L36: 13.35 | M36: 69 | N36: 19 | O36: 0 | P36: 2.07 | Q36: 32.35
A37: 04-02-2023 07:15 | B37: 99.08 | C37: 108.36 | D37: 138.07 | E37: 6.72 | F37: 3.47 | G37: 194.16 | H37: 69.32 | I37: Maint. | J37: 0.15 | K37: 342.13 | L37: 13.51 | M37: 70 | N37: 28.6 | O37: 0 | P37: 2.01 | Q37: 32.2
A38: 04-02-2023 07:30 | B38: 102.5 | C38: 110.25 | D38: 141.85 | E38: 6.88 | F38: 3.43 | G38: 172.07 | H38: 70.18 | I38: Maint. | J38: 0.13 | K38: 349.45 | L38: 13.79 | M38: 71 | N38: 40.1 | O38: 0 | P38: 2.1 | Q38: 32.22
A39: 04-02-2023 07:45 | B39: 106.89 | C39: 113.46 | D39: 147.15 | E39: 7.48 | F39: 3.49 | G39: 154.4 | H39: 70.86 | I39: Maint. | J39: 0.06 | K39: 148.78 | L39: 14.99 | M39: 65 | N39: 135.4 | O39: 0 | P39: 2.12 | Q39: 33.42
A40: 04-02-2023 08:00 | B40: 109.42 | C40: 116.75 | D40: 150.99 | E40: 5.16 | F40: 3.63 | G40: 154.4 | H40: 70.86 | I40: Maint. | J40: 0.22 | K40: 23.45 | L40: 19.11 | M40: 51 | N40: 221.2 | O40: 0 | P40: 2.15 | Q40: 34.34
A41: 04-02-2023 08:15 | B41: 113.51 | C41: 121.61 | D41: 156.95 | E41: 7.61 | F41: 3.54 | G41: 154.4 | H41: 70.86 | I41: Maint. | J41: 0.22 | K41: 28.14 | L41: 21.75 | M41: 46 | N41: 266.5 | O41: 0 | P41: 2.21 | Q41: 34.76
A42: 04-02-2023 08:30 | B42: 114.83 | C42: 126.85 | D42: 160.9 | E42: 7.68 | F42: 3.43 | G42: 179.29 | H42: 76.93 | I42: Maint. | J42: 0.11 | K42: 72.03 | L42: 23.64 | M42: 40 | N42: 308.6 | O42: 0 | P42: 2.23 | Q42: 35.09
A43: 04-02-2023 08:45 | B43: 113.05 | C43: 131.46 | D43: 162.02 | E43: 7.67 | F43: 3.58 | G43: 199.2 | H43: 81.79 | I43: Maint. | J43: 0.2 | K43: 93.66 | L43: 24.56 | M43: 34 | N43: 361.1 | O43: 0 | P43: 2.22 | Q43: 35.35
A44: 04-02-2023 09:00 | B44: 108.71 | C44: 134.43 | D44: 160.18 | E44: 8.02 | F44: 3.69 | G44: 199.2 | H44: 81.79 | I44: Maint. | J44: 0.91 | K44: 112.81 | L44: 23.3 | M44: 30 | N44: 417.8 | O44: 0 | P44: 2.17 | Q44: 35.4
... A59: 04-02-2023 12:45 | B59: 29.86 | C59: 113.66 | D59: 85.48 | E59: 6.95 | F59: 3.94 | G59: 52.78 | H59: 29.4 | I59: Maint. | J59: 0.39 | K59: 143.17 | L59: 29.8 | M59: 16 | N59: 641.7 | O59: 0 | P59: 1.11 | Q59: 31.59
A60: 04-02-2023 13:00 | B60: 26.57 | C60: 114.13 | D60: 83.11 | E60: 7.06 | F60: 4.11 | G60: 52.78 | H60: 29.4 | I60: 0.07 | J60: 0.28 | K60: 9.29 | L60: 31.57 | M60: 16 | N60: 585 | O60: 0 | P60: 1.06 | Q60: 31.09
A61: 04-02-2023 13:15 | B61: 24.17 | C61: 114.26 | D61: 81.25 | E61: 7.33 | F61: 4.41 | G61: 52.78 | H61: 29.4 | I61: 0.74 | J61: 0.23 | K61: 333.81 | L61: 31.17 | M61: 16 | N61: 549.8 | O61: 0 | P61: 1.09 | Q61: 30.39
A62: 04-02-2023 13:30 | B62: 20.63 | C62: 109.33 | D62: 75.69 | E62: 8.47 | F62: 7.27 | G62: 52.11 | H62: 27.31 | I62: 0.72 | J62: 0.19 | K62: 341.99 | L62: 32.06 | M62: 15 | N62: 509.5 | O62: 0 | P62: 1.1 | Q62: 29.46
A63: 04-02-2023 13:45 | B63: 16.6 | C63: 104.01 | D63: 69.52 | E63: 8.35 | F63: 8.33 | G63: 51.56 | H63: 25.64 | I63: 0.7 | J63: 0.3 | K63: 61.15 | L63: 30.6 | M63: 16 | N63: 470.6 | O63: 0 | P63: 1.07 | Q63: 29.64
A64: 04-02-2023 14:00 | B64: 16.73 | C64: 109.1 | D64: 72.44 | E64: 8.34 | F64: 6.99 | G64: 51.56 | H64: 25.64 | I64: 0.69 | J64: 0.58 | K64: 94.73 | L64: 31.38 | M64: 16 | N64: 441.8 | O64: 0 | P64: 1.08 | Q64: 30.17
A65: 04-02-2023 14:15 | B65: 14.2 | C65: 100.17 | D65: 65.48 | E65: 10.07 | F65: 9.95 | G65: 51.56 | H65: 25.64 | I65: 0.69 | J65: 0.48 | K65: 101.59 | L65: 29.61 | M65: 17 | N65: 435.4 | O65: 0 | P65: 1.03 | Q65: 30.98
A66: 04-02-2023 14:30 | B66: 14.41 | C66: 100.96 | D66: 66.08 | E66: 9.42 | F66: 9.72 | G66: 57.42 | H66: 26.02 | I66: 0.69 | J66: 0.85 | K66: 357.23 | L66: 31.94 | M66: 13 | N66: 453.2 | O66: 0 | P66: 0.99 | Q66: 31.14
A67: 04-02-2023 14:45 | B67: 13.66 | C67: 104.66 | D67: 67.53 | E67: 6.34 | F67: 5.54 | G67: 62.1 | H67: 26.31 | I67: 0.67 | J67: 0.87 | K67: 356.43 | L67: 33.46 | M67: 11 | N67: 461 | O67: 0 | P67: 1.01 | Q67: 30.99
...

Sheet 05
A1: Station: | B1: BHATAGAON RAIPUR
A2: Date: | B2: =$A$9 -> 05-02-2023 00:15 | D2: Power Off | G2: Pw.Off | L2: Link Fail | N2: Link F | P2: Maintenance | R2: Maint.
A3: Report Type: | B3: Mean | D3: Calibration | G3: Calib. | L3: Data Fail | N3: Data F | P3: Invalid | R3: Invalid
A4: Time Base: | B4: 15 Min | D4: Zero Referrence | G4: Z.Ref | L4: Warm Up | N4: Wm. Up
A7: Date & Time | B7: NO_BHATAGAON | C7: NO2__BHATAGAON | D7: NOX_BHATAGAON | E7: SO2__BHATAGAON | F7: O3__BHATAGAON | G7: PM10__BHATAGAON | H7: PM2_5__BHATAGAON | I7: BENZ__BHATAGAON | J7: WS__BHATAGAON | K7: WD__BHATAGAON | L7: TEMP__BHATAGAON | M7: HUM__BHATAGAON | N7: SR__BHATAGAON | O7: RG__BHATAGAON | P7: CO__BHATAGAON | Q7: NH3__BHATAGAON
B8: ug/m3 | C8: ug/m3 | D8: ppb | E8: ug/m3 | F8: ug/m3 | G8: ug/m3 | H8: ug/m3 | I8: ug/m3 | J8: m/sec | K8: deg | L8: degreC | M8: % | N8: w/m2 | O8: mm | P8: mg/m3 | Q8: ug/m3
A9: 05-02-2023 00:15 | B9: 223.18 | C9: 186.06 | D9: 280.47 | E9: 8.25 | F9: 3.63 | G9: 164.07 | H9: 68.93 | I9: 1.86 | J9: 0.04 | K9: 318.97 | L9: 17.07 | M9: 53 | N9: 4.4 | O9: 0 | P9: 3.54 | Q9: 47.07
A10: 05-02-2023 00:30 | B10: 209.87 | C10: 177.32 | D10: 264.97 | E10: 8.42 | F10: 3.6 | G10: 136.92 | H10: 64.67 | I10: 1.83 | J10: 0.08 | K10: 350.93 | L10: 16.54 | M10: 57 | N10: 4.2 | O10: 0 | P10: 3.41 | Q10: 45.9
A11: 05-02-2023 00:45 | B11: 200.5 | C11: 173.72 | D11: 255.47 | E11: 8.19 | F11: 3.46 | G11: 115.21 | H11: 61.41 | I11: 1.78 | J11: 0.09 | K11: 295.39 | L11: 16.43 | M11: 54 | N11: 4.1 | O11: 0 | P11: 3.29 | Q11: 44.75
A12: 05-02-2023 01:00 | B12: 189.85 | C12: 166.82 | D12: 243.12 | E12: 7.49 | F12: 3.4 | G12: 115.21 | H12: 61.41 | I12: 1.74 | J12: 0.13 | K12: 334.87 | L12: 16.34 | M12: 55 | N12: 4.2 | O12: 0 | P12: 3.17 | Q12: 43.89
A13: 05-02-2023 01:15 | B13: 181.42 | C13: 162.57 | D13: 234.01 | E13: 7.84 | F13: 3.39 | G13: 115.21 | H13: 61.41 | I13: 1.69 | J13: 0.06 | K13: 196.51 | L13: 16.15 | M13: 56 | N13: 4.3 | O13: 0 | P13: 2.78 | Q13: 42.92
A14: 05-02-2023 01:30 | B14: 171.18 | C14: 153.66 | D14: 220.88 | E14: 7.67 | F14: 3.65 | G14: 105.3 | H14: 57.14 | I14: 1.63 | J14: 0.16 | K14: 342.49 | L14: 15.99 | M14: 57 | N14: 4.2 | O14: 0 | P14: 2.83 | Q14: 42.11
A15: 05-02-2023 01:45 | B15: 165.11 | C15: 152.06 | D15: 215.14 | E15: 8.14 | F15: 3.56 | G15: 97.37 | H15: 53.73 | I15: 1.57 | J15: 0.05 | K15: 122.15 | L15: 16.08 | M15: 58 | N15: 3.7 | O15: 0 | P15: 2.74 | Q15: 42.23
A16: 05-02-2023 02:00 | B16: 157.34 | C16: 148.73 | D16: 207.07 | E16: 7.95 | F16: 3.63 | G16: 97.37 | H16: 53.73 | I16: 1.53 | J16: 0.03 | K16: 159.12 | L16: 16.04 | M16: 57 | N16: 4 | O16: 0 | P16: 2.65 | Q16: 42.11
A17: 05-02-2023 02:15 | B17: 149.08 | C17: 144.76 | D17: 198.26 | E17: 7.31 | F17: 3.68 | G17: 97.37 | H17: 53.73 | I17: 1.49 | J17: 0.09 | K17: 349.17 | L17: 16.02 | M17: 56 | N17: 4 | O17: 0 | P17: 2.55 | Q17: 41.33
A18: 05-02-2023 02:30 | B18: 141.54 | C18: 141.09 | D18: 190.18 | E18: 7.68 | F18: 3.63 | G18: 106.32 | H18: 52.41 | I18: 1.44 | J18: 0.03 | K18: 53.52 | L18: 16.41 | M18: 51 | N18: 3.5 | O18: 0 | P18: 2.46 | Q18: 40.43
A19: 05-02-2023 02:45 | B19: 133.39 | C19: 137.83 | D19: 181.84 | E19: 7.71 | F19: 3.44 | G19: 113.47 | H19: 51.36 | I19: 1.39 | J19: 0.16 | K19: 230.89 | L19: 16.68 | M19: 49 | N19: 3.8 | O19: 0 | P19: 2.38 | Q19: 39.68
A20: 05-02-2023 03:00 | B20: 124.43 | C20: 134.74 | D20: 172.95 | E20: 7.59 | F20: 3.57 | G20: 113.47 | H20: 51.36 | I20: 1.33 | J20: 0.16 | K20: 271.9 | L20: 16.76 | M20: 48 | N20: 4 | O20: 0 | P20: 2.28 | Q20: 38.72
... A34: 05-02-2023 06:30 | B34: 82.9 | C34: 108.41 | D34: 125.11 | E34: 6.46 | F34: 3.64 | G34: 104.79 | H34: 49.01 | I34: 0.93 | J34: 0.13 | K34: 314.15 | L34: 13.39 | M34: 77 | N34: 5.3 | O34: 0 | P34: 1.64 | Q34: 32.92
A35: 05-02-2023 06:45 | B35: 85.01 | C35: 109.26 | D35: 127.28 | E35: 6.41 | F35: 3.55 | G35: 95.14 | H35: 48.9 | I35: Maint. | J35: 0.15 | K35: 277.01 | L35: 13.18 | M35: 76 | N35: 9.7 | O35: 0 | P35: 1.64 | Q35: 32.8
A36: 05-02-2023 07:00 | B36: 90.27 | C36: 111.63 | D36: 132.81 | E36: 6.4 | F36: 3.47 | G36: 95.14 | H36: 48.9 | I36: Maint. | J36: 0.11 | K36: 325.07 | L36: 13.27 | M36: 78 | N36: 19.5 | O36: 0 | P36: 1.64 | Q36: 32.48
A37: 05-02-2023 07:15 | B37: 98.64 | C37: 115.33 | D37: 141.56 | E37: 6.12 | F37: 3.39 | G37: 95.14 | H37: 48.9 | I37: Maint. | J37: 0.14 | K37: 325.64 | L37: 13.52 | M37: 79 | N37: 29.2 | O37: 0 | P37: 1.62 | Q37: 32.69
A38: 05-02-2023 07:30 | B38: 107.35 | C38: 119.14 | D38: 150.65 | E38: 6.43 | F38: 3.5 | G38: 119.52 | H38: 50.54 | I38: Maint. | J38: 0.18 | K38: 257.59 | L38: 14.46 | M38: 76 | N38: 42.2 | O38: 0 | P38: 1.72 | Q38: 33.08
A39: 05-02-2023 07:45 | B39: 109.39 | C39: 120.51 | D39: 153.04 | E39: 6.62 | F39: 4.02 | G39: 139.01 | H39: 51.85 | I39: Maint. | J39: 0.49 | K39: 207.01 | L39: 16.09 | M39: 69 | N39: 140.9 | O39: 0 | P39: 1.77 | Q39: 33.54
A40: 05-02-2023 08:00 | B40: 105.84 | C40: 119.43 | D40: 149.6 | E40: 5.22 | F40: 3.66 | G40: 139.01 | H40: 51.85 | I40: Maint. | J40: 0.44 | K40: 207.77 | L40: 17.59 | M40: 63 | N40: 223.8 | O40: 0 | P40: 1.76 | Q40: 33.6
A41: 05-02-2023 08:15 | B41: 100.57 | C41: 118.05 | D41: 144.61 | E41: 7.15 | F41: 3.49 | G41: 139.01 | H41: 51.85 | I41: Maint. | J41: 0.06 | K41: 172.41 | L41: 20.2 | M41: 55 | N41: 265.1 | O41: 0 | P41: 1.75 | Q41: 33.37
A42: 05-02-2023 08:30 | B42: 97.03 | C42: 118.72 | D42: 142.14 | E42: 7.2 | F42: 3.48 | G42: 132.11 | H42: 54.9 | I42: Maint. | J42: 0.73 | K42: 169.82 | L42: 21.35 | M42: 51 | N42: 304.2 | O42: 0 | P42: 1.76 | Q42: 33.07
A43: 05-02-2023 08:45 | B43: 92.62 | C43: 119.29 | D43: 138.92 | E43: 6.85 | F43: 3.49 | G43: 126.59 | H43: 57.34 | I43: Maint. | J43: 0.97 | K43: 170.07 | L43: 20.54 | M43: 53 | N43: 343.9 | O43: 0 | P43: 1.75 | Q43: 33.19
A44: 05-02-2023 09:00 | B44: 86.19 | C44: 119.18 | D44: 133.7 | E44: 6.75 | F44: 3.54 | G44: 126.59 | H44: 57.34 | I44: Maint. | J44: 0.69 | K44: 169.57 | L44: 21.7 | M44: 48 | N44: 376.3 | O44: 0 | P44: 1.71 | Q44: 34.09
A45: 05-02-2023 09:15 | B45: 78.41 | C45: 119.67 | D45: 127.73 | E45: 6.59 | F45: 3.54 | G45: 126.59 | H45: 57.34 | I45: Maint. | J45: 0.6 | K45: 167.5 | L45: 22.66 | M45: 45 | N45: 416.1 | O45: 0 | P45: 1.69 | Q45: 34.08
A46: 05-02-2023 09:30 | B46: 70.74 | C46: 121.12 | D46: 122.38 | E46: 6.71 | F46: 3.52 | G46: 113.22 | H46: 56.22 | I46: Maint. | J46: 0.02 | K46: 170.14 | L46: 24.72 | M46: 40 | N46: 451.2 | O46: 0 | P46: 1.67 | Q46: 33.58
... A104: 05-02-2023 24:00 | B104: 183.52 | C104: 184.76 | D104: 247.94 | E104: 5.6 | F104: 3.88 | G104: 190.46 | H104: 68.12 | I104: Maint. | J104: 0.11 | K104: 225.9 | L104: 18.59 | M104: 49 | N104: 3.9 | O104: 0 | P104: 3.19 | Q104: 47.78
A106: Min | B106: =MIN(B9:B104) -> 4.73 | C106: =MIN(C9:C104) -> 88.18 | D106: =MIN(D9:D104) -> 52.31 | E106: =MIN(E9:E104) -> 4.33 | F106: =MIN(F9:F104) -> 2.71 | G106: =MIN(G9:G104) -> 32.42 | H106: =MIN(H9:H104) -> 19.67 | I106: =MIN(I9:I104) -> 0.89 | ... Q106: =MIN(Q9:Q104) -> 28.56
A107: Max | B107: =MAX(B9:B104) -> 223.18 | C107: =MAX(C9:C104) -> 188.98 | D107: =MAX(D9:D104) -> 280.47 | E107: =MAX(E9:E104) -> 19.61 | F107: =MAX(F9:F104) -> 22.08 | G107: =MAX(G9:G104) -> 212.69 | H107: =MAX(H9:H104) -> 68.93 | I107: =MAX(I9:I104) -> 1.86 | ... Q107: =MAX(Q9:Q104) -> 48.51
A108: Avg | B108: =AVERAGE(B9:B104) -> 80.595937 | C108: =AVERAGE(C9:C104) -> 127.26677 | D108: =AVERAGE(D9:D104) -> 133.67813 | E108: =AVERAGE(E9:E104) -> 7.5608333 | F108: =AVERAGE(F9:F104) -> 4.915625 | G108: =AVERAGE(G9:G104) -> 107.54302 | H108: =AVERAGE(H9:H104) -> 46.159271 | I108: =AVERAGE(I9:I104) -> 1.3111538 | ... Q108: =AVERAGE(Q9:Q104) -> 35.451354
A109: Stdev | B109: =STDEV(B9:B104) -> 61.19331 | C109: =STDEV(C9:C104) -> 27.879211 | D109: =STDEV(D9:D104) -> 63.124644 | E109: =STDEV(E9:E104) -> 2.279255 | F109: =STDEV(F9:F104) -> 3.3065319 | G109: =STDEV(G9:G104) -> 54.706714 | H109: =STDEV(H9:H104) -> 15.252285 | I109: =STDEV(I9:I104) -> 0.31688896 | ... Q109: =STDEV(Q9:Q104) -> 5.335989
A110: Num | B110: =COUNT(B9:B104) -> 96 | C110: =COUNT(C9:C104) -> 96 | D110: =COUNT(D9:D104) -> 96 | E110: =COUNT(E9:E104) -> 96 | F110: =COUNT(F9:F104) -> 96 | G110: =COUNT(G9:G104) -> 96 | H110: =COUNT(H9:H104) -> 96 | I110: =COUNT(I9:I104)+70 -> 96 | J110: =COUNT(J9:J104) -> 96 | K110: =COUNT(K9:K104) -> 96 | L110: =COUNT(L9:L104) -> 96 | M110: =COUNT(M9:M104) -> 96 | N110: =COUNT(N9:N104) -> 96 | O110: =COUNT(O9:O104) -> 96 | P110: =COUNT(P9:P104) -> 96 | Q110: =COUNT(Q9:Q104) -> 96
A111: DCR | B111: =IF(B110>=87,">90%",IF(B110<=87,"<90%")) -> >90% | C111: =IF(C110>=87,">90%",IF(C110<=87,"<90%")) -> >90% | D111: =IF(D110>=87,">90%",IF(D110<=87,"<90%")) -> >90% | E111: =IF(E110>=87,">90%",IF(E110<=87,"<90%")) -> >90% | F111: =IF(F110>=87,">90%",IF(F110<=87,"<90%")) -> >90% | G111: =IF(G110>=87,">90%",IF(G110<=87,"<90%")) -> >90% | H111: =IF(H110>=87,">90%",IF(H110<=87,"<90%")) -> >90% | I111: =IF(I110>=87,">90%",IF(I110<=87,"<90%")) -> >90% | ... Q111: =IF(Q110>=87,">90%",IF(Q110<=87,"<90%")) -> >90%
A112: Status | B112: =IF(B110>=87,"OK",IF(B110<=87,"LESS")) -> OK | C112: =IF(C110>=87,"OK",IF(C110<=87,"LESS")) -> OK | D112: =IF(D110>=87,"OK",IF(D110<=87,"LESS")) -> OK | E112: =IF(E110>=87,"OK",IF(E110<=87,"LESS")) -> OK | F112: =IF(F110>=87,"OK",IF(F110<=87,"LESS")) -> OK | G112: =IF(G110>=87,"OK",IF(G110<=87,"LESS")) -> OK | H112: =IF(H110>=87,"OK",IF(H110<=87,"LESS")) -> OK | I112: =IF(I110>=87,"OK",IF(I110<=87,"LESS")) -> OK | ... Q112: =IF(Q110>=87,"OK",IF(Q110<=87,"LESS")) -> OK
A115: Done by | B115: RK
...

Sheet 06
A1: Station: | B1: BHATAGAON RAIPUR
A2: Date: | B2: =$A$9 -> 06-02-2023 00:15 | D2: Power Off | G2: Pw.Off | L2: Link Fail | N2: Link F | P2: Maintenance | R2: Maint.
A3: Report Type: | B3: Mean | D3: Calibration | G3: Calib. | L3: Data Fail | N3: Data F | P3: Invalid | R3: Invalid
A4: Time Base: | B4: 15 Min | D4: Zero Referrence | G4: Z.Ref | L4: Warm Up | N4: Wm. Up
A7: Date & Time | B7: NO_BHATAGAON | C7: NO2__BHATAGAON | D7: NOX_BHATAGAON | E7: SO2__BHATAGAON | F7: O3__BHATAGAON | G7: PM10__BHATAGAON | H7: PM2_5__BHATAGAON | I7: BENZ__BHATAGAON | J7: WS__BHATAGAON | K7: WD__BHATAGAON | L7: TEMP__BHATAGAON | M7: HUM__BHATAGAON | N7: SR__BHATAGAON | O7: RG__BHATAGAON | P7: CO__BHATAGAON | Q7: NH3__BHATAGAON
B8: ug/m3 | C8: ug/m3 | D8: ppb | E8: ug/m3 | F8: ug/m3 | G8: ug/m3 | H8: ug/m3 | I8: ug/m3 | J8: m/sec | K8: deg | L8: degreC | M8: % | N8: w/m2 | O8: mm | P8: mg/m3 | Q8: ug/m3
A9: 06-02-2023 00:15 | B9: 171.66 | C9: 178.92 | D9: 235.21 | E9: 8.22 | F9: 3.57 | G9: 190.46 | H9: 68.12 | I9: Maint. | J9: 0.05 | K9: 331.05 | L9: 18.4 | M9: 50 | N9: 4.2 | O9: 0 | P9: 3.1 | Q9: 46.42
A10: 06-02-2023 00:30 | B10: 162.79 | C10: 174.87 | D10: 225.86 | E10: 8.43 | F10: 3.36 | G10: 145.61 | H10: 63.08 | I10: Maint. | J10: 0.08 | K10: 271.14 | L10: 17.83 | M10: 54 | N10: 4.3 | O10: 0 | P10: 3.03 | Q10: 45.12
A11: 06-02-2023 00:45 | B11: 152.5 | C11: 170.02 | D11: 214.94 | E11: 8.37 | F11: 3.43 | G11: 109.73 | H11: 59.04 | I11: Maint. | J11: 0.14 | K11: 335.58 | L11: 17.5 | M11: 57 | N11: 4.3 | O11: 0 | P11: 2.95 | Q11: 44.09
A12: 06-02-2023 01:00 | B12: 143.88 | C12: 164.87 | D12: 205.18 | E12: 7.98 | F12: 3.59 | G12: 109.73 | H12: 59.04 | I12: Maint. | J12: 0.15 | K12: 310.1 | L12: 17.68 | M12: 54 | N12: 3.7 | O12: 0 | P12: 2.89 | Q12: 42.72
A13: 06-02-2023 01:15 | B13: 138.76 | C13: 161.73 | D13: 199.34 | E13: 7.76 | F13: 3.41 | G13: 109.73 | H13: 59.04 | I13: Maint. | J13: 0.08 | K13: 330.26 | L13: 17.14 | M13: 56 | N13: 4.6 | O13: 0 | P13: 2.57 | Q13: 41.63
A14: 06-02-2023 01:30 | B14: 133.99 | C14: 158.9 | D14: 193.96 | E14: 8.12 | F14: 3.48 | G14: 109.01 | H14: 56.74 | I14: Maint. | J14: 0.14 | K14: 258.09 | L14: 17.2 | M14: 57 | N14: 4.1 | O14: 0 | P14: 2.64 | Q14: 40.75
A15: 06-02-2023 01:45 | B15: 129.84 | C15: 155.65 | D15: 188.83 | E15: 7.85 | F15: 3.35 | G15: 108.43 | H15: 54.9 | I15: Maint. | J15: 0.09 | K15: 310.4 | L15: 16.8 | M15: 60 | N15: 4.6 | O15: 0 | P15: 2.61 | Q15: 40.3
A16: 06-02-2023 02:00 | B16: 126.74 | C16: 152.88 | D16: 184.82 | E16: 7.76 | F16: 3.44 | G16: 108.43 | H16: 54.9 | I16: Maint. | J16: 0.15 | K16: 244.6 | L16: 16.58 | M16: 62 | N16: 3.7 | O16: 0 | P16: 2.57 | Q16: 40.03
A17: 06-02-2023 02:15 | B17: 124.56 | C17: 150.05 | D17: 181.51 | E17: 7.75 | F17: 3.47 | G17: 108.43 | H17: 54.9 | I17: Maint. | J17: 0.33 | K17: 228.02 | L17: 17.54 | M17: 58 | N17: 2.6 | O17: 0 | P17: 2.53 | Q17: 39.76
A18: 06-02-2023 02:30 | B18: 118.38 | C18: 143.87 | D18: 173.14 | E18: 7.95 | F18: 3.5 | G18: 104.58 | H18: 54.84 | I18: Maint. | J18: 0.32 | K18: 174.09 | L18: 17.59 | M18: 56 | N18: 3.7 | O18: 0 | P18: 2.45 | Q18: 39.13
A19: 06-02-2023 02:45 | B19: 111.84 | C19: 139.73 | D19: 165.61 | E19: 7.64 | F19: 3.51 | G19: 101.49 | H19: 54.8 | I19: Maint. | J19: 0.17 | K19: 323.91 | L19: 16.48 | M19: 61 | N19: 4.7 | O19: 0 | P19: 2.36 | Q19: 39.05
A20: 06-02-2023 03:00 | B20: 104.45 | C20: 135 | D20: 157.08 | E20: 7.61 | F20: 3.54 | G20: 101.49 | H20: 54.8 | I20: Maint. | J20: 0.13 | K20: 12.98 | L20: 15.74 | M20: 66 | N20: 4.7 | O20: 0 | P20: 2.26 | Q20: 39.02
... A51: 06-02-2023 10:45 | B51: 3.37 | C51: 141.14 | D51: 79.41 | E51: 25.45 | F51: 53.24 | G51: 150.85 | H51: 70.75 | I51: Maint. | J51: 0.38 | K51: 359.05 | L51: 32.14 | M51: 23 | N51: 438.1 | O51: 0 | P51: 2.81 | Q51: 15.22
A52: 06-02-2023 11:00 | B52: 2.61 | C52: 120.39 | D52: 67.34 | E52: 18.35 | F52: 38.86 | G52: 150.85 | H52: 70.75 | I52: 0.43 | J52: 0.1 | K52: 245.21 | L52: 30.62 | M52: 24 | N52: 475.4 | O52: 0 | P52: 2.51 | Q52: 13.36
A53: 06-02-2023 11:15 | B53: 2.86 | C53: 110.57 | D53: 62.13 | E53: 15.56 | F53: 33.24 | G53: 150.85 | H53: 70.75 | I53: 0.83 | J53: 0.43 | K53: 1.05 | L53: 32.71 | M53: 21 | N53: 456.5 | O53: 0 | P53: 2.41 | Q53: 12.71
A54: 06-02-2023 11:30 | B54: 2.52 | C54: 103.43 | D54: 57.91 | E54: 15.92 | F54: 45.73 | G54: 151.5 | H54: 71.71 | I54: 0.76 | J54: 0.11 | K54: 22.68 | L54: 31.94 | M54: 23 | N54: 447.9 | O54: 0 | P54: 2.33 | Q54: 13.24
A55: 06-02-2023 11:45 | B55: 2.52 | C55: 89.63 | D55: 50.3 | E55: 14.83 | F55: 28.46 | G55: 152.02 | H55: 72.47 | I55: 0.73 | J55: 0.32 | K55: 12.6 | L55: 32.73 | M55: 22 | N55: 454.8 | O55: 0 | P55: 2.28 | Q55: 13.34
A56: 06-02-2023 12:00 | B56: 2.85 | C56: 90.89 | D56: 51.26 | E56: 5.17 | F56: 18.01 | G56: 152.02 | H56: 72.47 | I56: 0.71 | J56: 0.27 | K56: 52.18 | L56: 32.1 | M56: 20 | N56: 528.6 | O56: 0 | P56: 2.27 | Q56: 13.13
A57: 06-02-2023 12:15 | B57: 3.52 | C57: 82.7 | D57: 47.27 | E57: 12.72 | F57: 22.83 | G57: 152.02 | H57: 72.47 | I57: 0.71 | J57: 0.37 | K57: 35.16 | L57: 31.78 | M57: 19 | N57: 449.4 | O57: 0 | P57: 2.2 | Q57: 13.47
A58: 06-02-2023 12:30 | B58: 4.18 | C58: 83.52 | D58: 48.25 | E58: 17.62 | F58: 24.43 | G58: 153.42 | H58: 72.29 | I58: 0.73 | J58: 0.39 | K58: 7.37 | L58: 32.72 | M58: 19 | N58: 416.5 | O58: 0 | P58: 2.22 | Q58: 14.83
A59: 06-02-2023 12:45 | B59: 3.18 | C59: 77.5 | D59: 44.14 | E59: 32.21 | F59: 48.42 | G59: 154.55 | H59: 72.15 | I59: 0.72 | J59: 0.16 | K59: 143.87 | L59: 32.22 | M59: 19 | N59: 387.2 | O59: 0 | P59: 2.15 | Q59: 15.46
A60: 06-02-2023 13:00 | B60: 3.64 | C60: 76.64 | D60: 44.02 | E60: 31.96 | F60: 32.82 | G60: 154.55 | H60: 72.15 | I60: 0.71 | J60: 0.26 | K60: 26.4 | L60: 30.85 | M60: 20 | N60: 336.1 | O60: 0 | P60: 2.1 | Q60: 15.5
A61: 06-02-2023 13:15 | B61: 3.71 | C61: 72.06 | D61: 41.55 | E61: 17.36 | F61: 18.16 | G61: 154.55 | H61: 72.15 | I61: 0.68 | J61: 0.71 | K61: 1.88 | L61: 32.77 | M61: 16 | N61: 344.3 | O61: 0 | P61: 1.99 | Q61: 15.85
A62: 06-02-2023 13:30 | B62: 3.57 | C62: 72.48 | D62: 41.67 | E62: 19.66 | F62: 9.8 | G62: 150.72 | H62: 70.55 | I62: 0.69 | J62: 0.59 | K62: 10.51 | L62: 32.66 | M62: 15 | N62: 403.5 | O62: 0 | P62: 2 | Q62: 17.48
A63: 06-02-2023 13:45 | B63: 3.55 | C63: 75.12 | D63: 43.12 | E63: 9.36 | F63: 7.51 | G63: 147.66 | H63: 69.28 | I63: 0.7 | J63: 0.2 | K63: 19.34 | L63: 33.27 | M63: 14 | N63: 419.7 | O63: 0 | P63: 1.95 | Q63: 19.79
... A68: 06-02-2023 15:00 | B68: 4.09 | C68: 66.53 | D68: 38.81 | E68: 6.69 | F68: 9.06 | G68: 70.11 | H68: 55.09 | I68: 0.62 | J68: 0.93 | K68: 13.64 | L68: 34.01 | M68: 13 | N68: 303.1 | O68: 0 | P68: 1.3 | Q68: 19.86
A69: 06-02-2023 15:15 | B69: 5.25 | C69: 65.39 | D69: 39.11 | E69: 7.45 | F69: 12.32 | G69: 70.11 | H69: 55.09 | I69: Maint. | J69: 1.1 | K69: 3.01 | L69: 34.17 | M69: 13 | N69: 183.9 | O69: 0 | P69: 1.22 | Q69: 20.05
A70: 06-02-2023 15:30 | B70: 5.93 | C70: 65.27 | D70: 39.59 | E70: 7.79 | F70: 14.71 | G70: 62.32 | H70: 49.73 | I70: Maint. | J70: 0.86 | K70: 10.01 | L70: 33.96 | M70: 13 | N70: 124.1 | O70: 0 | P70: 1.18 | Q70: 19.89
A71: 06-02-2023 15:45 | B71: 5.54 | C71: 66.61 | D71: 40.02 | E71: 6.58 | F71: 10 | G71: 56.09 | H71: 45.45 | I71: Maint. | J71: 0.6 | K71: 353.59 | L71: 33.48 | M71: 14 | N71: 116.4 | O71: 0 | P71: 1.17 | Q71: 19.84
A72: 06-02-2023 16:00 | B72: 8.61 | C72: 65 | D72: 41.59 | E72: 5.26 | F72: 12.13 | G72: 56.09 | H72: 45.45 | I72: Maint. | J72: 0.94 | K72: 11.02 | L72: 32.75 | M72: 15 | N72: 134.1 | O72: 0 | P72: 1.14 | Q72: 20.6
A73: 06-02-2023 16:15 | B73: 7.42 | C73: 60.18 | D73: 37.98 | E73: 11.84 | F73: 22.11 | G73: 56.09 | H73: 45.45 | I73: Maint. | J73: 0.49 | K73: 5.29 | L73: 31.35 | M73: 16 | N73: 87.3 | O73: 0 | P73: 1.05 | Q73: 21.45
A74: 06-02-2023 16:30 | B74: 8.91 | C74: 63.4 | D74: 40.95 | E74: 10.11 | F74: 17.44 | G74: 53.07 | H74: 38.86 | I74: Maint. | J74: 0.42 | K74: 340.4 | L74: 30.39 | M74: 17 | N74: 62.2 | O74: 0 | P74: 1.05 | Q74: 22.14
A75: 06-02-2023 16:45 | B75: 10.51 | C75: 64.84 | D75: 43.03 | E75: 10.71 | F75: 17.9 | G75: 50.65 | H75: 33.58 | I75: Maint. | J75: 0.51 | K75: 11.81 | L75: 29.74 | M75: 17 | N75: 55.3 | O75: 0 | P75: 1.03 | Q75: 23.01
A76: 06-02-2023 17:00 | B76: 10.67 | C76: 68.28 | D76: 45.05 | E76: 9.54 | F76: 13.49 | G76: 50.65 | H76: 33.58 | I76: Maint. | J76: 0.35 | K76: 21.2 | L76: 29.13 | M76: 19 | N76: 38.2 | O76: 0 | P76: 1.12 | Q76: 24.09
...

Sheet 07
A1: Station: | B1: BHATAGAON RAIPUR
A2: Date: | B2: =$A$9 -> 07-02-2023 00:15 | D2: Power Off | G2: Pw.Off | L2: Link Fail | N2: Link F | P2: Maintenance | R2: Maint.
A3: Report Type: | B3: Mean | D3: Calibration | G3: Calib. | L3: Data Fail | N3: Data F | P3: Invalid | R3: Invalid
A4: Time Base: | B4: 15 Min | D4: Zero Referrence | G4: Z.Ref | L4: Warm Up | N4: Wm. Up
A7: Date & Time | B7: NO_BHATAGAON | C7: NO2__BHATAGAON | D7: NOX_BHATAGAON | E7: SO2__BHATAGAON | F7: O3__BHATAGAON | G7: PM10__BHATAGAON | H7: PM2_5__BHATAGAON | I7: BENZ__BHATAGAON | J7: WS__BHATAGAON | K7: WD__BHATAGAON | L7: TEMP__BHATAGAON | M7: HUM__BHATAGAON | N7: SR__BHATAGAON | O7: RG__BHATAGAON | P7: CO__BHATAGAON | Q7: NH3__BHATAGAON
B8: ug/m3 | C8: ug/m3 | D8: ppb | E8: ug/m3 | F8: ug/m3 | G8: ug/m3 | H8: ug/m3 | I8: ug/m3 | J8: m/sec | K8: deg | L8: degreC | M8: % | N8: w/m2 | O8: mm | P8: mg/m3 | Q8: ug/m3
A9: 07-02-2023 00:15 | B9: 208.83 | C9: 83.63 | D9: 212.43 | E9: 7.44 | F9: 3.43 | G9: 246.73 | H9: 80.09 | I9: Maint. | J9: 0.12 | K9: 305.79 | L9: 19.08 | M9: 53 | N9: 4.1 | O9: 0 | P9: 3.11 | Q9: 49.17
A10: 07-02-2023 00:30 | B10: 193.59 | C10: 82.01 | D10: 199.32 | E10: 7.24 | F10: 3.41 | G10: 184.74 | H10: 75.35 | I10: Maint. | J10: 0.13 | K10: 301.97 | L10: 18.79 | M10: 51 | N10: 4.4 | O10: 0 | P10: 2.97 | Q10: 48.23
A11: 07-02-2023 00:45 | B11: 178.38 | C11: 80.94 | D11: 186.53 | E11: 7.49 | F11: 3.36 | G11: 135.14 | H11: 71.55 | I11: Maint. | J11: 0.08 | K11: 335.46 | L11: 18.52 | M11: 51 | N11: 4.5 | O11: 0 | P11: 2.84 | Q11: 46.94
A12: 07-02-2023 01:00 | B12: 165.67 | C12: 80.46 | D12: 176.07 | E12: 7.21 | F12: 3.38 | G12: 135.14 | H12: 71.55 | I12: Maint. | J12: 0.06 | K12: 114.48 | L12: 18.35 | M12: 53 | N12: 4.5 | O12: 0 | P12: 2.7 | Q12: 45.77
A13: 07-02-2023 01:15 | B13: 153.88 | C13: 80.61 | D13: 166.7 | E13: 6.87 | F13: 3.47 | G13: 135.14 | H13: 71.55 | I13: Maint. | J13: 0.12 | K13: 85.57 | L13: 18.12 | M13: 57 | N13: 4.4 | O13: 0 | P13: 2.39 | Q13: 44.43
A14: 07-02-2023 01:30 | B14: 143.22 | C14: 80.49 | D14: 158.08 | E14: 6.77 | F14: 3.36 | G14: 110.56 | H14: 65.55 | I14: Maint. | J14: 0.15 | K14: 7.85 | L14: 17.67 | M14: 61 | N14: 4.5 | O14: 0 | P14: 2.43 | Q14: 43.07
A15: 07-02-2023 01:45 | B15: 134.91 | C15: 80.42 | D15: 151.39 | E15: 6.56 | F15: 3.33 | G15: 90.89 | H15: 60.75 | I15: Maint. | J15: 0.07 | K15: 252.27 | L15: 17.88 | M15: 60 | N15: 3.7 | O15: 0 | P15: 2.36 | Q15: 42.04
A16: 07-02-2023 02:00 | B16: 121.83 | C16: 79.7 | D16: 140.49 | E16: 6.64 | F16: 3.4 | G16: 90.89 | H16: 60.75 | I16: Maint. | J16: 0.12 | K16: 357.59 | L16: 17.92 | M16: 59 | N16: 4.1 | O16: 0 | P16: 2.27 | Q16: 41.18
A17: 07-02-2023 02:15 | B17: 116.11 | C17: 79.81 | D17: 135.97 | E17: 6.5 | F17: 3.39 | G17: 90.89 | H17: 60.75 | I17: Maint. | J17: 0.14 | K17: 279.63 | L17: 17.97 | M17: 56 | N17: 4.2 | O17: 0 | P17: 2.22 | Q17: 39.62
A18: 07-02-2023 02:30 | B18: 113 | C18: 77.24 | D18: 132.05 | E18: 6.16 | F18: 3.42 | G18: 108.15 | H18: 58.42 | I18: Maint. | J18: 0.06 | K18: 337.41 | L18: 17.84 | M18: 56 | N18: 4.3 | O18: 0 | P18: 2.17 | Q18: 38.4
A19: 07-02-2023 02:45 | B19: 108.4 | C19: 76.5 | D19: 127.96 | E19: 6.51 | F19: 3.43 | G19: 121.97 | H19: 56.55 | I19: Maint. | J19: 0.13 | K19: 252.88 | L19: 17.73 | M19: 58 | N19: 4.1 | O19: 0 | P19: 2.12 | Q19: 37.79
A20: 07-02-2023 03:00 | B20: 102.58 | C20: 75.12 | D20: 122.53 | E20: 6.45 | F20: 3.46 | G20: 121.97 | H20: 56.55 | I20: Maint. | J20: 0.13 | K20: 291.93 | L20: 17.51 | M20: 59 | N20: 4.4 | O20: 0 | P20: 2.07 | Q20: 37.31
... A50: 07-02-2023 10:30 | B50: 31.18 | C50: 76.15 | D50: 65.84 | E50: 5.89 | F50: 4.13 | G50: 74.66 | H50: 40.86 | I50: Maint. | J50: 0.5 | K50: 359.08 | L50: 32.1 | M50: 27 | N50: 481.5 | O50: 0 | P50: 1.34 | Q50: 30.92
A51: 07-02-2023 10:45 | B51: 27.81 | C51: 74.66 | D51: 62.32 | E51: 6.54 | F51: 5.77 | G51: 83.22 | H51: 41.14 | I51: 0.79 | J51: 0.47 | K51: 13.75 | L51: 32.64 | M51: 24 | N51: 508.3 | O51: 0 | P51: 1.34 | Q51: 31.09
A52: 07-02-2023 11:00 | B52: 26.6 | C52: 76.83 | D52: 62.54 | E52: 5.44 | F52: 4.83 | G52: 83.22 | H52: 41.14 | I52: 0.76 | J52: 0.34 | K52: 12.41 | L52: 32.85 | M52: 23 | N52: 522.9 | O52: 0 | P52: 1.35 | Q52: 32.22
A53: 07-02-2023 11:15 | B53: 24.17 | C53: 81.3 | D53: 63.06 | E53: 5.77 | F53: 4.04 | G53: 83.22 | H53: 41.14 | I53: 0.74 | J53: 0.28 | K53: 69.09 | L53: 32.16 | M53: 24 | N53: 544.2 | O53: 0 | P53: 1.34 | Q53: 33.44
A54: 07-02-2023 11:30 | B54: 20.09 | C54: 84.24 | D54: 61.41 | E54: 5.84 | F54: 4.73 | G54: 74.29 | H54: 38.95 | I54: 0.73 | J54: 0.43 | K54: 71.53 | L54: 31.53 | M54: 24 | N54: 560.7 | O54: 0 | P54: 1.31 | Q54: 33.82
A55: 07-02-2023 11:45 | B55: 16.26 | C55: 86.62 | D55: 59.65 | E55: 5.95 | F55: 4.46 | G55: 67.14 | H55: 37.2 | I55: 0.73 | J55: 0.21 | K55: 29.6 | L55: 31.85 | M55: 23 | N55: 568.3 | O55: 0 | P55: 1.28 | Q55: 33.96
A56: 07-02-2023 12:00 | B56: 12.87 | C56: 88.73 | D56: 58.1 | E56: 4.19 | F56: 4.31 | G56: 67.14 | H56: 37.2 | I56: 0.72 | J56: 0.59 | K56: 4.79 | L56: 34.53 | M56: 18 | N56: 575 | O56: 0 | P56: 1.26 | Q56: 33.9
A57: 07-02-2023 12:15 | B57: 9.83 | C57: 89.83 | D57: 56.27 | E57: 5.77 | F57: 5.35 | G57: 67.14 | H57: 37.2 | I57: 0.71 | J57: 0.03 | K57: 237.95 | L57: 31.99 | M57: 20 | N57: 579.2 | O57: 0 | P57: 1.23 | Q57: 33.27
A58: 07-02-2023 12:30 | B58: 7.18 | C58: 89.57 | D58: 54 | E58: 6.09 | F58: 5.89 | G58: 70.18 | H58: 36.93 | I58: 0.7 | J58: 0.62 | K58: 12.91 | L58: 33.16 | M58: 18.92 | N58: 567.8 | O58: 0 | P58: 1.18 | Q58: 32.1
A59: 07-02-2023 12:45 | B59: 5.56 | C59: 80.82 | D59: 47.88 | E59: 7.81 | F59: 13.18 | G59: 72.61 | H59: 36.71 | I59: 0.68 | J59: 0.7 | K59: 357.23 | L59: 34.42 | M59: 17.74 | N59: 553.1 | O59: 0 | P59: 1.12 | Q59: 31.1
A60: 07-02-2023 13:00 | B60: 5.5 | C60: 85.81 | D60: 50.58 | E60: 5.67 | F60: 6.53 | G60: 72.61 | H60: 36.71 | I60: 0.66 | J60: 0.63 | K60: 4.19 | L60: 34.94 | M60: 17.2 | N60: 518.4 | O60: 0 | P60: 1.12 | Q60: 29.88
A61: 07-02-2023 13:15 | B61: 5.25 | C61: 85.64 | D61: 50.28 | E61: 5.84 | F61: 6.06 | G61: 72.61 | H61: 36.71 | I61: 0.66 | J61: 0.43 | K61: 355.79 | L61: 34.15 | M61: 17.42 | N61: 503.2 | O61: 0 | P61: 1.05 | Q61: 29.12
A62: 07-02-2023 13:30 | B62: 5.12 | C62: 81.02 | D62: 47.63 | E62: 5.8 | F62: 8.44 | G62: 62.92 | H62: 34.87 | I62: 0.66 | J62: 0.52 | K62: 344.4 | L62: 32.66 | M62: 17.36 | N62: 496.9 | O62: 0 | P62: 1.04 | Q62: 28.46
... A64: 07-02-2023 14:00 | B64: 4.03 | C64: 75.3 | D64: 43.6 | E64: 6.79 | F64: 8.13 | G64: 55.16 | H64: 33.4 | I64: 0.65 | J64: 0.64 | K64: 349.69 | L64: 34.2 | M64: 16.84 | N64: 451.5 | O64: 0 | P64: 0.96 | Q64: 27.56
A65: 07-02-2023 14:15 | B65: 3.82 | C65: 73.07 | D65: 42.2 | E65: 6.16 | F65: 7.24 | G65: 55.16 | H65: 33.4 | I65: Maint. | J65: 0.47 | K65: 356.07 | L65: 34.3 | M65: 16.11 | N65: 435.6 | O65: 0 | P65: 0.93 | Q65: 27.06
A66: 07-02-2023 14:30 | B66: 3.81 | C66: 71.04 | D66: 41.07 | E66: 6.28 | F66: 7.39 | G66: 44.26 | H66: 31.22 | I66: Maint. | J66: 0.5 | K66: 351.81 | L66: 33.96 | M66: 16.3 | N66: 399.6 | O66: 0 | P66: 0.9 | Q66: 27.3
A67: 07-02-2023 14:45 | B67: 3.79 | C67: 70.4 | D67: 40.7 | E67: 6.06 | F67: 7.77 | G67: 35.54 | H67: 29.47 | I67: Maint. | J67: 0.44 | K67: 347.43 | L67: 34.21 | M67: 16.75 | N67: 373.9 | O67: 0 | P67: 0.89 | Q67: 28.64
A68: 07-02-2023 15:00 | B68: 3.76 | C68: 68.54 | D68: 39.65 | E68: 6.4 | F68: 10 | G68: 35.54 | H68: 29.47 | I68: Maint. | J68: 0.52 | K68: 354.53 | L68: 34.35 | M68: 17.13 | N68: 279.7 | O68: 0 | P68: 0.87 | Q68: 29.4
A69: 07-02-2023 15:15 | B69: 3.85 | C69: 67.65 | D69: 39.23 | E69: 6.61 | F69: 8.96 | G69: 35.54 | H69: 29.47 | I69: Maint. | J69: 0.2 | K69: 355.21 | L69: 34.29 | M69: 16.71 | N69: 170.7 | O69: 0 | P69: 0.86 | Q69: 29.67
A70: 07-02-2023 15:30 | B70: 3.93 | C70: 68.88 | D70: 39.98 | E70: 6.61 | F70: 9.68 | G70: 26.58 | H70: 28.1 | I70: Maint. | J70: 0.19 | K70: 16.95 | L70: 32.79 | M70: 18.28 | N70: 130.7 | O70: 0 | P70: 0.87 | Q70: 29.54
A71: 07-02-2023 15:45 | B71: 4 | C71: 69.78 | D71: 40.53 | E71: 6.77 | F71: 7.24 | G71: 19.4 | H71: 27.01 | I71: Maint. | J71: 0.05 | K71: 197.92 | L71: 32 | M71: 19.07 | N71: 133.4 | O71: 0 | P71: 0.86 | Q71: 29.61
A72: 07-02-2023 16:00 | B72: 3.54 | C72: 69.89 | D72: 40.22 | E72: 4.87 | F72: 7.79 | G72: 19.4 | H72: 27.01 | I72: Maint. | J72: 0.11 | K72: 178.05 | L72: 31.44 | M72: 19.44 | N72: 123.6 | O72: 0 | P72: 0.86 | Q72: 29.76
...

Sheet 08
A1: Station: | B1: BHATAGAON RAIPUR
A2: Date: | B2: =$A$9 -> 08-02-2023 00:15 | D2: Power Off | G2: Pw.Off | L2: Link Fail | N2: Link F | P2: Maintenance | R2: Maint.
A3: Report Type: | B3: Mean | D3: Calibration | G3: Calib. | L3: Data Fail | N3: Data F | P3: Invalid | R3: Invalid
A4: Time Base: | B4: 15 Min | D4: Zero Referrence | G4: Z.Ref | L4: Warm Up | N4: Wm. Up
A7: Date & Time | B7: NO_BHATAGAON | C7: NO2__BHATAGAON | D7: NOX_BHATAGAON | E7: SO2__BHATAGAON | F7: O3__BHATAGAON | G7: PM10__BHATAGAON | H7: PM2_5__BHATAGAON | I7: BENZ__BHATAGAON | J7: WS__BHATAGAON | K7: WD__BHATAGAON | L7: TEMP__BHATAGAON | M7: HUM__BHATAGAON | N7: SR__BHATAGAON | O7: RG__BHATAGAON | P7: CO__BHATAGAON | Q7: NH3__BHATAGAON
B8: ug/m3 | C8: ug/m3 | D8: ppb | E8: ug/m3 | F8: ug/m3 | G8: ug/m3 | H8: ug/m3 | I8: ug/m3 | J8: m/sec | K8: deg | L8: degreC | M8: % | N8: w/m2 | O8: mm | P8: mg/m3 | Q8: ug/m3
A9: 08-02-2023 00:15 | B9: 69.95 | C9: 84.4 | D9: 101.49 | E9: 5.4 | F9: 3.31 | G9: 150.76 | H9: 47.74 | I9: Maint. | J9: 0.03 | K9: 77.73 | L9: 19.71 | M9: 57.97 | N9: 4.4 | O9: 0 | P9: 2.18 | Q9: 37.52
A10: 08-02-2023 00:30 | B10: 69.58 | C10: 83.3 | D10: 100.58 | E10: 5.73 | F10: 3.4 | G10: 130.03 | H10: 46.65 | I10: Maint. | J10: 0.53 | K10: 358.57 | L10: 19.56 | M10: 60.47 | N10: 3 | O10: 0 | P10: 2.17 | Q10: 37.48
