Workbook

Sheet 01
A1: Station: | B1: IGKV ,RAIPUR
A2: Date: | B2: =$A$9 -> 01/11/2023 01:00 | D2: Power Off | G2: Pw.Off | L2: Link Fail | N2: Link F | P2: Maintenance | R2: Maint.
A3: Report Type: | B3: Mean | D3: Calibration | G3: Calib. | L3: Data Fail | N3: Data F | P3: Invalid | R3: Invalid
A4: Time Base: | B4: 01 Hour | D4: Zero Referrence | G4: Z.Ref | L4: Warm Up | N4: Wm. Up
A7: Date & Time | B7: NO | C7: NO2 | D7: NOX | E7: SO2 | F7: O3 | G7: PM 10 | H7: PM 2.5 | I7: BENZ | J7: WS | K7: WD | L7: TEMP | M7: HUM | N7: SR | O7: RG | P7: CO | Q7: NH3
B8: ug/m3 | C8: ug/m3 | D8: ppb | E8: ug/m3 | F8: ug/m3 | G8: ug/m3 | H8: ug/m3 | I8: ug/m3 | J8: m/sec | K8: deg | L8: degreC | M8: % | N8: w/m2 | O8: mm | P8: mg/m3 | Q8: ug/m3
A9: 01/11/2023 01:00 | B9: 8.64 | C9: 19.92 | D9: 18.69 | E9: 4.4 | F9: 2.91 | G9: 54.51 | H9: 29.31 | I9: 6.81 | J9: 0.24 | K9: 263.54 | L9: 20.91 | M9: 93.15 | N9: 0 | O9: 0 | P9: 0.79 | Q9: 4.53
A10: 01/11/2023 02:00 | B10: 11.37 | C10: 22.1 | D10: 22.02 | E10: 4.91 | F10: 2.77 | G10: 51.81 | H10: 27.13 | I10: 6.79 | J10: 0.13 | K10: 184.54 | L10: 20.54 | M10: 94.84 | N10: 0 | O10: 0 | P10: 0.81 | Q10: 4.66
A11: 01/11/2023 03:00 | B11: 18.4 | C11: 25.87 | D11: 29.62 | E11: 6.32 | F11: 2.7 | G11: 62.61 | H11: 26.98 | I11: 6.7 | J11: 0.1 | K11: 179.66 | L11: 20.5 | M11: 95.3 | N11: 0 | O11: 0 | P11: 0.82 | Q11: 5.05
A12: 01/11/2023 04:00 | B12: 20.66 | C12: 27.05 | D12: 32.05 | E12: 6.29 | F12: 2.62 | G12: 64.65 | H12: 28.34 | I12: 6.68 | J12: 0.16 | K12: 218.44 | L12: 20.3 | M12: 95.68 | N12: 0 | O12: 0 | P12: 0.81 | Q12: 5.19
A13: 01/11/2023 05:00 | B13: 29.39 | C13: 28.71 | D13: 39.92 | E13: 6.74 | F13: 2.57 | G13: 70.08 | H13: 29.16 | I13: 6.62 | J13: 0.12 | K13: 342.17 | L13: 19.74 | M13: 98.26 | N13: 0 | O13: 0 | P13: 0.79 | Q13: 5.55
A14: 01/11/2023 06:00 | B14: 30.7 | C14: 28.59 | D14: 40.86 | E14: 6.92 | F14: 2.56 | G14: 71.64 | H14: 32.54 | I14: 6.87 | J14: 0.21 | K14: 58.75 | L14: 19.91 | M14: 97.27 | N14: 0 | O14: 0 | P14: 0.81 | Q14: 5.68
A15: 01/11/2023 07:00 | B15: 30.09 | C15: 28.56 | D15: 40.27 | E15: 7.23 | F15: 2.86 | G15: 71.64 | H15: 34.17 | I15: 7.1 | J15: 0.36 | K15: 51.59 | L15: 20.31 | M15: 95.84 | N15: 29.4 | O15: 0 | P15: 0.82 | Q15: 5.61
A16: 01/11/2023 08:00 | B16: 29.36 | C16: 26.13 | D16: 38.55 | E16: 6.22 | F16: 2.76 | G16: 66.34 | H16: 34.17 | I16: 7.15 | J16: 0.48 | K16: 104.37 | L16: 22.78 | M16: 89.76 | N16: 197.3 | O16: 0 | P16: 0.8 | Q16: 5.52
A17: 01/11/2023 09:00 | B17: 26.77 | C17: 25.88 | D17: 35.54 | E17: 6.03 | F17: 2.93 | G17: 71.76 | H17: 36.42 | I17: 7.17 | J17: 0.41 | K17: 95.54 | L17: 25.89 | M17: 75.14 | N17: 321.8 | O17: 0 | P17: 0.79 | Q17: 5.41
A18: 01/11/2023 10:00 | B18: 21.77 | C18: 25.86 | D18: 32.32 | E18: 6.43 | F18: 3.29 | G18: 71.76 | H18: 36.42 | I18: 7.21 | J18: 0.39 | K18: 108.65 | L18: 28.09 | M18: 64.85 | N18: 445.4 | O18: 0 | P18: 0.8 | Q18: 5.2
A19: 01/11/2023 11:00 | B19: 16.08 | C19: 24.33 | D19: 26.96 | E19: 8.32 | F19: 6.25 | G19: 68.99 | H19: 30.21 | I19: 7.04 | J19: 0.57 | K19: 116.45 | L19: 29.16 | M19: 56.03 | N19: 506.5 | O19: 0 | P19: 0.78 | Q19: 4.95
A20: 01/11/2023 12:00 | B20: 10.76 | C20: 23.49 | D20: 22.18 | E20: 8.11 | F20: 6.53 | G20: 64.48 | H20: 29.68 | I20: 6.74 | J20: 0.32 | K20: 129.32 | L20: 30.25 | M20: 47.8 | N20: 584.4 | O20: 0 | P20: 0.77 | Q20: 4.7
... A32: 01/11/2023 24:00 | B32: 23.57 | C32: 28.76 | D32: 35.28 | E32: 6.51 | F32: 2.63 | G32: 110.89 | H32: 34.42 | I32: 7.47 | J32: 0.16 | K32: 169.23 | L32: 22.71 | M32: 83.02 | N32: 0 | O32: 0 | P32: 0.98 | Q32: 5.31
A34: Min | B34: =MIN(B9:B32) -> 4.72 | C34: =MIN(C9:C32) -> 19.33 | D34: =MIN(D9:D32) -> 15.44 | E34: =MIN(E9:E32) -> 4.4 | F34: =MIN(F9:F32) -> 2.56 | G34: =MIN(G9:G32) -> 48.26 | H34: =MIN(H9:H32) -> 20.22 | I34: =MIN(I9:I32) -> 4.71 | ... Q34: =MIN(Q9:Q32) -> 4.31
A35: Max | B35: =MAX(B9:B32) -> 30.7 | C35: =MAX(C9:C32) -> 28.76 | D35: =MAX(D9:D32) -> 40.86 | E35: =MAX(E9:E32) -> 8.32 | F35: =MAX(F9:F32) -> 6.53 | G35: =MAX(G9:G32) -> 113.28 | H35: =MAX(H9:H32) -> 36.42 | I35: =MAX(I9:I32) -> 7.49 | ... Q35: =MAX(Q9:Q32) -> 5.68
A36: Avg | B36: =AVERAGE(B9:B32) -> 16.208333 | C36: =AVERAGE(C9:C32) -> 24.250833 | D36: =AVERAGE(D9:D32) -> 26.94 | E36: =AVERAGE(E9:E32) -> 6.6754167 | F36: =AVERAGE(F9:F32) -> 3.7654167 | G36: =AVERAGE(G9:G32) -> 73.307917 | H36: =AVERAGE(H9:H32) -> 29.50875 | I36: =AVERAGE(I9:I32) -> 6.4575 | ... Q36: =AVERAGE(Q9:Q32) -> 4.9095833
A37: Stdev | B37: =STDEV(B9:B32) -> 8.9426388 | C37: =STDEV(C9:C32) -> 3.1539608 | D37: =STDEV(D9:D32) -> 8.6783348 | E37: =STDEV(E9:E32) -> 1.0125516 | F37: =STDEV(F9:F32) -> 1.5610615 | G37: =STDEV(G9:G32) -> 21.350942 | H37: =STDEV(H9:H32) -> 4.8131652 | I37: =STDEV(I9:I32) -> 0.85573894 | ... Q37: =STDEV(Q9:Q32) -> 0.45684627
A38: Num | B38: =COUNT(B9:B32) -> 24 | C38: =COUNT(C9:C32) -> 24 | D38: =COUNT(D9:D32) -> 24 | E38: =COUNT(E9:E32) -> 24 | F38: =COUNT(F9:F32) -> 24 | G38: =COUNT(G9:G32) -> 24 | H38: =COUNT(H9:H32) -> 24 | I38: =COUNT(I9:I32) -> 24 | ... Q38: =COUNT(Q9:Q32) -> 24
A39: DCR | B39: =IF(B38>=22,">90%",IF(B38<=22,"<90%")) -> >90% | C39: =IF(C38>=22,">90%",IF(C38<=22,"<90%")) -> >90% | D39: =IF(D38>=22,">90%",IF(D38<=22,"<90%")) -> >90% | E39: =IF(E38>=22,">90%",IF(E38<=22,"<90%")) -> >90% | F39: =IF(F38>=22,">90%",IF(F38<=22,"<90%")) -> >90% | G39: =IF(G38>=22,">90%",IF(G38<=22,"<90%")) -> >90% | H39: =IF(H38>=22,">90%",IF(H38<=22,"<90%")) -> >90% | I39: =IF(I38>=22,">90%",IF(I38<=22,"<90%")) -> >90% | ... Q39: =IF(Q38>=22,">90%",IF(Q38<=22,"<90%")) -> >90%
A40: Status | B40: =IF(B38>=22,"OK",IF(B38<=22,"LESS")) -> OK | C40: =IF(C38>=22,"OK",IF(C38<=22,"LESS")) -> OK | D40: =IF(D38>=22,"OK",IF(D38<=22,"LESS")) -> OK | E40: =IF(E38>=22,"OK",IF(E38<=22,"LESS")) -> OK | F40: =IF(F38>=22,"OK",IF(F38<=22,"LESS")) -> OK | G40: =IF(G38>=22,"OK",IF(G38<=22,"LESS")) -> OK | H40: =IF(H38>=22,"OK",IF(H38<=22,"LESS")) -> OK | I40: =IF(I38>=22,"OK",IF(I38<=22,"LESS")) -> OK | ... Q40: =IF(Q38>=22,"OK",IF(Q38<=22,"LESS")) -> OK
A43: Done by | B43: AKASH
A45: Comment

Sheet 02
A1: Station: | B1: IGKV ,RAIPUR
A2: Date: | B2: =$A$9 -> 02/11/2023 01:00 | D2: Power Off | G2: Pw.Off | L2: Link Fail | N2: Link F | P2: Maintenance | R2: Maint.
A3: Report Type: | B3: Mean | D3: Calibration | G3: Calib. | L3: Data Fail | N3: Data F | P3: Invalid | R3: Invalid
A4: Time Base: | B4: 01 Hour | D4: Zero Referrence | G4: Z.Ref | L4: Warm Up | N4: Wm. Up
A7: Date & Time | B7: NO | C7: NO2 | D7: NOX | E7: SO2 | F7: O3 | G7: PM 10 | H7: PM 2.5 | I7: BENZ | J7: WS | K7: WD | L7: TEMP | M7: HUM | N7: SR | O7: RG | P7: CO | Q7: NH3
B8: ug/m3 | C8: ug/m3 | D8: ppb | E8: ug/m3 | F8: ug/m3 | G8: ug/m3 | H8: ug/m3 | I8: ug/m3 | J8: m/sec | K8: deg | L8: degreC | M8: % | N8: w/m2 | O8: mm | P8: mg/m3 | Q8: ug/m3
A9: 02/11/2023 01:00 | B9: 24.09 | C9: 28.65 | D9: 35.56 | E9: 6.97 | F9: 2.57 | G9: 96.47 | H9: 32.63 | I9: 7.37 | J9: 0.17 | K9: 182.99 | L9: 22.37 | M9: 85.05 | N9: 0 | O9: 0 | P9: 0.97 | Q9: 5.34
A10: 02/11/2023 02:00 | B10: 24.6 | C10: 28.36 | D10: 35.89 | E10: 7.14 | F10: 2.46 | G10: 93.56 | H10: 31.47 | I10: 7.44 | J10: 0.11 | K10: 172.63 | L10: 22.09 | M10: 87.42 | N10: 0 | O10: 0 | P10: 0.95 | Q10: 5.35
A11: 02/11/2023 03:00 | B11: 25.84 | C11: 28.78 | D11: 36.48 | E11: 6.28 | F11: 2.91 | G11: 90.39 | H11: 31.73 | I11: 7.78 | J11: 0.18 | K11: 138.15 | L11: 22.23 | M11: 82.14 | N11: 0 | O11: 0 | P11: 0.92 | Q11: 5.38
A12: 02/11/2023 04:00 | B12: 26.06 | C12: 25.6 | D12: 35.29 | E12: 6.53 | F12: 2.73 | G12: 90.39 | H12: 32.87 | I12: 9.02 | J12: 0.35 | K12: 42.16 | L12: 22.38 | M12: 81.05 | N12: 0 | O12: 0 | P12: 0.87 | Q12: 5.33
A13: 02/11/2023 05:00 | B13: 25.69 | C13: 24.45 | D13: 34.73 | E13: 6.19 | F13: 2.76 | G13: 88.97 | H13: 32.87 | I13: 9.02 | J13: 0.44 | K13: 40.13 | L13: 21.99 | M13: 84.32 | N13: 0 | O13: 0 | P13: 0.86 | Q13: 5.32
A14: 02/11/2023 06:00 | B14: 25.03 | C14: 24.62 | D14: 34.18 | E14: 6.35 | F14: 2.68 | G14: 87.85 | H14: 34.44 | I14: 8.77 | J14: 0.39 | K14: 46.04 | L14: 21.72 | M14: 86.11 | N14: 0 | O14: 0 | P14: 0.86 | Q14: 5.3
A15: 02/11/2023 07:00 | B15: 25.13 | C15: 24.06 | D15: 33.9 | E15: 6.34 | F15: 2.78 | G15: 87.85 | H15: 34.44 | I15: 8.77 | J15: 0.45 | K15: 68.01 | L15: 22.04 | M15: 86.35 | N15: 8.1 | O15: 0 | P15: 0.9 | Q15: 5.32
A16: 02/11/2023 08:00 | B16: 24.69 | C16: 25.39 | D16: 33.22 | E16: 6.52 | F16: 2.98 | G16: 90.86 | H16: 34.42 | I16: 8.9 | J16: 0.41 | K16: 108.37 | L16: 23.59 | M16: 83.6 | N16: 51.5 | O16: 0 | P16: 0.97 | Q16: 5.29
A17: 02/11/2023 09:00 | B17: 21.89 | C17: 27.37 | D17: 32.35 | E17: 6.86 | F17: 3.15 | G17: 90.86 | H17: 37 | I17: 8.89 | J17: 0.44 | K17: 48.76 | L17: 25.56 | M17: 77.43 | N17: 134.8 | O17: 0 | P17: 0.98 | Q17: 5.19
A18: 02/11/2023 10:00 | B18: 17.92 | C18: 28.84 | D18: 30.33 | E18: 7.21 | F18: 3.29 | G18: 89.97 | H18: 37.15 | I18: 8.57 | J18: 0.47 | K18: 142.66 | L18: 27.88 | M18: 71.03 | N18: 257.6 | O18: 0 | P18: 1.01 | Q18: 5.07
A19: 02/11/2023 11:00 | B19: 13.64 | C19: 28.58 | D19: 27.23 | E19: 7.02 | F19: 4.24 | G19: 89.97 | H19: 37.15 | I19: 8.54 | J19: 0.29 | K19: 175.9 | L19: 27.91 | M19: 67.71 | N19: 131.5 | O19: 0 | P19: 0.99 | Q19: 4.9
A20: 02/11/2023 12:00 | B20: 10.01 | C20: 27.79 | D20: 23.9 | E20: 7.35 | F20: 5.01 | G20: 81.72 | H20: 35.14 | I20: 8.09 | J20: 0.37 | K20: 336.82 | L20: 29.82 | M20: 67.02 | N20: 521.3 | O20: 0 | P20: 0.96 | Q20: 4.7
... A32: 02/11/2023 24:00 | B32: 22.13 | C32: 22.43 | D32: 30.19 | E32: 6.38 | F32: 2.8 | G32: 81.96 | H32: 27.99 | I32: 8.8 | J32: 0.12 | K32: 193.45 | L32: 24.47 | M32: 94.4 | N32: 0 | O32: 0 | P32: 1.11 | Q32: 5.13
A34: Min | B34: =MIN(B9:B32) -> 6.95 | C34: =MIN(C9:C32) -> 18.81 | D34: =MIN(D9:D32) -> 16.78 | E34: =MIN(E9:E32) -> 6.08 | F34: =MIN(F9:F32) -> 2.46 | G34: =MIN(G9:G32) -> 65.42 | H34: =MIN(H9:H32) -> 24.83 | I34: =MIN(I9:I32) -> 6.72 | ... Q34: =MIN(Q9:Q32) -> 4.4
A35: Max | B35: =MAX(B9:B32) -> 26.06 | C35: =MAX(C9:C32) -> 28.84 | D35: =MAX(D9:D32) -> 36.48 | E35: =MAX(E9:E32) -> 9.96 | F35: =MAX(F9:F32) -> 8.29 | G35: =MAX(G9:G32) -> 96.47 | H35: =MAX(H9:H32) -> 37.15 | I35: =MAX(I9:I32) -> 9.02 | ... Q35: =MAX(Q9:Q32) -> 5.38
A36: Avg | B36: =AVERAGE(B9:B32) -> 17.8425 | C36: =AVERAGE(C9:C32) -> 25.542917 | D36: =AVERAGE(D9:D32) -> 28.765833 | E36: =AVERAGE(E9:E32) -> 6.93125 | F36: =AVERAGE(F9:F32) -> 3.8825 | G36: =AVERAGE(G9:G32) -> 84.34875 | H36: =AVERAGE(H9:H32) -> 30.95875 | I36: =AVERAGE(I9:I32) -> 8.0370833 | ... Q36: =AVERAGE(Q9:Q32) -> 4.9958333
A37: Stdev | B37: =STDEV(B9:B32) -> 6.9215701 | C37: =STDEV(C9:C32) -> 2.8027696 | D37: =STDEV(D9:D32) -> 6.1589672 | E37: =STDEV(E9:E32) -> 0.77319952 | F37: =STDEV(F9:F32) -> 1.7822537 | G37: =STDEV(G9:G32) -> 7.9479537 | H37: =STDEV(H9:H32) -> 3.9909248 | I37: =STDEV(I9:I32) -> 0.77281799 | ... Q37: =STDEV(Q9:Q32) -> 0.33497458
A38: Num | B38: =COUNT(B9:B32) -> 24 | C38: =COUNT(C9:C32) -> 24 | D38: =COUNT(D9:D32) -> 24 | E38: =COUNT(E9:E32) -> 24 | F38: =COUNT(F9:F32) -> 24 | G38: =COUNT(G9:G32) -> 24 | H38: =COUNT(H9:H32) -> 24 | I38: =COUNT(I9:I32) -> 24 | ... Q38: =COUNT(Q9:Q32) -> 24
A39: DCR | B39: =IF(B38>=22,">90%",IF(B38<=22,"<90%")) -> >90% | C39: =IF(C38>=22,">90%",IF(C38<=22,"<90%")) -> >90% | D39: =IF(D38>=22,">90%",IF(D38<=22,"<90%")) -> >90% | E39: =IF(E38>=22,">90%",IF(E38<=22,"<90%")) -> >90% | F39: =IF(F38>=22,">90%",IF(F38<=22,"<90%")) -> >90% | G39: =IF(G38>=22,">90%",IF(G38<=22,"<90%")) -> >90% | H39: =IF(H38>=22,">90%",IF(H38<=22,"<90%")) -> >90% | I39: =IF(I38>=22,">90%",IF(I38<=22,"<90%")) -> >90% | ... Q39: =IF(Q38>=22,">90%",IF(Q38<=22,"<90%")) -> >90%
A40: Status | B40: =IF(B38>=22,"OK",IF(B38<=22,"LESS")) -> OK | C40: =IF(C38>=22,"OK",IF(C38<=22,"LESS")) -> OK | D40: =IF(D38>=22,"OK",IF(D38<=22,"LESS")) -> OK | E40: =IF(E38>=22,"OK",IF(E38<=22,"LESS")) -> OK | F40: =IF(F38>=22,"OK",IF(F38<=22,"LESS")) -> OK | G40: =IF(G38>=22,"OK",IF(G38<=22,"LESS")) -> OK | H40: =IF(H38>=22,"OK",IF(H38<=22,"LESS")) -> OK | I40: =IF(I38>=22,"OK",IF(I38<=22,"LESS")) -> OK | ... Q40: =IF(Q38>=22,"OK",IF(Q38<=22,"LESS")) -> OK
A43: Done by | B43: AKASH
A45: Comment

Sheet 03
A1: Station: | B1: IGKV ,RAIPUR
A2: Date: | B2: =$A$9 -> 03/11/2023 01:00 | D2: Power Off | G2: Pw.Off | L2: Link Fail | N2: Link F | P2: Maintenance | R2: Maint.
A3: Report Type: | B3: Mean | D3: Calibration | G3: Calib. | L3: Data Fail | N3: Data F | P3: Invalid | R3: Invalid
A4: Time Base: | B4: 01 Hour | D4: Zero Referrence | G4: Z.Ref | L4: Warm Up | N4: Wm. Up
A7: Date & Time | B7: NO | C7: NO2 | D7: NOX | E7: SO2 | F7: O3 | G7: PM 10 | H7: PM 2.5 | I7: BENZ | J7: WS | K7: WD | L7: TEMP | M7: HUM | N7: SR | O7: RG | P7: CO | Q7: NH3
B8: ug/m3 | C8: ug/m3 | D8: ppb | E8: ug/m3 | F8: ug/m3 | G8: ug/m3 | H8: ug/m3 | I8: ug/m3 | J8: m/sec | K8: deg | L8: degreC | M8: % | N8: w/m2 | O8: mm | P8: mg/m3 | Q8: ug/m3
A9: 03/11/2023 01:00 | B9: 25.39 | C9: 23.31 | D9: 32.96 | E9: 6.27 | F9: 2.63 | G9: 76.2 | H9: 27.99 | I9: 8.96 | J9: 0.16 | K9: 292.67 | L9: 24.46 | M9: 94.09 | N9: 0 | O9: 0 | P9: 1.11 | Q9: 5.29
A10: 03/11/2023 02:00 | B10: 30.75 | C10: 23.06 | D10: 37.89 | E10: 6.57 | F10: 2.72 | G10: 79.86 | H10: 27.5 | I10: 9.15 | J10: 0.18 | K10: 226.2 | L10: 24.36 | M10: 93.91 | N10: 0 | O10: 0 | P10: 1.13 | Q10: 5.5
A11: 03/11/2023 03:00 | B11: 31.17 | C11: 23.83 | D11: 38.12 | E11: 6.42 | F11: 2.88 | G11: 81.09 | H11: 30.13 | I11: 9.39 | J11: 0.16 | K11: 179.97 | L11: 24.35 | M11: 93.51 | N11: 0 | O11: 0 | P11: 1.16 | Q11: 5.53
A12: 03/11/2023 04:00 | B12: 32.28 | C12: 25.35 | D12: 40.48 | E12: 6.28 | F12: 2.7 | G12: 88.04 | H12: 31.37 | I12: 9.46 | J12: 0.14 | K12: 221.23 | L12: 23.64 | M12: 96.71 | N12: 0 | O12: 0 | P12: 1.17 | Q12: 5.63
A13: 03/11/2023 05:00 | B13: 34.42 | C13: 26.74 | D13: 42.92 | E13: 6.91 | F13: 2.61 | G13: 88.04 | H13: 36.04 | I13: 9.53 | J13: 0.23 | K13: 353.09 | L13: 23.28 | M13: 99.7 | N13: 0 | O13: 0 | P13: 1.17 | Q13: 5.77
A14: 03/11/2023 06:00 | B14: 35.84 | C14: 27.38 | D14: 44.12 | E14: 7.12 | F14: 2.55 | G14: 92.1 | H14: 36.04 | I14: 9.56 | J14: 0.25 | K14: 48.29 | L14: 23.18 | M14: 99.16 | N14: 0 | O14: 0 | P14: 1.16 | Q14: 5.83
A15: 03/11/2023 07:00 | B15: 35.78 | C15: 27.88 | D15: 44.61 | E15: 7.76 | F15: 2.57 | G15: 92.1 | H15: 35.85 | I15: 9.46 | J15: 0.32 | K15: 50.04 | L15: 23.78 | M15: 96.6 | N15: 36.8 | O15: 0 | P15: 1.15 | Q15: 5.85
A16: 03/11/2023 08:00 | B16: 35.55 | C16: 27.94 | D16: 44.38 | E16: 7.28 | F16: 2.49 | G16: 87.52 | H16: 35.03 | I16: 9.74 | J16: 0.61 | K16: 35.81 | L16: 24.25 | M16: 93.1 | N16: 92.7 | O16: 0 | P16: 1.16 | Q16: 5.85
A17: 03/11/2023 09:00 | B17: 34.75 | C17: 26.04 | D17: 42.82 | E17: 6.6 | F17: 3.04 | G17: 87.52 | H17: 33.59 | I17: 9.72 | J17: 0.62 | K17: 47.99 | L17: 26.47 | M17: 85.04 | N17: 214.4 | O17: 0 | P17: 1.11 | Q17: 5.77
A18: 03/11/2023 10:00 | B18: 32.62 | C18: 24.65 | D18: 39.27 | E18: 6.61 | F18: 3.47 | G18: 86.96 | H18: 33.08 | I18: 9.51 | J18: 0.5 | K18: 62.27 | L18: 29.83 | M18: 74.92 | N18: 405.2 | O18: 0 | P18: 1.05 | Q18: 5.61
A19: 03/11/2023 11:00 | B19: 27.94 | C19: 24.57 | D19: 36.6 | E19: 6.68 | F19: 5.4 | G19: 76.9 | H19: 33.08 | I19: 9.17 | J19: 0.42 | K19: 120.93 | L19: 30.85 | M19: 62.58 | N19: 417.3 | O19: 0 | P19: 1.02 | Q19: 5.42
A20: 03/11/2023 12:00 | B20: 23.2 | C20: 23.6 | D20: 32.29 | E20: 5.54 | F20: 3.88 | G20: 64.65 | H20: 26.49 | I20: 8.65 | J20: 0.3 | K20: 182.52 | L20: 30.73 | M20: 63 | N20: 428 | O20: 0 | P20: 0.95 | Q20: 5.24
... A32: 03/11/2023 24:00 | B32: 21.58 | C32: 21.61 | D32: 29.95 | E32: 5.91 | F32: 2.75 | G32: 36.86 | H32: 12.1 | I32: 7.14 | J32: 0.14 | K32: 321.85 | L32: 23.55 | M32: 102.79 | N32: 0 | O32: 0 | P32: 0.64 | Q32: 5.13
A34: Min | B34: =MIN(B9:B32) -> 10.73 | C34: =MIN(C9:C32) -> 20.7 | D34: =MIN(D9:D32) -> 21.83 | E34: =MIN(E9:E32) -> 4.84 | F34: =MIN(F9:F32) -> 2.49 | G34: =MIN(G9:G32) -> 36.86 | H34: =MIN(H9:H32) -> 12.1 | I34: =MIN(I9:I32) -> 5.59 | ... Q34: =MIN(Q9:Q32) -> 4.67
A35: Max | B35: =MAX(B9:B32) -> 35.84 | C35: =MAX(C9:C32) -> 27.94 | D35: =MAX(D9:D32) -> 44.61 | E35: =MAX(E9:E32) -> 7.76 | F35: =MAX(F9:F32) -> 5.58 | G35: =MAX(G9:G32) -> 92.1 | H35: =MAX(H9:H32) -> 36.04 | I35: =MAX(I9:I32) -> 9.74 | ... Q35: =MAX(Q9:Q32) -> 5.85
A36: Avg | B36: =AVERAGE(B9:B32) -> 24.399167 | C36: =AVERAGE(C9:C32) -> 23.675 | D36: =AVERAGE(D9:D32) -> 33.0375 | E36: =AVERAGE(E9:E32) -> 6.08125 | F36: =AVERAGE(F9:F32) -> 3.2570833 | G36: =AVERAGE(G9:G32) -> 64.882917 | H36: =AVERAGE(H9:H32) -> 23.765417 | I36: =AVERAGE(I9:I32) -> 8.3070833 | ... Q36: =AVERAGE(Q9:Q32) -> 5.25625
A37: Stdev | B37: =STDEV(B9:B32) -> 8.5462872 | C37: =STDEV(C9:C32) -> 2.2413486 | D37: =STDEV(D9:D32) -> 7.756622 | E37: =STDEV(E9:E32) -> 0.79331617 | F37: =STDEV(F9:F32) -> 0.89581384 | G37: =STDEV(G9:G32) -> 20.556817 | H37: =STDEV(H9:H32) -> 9.1283024 | I37: =STDEV(I9:I32) -> 1.2551164 | ... Q37: =STDEV(Q9:Q32) -> 0.40537489
A38: Num | B38: =COUNT(B9:B32) -> 24 | C38: =COUNT(C9:C32) -> 24 | D38: =COUNT(D9:D32) -> 24 | E38: =COUNT(E9:E32) -> 24 | F38: =COUNT(F9:F32) -> 24 | G38: =COUNT(G9:G32) -> 24 | H38: =COUNT(H9:H32) -> 24 | I38: =COUNT(I9:I32) -> 24 | ... Q38: =COUNT(Q9:Q32) -> 24
A39: DCR | B39: =IF(B38>=22,">90%",IF(B38<=22,"<90%")) -> >90% | C39: =IF(C38>=22,">90%",IF(C38<=22,"<90%")) -> >90% | D39: =IF(D38>=22,">90%",IF(D38<=22,"<90%")) -> >90% | E39: =IF(E38>=22,">90%",IF(E38<=22,"<90%")) -> >90% | F39: =IF(F38>=22,">90%",IF(F38<=22,"<90%")) -> >90% | G39: =IF(G38>=22,">90%",IF(G38<=22,"<90%")) -> >90% | H39: =IF(H38>=22,">90%",IF(H38<=22,"<90%")) -> >90% | I39: =IF(I38>=22,">90%",IF(I38<=22,"<90%")) -> >90% | ... Q39: =IF(Q38>=22,">90%",IF(Q38<=22,"<90%")) -> >90%
A40: Status | B40: =IF(B38>=22,"OK",IF(B38<=22,"LESS")) -> OK | C40: =IF(C38>=22,"OK",IF(C38<=22,"LESS")) -> OK | D40: =IF(D38>=22,"OK",IF(D38<=22,"LESS")) -> OK | E40: =IF(E38>=22,"OK",IF(E38<=22,"LESS")) -> OK | F40: =IF(F38>=22,"OK",IF(F38<=22,"LESS")) -> OK | G40: =IF(G38>=22,"OK",IF(G38<=22,"LESS")) -> OK | H40: =IF(H38>=22,"OK",IF(H38<=22,"LESS")) -> OK | I40: =IF(I38>=22,"OK",IF(I38<=22,"LESS")) -> OK | ... Q40: =IF(Q38>=22,"OK",IF(Q38<=22,"LESS")) -> OK
A43: Done by | B43: AKASH
A45: Comment

Sheet 04
A1: Station: | B1: IGKV ,RAIPUR
A2: Date: | B2: =$A$9 -> 04/11/2023 01:00 | D2: Power Off | G2: Pw.Off | L2: Link Fail | N2: Link F | P2: Maintenance | R2: Maint.
A3: Report Type: | B3: Mean | D3: Calibration | G3: Calib. | L3: Data Fail | N3: Data F | P3: Invalid | R3: Invalid
A4: Time Base: | B4: 01 Hour | D4: Zero Referrence | G4: Z.Ref | L4: Warm Up | N4: Wm. Up
A7: Date & Time | B7: NO | C7: NO2 | D7: NOX | E7: SO2 | F7: O3 | G7: PM 10 | H7: PM 2.5 | I7: BENZ | J7: WS | K7: WD | L7: TEMP | M7: HUM | N7: SR | O7: RG | P7: CO | Q7: NH3
B8: ug/m3 | C8: ug/m3 | D8: ppb | E8: ug/m3 | F8: ug/m3 | G8: ug/m3 | H8: ug/m3 | I8: ug/m3 | J8: m/sec | K8: deg | L8: degreC | M8: % | N8: w/m2 | O8: mm | P8: mg/m3 | Q8: ug/m3
A9: 04/11/2023 01:00 | B9: 23.4 | C9: 22.53 | D9: 31.68 | E9: 6.23 | F9: 2.68 | G9: 38.58 | H9: 13.14 | I9: 6.71 | J9: 0.12 | K9: 242.1 | L9: 23.22 | M9: 103.85 | N9: 0 | O9: 0 | P9: 0.64 | Q9: 5.21
A10: 04/11/2023 02:00 | B10: 22.33 | C10: 22.8 | D10: 31.17 | E10: 6.59 | F10: 2.47 | G10: 34.14 | H10: 11.83 | I10: 6.36 | J10: 0.17 | K10: 178.41 | L10: 23.04 | M10: 103.08 | N10: 0 | O10: 0 | P10: 0.61 | Q10: 5.21
A11: 04/11/2023 03:00 | B11: 27.11 | C11: 23.93 | D11: 35.6 | E11: 6.78 | F11: 2.45 | G11: 35.92 | H11: 14.36 | I11: 6.02 | J11: 0.21 | K11: 258.38 | L11: 22.82 | M11: 104.07 | N11: 0 | O11: 0 | P11: 0.59 | Q11: 5.39
A12: 04/11/2023 04:00 | B12: 32.92 | C12: 24.7 | D12: 39.45 | E12: 6.4 | F12: 2.89 | G12: 44.92 | H12: 14.36 | I12: 5.82 | J12: 0.18 | K12: 163.27 | L12: 22.63 | M12: 101.08 | N12: 0 | O12: 0 | P12: 0.58 | Q12: 5.63
A13: 04/11/2023 05:00 | B13: 35.26 | C13: 22.34 | D13: 41.14 | E13: 5.88 | F13: 2.91 | G13: 44.92 | H13: 12.97 | I13: 5.73 | J13: 0.14 | K13: 179.09 | L13: 22.48 | M13: 100.36 | N13: 0 | O13: 0 | P13: 0.51 | Q13: 5.65
A14: 04/11/2023 06:00 | B14: 35.23 | C14: 22.06 | D14: 40.78 | E14: 5.84 | F14: 2.71 | G14: 39.37 | H14: 13.36 | I14: 5.77 | J14: 0.11 | K14: 227.04 | L14: 22.46 | M14: 100.36 | N14: 0 | O14: 0 | P14: 0.51 | Q14: 5.65
A15: 04/11/2023 07:00 | B15: 34.32 | C15: 22.32 | D15: 40.3 | E15: 5.87 | F15: 2.74 | G15: 39.33 | H15: 13.36 | I15: 5.85 | J15: 0.1 | K15: 200.08 | L15: 22.58 | M15: 99.99 | N15: 35.2 | O15: 0 | P15: 0.51 | Q15: 5.61
A16: 04/11/2023 08:00 | B16: 33.27 | C16: 21.82 | D16: 39.38 | E16: 5.61 | F16: 2.7 | G16: 38.32 | H16: 9.76 | I16: 5.83 | J16: 0.19 | K16: 168.1 | L16: 24.47 | M16: 97.71 | N16: 157.7 | O16: 0 | P16: 0.5 | Q16: 5.57
A17: 04/11/2023 09:00 | B17: 32.12 | C17: 21.97 | D17: 37.75 | E17: 6.16 | F17: 3.14 | G17: 37.47 | H17: 10.57 | I17: 6.9 | J17: 0.4 | K17: 57.94 | L17: 26.75 | M17: 86.17 | N17: 316.6 | O17: 0 | P17: 0.55 | Q17: 5.52
A18: 04/11/2023 10:00 | B18: 28.44 | C18: 23.83 | D18: 35.93 | E18: 5.98 | F18: 3.01 | G18: 37.47 | H18: 11.95 | I18: 7.11 | J18: 0.43 | K18: 50.1 | L18: 28.29 | M18: 78.13 | N18: 494.3 | O18: 0 | P18: 0.58 | Q18: 5.36
A19: 04/11/2023 11:00 | B19: 24.38 | C19: 25.41 | D19: 33.51 | E19: 5.26 | F19: 3.41 | G19: 40.8 | H19: 15 | I19: 7.02 | J19: 0.42 | K19: 67.56 | L19: 29.62 | M19: 68.16 | N19: 580.5 | O19: 0 | P19: 0.58 | Q19: 5.28
A20: 04/11/2023 12:00 | B20: 19.68 | C20: 25.49 | D20: 30.34 | E20: 5.23 | F20: 3.34 | G20: 40.8 | H20: 15 | I20: 6.47 | J20: 0.45 | K20: 39.57 | L20: 28.71 | M20: 69.64 | N20: 210 | O20: 0 | P20: 0.58 | Q20: 5.12
... A32: 04/11/2023 24:00 | B32: 26.83 | C32: 31.6 | D32: 38.59 | E32: 7.87 | F32: 3.08 | G32: 119.69 | H32: 47.42 | I32: 8.9 | J32: 0.26 | K32: 106.6 | L32: 23.84 | M32: 92.34 | N32: 0 | O32: 0 | P32: 1.02 | Q32: 5.35
A34: Min | B34: =MIN(B9:B32) -> 4.19 | C34: =MIN(C9:C32) -> 20.48 | D34: =MIN(D9:D32) -> 15.69 | E34: =MIN(E9:E32) -> 5.23 | F34: =MIN(F9:F32) -> 2.45 | G34: =MIN(G9:G32) -> 34.14 | H34: =MIN(H9:H32) -> 9.76 | I34: =MIN(I9:I32) -> 4.79 | ... Q34: =MIN(Q9:Q32) -> 4.28
A35: Max | B35: =MAX(B9:B32) -> 35.26 | C35: =MAX(C9:C32) -> 31.6 | D35: =MAX(D9:D32) -> 41.14 | E35: =MAX(E9:E32) -> 13.05 | F35: =MAX(F9:F32) -> 16.4 | G35: =MAX(G9:G32) -> 119.69 | H35: =MAX(H9:H32) -> 47.42 | I35: =MAX(I9:I32) -> 8.9 | ... Q35: =MAX(Q9:Q32) -> 5.65
A36: Avg | B36: =AVERAGE(B9:B32) -> 21.77375 | C36: =AVERAGE(C9:C32) -> 25.028333 | D36: =AVERAGE(D9:D32) -> 31.642917 | E36: =AVERAGE(E9:E32) -> 7.15125 | F36: =AVERAGE(F9:F32) -> 4.3825 | G36: =AVERAGE(G9:G32) -> 60.53125 | H36: =AVERAGE(H9:H32) -> 22.384167 | I36: =AVERAGE(I9:I32) -> 6.4708333 | ... Q36: =AVERAGE(Q9:Q32) -> 5.1075
A37: Stdev | B37: =STDEV(B9:B32) -> 9.8860525 | C37: =STDEV(C9:C32) -> 3.5646119 | D37: =STDEV(D9:D32) -> 7.9211744 | E37: =STDEV(E9:E32) -> 1.9833356 | F37: =STDEV(F9:F32) -> 3.255492 | G37: =STDEV(G9:G32) -> 30.537848 | H37: =STDEV(H9:H32) -> 13.002167 | I37: =STDEV(I9:I32) -> 1.110773 | ... Q37: =STDEV(Q9:Q32) -> 0.45232972
A38: Num | B38: =COUNT(B9:B32) -> 24 | C38: =COUNT(C9:C32) -> 24 | D38: =COUNT(D9:D32) -> 24 | E38: =COUNT(E9:E32) -> 24 | F38: =COUNT(F9:F32) -> 24 | G38: =COUNT(G9:G32) -> 24 | H38: =COUNT(H9:H32) -> 24 | I38: =COUNT(I9:I32) -> 24 | ... Q38: =COUNT(Q9:Q32) -> 24
A39: DCR | B39: =IF(B38>=22,">90%",IF(B38<=22,"<90%")) -> >90% | C39: =IF(C38>=22,">90%",IF(C38<=22,"<90%")) -> >90% | D39: =IF(D38>=22,">90%",IF(D38<=22,"<90%")) -> >90% | E39: =IF(E38>=22,">90%",IF(E38<=22,"<90%")) -> >90% | F39: =IF(F38>=22,">90%",IF(F38<=22,"<90%")) -> >90% | G39: =IF(G38>=22,">90%",IF(G38<=22,"<90%")) -> >90% | H39: =IF(H38>=22,">90%",IF(H38<=22,"<90%")) -> >90% | I39: =IF(I38>=22,">90%",IF(I38<=22,"<90%")) -> >90% | ... Q39: =IF(Q38>=22,">90%",IF(Q38<=22,"<90%")) -> >90%
A40: Status | B40: =IF(B38>=22,"OK",IF(B38<=22,"LESS")) -> OK | C40: =IF(C38>=22,"OK",IF(C38<=22,"LESS")) -> OK | D40: =IF(D38>=22,"OK",IF(D38<=22,"LESS")) -> OK | E40: =IF(E38>=22,"OK",IF(E38<=22,"LESS")) -> OK | F40: =IF(F38>=22,"OK",IF(F38<=22,"LESS")) -> OK | G40: =IF(G38>=22,"OK",IF(G38<=22,"LESS")) -> OK | H40: =IF(H38>=22,"OK",IF(H38<=22,"LESS")) -> OK | I40: =IF(I38>=22,"OK",IF(I38<=22,"LESS")) -> OK | ... Q40: =IF(Q38>=22,"OK",IF(Q38<=22,"LESS")) -> OK
A43: Done by | B43: AKASH
A45: Comment

Sheet 05
A1: Station: | B1: IGKV ,RAIPUR
A2: Date: | B2: =$A$9 -> 05/11/2023 01:00 | D2: Power Off | G2: Pw.Off | L2: Link Fail | N2: Link F | P2: Maintenance | R2: Maint.
A3: Report Type: | B3: Mean | D3: Calibration | G3: Calib. | L3: Data Fail | N3: Data F | P3: Invalid | R3: Invalid
A4: Time Base: | B4: 01 Hour | D4: Zero Referrence | G4: Z.Ref | L4: Warm Up | N4: Wm. Up
A7: Date & Time | B7: NO | C7: NO2 | D7: NOX | E7: SO2 | F7: O3 | G7: PM 10 | H7: PM 2.5 | I7: BENZ | J7: WS | K7: WD | L7: TEMP | M7: HUM | N7: SR | O7: RG | P7: CO | Q7: NH3
B8: ug/m3 | C8: ug/m3 | D8: ppb | E8: ug/m3 | F8: ug/m3 | G8: ug/m3 | H8: ug/m3 | I8: ug/m3 | J8: m/sec | K8: deg | L8: degreC | M8: % | N8: w/m2 | O8: mm | P8: mg/m3 | Q8: ug/m3
A9: 05/11/2023 01:00 | B9: 29.03 | C9: 27.59 | D9: 37.96 | E9: 6.22 | F9: 2.92 | G9: 119.69 | H9: 46.62 | I9: 9.04 | J9: 0.2 | K9: 236.37 | L9: 23.56 | M9: 94.82 | N9: 0 | O9: 0 | P9: 0.96 | Q9: 5.38
A10: 05/11/2023 02:00 | B10: 29.13 | C10: 24.53 | D10: 37.49 | E10: 5.75 | F10: 2.92 | G10: 113.4 | H10: 45.62 | I10: 9.06 | J10: 0.43 | K10: 31.65 | L10: 22.66 | M10: 94.82 | N10: 0 | O10: 0 | P10: 0.93 | Q10: 5.37
A11: 05/11/2023 03:00 | B11: 28.55 | C11: 24.17 | D11: 36.88 | E11: 5.98 | F11: 2.81 | G11: 104.52 | H11: 43.16 | I11: 8.91 | J11: 0.26 | K11: 244.91 | L11: 22.36 | M11: 92.12 | N11: 0 | O11: 0 | P11: 0.89 | Q11: 5.35
A12: 05/11/2023 04:00 | B12: 28.02 | C12: 23.95 | D12: 36.15 | E12: 6.54 | F12: 2.68 | G12: 100.2 | H12: 42.76 | I12: 8.59 | J12: 0.45 | K12: 40.53 | L12: 21.8 | M12: 91.4 | N12: 0 | O12: 0 | P12: 0.86 | Q12: 5.32
A13: 05/11/2023 05:00 | B13: 27.93 | C13: 25.93 | D13: 36.89 | E13: 6.36 | F13: 2.76 | G13: 94.94 | H13: 42.07 | I13: 8.29 | J13: 0.42 | K13: 37.93 | L13: 21.47 | M13: 88.7 | N13: 0 | O13: 0 | P13: 0.85 | Q13: 5.35
A14: 05/11/2023 06:00 | B14: 27.58 | C14: 26.42 | D14: 37.23 | E14: 6.45 | F14: 2.8 | G14: 94.22 | H14: 41.14 | I14: 8.09 | J14: 0.38 | K14: 37.01 | L14: 20.73 | M14: 92.67 | N14: 0 | O14: 0 | P14: 0.82 | Q14: 5.37
A15: 05/11/2023 07:00 | B15: 28.91 | C15: 26.85 | D15: 38.57 | E15: 6.94 | F15: 2.75 | G15: 88.18 | H15: 41.29 | I15: 8.1 | J15: 0.39 | K15: 41.51 | L15: 21.03 | M15: 92.29 | N15: 40.2 | O15: 0 | P15: 0.83 | Q15: 5.42
A16: 05/11/2023 08:00 | B16: 28.75 | C16: 27.29 | D16: 38.46 | E16: 7.34 | F16: 2.59 | G16: 88.46 | H16: 41.29 | I16: 8.28 | J16: 0.59 | K16: 38.81 | L16: 22.28 | M16: 86.69 | N16: 141.2 | O16: 0 | P16: 0.84 | Q16: 5.45
A17: 05/11/2023 09:00 | B17: 27.31 | C17: 27.93 | D17: 37.56 | E17: 6.94 | F17: 2.69 | G17: 88.52 | H17: 40.42 | I17: 8.25 | J17: 0.76 | K17: 40.46 | L17: 24.42 | M17: 77.18 | N17: 278.2 | O17: 0 | P17: 0.83 | Q17: 5.39
A18: 05/11/2023 10:00 | B18: 24.19 | C18: 27.93 | D18: 35.34 | E18: 6.69 | F18: 3.17 | G18: 91.53 | H18: 40.42 | I18: 7.99 | J18: 0.64 | K18: 47.88 | L18: 27.07 | M18: 73.39 | N18: 440.6 | O18: 0 | P18: 0.81 | Q18: 5.24
A19: 05/11/2023 11:00 | B19: 21.87 | C19: 23.51 | D19: 31.17 | E19: 7.38 | F19: 4.42 | G19: 91.53 | H19: 39.12 | I19: 7.89 | J19: 0.51 | K19: 79.32 | L19: 28.9 | M19: 71.5 | N19: 528.8 | O19: 0 | P19: 0.77 | Q19: 5.08
A20: 05/11/2023 12:00 | B20: 16.96 | C20: 22.61 | D20: 26.76 | E20: 9.42 | F20: 7.94 | G20: 82.01 | H20: 33.83 | I20: 7.49 | J20: 0.94 | K20: 53.3 | L20: 29.55 | M20: 64.55 | N20: 551.5 | O20: 0 | P20: 0.73 | Q20: 4.88
... A32: 05/11/2023 24:00 | B32: 12.56 | C32: 21.26 | D32: 22.4 | E32: 6.25 | F32: 2.63 | G32: 82.81 | H32: 28.94 | I32: 6.44 | J32: 0.16 | K32: 230.75 | L32: 19.5 | M32: 87.62 | N32: 0 | O32: 0 | P32: 0.7 | Q32: 4.64
A34: Min | B34: =MIN(B9:B32) -> 5.88 | C34: =MIN(C9:C32) -> 21.05 | D34: =MIN(D9:D32) -> 17.18 | E34: =MIN(E9:E32) -> 5.45 | F34: =MIN(F9:F32) -> 2.59 | G34: =MIN(G9:G32) -> 61.35 | H34: =MIN(H9:H32) -> 24.54 | I34: =MIN(I9:I32) -> 5.17 | ... Q34: =MIN(Q9:Q32) -> 4.29
A35: Max | B35: =MAX(B9:B32) -> 29.13 | C35: =MAX(C9:C32) -> 27.93 | D35: =MAX(D9:D32) -> 38.57 | E35: =MAX(E9:E32) -> 9.42 | F35: =MAX(F9:F32) -> 8.93 | G35: =MAX(G9:G32) -> 119.69 | H35: =MAX(H9:H32) -> 46.62 | I35: =MAX(I9:I32) -> 9.06 | ... Q35: =MAX(Q9:Q32) -> 5.45
A36: Avg | B36: =AVERAGE(B9:B32) -> 18.564583 | C36: =AVERAGE(C9:C32) -> 24.299583 | D36: =AVERAGE(D9:D32) -> 28.790833 | E36: =AVERAGE(E9:E32) -> 6.7954167 | F36: =AVERAGE(F9:F32) -> 4.0370833 | G36: =AVERAGE(G9:G32) -> 89.449583 | H36: =AVERAGE(H9:H32) -> 35.41625 | I36: =AVERAGE(I9:I32) -> 7.1995833 | ... Q36: =AVERAGE(Q9:Q32) -> 4.9179167
A37: Stdev | B37: =STDEV(B9:B32) -> 8.7170567 | C37: =STDEV(C9:C32) -> 2.3967396 | D37: =STDEV(D9:D32) -> 7.8411778 | E37: =STDEV(E9:E32) -> 0.92100597 | F37: =STDEV(F9:F32) -> 2.1506995 | G37: =STDEV(G9:G32) -> 15.209346 | H37: =STDEV(H9:H32) -> 6.9375931 | I37: =STDEV(I9:I32) -> 1.2570513 | ... Q37: =STDEV(Q9:Q32) -> 0.41679918
A38: Num | B38: =COUNT(B9:B32) -> 24 | C38: =COUNT(C9:C32) -> 24 | D38: =COUNT(D9:D32) -> 24 | E38: =COUNT(E9:E32) -> 24 | F38: =COUNT(F9:F32) -> 24 | G38: =COUNT(G9:G32) -> 24 | H38: =COUNT(H9:H32) -> 24 | I38: =COUNT(I9:I32) -> 24 | ... Q38: =COUNT(Q9:Q32) -> 24
A39: DCR | B39: =IF(B38>=22,">90%",IF(B38<=22,"<90%")) -> >90% | C39: =IF(C38>=22,">90%",IF(C38<=22,"<90%")) -> >90% | D39: =IF(D38>=22,">90%",IF(D38<=22,"<90%")) -> >90% | E39: =IF(E38>=22,">90%",IF(E38<=22,"<90%")) -> >90% | F39: =IF(F38>=22,">90%",IF(F38<=22,"<90%")) -> >90% | G39: =IF(G38>=22,">90%",IF(G38<=22,"<90%")) -> >90% | H39: =IF(H38>=22,">90%",IF(H38<=22,"<90%")) -> >90% | I39: =IF(I38>=22,">90%",IF(I38<=22,"<90%")) -> >90% | ... Q39: =IF(Q38>=22,">90%",IF(Q38<=22,"<90%")) -> >90%
A40: Status | B40: =IF(B38>=22,"OK",IF(B38<=22,"LESS")) -> OK | C40: =IF(C38>=22,"OK",IF(C38<=22,"LESS")) -> OK | D40: =IF(D38>=22,"OK",IF(D38<=22,"LESS")) -> OK | E40: =IF(E38>=22,"OK",IF(E38<=22,"LESS")) -> OK | F40: =IF(F38>=22,"OK",IF(F38<=22,"LESS")) -> OK | G40: =IF(G38>=22,"OK",IF(G38<=22,"LESS")) -> OK | H40: =IF(H38>=22,"OK",IF(H38<=22,"LESS")) -> OK | I40: =IF(I38>=22,"OK",IF(I38<=22,"LESS")) -> OK | ... Q40: =IF(Q38>=22,"OK",IF(Q38<=22,"LESS")) -> OK
A43: Done by | B43: AKASH
A45: Comment

Sheet 06
A1: Station: | B1: IGKV ,RAIPUR
A2: Date: | B2: =$A$9 -> 06/11/2023 01:00 | D2: Power Off | G2: Pw.Off | L2: Link Fail | N2: Link F | P2: Maintenance | R2: Maint.
A3: Report Type: | B3: Mean | D3: Calibration | G3: Calib. | L3: Data Fail | N3: Data F | P3: Invalid | R3: Invalid
A4: Time Base: | B4: 01 Hour | D4: Zero Referrence | G4: Z.Ref | L4: Warm Up | N4: Wm. Up
A7: Date & Time | B7: NO | C7: NO2 | D7: NOX | E7: SO2 | F7: O3 | G7: PM 10 | H7: PM 2.5 | I7: BENZ | J7: WS | K7: WD | L7: TEMP | M7: HUM | N7: SR | O7: RG | P7: CO | Q7: NH3
B8: ug/m3 | C8: ug/m3 | D8: ppb | E8: ug/m3 | F8: ug/m3 | G8: ug/m3 | H8: ug/m3 | I8: ug/m3 | J8: m/sec | K8: deg | L8: degreC | M8: % | N8: w/m2 | O8: mm | P8: mg/m3 | Q8: ug/m3
A9: 06/11/2023 01:00 | B9: 15.53 | C9: 24.48 | D9: 26.59 | E9: 6.35 | F9: 2.66 | G9: 77.94 | H9: 28.94 | I9: 6.5 | J9: 0.44 | K9: 40.6 | L9: 20.18 | M9: 81.46 | N9: 0 | O9: 0 | P9: 0.72 | Q9: 4.79
A10: 06/11/2023 02:00 | B10: 15.46 | C10: 24.88 | D10: 26.57 | E10: 6.87 | F10: 2.87 | G10: 78.29 | H10: 28.67 | I10: 6.62 | J10: 0.39 | K10: 244.56 | L10: 20.21 | M10: 84.76 | N10: 0 | O10: 0 | P10: 0.72 | Q10: 4.8
A11: 06/11/2023 03:00 | B11: 16.33 | C11: 24.99 | D11: 27.51 | E11: 5.62 | F11: 2.73 | G11: 78.29 | H11: 29.05 | I11: 6.52 | J11: 0.19 | K11: 251.14 | L11: 19.18 | M11: 89.31 | N11: 0 | O11: 0 | P11: 0.72 | Q11: 4.81
A12: 06/11/2023 04:00 | B12: 18.61 | C12: 25.94 | D12: 29.73 | E12: 5.4 | F12: 2.77 | G12: 78.9 | H12: 31.58 | I12: 6.49 | J12: 0.21 | K12: 222.91 | L12: 19.26 | M12: 86.38 | N12: 0 | O12: 0 | P12: 0.71 | Q12: 4.94
A13: 06/11/2023 05:00 | B13: 20.23 | C13: 26.23 | D13: 31.28 | E13: 6.16 | F13: 2.59 | G13: 82.59 | H13: 31.61 | I13: 6.53 | J13: 0.28 | K13: 47.79 | L13: 19.37 | M13: 84.48 | N13: 0 | O13: 0 | P13: 0.7 | Q13: 4.98
A14: 06/11/2023 06:00 | B14: 23.22 | C14: 25.5 | D14: 32.49 | E14: 5.93 | F14: 2.84 | G14: 82.59 | H14: 32.66 | I14: 6.5 | J14: 0.21 | K14: 124.07 | L14: 18.97 | M14: 89.22 | N14: 0 | O14: 0 | P14: 0.68 | Q14: 5.08
A15: 06/11/2023 07:00 | B15: 27.65 | C15: 25.09 | D15: 36.59 | E15: 5.96 | F15: 2.53 | G15: 88.06 | H15: 36.08 | I15: 6.58 | J15: 0.24 | K15: 52.96 | L15: 19.34 | M15: 87.89 | N15: 29 | O15: 0 | P15: 0.72 | Q15: 5.24
A16: 06/11/2023 08:00 | B16: 30.73 | C16: 26.09 | D16: 39.52 | E16: 6.24 | F16: 2.79 | G16: 93.59 | H16: 37.27 | I16: 7.67 | J16: 0.59 | K16: 49.06 | L16: 21.16 | M16: 81.05 | N16: 152.3 | O16: 0 | P16: 0.81 | Q16: 5.38
A17: 06/11/2023 09:00 | B17: 30.5 | C17: 26.45 | D17: 39.63 | E17: 5.45 | F17: 2.85 | G17: 94.65 | H17: 38.44 | I17: 8.07 | J17: 0.68 | K17: 41.38 | L17: 24.66 | M17: 75.29 | N17: 368.8 | O17: 0 | P17: 0.82 | Q17: 5.39
A18: 06/11/2023 10:00 | B18: 28.57 | C18: 26.41 | D18: 37.71 | E18: 6.04 | F18: 3.47 | G18: 97.5 | H18: 38.65 | I18: 8.06 | J18: 0.59 | K18: 82.32 | L18: 28.04 | M18: 61.39 | N18: 495.8 | O18: 0 | P18: 0.84 | Q18: 5.32
A19: 06/11/2023 11:00 | B19: 23.81 | C19: 27.66 | D19: 34.31 | E19: 7.67 | F19: 4.08 | G19: 97.5 | H19: 38.65 | I19: 8.04 | J19: 0.48 | K19: 91.44 | L19: 29.59 | M19: 56.31 | N19: 578.4 | O19: 0 | P19: 0.85 | Q19: 5.15
A20: 06/11/2023 12:00 | B20: 16.76 | C20: 28.05 | D20: 29.38 | E20: 8.31 | F20: 4.33 | G20: 86.47 | H20: 37.11 | I20: 7.6 | J20: 0.5 | K20: 69.6 | L20: 30.78 | M20: 46.84 | N20: 661.1 | O20: 0 | P20: 0.8 | Q20: 4.86
... A32: 06/11/2023 24:00 | B32: 42.17 | C32: 30.18 | D32: 50.94 | E32: 7 | F32: 2.66 | G32: 122.87 | H32: 38.5 | I32: 9.34 | J32: 0.13 | K32: 192.88 | L32: 20.42 | M32: 85.2 | N32: 0 | O32: 0 | P32: 1.08 | Q32: 5.83
A34: Min | B34: =MIN(B9:B32) -> 6.32 | C34: =MIN(C9:C32) -> 19.22 | D34: =MIN(D9:D32) -> 16.71 | E34: =MIN(E9:E32) -> 5.4 | F34: =MIN(F9:F32) -> 2.53 | G34: =MIN(G9:G32) -> 51.93 | H34: =MIN(H9:H32) -> 20.99 | I34: =MIN(I9:I32) -> 5.04 | ... Q34: =MIN(Q9:Q32) -> 4.26
A35: Max | B35: =MAX(B9:B32) -> 42.17 | C35: =MAX(C9:C32) -> 30.48 | D35: =MAX(D9:D32) -> 50.94 | E35: =MAX(E9:E32) -> 8.6 | F35: =MAX(F9:F32) -> 7.06 | G35: =MAX(G9:G32) -> 135.62 | H35: =MAX(H9:H32) -> 38.65 | I35: =MAX(I9:I32) -> 9.34 | ... Q35: =MAX(Q9:Q32) -> 5.83
A36: Avg | B36: =AVERAGE(B9:B32) -> 19.96625 | C36: =AVERAGE(C9:C32) -> 25.69375 | D36: =AVERAGE(D9:D32) -> 30.647083 | E36: =AVERAGE(E9:E32) -> 6.5004167 | F36: =AVERAGE(F9:F32) -> 3.45625 | G36: =AVERAGE(G9:G32) -> 88.720833 | H36: =AVERAGE(H9:H32) -> 32.3 | I36: =AVERAGE(I9:I32) -> 7.0416667 | ... Q36: =AVERAGE(Q9:Q32) -> 4.93625
A37: Stdev | B37: =STDEV(B9:B32) -> 10.147509 | C37: =STDEV(C9:C32) -> 2.6337439 | D37: =STDEV(D9:D32) -> 9.1984032 | E37: =STDEV(E9:E32) -> 0.87074421 | F37: =STDEV(F9:F32) -> 1.2011654 | G37: =STDEV(G9:G32) -> 23.614481 | H37: =STDEV(H9:H32) -> 5.7299624 | I37: =STDEV(I9:I32) -> 1.1888967 | ... Q37: =STDEV(Q9:Q32) -> 0.43597779
A38: Num | B38: =COUNT(B9:B32) -> 24 | C38: =COUNT(C9:C32) -> 24 | D38: =COUNT(D9:D32) -> 24 | E38: =COUNT(E9:E32) -> 24 | F38: =COUNT(F9:F32) -> 24 | G38: =COUNT(G9:G32) -> 24 | H38: =COUNT(H9:H32) -> 24 | I38: =COUNT(I9:I32) -> 24 | ... Q38: =COUNT(Q9:Q32) -> 24
A39: DCR | B39: =IF(B38>=22,">90%",IF(B38<=22,"<90%")) -> >90% | C39: =IF(C38>=22,">90%",IF(C38<=22,"<90%")) -> >90% | D39: =IF(D38>=22,">90%",IF(D38<=22,"<90%")) -> >90% | E39: =IF(E38>=22,">90%",IF(E38<=22,"<90%")) -> >90% | F39: =IF(F38>=22,">90%",IF(F38<=22,"<90%")) -> >90% | G39: =IF(G38>=22,">90%",IF(G38<=22,"<90%")) -> >90% | H39: =IF(H38>=22,">90%",IF(H38<=22,"<90%")) -> >90% | I39: =IF(I38>=22,">90%",IF(I38<=22,"<90%")) -> >90% | ... Q39: =IF(Q38>=22,">90%",IF(Q38<=22,"<90%")) -> >90%
A40: Status | B40: =IF(B38>=22,"OK",IF(B38<=22,"LESS")) -> OK | C40: =IF(C38>=22,"OK",IF(C38<=22,"LESS")) -> OK | D40: =IF(D38>=22,"OK",IF(D38<=22,"LESS")) -> OK | E40: =IF(E38>=22,"OK",IF(E38<=22,"LESS")) -> OK | F40: =IF(F38>=22,"OK",IF(F38<=22,"LESS")) -> OK | G40: =IF(G38>=22,"OK",IF(G38<=22,"LESS")) -> OK | H40: =IF(H38>=22,"OK",IF(H38<=22,"LESS")) -> OK | I40: =IF(I38>=22,"OK",IF(I38<=22,"LESS")) -> OK | ... Q40: =IF(Q38>=22,"OK",IF(Q38<=22,"LESS")) -> OK
A43: Done by | B43: AKASH
A45: Comment

Sheet 07
A1: Station: | B1: IGKV ,RAIPUR
A2: Date: | B2: =$A$9 -> 07/11/2023 01:00 | D2: Power Off | G2: Pw.Off | L2: Link Fail | N2: Link F | P2: Maintenance | R2: Maint.
A3: Report Type: | B3: Mean | D3: Calibration | G3: Calib. | L3: Data Fail | N3: Data F | P3: Invalid | R3: Invalid
A4: Time Base: | B4: 01 Hour | D4: Zero Referrence | G4: Z.Ref | L4: Warm Up | N4: Wm. Up
A7: Date & Time | B7: NO | C7: NO2 | D7: NOX | E7: SO2 | F7: O3 | G7: PM 10 | H7: PM 2.5 | I7: BENZ | J7: WS | K7: WD | L7: TEMP | M7: HUM | N7: SR | O7: RG | P7: CO | Q7: NH3
B8: ug/m3 | C8: ug/m3 | D8: ppb | E8: ug/m3 | F8: ug/m3 | G8: ug/m3 | H8: ug/m3 | I8: ug/m3 | J8: m/sec | K8: deg | L8: degreC | M8: % | N8: w/m2 | O8: mm | P8: mg/m3 | Q8: ug/m3
A9: 07/11/2023 01:00 | B9: 47.53 | C9: 30.62 | D9: 55.42 | E9: 7.47 | F9: 2.65 | G9: 109.01 | H9: 36.36 | I9: 9.63 | J9: 0.16 | K9: 186.97 | L9: 20.26 | M9: 88.44 | N9: 0 | O9: 0 | P9: 1.1 | Q9: 6.05
A10: 07/11/2023 02:00 | B10: 55.12 | C10: 28.95 | D10: 60.68 | E10: 6.79 | F10: 2.87 | G10: 116.22 | H10: 35.88 | I10: 9.65 | J10: 0.1 | K10: 237.09 | L10: 19.87 | M10: 87.58 | N10: 0 | O10: 0 | P10: 1.07 | Q10: 6.28
A11: 07/11/2023 03:00 | B11: 58.29 | C11: 28.72 | D11: 63.1 | E11: 6.91 | F11: 2.71 | G11: 116.76 | H11: 39.14 | I11: 9.9 | J11: 0.12 | K11: 201.71 | L11: 19.69 | M11: 90.51 | N11: 0 | O11: 0 | P11: 1.07 | Q11: 6.42
A12: 07/11/2023 04:00 | B12: 60.6 | C12: 28.57 | D12: 64.46 | E12: 6.7 | F12: 2.63 | G12: 116.76 | H12: 39.62 | I12: 10.07 | J12: 0.11 | K12: 240.27 | L12: 19.4 | M12: 89.62 | N12: 0 | O12: 0 | P12: 1.07 | Q12: 6.51
A13: 07/11/2023 05:00 | B13: 60.87 | C13: 28.32 | D13: 64.96 | E13: 7 | F13: 2.69 | G13: 116.39 | H13: 39.62 | I13: 10.11 | J13: 0.14 | K13: 248.29 | L13: 19.22 | M13: 92.99 | N13: 0 | O13: 0 | P13: 1.04 | Q13: 6.53
A14: 07/11/2023 06:00 | B14: 61.92 | C14: 27.11 | D14: 64.87 | E14: 6.88 | F14: 2.64 | G14: 106.33 | H14: 37.49 | I14: 9.87 | J14: 0.22 | K14: 181.04 | L14: 18.55 | M14: 93.72 | N14: 0 | O14: 0 | P14: 1.01 | Q14: 6.55
A15: 07/11/2023 07:00 | B15: 62.12 | C15: 27.9 | D15: 65.74 | E15: 6.98 | F15: 2.7 | G15: 101.61 | H15: 36.69 | I15: 9.77 | J15: 0.12 | K15: 356.98 | L15: 18.9 | M15: 93.21 | N15: 26.6 | O15: 0 | P15: 1.04 | Q15: 6.52
A16: 07/11/2023 08:00 | B16: 63.73 | C16: 29.66 | D16: 67.48 | E16: 7.46 | F16: 2.59 | G16: 117.81 | H16: 41.34 | I16: 10.11 | J16: 0.3 | K16: 219.25 | L16: 22.07 | M16: 87.47 | N16: 191.6 | O16: 0 | P16: 1.08 | Q16: 6.75
A17: 07/11/2023 09:00 | B17: 58.31 | C17: 32.59 | D17: 63.81 | E17: 7.59 | F17: 2.86 | G17: 125.98 | H17: 48.76 | I17: 10.25 | J17: 0.44 | K17: 53.81 | L17: 25.59 | M17: 67.41 | N17: 350.8 | O17: 0 | P17: 1.11 | Q17: 6.59
A18: 07/11/2023 10:00 | B18: 47.08 | C18: 35.37 | D18: 56.52 | E18: 8.08 | F18: 2.87 | G18: 128.07 | H18: 48.76 | I18: 10.42 | J18: 0.36 | K18: 196.18 | L18: 28.71 | M18: 57.21 | N18: 507.7 | O18: 0 | P18: 1.13 | Q18: 6.22
A19: 07/11/2023 11:00 | B19: 32.98 | C19: 35.86 | D19: 46.22 | E19: 6.29 | F19: 2.94 | G19: 128.07 | H19: 48.12 | I19: 10.32 | J19: 0.27 | K19: 169.78 | L19: 30.77 | M19: 44.41 | N19: 607.9 | O19: 0 | P19: 1.1 | Q19: 5.66
A20: 07/11/2023 12:00 | B20: 21.44 | C20: 32.51 | D20: 35.53 | E20: 5.85 | F20: 3.68 | G20: 111.88 | H20: 43.44 | I20: 9.63 | J20: 0.38 | K20: 249.43 | L20: 31.51 | M20: 33.53 | N20: 662.5 | O20: 0 | P20: 1.02 | Q20: 5.15
... A32: 07/11/2023 24:00 | B32: 13.2 | C32: 23.22 | D32: 23.81 | E32: 7.02 | F32: 2.67 | G32: 86.81 | H32: 32.23 | I32: 8.04 | J32: 0.21 | K32: 218.88 | L32: 19.85 | M32: 88.1 | N32: 0 | O32: 0 | P32: 0.84 | Q32: 4.66
A34: Min | B34: =MIN(B9:B32) -> 6.91 | C34: =MIN(C9:C32) -> 23.22 | D34: =MIN(D9:D32) -> 19.47 | E34: =MIN(E9:E32) -> 4.16 | F34: =MIN(F9:F32) -> 2.59 | G34: =MIN(G9:G32) -> 75.35 | H34: =MIN(H9:H32) -> 27.01 | I34: =MIN(I9:I32) -> 5.94 | ... Q34: =MIN(Q9:Q32) -> 4.34
A35: Max | B35: =MAX(B9:B32) -> 63.73 | C35: =MAX(C9:C32) -> 35.86 | D35: =MAX(D9:D32) -> 67.48 | E35: =MAX(E9:E32) -> 8.08 | F35: =MAX(F9:F32) -> 8.84 | G35: =MAX(G9:G32) -> 128.07 | H35: =MAX(H9:H32) -> 48.76 | I35: =MAX(I9:I32) -> 10.42 | ... Q35: =MAX(Q9:Q32) -> 6.75
A36: Avg | B36: =AVERAGE(B9:B32) -> 31.707083 | C36: =AVERAGE(C9:C32) -> 28.360833 | D36: =AVERAGE(D9:D32) -> 41.371667 | E36: =AVERAGE(E9:E32) -> 6.5658333 | F36: =AVERAGE(F9:F32) -> 3.6883333 | G36: =AVERAGE(G9:G32) -> 107.86208 | H36: =AVERAGE(H9:H32) -> 36.898333 | I36: =AVERAGE(I9:I32) -> 8.695 | ... Q36: =AVERAGE(Q9:Q32) -> 5.4175
A37: Stdev | B37: =STDEV(B9:B32) -> 23.180911 | C37: =STDEV(C9:C32) -> 3.3674334 | D37: =STDEV(D9:D32) -> 19.31298 | E37: =STDEV(E9:E32) -> 0.97919184 | F37: =STDEV(F9:F32) -> 1.8551167 | G37: =STDEV(G9:G32) -> 16.95444 | H37: =STDEV(H9:H32) -> 6.0582884 | I37: =STDEV(I9:I32) -> 1.4538405 | ... Q37: =STDEV(Q9:Q32) -> 0.93063443
A38: Num | B38: =COUNT(B9:B32) -> 24 | C38: =COUNT(C9:C32) -> 24 | D38: =COUNT(D9:D32) -> 24 | E38: =COUNT(E9:E32) -> 24 | F38: =COUNT(F9:F32) -> 24 | G38: =COUNT(G9:G32) -> 24 | H38: =COUNT(H9:H32) -> 24 | I38: =COUNT(I9:I32) -> 24 | ... Q38: =COUNT(Q9:Q32) -> 24
A39: DCR | B39: =IF(B38>=22,">90%",IF(B38<=22,"<90%")) -> >90% | C39: =IF(C38>=22,">90%",IF(C38<=22,"<90%")) -> >90% | D39: =IF(D38>=22,">90%",IF(D38<=22,"<90%")) -> >90% | E39: =IF(E38>=22,">90%",IF(E38<=22,"<90%")) -> >90% | F39: =IF(F38>=22,">90%",IF(F38<=22,"<90%")) -> >90% | G39: =IF(G38>=22,">90%",IF(G38<=22,"<90%")) -> >90% | H39: =IF(H38>=22,">90%",IF(H38<=22,"<90%")) -> >90% | I39: =IF(I38>=22,">90%",IF(I38<=22,"<90%")) -> >90% | ... Q39: =IF(Q38>=22,">90%",IF(Q38<=22,"<90%")) -> >90%
A40: Status | B40: =IF(B38>=22,"OK",IF(B38<=22,"LESS")) -> OK | C40: =IF(C38>=22,"OK",IF(C38<=22,"LESS")) -> OK | D40: =IF(D38>=22,"OK",IF(D38<=22,"LESS")) -> OK | E40: =IF(E38>=22,"OK",IF(E38<=22,"LESS")) -> OK | F40: =IF(F38>=22,"OK",IF(F38<=22,"LESS")) -> OK | G40: =IF(G38>=22,"OK",IF(G38<=22,"LESS")) -> OK | H40: =IF(H38>=22,"OK",IF(H38<=22,"LESS")) -> OK | I40: =IF(I38>=22,"OK",IF(I38<=22,"LESS")) -> OK | ... Q40: =IF(Q38>=22,"OK",IF(Q38<=22,"LESS")) -> OK
A43: Done by | B43: AKASH
A45: Comment

Sheet 08
A1: Station: | B1: IGKV ,RAIPUR
A2: Date: | B2: =$A$9 -> 08/11/2023 01:00 | D2: Power Off | G2: Pw.Off | L2: Link Fail | N2: Link F | P2: Maintenance | R2: Maint.
A3: Report Type: | B3: Mean | D3: Calibration | G3: Calib. | L3: Data Fail | N3: Data F | P3: Invalid | R3: Invalid
A4: Time Base: | B4: 01 Hour | D4: Zero Referrence | G4: Z.Ref | L4: Warm Up | N4: Wm. Up
A7: Date & Time | B7: NO | C7: NO2 | D7: NOX | E7: SO2 | F7: O3 | G7: PM 10 | H7: PM 2.5 | I7: BENZ | J7: WS | K7: WD | L7: TEMP | M7: HUM | N7: SR | O7: RG | P7: CO | Q7: NH3
B8: ug/m3 | C8: ug/m3 | D8: ppb | E8: ug/m3 | F8: ug/m3 | G8: ug/m3 | H8: ug/m3 | I8: ug/m3 | J8: m/sec | K8: deg | L8: degreC | M8: % | N8: w/m2 | O8: mm | P8: mg/m3 | Q8: ug/m3
A9: 08/11/2023 01:00 | B9: 18.52 | C9: 24.19 | D9: 28.84 | E9: 7.13 | F9: 2.63 | G9: 74.64 | H9: 31.48 | I9: 8.22 | J9: 0.06 | K9: 171.36 | L9: 19.6 | M9: 87.23 | N9: 0 | O9: 0 | P9: 0.88 | Q9: 4.88
A10: 08/11/2023 02:00 | B10: 27.97 | C10: 26.64 | D10: 37.7 | E10: 7.81 | F10: 2.68 | G10: 90.44 | H10: 36.2 | I10: 8.83 | J10: 0.22 | K10: 164.43 | L10: 19.94 | M10: 82.59 | N10: 0 | O10: 0 | P10: 0.99 | Q10: 5.34
A11: 08/11/2023 03:00 | B11: 30.6 | C11: 27.72 | D11: 40.37 | E11: 7.32 | F11: 2.7 | G11: 109.33 | H11: 38.89 | I11: 9.98 | J11: 0.19 | K11: 234.69 | L11: 19.24 | M11: 89.68 | N11: 0 | O11: 0 | P11: 1.06 | Q11: 5.44
A12: 08/11/2023 04:00 | B12: 30.32 | C12: 27.39 | D12: 39.98 | E12: 7.81 | F12: 2.62 | G12: 109.33 | H12: 38.89 | I12: 10.5 | J12: 0.32 | K12: 185.57 | L12: 18.48 | M12: 92.93 | N12: 0 | O12: 0 | P12: 1.09 | Q12: 5.45
A13: 08/11/2023 05:00 | B13: 32.19 | C13: 27.45 | D13: 41.51 | E13: 8.04 | F13: 2.62 | G13: 107.53 | H13: 41.71 | I13: 10.92 | J13: 0.1 | K13: 187.21 | L13: 18.18 | M13: 92.5 | N13: 0 | O13: 0 | P13: 1.14 | Q13: 5.52
A14: 08/11/2023 06:00 | B14: 35.59 | C14: 27.72 | D14: 44.33 | E14: 8.18 | F14: 2.62 | G14: 111.71 | H14: 42.45 | I14: 11.62 | J14: 0.12 | K14: 195.83 | L14: 18.05 | M14: 94.38 | N14: 0 | O14: 0 | P14: 1.19 | Q14: 5.7
A15: 08/11/2023 07:00 | B15: 51.47 | C15: 28.96 | D15: 56.87 | E15: 8.52 | F15: 2.69 | G15: 125.47 | H15: 44.98 | I15: 12.48 | J15: 0.35 | K15: 234.5 | L15: 18.41 | M15: 95.12 | N15: 28 | O15: 0 | P15: 1.25 | Q15: 6.25
A16: 08/11/2023 08:00 | B16: 50.96 | C16: 29.02 | D16: 56.54 | E16: 8.24 | F16: 2.69 | G16: 135.59 | H16: 46.81 | I16: 12.88 | J16: 0.1 | K16: 253.41 | L16: 21.65 | M16: 90.84 | N16: 165.8 | O16: 0 | P16: 1.29 | Q16: 6.24
A17: 08/11/2023 09:00 | B17: 48.85 | C17: 29.73 | D17: 55.33 | E17: 8 | F17: 2.83 | G17: 160.72 | H17: 56.49 | I17: 13.47 | J17: 0.35 | K17: 253.36 | L17: 25.37 | M17: 68.72 | N17: 296.9 | O17: 0 | P17: 1.36 | Q17: 6.13
A18: 08/11/2023 10:00 | B18: 40.52 | C18: 31.25 | D18: 49.57 | E18: 7.58 | F18: 2.8 | G18: 188.26 | H18: 66.91 | I18: 13.6 | J18: 0.21 | K18: 202.75 | L18: 27.38 | M18: 55 | N18: 439.2 | O18: 0 | P18: 1.41 | Q18: 5.88
A19: 08/11/2023 11:00 | B19: 31.54 | C19: 32.69 | D19: 42.89 | E19: 5.71 | F19: 2.88 | G19: 188.26 | H19: 66.91 | I19: 13.64 | J19: 0.26 | K19: 252.41 | L19: 29.24 | M19: 43.53 | N19: 501.2 | O19: 0 | P19: 1.4 | Q19: 5.58
A20: 08/11/2023 12:00 | B20: 21.65 | C20: 34.03 | D20: 36.12 | E20: 6.29 | F20: 4.7 | G20: 164.08 | H20: 61.98 | I20: 13.2 | J20: 0.32 | K20: 243.92 | L20: 30.82 | M20: 38.98 | N20: 577.9 | O20: 0 | P20: 1.39 | Q20: 5.14
... A32: 08/11/2023 24:00 | B32: 10.51 | C32: 26.58 | D32: 23.67 | E32: 7.71 | F32: 2.75 | G32: 90.82 | H32: 38.75 | I32: 9.3 | J32: 0.13 | K32: 231.07 | L32: 20.26 | M32: 82.06 | N32: 0 | O32: 0 | P32: 1 | Q32: 4.61
A34: Min | B34: =MIN(B9:B32) -> 3.8 | C34: =MIN(C9:C32) -> 24.19 | D34: =MIN(D9:D32) -> 18.57 | E34: =MIN(E9:E32) -> 4.23 | F34: =MIN(F9:F32) -> 2.56 | G34: =MIN(G9:G32) -> 74.64 | H34: =MIN(H9:H32) -> 31.48 | I34: =MIN(I9:I32) -> 8.22 | ... Q34: =MIN(Q9:Q32) -> 4.3
A35: Max | B35: =MAX(B9:B32) -> 51.47 | C35: =MAX(C9:C32) -> 34.03 | D35: =MAX(D9:D32) -> 56.87 | E35: =MAX(E9:E32) -> 8.52 | F35: =MAX(F9:F32) -> 9.98 | G35: =MAX(G9:G32) -> 196.74 | H35: =MAX(H9:H32) -> 66.91 | I35: =MAX(I9:I32) -> 13.64 | ... Q35: =MAX(Q9:Q32) -> 6.25
A36: Avg | B36: =AVERAGE(B9:B32) -> 21.5425 | C36: =AVERAGE(C9:C32) -> 28.199167 | D36: =AVERAGE(D9:D32) -> 33.13375 | E36: =AVERAGE(E9:E32) -> 7.00875 | F36: =AVERAGE(F9:F32) -> 3.7875 | G36: =AVERAGE(G9:G32) -> 130.01667 | H36: =AVERAGE(H9:H32) -> 45.142083 | I36: =AVERAGE(I9:I32) -> 10.637917 | ... Q36: =AVERAGE(Q9:Q32) -> 5.0566667
A37: Stdev | B37: =STDEV(B9:B32) -> 15.809288 | C37: =STDEV(C9:C32) -> 2.5404894 | D37: =STDEV(D9:D32) -> 12.906854 | E37: =STDEV(E9:E32) -> 1.1128706 | F37: =STDEV(F9:F32) -> 2.2228346 | G37: =STDEV(G9:G32) -> 36.091981 | H37: =STDEV(H9:H32) -> 9.6332427 | I37: =STDEV(I9:I32) -> 1.8289959 | ... Q37: =STDEV(Q9:Q32) -> 0.66296217
A38: Num | B38: =COUNT(B9:B32) -> 24 | C38: =COUNT(C9:C32) -> 24 | D38: =COUNT(D9:D32) -> 24 | E38: =COUNT(E9:E32) -> 24 | F38: =COUNT(F9:F32) -> 24 | G38: =COUNT(G9:G32) -> 24 | H38: =COUNT(H9:H32) -> 24 | I38: =COUNT(I9:I32) -> 24 | ... Q38: =COUNT(Q9:Q32) -> 24
A39: DCR | B39: =IF(B38>=22,">90%",IF(B38<=22,"<90%")) -> >90% | C39: =IF(C38>=22,">90%",IF(C38<=22,"<90%")) -> >90% | D39: =IF(D38>=22,">90%",IF(D38<=22,"<90%")) -> >90% | E39: =IF(E38>=22,">90%",IF(E38<=22,"<90%")) -> >90% | F39: =IF(F38>=22,">90%",IF(F38<=22,"<90%")) -> >90% | G39: =IF(G38>=22,">90%",IF(G38<=22,"<90%")) -> >90% | H39: =IF(H38>=22,">90%",IF(H38<=22,"<90%")) -> >90% | I39: =IF(I38>=22,">90%",IF(I38<=22,"<90%")) -> >90% | ... Q39: =IF(Q38>=22,">90%",IF(Q38<=22,"<90%")) -> >90%
A40: Status | B40: =IF(B38>=22,"OK",IF(B38<=22,"LESS")) -> OK | C40: =IF(C38>=22,"OK",IF(C38<=22,"LESS")) -> OK | D40: =IF(D38>=22,"OK",IF(D38<=22,"LESS")) -> OK | E40: =IF(E38>=22,"OK",IF(E38<=22,"LESS")) -> OK | F40: =IF(F38>=22,"OK",IF(F38<=22,"LESS")) -> OK | G40: =IF(G38>=22,"OK",IF(G38<=22,"LESS")) -> OK | H40: =IF(H38>=22,"OK",IF(H38<=22,"LESS")) -> OK | I40: =IF(I38>=22,"OK",IF(I38<=22,"LESS")) -> OK | ... Q40: =IF(Q38>=22,"OK",IF(Q38<=22,"LESS")) -> OK
A43: Done by | B43: AKASH
A45: Comment

Sheet 09
A1: Station: | B1: IGKV ,RAIPUR
A2: Date: | B2: =$A$9 -> 09/11/2023 01:00 | D2: Power Off | G2: Pw.Off | L2: Link Fail | N2: Link F | P2: Maintenance | R2: Maint.
A3: Report Type: | B3: Mean | D3: Calibration | G3: Calib. | L3: Data Fail | N3: Data F | P3: Invalid | R3: Invalid
A4: Time Base: | B4: 01 Hour | D4: Zero Referrence | G4: Z.Ref | L4: Warm Up | N4: Wm. Up
A7: Date & Time | B7: NO | C7: NO2 | D7: NOX | E7: SO2 | F7: O3 | G7: PM 10 | H7: PM 2.5 | I7: BENZ | J7: WS | K7: WD | L7: TEMP | M7: HUM | N7: SR | O7: RG | P7: CO | Q7: NH3
B8: ug/m3 | C8: ug/m3 | D8: ppb | E8: ug/m3 | F8: ug/m3 | G8: ug/m3 | H8: ug/m3 | I8: ug/m3 | J8: m/sec | K8: deg | L8: degreC | M8: % | N8: w/m2 | O8: mm | P8: mg/m3 | Q8: ug/m3
A9: 09/11/2023 01:00 | B9: 11.66 | C9: 26.71 | D9: 24.56 | E9: 7.63 | F9: 2.64 | G9: 90.82 | H9: 38.75 | I9: 9.52 | J9: 0.12 | K9: 213.6 | L9: 19.86 | M9: 88.64 | N9: 0 | O9: 0 | P9: 1.02 | Q9: 4.69
A10: 09/11/2023 02:00 | B10: 10.96 | C10: 26.34 | D10: 23.9 | E10: 7.68 | F10: 2.64 | G10: 76.75 | H10: 36.52 | I10: 9.57 | J10: 0.12 | K10: 217.45 | L10: 19.38 | M10: 86.04 | N10: 0 | O10: 0 | P10: 1.02 | Q10: 4.69
A11: 09/11/2023 03:00 | B11: 11.53 | C11: 25.38 | D11: 23.12 | E11: 5.99 | F11: 2.95 | G11: 76.75 | H11: 36.32 | I11: 9.41 | J11: 0.15 | K11: 199.58 | L11: 19.32 | M11: 83.98 | N11: 0 | O11: 0 | P11: 0.99 | Q11: 4.63
A12: 09/11/2023 04:00 | B12: 12.21 | C12: 24.36 | D12: 23.87 | E12: 5.21 | F12: 2.66 | G12: 75.67 | H12: 34.88 | I12: 9.13 | J12: 0.22 | K12: 201.83 | L12: 18.92 | M12: 89.21 | N12: 0 | O12: 0 | P12: 0.92 | Q12: 4.67
A13: 09/11/2023 05:00 | B13: 16.4 | C13: 25.6 | D13: 27.87 | E13: 5.56 | F13: 2.72 | G13: 81.29 | H13: 32.99 | I13: 8.96 | J13: 0.13 | K13: 198.78 | L13: 18.36 | M13: 89.23 | N13: 0 | O13: 0 | P13: 0.91 | Q13: 4.83
A14: 09/11/2023 06:00 | B14: 17.49 | C14: 25.5 | D14: 28.67 | E14: 5.66 | F14: 2.67 | G14: 81.29 | H14: 32.78 | I14: 8.78 | J14: 0.13 | K14: 240.31 | L14: 18.37 | M14: 91.68 | N14: 0 | O14: 0 | P14: 0.89 | Q14: 4.89
A15: 09/11/2023 07:00 | B15: 18.14 | C15: 24.97 | D15: 28.94 | E15: 5.67 | F15: 2.55 | G15: 63.49 | H15: 31.75 | I15: 8.62 | J15: 0.18 | K15: 172.44 | L15: 19.36 | M15: 90.87 | N15: 28.3 | O15: 0 | P15: 0.89 | Q15: 4.89
A16: 09/11/2023 08:00 | B16: 23.61 | C16: 27.58 | D16: 34.7 | E16: 6.17 | F16: 2.75 | G16: 97.83 | H16: 33.43 | I16: 8.93 | J16: 0.28 | K16: 150.26 | L16: 22.38 | M16: 84.15 | N16: 173.9 | O16: 0 | P16: 0.99 | Q16: 5.17
A17: 09/11/2023 09:00 | B17: 23.09 | C17: 31.34 | D17: 34.74 | E17: 6.61 | F17: 2.87 | G17: 147.45 | H17: 48.27 | I17: 10.3 | J17: 0.21 | K17: 172.25 | L17: 26.26 | M17: 65.57 | N17: 341.9 | O17: 0 | P17: 1.12 | Q17: 5.18
A18: 09/11/2023 10:00 | B18: 17.67 | C18: 31.93 | D18: 32.01 | E18: 6.63 | F18: 3.3 | G18: 147.45 | H18: 48.27 | I18: 10.8 | J18: 0.23 | K18: 260.99 | L18: 28.43 | M18: 50.62 | N18: 483.9 | O18: 0 | P18: 1.15 | Q18: 5.01
A19: 09/11/2023 11:00 | B19: 10.1 | C19: 30.94 | D19: 25.62 | E19: 6.34 | F19: 3.99 | G19: 128.14 | H19: 47.77 | I19: 10.61 | J19: 0.27 | K19: 194.87 | L19: 30.47 | M19: 45.26 | N19: 553.1 | O19: 0 | P19: 1.14 | Q19: 4.66
A20: 09/11/2023 12:00 | B20: 5.11 | C20: 28.22 | D20: 20.19 | E20: 6.77 | F20: 5.23 | G20: 111.73 | H20: 47.77 | I20: 10.3 | J20: 0.38 | K20: 210.87 | L20: 31.85 | M20: 37.37 | N20: 630.1 | O20: 0 | P20: 1.08 | Q20: 4.39
... A32: 09/11/2023 24:00 | B32: 8.83 | C32: 22.46 | D32: 20.17 | E32: 5.52 | F32: 2.69 | G32: 92.39 | H32: 29.37 | I32: 6.64 | J32: 0.15 | K32: 229.9 | L32: 20.55 | M32: 78.55 | N32: 0 | O32: 0 | P32: 0.79 | Q32: 4.48
A34: Min | B34: =MIN(B9:B32) -> 4.31 | C34: =MIN(C9:C32) -> 18.93 | D34: =MIN(D9:D32) -> 14.87 | E34: =MIN(E9:E32) -> 5.21 | F34: =MIN(F9:F32) -> 2.55 | G34: =MIN(G9:G32) -> 63.49 | H34: =MIN(H9:H32) -> 28.75 | I34: =MIN(I9:I32) -> 6.47 | ... Q34: =MIN(Q9:Q32) -> 4.23
A35: Max | B35: =MAX(B9:B32) -> 23.61 | C35: =MAX(C9:C32) -> 31.93 | D35: =MAX(D9:D32) -> 34.74 | E35: =MAX(E9:E32) -> 7.68 | F35: =MAX(F9:F32) -> 6.7 | G35: =MAX(G9:G32) -> 152.81 | H35: =MAX(H9:H32) -> 48.27 | I35: =MAX(I9:I32) -> 10.8 | ... Q35: =MAX(Q9:Q32) -> 5.18
A36: Avg | B36: =AVERAGE(B9:B32) -> 10.354167 | C36: =AVERAGE(C9:C32) -> 24.744167 | D36: =AVERAGE(D9:D32) -> 22.437083 | E36: =AVERAGE(E9:E32) -> 6.0591667 | F36: =AVERAGE(F9:F32) -> 3.675 | G36: =AVERAGE(G9:G32) -> 101.55042 | H36: =AVERAGE(H9:H32) -> 36.081667 | I36: =AVERAGE(I9:I32) -> 8.445 | ... Q36: =AVERAGE(Q9:Q32) -> 4.5695833
A37: Stdev | B37: =STDEV(B9:B32) -> 6.0589552 | C37: =STDEV(C9:C32) -> 3.5154243 | D37: =STDEV(D9:D32) -> 6.1119843 | E37: =STDEV(E9:E32) -> 0.64210196 | F37: =STDEV(F9:F32) -> 1.3411287 | G37: =STDEV(G9:G32) -> 29.208729 | H37: =STDEV(H9:H32) -> 6.2460225 | I37: =STDEV(I9:I32) -> 1.4355154 | ... Q37: =STDEV(Q9:Q32) -> 0.29978948
A38: Num | B38: =COUNT(B9:B32) -> 24 | C38: =COUNT(C9:C32) -> 24 | D38: =COUNT(D9:D32) -> 24 | E38: =COUNT(E9:E32) -> 24 | F38: =COUNT(F9:F32) -> 24 | G38: =COUNT(G9:G32) -> 24 | H38: =COUNT(H9:H32) -> 24 | I38: =COUNT(I9:I32) -> 24 | ... Q38: =COUNT(Q9:Q32) -> 24
A39: DCR | B39: =IF(B38>=22,">90%",IF(B38<=22,"<90%")) -> >90% | C39: =IF(C38>=22,">90%",IF(C38<=22,"<90%")) -> >90% | D39: =IF(D38>=22,">90%",IF(D38<=22,"<90%")) -> >90% | E39: =IF(E38>=22,">90%",IF(E38<=22,"<90%")) -> >90% | F39: =IF(F38>=22,">90%",IF(F38<=22,"<90%")) -> >90% | G39: =IF(G38>=22,">90%",IF(G38<=22,"<90%")) -> >90% | H39: =IF(H38>=22,">90%",IF(H38<=22,"<90%")) -> >90% | I39: =IF(I38>=22,">90%",IF(I38<=22,"<90%")) -> >90% | ... Q39: =IF(Q38>=22,">90%",IF(Q38<=22,"<90%")) -> >90%
A40: Status | B40: =IF(B38>=22,"OK",IF(B38<=22,"LESS")) -> OK | C40: =IF(C38>=22,"OK",IF(C38<=22,"LESS")) -> OK | D40: =IF(D38>=22,"OK",IF(D38<=22,"LESS")) -> OK | E40: =IF(E38>=22,"OK",IF(E38<=22,"LESS")) -> OK | F40: =IF(F38>=22,"OK",IF(F38<=22,"LESS")) -> OK | G40: =IF(G38>=22,"OK",IF(G38<=22,"LESS")) -> OK | H40: =IF(H38>=22,"OK",IF(H38<=22,"LESS")) -> OK | I40: =IF(I38>=22,"OK",IF(I38<=22,"LESS")) -> OK | ... Q40: =IF(Q38>=22,"OK",IF(Q38<=22,"LESS")) -> OK
A43: Done by | B43: AKASH
A45: Comment

Sheet 10
A1: Station: | B1: IGKV ,RAIPUR
A2: Date: | B2: =$A$9 -> 10/11/2023 01:00 | D2: Power Off | G2: Pw.Off | L2: Link Fail | N2: Link F | P2: Maintenance | R2: Maint.
A3: Report Type: | B3: Mean | D3: Calibration | G3: Calib. | L3: Data Fail | N3: Data F | P3: Invalid | R3: Invalid
A4: Time Base: | B4: 01 Hour | D4: Zero Referrence | G4: Z.Ref | L4: Warm Up | N4: Wm. Up
A7: Date & Time | B7: NO | C7: NO2 | D7: NOX | E7: SO2 | F7: O3 | G7: PM 10 | H7: PM 2.5 | I7: BENZ | J7: WS | K7: WD | L7: TEMP | M7: HUM | N7: SR | O7: RG | P7: CO | Q7: NH3
B8: ug/m3 | C8: ug/m3 | D8: ppb | E8: ug/m3 | F8: ug/m3 | G8: ug/m3 | H8: ug/m3 | I8: ug/m3 | J8: m/sec | K8: deg | L8: degreC | M8: % | N8: w/m2 | O8: mm | P8: mg/m3 | Q8: ug/m3
A9: 10/11/2023 01:00 | B9: 13.49 | C9: 23.98 | D9: 24.7 | E9: 5.86 | F9: 2.65 | G9: 89.54 | H9: 31.6 | I9: 6.87 | J9: 0.13 | K9: 259.75 | L9: 20.46 | M9: 77.75 | N9: 0 | O9: 0 | P9: 0.83 | Q9: 4.69
A10: 10/11/2023 02:00 | B10: 18.48 | C10: 26.36 | D10: 29.94 | E10: 6.16 | F10: 2.59 | G10: 88.22 | H10: 33.31 | I10: 7.54 | J10: 0.13 | K10: 221.69 | L10: 20.21 | M10: 85.84 | N10: 0 | O10: 0 | P10: 0.91 | Q10: 4.91
A11: 10/11/2023 03:00 | B11: 21.7 | C11: 27.43 | D11: 32.94 | E11: 5.41 | F11: 2.57 | G11: 94.58 | H11: 34.36 | I11: 8.42 | J11: 0.24 | K11: 208.38 | L11: 19.7 | M11: 91.03 | N11: 0 | O11: 0 | P11: 1.02 | Q11: 5.07
A12: 10/11/2023 04:00 | B12: 21.01 | C12: 27.4 | D12: 32.52 | E12: 5.12 | F12: 2.76 | G12: 94.58 | H12: 34.36 | I12: 8.77 | J12: 0.14 | K12: 187.65 | L12: 19.29 | M12: 88.61 | N12: 0 | O12: 0 | P12: 1.04 | Q12: 5.06
A13: 10/11/2023 05:00 | B13: 18.76 | C13: 26.36 | D13: 30.17 | E13: 5.13 | F13: 2.69 | G13: 83.01 | H13: 34.34 | I13: 8.75 | J13: 0.1 | K13: 216.33 | L13: 18.85 | M13: 91.89 | N13: 0 | O13: 0 | P13: 1.02 | Q13: 4.98
A14: 10/11/2023 06:00 | B14: 16.92 | C14: 25.21 | D14: 28.09 | E14: 4.96 | F14: 2.61 | G14: 73.12 | H14: 30.96 | I14: 8.66 | J14: 0.13 | K14: 195.15 | L14: 18.5 | M14: 92.52 | N14: 0 | O14: 0 | P14: 0.99 | Q14: 4.91
A15: 10/11/2023 07:00 | B15: 16.01 | C15: 24.85 | D15: 27.18 | E15: 4.98 | F15: 2.55 | G15: 74.95 | H15: 31.2 | I15: 8.47 | J15: 0.23 | K15: 175.56 | L15: 19.16 | M15: 91.88 | N15: 29.7 | O15: 0 | P15: 0.96 | Q15: 4.86
A16: 10/11/2023 08:00 | B16: 14.83 | C16: 25.45 | D16: 26 | E16: 5.3 | F16: 2.65 | G16: 77.3 | H16: 31.2 | I16: 8.34 | J16: 0.28 | K16: 168.7 | L16: 22.77 | M16: 82.78 | N16: 177.6 | O16: 0 | P16: 0.93 | Q16: 4.82
A17: 10/11/2023 09:00 | B17: 13.07 | C17: 23.71 | D17: 24.22 | E17: 4.7 | F17: 2.92 | G17: 77.3 | H17: 32.35 | I17: 8.46 | J17: 0.13 | K17: 260.26 | L17: 25.95 | M17: 68.22 | N17: 327.9 | O17: 0 | P17: 0.9 | Q17: 4.7
A18: 10/11/2023 10:00 | B18: 11.17 | C18: 23.31 | D18: 22.05 | E18: 4.47 | F18: 3.11 | G18: 71.26 | H18: 32.35 | I18: 8.43 | J18: 0.16 | K18: 199.64 | L18: 28.7 | M18: 55.69 | N18: 474.4 | O18: 0 | P18: 0.86 | Q18: 4.59
A19: 10/11/2023 11:00 | B19: 8.91 | C19: 21.48 | D19: 19.72 | E19: 5.67 | F19: 3.6 | G19: 70.78 | H19: 32.17 | I19: 8.28 | J19: 0.3 | K19: 235.09 | L19: 30.14 | M19: 44.75 | N19: 542.1 | O19: 0 | P19: 0.84 | Q19: 4.48
A20: 10/11/2023 12:00 | B20: 6.58 | C20: 20.64 | D20: 17.37 | E20: 6.27 | F20: 6.38 | G20: 65.73 | H20: 30.5 | I20: 7.89 | J20: 0.21 | K20: 144.48 | L20: 31.44 | M20: 40.94 | N20: 587.2 | O20: 0 | P20: 0.79 | Q20: 4.34
... A22: 10/11/2023 14:00 | B22: 4.36 | C22: 20.6 | D22: 15.51 | E22: 8.37 | F22: 15.53 | G22: 73.35 | H22: 29.59 | I22: 7.03 | J22: 0.45 | K22: 256.84 | L22: 32.5 | M22: 35.53 | N22: 490.4 | O22: 0 | P22: 0.76 | Q22: 4.23
A23: 10/11/2023 15:00 | B23: 3.64 | C23: 22.4 | D23: 14.87 | E23: 18.48 | F23: 44.17 | G23: Calib. | H23: Calib. | I23: 6.47 | J23: 0.45 | K23: 42.34 | L23: 32.2 | M23: 34.75 | N23: 382.8 | O23: 0 | P23: 0.72 | Q23: 4.25
A24: 10/11/2023 16:00 | B24: 4.77 | C24: 28.92 | D24: 19.98 | E24: 9.45 | F24: 11.91 | G24: 67.61 | H24: 18.73 | I24: 5.12 | J24: 0.44 | K24: 74.5 | L24: 30.74 | M24: 36.68 | N24: 88.3 | O24: 0 | P24: 0.72 | Q24: 4.29
A25: 10/11/2023 17:00 | B25: 5.43 | C25: 29.19 | D25: 20.72 | E25: 7.43 | F25: 5.3 | G25: 78.7 | H25: 23.64 | I25: 4.92 | J25: 0.26 | K25: 171.29 | L25: 29.96 | M25: 50 | N25: 45 | O25: 0 | P25: 0.71 | Q25: 4.31
A26: 10/11/2023 18:00 | B26: 6.6 | C26: 29.01 | D26: 21.8 | E26: 7.35 | F26: 4.37 | G26: 89.16 | H26: 27.25 | I26: 4.87 | J26: 0.25 | K26: 174.16 | L26: 27.37 | M26: 64.53 | N26: 0 | O26: 0 | P26: 0.77 | Q26: 4.31
A27: 10/11/2023 19:00 | B27: 8.51 | C27: 26.71 | D27: 20.96 | E27: 5.86 | F27: 3.36 | G27: 99.65 | H27: 29.88 | I27: 5.57 | J27: 0.2 | K27: 230.85 | L27: 25.7 | M27: 68.17 | N27: 0 | O27: 0 | P27: 0.76 | Q27: 4.36
A28: 10/11/2023 20:00 | B28: 9.05 | C28: 24.67 | D28: 21.06 | E28: 5.57 | F28: 2.95 | G28: 101.83 | H28: 33.25 | I28: 5.9 | J28: 0.13 | K28: 214.88 | L28: 24.49 | M28: 74.04 | N28: 0 | O28: 0 | P28: 0.77 | Q28: 4.37
A29: 10/11/2023 21:00 | B29: 9.95 | C29: 23.3 | D29: 21.48 | E29: 5.85 | F29: 2.79 | G29: 101.83 | H29: 33.25 | I29: 6.1 | J29: 0.15 | K29: 173.88 | L29: 23.45 | M29: 81.6 | N29: 0 | O29: 0 | P29: 0.78 | Q29: 4.42
A30: 10/11/2023 22:00 | B30: 11.04 | C30: 22.73 | D30: 22.08 | E30: 6 | F30: 2.76 | G30: 94.04 | H30: 32.37 | I30: 6.33 | J30: 0.12 | K30: 225.8 | L30: 22.68 | M30: 84.45 | N30: 0 | O30: 0 | P30: 0.81 | Q30: 4.44
A31: 10/11/2023 23:00 | B31: 11.62 | C31: 22.66 | D31: 22.5 | E31: 6.13 | F31: 2.74 | G31: 94.04 | H31: 32.55 | I31: 6.55 | J31: 0.13 | K31: 240.08 | L31: 21.79 | M31: 86.88 | N31: 0 | O31: 0 | P31: 0.87 | Q31: 4.49
A32: 10/11/2023 24:00 | B32: 11.48 | C32: 23.94 | D32: 22.92 | E32: 7.03 | F32: 2.7 | G32: 85.25 | H32: 33.02 | I32: 7.18 | J32: 0.16 | K32: 237.44 | L32: 21.48 | M32: 87.42 | N32: 0 | O32: 0 | P32: 0.96 | Q32: 4.5
